<robot name="onshape">
  <link name="buste">
    <visual>
      <origin xyz="0.023714486581865652781 -2.417207568411775005e-17 -0.010000000000000001943" rpy="0 -0 1.570796326794896558" />
      <geometry>
        <mesh filename="package:///buste.stl" />
      </geometry>
      <material name="buste_material">
        <color rgba="0.61568627450980395466 0.81176470588235294379 0.92941176470588238168 1.0" />
      </material>
    </visual>
    <collision>
      <origin xyz="0.023714486581865652781 -2.417207568411775005e-17 -0.010000000000000001943" rpy="0 -0 1.570796326794896558" />
      <geometry>
        <mesh filename="package:///buste.stl" />
      </geometry>
    </collision>
    <inertial>
      <origin xyz="0.0022859555586266684657 -1.8042136335437623588e-17 0.049518025500839904507" rpy="0 0 0" />
      <mass value="17.423073581028333479" />
      <inertia ixx="0.18723361629930243555" ixy="0" ixz="0.00017994559990526189965" iyy="0.064444255179420040225" iyz="0" izz="0.22197571207699803852" />
    </inertial>
  </link>
  <link name="hip">
    <inertial>
      <origin xyz="0 0 0" rpy="0 0 0" />
      <mass value="1e-9" />
      <inertia ixx="0" ixy="0" ixz="0" iyy="0" iyz="0" izz="0" />
    </inertial>
  </link>
  <joint name="hip_frame" type="fixed">
    <origin xyz="2.4027501270446963816e-19 0.074999999999999997224 -0.097500000000000003331" rpy="0 -0 0" />
    <parent link="buste" />
    <child link="hip" />
    <axis xyz="0 0 0" />
  </joint>
  <link name="hip_x">
    <visual>
      <origin xyz="0 0 -0.093499999999999999778" rpy="0 -0 0" />
      <geometry>
        <mesh filename="package:///hip_x.stl" />
      </geometry>
      <material name="hip_x_material">
        <color rgba="0.2313725490196078538 0.38039215686274507888 0.7058823529411765163 1.0" />
      </material>
    </visual>
    <collision>
      <origin xyz="0 0 -0.093499999999999999778" rpy="0 -0 0" />
      <geometry>
        <mesh filename="package:///hip_x.stl" />
      </geometry>
    </collision>
    <visual>
      <origin xyz="-1.3877787807814456755e-17 0 -0.093499999999999999778" rpy="0 -0 0" />
      <geometry>
        <mesh filename="package:///actuator_hips_z.stl" />
      </geometry>
      <material name="actuator_hips_z_material">
        <color rgba="1 0 0 1.0" />
      </material>
    </visual>
    <collision>
      <origin xyz="-1.3877787807814456755e-17 0 -0.093499999999999999778" rpy="0 -0 0" />
      <geometry>
        <mesh filename="package:///actuator_hips_z.stl" />
      </geometry>
    </collision>
    <inertial>
      <origin xyz="0.017054714011326667367 -6.4780929190869858455e-09 -0.069758223152321344185" rpy="0 0 0" />
      <mass value="0.79889634230491635147" />
      <inertia ixx="0.0013635138447202596775" ixy="1.3354706702426279735e-10" ixz="0.00032719026686676012505" iyy="0.0025036050424484005902" iyz="1.1905127724661978864e-12" izz="0.0018853339334759925718" />
    </inertial>
  </link>
  <link name="hip_y">
    <visual>
      <origin xyz="0 0 -0.026000000000000002276" rpy="1.570796326794896558 1.570796326794896558 0" />
      <geometry>
        <mesh filename="package:///hip_y.stl" />
      </geometry>
      <material name="hip_y_material">
        <color rgba="0.64705882352941179736 0.64705882352941179736 0.64705882352941179736 1.0" />
      </material>
    </visual>
    <collision>
      <origin xyz="0 0 -0.026000000000000002276" rpy="1.570796326794896558 1.570796326794896558 0" />
      <geometry>
        <mesh filename="package:///hip_y.stl" />
      </geometry>
    </collision>
    <inertial>
      <origin xyz="-0.0055313247017613710252 4.0880417798708336253e-10 -0.025999999997307263883" rpy="0 0 0" />
      <mass value="0.38394260097400612075" />
      <inertia ixx="0.00025283500733849957349" ixy="3.2035415086675115156e-11" ixz="-1.5625927720724130284e-12" iyy="0.00042233469379332656693" iyz="8.8873417128492104446e-11" izz="0.00051565216560767364058" />
    </inertial>
  </link>
  <link name="hip_z">
    <visual>
      <origin xyz="2.7755575615628913511e-17 -1.3877787807814456755e-17 -0.14299999999999998823" rpy="-1.570796326794896558 -2.4010857238027045242e-32 3.141592653589793116" />
      <geometry>
        <mesh filename="package:///actuator_hips_x.stl" />
      </geometry>
      <material name="actuator_hips_x_material">
        <color rgba="1 0 0 1.0" />
      </material>
    </visual>
    <collision>
      <origin xyz="2.7755575615628913511e-17 -1.3877787807814456755e-17 -0.14299999999999998823" rpy="-1.570796326794896558 -2.4010857238027045242e-32 3.141592653589793116" />
      <geometry>
        <mesh filename="package:///actuator_hips_x.stl" />
      </geometry>
    </collision>
    <visual>
      <origin xyz="0 0 0.078000000000000013767" rpy="1.570796326794896558 2.4010857238027045242e-32 -4.9811775657316047501e-17" />
      <geometry>
        <mesh filename="package:///hip_z.stl" />
      </geometry>
      <material name="hip_z_material">
        <color rgba="0.61568627450980395466 0.81176470588235294379 0.92941176470588238168 1.0" />
      </material>
    </visual>
    <collision>
      <origin xyz="0 0 0.078000000000000013767" rpy="1.570796326794896558 2.4010857238027045242e-32 -4.9811775657316047501e-17" />
      <geometry>
        <mesh filename="package:///hip_z.stl" />
      </geometry>
    </collision>
    <visual>
      <origin xyz="0.036373347091698829403 -1.3877787807814456755e-17 0.027999999999999997113" rpy="-1.570796326794896558 -2.4010857238027045242e-32 3.141592653589793116" />
      <geometry>
        <mesh filename="package:///actuator_knee.stl" />
      </geometry>
      <material name="actuator_knee_material">
        <color rgba="1 0 0 1.0" />
      </material>
    </visual>
    <collision>
      <origin xyz="0.036373347091698829403 -1.3877787807814456755e-17 0.027999999999999997113" rpy="-1.570796326794896558 -2.4010857238027045242e-32 3.141592653589793116" />
      <geometry>
        <mesh filename="package:///actuator_knee.stl" />
      </geometry>
    </collision>
    <inertial>
      <origin xyz="0.0055325539197899195262 0.18769424803443374161 0.050351704099684008176" rpy="0 0 0" />
      <mass value="5.8694864970653579661" />
      <inertia ixx="0.13019083513029794386" ixy="-0.0038753626410786847466" ixz="-0.00086026287749622388796" iyy="0.026228042799416206865" iyz="-0.009932825904601377473" izz="0.11341736530762283608" />
    </inertial>
  </link>
  <link name="knee">
    <visual>
      <origin xyz="5.5511151231257827021e-17 5.5511151231257827021e-17 0.045986999999999972344" rpy="1.570796326794896558 1.5134452057357974515e-32 -2.9100559463524521154e-17" />
      <geometry>
        <mesh filename="package:///actuator_knee_foot.stl" />
      </geometry>
      <material name="actuator_knee_foot_material">
        <color rgba="1 0 0 1.0" />
      </material>
    </visual>
    <collision>
      <origin xyz="5.5511151231257827021e-17 5.5511151231257827021e-17 0.045986999999999972344" rpy="1.570796326794896558 1.5134452057357974515e-32 -2.9100559463524521154e-17" />
      <geometry>
        <mesh filename="package:///actuator_knee_foot.stl" />
      </geometry>
    </collision>
    <visual>
      <origin xyz="0 0 0.045986999999999986222" rpy="1.570796326794896558 1.5134452057357974515e-32 -2.9100559463524521154e-17" />
      <geometry>
        <mesh filename="package:///knee.stl" />
      </geometry>
      <material name="knee_material">
        <color rgba="0.61568627450980395466 0.81176470588235294379 0.92941176470588238168 1.0" />
      </material>
    </visual>
    <collision>
      <origin xyz="0 0 0.045986999999999986222" rpy="1.570796326794896558 1.5134452057357974515e-32 -2.9100559463524521154e-17" />
      <geometry>
        <mesh filename="package:///knee.stl" />
      </geometry>
    </collision>
    <inertial>
      <origin xyz="0.0078531393597166057607 0.12111110124104412789 0.040634708782777688441" rpy="0 0 0" />
      <mass value="3.1208537261855555656" />
      <inertia ixx="0.038229209074074871344" ixy="-0.00049246646309945353061" ixz="-0.00010865929182100906648" iyy="0.012198141411248501417" iyz="0.00095377997534115503946" izz="0.030278543869092917201" />
    </inertial>
  </link>
  <link name="ankle">
    <visual>
      <origin xyz="3.0531133177191804862e-16 -0.32492299999999979532 -0.075212999999999974321" rpy="1.570796326794896558 8.4027677057582109606e-34 -1.0918493828887882866e-17" />
      <geometry>
        <mesh filename="package:///ankle.stl" />
      </geometry>
      <material name="ankle_material">
        <color rgba="0.64705882352941179736 0.64705882352941179736 0.64705882352941179736 1.0" />
      </material>
    </visual>
    <collision>
      <origin xyz="3.0531133177191804862e-16 -0.32492299999999979532 -0.075212999999999974321" rpy="1.570796326794896558 8.4027677057582109606e-34 -1.0918493828887882866e-17" />
      <geometry>
        <mesh filename="package:///ankle.stl" />
      </geometry>
    </collision>
    <inertial>
      <origin xyz="-0.0019235642903051434257 0.00022331957414511993676 -0.090755982071927407406" rpy="0 0 0" />
      <mass value="0.42546920173156782541" />
      <inertia ixx="0.0011060324937698857214" ixy="-1.1573687189319687013e-05" ixz="7.0308974432228271288e-05" iyy="0.0010920583433501301462" iyz="2.4867781667232776344e-05" izz="0.00024915310079955197819" />
    </inertial>
  </link>
  <link name="foot_part">
    <visual>
      <origin xyz="4.1633363423443370266e-17 0.0048038851135427940164 0.033023499999999997301" rpy="-1.570796326794896558 -1.570796326794896558 0" />
      <geometry>
        <mesh filename="package:///foot_part.stl" />
      </geometry>
      <material name="foot_part_material">
        <color rgba="0.61568627450980395466 0.81176470588235294379 0.92941176470588238168 1.0" />
      </material>
    </visual>
    <collision>
      <origin xyz="4.1633363423443370266e-17 0.0048038851135427940164 0.033023499999999997301" rpy="-1.570796326794896558 -1.570796326794896558 0" />
      <geometry>
        <mesh filename="package:///foot_part.stl" />
      </geometry>
    </collision>
    <visual>
      <origin xyz="4.1633363423443370266e-17 0.0048038851135427940164 0.033023499999999997301" rpy="-1.570796326794896558 -1.570796326794896558 0" />
      <geometry>
        <mesh filename="package:///actuator_foot2.stl" />
      </geometry>
      <material name="actuator_foot2_material">
        <color rgba="1 0 0 1.0" />
      </material>
    </visual>
    <collision>
      <origin xyz="4.1633363423443370266e-17 0.0048038851135427940164 0.033023499999999997301" rpy="-1.570796326794896558 -1.570796326794896558 0" />
      <geometry>
        <mesh filename="package:///actuator_foot2.stl" />
      </geometry>
    </collision>
    <inertial>
      <origin xyz="0.0016000324224781350881 -0.036970219050314417908 -0.00070679916642805561567" rpy="0 0 0" />
      <mass value="2.4399385078931685733" />
      <inertia ixx="0.013454021349958959416" ixy="0.00017776259115871620008" ixz="-0.00010674142878734243806" iyy="0.010565640462104038469" iyz="0.0024269417594425146852" izz="0.0070124115536168351789" />
    </inertial>
  </link>
  <link name="foot">
    <inertial>
      <origin xyz="0 0 0" rpy="0 0 0" />
      <mass value="1e-9" />
      <inertia ixx="0" ixy="0" ixz="0" iyy="0" iyz="0" izz="0" />
    </inertial>
  </link>
  <joint name="foot_frame" type="fixed">
    <origin xyz="0.0037180509068605316347 -0.10113711488645715786 0.026634499999999984576" rpy="-1.570796326794896558 -1.570796326794896558 0" />
    <parent link="foot_part" />
    <child link="foot" />
    <axis xyz="0 0 0" />
  </joint>
  <joint name="motor_ankle" type="revolute">
    <origin xyz="-0.026499999999999714756 0.0013713509343774576976 -0.10499999999999996836" rpy="1.570796326794896558 -1.567289850670234852 1.570796326794896558" />
    <parent link="ankle" />
    <child link="foot_part" />
    <axis xyz="0 0 1" />
    <limit effort="1" velocity="20" />
    <joint_properties friction="0.0" />
  </joint>
  <link name="rod_2">
    <visual>
      <origin xyz="0.066043388667753361032 -0.060532000000000002471 0.19736045856093031858" rpy="1.1031832926239796083e-17 1.2402679690537874238e-19 2.8653805943460018156e-19" />
      <geometry>
        <mesh filename="package:///rod_2.stl" />
      </geometry>
      <material name="rod_2_material">
        <color rgba="0.91764705882352937127 0.91764705882352937127 0.91764705882352937127 1.0" />
      </material>
    </visual>
    <collision>
      <origin xyz="0.066043388667753361032 -0.060532000000000002471 0.19736045856093031858" rpy="1.1031832926239796083e-17 1.2402679690537874238e-19 2.8653805943460018156e-19" />
      <geometry>
        <mesh filename="package:///rod_2.stl" />
      </geometry>
    </collision>
    <inertial>
      <origin xyz="-0.0028010050235989236711 -1.9934160633700936238e-17 -0.053503477425454082361" rpy="0 0 0" />
      <mass value="0.01071537057143842446" />
      <inertia ixx="1.0314061869205781277e-05" ixy="4.7154166502509314148e-23" ixz="-5.3372477602143115565e-07" iyy="1.0342166612297668834e-05" iyz="1.1319673307388156157e-22" izz="2.0669425261585886115e-07" />
    </inertial>
  </link>
  <link name="closedloop1_B">
    <inertial>
      <origin xyz="0 0 0" rpy="0 0 0" />
      <mass value="1e-9" />
      <inertia ixx="0" ixy="0" ixz="0" iyy="0" iyz="0" izz="0" />
    </inertial>
  </link>
  <joint name="closedloop1_B_frame" type="fixed">
    <origin xyz="-0.0056101647180722413744 1.3183898417423733918e-16 -0.10700674137717303136" rpy="-3.0892124683058885815 -4.0155837822672816926e-17 1.5707963267948958919" />
    <parent link="rod_2" />
    <child link="closedloop1_B" />
    <axis xyz="0 0 0" />
  </joint>
  <joint name="free_ankle" type="revolute">
    <origin xyz="-2.7755575615628913511e-16 0.32492299999999990634 0.12120000000000001605" rpy="-3.4526838239814990521e-16 1.3436275590745426018e-16 -0.44981338557612621232" />
    <parent link="knee" />
    <child link="ankle" />
    <axis xyz="0 0 1" />
    <limit effort="1" velocity="20" />
    <joint_properties friction="0.0" />
  </joint>
  <link name="moteur">
    <visual>
      <origin xyz="-0.010729000000000044057 0.12028099999999997127 0.065531999999999979156" rpy="-1.570796326794896558 -1.8080213958956081853e-32 -3.2610358239416864912e-17" />
      <geometry>
        <mesh filename="package:///moteur.stl" />
      </geometry>
      <material name="moteur_material">
        <color rgba="0.2313725490196078538 0.38039215686274507888 0.7058823529411765163 1.0" />
      </material>
    </visual>
    <collision>
      <origin xyz="-0.010729000000000044057 0.12028099999999997127 0.065531999999999979156" rpy="-1.570796326794896558 -1.8080213958956081853e-32 -3.2610358239416864912e-17" />
      <geometry>
        <mesh filename="package:///moteur.stl" />
      </geometry>
    </collision>
    <inertial>
      <origin xyz="-0.02455859532687598365 0.0070453111044206087263 -0.0048405000000000114602" rpy="0 0 0" />
      <mass value="0.038626098739875748544" />
      <inertia ixx="7.4302589031174778926e-06" ixy="7.3853124072044585576e-06" ixz="-4.6956052461449553674e-37" iyy="3.1055352414275530048e-05" iyz="9.6053244717321955006e-37" izz="3.788226031831617291e-05" />
    </inertial>
  </link>
  <link name="rod_1">
    <visual>
      <origin xyz="0.055619757522592405685 -0.060531999999999974715 0.10277820430949599628" rpy="-1.4465544117253960317e-16 -0.052380185283905741911 -7.1948801843913737363e-17" />
      <geometry>
        <mesh filename="package:///rod_1.stl" />
      </geometry>
      <material name="rod_1_material">
        <color rgba="0.91764705882352937127 0.91764705882352937127 0.91764705882352937127 1.0" />
      </material>
    </visual>
    <collision>
      <origin xyz="0.055619757522592405685 -0.060531999999999974715 0.10277820430949599628" rpy="-1.4465544117253960317e-16 -0.052380185283905741911 -7.1948801843913737363e-17" />
      <geometry>
        <mesh filename="package:///rod_1.stl" />
      </geometry>
    </collision>
    <inertial>
      <origin xyz="-4.4732743201617020112e-06 5.1910273182890374658e-18 -0.048834724618959310383" rpy="0 0 0" />
      <mass value="0.0097669214712453669702" />
      <inertia ixx="7.8456157661067766745e-06" ixy="-5.0781461964052383621e-22" ixz="-2.1335846837136089048e-09" iyy="7.8456155706688894736e-06" iyz="-1.1193005654322464218e-21" izz="1.6278182908286845906e-07" />
    </inertial>
  </link>
  <link name="closedloop1_A">
    <inertial>
      <origin xyz="0 0 0" rpy="0 0 0" />
      <mass value="1e-9" />
      <inertia ixx="0" ixy="0" ixz="0" iyy="0" iyz="0" izz="0" />
    </inertial>
  </link>
  <joint name="closedloop1_A_frame" type="fixed">
    <origin xyz="1.1102230246251565404e-16 1.1102230246251565404e-16 -0.097669214712453877869" rpy="-3.4522675283876850989e-16 -0.052380185283905041083 -1.9632688463124169043e-16" />
    <parent link="rod_1" />
    <child link="closedloop1_A" />
    <axis xyz="0 0 0" />
  </joint>
  <joint name="motor_shin" type="revolute">
    <origin xyz="0.010729000000000044057 0.12028099999999997127 0.12120000000000001605" rpy="-1.7163581602055608654e-16 3.2833637602275228514e-16 0.26818340469683032978" />
    <parent link="knee" />
    <child link="moteur" />
    <axis xyz="0 0 1" />
    <limit effort="1" velocity="20" />
    <joint_properties friction="0.0" />
  </joint>
  <joint name="motor_knee" type="revolute">
    <origin xyz="0.018186673545849449396 0.37956454642832049284 0.096000000000000029754" rpy="-3.141592653589793116 3.7503479430427692051e-17 2.1726736438687357378" />
    <parent link="hip_z" />
    <child link="knee" />
    <axis xyz="0 0 1" />
    <limit effort="1" velocity="20" />
    <joint_properties friction="0.0" />
  </joint>
  <joint name="motor_hip_y" type="revolute">
    <origin xyz="-0.0780000000000000554 1.3877787807814456755e-17 -0.025999999999999967581" rpy="-1.5707963267948970021 -0.99311814123129293908 -1.5707963267948961139" />
    <parent link="hip_y" />
    <child link="hip_z" />
    <axis xyz="0 0 1" />
    <limit effort="1" velocity="20" />
    <joint_properties friction="0.0" />
  </joint>
  <joint name="motor_hip_x" type="revolute">
    <origin xyz="-0.025999999999999998807 2.7755575615628913511e-17 -0.0934999999999999859" rpy="1.570796326794896558 4.3603698957148256544e-17 -1.570796326794896558" />
    <parent link="hip_x" />
    <child link="hip_y" />
    <axis xyz="0 0 1" />
    <limit effort="1" velocity="20" />
    <joint_properties friction="0.0" />
  </joint>
  <joint name="motor_hip_z" type="revolute">
    <origin xyz="0.02371448658186565972 0.084999999999999992228 -0.010000000000000008882" rpy="0 -0 0" />
    <parent link="buste" />
    <child link="hip_x" />
    <axis xyz="0 0 1" />
    <limit effort="1" velocity="20" />
    <joint_properties friction="0.0" />
  </joint>
  <link name="ankle_int1_1">
    <inertial>
      <mass value="0.0" />
      <inertia ixx="0.0" ixy="0.0" ixz="0.0" iyy="0.0" iyz="0.0" izz="0.0" />
    </inertial>
  </link>
  <link name="ankle_int2_1">
    <inertial>
      <mass value="0.0" />
      <inertia ixx="0.0" ixy="0.0" ixz="0.0" iyy="0.0" iyz="0.0" izz="0.0" />
    </inertial>
  </link>
  <joint name="ankle_rod_2_rev0" type="revolute">
    <origin xyz="-0.071653553385825324851 -0.020555800061897278042 -0.0096809999999999951648" />
    <parent link="ankle" />
    <child link="ankle_int1_1" />
    <axis xyz="1 0 0" />
    <limit effort="1" velocity="20" />
  </joint>
  <joint name="ankle_rod_2_rev1" type="revolute">
    <parent link="ankle_int1_1" />
    <child link="ankle_int2_1" />
    <axis xyz="0 1 0" />
    <limit effort="1" velocity="20" />
  </joint>
  <joint name="ankle_rod_2_rev2" type="revolute">
    <parent link="ankle_int2_1" />
    <child link="rod_2" />
    <axis xyz="0 0 1" />
    <limit effort="1" velocity="20" />
  </joint>
  <link name="moteur_int1_2">
    <inertial>
      <mass value="0.0" />
      <inertia ixx="0.0" ixy="0.0" ixz="0.0" iyy="0.0" iyz="0.0" izz="0.0" />
    </inertial>
  </link>
  <link name="moteur_int2_2">
    <inertial>
      <mass value="0.0" />
      <inertia ixx="0.0" ixy="0.0" ixz="0.0" iyy="0.0" iyz="0.0" izz="0.0" />
    </inertial>
  </link>
  <joint name="moteur_rod_1_rev0" type="revolute">
    <origin xyz="-0.071653553385825130562 0.020555800061898721331 -0.0096810000000000784315" />
    <parent link="moteur" />
    <child link="moteur_int1_2" />
    <axis xyz="1 0 0" />
    <limit effort="1" velocity="20" />
  </joint>
  <joint name="moteur_rod_1_rev1" type="revolute">
    <parent link="moteur_int1_2" />
    <child link="moteur_int2_2" />
    <axis xyz="0 1 0" />
    <limit effort="1" velocity="20" />
  </joint>
  <joint name="moteur_rod_1_rev2" type="revolute">
    <parent link="moteur_int2_2" />
    <child link="rod_1" />
    <axis xyz="0 0 1" />
    <limit effort="1" velocity="20" />
  </joint>
</robot>
