<robot name="onshape">
<link name="part_11">
<visual>
<origin xyz="0.014916008950699914323 -0.11032221992409163569 -0.25988413956214584388" rpy="6.1232339957367660359e-17 1.232595164407830946e-32 -6.1232339957367648033e-17" />
<geometry>
<mesh filename="package:///part_11.stl"/>
</geometry>
<material name="part_11_material">
<color rgba="0.61568627450980395466 0.81176470588235294379 0.92941176470588238168 1.0"/>
</material>
</visual>
<collision>
<origin xyz="0.014916008950699914323 -0.11032221992409163569 -0.25988413956214584388" rpy="6.1232339957367660359e-17 1.232595164407830946e-32 -6.1232339957367648033e-17" />
<geometry>
<mesh filename="package:///part_11.stl"/>
</geometry>
<material name="part_11_material">
<color rgba="0.61568627450980395466 0.81176470588235294379 0.92941176470588238168 1.0"/>
</material>
</collision>
<inertial>
<origin xyz="-0.017433047653073671657 -0.075990644102685869776 -0.006914165767531954554" rpy="0 0 0"/>
<mass value="0.59895391977948031492" />
<inertia ixx="0.00098062611696921628095" ixy="-4.896414261159503435e-20"  ixz="2.1164213654682558533e-22" iyy="0.00018098098425526492911" iyz="3.4563783891678767589e-06" izz="0.00092861266260167707725" />
</inertial>
</link>

<link name="centre_hanche">
<inertial>
<origin xyz="0 0 0" rpy="0 0 0" />
<mass value="1e-9" />
<inertia ixx="0" ixy="0" ixz="0" iyy="0" iyz="0" izz="0" />
</inertial>
</link>
<joint name="centre_hanche_frame" type="fixed">
<origin xyz="-0.017433047653073678596 -0.076775050112770887312 0.019380011381250363683" rpy="6.1232339957367660359e-17 1.232595164407830946e-32 -6.1232339957367648033e-17" />
<parent link="part_11" />
<child link="centre_hanche" />
<axis xyz="0 0 0"/>
</joint>

<link name="bloc_moteur2">
<visual>
<origin xyz="-0.022165094339622673503 0.24561320754716980952 -0.014377358490566038984" rpy="1.570796326794896558 1.570796326794896558 0" />
<geometry>
<mesh filename="package:///bloc_moteur2.stl"/>
</geometry>
<material name="bloc_moteur2_material">
<color rgba="0.49803921568627451677 0.49803921568627451677 0.49803921568627451677 1.0"/>
</material>
</visual>
<collision>
<origin xyz="-0.022165094339622673503 0.24561320754716980952 -0.014377358490566038984" rpy="1.570796326794896558 1.570796326794896558 0" />
<geometry>
<mesh filename="package:///bloc_moteur2.stl"/>
</geometry>
<material name="bloc_moteur2_material">
<color rgba="0.49803921568627451677 0.49803921568627451677 0.49803921568627451677 1.0"/>
</material>
</collision>
<inertial>
<origin xyz="-7.9947947823472322479e-19 -0.015498565223029002122 -0.027433849207585056518" rpy="0 0 0"/>
<mass value="0.18908865794820378659" />
<inertia ixx="0.00011582769866125839156" ixy="6.8655008904598452188e-23"  ixz="-2.6119952522463239774e-21" iyy="5.5677265646738170377e-05" iyz="1.1212213832167567021e-06" izz="7.3170579007413757131e-05" />
</inertial>
</link>

<link name="part_8">
<visual>
<origin xyz="-0.02130312574122306124 -0.300384308548851231 0.01984905660377359049" rpy="-1.570796326794896558 -6.1232339957367660359e-17 0" />
<geometry>
<mesh filename="package:///part_8.stl"/>
</geometry>
<material name="part_8_material">
<color rgba="0.98039215686274505668 0.71372549019607844922 0.0039215686274509803377 1.0"/>
</material>
</visual>
<collision>
<origin xyz="-0.02130312574122306124 -0.300384308548851231 0.01984905660377359049" rpy="-1.570796326794896558 -6.1232339957367660359e-17 0" />
<geometry>
<mesh filename="package:///part_8.stl"/>
</geometry>
<material name="part_8_material">
<color rgba="0.98039215686274505668 0.71372549019607844922 0.0039215686274509803377 1.0"/>
</material>
</collision>
<inertial>
<origin xyz="0.0061832979617809898445 -1.9615142843321109467e-11 -0.01249999999999999549" rpy="0 0 0"/>
<mass value="0.0051771836100694083177" />
<inertia ixx="1.9356357704535493454e-07" ixy="1.1603957065493950639e-14"  ixz="-1.0937893882837671976e-23" iyy="5.0522363102989444931e-07" iyz="-1.7681889915813909643e-13" izz="3.7219294006582840664e-07" />
</inertial>
</link>

<link name="fermeture3_B">
<inertial>
<origin xyz="0 0 0" rpy="0 0 0" />
<mass value="1e-9" />
<inertia ixx="0" ixy="0" ixz="0" iyy="0" iyz="0" izz="0" />
</inertial>
</link>
<joint name="fermeture3_B_frame" type="fixed">
<origin xyz="0.023912264150939596674 -2.7755575615628913511e-17 -0.012499999999999927836" rpy="1.570796326794896558 -1.232595164407830946e-32 -1.570796326794896336" />
<parent link="part_8" />
<child link="fermeture3_B" />
<axis xyz="0 0 0"/>
</joint>

<joint name="mot_4link1" type="revolute">
<origin xyz="0.010183962264150914212 -0.031150943396226427051 -0.039537735849056607207" rpy="-3.141592653589793116 1.570796326794896558 0" />
<parent link="bloc_moteur2" />
<child link="part_8" />
<axis xyz="0 0 1"/>
<limit effort="1" velocity="20" />
<joint_properties friction="0.0"/>
</joint>

<link name="cuisse_1">
<visual>
<origin xyz="1.7347234759768070944e-18 -0.24561320754716980952 0.01984905660377359049" rpy="-1.570796326794896558 -6.1232339957367660359e-17 0" />
<geometry>
<mesh filename="package:///cuisse_1.stl"/>
</geometry>
<material name="cuisse_1_material">
<color rgba="0.76862745098039220171 0.88627450980392152857 0.95294117647058818044 1.0"/>
</material>
</visual>
<collision>
<origin xyz="1.7347234759768070944e-18 -0.24561320754716980952 0.01984905660377359049" rpy="-1.570796326794896558 -6.1232339957367660359e-17 0" />
<geometry>
<mesh filename="package:///cuisse_1.stl"/>
</geometry>
<material name="cuisse_1_material">
<color rgba="0.76862745098039220171 0.88627450980392152857 0.95294117647058818044 1.0"/>
</material>
</collision>
<inertial>
<origin xyz="1.8573961650237243068e-18 -0.05511320754716983461 -0.012499975668522671224" rpy="0 0 0"/>
<mass value="0.017558374486852622309" />
<inertia ixx="2.8179142623395863644e-05" ixy="5.8766572650822571336e-11"  ixz="5.2318040297869049922e-12" iyy="4.6983411885038097882e-07" iyz="3.5984147546845121287e-27" izz="2.791304966480971181e-05" />
</inertial>
</link>

<link name="tibias">
<visual>
<origin xyz="1.7347234759768070944e-18 -0.13538679245283019581 0.032349056603773573837" rpy="-1.570796326794896558 -6.1232339957367660359e-17 0" />
<geometry>
<mesh filename="package:///tibias.stl"/>
</geometry>
<material name="tibias_material">
<color rgba="0.91764705882352937127 0.91764705882352937127 0.91764705882352937127 1.0"/>
</material>
</visual>
<collision>
<origin xyz="1.7347234759768070944e-18 -0.13538679245283019581 0.032349056603773573837" rpy="-1.570796326794896558 -6.1232339957367660359e-17 0" />
<geometry>
<mesh filename="package:///tibias.stl"/>
</geometry>
<material name="tibias_material">
<color rgba="0.91764705882352937127 0.91764705882352937127 0.91764705882352937127 1.0"/>
</material>
</collision>
<inertial>
<origin xyz="0.0082169884740478753293 -0.021582339964505967145 7.6991363174242708429e-08" rpy="0 0 0"/>
<mass value="0.023035078738552670907" />
<inertia ixx="4.7553665715035306363e-05" ixy="-9.9417662899894668806e-06"  ixz="-2.7503179156743881011e-11" iyy="4.4336691972740291027e-06" iyz="-3.569607872529120713e-11" izz="5.1188895392911973943e-05" />
</inertial>
</link>

<link name="cardan">
<visual>
<origin xyz="3.4694469519536141888e-18 0.032349056603773587715 0.025085377358490562605" rpy="3.141592653589793116 -0 7.5474686136827787456e-49" />
<geometry>
<mesh filename="package:///cardan.stl"/>
</geometry>
<material name="cardan_material">
<color rgba="0.2313725490196078538 0.38039215686274507888 0.7058823529411765163 1.0"/>
</material>
</visual>
<collision>
<origin xyz="3.4694469519536141888e-18 0.032349056603773587715 0.025085377358490562605" rpy="3.141592653589793116 -0 7.5474686136827787456e-49" />
<geometry>
<mesh filename="package:///cardan.stl"/>
</geometry>
<material name="cardan_material">
<color rgba="0.2313725490196078538 0.38039215686274507888 0.7058823529411765163 1.0"/>
</material>
</collision>
<inertial>
<origin xyz="6.2199211710491328202e-09 4.6944659791888819903e-57 -7.4993780078837224412e-05" rpy="0 0 0"/>
<mass value="0.0048331041712159142354" />
<inertia ixx="1.8997247887664700798e-07" ixy="-5.8978437973623104663e-13"  ixz="4.4513790950504313708e-61" iyy="3.2228119467759177645e-07" iyz="5.8978437975621949455e-13" izz="1.8997247887664700798e-07" />
</inertial>
</link>

<link name="cheville">
<visual>
<origin xyz="-0.032349056603773601593 0.0251603773584905821 0" rpy="1.570796326794896558 1.570796326794896558 0" />
<geometry>
<mesh filename="package:///cheville.stl"/>
</geometry>
<material name="cheville_material">
<color rgba="0.64705882352941179736 0.64705882352941179736 0.64705882352941179736 1.0"/>
</material>
</visual>
<collision>
<origin xyz="-0.032349056603773601593 0.0251603773584905821 0" rpy="1.570796326794896558 1.570796326794896558 0" />
<geometry>
<mesh filename="package:///cheville.stl"/>
</geometry>
<material name="cheville_material">
<color rgba="0.64705882352941179736 0.64705882352941179736 0.64705882352941179736 1.0"/>
</material>
</collision>
<inertial>
<origin xyz="-0.032349056603773587715 1.3877787807814456755e-17 4.9486715615727812696e-18" rpy="0 0 0"/>
<mass value="0.012302391121821361353" />
<inertia ixx="4.0949688628445133302e-07" ixy="1.2383767550218256784e-13"  ixz="-9.6493801821082900825e-29" iyy="8.1569347292422682315e-06" iyz="3.0708414957250004657e-12" izz="7.8908750295496533e-06" />
</inertial>
</link>

<link name="cardan_2">
<visual>
<origin xyz="-2.7755575615628913511e-17 0.032349056603773629348 0.025085377358490569544" rpy="3.141592653589793116 -1.2594572952646196083e-33 3.1422592786896289052e-17" />
<geometry>
<mesh filename="package:///cardan.stl"/>
</geometry>
<material name="cardan_material">
<color rgba="0.2313725490196078538 0.38039215686274507888 0.7058823529411765163 1.0"/>
</material>
</visual>
<collision>
<origin xyz="-2.7755575615628913511e-17 0.032349056603773629348 0.025085377358490569544" rpy="3.141592653589793116 -1.2594572952646196083e-33 3.1422592786896289052e-17" />
<geometry>
<mesh filename="package:///cardan.stl"/>
</geometry>
<material name="cardan_material">
<color rgba="0.2313725490196078538 0.38039215686274507888 0.7058823529411765163 1.0"/>
</material>
</collision>
<inertial>
<origin xyz="6.2199211413288907532e-09 4.1633363618889421917e-17 -7.4993780078830285518e-05" rpy="0 0 0"/>
<mass value="0.0048331041712159142354" />
<inertia ixx="1.8997247887664700798e-07" ixy="-5.8978437974525319201e-13"  ixz="-2.743500762904161787e-29" iyy="3.2228119467759177645e-07" iyz="5.8978437975621949455e-13" izz="1.8997247887664700798e-07" />
</inertial>
</link>

<link name="tibias_mirror">
<visual>
<origin xyz="3.4694469519536141888e-18 -0.032349056603773601593 0.025160377358490554345" rpy="-3.141592653589793116 5.0059711325064321798e-33 -7.0510774028809602427e-33" />
<geometry>
<mesh filename="package:///tibias_mirror.stl"/>
</geometry>
<material name="tibias_mirror_material">
<color rgba="0.91764705882352937127 0.91764705882352937127 0.91764705882352937127 1.0"/>
</material>
</visual>
<collision>
<origin xyz="3.4694469519536141888e-18 -0.032349056603773601593 0.025160377358490554345" rpy="-3.141592653589793116 5.0059711325064321798e-33 -7.0510774028809602427e-33" />
<geometry>
<mesh filename="package:///tibias_mirror.stl"/>
</geometry>
<material name="tibias_mirror_material">
<color rgba="0.91764705882352937127 0.91764705882352937127 0.91764705882352937127 1.0"/>
</material>
</collision>
<inertial>
<origin xyz="-9.6077076114500062975e-19 -1.4747521755243798103e-17 -0.017372641509433982276" rpy="0 0 0"/>
<mass value="0.0040112654511116375977" />
<inertia ixx="4.2657719020569615085e-07" ixy="-5.9707778495512959107e-39"  ixz="-1.9368290204583038008e-39" iyy="4.2657719020567232805e-07" iyz="1.8890966887876376118e-23" izz="4.6064578469927354701e-08" />
</inertial>
</link>

<link name="fermeture1_A">
<inertial>
<origin xyz="0 0 0" rpy="0 0 0" />
<mass value="1e-9" />
<inertia ixx="0" ixy="0" ixz="0" iyy="0" iyz="0" izz="0" />
</inertial>
</link>
<joint name="fermeture1_A_frame" type="fixed">
<origin xyz="-1.7347234759768070944e-18 0 -0.034745283018867909042" rpy="-3.141592653589793116 -2.3309679287756284669e-33 -4.7737334535330456626e-32" />
<parent link="tibias_mirror" />
<child link="fermeture1_A" />
<axis xyz="0 0 0"/>
</joint>

<joint name="free_cardan4" type="revolute">
<origin xyz="7.4999999999908473214e-05 0 -7.4999999999998678835e-05" rpy="-2.0448441483311558481e-17 1.570796326794896558 0" />
<parent link="cardan_2" />
<child link="tibias_mirror" />
<axis xyz="0 0 1"/>
<limit effort="1" velocity="20" />
<joint_properties friction="0.0"/>
</joint>

<joint name="free_cardan3" type="revolute">
<origin xyz="-0.064698113207547175429 0 -1.7347234759768070944e-18" rpy="-1.5896403521858079647e-33 -2.2423342133746970721e-33 1.570796326794896558" />
<parent link="cheville" />
<child link="cardan_2" />
<axis xyz="0 0 1"/>
<limit effort="1" velocity="20" />
<joint_properties friction="0.0"/>
</joint>

<link name="foot">
<visual>
<origin xyz="3.4694469519536141888e-18 0.025160377358490554345 0" rpy="1.570796326794896558 3.6977854932234928379e-32 -4.3140830754274083108e-32" />
<geometry>
<mesh filename="package:///foot.stl"/>
</geometry>
<material name="foot_material">
<color rgba="0.61568627450980395466 0.81176470588235294379 0.92941176470588238168 1.0"/>
</material>
</visual>
<collision>
<origin xyz="3.4694469519536141888e-18 0.025160377358490554345 0" rpy="1.570796326794896558 3.6977854932234928379e-32 -4.3140830754274083108e-32" />
<geometry>
<mesh filename="package:///foot.stl"/>
</geometry>
<material name="foot_material">
<color rgba="0.61568627450980395466 0.81176470588235294379 0.92941176470588238168 1.0"/>
</material>
</collision>
<inertial>
<origin xyz="0.0086007177827431852829 0.016950874731062208489 8.0422304140929297343e-19" rpy="0 0 0"/>
<mass value="0.26771903485844583681" />
<inertia ixx="0.00013914255866321294372" ixy="-5.4659357927142044923e-06"  ixz="1.1125095241699857824e-22" iyy="0.00030333301998280683609" iyz="-1.6840639914778287844e-20" izz="0.00025293577646975641494" />
</inertial>
</link>

<link name="bout_pied">
<inertial>
<origin xyz="0 0 0" rpy="0 0 0" />
<mass value="1e-9" />
<inertia ixx="0" ixy="0" ixz="0" iyy="0" iyz="0" izz="0" />
</inertial>
</link>
<joint name="bout_pied_frame" type="fixed">
<origin xyz="0.0083867924528302027071 0.027452830188679250289 0" rpy="1.570796326794896558 3.6977854932234928379e-32 -4.3140830754274083108e-32" />
<parent link="foot" />
<child link="bout_pied" />
<axis xyz="0 0 0"/>
</joint>

<joint name="mot_cheville" type="revolute">
<origin xyz="-0.032349056603773573837 0 3.4694469519536141888e-18" rpy="5.7012438214319484287e-16 1.570796326794896558 0" />
<parent link="cheville" />
<child link="foot" />
<axis xyz="0 0 1"/>
<limit effort="1" velocity="20" />
<joint_properties friction="0.0"/>
</joint>

<joint name="free_cardan2" type="revolute">
<origin xyz="-7.5000000000000413558e-05 0 -7.5000000000019495516e-05" rpy="1.570796326794896558 0.64205984656181225301 -1.570796326794896558" />
<parent link="cardan" />
<child link="cheville" />
<axis xyz="0 0 1"/>
<limit effort="1" velocity="20" />
<joint_properties friction="0.0"/>
</joint>

<joint name="free_cardan1" type="revolute">
<origin xyz="0 -0.11022641509433964147 -1.3877787807814456755e-17" rpy="1.570796326794896558 -6.1232339957367660359e-17 0" />
<parent link="tibias" />
<child link="cardan" />
<axis xyz="0 0 1"/>
<limit effort="1" velocity="20" />
<joint_properties friction="0.0"/>
</joint>

<link name="cuiqqe_2">
<visual>
<origin xyz="-0.035117257249881420056 -0.17308257465018811461 0.032349056603773587715" rpy="-1.570796326794896558 -6.1232339957367660359e-17 0" />
<geometry>
<mesh filename="package:///cuiqqe_2.stl"/>
</geometry>
<material name="cuiqqe_2_material">
<color rgba="0.97254901960784312376 0.52941176470588235947 0.0039215686274509803377 1.0"/>
</material>
</visual>
<collision>
<origin xyz="-0.035117257249881420056 -0.17308257465018811461 0.032349056603773587715" rpy="-1.570796326794896558 -6.1232339957367660359e-17 0" />
<geometry>
<mesh filename="package:///cuiqqe_2.stl"/>
</geometry>
<material name="cuiqqe_2_material">
<color rgba="0.97254901960784312376 0.52941176470588235947 0.0039215686274509803377 1.0"/>
</material>
</collision>
<inertial>
<origin xyz="0.017055198396614242029 0.06365086694933166922 2.5590346983547759065e-08" rpy="0 0 0"/>
<mass value="0.020048097436372345342" />
<inertia ixx="4.0788668580033780105e-05" ixy="-1.0795657082613442217e-05"  ixz="6.0422696691767325742e-12" iyy="3.3910867366475971126e-06" iyz="-1.6190212717905067407e-12" izz="4.3415234962763218408e-05" />
</inertial>
</link>

<link name="part_7">
<visual>
<origin xyz="-0.069227654043109848603 -0.300384308548851231 0.019849056603773576613" rpy="-1.570796326794896558 -6.1232339957367660359e-17 0" />
<geometry>
<mesh filename="package:///part_7.stl"/>
</geometry>
<material name="part_7_material">
<color rgba="0.98039215686274505668 0.71372549019607844922 0.0039215686274509803377 1.0"/>
</material>
</visual>
<collision>
<origin xyz="-0.069227654043109848603 -0.300384308548851231 0.019849056603773576613" rpy="-1.570796326794896558 -6.1232339957367660359e-17 0" />
<geometry>
<mesh filename="package:///part_7.stl"/>
</geometry>
<material name="part_7_material">
<color rgba="0.98039215686274505668 0.71372549019607844922 0.0039215686274509803377 1.0"/>
</material>
</collision>
<inertial>
<origin xyz="-0.0061832857558966058953 1.9615198354472340725e-11 -0.012500000000000016306" rpy="0 0 0"/>
<mass value="0.0051771712678282859679" />
<inertia ixx="1.9356340696232820132e-07" ixy="1.1603958306098918378e-14"  ixz="-1.0937892887634393992e-23" iyy="5.0522228097855935559e-07" iyz="1.3050652896851172602e-12" izz="3.7219275372989875315e-07" />
</inertial>
</link>

<link name="fermeture3_A">
<inertial>
<origin xyz="0 0 0" rpy="0 0 0" />
<mass value="1e-9" />
<inertia ixx="0" ixy="0" ixz="0" iyy="0" iyz="0" izz="0" />
</inertial>
</link>
<joint name="fermeture3_A_frame" type="fixed">
<origin xyz="-0.023912264150947201702 -2.7755575615628913511e-17 -0.012499999999999941713" rpy="1.570796326794896558 -1.232595164407830946e-32 -1.570796326794896336" />
<parent link="part_7" />
<child link="fermeture3_A" />
<axis xyz="0 0 0"/>
</joint>

<joint name="free_to_rotule_4link5" type="revolute">
<origin xyz="0.034110396793228428547 0.1273017338986631164 0" rpy="0 -5.2516235920243112527e-49 0" />
<parent link="cuiqqe_2" />
<child link="part_7" />
<axis xyz="0 0 1"/>
<limit effort="1" velocity="20" />
<joint_properties friction="0.0"/>
</joint>

<joint name="free_to_rotule_4link4" type="revolute">
<origin xyz="0.035117257249881420056 0.037695782197357918797 -1.3877787807814456755e-17" rpy="0 -5.2516235920243112527e-49 0" />
<parent link="tibias" />
<child link="cuiqqe_2" />
<axis xyz="0 0 1"/>
<limit effort="1" velocity="20" />
<joint_properties friction="0.0"/>
</joint>

<joint name="free_4link5" type="revolute">
<origin xyz="0 -0.11022641509433961371 1.3877787807814456755e-17" rpy="0 -5.2516235920243112527e-49 0" />
<parent link="cuisse_1" />
<child link="tibias" />
<axis xyz="0 0 1"/>
<limit effort="1" velocity="20" />
<joint_properties friction="0.0"/>
</joint>

<joint name="mot_4link3" type="revolute">
<origin xyz="0.010183962264150914212 0 -0.01437735849056603725" rpy="-3.141592653589793116 1.570796326794896558 0" />
<parent link="bloc_moteur2" />
<child link="cuisse_1" />
<axis xyz="0 0 1"/>
<limit effort="1" velocity="20" />
<joint_properties friction="0.0"/>
</joint>

<joint name="mot_hipsx" type="revolute">
<origin xyz="0.00053865046013387533896 -0.088157125584468976065 -0.014270932014976034363" rpy="-1.570796326794896558 -6.1232339957367660359e-17 1.570796326794896558" />
<parent link="part_11" />
<child link="bloc_moteur2" />
<axis xyz="0 0 1"/>
<limit effort="1" velocity="20" />
<joint_properties friction="0.0"/>
</joint>

<link name="bloc_moteur">
<visual>
<origin xyz="0.022165094339622604114 0.24561320754716980952 -0.014377358490566038984" rpy="1.570796326794896558 1.570796326794896558 0" />
<geometry>
<mesh filename="package:///bloc_moteur.stl"/>
</geometry>
<material name="bloc_moteur_material">
<color rgba="0.49803921568627451677 0.49803921568627451677 0.49803921568627451677 1.0"/>
</material>
</visual>
<collision>
<origin xyz="0.022165094339622604114 0.24561320754716980952 -0.014377358490566038984" rpy="1.570796326794896558 1.570796326794896558 0" />
<geometry>
<mesh filename="package:///bloc_moteur.stl"/>
</geometry>
<material name="bloc_moteur_material">
<color rgba="0.49803921568627451677 0.49803921568627451677 0.49803921568627451677 1.0"/>
</material>
</collision>
<inertial>
<origin xyz="-7.9947947823472341739e-19 -0.015498565223028948346 -0.027433849207585053048" rpy="0 0 0"/>
<mass value="0.18908865794820506334" />
<inertia ixx="0.00011582769866125935379" ixy="6.8655008904599756986e-23"  ixz="-2.6119952522463582078e-21" iyy="5.5677265646738231363e-05" iyz="1.1212213832167780896e-06" izz="7.3170579007414163707e-05" />
</inertial>
</link>

<link name="part_8_2">
<visual>
<origin xyz="-0.02130312574122306124 -0.300384308548851231 0.019849056603773576613" rpy="-1.570796326794896558 -6.1232339957367660359e-17 -6.8422776578360208541e-49" />
<geometry>
<mesh filename="package:///part_8.stl"/>
</geometry>
<material name="part_8_material">
<color rgba="0.98039215686274505668 0.71372549019607844922 0.0039215686274509803377 1.0"/>
</material>
</visual>
<collision>
<origin xyz="-0.02130312574122306124 -0.300384308548851231 0.019849056603773576613" rpy="-1.570796326794896558 -6.1232339957367660359e-17 -6.8422776578360208541e-49" />
<geometry>
<mesh filename="package:///part_8.stl"/>
</geometry>
<material name="part_8_material">
<color rgba="0.98039215686274505668 0.71372549019607844922 0.0039215686274509803377 1.0"/>
</material>
</collision>
<inertial>
<origin xyz="0.0061832979617809898445 -1.9615142843321109467e-11 -0.012500000000000011102" rpy="0 0 0"/>
<mass value="0.0051771836100694083177" />
<inertia ixx="1.9356357704535493454e-07" ixy="1.1603957065493950639e-14"  ixz="-1.0937893882837664629e-23" iyy="5.0522363102989444931e-07" iyz="-1.7681889915813909643e-13" izz="3.7219294006582840664e-07" />
</inertial>
</link>

<link name="fermeture2_A">
<inertial>
<origin xyz="0 0 0" rpy="0 0 0" />
<mass value="1e-9" />
<inertia ixx="0" ixy="0" ixz="0" iyy="0" iyz="0" izz="0" />
</inertial>
</link>
<joint name="fermeture2_A_frame" type="fixed">
<origin xyz="0.023912264150939582796 2.7755575615628913511e-17 -0.012499999999999927836" rpy="1.570796326794896558 -1.232595164407830946e-32 -1.570796326794896336" />
<parent link="part_8_2" />
<child link="fermeture2_A" />
<axis xyz="0 0 0"/>
</joint>

<joint name="mot_4link2" type="revolute">
<origin xyz="-0.010183962264150969723 -0.031150943396226427051 -0.039537735849056593329" rpy="-0 1.570796326794896558 0" />
<parent link="bloc_moteur" />
<child link="part_8_2" />
<axis xyz="0 0 1"/>
<limit effort="1" velocity="20" />
<joint_properties friction="0.0"/>
</joint>

<link name="cuisse_1_2">
<visual>
<origin xyz="1.7347234759768070944e-18 0.24561320754716980952 -0.044849056603773612695" rpy="1.570796326794896558 6.1232339957367660359e-17 0" />
<geometry>
<mesh filename="package:///cuisse_1.stl"/>
</geometry>
<material name="cuisse_1_material">
<color rgba="0.76862745098039220171 0.88627450980392152857 0.95294117647058818044 1.0"/>
</material>
</visual>
<collision>
<origin xyz="1.7347234759768070944e-18 0.24561320754716980952 -0.044849056603773612695" rpy="1.570796326794896558 6.1232339957367660359e-17 0" />
<geometry>
<mesh filename="package:///cuisse_1.stl"/>
</geometry>
<material name="cuisse_1_material">
<color rgba="0.76862745098039220171 0.88627450980392152857 0.95294117647058818044 1.0"/>
</material>
</collision>
<inertial>
<origin xyz="1.8573961650237243068e-18 0.05511320754716983461 -0.012500024331477350981" rpy="0 0 0"/>
<mass value="0.017558374486852622309" />
<inertia ixx="2.8179142623395863644e-05" ixy="-5.8766572650822571336e-11"  ixz="-5.2318040297869049922e-12" iyy="4.6983411885038097882e-07" iyz="3.5984147546845121287e-27" izz="2.791304966480971181e-05" />
</inertial>
</link>

<link name="tibias_mirror2">
<visual>
<origin xyz="1.7347234759768070944e-18 0.13538679245283019581 0.032349056603773587715" rpy="1.570796326794896558 -6.1232339957367660359e-17 -6.8422776578360208541e-49" />
<geometry>
<mesh filename="package:///tibias_mirror2.stl"/>
</geometry>
<material name="tibias_mirror2_material">
<color rgba="0.91764705882352937127 0.91764705882352937127 0.91764705882352937127 1.0"/>
</material>
</visual>
<collision>
<origin xyz="1.7347234759768070944e-18 0.13538679245283019581 0.032349056603773587715" rpy="1.570796326794896558 -6.1232339957367660359e-17 -6.8422776578360208541e-49" />
<geometry>
<mesh filename="package:///tibias_mirror2.stl"/>
</geometry>
<material name="tibias_mirror2_material">
<color rgba="0.91764705882352937127 0.91764705882352937127 0.91764705882352937127 1.0"/>
</material>
</collision>
<inertial>
<origin xyz="0.0099557611396274281468 0.0065124719326968014479 -5.2801480714904554028e-08" rpy="0 0 0"/>
<mass value="0.019012335635048973476" />
<inertia ixx="2.2400237755941347639e-05" ixy="7.0893867150224942612e-06"  ixz="1.3407484781812131296e-11" iyy="4.0584205301178744922e-06" iyz="-1.1653395213463776552e-11" izz="2.5706408296353003181e-05" />
</inertial>
</link>

<link name="fermeture1_B">
<inertial>
<origin xyz="0 0 0" rpy="0 0 0" />
<mass value="1e-9" />
<inertia ixx="0" ixy="0" ixz="0" iyy="0" iyz="0" izz="0" />
</inertial>
</link>
<joint name="fermeture1_B_frame" type="fixed">
<origin xyz="0 0.075381132075471743437 0" rpy="1.570796326794896558 -6.1232339957367660359e-17 -6.8422776578360208541e-49" />
<parent link="tibias_mirror2" />
<child link="fermeture1_B" />
<axis xyz="0 0 0"/>
</joint>

<link name="cuiqqe_2_2">
<visual>
<origin xyz="-0.035117257249881420056 -0.17308257465018811461 0.032349056603773601593" rpy="-1.570796326794896558 -6.1232339957367660359e-17 0" />
<geometry>
<mesh filename="package:///cuiqqe_2.stl"/>
</geometry>
<material name="cuiqqe_2_material">
<color rgba="0.97254901960784312376 0.52941176470588235947 0.0039215686274509803377 1.0"/>
</material>
</visual>
<collision>
<origin xyz="-0.035117257249881420056 -0.17308257465018811461 0.032349056603773601593" rpy="-1.570796326794896558 -6.1232339957367660359e-17 0" />
<geometry>
<mesh filename="package:///cuiqqe_2.stl"/>
</geometry>
<material name="cuiqqe_2_material">
<color rgba="0.97254901960784312376 0.52941176470588235947 0.0039215686274509803377 1.0"/>
</material>
</collision>
<inertial>
<origin xyz="0.017055198396614242029 0.06365086694933166922 2.5590346997425546873e-08" rpy="0 0 0"/>
<mass value="0.020048097436372345342" />
<inertia ixx="4.0788668580033780105e-05" ixy="-1.0795657082613442217e-05"  ixz="6.0422696691767325742e-12" iyy="3.3910867366475971126e-06" iyz="-1.6190212717905067407e-12" izz="4.3415234962763218408e-05" />
</inertial>
</link>

<link name="part_7_2">
<visual>
<origin xyz="-0.069227654043109876358 -0.30038430854885117549 0.032349056603773573837" rpy="-1.570796326794896558 -6.1232339957367672685e-17 -4.2497157809889018843e-17" />
<geometry>
<mesh filename="package:///part_7.stl"/>
</geometry>
<material name="part_7_material">
<color rgba="0.98039215686274505668 0.71372549019607844922 0.0039215686274509803377 1.0"/>
</material>
</visual>
<collision>
<origin xyz="-0.069227654043109876358 -0.30038430854885117549 0.032349056603773573837" rpy="-1.570796326794896558 -6.1232339957367672685e-17 -4.2497157809889018843e-17" />
<geometry>
<mesh filename="package:///part_7.stl"/>
</geometry>
<material name="part_7_material">
<color rgba="0.98039215686274505668 0.71372549019607844922 0.0039215686274509803377 1.0"/>
</material>
</collision>
<inertial>
<origin xyz="-0.0061832857558966336509 1.9615198354472340725e-11 -1.6956327520361557795e-17" rpy="0 0 0"/>
<mass value="0.0051771712678282859679" />
<inertia ixx="1.9356340696232814838e-07" ixy="1.160395832169706979e-14"  ixz="-1.0937831346525502606e-23" iyy="5.0522228097855914383e-07" iyz="1.3050652896851170583e-12" izz="3.7219275372989875315e-07" />
</inertial>
</link>

<link name="fermeture2_B">
<inertial>
<origin xyz="0 0 0" rpy="0 0 0" />
<mass value="1e-9" />
<inertia ixx="0" ixy="0" ixz="0" iyy="0" iyz="0" izz="0" />
</inertial>
</link>
<joint name="fermeture2_B_frame" type="fixed">
<origin xyz="-0.023912264150947229457 -1.3877787807814456755e-17 5.5511151231257827021e-17" rpy="-1.570796326794896558 2.196504800771137112e-32 1.57079632679489678" />
<parent link="part_7_2" />
<child link="fermeture2_B" />
<axis xyz="0 0 0"/>
</joint>

<joint name="free_to_rotule_4link6" type="revolute">
<origin xyz="0.034110396793228428547 0.12730173389866308864 0.012500000000000011102" rpy="-3.2616319754418623215e-29 -5.7987606467589352553e-30 2.5148967579424548191" />
<parent link="cuiqqe_2_2" />
<child link="part_7_2" />
<axis xyz="0 0 1"/>
<limit effort="1" velocity="20" />
<joint_properties friction="0.0"/>
</joint>

<joint name="free_to_rotule_4link3" type="revolute">
<origin xyz="0.035117257249881420056 -0.037695782197357918797 0" rpy="3.141592653589793116 5.2516235920243112527e-49 0" />
<parent link="tibias_mirror2" />
<child link="cuiqqe_2_2" />
<axis xyz="0 0 1"/>
<limit effort="1" velocity="20" />
<joint_properties friction="0.0"/>
</joint>

<joint name="free_4link6" type="revolute">
<origin xyz="0 0.11022641509433961371 0" rpy="0 5.2516235920243112527e-49 0" />
<parent link="cuisse_1_2" />
<child link="tibias_mirror2" />
<axis xyz="0 0 1"/>
<limit effort="1" velocity="20" />
<joint_properties friction="0.0"/>
</joint>

<joint name="mot_4link4" type="revolute">
<origin xyz="-0.010183962264150997479 0 -0.01437735849056603725" rpy="-0 1.570796326794896558 0" />
<parent link="bloc_moteur" />
<child link="cuisse_1_2" />
<axis xyz="0 0 1"/>
<limit effort="1" velocity="20" />
<joint_properties friction="0.0"/>
</joint>

<joint name="free_hipsx" type="revolute">
<origin xyz="0.00053865046013387533896 -0.13248731426371426756 -0.014270932014976034363" rpy="-1.570796326794896558 -6.1232339957367660359e-17 1.570796326794896558" />
<parent link="part_11" />
<child link="bloc_moteur" />
<axis xyz="0 0 1"/>
<limit effort="1" velocity="20" />
<joint_properties friction="0.0"/>
</joint>


</robot>
