<robot name="onshape">
<link name="torso">
<visual>
<origin xyz="-3.6658488180179105565e-18 2.0816681711721685133e-17 0.059867854479678836443" rpy="-6.1232339957367660359e-17 -0 1.570796326794896558" />
<geometry>
<mesh filename="package:///torso.stl"/>
</geometry>
<material name="torso_material">
<color rgba="0.61568627450980395466 0.81176470588235294379 0.92941176470588238168 1.0"/>
</material>
</visual>
<collision>
<origin xyz="-3.6658488180179105565e-18 2.0816681711721685133e-17 0.059867854479678836443" rpy="-6.1232339957367660359e-17 -0 1.570796326794896558" />
<geometry>
<mesh filename="package:///torso.stl"/>
</geometry>
</collision>
<inertial>
<origin xyz="-4.2892460256780936002e-18 2.2226127192440522264e-17 0.070603948746371325562" rpy="0 0 0"/>
<mass value="3.2452322404414171153" />
<inertia ixx="0.012163262961236534151" ixy="0"  ixz="1.2921033060725064293e-19" iyy="0.0040573041803173628961" iyz="0" izz="0.010053098125184019296" />
</inertial>
</link>

<link name="hip">
<inertial>
<origin xyz="0 0 0" rpy="0 0 0" />
<mass value="1e-9" />
<inertia ixx="0" ixy="0" ixz="0" iyy="0" iyz="0" izz="0" />
</inertial>
</link>
<joint name="hip_frame" type="fixed">
<origin xyz="2.4027501270446886779e-19 -1.626303258728255688e-19 0.0024999999999999996184" rpy="2.8421709430404007435e-14 3.0814879110196404233e-31 0" />
<parent link="torso" />
<child link="hip" />
<axis xyz="0 0 0"/>
</joint>

<link name="hip_y">
<visual>
<origin xyz="0.1070657929734565722 0 -0.035199999999999995182" rpy="-1.570796326794896558 -1.1844937103675576483e-32 1.4161262230606110952e-20" />
<geometry>
<mesh filename="package:///hip_y.stl"/>
</geometry>
<material name="hip_y_material">
<color rgba="0.2313725490196078538 0.38039215686274507888 0.7058823529411765163 1.0"/>
</material>
</visual>
<collision>
<origin xyz="0.1070657929734565722 0 -0.035199999999999995182" rpy="-1.570796326794896558 -1.1844937103675576483e-32 1.4161262230606110952e-20" />
<geometry>
<mesh filename="package:///hip_y.stl"/>
</geometry>
</collision>
<inertial>
<origin xyz="0.015578666288194945033 -1.2357431137270556961e-07 -0.034149457045324432825" rpy="0 0 0"/>
<mass value="1.2895238899898622265" />
<inertia ixx="0.00089621011138626526914" ixy="-1.7957438648414495318e-09"  ixz="3.2112420914059134399e-05" iyy="0.0010420724953831758935" iyz="3.049249647458305054e-09" izz="0.0010213484696825509291" />
</inertial>
</link>

<link name="hip_x">
<visual>
<origin xyz="0 0 -0.054400000000000003908" rpy="1.570796326794896558 1.570796326794896558 0" />
<geometry>
<mesh filename="package:///hip_x.stl"/>
</geometry>
<material name="hip_x_material">
<color rgba="0.64705882352941179736 0.64705882352941179736 0.64705882352941179736 1.0"/>
</material>
</visual>
<collision>
<origin xyz="0 0 -0.054400000000000003908" rpy="1.570796326794896558 1.570796326794896558 0" />
<geometry>
<mesh filename="package:///hip_x.stl"/>
</geometry>
</collision>
<inertial>
<origin xyz="0.0023378176535870068449 -8.4710947525755844375e-19 -0.045216753463575065641" rpy="0 0 0"/>
<mass value="1.4197410037164888141" />
<inertia ixx="0.0014949229305128526255" ixy="-6.9793458158034925278e-22"  ixz="-1.2476184392984375319e-05" iyy="0.0013017541081209297628" iyz="-4.0022934241776067926e-23" izz="0.00094724669336309881909" />
</inertial>
</link>

<link name="hip_z">
<visual>
<origin xyz="-0.12000000000000002331 0 -0.070000000000000006661" rpy="-1.570796326794896558 1.3435810028428300928e-19 5.9775835915032519012e-17" />
<geometry>
<mesh filename="package:///hip_z.stl"/>
</geometry>
<material name="hip_z_material">
<color rgba="0.61568627450980395466 0.81176470588235294379 0.92941176470588238168 1.0"/>
</material>
</visual>
<collision>
<origin xyz="-0.12000000000000002331 0 -0.070000000000000006661" rpy="-1.570796326794896558 1.3435810028428300928e-19 5.9775835915032519012e-17" />
<geometry>
<mesh filename="package:///hip_z.stl"/>
</geometry>
</collision>
<inertial>
<origin xyz="-0.060000000000000018596 3.9838076762061399048e-18 -0.022000000000000005662" rpy="0 0 0"/>
<mass value="3.8932756153047387571" />
<inertia ixx="0.0040205863361596526698" ixy="8.6734434996373926088e-19"  ixz="2.7829775778561473385e-20" iyy="0.014779167671256705774" iyz="4.5852855781184215639e-20" izz="0.017543523742211360184" />
</inertial>
</link>

<link name="shin">
<visual>
<origin xyz="0 5.5511151231257827021e-17 -0.025000000000000008327" rpy="-1.570796326794896558 1.5421059036166658938e-18 3.6887305321401350811e-17" />
<geometry>
<mesh filename="package:///shin.stl"/>
</geometry>
<material name="shin_material">
<color rgba="0.61568627450980395466 0.81176470588235294379 0.92941176470588238168 1.0"/>
</material>
</visual>
<collision>
<origin xyz="0 5.5511151231257827021e-17 -0.025000000000000008327" rpy="-1.570796326794896558 1.5421059036166658938e-18 3.6887305321401350811e-17" />
<geometry>
<mesh filename="package:///shin.stl"/>
</geometry>
</collision>
<inertial>
<origin xyz="0.086542930154570318901 0.024349627108824788146 -0.025000000824260217025" rpy="0 0 0"/>
<mass value="0.55578140933316355632" />
<inertia ixx="0.0004664406681127265873" ixy="-0.00088329043391741567885"  ixz="6.3639812830299238928e-13" iyy="0.0090559095871162419156" iyz="1.1189385828538000778e-11" izz="0.0093490826129847687254" />
</inertial>
</link>

<link name="tarsus">
<visual>
<origin xyz="-0.11600000000000042222 -0.11491398237765959589 -1.249000902703301108e-16" rpy="3.1415926535897926719 1.570796326794896336 0" />
<geometry>
<mesh filename="package:///actuator_molet.stl"/>
</geometry>
<material name="actuator_molet_material">
<color rgba="0.91764705882352937127 0.91764705882352937127 0.91764705882352937127 1.0"/>
</material>
</visual>
<collision>
<origin xyz="-0.11600000000000042222 -0.11491398237765959589 -1.249000902703301108e-16" rpy="3.1415926535897926719 1.570796326794896336 0" />
<geometry>
<mesh filename="package:///actuator_molet.stl"/>
</geometry>
</collision>
<visual>
<origin xyz="1.0408340855860842566e-17 0.0010860176223413953167 -1.3877787807814456755e-17" rpy="-1.570796326794896558 -1.570796326794896558 0" />
<geometry>
<mesh filename="package:///tarsus.stl"/>
</geometry>
<material name="tarsus_material">
<color rgba="0.61568627450980395466 0.81176470588235294379 0.92941176470588238168 1.0"/>
</material>
</visual>
<collision>
<origin xyz="1.0408340855860842566e-17 0.0010860176223413953167 -1.3877787807814456755e-17" rpy="-1.570796326794896558 -1.570796326794896558 0" />
<geometry>
<mesh filename="package:///tarsus.stl"/>
</geometry>
</collision>
<inertial>
<origin xyz="-0.083086291902174758128 -0.020033778925019920386 2.8736095503481446728e-08" rpy="0 0 0"/>
<mass value="0.74284619422086228813" />
<inertia ixx="0.0003981883511251220367" ixy="-0.00054213231673499973854"  ixz="-5.2637644316911096689e-10" iyy="0.007985191784274097912" iyz="1.2685116127629153186e-10" izz="0.0079848716361182459078" />
</inertial>
</link>

<link name="foot_roll">
<visual>
<origin xyz="0.32599840000000002149 0.039743999999999946038 -0.013999999999999873657" rpy="-1.570796326794896558 -1.570796326794896336 0" />
<geometry>
<mesh filename="package:///foot_roll.stl"/>
</geometry>
<material name="foot_roll_material">
<color rgba="0.2313725490196078538 0.38039215686274507888 0.7058823529411765163 1.0"/>
</material>
</visual>
<collision>
<origin xyz="0.32599840000000002149 0.039743999999999946038 -0.013999999999999873657" rpy="-1.570796326794896558 -1.570796326794896336 0" />
<geometry>
<mesh filename="package:///foot_roll.stl"/>
</geometry>
</collision>
<inertial>
<origin xyz="-2.1851523865201681097e-08 -0.0014449033387293060918 -0.013999993222565306969" rpy="0 0 0"/>
<mass value="0.0027067106871796991867" />
<inertia ixx="1.8232396912107801821e-07" ixy="1.2456494872815071937e-13"  ixz="-3.0177862000852598198e-13" iyy="1.1958745424438041694e-07" iyz="4.5807687216678604469e-14" izz="1.0944659228682656112e-07" />
</inertial>
</link>

<link name="foot_part">
<visual>
<origin xyz="-0.0011288304490429945659 1.3877787807814456755e-17 0.0090799999999999769784" rpy="1.570796326794896558 -2.4151009359747052609e-18 1.0050787149806718802e-18" />
<geometry>
<mesh filename="package:///foot_part.stl"/>
</geometry>
<material name="foot_part_material">
<color rgba="0.61568627450980395466 0.81176470588235294379 0.92941176470588238168 1.0"/>
</material>
</visual>
<collision>
<origin xyz="-0.0011288304490429945659 1.3877787807814456755e-17 0.0090799999999999769784" rpy="1.570796326794896558 -2.4151009359747052609e-18 1.0050787149806718802e-18" />
<geometry>
<mesh filename="package:///foot_part.stl"/>
</geometry>
</collision>
<inertial>
<origin xyz="-0.042296631354857151808 -6.7228490678842270848e-10 0.011797351827666179708" rpy="0 0 0"/>
<mass value="0.3309516742025366276" />
<inertia ixx="0.0010118322945958278195" ixy="2.5339652270110832944e-12"  ixz="-0.00049446274168876561735" iyy="0.0012276801049992628473" iyz="7.2849212783796543501e-12" izz="0.00051045333461432855493" />
</inertial>
</link>

<link name="foot">
<inertial>
<origin xyz="0 0 0" rpy="0 0 0" />
<mass value="1e-9" />
<inertia ixx="0" ixy="0" ixz="0" iyy="0" iyz="0" izz="0" />
</inertial>
</link>
<joint name="foot_frame" type="fixed">
<origin xyz="-0.05589761960057737511 1.3877787807814456755e-17 0.014375929767894479738" rpy="3.1415926535897926719 1.0420837364882549192 3.141592653589793116" />
<parent link="foot_part" />
<child link="foot" />
<axis xyz="0 0 0"/>
</joint>

<link name="toe_b_1/2">
<visual>
<origin xyz="-0.054171488011523785677 -0.043924303555988974956 4.9999999999883470991e-05" rpy="-1.570796326794896558 -1.570796326794896558 0" />
<geometry>
<mesh filename="package:///toe_b_1_2.stl"/>
</geometry>
<material name="toe_b_1/2_material">
<color rgba="0.64705882352941179736 0.64705882352941179736 0.64705882352941179736 1.0"/>
</material>
</visual>
<collision>
<origin xyz="-0.054171488011523785677 -0.043924303555988974956 4.9999999999883470991e-05" rpy="-1.570796326794896558 -1.570796326794896558 0" />
<geometry>
<mesh filename="package:///toe_b_1_2.stl"/>
</geometry>
</collision>
<inertial>
<origin xyz="-6.6563453546980869866e-19 -4.1633363423443370266e-17 -0.059975000000000076861" rpy="0 0 0"/>
<mass value="0.0060293446207695467268" />
<inertia ixx="7.2533028348992199005e-06" ixy="1.0389602075683766194e-22"  ixz="3.293933459331806166e-23" iyy="7.2533028348992088891e-06" iyz="-4.4149525664705793399e-22" izz="4.8234756966146925458e-08" />
</inertial>
</link>

<link name="closedloop3_B">
<inertial>
<origin xyz="0 0 0" rpy="0 0 0" />
<mass value="1e-9" />
<inertia ixx="0" ixy="0" ixz="0" iyy="0" iyz="0" izz="0" />
</inertial>
</link>
<joint name="closedloop3_B_frame" type="fixed">
<origin xyz="1.9949319973733281586e-17 -1.1102230246251565404e-16 -0.11995000000000011209" rpy="3.141592653589793116 6.1562166213320717002e-17 1.570796326794896558" />
<parent link="toe_b_1/2" />
<child link="closedloop3_B" />
<axis xyz="0 0 0"/>
</joint>

<joint name="spherical_free_foot1" type="revolute">
<origin xyz="-0.0091288304490430571825 -0.01427599999999996927 0.052813599999999905066" rpy="1.57079632679489678 0.17116739882267056894 -1.5707963267948981123" />
<parent link="foot_part" />
<child link="toe_b_1/2" />
<axis xyz="0 0 1"/>
<limit effort="1" velocity="20" />
<joint_properties friction="0.0"/>
</joint>

<link name="toe_b_1/2_2">
<visual>
<origin xyz="-0.054171488011523771799 0.043924303555988974956 -0.12000000000000005107" rpy="1.570796326794896558 1.570796326794896558 0" />
<geometry>
<mesh filename="package:///toe_b_1_2.stl"/>
</geometry>
<material name="toe_b_1/2_material">
<color rgba="0.64705882352941179736 0.64705882352941179736 0.64705882352941179736 1.0"/>
</material>
</visual>
<collision>
<origin xyz="-0.054171488011523771799 0.043924303555988974956 -0.12000000000000005107" rpy="1.570796326794896558 1.570796326794896558 0" />
<geometry>
<mesh filename="package:///toe_b_1_2.stl"/>
</geometry>
</collision>
<inertial>
<origin xyz="1.3865440855350116646e-17 2.7755575615628913511e-17 -0.059975000000000090739" rpy="0 0 0"/>
<mass value="0.0060293446207695467268" />
<inertia ixx="7.2533028348992199005e-06" ixy="1.5057167467410681306e-22"  ixz="-2.9374392211855169631e-23" iyy="7.2533028348992105832e-06" iyz="1.2982278501752193601e-22" izz="4.8234756966146925458e-08" />
</inertial>
</link>

<link name="closedloop2_B">
<inertial>
<origin xyz="0 0 0" rpy="0 0 0" />
<mass value="1e-9" />
<inertia ixx="0" ixy="0" ixz="0" iyy="0" iyz="0" izz="0" />
</inertial>
</link>
<joint name="closedloop2_B_frame" type="fixed">
<origin xyz="-1.3877787807814456755e-17 0 -0.1199500000000001676" rpy="-3.141592653589793116 -1.7785462404289089151e-17 1.570796326794896558" />
<parent link="toe_b_1/2_2" />
<child link="closedloop2_B" />
<axis xyz="0 0 0"/>
</joint>

<joint name="spherical_free_foot2" type="revolute">
<origin xyz="-0.0091288304490430016713 0.014276000000000024781 0.052813600000000016088" rpy="1.570796326794896558 0.17116739882267226203 -1.570796326794896558" />
<parent link="foot_part" />
<child link="toe_b_1/2_2" />
<axis xyz="0 0 1"/>
<limit effort="1" velocity="20" />
<joint_properties friction="0.0"/>
</joint>

<joint name="free_foot2" type="revolute">
<origin xyz="0 0.0089999999999999524825 -0.014000000000000012434" rpy="-1.570796326794896558 0.0068053161721140344523 -3.1415926535897904515" />
<parent link="foot_roll" />
<child link="foot_part" />
<axis xyz="0 0 1"/>
<limit effort="1" velocity="20" />
<joint_properties friction="0.0"/>
</joint>

<joint name="free_foot1" type="revolute">
<origin xyz="-0.32599840000000002149 -0.038657982377658606232 -0.014000000000000067946" rpy="-3.1415926535897917837 -6.8122768436356686698e-17 1.8602703927245938242" />
<parent link="tarsus" />
<child link="foot_roll" />
<axis xyz="0 0 1"/>
<limit effort="1" velocity="20" />
<joint_properties friction="0.0"/>
</joint>

<link name="crank">
<visual>
<origin xyz="0.088800000000000101075 0.027200000000000001954 0.029999999999999991951" rpy="-1.570796326794896558 -1.570796326794896558 0" />
<geometry>
<mesh filename="package:///crank.stl"/>
</geometry>
<material name="crank_material">
<color rgba="0.64705882352941179736 0.64705882352941179736 0.64705882352941179736 1.0"/>
</material>
</visual>
<collision>
<origin xyz="0.088800000000000101075 0.027200000000000001954 0.029999999999999991951" rpy="-1.570796326794896558 -1.570796326794896558 0" />
<geometry>
<mesh filename="package:///crank.stl"/>
</geometry>
</collision>
<inertial>
<origin xyz="6.9464433186441986351e-17 0.015221680213895987313 -0.00095148915120265090128" rpy="0 0 0"/>
<mass value="0.0045332434126214744829" />
<inertia ixx="2.0190313503504425919e-06" ixy="1.1808396937405624902e-25"  ixz="-1.1186842369827592174e-23" iyy="3.8254267160843603214e-07" iyz="-9.1875323763545036488e-09" izz="2.3968139039834541711e-06" />
</inertial>
</link>

<link name="toe_b_2/2">
<visual>
<origin xyz="-0.054171488011523827311 -0.04392430355598895414 -0.12000000000000005107" rpy="-1.570796326794896558 -1.570796326794896558 0" />
<geometry>
<mesh filename="package:///toe_b_2_2.stl"/>
</geometry>
<material name="toe_b_2/2_material">
<color rgba="0.64705882352941179736 0.64705882352941179736 0.64705882352941179736 1.0"/>
</material>
</visual>
<collision>
<origin xyz="-0.054171488011523827311 -0.04392430355598895414 -0.12000000000000005107" rpy="-1.570796326794896558 -1.570796326794896558 0" />
<geometry>
<mesh filename="package:///toe_b_2_2.stl"/>
</geometry>
</collision>
<inertial>
<origin xyz="-3.4623961118958146631e-17 -6.9388939039072283776e-18 -0.059974999999999986655" rpy="0 0 0"/>
<mass value="0.0060293446207695345837" />
<inertia ixx="7.2533028348992021128e-06" ixy="-2.1236101182141503058e-25"  ixz="2.8616539242916527064e-25" iyy="7.2533028348991885603e-06" iyz="2.406592865855183527e-23" izz="4.8234756966146826196e-08" />
</inertial>
</link>

<link name="closedloop2_A">
<inertial>
<origin xyz="0 0 0" rpy="0 0 0" />
<mass value="1e-9" />
<inertia ixx="0" ixy="0" ixz="0" iyy="0" iyz="0" izz="0" />
</inertial>
</link>
<joint name="closedloop2_A_frame" type="fixed">
<origin xyz="-5.5511151231257827021e-17 -3.4694469519536141888e-18 -0.11994999999999983453" rpy="3.4326414718463428853e-16 -3.9801083377604632754e-20 -1.7060090772934402995e-18" />
<parent link="toe_b_2/2" />
<child link="closedloop2_A" />
<axis xyz="0 0 0"/>
</joint>

<joint name="spherical_free_shin2" type="revolute">
<origin xyz="0 0.057000000000000050626 0.0025000000000000022204" rpy="1.570796326794896558 -0.043999020249819484341 1.5707963267948952257" />
<parent link="crank" />
<child link="toe_b_2/2" />
<axis xyz="0 0 1"/>
<limit effort="1" velocity="20" />
<joint_properties friction="0.0"/>
</joint>

<joint name="motor_shin1" type="revolute">
<origin xyz="-0.088800000000000017808 -0.02611398237765871766 0.029999999999999971134" rpy="3.141592653589793116 1.1559547673004707569e-15 0.7069149543481728637" />
<parent link="tarsus" />
<child link="crank" />
<axis xyz="0 0 1"/>
<limit effort="1" velocity="20" />
<joint_properties friction="0.0"/>
</joint>

<link name="crank_2">
<visual>
<origin xyz="0.088799999999999934541 0.027200000000000001954 0.02999999999999999889" rpy="-1.570796326794896558 -1.570796326794896558 0" />
<geometry>
<mesh filename="package:///crank.stl"/>
</geometry>
<material name="crank_material">
<color rgba="0.64705882352941179736 0.64705882352941179736 0.64705882352941179736 1.0"/>
</material>
</visual>
<collision>
<origin xyz="0.088799999999999934541 0.027200000000000001954 0.02999999999999999889" rpy="-1.570796326794896558 -1.570796326794896558 0" />
<geometry>
<mesh filename="package:///crank.stl"/>
</geometry>
</collision>
<inertial>
<origin xyz="-8.3284131142908954542e-17 0.015221680213895987313 -0.00095148915120264754026" rpy="0 0 0"/>
<mass value="0.0045332434126214744829" />
<inertia ixx="2.0190313503504417449e-06" ixy="2.4136633005743384843e-26"  ixz="1.1261704340225916773e-24" iyy="3.8254267160843592626e-07" iyz="-9.1875323763544986857e-09" izz="2.3968139039834550182e-06" />
</inertial>
</link>

<link name="toe_b_2/2_2">
<visual>
<origin xyz="-0.054171488011523882822 -0.043924303555988947201 -0.11999999999999999556" rpy="-1.570796326794896558 -1.570796326794896558 0" />
<geometry>
<mesh filename="package:///toe_b_2_2.stl"/>
</geometry>
<material name="toe_b_2/2_material">
<color rgba="0.64705882352941179736 0.64705882352941179736 0.64705882352941179736 1.0"/>
</material>
</visual>
<collision>
<origin xyz="-0.054171488011523882822 -0.043924303555988947201 -0.11999999999999999556" rpy="-1.570796326794896558 -1.570796326794896558 0" />
<geometry>
<mesh filename="package:///toe_b_2_2.stl"/>
</geometry>
</collision>
<inertial>
<origin xyz="-1.0407340479434012741e-16 0 -0.059974999999999917266" rpy="0 0 0"/>
<mass value="0.0060293446207695345837" />
<inertia ixx="7.2533028348991987247e-06" ixy="-2.1988757397418470838e-23"  ixz="1.1917855800902583826e-25" iyy="7.2533028348991885603e-06" iyz="-8.7138739168927235688e-25" izz="4.8234756966146852666e-08" />
</inertial>
</link>

<link name="closedloop3_A">
<inertial>
<origin xyz="0 0 0" rpy="0 0 0" />
<mass value="1e-9" />
<inertia ixx="0" ixy="0" ixz="0" iyy="0" iyz="0" izz="0" />
</inertial>
</link>
<joint name="closedloop3_A_frame" type="fixed">
<origin xyz="-5.5511151231257827021e-17 -1.3877787807814456755e-17 -0.11994999999999989004" rpy="5.4796299760769498158e-16 -1.6492169195407397826e-20 -3.2718841564329059315e-18" />
<parent link="toe_b_2/2_2" />
<child link="closedloop3_A" />
<axis xyz="0 0 0"/>
</joint>

<joint name="spherical_free_shin1" type="revolute">
<origin xyz="5.5511151231257827021e-17 0.056999999999999884093 0.0025000000000000022204" rpy="-1.57079632679489678 0.040608021976129123065 1.5707963267948990005" />
<parent link="crank_2" />
<child link="toe_b_2/2_2" />
<axis xyz="0 0 1"/>
<limit effort="1" velocity="20" />
<joint_properties friction="0.0"/>
</joint>

<joint name="motor_shin2" type="revolute">
<origin xyz="-0.088800000000000017808 -0.02611398237765871766 -0.030000000000000012768" rpy="9.0029948949621089308e-16 -1.3909315756828847546e-15 -2.4346776992416199192" />
<parent link="tarsus" />
<child link="crank_2" />
<axis xyz="0 0 1"/>
<limit effort="1" velocity="20" />
<joint_properties friction="0.0"/>
</joint>

<link name="toe_a_1/2">
<visual>
<origin xyz="0.056794565202878954935 -0.040773406646044452195 4.9999999999994493294e-05" rpy="-1.570796326794896558 -1.570796326794896558 0" />
<geometry>
<mesh filename="package:///toe_a_1_2.stl"/>
</geometry>
<material name="toe_a_1/2_material">
<color rgba="0.61568627450980395466 0.81176470588235294379 0.92941176470588238168 1.0"/>
</material>
</visual>
<collision>
<origin xyz="0.056794565202878954935 -0.040773406646044452195 4.9999999999994493294e-05" rpy="-1.570796326794896558 -1.570796326794896558 0" />
<geometry>
<mesh filename="package:///toe_a_1_2.stl"/>
</geometry>
</collision>
<inertial>
<origin xyz="-5.7063895794484359958e-17 6.9388939039072283776e-18 -0.099974999999999966671" rpy="0 0 0"/>
<mass value="0.015704036277131967758" />
<inertia ixx="5.241876769505099447e-05" ixy="1.8472966973059125198e-22"  ixz="3.9246348623489026058e-21" iyy="5.2418767695050980918e-05" iyz="-3.1992107165520627842e-21" izz="1.9630045346413525667e-07" />
</inertial>
</link>

<link name="closedloop1_B">
<inertial>
<origin xyz="0 0 0" rpy="0 0 0" />
<mass value="1e-9" />
<inertia ixx="0" ixy="0" ixz="0" iyy="0" iyz="0" izz="0" />
</inertial>
</link>
<joint name="closedloop1_B_frame" type="fixed">
<origin xyz="2.7755575615628913511e-17 8.3266726846886740532e-17 -0.19995000000000029416" rpy="-3.141592653589793116 7.4547420754140838791e-17 3.141592653589793116" />
<parent link="toe_a_1/2" />
<child link="closedloop1_B" />
<axis xyz="0 0 0"/>
</joint>

<joint name="spherical_free_knee" type="revolute">
<origin xyz="0.11418993498637033945 0.036206749731294562977 -6.9388939039072283776e-17" rpy="-1.57079632679489678 -0.0024782974323323777623 3.1415926535897926719" />
<parent link="tarsus" />
<child link="toe_a_1/2" />
<axis xyz="0 0 1"/>
<limit effort="1" velocity="20" />
<joint_properties friction="0.0"/>
</joint>

<joint name="free_knee" type="revolute">
<origin xyz="0.39567486363081366685 0.053875166733171858668 -0.024999999999999994449" rpy="-3.1415926535897913396 -5.6727426674657804652e-16 -1.1259608736106343496" />
<parent link="shin" />
<child link="tarsus" />
<axis xyz="0 0 1"/>
<limit effort="1" velocity="20" />
<joint_properties friction="0.0"/>
</joint>

<joint name="motor_knee" type="revolute">
<origin xyz="-0.11999999999999930167 -1.1102230246251565404e-16 2.7755575615628913511e-17" rpy="-3.1415926535897900074 -2.8892848188444140326e-15 -1.5679404125952058902" />
<parent link="hip_z" />
<child link="shin" />
<axis xyz="0 0 1"/>
<limit effort="1" velocity="20" />
<joint_properties friction="0.0"/>
</joint>

<joint name="motor_hip_y" type="revolute">
<origin xyz="-0.025999999999999870437 4.1633363423443370266e-17 -0.054399999999993300936" rpy="1.5707963267948970021 -1.3059816663625789523 1.570796326794901665" />
<parent link="hip_x" />
<child link="hip_z" />
<axis xyz="0 0 1"/>
<limit effort="1" velocity="20" />
<joint_properties friction="0.0"/>
</joint>

<link name="toe_a_2/2">
<visual>
<origin xyz="0.056794565202878989629 -0.040773406646044452195 -0.2000000000000000111" rpy="-1.570796326794896558 -1.570796326794896558 0" />
<geometry>
<mesh filename="package:///toe_a_2_2.stl"/>
</geometry>
<material name="toe_a_2/2_material">
<color rgba="0.61568627450980395466 0.81176470588235294379 0.92941176470588238168 1.0"/>
</material>
</visual>
<collision>
<origin xyz="0.056794565202878989629 -0.040773406646044452195 -0.2000000000000000111" rpy="-1.570796326794896558 -1.570796326794896558 0" />
<geometry>
<mesh filename="package:///toe_a_2_2.stl"/>
</geometry>
</collision>
<inertial>
<origin xyz="-7.2512901683149383743e-18 -6.9388939039072283776e-18 -0.099974999999999938916" rpy="0 0 0"/>
<mass value="0.015704036277131950411" />
<inertia ixx="5.2418767695050845392e-05" ixy="-4.4771008552146945447e-22"  ixz="-2.0244450031833117512e-24" iyy="5.2418767695050818287e-05" iyz="-1.6729487195066324912e-22" izz="1.9630045346413507138e-07" />
</inertial>
</link>

<link name="closedloop1_A">
<inertial>
<origin xyz="0 0 0" rpy="0 0 0" />
<mass value="1e-9" />
<inertia ixx="0" ixy="0" ixz="0" iyy="0" iyz="0" izz="0" />
</inertial>
</link>
<joint name="closedloop1_A_frame" type="fixed">
<origin xyz="6.9388939039072283776e-17 -1.3877787807814456755e-17 -0.1999499999999999611" rpy="-3.788813618164422701e-16 -6.1252745321360377712e-19 3.1025899480884559963e-18" />
<parent link="toe_a_2/2" />
<child link="closedloop1_A" />
<axis xyz="0 0 0"/>
</joint>

<joint name="spherical_free_hip" type="revolute">
<origin xyz="0.033685999999999993726 1.3877787807814456755e-17 -0.054399999999999983091" rpy="-1.5707963267948983344 -1.5498622103990022936 3.1415926535893028415" />
<parent link="hip_x" />
<child link="toe_a_2/2" />
<axis xyz="0 0 1"/>
<limit effort="1" velocity="20" />
<joint_properties friction="0.0"/>
</joint>

<joint name="motor_hip_z" type="revolute">
<origin xyz="0.052665792973456568293 1.3877787807814456755e-17 -0.035200000000000009059" rpy="-1.5707963267948952257 -0.013078473573069489613 1.5707963267948958919" />
<parent link="hip_y" />
<child link="hip_x" />
<axis xyz="0 0 1"/>
<limit effort="1" velocity="20" />
<joint_properties friction="0.0"/>
</joint>

<joint name="motor_hip_x" type="revolute">
<origin xyz="-0.02999999999999999889 -0.072800000000000003597 0.059867854479678822566" rpy="1.5707963267948932273 1.5524862860405099774 1.5707963267948932273" />
<parent link="torso" />
<child link="hip_y" />
<axis xyz="0 0 1"/>
<limit effort="1" velocity="20" />
<joint_properties friction="0.0"/>
</joint>

<link name="hip_y_2">
<visual>
<origin xyz="0.10440000000000000668 1.3877787807814456755e-17 -0.035199999999999995182" rpy="-1.570796326794896558 1.3206928271447807755e-33 4.5540479520856111524e-18" />
<geometry>
<mesh filename="package:///hip_y.stl"/>
</geometry>
<material name="hip_y_material">
<color rgba="0.2313725490196078538 0.38039215686274507888 0.7058823529411765163 1.0"/>
</material>
</visual>
<collision>
<origin xyz="0.10440000000000000668 1.3877787807814456755e-17 -0.035199999999999995182" rpy="-1.570796326794896558 1.3206928271447807755e-33 4.5540479520856111524e-18" />
<geometry>
<mesh filename="package:///hip_y.stl"/>
</geometry>
</collision>
<inertial>
<origin xyz="0.012912873314738379515 -1.2357431135924311911e-07 -0.034149457045324432825" rpy="0 0 0"/>
<mass value="1.2895238899898622265" />
<inertia ixx="0.00089621011138626526914" ixy="-1.7957438648349063264e-09"  ixz="3.2112420914059134399e-05" iyy="0.0010420724953831758935" iyz="3.0492496474584510513e-09" izz="0.0010213484696825509291" />
</inertial>
</link>

<link name="hip_x_2">
<visual>
<origin xyz="-0.0031172266567815881677 -1.3877787807814456755e-17 -0.054400000000000003908" rpy="1.570796326794896558 1.570796326794896558 0" />
<geometry>
<mesh filename="package:///hip_x.stl"/>
</geometry>
<material name="hip_x_material">
<color rgba="0.64705882352941179736 0.64705882352941179736 0.64705882352941179736 1.0"/>
</material>
</visual>
<collision>
<origin xyz="-0.0031172266567815881677 -1.3877787807814456755e-17 -0.054400000000000003908" rpy="1.570796326794896558 1.570796326794896558 0" />
<geometry>
<mesh filename="package:///hip_x.stl"/>
</geometry>
</collision>
<inertial>
<origin xyz="-0.00077940900319458132281 -1.4724536241557834134e-17 -0.045216753463575065641" rpy="0 0 0"/>
<mass value="1.4197410037164888141" />
<inertia ixx="0.0014949229305128526255" ixy="4.6872303244728068779e-22"  ixz="-1.2476184392984378707e-05" iyy="0.0013017541081209297628" iyz="-3.327084348656620667e-24" izz="0.00094724669336309881909" />
</inertial>
</link>

<link name="hip_z_2">
<visual>
<origin xyz="3.4694469519536141888e-18 1.3877787807814456755e-17 -0.070000000000000020539" rpy="-1.570796326794896558 1.6911752321411738822e-18 1.9421011686997654782e-17" />
<geometry>
<mesh filename="package:///hip_z.stl"/>
</geometry>
<material name="hip_z_material">
<color rgba="0.61568627450980395466 0.81176470588235294379 0.92941176470588238168 1.0"/>
</material>
</visual>
<collision>
<origin xyz="3.4694469519536141888e-18 1.3877787807814456755e-17 -0.070000000000000020539" rpy="-1.570796326794896558 1.6911752321411738822e-18 1.9421011686997654782e-17" />
<geometry>
<mesh filename="package:///hip_z.stl"/>
</geometry>
</collision>
<inertial>
<origin xyz="0.059999999999999990841 1.5201727879109244861e-17 -0.02200000000000001954" rpy="0 0 0"/>
<mass value="3.8932756153047387571" />
<inertia ixx="0.0040205863361596509351" ixy="-6.1338047162992566651e-19"  ixz="-8.952527963620354459e-21" iyy="0.014779167671256709243" iyz="7.5153163212793971658e-21" izz="0.017543523742211360184" />
</inertial>
</link>

<link name="shin_2">
<visual>
<origin xyz="-1.3877787807814456755e-17 0 -0.024999999999999994449" rpy="1.570796326794896558 3.8794969757206229507e-19 1.6969176157191160305e-17" />
<geometry>
<mesh filename="package:///shin.stl"/>
</geometry>
<material name="shin_material">
<color rgba="0.61568627450980395466 0.81176470588235294379 0.92941176470588238168 1.0"/>
</material>
</visual>
<collision>
<origin xyz="-1.3877787807814456755e-17 0 -0.024999999999999994449" rpy="1.570796326794896558 3.8794969757206229507e-19 1.6969176157191160305e-17" />
<geometry>
<mesh filename="package:///shin.stl"/>
</geometry>
</collision>
<inertial>
<origin xyz="0.086542930154570332779 -0.024349627108824729166 -0.024999999175739785751" rpy="0 0 0"/>
<mass value="0.55578140933316355632" />
<inertia ixx="0.0004664406681127271294" ixy="0.00088329043391741654621"  ixz="-6.3639815832171669797e-13" iyy="0.0090559095871162419156" iyz="1.1189385792173961672e-11" izz="0.0093490826129847687254" />
</inertial>
</link>

<link name="tarsus_2">
<visual>
<origin xyz="-9.7144514654701197287e-17 0.001086017622341506339 -1.3877787807814456755e-17" rpy="-1.570796326794896558 -1.570796326794896558 0" />
<geometry>
<mesh filename="package:///tarsus.stl"/>
</geometry>
<material name="tarsus_material">
<color rgba="0.61568627450980395466 0.81176470588235294379 0.92941176470588238168 1.0"/>
</material>
</visual>
<collision>
<origin xyz="-9.7144514654701197287e-17 0.001086017622341506339 -1.3877787807814456755e-17" rpy="-1.570796326794896558 -1.570796326794896558 0" />
<geometry>
<mesh filename="package:///tarsus.stl"/>
</geometry>
</collision>
<visual>
<origin xyz="-0.061600000000000473821 -0.11491398237765759749 9.7144514654701197287e-17" rpy="3.1415926535897922278 -1.570796326794896558 0" />
<geometry>
<mesh filename="package:///actuator_molet.stl"/>
</geometry>
<material name="actuator_molet_material">
<color rgba="0.91764705882352937127 0.91764705882352937127 0.91764705882352937127 1.0"/>
</material>
</visual>
<collision>
<origin xyz="-0.061600000000000473821 -0.11491398237765759749 9.7144514654701197287e-17" rpy="3.1415926535897922278 -1.570796326794896558 0" />
<geometry>
<mesh filename="package:///actuator_molet.stl"/>
</geometry>
</collision>
<inertial>
<origin xyz="-0.083086291902174855273 -0.020033778925019798955 2.8736095531614398682e-08" rpy="0 0 0"/>
<mass value="0.74284619422086228813" />
<inertia ixx="0.00039818835112512057303" ixy="-0.00054213231673499963012"  ixz="-5.2637644302880076568e-10" iyy="0.0079851917842740961773" iyz="1.2685116134705290415e-10" izz="0.0079848716361182493773" />
</inertial>
</link>

<link name="foot_roll_2">
<visual>
<origin xyz="0.32599840000000002149 0.039743999999999890527 1.249000902703301108e-16" rpy="-1.570796326794896558 -1.570796326794896336 0" />
<geometry>
<mesh filename="package:///foot_roll.stl"/>
</geometry>
<material name="foot_roll_material">
<color rgba="0.2313725490196078538 0.38039215686274507888 0.7058823529411765163 1.0"/>
</material>
</visual>
<collision>
<origin xyz="0.32599840000000002149 0.039743999999999890527 1.249000902703301108e-16" rpy="-1.570796326794896558 -1.570796326794896336 0" />
<geometry>
<mesh filename="package:///foot_roll.stl"/>
</geometry>
</collision>
<inertial>
<origin xyz="-2.185152381175572854e-08 -0.0014449033387293752639 6.7774346912261958309e-09" rpy="0 0 0"/>
<mass value="0.0027067106871796991867" />
<inertia ixx="1.8232396912107796527e-07" ixy="1.2456494873648333721e-13"  ixz="-3.0177862000975509038e-13" iyy="1.1958745424438046988e-07" iyz="4.5807687216522637202e-14" izz="1.0944659228682656112e-07" />
</inertial>
</link>

<link name="foot_part_2">
<visual>
<origin xyz="-0.0011288304490428835436 -1.3877787807814456755e-17 0.0090799999999999769784" rpy="-1.570796326794896558 3.0863088493385133715e-17 -4.3551584473673174824e-18" />
<geometry>
<mesh filename="package:///foot_part.stl"/>
</geometry>
<material name="foot_part_material">
<color rgba="0.61568627450980395466 0.81176470588235294379 0.92941176470588238168 1.0"/>
</material>
</visual>
<collision>
<origin xyz="-0.0011288304490428835436 -1.3877787807814456755e-17 0.0090799999999999769784" rpy="-1.570796326794896558 3.0863088493385133715e-17 -4.3551584473673174824e-18" />
<geometry>
<mesh filename="package:///foot_part.stl"/>
</geometry>
</collision>
<inertial>
<origin xyz="-0.042296631354857040785 6.7228490693099287053e-10 0.0063626481723337742491" rpy="0 0 0"/>
<mass value="0.3309516742025366276" />
<inertia ixx="0.0010118322945958278195" ixy="-2.5339652248933098831e-12"  ixz="0.00049446274168876572577" iyy="0.001227680104999263281" iyz="7.2849212754264644669e-12" izz="0.00051045333461432855493" />
</inertial>
</link>

<link name="foot_left">
<inertial>
<origin xyz="0 0 0" rpy="0 0 0" />
<mass value="1e-9" />
<inertia ixx="0" ixy="0" ixz="0" iyy="0" iyz="0" izz="0" />
</inertial>
</link>
<joint name="foot_left_frame" type="fixed">
<origin xyz="-0.055897619600577208576 -2.7755575615628913511e-17 0.0037840702321054742185" rpy="1.3316860532596122812e-16 -1.0420837364882493681 -3.141592653589793116" />
<parent link="foot_part_2" />
<child link="foot_left" />
<axis xyz="0 0 0"/>
</joint>

<link name="toe_b_1/2_3">
<visual>
<origin xyz="-0.054171488011523785677 0.043924303555988863934 -0.11999999999999999556" rpy="1.570796326794896558 1.570796326794896558 0" />
<geometry>
<mesh filename="package:///toe_b_1_2.stl"/>
</geometry>
<material name="toe_b_1/2_material">
<color rgba="0.64705882352941179736 0.64705882352941179736 0.64705882352941179736 1.0"/>
</material>
</visual>
<collision>
<origin xyz="-0.054171488011523785677 0.043924303555988863934 -0.11999999999999999556" rpy="1.570796326794896558 1.570796326794896558 0" />
<geometry>
<mesh filename="package:///toe_b_1_2.stl"/>
</geometry>
</collision>
<inertial>
<origin xyz="-8.7343676072460452695e-19 -8.3266726846886740532e-17 -0.059975000000000042166" rpy="0 0 0"/>
<mass value="0.0060293446207695467268" />
<inertia ixx="7.2533028348992199005e-06" ixy="1.7690372137992345643e-23"  ixz="-2.6989202672349344311e-24" iyy="7.2533028348992105832e-06" iyz="-2.7640834275588023134e-23" izz="4.8234756966146912223e-08" />
</inertial>
</link>

<link name="closedloop4_A">
<inertial>
<origin xyz="0 0 0" rpy="0 0 0" />
<mass value="1e-9" />
<inertia ixx="0" ixy="0" ixz="0" iyy="0" iyz="0" izz="0" />
</inertial>
</link>
<joint name="closedloop4_A_frame" type="fixed">
<origin xyz="0 -5.5511151231257827021e-17 -0.11995000000000000107" rpy="-3.1415926535897926719 1.5256704509479419219e-15 1.57079632679489678" />
<parent link="toe_b_1/2_3" />
<child link="closedloop4_A" />
<axis xyz="0 0 0"/>
</joint>

<joint name="spherical_free_foot1_left" type="revolute">
<origin xyz="-0.0091288304490428351379 -0.014276000000000024781 -0.034653600000000062131" rpy="1.570796326794896558 0.17135811403969766764 -1.570796326794896336" />
<parent link="foot_part_2" />
<child link="toe_b_1/2_3" />
<axis xyz="0 0 1"/>
<limit effort="1" velocity="20" />
<joint_properties friction="0.0"/>
</joint>

<link name="toe_b_2/2_3">
<visual>
<origin xyz="-0.054171488011523771799 0.043924303555988919445 5.0000000000161026747e-05" rpy="1.570796326794896558 1.570796326794896558 0" />
<geometry>
<mesh filename="package:///toe_b_2_2.stl"/>
</geometry>
<material name="toe_b_2/2_material">
<color rgba="0.64705882352941179736 0.64705882352941179736 0.64705882352941179736 1.0"/>
</material>
</visual>
<collision>
<origin xyz="-0.054171488011523771799 0.043924303555988919445 5.0000000000161026747e-05" rpy="1.570796326794896558 1.570796326794896558 0" />
<geometry>
<mesh filename="package:///toe_b_2_2.stl"/>
</geometry>
</collision>
<inertial>
<origin xyz="8.8876309768919335932e-18 -2.7755575615628913511e-17 -0.059974999999999889511" rpy="0 0 0"/>
<mass value="0.0060293446207695345837" />
<inertia ixx="7.2533028348991987247e-06" ixy="-3.2683996520434794628e-22"  ixz="3.0418641254536872658e-23" iyy="7.2533028348991885603e-06" iyz="-7.1261133700312990728e-22" izz="4.8234756966146812962e-08" />
</inertial>
</link>

<link name="closedloop5_A">
<inertial>
<origin xyz="0 0 0" rpy="0 0 0" />
<mass value="1e-9" />
<inertia ixx="0" ixy="0" ixz="0" iyy="0" iyz="0" izz="0" />
</inertial>
</link>
<joint name="closedloop5_A_frame" type="fixed">
<origin xyz="2.7755575615628913511e-17 0 -0.11994999999999977902" rpy="-3.1415926535897922278 4.1186175175171797252e-15 1.570796326794896558" />
<parent link="toe_b_2/2_3" />
<child link="closedloop5_A" />
<axis xyz="0 0 0"/>
</joint>

<joint name="spherical_free_foot2_left" type="revolute">
<origin xyz="-0.009128830449042890649 0.014276000000000003964 -0.034653600000000117642" rpy="1.5707963267948950037 0.17135811403969555822 -1.5707963267948961139" />
<parent link="foot_part_2" />
<child link="toe_b_2/2_3" />
<axis xyz="0 0 1"/>
<limit effort="1" velocity="20" />
<joint_properties friction="0.0"/>
</joint>

<joint name="free_foot2_left" type="revolute">
<origin xyz="5.5511151231257827021e-17 0.0089999999999998969713 -2.7755575615628913511e-17" rpy="-1.570796326794896558 -0.0068053161721121089092 3.1415926535897917837" />
<parent link="foot_roll_2" />
<child link="foot_part_2" />
<axis xyz="0 0 1"/>
<limit effort="1" velocity="20" />
<joint_properties friction="0.0"/>
</joint>

<joint name="free_foot1_left" type="revolute">
<origin xyz="-0.32599839999999913331 -0.038657982377660826678 -1.8041124150158793782e-16" rpy="1.3712330642673959594e-15 1.4865211215266053391e-15 1.8602703927245916038" />
<parent link="tarsus_2" />
<child link="foot_roll_2" />
<axis xyz="0 0 1"/>
<limit effort="1" velocity="20" />
<joint_properties friction="0.0"/>
</joint>

<link name="crank_3">
<visual>
<origin xyz="0.088799999999999990052 0.027200000000000057465 0.02999999999999999889" rpy="-1.570796326794896558 -1.570796326794896558 0" />
<geometry>
<mesh filename="package:///crank.stl"/>
</geometry>
<material name="crank_material">
<color rgba="0.64705882352941179736 0.64705882352941179736 0.64705882352941179736 1.0"/>
</material>
</visual>
<collision>
<origin xyz="0.088799999999999990052 0.027200000000000057465 0.02999999999999999889" rpy="-1.570796326794896558 -1.570796326794896558 0" />
<geometry>
<mesh filename="package:///crank.stl"/>
</geometry>
</collision>
<inertial>
<origin xyz="-2.7735541903863111114e-17 0.01522168021389604109 -0.00095148915120264754026" rpy="0 0 0"/>
<mass value="0.0045332434126214744829" />
<inertia ixx="2.0190313503504417449e-06" ixy="-2.5123838184474501346e-26"  ixz="6.4582106659066417215e-25" iyy="3.8254267160843603214e-07" iyz="-9.1875323763545069575e-09" izz="2.3968139039834550182e-06" />
</inertial>
</link>

<link name="toe_b_2/2_4">
<visual>
<origin xyz="-0.054171488011523827311 0.043924303555988947201 5.0000000000105515596e-05" rpy="1.570796326794896558 1.570796326794896558 0" />
<geometry>
<mesh filename="package:///toe_b_2_2.stl"/>
</geometry>
<material name="toe_b_2/2_material">
<color rgba="0.64705882352941179736 0.64705882352941179736 0.64705882352941179736 1.0"/>
</material>
</visual>
<collision>
<origin xyz="-0.054171488011523827311 0.043924303555988947201 5.0000000000105515596e-05" rpy="1.570796326794896558 1.570796326794896558 0" />
<geometry>
<mesh filename="package:///toe_b_2_2.stl"/>
</geometry>
</collision>
<inertial>
<origin xyz="-4.866886746347340856e-17 0 -0.0599749999999999589" rpy="0 0 0"/>
<mass value="0.0060293446207695345837" />
<inertia ixx="7.2533028348991987247e-06" ixy="-2.7844677473794088735e-23"  ixz="9.5766761444913956e-25" iyy="7.2533028348991868662e-06" iyz="-4.4248195497136009769e-22" izz="4.8234756966146826196e-08" />
</inertial>
</link>

<link name="closedloop4_B">
<inertial>
<origin xyz="0 0 0" rpy="0 0 0" />
<mass value="1e-9" />
<inertia ixx="0" ixy="0" ixz="0" iyy="0" iyz="0" izz="0" />
</inertial>
</link>
<joint name="closedloop4_B_frame" type="fixed">
<origin xyz="-5.5511151231257827021e-17 -1.3877787807814456755e-17 -0.11994999999999994555" rpy="1.7099006292900051404e-16 -3.8344261464318977883e-16 -8.2337209764616805999e-17" />
<parent link="toe_b_2/2_4" />
<child link="closedloop4_B" />
<axis xyz="0 0 0"/>
</joint>

<joint name="spherical_free_shin2_left" type="revolute">
<origin xyz="-1.1102230246251565404e-16 0.057000000000000106137 0.0024999999999999744649" rpy="-1.57079632679489678 -0.027781755534782608813 -1.5707963267949005548" />
<parent link="crank_3" />
<child link="toe_b_2/2_4" />
<axis xyz="0 0 1"/>
<limit effort="1" velocity="20" />
<joint_properties friction="0.0"/>
</joint>

<joint name="motor_shin1_left" type="revolute">
<origin xyz="-0.088799999999999004729 -0.026113982377660716061 0.02999999999999987399" rpy="3.141592653589793116 1.1145641153506547459e-15 0.70691495434817341881" />
<parent link="tarsus_2" />
<child link="crank_3" />
<axis xyz="0 0 1"/>
<limit effort="1" velocity="20" />
<joint_properties friction="0.0"/>
</joint>

<link name="crank_4">
<visual>
<origin xyz="0.088799999999999990052 0.027200000000000057465 0.02999999999999999889" rpy="-1.570796326794896558 -1.570796326794896558 0" />
<geometry>
<mesh filename="package:///crank.stl"/>
</geometry>
<material name="crank_material">
<color rgba="0.64705882352941179736 0.64705882352941179736 0.64705882352941179736 1.0"/>
</material>
</visual>
<collision>
<origin xyz="0.088799999999999990052 0.027200000000000057465 0.02999999999999999889" rpy="-1.570796326794896558 -1.570796326794896558 0" />
<geometry>
<mesh filename="package:///crank.stl"/>
</geometry>
</collision>
<inertial>
<origin xyz="-2.7699258129924889488e-17 0.01522168021389604109 -0.00095148915120264396239" rpy="0 0 0"/>
<mass value="0.0045332434126214744829" />
<inertia ixx="2.0190313503504417449e-06" ixy="5.7671148818847308989e-26"  ixz="-6.7640118258110011563e-24" iyy="3.8254267160843603214e-07" iyz="-9.1875323763545053031e-09" izz="2.3968139039834541711e-06" />
</inertial>
</link>

<link name="toe_b_1/2_4">
<visual>
<origin xyz="-0.054171488011523771799 0.043924303555988947201 -0.12000000000000005107" rpy="1.570796326794896558 1.570796326794896558 0" />
<geometry>
<mesh filename="package:///toe_b_1_2.stl"/>
</geometry>
<material name="toe_b_1/2_material">
<color rgba="0.64705882352941179736 0.64705882352941179736 0.64705882352941179736 1.0"/>
</material>
</visual>
<collision>
<origin xyz="-0.054171488011523771799 0.043924303555988947201 -0.12000000000000005107" rpy="1.570796326794896558 1.570796326794896558 0" />
<geometry>
<mesh filename="package:///toe_b_1_2.stl"/>
</geometry>
</collision>
<inertial>
<origin xyz="1.3883676358285011272e-17 0 -0.059975000000000090739" rpy="0 0 0"/>
<mass value="0.0060293446207695467268" />
<inertia ixx="7.2533028348992199005e-06" ixy="-6.8710721279852667773e-24"  ixz="-2.6455535133587181863e-25" iyy="7.2533028348992105832e-06" iyz="-9.9559711807352741239e-24" izz="4.8234756966146925458e-08" />
</inertial>
</link>

<link name="closedloop5_B">
<inertial>
<origin xyz="0 0 0" rpy="0 0 0" />
<mass value="1e-9" />
<inertia ixx="0" ixy="0" ixz="0" iyy="0" iyz="0" izz="0" />
</inertial>
</link>
<joint name="closedloop5_B_frame" type="fixed">
<origin xyz="0 0 -0.1199500000000001676" rpy="1.2623163092897104231e-16 1.1091301729747949746e-15 -3.141592653589793116" />
<parent link="toe_b_1/2_4" />
<child link="closedloop5_B" />
<axis xyz="0 0 0"/>
</joint>

<joint name="spherical_free_shin1_left" type="revolute">
<origin xyz="0 0.057000000000000050626 0.0024999999999999952816" rpy="-1.57079632679489678 -0.027781755534719884682 1.5707963267949012209" />
<parent link="crank_4" />
<child link="toe_b_1/2_4" />
<axis xyz="0 0 1"/>
<limit effort="1" velocity="20" />
<joint_properties friction="0.0"/>
</joint>

<joint name="motor_shin2_left" type="revolute">
<origin xyz="-0.088799999999999046363 -0.026113982377660827083 -0.030000000000000102973" rpy="1.4361021807975174281e-16 -1.2580190192396560789e-15 -2.4346776992416208074" />
<parent link="tarsus_2" />
<child link="crank_4" />
<axis xyz="0 0 1"/>
<limit effort="1" velocity="20" />
<joint_properties friction="0.0"/>
</joint>

<link name="toe_a_1/2_2">
<visual>
<origin xyz="0.056794565202878913301 0.040773406646044431378 -0.19999999999999995559" rpy="1.570796326794896558 1.570796326794896558 0" />
<geometry>
<mesh filename="package:///toe_a_1_2.stl"/>
</geometry>
<material name="toe_a_1/2_material">
<color rgba="0.61568627450980395466 0.81176470588235294379 0.92941176470588238168 1.0"/>
</material>
</visual>
<collision>
<origin xyz="0.056794565202878913301 0.040773406646044431378 -0.19999999999999995559" rpy="1.570796326794896558 1.570796326794896558 0" />
<geometry>
<mesh filename="package:///toe_a_1_2.stl"/>
</geometry>
</collision>
<inertial>
<origin xyz="-9.0205537320827901399e-17 -3.4694469519536141888e-17 -0.099974999999999994427" rpy="0 0 0"/>
<mass value="0.015704036277131967758" />
<inertia ixx="5.2418767695051021575e-05" ixy="2.8362724361759434242e-23"  ixz="1.9681020995652825703e-21" iyy="5.2418767695050980918e-05" iyz="-5.1793241715970667596e-22" izz="1.9630045346413525667e-07" />
</inertial>
</link>

<link name="closedloop6_A">
<inertial>
<origin xyz="0 0 0" rpy="0 0 0" />
<mass value="1e-9" />
<inertia ixx="0" ixy="0" ixz="0" iyy="0" iyz="0" izz="0" />
</inertial>
</link>
<joint name="closedloop6_A_frame" type="fixed">
<origin xyz="-8.3266726846886740532e-17 -2.7755575615628913511e-17 -0.19995000000000001661" rpy="-3.141592653589793116 9.3065370271098693317e-16 1.1566469354901175842e-16" />
<parent link="toe_a_1/2_2" />
<child link="closedloop6_A" />
<axis xyz="0 0 0"/>
</joint>

<joint name="spherical_free_knee_left" type="revolute">
<origin xyz="0.1141899349863701868 0.036206749731294507466 0" rpy="-1.57079632679489678 0.18921460045656104954 3.1415926535897917837" />
<parent link="tarsus_2" />
<child link="toe_a_1/2_2" />
<axis xyz="0 0 1"/>
<limit effort="1" velocity="20" />
<joint_properties friction="0.0"/>
</joint>

<joint name="free_knee_left" type="revolute">
<origin xyz="0.3956748636308139444 -0.053875166733171664379 -0.024999999999999994449" rpy="2.9138174925510993941e-15 -6.5841678893026028255e-16 1.1443674094310145595" />
<parent link="shin_2" />
<child link="tarsus_2" />
<axis xyz="0 0 1"/>
<limit effort="1" velocity="20" />
<joint_properties friction="0.0"/>
</joint>

<joint name="motor_knee_left" type="revolute">
<origin xyz="0.12000000000000005107 2.6506574712925612403e-15 1.3877787807814456755e-17" rpy="-3.1415926535897917837 3.0237971669895305397e-15 -1.5552457051742101246" />
<parent link="hip_z_2" />
<child link="shin_2" />
<axis xyz="0 0 1"/>
<limit effort="1" velocity="20" />
<joint_properties friction="0.0"/>
</joint>

<joint name="motor_hip_y_left" type="revolute">
<origin xyz="-0.029117226656781597383 0 -0.047379470518249235111" rpy="1.5707963267948958919 1.305981666362586946 1.5707963267949012209" />
<parent link="hip_x_2" />
<child link="hip_z_2" />
<axis xyz="0 0 1"/>
<limit effort="1" velocity="20" />
<joint_properties friction="0.0"/>
</joint>

<link name="toe_a_2/2_2">
<visual>
<origin xyz="0.056794565202879003507 0.040773406646044452195 5.0000000000133271172e-05" rpy="1.570796326794896558 1.570796326794896558 0" />
<geometry>
<mesh filename="package:///toe_a_2_2.stl"/>
</geometry>
<material name="toe_a_2/2_material">
<color rgba="0.61568627450980395466 0.81176470588235294379 0.92941176470588238168 1.0"/>
</material>
</visual>
<collision>
<origin xyz="0.056794565202879003507 0.040773406646044452195 5.0000000000133271172e-05" rpy="1.570796326794896558 1.570796326794896558 0" />
<geometry>
<mesh filename="package:///toe_a_2_2.stl"/>
</geometry>
</collision>
<inertial>
<origin xyz="6.9402673665853180814e-18 -6.9388939039072283776e-18 -0.099974999999999938916" rpy="0 0 0"/>
<mass value="0.015704036277131950411" />
<inertia ixx="5.2418767695050845392e-05" ixy="-3.9806148737395421029e-22"  ixz="4.3912862991162133658e-24" iyy="5.241876769505083184e-05" iyz="-3.2821379185606686313e-21" izz="1.9630045346413507138e-07" />
</inertial>
</link>

<link name="closedloop6_B">
<inertial>
<origin xyz="0 0 0" rpy="0 0 0" />
<mass value="1e-9" />
<inertia ixx="0" ixy="0" ixz="0" iyy="0" iyz="0" izz="0" />
</inertial>
</link>
<joint name="closedloop6_B_frame" type="fixed">
<origin xyz="6.9388939039072283776e-18 -6.9388939039072283776e-18 -0.19994999999999990559" rpy="-6.2841240652970591823e-17 -8.3557163575224844715e-20 -7.4186862763841184082e-18" />
<parent link="toe_a_2/2_2" />
<child link="closedloop6_B" />
<axis xyz="0 0 0"/>
</joint>

<joint name="spherical_free_hip_left" type="revolute">
<origin xyz="0.030568773343218412497 1.3877787807814456755e-17 -0.054400000000000017786" rpy="1.5707963267949007768 1.5498694414327498503 3.1415926535897269467" />
<parent link="hip_x_2" />
<child link="toe_a_2/2_2" />
<axis xyz="0 0 1"/>
<limit effort="1" velocity="20" />
<joint_properties friction="0.0"/>
</joint>

<joint name="motor_hip_z_left" type="revolute">
<origin xyz="0.050000000000000009714 4.1633363423443370266e-17 -0.035200000000000009059" rpy="1.570796326794896558 0.013078473573069846966 -1.5707963267948974462" />
<parent link="hip_y_2" />
<child link="hip_x_2" />
<axis xyz="0 0 1"/>
<limit effort="1" velocity="20" />
<joint_properties friction="0.0"/>
</joint>

<joint name="motor_hip_x_left" type="revolute">
<origin xyz="-0.02999999999999999889 0.072800000000000017475 0.059867854479678822566" rpy="1.5707963267948932273 1.5524862860405099774 1.5707963267948932273" />
<parent link="torso" />
<child link="hip_y_2" />
<axis xyz="0 0 1"/>
<limit effort="1" velocity="20" />
<joint_properties friction="0.0"/>
</joint>


</robot>
