<robot name="onshape">
<link name="torso">
<visual>
<origin xyz="-3.6658488180179105565e-18 2.0816681711721685133e-17 0.059867854479678836443" rpy="-6.1232339957367660359e-17 -0 1.570796326794896558" />
<geometry>
<mesh filename="package:///torso.stl"/>
</geometry>
<material name="torso_material">
<color rgba="0.61568627450980395466 0.81176470588235294379 0.92941176470588238168 1.0"/>
</material>
</visual>
<collision>
<origin xyz="-3.6658488180179105565e-18 2.0816681711721685133e-17 0.059867854479678836443" rpy="-6.1232339957367660359e-17 -0 1.570796326794896558" />
<geometry>
<mesh filename="package:///torso.stl"/>
</geometry>
</collision>
<inertial>
<origin xyz="-4.323244991970371108e-18 2.0266117070815889138e-17 0.070603948746371325562" rpy="0 0 0"/>
<mass value="3.2452322404414171153" />
<inertia ixx="0.012163262961236534151" ixy="0"  ixz="1.2921033060725054663e-19" iyy="0.0040573041803173628961" iyz="0" izz="0.010053098125184021031" />
</inertial>
</link>

<link name="hip">
<inertial>
<origin xyz="0 0 0" rpy="0 0 0" />
<mass value="1e-9" />
<inertia ixx="0" ixy="0" ixz="0" iyy="0" iyz="0" izz="0" />
</inertial>
</link>
<joint name="hip_frame" type="fixed">
<origin xyz="2.4027501270446886779e-19 -1.626303258728255688e-19 0.0024999999999999996184" rpy="2.8421709430404007435e-14 3.0814879110196404233e-31 0" />
<parent link="torso" />
<child link="hip" />
<axis xyz="0 0 0"/>
</joint>

<link name="hip_y">
<visual>
<origin xyz="0.10706579297345658608 -1.3877787807814456755e-17 -0.035199999999999995182" rpy="-1.570796326794896558 -6.5454206199920959897e-33 3.7588477667789017068e-20" />
<geometry>
<mesh filename="package:///hip_y.stl"/>
</geometry>
<material name="hip_y_material">
<color rgba="0.2313725490196078538 0.38039215686274507888 0.7058823529411765163 1.0"/>
</material>
</visual>
<collision>
<origin xyz="0.10706579297345658608 -1.3877787807814456755e-17 -0.035199999999999995182" rpy="-1.570796326794896558 -6.5454206199920959897e-33 3.7588477667789017068e-20" />
<geometry>
<mesh filename="package:///hip_y.stl"/>
</geometry>
</collision>
<inertial>
<origin xyz="0.015578666288194957176 -1.2357431138658555441e-07 -0.034149457045324432825" rpy="0 0 0"/>
<mass value="1.2895238899898622265" />
<inertia ixx="0.00089621011138626526914" ixy="-1.7957438648417713051e-09"  ixz="3.2112420914059134399e-05" iyy="0.0010420724953831763272" iyz="3.0492496474583062947e-09" izz="0.0010213484696825509291" />
</inertial>
</link>

<link name="hip_x">
<visual>
<origin xyz="-1.3877787807814456755e-17 1.3877787807814456755e-17 -0.054400000000000010847" rpy="1.570796326794896558 1.570796326794896558 0" />
<geometry>
<mesh filename="package:///hip_x.stl"/>
</geometry>
<material name="hip_x_material">
<color rgba="0.64705882352941179736 0.64705882352941179736 0.64705882352941179736 1.0"/>
</material>
</visual>
<collision>
<origin xyz="-1.3877787807814456755e-17 1.3877787807814456755e-17 -0.054400000000000010847" rpy="1.570796326794896558 1.570796326794896558 0" />
<geometry>
<mesh filename="package:///hip_x.stl"/>
</geometry>
</collision>
<inertial>
<origin xyz="0.0023378176535869920998 1.3013938294015064237e-17 -0.04521675346357507258" rpy="0 0 0"/>
<mass value="1.4197410037164885921" />
<inertia ixx="0.0014949229305128526255" ixy="3.5008688583593532813e-23"  ixz="-1.2476184392984378707e-05" iyy="0.0013017541081209293291" iyz="-1.0860343342035171147e-26" izz="0.00094724669336309925277" />
</inertial>
</link>

<link name="hip_z">
<visual>
<origin xyz="-0.11999999999999999556 -1.3877787807814456755e-17 -0.070000000000000020539" rpy="-1.570796326794896558 1.6980416355138780894e-20 1.9267181545377181319e-17" />
<geometry>
<mesh filename="package:///hip_z.stl"/>
</geometry>
<material name="hip_z_material">
<color rgba="0.61568627450980395466 0.81176470588235294379 0.92941176470588238168 1.0"/>
</material>
</visual>
<collision>
<origin xyz="-0.11999999999999999556 -1.3877787807814456755e-17 -0.070000000000000020539" rpy="-1.570796326794896558 1.6980416355138780894e-20 1.9267181545377181319e-17" />
<geometry>
<mesh filename="package:///hip_z.stl"/>
</geometry>
</collision>
<inertial>
<origin xyz="-0.059999999999999990841 -1.2284845364228189375e-17 -0.022000000000000012601" rpy="0 0 0"/>
<mass value="3.8932756153047387571" />
<inertia ixx="0.0040205863361596526698" ixy="4.5548731072925747994e-19"  ixz="1.4051778221314791716e-22" iyy="0.014779167671256709243" iyz="7.6079049399579064712e-22" izz="0.017543523742211367122" />
</inertial>
</link>

<link name="shin">
<visual>
<origin xyz="0 2.0816681711721685133e-17 -0.024999999999999994449" rpy="-1.570796326794896558 -1.5401348546694420968e-20 1.4023640727766785457e-17" />
<geometry>
<mesh filename="package:///shin.stl"/>
</geometry>
<material name="shin_material">
<color rgba="0.61568627450980395466 0.81176470588235294379 0.92941176470588238168 1.0"/>
</material>
</visual>
<collision>
<origin xyz="0 2.0816681711721685133e-17 -0.024999999999999994449" rpy="-1.570796326794896558 -1.5401348546694420968e-20 1.4023640727766785457e-17" />
<geometry>
<mesh filename="package:///shin.stl"/>
</geometry>
</collision>
<inertial>
<origin xyz="0.086542930154570346657 0.024349627108824753452 -0.025000000824260203147" rpy="0 0 0"/>
<mass value="0.5557814093331634453" />
<inertia ixx="0.00046644066811272669572" ixy="-0.00088329043391741524516"  ixz="6.3639812417202403644e-13" iyy="0.0090559095871162471197" iyz="1.1189385759855533694e-11" izz="0.0093490826129847721948" />
</inertial>
</link>

<link name="tarsus">
<visual>
<origin xyz="-0.11600000000000038058 -0.11491398237765948487 -1.3877787807814456755e-16" rpy="-3.141592653589793116 1.570796326794896558 0" />
<geometry>
<mesh filename="package:///actuator_molet.stl"/>
</geometry>
<material name="actuator_molet_material">
<color rgba="0.91764705882352937127 0.91764705882352937127 0.91764705882352937127 1.0"/>
</material>
</visual>
<collision>
<origin xyz="-0.11600000000000038058 -0.11491398237765948487 -1.3877787807814456755e-16" rpy="-3.141592653589793116 1.570796326794896558 0" />
<geometry>
<mesh filename="package:///actuator_molet.stl"/>
</geometry>
</collision>
<visual>
<origin xyz="-5.5511151231257827021e-17 0.001086017622341506339 -2.7755575615628913511e-17" rpy="-1.570796326794896558 -1.570796326794896558 0" />
<geometry>
<mesh filename="package:///tarsus.stl"/>
</geometry>
<material name="tarsus_material">
<color rgba="0.61568627450980395466 0.81176470588235294379 0.92941176470588238168 1.0"/>
</material>
</visual>
<collision>
<origin xyz="-5.5511151231257827021e-17 0.001086017622341506339 -2.7755575615628913511e-17" rpy="-1.570796326794896558 -1.570796326794896558 0" />
<geometry>
<mesh filename="package:///tarsus.stl"/>
</geometry>
</collision>
<inertial>
<origin xyz="-0.083086291902174813639 -0.020033778925019798955 2.8736095490408896085e-08" rpy="0 0 0"/>
<mass value="0.7428461942208621771" />
<inertia ixx="0.00039818835112512181986" ixy="-0.00054213231673499919644"  ixz="-5.263764431266323473e-10" iyy="0.0079851917842740961773" iyz="1.2685116125843502888e-10" izz="0.0079848716361182476425" />
</inertial>
</link>

<link name="foot_roll">
<visual>
<origin xyz="0.32599839999999991047 0.039744000000000001549 -0.013999999999999887534" rpy="-1.570796326794896558 -1.570796326794896336 0" />
<geometry>
<mesh filename="package:///foot_roll.stl"/>
</geometry>
<material name="foot_roll_material">
<color rgba="0.2313725490196078538 0.38039215686274507888 0.7058823529411765163 1.0"/>
</material>
</visual>
<collision>
<origin xyz="0.32599839999999991047 0.039744000000000001549 -0.013999999999999887534" rpy="-1.570796326794896558 -1.570796326794896336 0" />
<geometry>
<mesh filename="package:///foot_roll.stl"/>
</geometry>
</collision>
<inertial>
<origin xyz="-2.1851523976701564558e-08 -0.0014449033387292503638 -0.013999993222565322581" rpy="0 0 0"/>
<mass value="0.0027067106871796996204" />
<inertia ixx="1.8232396912107804468e-07" ixy="1.2456494872728746573e-13"  ixz="-3.0177862000949891884e-13" iyy="1.1958745424438046988e-07" iyz="4.5807687216843501642e-14" izz="1.0944659228682654788e-07" />
</inertial>
</link>

<link name="foot_part">
<visual>
<origin xyz="-0.0011288304490429945659 0 0.0090800000000000324896" rpy="1.570796326794896558 3.1319183015339479964e-17 -1.259943990830869585e-20" />
<geometry>
<mesh filename="package:///foot_part.stl"/>
</geometry>
<material name="foot_part_material">
<color rgba="0.61568627450980395466 0.81176470588235294379 0.92941176470588238168 1.0"/>
</material>
</visual>
<collision>
<origin xyz="-0.0011288304490429945659 0 0.0090800000000000324896" rpy="1.570796326794896558 3.1319183015339479964e-17 -1.259943990830869585e-20" />
<geometry>
<mesh filename="package:///foot_part.stl"/>
</geometry>
</collision>
<inertial>
<origin xyz="-0.042296631354857151808 -6.722849202322864562e-10 0.011797351827666236954" rpy="0 0 0"/>
<mass value="0.33095167420253657209" />
<inertia ixx="0.0010118322945958278195" ixy="2.5339652312776873563e-12"  ixz="-0.00049446274168876583419" iyy="0.001227680104999263281" iyz="7.2849212788359543178e-12" izz="0.00051045333461432888019" />
</inertial>
</link>

<link name="foot">
<inertial>
<origin xyz="0 0 0" rpy="0 0 0" />
<mass value="1e-9" />
<inertia ixx="0" ixy="0" ixz="0" iyy="0" iyz="0" izz="0" />
</inertial>
</link>
<joint name="foot_frame" type="fixed">
<origin xyz="-0.055897619600577264087 1.3877787807814456755e-17 0.014375929767894479738" rpy="3.141592653589793116 1.0420837364882529208 3.141592653589793116" />
<parent link="foot_part" />
<child link="foot" />
<axis xyz="0 0 0"/>
</joint>

<link name="toe_b_1/2">
<visual>
<origin xyz="-0.054171488011523785677 -0.043924303555988974956 4.9999999999883470991e-05" rpy="-1.570796326794896558 -1.570796326794896558 0" />
<geometry>
<mesh filename="package:///toe_b_1_2.stl"/>
</geometry>
<material name="toe_b_1/2_material">
<color rgba="0.64705882352941179736 0.64705882352941179736 0.64705882352941179736 1.0"/>
</material>
</visual>
<collision>
<origin xyz="-0.054171488011523785677 -0.043924303555988974956 4.9999999999883470991e-05" rpy="-1.570796326794896558 -1.570796326794896558 0" />
<geometry>
<mesh filename="package:///toe_b_1_2.stl"/>
</geometry>
</collision>
<inertial>
<origin xyz="-1.7101905355203223078e-21 -3.4694469519536141888e-17 -0.059975000000000076861" rpy="0 0 0"/>
<mass value="0.0060293446207695467268" />
<inertia ixx="7.2533028348992190535e-06" ixy="-1.2379820933378236992e-25"  ixz="-2.3897670158028944589e-26" iyy="7.2533028348992097361e-06" iyz="-9.8979508385929148126e-23" izz="4.8234756966146925458e-08" />
</inertial>
</link>

<link name="closedloop3_B">
<inertial>
<origin xyz="0 0 0" rpy="0 0 0" />
<mass value="1e-9" />
<inertia ixx="0" ixy="0" ixz="0" iyy="0" iyz="0" izz="0" />
</inertial>
</link>
<joint name="closedloop3_B_frame" type="fixed">
<origin xyz="0 -5.5511151231257827021e-17 -0.11995000000000000107" rpy="-3.141592653589793116 1.4082337349770990484e-17 1.570796326794896558" />
<parent link="toe_b_1/2" />
<child link="closedloop3_B" />
<axis xyz="0 0 0"/>
</joint>

<joint name="spherical_free_foot1" type="revolute">
<origin xyz="-0.0091288304490427796267 -0.014275999999999955392 0.052813600000000016088" rpy="1.570796326794896558 0.00015724417883685367909 -1.5707963267948981123" />
<parent link="foot_part" />
<child link="toe_b_1/2" />
<axis xyz="0 0 1"/>
<limit effort="1" velocity="20" />
<joint_properties friction="0.0"/>
</joint>

<link name="toe_b_1/2_2">
<visual>
<origin xyz="-0.054171488011523792616 0.043924303555988919445 -0.12000000000000010658" rpy="1.570796326794896558 1.570796326794896558 0" />
<geometry>
<mesh filename="package:///toe_b_1_2.stl"/>
</geometry>
<material name="toe_b_1/2_material">
<color rgba="0.64705882352941179736 0.64705882352941179736 0.64705882352941179736 1.0"/>
</material>
</visual>
<collision>
<origin xyz="-0.054171488011523792616 0.043924303555988919445 -0.12000000000000010658" rpy="1.570796326794896558 1.570796326794896558 0" />
<geometry>
<mesh filename="package:///toe_b_1_2.stl"/>
</geometry>
</collision>
<inertial>
<origin xyz="-6.9390178172638243937e-18 -2.0816681711721685133e-17 -0.059975000000000153189" rpy="0 0 0"/>
<mass value="0.0060293446207695467268" />
<inertia ixx="7.2533028348992190535e-06" ixy="-5.1506015670697940421e-26"  ixz="5.662006217723576991e-26" iyy="7.2533028348992080421e-06" iyz="6.7101939875660202138e-22" izz="4.8234756966146925458e-08" />
</inertial>
</link>

<link name="closedloop2_B">
<inertial>
<origin xyz="0 0 0" rpy="0 0 0" />
<mass value="1e-9" />
<inertia ixx="0" ixy="0" ixz="0" iyy="0" iyz="0" izz="0" />
</inertial>
</link>
<joint name="closedloop2_B_frame" type="fixed">
<origin xyz="-4.1633363423443370266e-17 5.5511151231257827021e-17 -0.11995000000000022311" rpy="3.141592653589793116 -9.2337153002951306109e-17 1.570796326794896558" />
<parent link="toe_b_1/2_2" />
<child link="closedloop2_B" />
<axis xyz="0 0 0"/>
</joint>

<joint name="spherical_free_foot2" type="revolute">
<origin xyz="-0.0091288304490430016713 0.014276000000000024781 0.052813600000000016088" rpy="1.57079632679489678 0.00015724417883817773389 -1.570796326794896558" />
<parent link="foot_part" />
<child link="toe_b_1/2_2" />
<axis xyz="0 0 1"/>
<limit effort="1" velocity="20" />
<joint_properties friction="0.0"/>
</joint>

<joint name="free_foot2" type="revolute">
<origin xyz="1.1102230246251565404e-16 0.0089999999999999524825 -0.013999999999999998557" rpy="-1.570796326794896558 0.00022603698986956599648 -3.1415926535897913396" />
<parent link="foot_roll" />
<child link="foot_part" />
<axis xyz="0 0 1"/>
<limit effort="1" velocity="20" />
<joint_properties friction="0.0"/>
</joint>

<joint name="free_foot1" type="revolute">
<origin xyz="-0.325998400000000077 -0.038657982377658606232 -0.014000000000000067946" rpy="3.141592653589793116 -5.0097838604174264603e-17 -2.8759599356941945025" />
<parent link="tarsus" />
<child link="foot_roll" />
<axis xyz="0 0 1"/>
<limit effort="1" velocity="20" />
<joint_properties friction="0.0"/>
</joint>

<link name="crank">
<visual>
<origin xyz="0.08879999999999987903 0.027199999999999890932 0.029999999999999991951" rpy="-1.570796326794896558 -1.570796326794896558 0" />
<geometry>
<mesh filename="package:///crank.stl"/>
</geometry>
<material name="crank_material">
<color rgba="0.64705882352941179736 0.64705882352941179736 0.64705882352941179736 1.0"/>
</material>
</visual>
<collision>
<origin xyz="0.08879999999999987903 0.027199999999999890932 0.029999999999999991951" rpy="-1.570796326794896558 -1.570796326794896558 0" />
<geometry>
<mesh filename="package:///crank.stl"/>
</geometry>
</collision>
<inertial>
<origin xyz="-1.6579199963324349087e-16 0.015221680213895876291 -0.00095148915120265090128" rpy="0 0 0"/>
<mass value="0.0045332434126214744829" />
<inertia ixx="2.0190313503504434389e-06" ixy="-3.530224297847571271e-23"  ixz="4.7697602424643704391e-25" iyy="3.8254267160843592626e-07" iyz="-9.1875323763544887595e-09" izz="2.3968139039834541711e-06" />
</inertial>
</link>

<link name="toe_b_2/2">
<visual>
<origin xyz="-0.054171488011523716288 -0.043924303555988863934 -0.11999999999999999556" rpy="-1.570796326794896558 -1.570796326794896558 0" />
<geometry>
<mesh filename="package:///toe_b_2_2.stl"/>
</geometry>
<material name="toe_b_2/2_material">
<color rgba="0.64705882352941179736 0.64705882352941179736 0.64705882352941179736 1.0"/>
</material>
</visual>
<collision>
<origin xyz="-0.054171488011523716288 -0.043924303555988863934 -0.11999999999999999556" rpy="-1.570796326794896558 -1.570796326794896558 0" />
<geometry>
<mesh filename="package:///toe_b_2_2.stl"/>
</geometry>
</collision>
<inertial>
<origin xyz="5.2637828556623457022e-17 7.632783294297952448e-17 -0.059974999999999938083" rpy="0 0 0"/>
<mass value="0.0060293446207695345837" />
<inertia ixx="7.2533028348991970306e-06" ixy="-3.1186271380679218486e-22"  ixz="-2.3680850255565251807e-22" iyy="7.2533028348991868662e-06" iyz="-2.0741896971216883081e-22" izz="4.8234756966146826196e-08" />
</inertial>
</link>

<link name="closedloop2_A">
<inertial>
<origin xyz="0 0 0" rpy="0 0 0" />
<mass value="1e-9" />
<inertia ixx="0" ixy="0" ixz="0" iyy="0" iyz="0" izz="0" />
</inertial>
</link>
<joint name="closedloop2_A_frame" type="fixed">
<origin xyz="5.5511151231257827021e-17 1.1102230246251565404e-16 -0.11994999999999994555" rpy="2.1842893656284317977e-16 3.267742848578937711e-17 2.8391108377426899969e-17" />
<parent link="toe_b_2/2" />
<child link="closedloop2_A" />
<axis xyz="0 0 0"/>
</joint>

<joint name="spherical_free_shin2" type="revolute">
<origin xyz="-1.6653345369377348106e-16 0.056999999999999828582 0.0025000000000000091593" rpy="-1.570796326794896558 -1.0576818073076525994 -1.5707963267948981123" />
<parent link="crank" />
<child link="toe_b_2/2" />
<axis xyz="0 0 1"/>
<limit effort="1" velocity="20" />
<joint_properties friction="0.0"/>
</joint>

<joint name="motor_shin1" type="revolute">
<origin xyz="-0.088800000000000045564 -0.026113982377658828682 0.029999999999999943379" rpy="-3.141592653589793116 -2.1102062293755973316e-16 0.086002635339051156094" />
<parent link="tarsus" />
<child link="crank" />
<axis xyz="0 0 1"/>
<limit effort="1" velocity="20" />
<joint_properties friction="0.0"/>
</joint>

<link name="crank_2">
<visual>
<origin xyz="0.088800000000000045564 0.027200000000000001954 0.02999999999999999889" rpy="-1.570796326794896558 -1.570796326794896558 0" />
<geometry>
<mesh filename="package:///crank.stl"/>
</geometry>
<material name="crank_material">
<color rgba="0.64705882352941179736 0.64705882352941179736 0.64705882352941179736 1.0"/>
</material>
</visual>
<collision>
<origin xyz="0.088800000000000045564 0.027200000000000001954 0.02999999999999999889" rpy="-1.570796326794896558 -1.570796326794896558 0" />
<geometry>
<mesh filename="package:///crank.stl"/>
</geometry>
</collision>
<inertial>
<origin xyz="1.4757150507359764712e-17 0.015221680213895987313 -0.00095148915120264396239" rpy="0 0 0"/>
<mass value="0.0045332434126214744829" />
<inertia ixx="2.0190313503504425919e-06" ixy="-2.3751158403181338156e-23"  ixz="6.0841290431599026718e-25" iyy="3.8254267160843603214e-07" iyz="-9.1875323763544904139e-09" izz="2.3968139039834541711e-06" />
</inertial>
</link>

<link name="toe_b_2/2_2">
<visual>
<origin xyz="-0.054171488011523799555 -0.043924303555988974956 -0.12000000000000005107" rpy="-1.570796326794896558 -1.570796326794896558 0" />
<geometry>
<mesh filename="package:///toe_b_2_2.stl"/>
</geometry>
<material name="toe_b_2/2_material">
<color rgba="0.64705882352941179736 0.64705882352941179736 0.64705882352941179736 1.0"/>
</material>
</visual>
<collision>
<origin xyz="-0.054171488011523799555 -0.043924303555988974956 -0.12000000000000005107" rpy="-1.570796326794896558 -1.570796326794896558 0" />
<geometry>
<mesh filename="package:///toe_b_2_2.stl"/>
</geometry>
</collision>
<inertial>
<origin xyz="-2.1048572749567911888e-17 -3.4694469519536141888e-17 -0.059974999999999986655" rpy="0 0 0"/>
<mass value="0.0060293446207695345837" />
<inertia ixx="7.2533028348991987247e-06" ixy="1.3444824906404654566e-22"  ixz="-3.9038596153756672311e-24" iyy="7.2533028348991868662e-06" iyz="2.4697414896185934813e-22" izz="4.8234756966146826196e-08" />
</inertial>
</link>

<link name="closedloop3_A">
<inertial>
<origin xyz="0 0 0" rpy="0 0 0" />
<mass value="1e-9" />
<inertia ixx="0" ixy="0" ixz="0" iyy="0" iyz="0" izz="0" />
</inertial>
</link>
<joint name="closedloop3_A_frame" type="fixed">
<origin xyz="0 -1.1102230246251565404e-16 -0.11994999999999994555" rpy="4.3153759858238539441e-16 5.5326454623166440589e-19 2.690743573481835155e-17" />
<parent link="toe_b_2/2_2" />
<child link="closedloop3_A" />
<axis xyz="0 0 0"/>
</joint>

<joint name="spherical_free_shin1" type="revolute">
<origin xyz="5.5511151231257827021e-17 0.057000000000000161648 0.0025000000000000160982" rpy="1.5707963267949196506 -1.477603911516246038 -1.5707963267949121011" />
<parent link="crank_2" />
<child link="toe_b_2/2_2" />
<axis xyz="0 0 1"/>
<limit effort="1" velocity="20" />
<joint_properties friction="0.0"/>
</joint>

<joint name="motor_shin2" type="revolute">
<origin xyz="-0.088799999999999990052 -0.026113982377658495615 -0.030000000000000026645" rpy="6.3640585351423805025e-17 -1.0365439080542638912e-15 -3.0644073228173649426" />
<parent link="tarsus" />
<child link="crank_2" />
<axis xyz="0 0 1"/>
<limit effort="1" velocity="20" />
<joint_properties friction="0.0"/>
</joint>

<link name="toe_a_1/2">
<visual>
<origin xyz="0.056794565202878968813 -0.04077340664604448689 4.9999999999883470991e-05" rpy="-1.570796326794896558 -1.570796326794896558 0" />
<geometry>
<mesh filename="package:///toe_a_1_2.stl"/>
</geometry>
<material name="toe_a_1/2_material">
<color rgba="0.61568627450980395466 0.81176470588235294379 0.92941176470588238168 1.0"/>
</material>
</visual>
<collision>
<origin xyz="0.056794565202878968813 -0.04077340664604448689 4.9999999999883470991e-05" rpy="-1.570796326794896558 -1.570796326794896558 0" />
<geometry>
<mesh filename="package:///toe_a_1_2.stl"/>
</geometry>
</collision>
<inertial>
<origin xyz="-3.3665459423169792534e-17 -2.0816681711721685133e-17 -0.099975000000000077693" rpy="0 0 0"/>
<mass value="0.015704036277131967758" />
<inertia ixx="5.241876769505099447e-05" ixy="1.0586120658653149915e-21"  ixz="-1.4156122207035899022e-23" iyy="5.2418767695050980918e-05" iyz="-9.5266325297039447413e-22" izz="1.9630045346413525667e-07" />
</inertial>
</link>

<link name="closedloop1_B">
<inertial>
<origin xyz="0 0 0" rpy="0 0 0" />
<mass value="1e-9" />
<inertia ixx="0" ixy="0" ixz="0" iyy="0" iyz="0" izz="0" />
</inertial>
</link>
<joint name="closedloop1_B_frame" type="fixed">
<origin xyz="-1.3877787807814456755e-17 -4.1633363423443370266e-17 -0.19995000000000007212" rpy="-3.141592653589793116 -1.7835368752394309275e-19 -3.141592653589793116" />
<parent link="toe_a_1/2" />
<child link="closedloop1_B" />
<axis xyz="0 0 0"/>
</joint>

<joint name="spherical_free_knee" type="revolute">
<origin xyz="0.11418993498637028394 0.036206749731294674 0" rpy="-1.57079632679489678 -1.273128742691381099 -3.141592653589793116" />
<parent link="tarsus" />
<child link="toe_a_1/2" />
<axis xyz="0 0 1"/>
<limit effort="1" velocity="20" />
<joint_properties friction="0.0"/>
</joint>

<joint name="free_knee" type="revolute">
<origin xyz="0.39567486363081449952 0.053875166733173364408 -0.024999999999999911182" rpy="-3.141592653589793116 1.7396919582285806086e-15 -1.6905869617439772679" />
<parent link="shin" />
<child link="tarsus" />
<axis xyz="0 0 1"/>
<limit effort="1" velocity="20" />
<joint_properties friction="0.0"/>
</joint>

<joint name="motor_knee" type="revolute">
<origin xyz="-0.12000000000000010658 -5.5511151231257827021e-17 -2.7755575615628913511e-17" rpy="3.1415926535897926719 6.6787990227716521976e-17 -2.6827965911004429955" />
<parent link="hip_z" />
<child link="shin" />
<axis xyz="0 0 1"/>
<limit effort="1" velocity="20" />
<joint_properties friction="0.0"/>
</joint>

<joint name="motor_hip_y" type="revolute">
<origin xyz="-0.026000000000000023093 5.5511151231257827021e-17 -0.05440000000000011493" rpy="-1.5707963267948976682 -1.1932852897669119496 -1.5707963267948954478" />
<parent link="hip_x" />
<child link="hip_z" />
<axis xyz="0 0 1"/>
<limit effort="1" velocity="20" />
<joint_properties friction="0.0"/>
</joint>

<link name="toe_a_2/2">
<visual>
<origin xyz="0.056794565202878996568 -0.040773406646044466073 -0.2000000000000000111" rpy="-1.570796326794896558 -1.570796326794896558 0" />
<geometry>
<mesh filename="package:///toe_a_2_2.stl"/>
</geometry>
<material name="toe_a_2/2_material">
<color rgba="0.61568627450980395466 0.81176470588235294379 0.92941176470588238168 1.0"/>
</material>
</visual>
<collision>
<origin xyz="0.056794565202878996568 -0.040773406646044466073 -0.2000000000000000111" rpy="-1.570796326794896558 -1.570796326794896558 0" />
<geometry>
<mesh filename="package:///toe_a_2_2.stl"/>
</geometry>
</collision>
<inertial>
<origin xyz="-2.3209637486815574298e-25 -1.3877787807814456755e-17 -0.099974999999999952793" rpy="0 0 0"/>
<mass value="0.015704036277131950411" />
<inertia ixx="5.2418767695050838616e-05" ixy="7.1417327461810878514e-32"  ixz="2.5346569691633947778e-30" iyy="5.2418767695050825063e-05" iyz="1.4009035999773451489e-24" izz="1.9630045346413501844e-07" />
</inertial>
</link>

<link name="closedloop1_A">
<inertial>
<origin xyz="0 0 0" rpy="0 0 0" />
<mass value="1e-9" />
<inertia ixx="0" ixy="0" ixz="0" iyy="0" iyz="0" izz="0" />
</inertial>
</link>
<joint name="closedloop1_A_frame" type="fixed">
<origin xyz="8.3266726846886740532e-17 -2.0816681711721685133e-17 -0.19994999999999985008" rpy="-3.6730477635741736581e-16 2.9460981308595112864e-21 7.5096808214324432057e-23" />
<parent link="toe_a_2/2" />
<child link="closedloop1_A" />
<axis xyz="0 0 0"/>
</joint>

<joint name="spherical_free_hip" type="revolute">
<origin xyz="0.033685999999999945154 5.5511151231257827021e-17 -0.054400000000000010847" rpy="1.570796326794896558 -1.5706708750796685159 6.9310404253907578621e-11" />
<parent link="hip_x" />
<child link="toe_a_2/2" />
<axis xyz="0 0 1"/>
<limit effort="1" velocity="20" />
<joint_properties friction="0.0"/>
</joint>

<joint name="motor_hip_z" type="revolute">
<origin xyz="0.052665792973456582171 0 -0.035199999999999995182" rpy="-1.570796326794896558 -0.000210470252546097027 1.570796326794896336" />
<parent link="hip_y" />
<child link="hip_x" />
<axis xyz="0 0 1"/>
<limit effort="1" velocity="20" />
<joint_properties friction="0.0"/>
</joint>

<joint name="motor_hip_x" type="revolute">
<origin xyz="-0.02999999999999999889 -0.072799999999999975842 0.059867854479678822566" rpy="1.570796326794408504 1.5706708750796680718 1.570796326794408504" />
<parent link="torso" />
<child link="hip_y" />
<axis xyz="0 0 1"/>
<limit effort="1" velocity="20" />
<joint_properties friction="0.0"/>
</joint>

<link name="hip_y_2">
<visual>
<origin xyz="0.10440000000000002056 0 -0.035199999999999995182" rpy="-1.570796326794896558 -0 0" />
<geometry>
<mesh filename="package:///hip_y.stl"/>
</geometry>
<material name="hip_y_material">
<color rgba="0.2313725490196078538 0.38039215686274507888 0.7058823529411765163 1.0"/>
</material>
</visual>
<collision>
<origin xyz="0.10440000000000002056 0 -0.035199999999999995182" rpy="-1.570796326794896558 -0 0" />
<geometry>
<mesh filename="package:///hip_y.stl"/>
</geometry>
</collision>
<inertial>
<origin xyz="0.012912873314738379515 -1.2357431137270429906e-07 -0.034149457045324432825" rpy="0 0 0"/>
<mass value="1.2895238899898622265" />
<inertia ixx="0.00089621011138626548598" ixy="-1.7957438648418447173e-09"  ixz="3.2112420914059141175e-05" iyy="0.0010420724953831758935" iyz="3.0492496474583042268e-09" izz="0.0010213484696825509291" />
</inertial>
</link>

<link name="hip_x_2">
<visual>
<origin xyz="-0.0031172266567815881677 0 -0.054400000000000003908" rpy="1.570796326794896558 1.570796326794896558 0" />
<geometry>
<mesh filename="package:///hip_x.stl"/>
</geometry>
<material name="hip_x_material">
<color rgba="0.64705882352941179736 0.64705882352941179736 0.64705882352941179736 1.0"/>
</material>
</visual>
<collision>
<origin xyz="-0.0031172266567815881677 0 -0.054400000000000003908" rpy="1.570796326794896558 1.570796326794896558 0" />
<geometry>
<mesh filename="package:///hip_x.stl"/>
</geometry>
</collision>
<inertial>
<origin xyz="-0.00077940900319458219017 -8.6385233893850053867e-19 -0.04521675346357507258" rpy="0 0 0"/>
<mass value="1.4197410037164885921" />
<inertia ixx="0.0014949229305128526255" ixy="0"  ixz="-1.2476184392984375319e-05" iyy="0.0013017541081209297628" iyz="0" izz="0.00094724669336309881909" />
</inertial>
</link>

<link name="hip_z_2">
<visual>
<origin xyz="0 0 -0.070000000000000006661" rpy="-1.570796326794896558 -0 -3.6217972674632358542e-17" />
<geometry>
<mesh filename="package:///hip_z.stl"/>
</geometry>
<material name="hip_z_material">
<color rgba="0.61568627450980395466 0.81176470588235294379 0.92941176470588238168 1.0"/>
</material>
</visual>
<collision>
<origin xyz="0 0 -0.070000000000000006661" rpy="-1.570796326794896558 -0 -3.6217972674632358542e-17" />
<geometry>
<mesh filename="package:///hip_z.stl"/>
</geometry>
</collision>
<inertial>
<origin xyz="0.059999999999999990841 -1.7372056755744261817e-18 -0.021999999999999998723" rpy="0 0 0"/>
<mass value="3.8932756153047387571" />
<inertia ixx="0.0040205863361596509351" ixy="5.1429225604894214473e-19"  ixz="0" iyy="0.014779167671256709243" iyz="0" izz="0.017543523742211367122" />
</inertial>
</link>

<link name="shin_2">
<visual>
<origin xyz="0 -6.9388939039072283776e-18 -0.024999999999999994449" rpy="1.570796326794896558 -0 6.0456418469048474632e-17" />
<geometry>
<mesh filename="package:///shin.stl"/>
</geometry>
<material name="shin_material">
<color rgba="0.61568627450980395466 0.81176470588235294379 0.92941176470588238168 1.0"/>
</material>
</visual>
<collision>
<origin xyz="0 -6.9388939039072283776e-18 -0.024999999999999994449" rpy="1.570796326794896558 -0 6.0456418469048474632e-17" />
<geometry>
<mesh filename="package:///shin.stl"/>
</geometry>
</collision>
<inertial>
<origin xyz="0.086542930154570346657 -0.024349627108824732635 -0.024999999175739785751" rpy="0 0 0"/>
<mass value="0.5557814093331634453" />
<inertia ixx="0.00046644066811272680414" ixy="0.00088329043391741578727"  ixz="-6.3639812423557366122e-13" iyy="0.0090559095871162471197" iyz="1.1189385759788383431e-11" izz="0.0093490826129847756643" />
</inertial>
</link>

<link name="tarsus_2">
<visual>
<origin xyz="1.3877787807814456755e-17 0.0010860176223413953167 0" rpy="-1.570796326794896558 -1.570796326794896558 0" />
<geometry>
<mesh filename="package:///tarsus.stl"/>
</geometry>
<material name="tarsus_material">
<color rgba="0.61568627450980395466 0.81176470588235294379 0.92941176470588238168 1.0"/>
</material>
</visual>
<collision>
<origin xyz="1.3877787807814456755e-17 0.0010860176223413953167 0" rpy="-1.570796326794896558 -1.570796326794896558 0" />
<geometry>
<mesh filename="package:///tarsus.stl"/>
</geometry>
</collision>
<visual>
<origin xyz="-0.061600000000000057487 -0.11491398237765870771 0" rpy="-3.141592653589793116 -1.570796326794896558 0" />
<geometry>
<mesh filename="package:///actuator_molet.stl"/>
</geometry>
<material name="actuator_molet_material">
<color rgba="0.91764705882352937127 0.91764705882352937127 0.91764705882352937127 1.0"/>
</material>
</visual>
<collision>
<origin xyz="-0.061600000000000057487 -0.11491398237765870771 0" rpy="-3.141592653589793116 -1.570796326794896558 0" />
<geometry>
<mesh filename="package:///actuator_molet.stl"/>
</geometry>
</collision>
<inertial>
<origin xyz="-0.083086291902174758128 -0.020033778925019923856 2.8736095531692249613e-08" rpy="0 0 0"/>
<mass value="0.7428461942208621771" />
<inertia ixx="0.00039818835112512165723" ixy="-0.00054213231673500038906"  ixz="-5.263764430699256008e-10" iyy="0.007985191784274097912" iyz="1.2685116131769644516e-10" izz="0.0079848716361182476425" />
</inertial>
</link>

<link name="foot_roll_2">
<visual>
<origin xyz="0.325998400000000077 0.039743999999999890527 1.249000902703301108e-16" rpy="-1.570796326794896558 -1.570796326794896336 0" />
<geometry>
<mesh filename="package:///foot_roll.stl"/>
</geometry>
<material name="foot_roll_material">
<color rgba="0.2313725490196078538 0.38039215686274507888 0.7058823529411765163 1.0"/>
</material>
</visual>
<collision>
<origin xyz="0.325998400000000077 0.039743999999999890527 1.249000902703301108e-16" rpy="-1.570796326794896558 -1.570796326794896336 0" />
<geometry>
<mesh filename="package:///foot_roll.stl"/>
</geometry>
</collision>
<inertial>
<origin xyz="-2.1851523803977209919e-08 -0.0014449033387293822028 6.7774346911495724364e-09" rpy="0 0 0"/>
<mass value="0.0027067106871796996204" />
<inertia ixx="1.8232396912107804468e-07" ixy="1.2456494871913400136e-13"  ixz="-3.0177862000950189758e-13" iyy="1.1958745424438052282e-07" iyz="4.580768721684754061e-14" izz="1.0944659228682657435e-07" />
</inertial>
</link>

<link name="foot_part_2">
<visual>
<origin xyz="-0.0011288304490431055882 -1.3877787807814456755e-17 0.0090799999999999769784" rpy="-1.570796326794896558 -1.253981591208055539e-17 9.5956049968737077813e-34" />
<geometry>
<mesh filename="package:///foot_part.stl"/>
</geometry>
<material name="foot_part_material">
<color rgba="0.61568627450980395466 0.81176470588235294379 0.92941176470588238168 1.0"/>
</material>
</visual>
<collision>
<origin xyz="-0.0011288304490431055882 -1.3877787807814456755e-17 0.0090799999999999769784" rpy="-1.570796326794896558 -1.253981591208055539e-17 9.5956049968737077813e-34" />
<geometry>
<mesh filename="package:///foot_part.stl"/>
</geometry>
</collision>
<inertial>
<origin xyz="-0.042296631354857269769 6.7228490635484678803e-10 0.0063626481723337733817" rpy="0 0 0"/>
<mass value="0.33095167420253657209" />
<inertia ixx="0.0010118322945958282532" ixy="-2.5339652312489177884e-12"  ixz="0.00049446274168876605103" iyy="0.001227680104999263281" iyz="7.2849212788249101642e-12" izz="0.00051045333461432888019" />
</inertial>
</link>

<link name="foot_left">
<inertial>
<origin xyz="0 0 0" rpy="0 0 0" />
<mass value="1e-9" />
<inertia ixx="0" ixy="0" ixz="0" iyy="0" iyz="0" izz="0" />
</inertial>
</link>
<joint name="foot_left_frame" type="fixed">
<origin xyz="-0.055897619600577430621 0 0.0037840702321054742185" rpy="-2.0029632011476419211e-16 -1.0420837364882549192 -3.141592653589793116" />
<parent link="foot_part_2" />
<child link="foot_left" />
<axis xyz="0 0 0"/>
</joint>

<link name="toe_b_1/2_3">
<visual>
<origin xyz="-0.054171488011523778738 0.043924303555988974956 -0.11999999999999999556" rpy="1.570796326794896558 1.570796326794896558 0" />
<geometry>
<mesh filename="package:///toe_b_1_2.stl"/>
</geometry>
<material name="toe_b_1/2_material">
<color rgba="0.64705882352941179736 0.64705882352941179736 0.64705882352941179736 1.0"/>
</material>
</visual>
<collision>
<origin xyz="-0.054171488011523778738 0.043924303555988974956 -0.11999999999999999556" rpy="1.570796326794896558 1.570796326794896558 0" />
<geometry>
<mesh filename="package:///toe_b_1_2.stl"/>
</geometry>
</collision>
<inertial>
<origin xyz="6.9388939039072276073e-18 3.4694469519536141888e-17 -0.059975000000000042166" rpy="0 0 0"/>
<mass value="0.0060293446207695467268" />
<inertia ixx="7.2533028348992190535e-06" ixy="-6.5986121973754776589e-37"  ixz="2.9997503754211436675e-37" iyy="7.2533028348992097361e-06" iyz="-3.217685428198045049e-22" izz="4.8234756966146925458e-08" />
</inertial>
</link>

<link name="closedloop4_A">
<inertial>
<origin xyz="0 0 0" rpy="0 0 0" />
<mass value="1e-9" />
<inertia ixx="0" ixy="0" ixz="0" iyy="0" iyz="0" izz="0" />
</inertial>
</link>
<joint name="closedloop4_A_frame" type="fixed">
<origin xyz="0 -1.1102230246251565404e-16 -0.11995000000000000107" rpy="-3.1415926535897926719 1.4557857793770605109e-15 1.570796326794896558" />
<parent link="toe_b_1/2_3" />
<child link="closedloop4_A" />
<axis xyz="0 0 0"/>
</joint>

<joint name="spherical_free_foot1_left" type="revolute">
<origin xyz="-0.0091288304490432237159 -0.014276000000000010903 -0.034653600000000173154" rpy="1.5707963267948970021 -1.0103389770218152502e-16 -1.5707963267948961139" />
<parent link="foot_part_2" />
<child link="toe_b_1/2_3" />
<axis xyz="0 0 1"/>
<limit effort="1" velocity="20" />
<joint_properties friction="0.0"/>
</joint>

<link name="toe_b_2/2_3">
<visual>
<origin xyz="-0.054171488011523771799 0.043924303555988974956 5.0000000000105515596e-05" rpy="1.570796326794896558 1.570796326794896558 0" />
<geometry>
<mesh filename="package:///toe_b_2_2.stl"/>
</geometry>
<material name="toe_b_2/2_material">
<color rgba="0.64705882352941179736 0.64705882352941179736 0.64705882352941179736 1.0"/>
</material>
</visual>
<collision>
<origin xyz="-0.054171488011523771799 0.043924303555988974956 5.0000000000105515596e-05" rpy="1.570796326794896558 1.570796326794896558 0" />
<geometry>
<mesh filename="package:///toe_b_2_2.stl"/>
</geometry>
</collision>
<inertial>
<origin xyz="6.9388939039072299184e-18 2.0816681711721685133e-17 -0.0599749999999999589" rpy="0 0 0"/>
<mass value="0.0060293446207695345837" />
<inertia ixx="7.2533028348991987247e-06" ixy="-8.3866893974319323189e-37"  ixz="6.5759047755340805502e-37" iyy="7.2533028348991885603e-06" iyz="-3.2176854281980351748e-22" izz="4.8234756966146826196e-08" />
</inertial>
</link>

<link name="closedloop5_A">
<inertial>
<origin xyz="0 0 0" rpy="0 0 0" />
<mass value="1e-9" />
<inertia ixx="0" ixy="0" ixz="0" iyy="0" iyz="0" izz="0" />
</inertial>
</link>
<joint name="closedloop5_A_frame" type="fixed">
<origin xyz="0 1.1102230246251565404e-16 -0.11994999999999977902" rpy="-3.1415926535897926719 1.4557857793770605109e-15 1.570796326794896558" />
<parent link="toe_b_2/2_3" />
<child link="closedloop5_A" />
<axis xyz="0 0 0"/>
</joint>

<joint name="spherical_free_foot2_left" type="revolute">
<origin xyz="-0.0091288304490432237159 0.014275999999999927637 -0.034653600000000284176" rpy="1.5707963267948970021 -1.0103389770218157432e-16 -1.5707963267948961139" />
<parent link="foot_part_2" />
<child link="toe_b_2/2_3" />
<axis xyz="0 0 1"/>
<limit effort="1" velocity="20" />
<joint_properties friction="0.0"/>
</joint>

<joint name="free_foot2_left" type="revolute">
<origin xyz="1.1102230246251565404e-16 0.0090000000000000079936 -8.3266726846886740532e-17" rpy="-1.570796326794896558 7.3354943207976340417e-16 -3.141592653589793116" />
<parent link="foot_roll_2" />
<child link="foot_part_2" />
<axis xyz="0 0 1"/>
<limit effort="1" velocity="20" />
<joint_properties friction="0.0"/>
</joint>

<joint name="free_foot1_left" type="revolute">
<origin xyz="-0.325998400000000077 -0.038657982377658717255 -5.5511151231257827021e-17" rpy="5.5511151231257814695e-17 2.7597873481449337343e-16 -3.1415926535897624738" />
<parent link="tarsus_2" />
<child link="foot_roll_2" />
<axis xyz="0 0 1"/>
<limit effort="1" velocity="20" />
<joint_properties friction="0.0"/>
</joint>

<link name="crank_3">
<visual>
<origin xyz="0.088799999999999990052 0.027200000000000001954 0.02999999999999999889" rpy="-1.570796326794896558 -1.570796326794896558 0" />
<geometry>
<mesh filename="package:///crank.stl"/>
</geometry>
<material name="crank_material">
<color rgba="0.64705882352941179736 0.64705882352941179736 0.64705882352941179736 1.0"/>
</material>
</visual>
<collision>
<origin xyz="0.088799999999999990052 0.027200000000000001954 0.02999999999999999889" rpy="-1.570796326794896558 -1.570796326794896558 0" />
<geometry>
<mesh filename="package:///crank.stl"/>
</geometry>
</collision>
<inertial>
<origin xyz="-4.1591130659041493929e-17 0.015221680213895983844 -0.00095148915120264754026" rpy="0 0 0"/>
<mass value="0.0045332434126214744829" />
<inertia ixx="2.0190313503504425919e-06" ixy="6.7402656531618124051e-23"  ixz="3.2393098298753766355e-26" iyy="3.8254267160843592626e-07" iyz="-9.1875323763544904139e-09" izz="2.3968139039834550182e-06" />
</inertial>
</link>

<link name="toe_b_2/2_4">
<visual>
<origin xyz="-0.054171488011523827311 0.043924303555988961079 5.0000000000105515596e-05" rpy="1.570796326794896558 1.570796326794896558 0" />
<geometry>
<mesh filename="package:///toe_b_2_2.stl"/>
</geometry>
<material name="toe_b_2/2_material">
<color rgba="0.64705882352941179736 0.64705882352941179736 0.64705882352941179736 1.0"/>
</material>
</visual>
<collision>
<origin xyz="-0.054171488011523827311 0.043924303555988961079 5.0000000000105515596e-05" rpy="1.570796326794896558 1.570796326794896558 0" />
<geometry>
<mesh filename="package:///toe_b_2_2.stl"/>
</geometry>
</collision>
<inertial>
<origin xyz="-5.7792268147074716097e-17 6.9388939039072283776e-18 -0.0599749999999999589" rpy="0 0 0"/>
<mass value="0.0060293446207695345837" />
<inertia ixx="7.2533028348991987247e-06" ixy="1.0798552882945254333e-34"  ixz="2.9748227916399746356e-22" iyy="7.2533028348991885603e-06" iyz="-4.4111929785268494234e-22" izz="4.8234756966146826196e-08" />
</inertial>
</link>

<link name="closedloop4_B">
<inertial>
<origin xyz="0 0 0" rpy="0 0 0" />
<mass value="1e-9" />
<inertia ixx="0" ixy="0" ixz="0" iyy="0" iyz="0" izz="0" />
</inertial>
</link>
<joint name="closedloop4_B_frame" type="fixed">
<origin xyz="0 -2.7755575615628913511e-17 -0.11994999999999983453" rpy="2.5132107670464821188e-16 -1.5516628120086465861e-16 -7.8371506725709791247e-17" />
<parent link="toe_b_2/2_4" />
<child link="closedloop4_B" />
<axis xyz="0 0 0"/>
</joint>

<joint name="spherical_free_shin2_left" type="revolute">
<origin xyz="-5.5511151231257827021e-17 0.057000000000000050626 0.0025000000000000022204" rpy="-1.57079632679489678 -6.1989581036318994383e-14 -1.570796326794896558" />
<parent link="crank_3" />
<child link="toe_b_2/2_4" />
<axis xyz="0 0 1"/>
<limit effort="1" velocity="20" />
<joint_properties friction="0.0"/>
</joint>

<joint name="motor_shin1_left" type="revolute">
<origin xyz="-0.088800000000002418665 -0.026113982377657718459 0.02999999999999999889" rpy="3.141592653589793116 -0 -1.1936089721976891145e-17" />
<parent link="tarsus_2" />
<child link="crank_3" />
<axis xyz="0 0 1"/>
<limit effort="1" velocity="20" />
<joint_properties friction="0.0"/>
</joint>

<link name="crank_4">
<visual>
<origin xyz="0.088800000000000045564 0.027200000000000001954 0.02999999999999999889" rpy="-1.57079632679489678 -1.570796326794896558 0" />
<geometry>
<mesh filename="package:///crank.stl"/>
</geometry>
<material name="crank_material">
<color rgba="0.64705882352941179736 0.64705882352941179736 0.64705882352941179736 1.0"/>
</material>
</visual>
<collision>
<origin xyz="0.088800000000000045564 0.027200000000000001954 0.02999999999999999889" rpy="-1.57079632679489678 -1.570796326794896558 0" />
<geometry>
<mesh filename="package:///crank.stl"/>
</geometry>
</collision>
<inertial>
<origin xyz="1.4145304685638640009e-17 0.015221680213895992517 -0.00095148915120264754026" rpy="0 0 0"/>
<mass value="0.0045332434126214744829" />
<inertia ixx="2.0190313503504425919e-06" ixy="-1.3716314016687037039e-22"  ixz="2.0518904321472164902e-25" iyy="3.8254267160843603214e-07" iyz="-9.1875323763544920682e-09" izz="2.3968139039834550182e-06" />
</inertial>
</link>

<link name="toe_b_1/2_4">
<visual>
<origin xyz="-0.054171488011523827311 0.043924303555988947201 -0.1199999999999999678" rpy="1.570796326794896558 1.570796326794896558 0" />
<geometry>
<mesh filename="package:///toe_b_1_2.stl"/>
</geometry>
<material name="toe_b_1/2_material">
<color rgba="0.64705882352941179736 0.64705882352941179736 0.64705882352941179736 1.0"/>
</material>
</visual>
<collision>
<origin xyz="-0.054171488011523827311 0.043924303555988947201 -0.1199999999999999678" rpy="1.570796326794896558 1.570796326794896558 0" />
<geometry>
<mesh filename="package:///toe_b_1_2.stl"/>
</geometry>
</collision>
<inertial>
<origin xyz="-3.7825359619280775841e-17 0 -0.059975000000000014411" rpy="0 0 0"/>
<mass value="0.0060293446207695467268" />
<inertia ixx="7.2533028348992190535e-06" ixy="-3.6608572795448263879e-38"  ixz="-1.1433637232898345649e-22" iyy="7.2533028348992097361e-06" iyz="-9.8307778635727617543e-41" izz="4.8234756966146912223e-08" />
</inertial>
</link>

<link name="closedloop5_B">
<inertial>
<origin xyz="0 0 0" rpy="0 0 0" />
<mass value="1e-9" />
<inertia ixx="0" ixy="0" ixz="0" iyy="0" iyz="0" izz="0" />
</inertial>
</link>
<joint name="closedloop5_B_frame" type="fixed">
<origin xyz="-3.3306690738754696213e-16 0 -0.1199499999999999178" rpy="1.3570894085680469023e-16 1.1131720658713263778e-15 -3.141592653589793116" />
<parent link="toe_b_1/2_4" />
<child link="closedloop5_B" />
<axis xyz="0 0 0"/>
</joint>

<joint name="spherical_free_shin1_left" type="revolute">
<origin xyz="2.2204460492503130808e-16 0.057000000000000494715 0.0025000000000004185541" rpy="-1.570796326794896558 -1.866329740155221443e-16 1.5707963267948970021" />
<parent link="crank_4" />
<child link="toe_b_1/2_4" />
<axis xyz="0 0 1"/>
<limit effort="1" velocity="20" />
<joint_properties friction="0.0"/>
</joint>

<joint name="motor_shin2_left" type="revolute">
<origin xyz="-0.08880000000000000393 -0.026113982377658606637 -0.029999999999999978073" rpy="-2.4214412524677942898e-16 -8.9555256306153669199e-17 3.141592653589793116" />
<parent link="tarsus_2" />
<child link="crank_4" />
<axis xyz="0 0 1"/>
<limit effort="1" velocity="20" />
<joint_properties friction="0.0"/>
</joint>

<link name="toe_a_1/2_2">
<visual>
<origin xyz="0.056794565202879024324 0.040773406646044459134 -0.19999999999999995559" rpy="1.570796326794896558 1.570796326794896558 0" />
<geometry>
<mesh filename="package:///toe_a_1_2.stl"/>
</geometry>
<material name="toe_a_1/2_material">
<color rgba="0.61568627450980395466 0.81176470588235294379 0.92941176470588238168 1.0"/>
</material>
</visual>
<collision>
<origin xyz="0.056794565202879024324 0.040773406646044459134 -0.19999999999999995559" rpy="1.570796326794896558 1.570796326794896558 0" />
<geometry>
<mesh filename="package:///toe_a_1_2.stl"/>
</geometry>
</collision>
<inertial>
<origin xyz="1.5636775695836450254e-17 -6.9388939039072283776e-18 -0.099974999999999966671" rpy="0 0 0"/>
<mass value="0.015704036277131967758" />
<inertia ixx="5.2418767695050980918e-05" ixy="-2.0997297292780270681e-37"  ixz="5.3594272756806182536e-21" iyy="5.2418767695050980918e-05" iyz="-1.3098890123765843119e-37" izz="1.9630045346413536255e-07" />
</inertial>
</link>

<link name="closedloop6_A">
<inertial>
<origin xyz="0 0 0" rpy="0 0 0" />
<mass value="1e-9" />
<inertia ixx="0" ixy="0" ixz="0" iyy="0" iyz="0" izz="0" />
</inertial>
</link>
<joint name="closedloop6_A_frame" type="fixed">
<origin xyz="6.5919492087118669588e-17 0 -0.19995000000000007212" rpy="-3.141592653589793116 -7.0048445437832687964e-17 -2.6752620058038898353e-33" />
<parent link="toe_a_1/2_2" />
<child link="closedloop6_A" />
<axis xyz="0 0 0"/>
</joint>

<joint name="spherical_free_hip_left" type="revolute">
<origin xyz="0.1141899349863718105 0.03620674973129278662 7.3552275381416620803e-16" rpy="-1.570796326794896558 -6.032224767520871884e-18 3.141592653589793116" />
<parent link="tarsus_2" />
<child link="toe_a_1/2_2" />
<axis xyz="0 0 1"/>
<limit effort="1" velocity="20" />
<joint_properties friction="0.0"/>
</joint>

<joint name="free_knee_left" type="revolute">
<origin xyz="0.39567486363081372236 -0.053875166733171747646 -0.024999999999999994449" rpy="0 -0 1.570796326794896558" />
<parent link="shin_2" />
<child link="tarsus_2" />
<axis xyz="0 0 1"/>
<limit effort="1" velocity="20" />
<joint_properties friction="0.0"/>
</joint>

<joint name="motor_knee_left" type="revolute">
<origin xyz="0.1199999999999999678 0 1.6930901125533637241e-15" rpy="3.141592653589793116 -0 -0.55703373375772102793" />
<parent link="hip_z_2" />
<child link="shin_2" />
<axis xyz="0 0 1"/>
<limit effort="1" velocity="20" />
<joint_properties friction="0.0"/>
</joint>

<joint name="motor_hip_y_left" type="revolute">
<origin xyz="-0.029117226656781597383 0 -0.047379470518249228173" rpy="-1.570796326794896558 1.2655169802117200994 -1.570796326794896558" />
<parent link="hip_x_2" />
<child link="hip_z_2" />
<axis xyz="0 0 1"/>
<limit effort="1" velocity="20" />
<joint_properties friction="0.0"/>
</joint>

<link name="toe_a_2/2_2">
<visual>
<origin xyz="0.056794565202879003507 0.040773406646044445256 5.0000000000133271172e-05" rpy="1.570796326794896558 1.570796326794896558 0" />
<geometry>
<mesh filename="package:///toe_a_2_2.stl"/>
</geometry>
<material name="toe_a_2/2_material">
<color rgba="0.61568627450980395466 0.81176470588235294379 0.92941176470588238168 1.0"/>
</material>
</visual>
<collision>
<origin xyz="0.056794565202879003507 0.040773406646044445256 5.0000000000133271172e-05" rpy="1.570796326794896558 1.570796326794896558 0" />
<geometry>
<mesh filename="package:///toe_a_2_2.stl"/>
</geometry>
</collision>
<inertial>
<origin xyz="6.9388939039072283776e-18 -1.3877787807814456755e-17 -0.099974999999999938916" rpy="0 0 0"/>
<mass value="0.015704036277131950411" />
<inertia ixx="5.2418767695050838616e-05" ixy="0"  ixz="0" iyy="5.2418767695050825063e-05" iyz="-3.1972408633164225501e-21" izz="1.9630045346413507138e-07" />
</inertial>
</link>

<link name="closedloop6_B">
<inertial>
<origin xyz="0 0 0" rpy="0 0 0" />
<mass value="1e-9" />
<inertia ixx="0" ixy="0" ixz="0" iyy="0" iyz="0" izz="0" />
</inertial>
</link>
<joint name="closedloop6_B_frame" type="fixed">
<origin xyz="6.9388939039072283776e-18 -2.0816681711721685133e-17 -0.19994999999999985008" rpy="-6.1223473960463149353e-17 2.4651903288156618919e-32 9.6553912330110834249e-33" />
<parent link="toe_a_2/2_2" />
<child link="closedloop6_B" />
<axis xyz="0 0 0"/>
</joint>

<joint name="spherical_free_knee_left" type="revolute">
<origin xyz="0.030568773343218405558 0 -0.054400000000000003908" rpy="-1.57079632679489678 1.570796326794896558 0" />
<parent link="hip_x_2" />
<child link="toe_a_2/2_2" />
<axis xyz="0 0 1"/>
<limit effort="1" velocity="20" />
<joint_properties friction="0.0"/>
</joint>

<joint name="motor_hip_z_left" type="revolute">
<origin xyz="0.050000000000000016653 0 -0.035199999999999981304" rpy="1.570796326794896558 -0 -1.570796326794896558" />
<parent link="hip_y_2" />
<child link="hip_x_2" />
<axis xyz="0 0 1"/>
<limit effort="1" velocity="20" />
<joint_properties friction="0.0"/>
</joint>

<joint name="motor_hip_x_left" type="revolute">
<origin xyz="-0.02999999999999999889 0.072800000000000031353 0.059867854479678822566" rpy="-0 1.570796326794896558 0" />
<parent link="torso" />
<child link="hip_y_2" />
<axis xyz="0 0 1"/>
<limit effort="1" velocity="20" />
<joint_properties friction="0.0"/>
</joint>


</robot>
