<robot name="onshape">
  <link name="hip_ground">
    <visual>
      <origin xyz="0.018000000000009067774 0.27650000000001295763 -0.9400000000000158229" rpy="-1.7037880943457418704e-31 -4.5021244384580047798e-15 -4.4619944951562846857e-29" />
      <geometry>
        <mesh filename="package:///hip_ground.stl" />
      </geometry>
      <material name="hip_ground_material">
        <color rgba="0.61568627450980395466 0.81176470588235294379 0.92941176470588238168 1.0" />
      </material>
    </visual>
    <collision>
      <origin xyz="0.018000000000009067774 0.27650000000001295763 -0.9400000000000158229" rpy="-1.7037880943457418704e-31 -4.5021244384580047798e-15 -4.4619944951562846857e-29" />
      <geometry>
        <mesh filename="package:///hip_ground.stl" />
      </geometry>
    </collision>
    <inertial>
      <origin xyz="-0.0014786115366831747986 0.1276542468606598757 0.024304995635825776823" rpy="0 0 0" />
      <mass value="1.5865591647149870358" />
      <inertia ixx="0.0088382827967698161797" ixy="0.0002748776218202433853" ixz="-2.920764549681984781e-05" iyy="0.0025754201921633630527" iyz="6.8858407992517019366e-05" izz="0.010752178054608726651" />
    </inertial>
  </link>
  <link name="hip_center">
    <inertial>
      <origin xyz="0 0 0" rpy="0 0 0" />
      <mass value="1e-9" />
      <inertia ixx="0" ixy="0" ixz="0" iyy="0" iyz="0" izz="0" />
    </inertial>
  </link>
  <joint name="hip_center_frame" type="fixed">
    <origin xyz="-0.0047474699228997607747 0.28861143158345337056 -0.17250000000000290101" rpy="2.6505726415425557215e-28 -8.3196567936654447285e-16 -1.1492717312938456553e-28" />
    <parent link="hip_ground" />
    <child link="hip_center" />
    <axis xyz="0 0 0" />
  </joint>
  <link name="hip_part">
    <visual>
      <origin xyz="0.0055000000000023745172 0.071500000000000035749 -0.93500000000000038636" rpy="2.6671279651263395835e-31 -3.6701587590914514323e-15 -2.2623412947170761627e-32" />
      <geometry>
        <mesh filename="package:///hip_part.stl" />
      </geometry>
      <material name="hip_part_material">
        <color rgba="0.2313725490196078538 0.38039215686274507888 0.7058823529411765163 1.0" />
      </material>
    </visual>
    <collision>
      <origin xyz="0.0055000000000023745172 0.071500000000000035749 -0.93500000000000038636" rpy="2.6671279651263395835e-31 -3.6701587590914514323e-15 -2.2623412947170761627e-32" />
      <geometry>
        <mesh filename="package:///hip_part.stl" />
      </geometry>
    </collision>
    <inertial>
      <origin xyz="3.4156793823035547231e-08 0.0030510835733530833336 -0.083365236807579123912" rpy="0 0 0" />
      <mass value="0.1490882064698049736" />
      <inertia ixx="0.00035636864137915798224" ixy="1.6418959534102587027e-10" ixz="-6.6325805549172388776e-11" iyy="0.00032228379449719354345" iyz="-1.6655006554546136825e-05" izz="4.9201065872666322333e-05" />
    </inertial>
  </link>
  <link name="universal_foot">
    <visual>
      <origin xyz="0 0.038499999999999978684 -6.6000000000000086375e-05" rpy="1.570796326794896558 1.570796326794896558 0" />
      <geometry>
        <mesh filename="package:///universal_foot.stl" />
      </geometry>
      <material name="universal_foot_material">
        <color rgba="0.64705882352941179736 0.64705882352941179736 0.64705882352941179736 1.0" />
      </material>
    </visual>
    <collision>
      <origin xyz="0 0.038499999999999978684 -6.6000000000000086375e-05" rpy="1.570796326794896558 1.570796326794896558 0" />
      <geometry>
        <mesh filename="package:///universal_foot.stl" />
      </geometry>
    </collision>
    <inertial>
      <origin xyz="6.7228290681873054761e-09 -1.3877787807814456755e-17 -6.5993277170931378462e-05" rpy="0 0 0" />
      <mass value="0.0064135211594024193679" />
      <inertia ixx="3.3475011343990649772e-07" ixy="-2.848658323731531802e-12" ixz="-8.8726912462034705212e-40" iyy="4.3082408299805979528e-07" iyz="2.8486583237702012839e-12" izz="3.3475011343990644478e-07" />
    </inertial>
  </link>
  <link name="part_1">
    <visual>
      <origin xyz="-5.5511151231257827021e-17 0 0" rpy="1.570796326794896558 1.570796326794896558 0" />
      <geometry>
        <mesh filename="package:///part_1.stl" />
      </geometry>
      <material name="part_1_material">
        <color rgba="0.34901960784313723618 0.37647058823529411242 0.4000000000000000222 1.0" />
      </material>
    </visual>
    <collision>
      <origin xyz="-5.5511151231257827021e-17 0 0" rpy="1.570796326794896558 1.570796326794896558 0" />
      <geometry>
        <mesh filename="package:///part_1.stl" />
      </geometry>
    </collision>
    <inertial>
      <origin xyz="0.0067026039127809581425 0.016607315554245553196 -0.045523329198624416791" rpy="0 0 0" />
      <mass value="0.24432174426363428843" />
      <inertia ixx="0.00038002986328721221352" ixy="-4.5343822480551211444e-05" ixz="0.00019115477962150834884" iyy="0.00063262805206548233892" iyz="7.0096670808240417656e-05" izz="0.00036002210019491686028" />
    </inertial>
  </link>
  <link name="closedloop7_B">
    <inertial>
      <origin xyz="0 0 0" rpy="0 0 0" />
      <mass value="1e-9" />
      <inertia ixx="0" ixy="0" ixz="0" iyy="0" iyz="0" izz="0" />
    </inertial>
  </link>
  <joint name="closedloop7_B_frame" type="fixed">
    <origin xyz="0.083867056794542357845 -0.0077119035015027481705 -0.071500000000000035749" rpy="1.570796326794896558 -2.1742890467508124463e-30 -1.3975154895155261838e-14" />
    <parent link="part_1" />
    <child link="closedloop7_B" />
    <axis xyz="0 0 0" />
  </joint>
  <link name="cylinder">
    <visual>
      <origin xyz="-0.10179556944408768571 0.15392457132099846007 -0.85800000000000009592" rpy="-2.1031807460694252989e-18 -1.2075246725575147081e-17 -1.6981706715339906721e-17" />
      <geometry>
        <mesh filename="package:///cylinder.stl" />
      </geometry>
      <material name="cylinder_material">
        <color rgba="0.91764705882352937127 0.91764705882352937127 0.91764705882352937127 1.0" />
      </material>
    </visual>
    <collision>
      <origin xyz="-0.10179556944408768571 0.15392457132099846007 -0.85800000000000009592" rpy="-2.1031807460694252989e-18 -1.2075246725575147081e-17 -1.6981706715339906721e-17" />
      <geometry>
        <mesh filename="package:///cylinder.stl" />
      </geometry>
    </collision>
    <inertial>
      <origin xyz="-1.3877787807814456755e-17 -2.9395291668848456636e-17 -0.011000000000000231815" rpy="0 0 0" />
      <mass value="0.0047041422996690132607" />
      <inertia ixx="2.6977766073778931429e-07" ixy="-8.7874997411290495456e-24" ixz="5.3995982256265442411e-24" iyy="2.6977766073778920841e-07" iyz="-5.5057979381297032351e-25" izz="1.6008784263561083015e-07" />
    </inertial>
  </link>
  <link name="closedloop3_A">
    <inertial>
      <origin xyz="0 0 0" rpy="0 0 0" />
      <mass value="1e-9" />
      <inertia ixx="0" ixy="0" ixz="0" iyy="0" iyz="0" izz="0" />
    </inertial>
  </link>
  <joint name="closedloop3_A_frame" type="fixed">
    <origin xyz="2.7755575615628913511e-17 -5.5511151231257827021e-17 -0.021999999999999964029" rpy="-3.141592653589793116 -1.4810179096329776666e-15 -2.2307564621250647706e-17" />
    <parent link="cylinder" />
    <child link="closedloop3_A" />
    <axis xyz="0 0 0" />
  </joint>
  <link name="cylinder_2">
    <visual>
      <origin xyz="-0.10179556944408768571 0.15392457132099851558 -0.85800000000000009592" rpy="5.5120583953070733461e-19 -1.2112300357150854013e-18 1.2258409856528676875e-17" />
      <geometry>
        <mesh filename="package:///cylinder.stl" />
      </geometry>
      <material name="cylinder_material">
        <color rgba="0.91764705882352937127 0.91764705882352937127 0.91764705882352937127 1.0" />
      </material>
    </visual>
    <collision>
      <origin xyz="-0.10179556944408768571 0.15392457132099851558 -0.85800000000000009592" rpy="5.5120583953070733461e-19 -1.2112300357150854013e-18 1.2258409856528676875e-17" />
      <geometry>
        <mesh filename="package:///cylinder.stl" />
      </geometry>
    </collision>
    <inertial>
      <origin xyz="-4.1633363423443370266e-17 -2.6976712812694296968e-17 -0.011000000000000231815" rpy="0 0 0" />
      <mass value="0.0047041422996690132607" />
      <inertia ixx="2.6977766073778920841e-07" ixy="8.9200697687502609324e-24" ixz="-1.9918143442413452401e-26" iyy="2.6977766073778942017e-07" iyz="6.0061417896896131773e-26" izz="1.6008784263561083015e-07" />
    </inertial>
  </link>
  <link name="closedloop4_A">
    <inertial>
      <origin xyz="0 0 0" rpy="0 0 0" />
      <mass value="1e-9" />
      <inertia ixx="0" ixy="0" ixz="0" iyy="0" iyz="0" izz="0" />
    </inertial>
  </link>
  <joint name="closedloop4_A_frame" type="fixed">
    <origin xyz="-2.7755575615628913511e-17 2.7755575615628913511e-17 -0.021999999999999991784" rpy="-3.1415926535897895633 -5.9339792050261044152e-14 -2.0808136697909534971e-18" />
    <parent link="cylinder_2" />
    <child link="closedloop4_A" />
    <axis xyz="0 0 0" />
  </joint>
  <link name="part_2">
    <visual>
      <origin xyz="-2.3314683517128287349e-15 0.046752000000001514568 -0.071500000000000007994" rpy="-1.570796326794896558 -1.570796326794896558 0" />
      <geometry>
        <mesh filename="package:///part_2.stl" />
      </geometry>
      <material name="part_2_material">
        <color rgba="0.76862745098039220171 0.88627450980392152857 0.95294117647058818044 1.0" />
      </material>
    </visual>
    <collision>
      <origin xyz="-2.3314683517128287349e-15 0.046752000000001514568 -0.071500000000000007994" rpy="-1.570796326794896558 -1.570796326794896558 0" />
      <geometry>
        <mesh filename="package:///part_2.stl" />
      </geometry>
    </collision>
    <inertial>
      <origin xyz="-0.10353133038219136663 -0.14056766472890799835 -5.9849347699980626203e-13" rpy="0 0 0" />
      <mass value="0.39806472503371775895" />
      <inertia ixx="0.0031977111359881450064" ixy="-0.0018588463574926391599" ixz="5.7043161108603627435e-15" iyy="0.0012912945788078695943" iyz="2.6363835897607748943e-14" izz="0.0044624680664483223555" />
    </inertial>
  </link>
  <link name="part_3">
    <visual>
      <origin xyz="0.2174705007161493453 0.38247000862966429313 -0.071500000000000035749" rpy="-1.570796326794896558 -1.570796326794896558 0" />
      <geometry>
        <mesh filename="package:///part_3.stl" />
      </geometry>
      <material name="part_3_material">
        <color rgba="0.76862745098039220171 0.88627450980392152857 0.95294117647058818044 1.0" />
      </material>
    </visual>
    <collision>
      <origin xyz="0.2174705007161493453 0.38247000862966429313 -0.071500000000000035749" rpy="-1.570796326794896558 -1.570796326794896558 0" />
      <geometry>
        <mesh filename="package:///part_3.stl" />
      </geometry>
    </collision>
    <inertial>
      <origin xyz="0.10608938835476387774 -0.17986935727287689524 -4.1633363423443376429e-17" rpy="0 0 0" />
      <mass value="0.20213480893965668495" />
      <inertia ixx="0.0018459328059746533349" ixy="0.0012583807608323395368" ixz="-2.1320581617829652027e-35" iyy="0.0008879700532368084865" iyz="5.3263080806990051643e-36" izz="0.0027204272052821520424" />
    </inertial>
  </link>
  <link name="universal_foot_2">
    <visual>
      <origin xyz="-2.7755575615628913511e-17 0.038500000000000089706 6.5999999999927227989e-05" rpy="1.570796326794896558 1.570796326794896558 0" />
      <geometry>
        <mesh filename="package:///universal_foot.stl" />
      </geometry>
      <material name="universal_foot_material">
        <color rgba="0.64705882352941179736 0.64705882352941179736 0.64705882352941179736 1.0" />
      </material>
    </visual>
    <collision>
      <origin xyz="-2.7755575615628913511e-17 0.038500000000000089706 6.5999999999927227989e-05" rpy="1.570796326794896558 1.570796326794896558 0" />
      <geometry>
        <mesh filename="package:///universal_foot.stl" />
      </geometry>
    </collision>
    <inertial>
      <origin xyz="6.7228290398074690599e-09 9.7144514654701197287e-17 6.6006722828996708397e-05" rpy="0 0 0" />
      <mass value="0.0064135211594024193679" />
      <inertia ixx="3.3475011343990649772e-07" ixy="-2.8486583237225656973e-12" ixz="-9.9917818494775399301e-25" iyy="4.3082408299805979528e-07" iyz="2.8486583237685440954e-12" izz="3.3475011343990655066e-07" />
    </inertial>
  </link>
  <link name="foot_part">
    <visual>
      <origin xyz="0 0.038499999999999978684 0" rpy="1.570796326794896558 -5.1447000778121673909e-20 -1.2180584490873314178e-17" />
      <geometry>
        <mesh filename="package:///foot_part.stl" />
      </geometry>
      <material name="foot_part_material">
        <color rgba="0.61568627450980395466 0.81176470588235294379 0.92941176470588238168 1.0" />
      </material>
    </visual>
    <collision>
      <origin xyz="0 0.038499999999999978684 0" rpy="1.570796326794896558 -5.1447000778121673909e-20 -1.2180584490873314178e-17" />
      <geometry>
        <mesh filename="package:///foot_part.stl" />
      </geometry>
    </collision>
    <inertial>
      <origin xyz="-0.0036358817134150766756 0.024966449369929560875 9.0007330082631464581e-08" rpy="0 0 0" />
      <mass value="0.31091298222930213724" />
      <inertia ixx="0.0002632861258833189594" ixy="-5.3028311481364777044e-05" ixz="-1.7872775968686235377e-09" iyy="0.00071897520566117803596" iyz="-2.090309616935568805e-10" izz="0.00052661427619001336103" />
    </inertial>
  </link>
  <link name="foot">
    <inertial>
      <origin xyz="0 0 0" rpy="0 0 0" />
      <mass value="1e-9" />
      <inertia ixx="0" ixy="0" ixz="0" iyy="0" iyz="0" izz="0" />
    </inertial>
  </link>
  <joint name="foot_frame" type="fixed">
    <origin xyz="0.012016949221079820109 0.038499999999999978684 6.8117394502742456552e-09" rpy="1.5707963267948972241 1.0529999139445015132e-16 9.3156790618841999074e-16" />
    <parent link="foot_part" />
    <child link="foot" />
    <axis xyz="0 0 0" />
  </joint>
  <link name="closedloop0_A">
    <inertial>
      <origin xyz="0 0 0" rpy="0 0 0" />
      <mass value="1e-9" />
      <inertia ixx="0" ixy="0" ixz="0" iyy="0" iyz="0" izz="0" />
    </inertial>
  </link>
  <joint name="closedloop0_A_frame" type="fixed">
    <origin xyz="-0.054999999999999993339 -0.01100000000000000977 0.038500000000000006439" rpy="1.570796326794896558 7.0549938242594490701e-17 -1.570796326794896558" />
    <parent link="foot_part" />
    <child link="closedloop0_A" />
    <axis xyz="0 0 0" />
  </joint>
  <link name="closedloop11_A">
    <inertial>
      <origin xyz="0 0 0" rpy="0 0 0" />
      <mass value="1e-9" />
      <inertia ixx="0" ixy="0" ixz="0" iyy="0" iyz="0" izz="0" />
    </inertial>
  </link>
  <joint name="closedloop11_A_frame" type="fixed">
    <origin xyz="-0.054999999999999965583 -0.010999999999999898748 -0.038500000000000006439" rpy="1.570796326794896558 7.0549938242594490701e-17 -1.570796326794896558" />
    <parent link="foot_part" />
    <child link="closedloop11_A" />
    <axis xyz="0 0 0" />
  </joint>
  <joint name="free_ankle_universalx" type="revolute">
    <origin xyz="6.6000000000010494716e-05 1.1102230246251565404e-16 6.5999999999954983565e-05" rpy="1.5707963267949303088 -1.5331629223910492321 1.570796326794896336" />
    <parent link="universal_foot_2" />
    <child link="foot_part" />
    <axis xyz="0 0 1" />
    <limit effort="1" velocity="20" />
    <joint_properties friction="0.0" />
  </joint>
  <joint name="universal_foot_up" type="revolute">
    <origin xyz="0.2174705007161493453 -0.33571800862966416634 0" rpy="-1.5707963267948972241 -1.4835298641951775167 1.5707963267949347497" />
    <parent link="part_3" />
    <child link="universal_foot_2" />
    <axis xyz="0 0 1" />
    <limit effort="1" velocity="20" />
    <joint_properties friction="0.0" />
  </joint>
  <link name="part_6">
    <visual>
      <origin xyz="0.10788167727912303939 -0.039150197130724539996 -5.5511151231257827021e-17" rpy="-3.141592653589793116 -2.130559693754528357e-18 1.0318508346194439108e-31" />
      <geometry>
        <mesh filename="package:///part_6.stl" />
      </geometry>
      <material name="part_6_material">
        <color rgba="0.76862745098039220171 0.88627450980392152857 0.95294117647058818044 1.0" />
      </material>
    </visual>
    <collision>
      <origin xyz="0.10788167727912303939 -0.039150197130724539996 -5.5511151231257827021e-17" rpy="-3.141592653589793116 -2.130559693754528357e-18 1.0318508346194439108e-31" />
      <geometry>
        <mesh filename="package:///part_6.stl" />
      </geometry>
    </collision>
    <inertial>
      <origin xyz="5.5511151231257827021e-17 3.4694469519536135725e-17 -0.21360000000000006759" rpy="0 0 0" />
      <mass value="0.033552209540339043847" />
      <inertia ixx="0.00051048244070615617519" ixy="2.9254549556754045775e-35" ixz="1.0879354237550174507e-21" iyy="0.00051048244070615639203" iyz="1.6477465880720036669e-35" izz="4.1940261925423872038e-07" />
    </inertial>
  </link>
  <link name="closedloop6_B">
    <inertial>
      <origin xyz="0 0 0" rpy="0 0 0" />
      <mass value="1e-9" />
      <inertia ixx="0" ixy="0" ixz="0" iyy="0" iyz="0" izz="0" />
    </inertial>
  </link>
  <joint name="closedloop6_B_frame" type="fixed">
    <origin xyz="5.5511151231257827021e-17 5.5511151231257827021e-17 -0.42720000000000002416" rpy="-3.1415926535897926719 3.4737141109842255094e-16 -3.141592653589793116" />
    <parent link="part_6" />
    <child link="closedloop6_B" />
    <axis xyz="0 0 0" />
  </joint>
  <joint name="lower_knee" type="revolute">
    <origin xyz="-0.21747050071615151023 -0.33571800862966272305 5.5511151231257827021e-17" rpy="-1.7726512667869372285e-16 -4.9802783514596252578e-17 0.89630439304597708805" />
    <parent link="part_2" />
    <child link="part_3" />
    <axis xyz="0 0 1" />
    <limit effort="1" velocity="20" />
    <joint_properties friction="0.0" />
  </joint>
  <link name="transmission_ankle2">
    <visual>
      <origin xyz="-0.11550000000000000544 -0.35749999999999992895 0.03300000000000002931" rpy="-1.570796326794896558 8.258859173371421546e-33 -1.674842542133789519e-17" />
      <geometry>
        <mesh filename="package:///transmission_ankle2.stl" />
      </geometry>
      <material name="transmission_ankle2_material">
        <color rgba="0.91764705882352937127 0.91764705882352937127 0.91764705882352937127 1.0" />
      </material>
    </visual>
    <collision>
      <origin xyz="-0.11550000000000000544 -0.35749999999999992895 0.03300000000000002931" rpy="-1.570796326794896558 8.258859173371421546e-33 -1.674842542133789519e-17" />
      <geometry>
        <mesh filename="package:///transmission_ankle2.stl" />
      </geometry>
    </collision>
    <inertial>
      <origin xyz="-0.033596086250149273522 -0.018380744757818978652 -0.014122199558543407916" rpy="0 0 0" />
      <mass value="0.074310320490072731547" />
      <inertia ixx="4.1295450354366541358e-05" ixy="1.9886051938184637935e-06" ixz="-2.0689202263474873248e-06" iyy="3.2625641947312127868e-05" iyz="-9.9798202174584469521e-06" izz="5.1310129727252670956e-05" />
    </inertial>
  </link>
  <link name="closedloop10_B">
    <inertial>
      <origin xyz="0 0 0" rpy="0 0 0" />
      <mass value="1e-9" />
      <inertia ixx="0" ixy="0" ixz="0" iyy="0" iyz="0" izz="0" />
    </inertial>
  </link>
  <joint name="closedloop10_B_frame" type="fixed">
    <origin xyz="-0.035854717888628970246 -0.041706584673488089621 -0.052249999999999963141" rpy="-1.57079632679489678 4.2500725161430664477e-17 -3.7753854610413260056e-16" />
    <parent link="transmission_ankle2" />
    <child link="closedloop10_B" />
    <axis xyz="0 0 0" />
  </joint>
  <link name="part_7">
    <visual>
      <origin xyz="0.062087559207389841909 0.15255026628033757641 -7.459310946700270506e-17" rpy="-3.141592653589793116 5.2527731110155603152e-17 -1.3625200193489927302e-31" />
      <geometry>
        <mesh filename="package:///part_7.stl" />
      </geometry>
      <material name="part_7_material">
        <color rgba="0.91764705882352937127 0.91764705882352937127 0.91764705882352937127 1.0" />
      </material>
    </visual>
    <collision>
      <origin xyz="0.062087559207389841909 0.15255026628033757641 -7.459310946700270506e-17" rpy="-3.141592653589793116 5.2527731110155603152e-17 -1.3625200193489927302e-31" />
      <geometry>
        <mesh filename="package:///part_7.stl" />
      </geometry>
    </collision>
    <inertial>
      <origin xyz="-6.9388939039072283776e-18 -2.7755575615628901185e-17 -0.20000000000000017764" rpy="0 0 0" />
      <mass value="0.031415926535897982508" />
      <inertia ixx="0.00041907537001948904276" ixy="-6.0040359734066492533e-35" ixz="-2.2003333319438288253e-20" iyy="0.00041907537001948915118" iyz="1.5859336841924123775e-35" izz="3.9269908169872580702e-07" />
    </inertial>
  </link>
  <link name="closedloop0_B">
    <inertial>
      <origin xyz="0 0 0" rpy="0 0 0" />
      <mass value="1e-9" />
      <inertia ixx="0" ixy="0" ixz="0" iyy="0" iyz="0" izz="0" />
    </inertial>
  </link>
  <joint name="closedloop0_B_frame" type="fixed">
    <origin xyz="0 0 -0.40000000000000007772" rpy="3.1415926535897913396 1.2983444000664018813e-15 -1.570796326794896558" />
    <parent link="part_7" />
    <child link="closedloop0_B" />
    <axis xyz="0 0 0" />
  </joint>
  <joint name="knee_transmission_1" type="revolute">
    <origin xyz="-0.21747050071615148248 -0.33571800862966283407 0.0099999999999999533706" rpy="3.1415926535897926719 2.3487564121428828494e-15 3.0459021140380468928" />
    <parent link="part_2" />
    <child link="transmission_ankle2" />
    <axis xyz="0 0 1" />
    <limit effort="1" velocity="20" />
    <joint_properties friction="0.0" />
  </joint>
  <link name="transmission_ankle">
    <visual>
      <origin xyz="-0.11549999999999993605 -0.35749999999999992895 -0.032999999999999973799" rpy="-1.570796326794896558 3.2673384327120176724e-31 -4.3105056776335849615e-17" />
      <geometry>
        <mesh filename="package:///transmission_ankle.stl" />
      </geometry>
      <material name="transmission_ankle_material">
        <color rgba="0.91764705882352937127 0.91764705882352937127 0.91764705882352937127 1.0" />
      </material>
    </visual>
    <collision>
      <origin xyz="-0.11549999999999993605 -0.35749999999999992895 -0.032999999999999973799" rpy="-1.570796326794896558 3.2673384327120176724e-31 -4.3105056776335849615e-17" />
      <geometry>
        <mesh filename="package:///transmission_ankle.stl" />
      </geometry>
    </collision>
    <inertial>
      <origin xyz="-0.033596086592530785553 -0.018380744754187272605 0.01412219960993155686" rpy="0 0 0" />
      <mass value="0.074310321213953561825" />
      <inertia ixx="4.1295450352451955518e-05" ixy="1.9886053203183185098e-06" ixz="2.0689203249184054627e-06" iyy="3.2625642523550437595e-05" iyz="9.9798202218794591873e-06" izz="5.1310130219953345595e-05" />
    </inertial>
  </link>
  <link name="closedloop9_B">
    <inertial>
      <origin xyz="0 0 0" rpy="0 0 0" />
      <mass value="1e-9" />
      <inertia ixx="0" ixy="0" ixz="0" iyy="0" iyz="0" izz="0" />
    </inertial>
  </link>
  <joint name="closedloop9_B_frame" type="fixed">
    <origin xyz="-0.035854717888629011879 -0.041706584673488200643 0.052249999999999990896" rpy="1.570796326794896558 -3.2748092031556818832e-31 -3.1415926535897913396" />
    <parent link="transmission_ankle" />
    <child link="closedloop9_B" />
    <axis xyz="0 0 0" />
  </joint>
  <link name="part_7_2">
    <visual>
      <origin xyz="0.062087559207389841909 -0.15255026628033760416 -0.4000000000000000222" rpy="-4.389542914842480084e-32 1.4408326338524456722e-17 -1.5423037788631492986e-31" />
      <geometry>
        <mesh filename="package:///part_7.stl" />
      </geometry>
      <material name="part_7_material">
        <color rgba="0.91764705882352937127 0.91764705882352937127 0.91764705882352937127 1.0" />
      </material>
    </visual>
    <collision>
      <origin xyz="0.062087559207389841909 -0.15255026628033760416 -0.4000000000000000222" rpy="-4.389542914842480084e-32 1.4408326338524456722e-17 -1.5423037788631492986e-31" />
      <geometry>
        <mesh filename="package:///part_7.stl" />
      </geometry>
    </collision>
    <inertial>
      <origin xyz="6.9388939039072283776e-18 3.7051421436559636589e-32 -0.19999999999999998335" rpy="0 0 0" />
      <mass value="0.031415926535897982508" />
      <inertia ixx="0.00041907537001948915118" ixy="-5.552485011830743638e-35" ixz="-6.0077333206703653247e-21" iyy="0.00041907537001948915118" iyz="-1.8341544931889713568e-35" izz="3.9269908169872559526e-07" />
    </inertial>
  </link>
  <link name="closedloop11_B">
    <inertial>
      <origin xyz="0 0 0" rpy="0 0 0" />
      <mass value="1e-9" />
      <inertia ixx="0" ixy="0" ixz="0" iyy="0" iyz="0" izz="0" />
    </inertial>
  </link>
  <joint name="closedloop11_B_frame" type="fixed">
    <origin xyz="0 2.7755575615628913511e-17 -0.39999999999999996669" rpy="3.1415926535897895633 -3.9070079812038025555e-16 1.570796326794896558" />
    <parent link="part_7_2" />
    <child link="closedloop11_B" />
    <axis xyz="0 0 0" />
  </joint>
  <joint name="knee_transmission_2" type="revolute">
    <origin xyz="-0.21747050071615170452 -0.33571800862966272305 -0.010000000000000064393" rpy="3.141592653589793116 2.1953367209117600024e-15 3.0659322643825968058" />
    <parent link="part_2" />
    <child link="transmission_ankle" />
    <axis xyz="0 0 1" />
    <limit effort="1" velocity="20" />
    <joint_properties friction="0.0" />
  </joint>
  <link name="part_4">
    <visual>
      <origin xyz="-0.010530049701071075852 0.092146047735299219106 -0.071500000000000007994" rpy="-1.570796326794896558 -1.570796326794896558 0" />
      <geometry>
        <mesh filename="package:///part_4.stl" />
      </geometry>
      <material name="part_4_material">
        <color rgba="1 0.7568627450980391913 0.054901960784313724728 1.0" />
      </material>
    </visual>
    <collision>
      <origin xyz="-0.010530049701071075852 0.092146047735299219106 -0.071500000000000007994" rpy="-1.570796326794896558 -1.570796326794896558 0" />
      <geometry>
        <mesh filename="package:///part_4.stl" />
      </geometry>
    </collision>
    <inertial>
      <origin xyz="0.019483726843524864364 -0.046047631733748345395 0" rpy="0 0 0" />
      <mass value="0.011311035579799526632" />
      <inertia ixx="1.0009836990585404797e-05" ixy="4.1536946028868310457e-06" ixz="3.1372276733766616975e-37" iyy="1.9505556032253776816e-06" iyz="5.4148837522447928884e-38" izz="1.1771875334147456995e-05" />
    </inertial>
  </link>
  <link name="closedloop6_A">
    <inertial>
      <origin xyz="0 0 0" rpy="0 0 0" />
      <mass value="1e-9" />
      <inertia ixx="0" ixy="0" ixz="0" iyy="0" iyz="0" izz="0" />
    </inertial>
  </link>
  <joint name="closedloop6_A_frame" type="fixed">
    <origin xyz="0.038967453687049763422 -0.092095263467496704668 0" rpy="1.570796326794896558 -5.7748320244677594273e-24 -1.570796326794896336" />
    <parent link="part_4" />
    <child link="closedloop6_A" />
    <axis xyz="0 0 0" />
  </joint>
  <link name="part_5">
    <visual>
      <origin xyz="0.063404956281616769997 0.053322112528135678922 0" rpy="3.141592653589793116 -1.1300511501620222314e-17 -2.0805099756920142149e-18" />
      <geometry>
        <mesh filename="package:///part_5.stl" />
      </geometry>
      <material name="part_5_material">
        <color rgba="0.91764705882352937127 0.91764705882352937127 0.91764705882352937127 1.0" />
      </material>
    </visual>
    <collision>
      <origin xyz="0.063404956281616769997 0.053322112528135678922 0" rpy="3.141592653589793116 -1.1300511501620222314e-17 -2.0805099756920142149e-18" />
      <geometry>
        <mesh filename="package:///part_5.stl" />
      </geometry>
    </collision>
    <inertial>
      <origin xyz="0 4.1792121910006938696e-17 -0.070709999999999995079" rpy="0 0 0" />
      <mass value="0.011107100826766714077" />
      <inertia ixx="1.8580899034455380096e-05" ixy="1.0684643245767610146e-22" ixz="2.180379539523984552e-22" iyy="1.8580899034455386872e-05" iyz="-1.3706830874932091647e-23" izz="1.3883876033458398932e-07" />
    </inertial>
  </link>
  <link name="closedloop7_A">
    <inertial>
      <origin xyz="0 0 0" rpy="0 0 0" />
      <mass value="1e-9" />
      <inertia ixx="0" ixy="0" ixz="0" iyy="0" iyz="0" izz="0" />
    </inertial>
  </link>
  <joint name="closedloop7_A_frame" type="fixed">
    <origin xyz="0 5.5511151231257827021e-17 -0.14141999999999999016" rpy="-3.141592653589793116 -1.2232281396413594261e-16 1.505751559102670748e-16" />
    <parent link="part_5" />
    <child link="closedloop7_A" />
    <axis xyz="0 0 0" />
  </joint>
  <joint name="sherical_4bar" type="revolute">
    <origin xyz="0.019483726843524923344 -0.046047631733748387028 0" rpy="-1.57079632679489678 0.033617431841822156824 -1.5707963267948954478" />
    <parent link="part_4" />
    <child link="part_5" />
    <axis xyz="0 0 1" />
    <limit effort="1" velocity="20" />
    <joint_properties friction="0.0" />
  </joint>
  <joint name="4barlink_knee" type="revolute">
    <origin xyz="0.046047631733746000049 -0.019483726843523341277 0" rpy="3.141592653589793116 -2.0953369411995213608e-17 -1.2672660179279418013" />
    <parent link="part_2" />
    <child link="part_4" />
    <axis xyz="0 0 1" />
    <limit effort="1" velocity="20" />
    <joint_properties friction="0.0" />
  </joint>
  <link name="rotation_motor">
    <visual>
      <origin xyz="0.033000000000000001554 0.88825000000000031708 -0.10449999999999906586" rpy="1.570796326794896558 1.5707963267948930053 0" />
      <geometry>
        <mesh filename="package:///rotation_motor.stl" />
      </geometry>
      <material name="rotation_motor_material">
        <color rgba="1 0 0 1.0" />
      </material>
    </visual>
    <collision>
      <origin xyz="0.033000000000000001554 0.88825000000000031708 -0.10449999999999906586" rpy="1.570796326794896558 1.5707963267948930053 0" />
      <geometry>
        <mesh filename="package:///rotation_motor.stl" />
      </geometry>
    </collision>
    <inertial>
      <origin xyz="1.1089102675037425126e-17 1.1102230246251565404e-16 -0.017243243243243222551" rpy="0 0 0" />
      <mass value="0.19339251676417062997" />
      <inertia ixx="4.9207470246053547824e-05" ixy="-1.7988934217760573118e-21" ixz="3.3571905543948014317e-22" iyy="4.9207470246053547824e-05" iyz="-5.5896554346979924428e-20" izz="3.3697502678236654502e-05" />
    </inertial>
  </link>
  <link name="cylinder_3">
    <visual>
      <origin xyz="-0.10179556944408765795 0.15392457132099854333 -0.85799999999999987388" rpy="-4.1953019880065188266e-17 5.0773032155226757187e-18 -9.3508176160679138869e-17" />
      <geometry>
        <mesh filename="package:///cylinder.stl" />
      </geometry>
      <material name="cylinder_material">
        <color rgba="0.91764705882352937127 0.91764705882352937127 0.91764705882352937127 1.0" />
      </material>
    </visual>
    <collision>
      <origin xyz="-0.10179556944408765795 0.15392457132099854333 -0.85799999999999987388" rpy="-4.1953019880065188266e-17 5.0773032155226757187e-18 -9.3508176160679138869e-17" />
      <geometry>
        <mesh filename="package:///cylinder.stl" />
      </geometry>
    </collision>
    <inertial>
      <origin xyz="0 6.2055422165643366172e-18 -0.01100000000000000977" rpy="0 0 0" />
      <mass value="0.0047041422996690132607" />
      <inertia ixx="2.6977766073778931429e-07" ixy="-1.7186342562301926889e-23" ixz="-2.4765185528175857906e-24" iyy="2.6977766073778931429e-07" iyz="-1.359197495481311973e-23" izz="1.6008784263561083015e-07" />
    </inertial>
  </link>
  <link name="closedloop8_A">
    <inertial>
      <origin xyz="0 0 0" rpy="0 0 0" />
      <mass value="1e-9" />
      <inertia ixx="0" ixy="0" ixz="0" iyy="0" iyz="0" izz="0" />
    </inertial>
  </link>
  <joint name="closedloop8_A_frame" type="fixed">
    <origin xyz="0 5.5511151231257827021e-17 -0.022000000000000213829" rpy="-3.141592653589793116 -6.0722954362721615853e-17 -1.570796326794896336" />
    <parent link="cylinder_3" />
    <child link="closedloop8_A" />
    <axis xyz="0 0 0" />
  </joint>
  <joint name="motor_knee" type="prismatic">
    <origin xyz="-2.7755575615628913511e-17 2.7755575615628913511e-17 -0.022568234725387908979" rpy="3.141592653589793116 1.6075711619745091793e-15 -4.0446422624590046478e-15" />
    <parent link="rotation_motor" />
    <child link="cylinder_3" />
    <axis xyz="0 0 1" />
    <limit effort="1" velocity="20" />
    <joint_properties friction="0.0" />
  </joint>
  <joint name="frame_motor_knee" type="revolute">
    <origin xyz="-0.061655078133537342955 -0.018724201373191751152 4.2972847502653621632e-12" rpy="-1.5707963267948970021 1.2771385194773068328 -0.60601731071218267743" />
    <parent link="part_2" />
    <child link="rotation_motor" />
    <axis xyz="0 0 1" />
    <limit effort="1" velocity="20" />
    <joint_properties friction="0.0" />
  </joint>
  <joint name="upper_knee" type="revolute">
    <origin xyz="-6.5919492087118669588e-17 0.046751999999999988011 -0.07150000000000009126" rpy="-3.1415926535897855665 -5.4851651532674043147e-15 0.72447699933333153943" />
    <parent link="part_1" />
    <child link="part_2" />
    <axis xyz="0 0 1" />
    <limit effort="1" velocity="20" />
    <joint_properties friction="0.0" />
  </joint>
  <link name="part_8">
    <visual>
      <origin xyz="0 -0.046752000000000043523 0.087999999999999967137" rpy="1.570796326794896558 1.570796326794896558 0" />
      <geometry>
        <mesh filename="package:///part_8.stl" />
      </geometry>
      <material name="part_8_material">
        <color rgba="0.49803921568627451677 0.49803921568627451677 0.49803921568627451677 1.0" />
      </material>
    </visual>
    <collision>
      <origin xyz="0 -0.046752000000000043523 0.087999999999999967137" rpy="1.570796326794896558 1.570796326794896558 0" />
      <geometry>
        <mesh filename="package:///part_8.stl" />
      </geometry>
    </collision>
    <inertial>
      <origin xyz="0.031934770108260172872 0.010733820853410597218 -0.0056648401062836251096" rpy="0 0 0" />
      <mass value="0.0062040903886272707676" />
      <inertia ixx="9.174211164042201537e-07" ixy="-1.6316603808924180208e-07" ixz="2.2769789117187752367e-07" iyy="1.3280669465102740276e-06" iyz="-1.4783479338790852224e-07" izz="1.7548720440932144339e-06" />
    </inertial>
  </link>
  <link name="cylinder_4">
    <visual>
      <origin xyz="-0.10179556944408765795 -0.15392457132099843231 0.83600000000000007638" rpy="-3.141592653589793116 8.4503870823467951101e-18 -8.8325662762901629775e-17" />
      <geometry>
        <mesh filename="package:///cylinder.stl" />
      </geometry>
      <material name="cylinder_material">
        <color rgba="0.91764705882352937127 0.91764705882352937127 0.91764705882352937127 1.0" />
      </material>
    </visual>
    <collision>
      <origin xyz="-0.10179556944408765795 -0.15392457132099843231 0.83600000000000007638" rpy="-3.141592653589793116 8.4503870823467951101e-18 -8.8325662762901629775e-17" />
      <geometry>
        <mesh filename="package:///cylinder.stl" />
      </geometry>
    </collision>
    <inertial>
      <origin xyz="-1.3877787807814456755e-17 -5.3831151469177711818e-17 -0.010999999999999787725" rpy="0 0 0" />
      <mass value="0.0047041422996690132607" />
      <inertia ixx="2.6977766073778920841e-07" ixy="-2.4738480177638826212e-23" ixz="-2.8431519103760395073e-24" iyy="2.6977766073778920841e-07" iyz="3.3688184424380707402e-23" izz="1.6008784263561083015e-07" />
    </inertial>
  </link>
  <link name="closedloop1_B">
    <inertial>
      <origin xyz="0 0 0" rpy="0 0 0" />
      <mass value="1e-9" />
      <inertia ixx="0" ixy="0" ixz="0" iyy="0" iyz="0" izz="0" />
    </inertial>
  </link>
  <joint name="closedloop1_B_frame" type="fixed">
    <origin xyz="-5.5511151231257827021e-17 -5.5511151231257827021e-17 -0.02200000000000001954" rpy="-3.1415926535897904515 2.0111125192863830092e-15 -1.570796326794896336" />
    <parent link="cylinder_4" />
    <child link="closedloop1_B" />
    <axis xyz="0 0 0" />
  </joint>
  <link name="part_7_3">
    <visual>
      <origin xyz="0.062087559207389841909 -0.15255026628033754865 -0.4000000000000000222" rpy="-9.4573712719047329459e-18 -1.042331617648009064e-16 2.1613189605137239451e-18" />
      <geometry>
        <mesh filename="package:///part_7.stl" />
      </geometry>
      <material name="part_7_material">
        <color rgba="0.91764705882352937127 0.91764705882352937127 0.91764705882352937127 1.0" />
      </material>
    </visual>
    <collision>
      <origin xyz="0.062087559207389841909 -0.15255026628033754865 -0.4000000000000000222" rpy="-9.4573712719047329459e-18 -1.042331617648009064e-16 2.1613189605137239451e-18" />
      <geometry>
        <mesh filename="package:///part_7.stl" />
      </geometry>
    </collision>
    <inertial>
      <origin xyz="-6.9388939039072283776e-18 5.6647199104003628762e-17 -0.19999999999999992784" rpy="0 0 0" />
      <mass value="0.031415926535897982508" />
      <inertia ixx="0.00041907537001948915118" ixy="3.2521012878445097591e-21" ixz="4.3676178338764574661e-20" iyy="0.00041907537001948915118" iyz="-3.9608572569536742782e-21" izz="3.9269908169872580702e-07" />
    </inertial>
  </link>
  <link name="closedloop10_A">
    <inertial>
      <origin xyz="0 0 0" rpy="0 0 0" />
      <mass value="1e-9" />
      <inertia ixx="0" ixy="0" ixz="0" iyy="0" iyz="0" izz="0" />
    </inertial>
  </link>
  <joint name="closedloop10_A_frame" type="fixed">
    <origin xyz="0 0 -0.4000000000000000222" rpy="1.4735023840744858996e-16 6.8620917561167023512e-16 -4.2558792724255830793e-16" />
    <parent link="part_7_3" />
    <child link="closedloop10_A" />
    <axis xyz="0 0 0" />
  </joint>
  <joint name="hip_transmission_1" type="revolute">
    <origin xyz="-6.9388939039072283776e-17 0.046751999999999988011 -0.087999999999999994893" rpy="7.0625044874992382189e-15 -6.8120459426221159297e-15 1.0736013892061464503" />
    <parent link="part_1" />
    <child link="part_8" />
    <axis xyz="0 0 1" />
    <limit effort="1" velocity="20" />
    <joint_properties friction="0.0" />
  </joint>
  <link name="part_9">
    <visual>
      <origin xyz="-2.7755575615628913511e-17 0.046752000000000015767 -0.054999999999999993339" rpy="-1.570796326794896558 -1.570796326794896558 0" />
      <geometry>
        <mesh filename="package:///part_9.stl" />
      </geometry>
      <material name="part_9_material">
        <color rgba="0.49803921568627451677 0.49803921568627451677 0.49803921568627451677 1.0" />
      </material>
    </visual>
    <collision>
      <origin xyz="-2.7755575615628913511e-17 0.046752000000000015767 -0.054999999999999993339" rpy="-1.570796326794896558 -1.570796326794896558 0" />
      <geometry>
        <mesh filename="package:///part_9.stl" />
      </geometry>
    </collision>
    <inertial>
      <origin xyz="0.031934770108260138177 -0.010733820853410619769 -0.0056648401062835765374" rpy="0 0 0" />
      <mass value="0.0062040903886272699003" />
      <inertia ixx="9.1742111640423349447e-07" ixy="1.6316603808924365497e-07" ixz="2.2769789117187741779e-07" iyy="1.3280669465102725453e-06" iyz="1.4783479338790955456e-07" izz="1.7548720440932269276e-06" />
    </inertial>
  </link>
  <link name="cylinder_5">
    <visual>
      <origin xyz="-0.1017955694440876302 -0.15392457132099823802 0.83600000000000007638" rpy="3.141592653589793116 1.1216605826202253959e-17 -5.9537328437594727336e-17" />
      <geometry>
        <mesh filename="package:///cylinder.stl" />
      </geometry>
      <material name="cylinder_material">
        <color rgba="0.91764705882352937127 0.91764705882352937127 0.91764705882352937127 1.0" />
      </material>
    </visual>
    <collision>
      <origin xyz="-0.1017955694440876302 -0.15392457132099823802 0.83600000000000007638" rpy="3.141592653589793116 1.1216605826202253959e-17 -5.9537328437594727336e-17" />
      <geometry>
        <mesh filename="package:///cylinder.stl" />
      </geometry>
    </collision>
    <inertial>
      <origin xyz="-2.7755575615628913511e-17 7.754784939455351064e-17 -0.01100000000000000977" rpy="0 0 0" />
      <mass value="0.0047041422996690132607" />
      <inertia ixx="2.6977766073778931429e-07" ixy="-1.8659830905020394145e-23" ixz="6.6059985217953245973e-24" iyy="2.6977766073778920841e-07" iyz="1.4356672836162850936e-25" izz="1.6008784263561088309e-07" />
    </inertial>
  </link>
  <link name="closedloop2_B">
    <inertial>
      <origin xyz="0 0 0" rpy="0 0 0" />
      <mass value="1e-9" />
      <inertia ixx="0" ixy="0" ixz="0" iyy="0" iyz="0" izz="0" />
    </inertial>
  </link>
  <joint name="closedloop2_B_frame" type="fixed">
    <origin xyz="2.7755575615628913511e-17 0 -0.02200000000000001954" rpy="3.1415926535897917837 3.0726606491544917811e-15 -1.570796326794896558" />
    <parent link="cylinder_5" />
    <child link="closedloop2_B" />
    <axis xyz="0 0 0" />
  </joint>
  <link name="part_7_4">
    <visual>
      <origin xyz="0.062087559207389869664 -0.15255026628033760416 -0.4000000000000000222" rpy="-1.1394404642027517755e-16 9.7905229845103463093e-18 2.2284503126478838171e-17" />
      <geometry>
        <mesh filename="package:///part_7.stl" />
      </geometry>
      <material name="part_7_material">
        <color rgba="0.91764705882352937127 0.91764705882352937127 0.91764705882352937127 1.0" />
      </material>
    </visual>
    <collision>
      <origin xyz="0.062087559207389869664 -0.15255026628033760416 -0.4000000000000000222" rpy="-1.1394404642027517755e-16 9.7905229845103463093e-18 2.2284503126478838171e-17" />
      <geometry>
        <mesh filename="package:///part_7.stl" />
      </geometry>
    </collision>
    <inertial>
      <origin xyz="2.7755575615628913511e-17 1.0904753764920037321e-17 -0.2000000000000000111" rpy="0 0 0" />
      <mass value="0.031415926535897982508" />
      <inertia ixx="0.00041907537001948915118" ixy="2.3561138474004321906e-20" ixz="-4.1009741137783306495e-21" iyy="0.00041907537001948915118" iyz="-4.7727015307734565219e-20" izz="3.9269908169872548938e-07" />
    </inertial>
  </link>
  <link name="closedloop9_A">
    <inertial>
      <origin xyz="0 0 0" rpy="0 0 0" />
      <mass value="1e-9" />
      <inertia ixx="0" ixy="0" ixz="0" iyy="0" iyz="0" izz="0" />
    </inertial>
  </link>
  <joint name="closedloop9_A_frame" type="fixed">
    <origin xyz="0 -8.3266726846886740532e-17 -0.4000000000000000222" rpy="-2.3952719085374775399e-15 -9.8359338965770896915e-16 -1.5707963267948972241" />
    <parent link="part_7_4" />
    <child link="closedloop9_A" />
    <axis xyz="0 0 0" />
  </joint>
  <joint name="hip_transmission_2" type="revolute">
    <origin xyz="-6.2450045135165055399e-17 0.046751999999999988011 -0.055000000000000021094" rpy="-3.1415926535897860106 -7.0534351170114349528e-15 1.0500864465451529295" />
    <parent link="part_1" />
    <child link="part_9" />
    <axis xyz="0 0 1" />
    <limit effort="1" velocity="20" />
    <joint_properties friction="0.0" />
  </joint>
  <link name="cylinder_6">
    <visual>
      <origin xyz="-0.10179556944408768571 0.15392457132099848782 -0.8579999999999999849" rpy="-1.096194281328379359e-17 -2.352890010273287309e-18 3.2640360997101456778e-17" />
      <geometry>
        <mesh filename="package:///cylinder.stl" />
      </geometry>
      <material name="cylinder_material">
        <color rgba="0.91764705882352937127 0.91764705882352937127 0.91764705882352937127 1.0" />
      </material>
    </visual>
    <collision>
      <origin xyz="-0.10179556944408768571 0.15392457132099848782 -0.8579999999999999849" rpy="-1.096194281328379359e-17 -2.352890010273287309e-18 3.2640360997101456778e-17" />
      <geometry>
        <mesh filename="package:///cylinder.stl" />
      </geometry>
    </collision>
    <inertial>
      <origin xyz="-1.3877787807814456755e-17 -1.9724276230554723826e-17 -0.011000000000000120792" rpy="0 0 0" />
      <mass value="0.0047041422996690132607" />
      <inertia ixx="2.6977766073778931429e-07" ixy="1.6222979441191178977e-23" ixz="2.4435282604952561319e-24" iyy="2.6977766073778931429e-07" iyz="-2.0673245257086825587e-24" izz="1.6008784263561083015e-07" />
    </inertial>
  </link>
  <link name="closedloop8_B">
    <inertial>
      <origin xyz="0 0 0" rpy="0 0 0" />
      <mass value="1e-9" />
      <inertia ixx="0" ixy="0" ixz="0" iyy="0" iyz="0" izz="0" />
    </inertial>
  </link>
  <joint name="closedloop8_B_frame" type="fixed">
    <origin xyz="5.5511151231257827021e-17 1.4745149545802860303e-17 -0.022000000000000061173" rpy="9.260101808175594684e-16 -6.0667578152815541166e-16 1.5707963267948974462" />
    <parent link="cylinder_6" />
    <child link="closedloop8_B" />
    <axis xyz="0 0 0" />
  </joint>
  <link name="rotation_motor_2">
    <visual>
      <origin xyz="0.032999999999999973799 0.88825000000000020606 -0.10449999999999906586" rpy="1.570796326794896558 1.5707963267948930053 0" />
      <geometry>
        <mesh filename="package:///rotation_motor.stl" />
      </geometry>
      <material name="rotation_motor_material">
        <color rgba="1 0 0 1.0" />
      </material>
    </visual>
    <collision>
      <origin xyz="0.032999999999999973799 0.88825000000000020606 -0.10449999999999906586" rpy="1.570796326794896558 1.5707963267948930053 0" />
      <geometry>
        <mesh filename="package:///rotation_motor.stl" />
      </geometry>
    </collision>
    <inertial>
      <origin xyz="-5.4124136762963323675e-17 0 -0.017243243243243236429" rpy="0 0 0" />
      <mass value="0.19339251676417062997" />
      <inertia ixx="4.9207470246053547824e-05" ixy="2.9715388812645594822e-21" ixz="1.3688581851601861445e-21" iyy="4.9207470246053547824e-05" iyz="-5.6861006730007895499e-20" izz="3.3697502678236654502e-05" />
    </inertial>
  </link>
  <link name="cylinder_7">
    <visual>
      <origin xyz="-0.1017955694440876302 -0.15392457132099851558 0.83599999999999985434" rpy="-3.141592653589793116 2.3894623988558647799e-19 -6.7387693774437449074e-17" />
      <geometry>
        <mesh filename="package:///cylinder.stl" />
      </geometry>
      <material name="cylinder_material">
        <color rgba="0.91764705882352937127 0.91764705882352937127 0.91764705882352937127 1.0" />
      </material>
    </visual>
    <collision>
      <origin xyz="-0.1017955694440876302 -0.15392457132099851558 0.83599999999999985434" rpy="-3.141592653589793116 2.3894623988558647799e-19 -6.7387693774437449074e-17" />
      <geometry>
        <mesh filename="package:///cylinder.stl" />
      </geometry>
    </collision>
    <inertial>
      <origin xyz="2.7755575615628913511e-17 -3.9923988969831751414e-17 -0.010999999999999898748" rpy="0 0 0" />
      <mass value="0.0047041422996690132607" />
      <inertia ixx="2.6977766073778931429e-07" ixy="1.3595455184845708085e-24" ixz="1.4133828815673571835e-24" iyy="2.6977766073778920841e-07" iyz="2.429270556828382068e-24" izz="1.6008784263561077721e-07" />
    </inertial>
  </link>
  <link name="closedloop1_A">
    <inertial>
      <origin xyz="0 0 0" rpy="0 0 0" />
      <mass value="1e-9" />
      <inertia ixx="0" ixy="0" ixz="0" iyy="0" iyz="0" izz="0" />
    </inertial>
  </link>
  <joint name="closedloop1_A_frame" type="fixed">
    <origin xyz="0 0 -0.02200000000000001954" rpy="-2.7819127417443369016e-15 4.1538050120666868689e-17 -7.0215725374297579137e-17" />
    <parent link="cylinder_7" />
    <child link="closedloop1_A" />
    <axis xyz="0 0 0" />
  </joint>
  <joint name="motor_ankle2" type="prismatic">
    <origin xyz="-5.5511151231257827021e-17 -8.3266726846886740532e-17 0.051330395129961847722" rpy="3.141592653589793116 1.8208947195106360443e-14 3.1415926535897815697" />
    <parent link="rotation_motor_2" />
    <child link="cylinder_7" />
    <axis xyz="0 0 1" />
    <limit effort="1" velocity="20" />
    <joint_properties friction="0.0" />
  </joint>
  <joint name="frame_motor_foot1" type="revolute">
    <origin xyz="0.054086706326755197571 0.014047405294960763067 -0.118249999999999994" rpy="-1.570796326794896558 0.70569698106852796204 0.2858933777993261649" />
    <parent link="part_1" />
    <child link="rotation_motor_2" />
    <axis xyz="0 0 1" />
    <limit effort="1" velocity="20" />
    <joint_properties friction="0.0" />
  </joint>
  <link name="rotation_motor_3">
    <visual>
      <origin xyz="0.033000000000000098699 0.88825000000000031708 -0.10449999999999906586" rpy="1.570796326794896558 1.5707963267948930053 0" />
      <geometry>
        <mesh filename="package:///rotation_motor.stl" />
      </geometry>
      <material name="rotation_motor_material">
        <color rgba="1 0 0 1.0" />
      </material>
    </visual>
    <collision>
      <origin xyz="0.033000000000000098699 0.88825000000000031708 -0.10449999999999906586" rpy="1.570796326794896558 1.5707963267948930053 0" />
      <geometry>
        <mesh filename="package:///rotation_motor.stl" />
      </geometry>
    </collision>
    <inertial>
      <origin xyz="3.4685363772641194613e-17 -1.1102230246251565404e-16 -0.017243243243243236429" rpy="0 0 0" />
      <mass value="0.19339251676417062997" />
      <inertia ixx="4.9207470246053574929e-05" ixy="3.2401734660729780714e-22" ixz="5.872290902427135467e-22" iyy="4.9207470246053574929e-05" iyz="-5.6948859762252479514e-20" izz="3.3697502678236654502e-05" />
    </inertial>
  </link>
  <link name="cylinder_8">
    <visual>
      <origin xyz="-0.10179556944408767183 -0.15392457132099851558 0.83600000000000007638" rpy="-3.141592653589793116 -2.3467809445344488647e-17 4.0915515566894001314e-18" />
      <geometry>
        <mesh filename="package:///cylinder.stl" />
      </geometry>
      <material name="cylinder_material">
        <color rgba="0.91764705882352937127 0.91764705882352937127 0.91764705882352937127 1.0" />
      </material>
    </visual>
    <collision>
      <origin xyz="-0.10179556944408767183 -0.15392457132099851558 0.83600000000000007638" rpy="-3.141592653589793116 -2.3467809445344488647e-17 4.0915515566894001314e-18" />
      <geometry>
        <mesh filename="package:///cylinder.stl" />
      </geometry>
    </collision>
    <inertial>
      <origin xyz="-2.7755575615628913511e-17 -3.3075112507033638872e-19 -0.010999999999999787725" rpy="0 0 0" />
      <mass value="0.0047041422996690132607" />
      <inertia ixx="2.6977766073778931429e-07" ixy="-1.1196181807342188736e-24" ixz="8.0486640391560114133e-24" iyy="2.6977766073778931429e-07" iyz="2.1981164976484690993e-25" izz="1.6008784263561083015e-07" />
    </inertial>
  </link>
  <link name="closedloop2_A">
    <inertial>
      <origin xyz="0 0 0" rpy="0 0 0" />
      <mass value="1e-9" />
      <inertia ixx="0" ixy="0" ixz="0" iyy="0" iyz="0" izz="0" />
    </inertial>
  </link>
  <joint name="closedloop2_A_frame" type="fixed">
    <origin xyz="-1.3877787807814456755e-17 -2.7755575615628913511e-17 -0.021999999999999880762" rpy="-1.3082333062209864418e-15 3.1484991343763797587e-15 5.5969162711631674861e-17" />
    <parent link="cylinder_8" />
    <child link="closedloop2_A" />
    <axis xyz="0 0 0" />
  </joint>
  <joint name="motor_ankle1" type="prismatic">
    <origin xyz="9.7144514654701197287e-17 1.6653345369377348106e-16 0.048590062929759286758" rpy="3.141592653589793116 6.5278587787792881949e-16 3.1415926535897922278" />
    <parent link="rotation_motor_3" />
    <child link="cylinder_8" />
    <axis xyz="0 0 1" />
    <limit effort="1" velocity="20" />
    <joint_properties friction="0.0" />
  </joint>
  <joint name="frame_motor_foot2" type="revolute">
    <origin xyz="0.054086706326755190632 0.014047405294960790823 -0.024749999999999966471" rpy="1.570796326794896558 -0.16946695988620705253 -2.8556992757904748892" />
    <parent link="part_1" />
    <child link="rotation_motor_3" />
    <axis xyz="0 0 1" />
    <limit effort="1" velocity="20" />
    <joint_properties friction="0.0" />
  </joint>
  <joint name="lower_hip" type="revolute">
    <origin xyz="6.6000000000010494716e-05 -8.3266726846886740532e-17 -6.5999999999998351652e-05" rpy="1.5707963267949149877 -1.4738036229882285344 1.5707963267948861219" />
    <parent link="universal_foot" />
    <child link="part_1" />
    <axis xyz="0 0 1" />
    <limit effort="1" velocity="20" />
    <joint_properties friction="0.0" />
  </joint>
  <joint name="free_universal_yhip" type="revolute">
    <origin xyz="-1.7347234759768070944e-18 0 -0.1649999999999999245" rpy="1.570796326794896558 -9.6290805123406329139e-15 -1.5707963267948992225" />
    <parent link="hip_part" />
    <child link="universal_foot" />
    <axis xyz="0 0 1" />
    <limit effort="1" velocity="20" />
    <joint_properties friction="0.0" />
  </joint>
  <link name="universal_hip">
    <visual>
      <origin xyz="0.10862499999999999933 0.85800000000000009592 -0.0055000000000023745172" rpy="1.570796326794896558 1.5707963267948930053 0" />
      <geometry>
        <mesh filename="package:///universal_hip.stl" />
      </geometry>
      <material name="universal_hip_material">
        <color rgba="0.49803921568627451677 0.49803921568627451677 0.49803921568627451677 1.0" />
      </material>
    </visual>
    <collision>
      <origin xyz="0.10862499999999999933 0.85800000000000009592 -0.0055000000000023745172" rpy="1.570796326794896558 1.5707963267948930053 0" />
      <geometry>
        <mesh filename="package:///universal_hip.stl" />
      </geometry>
    </collision>
    <inertial>
      <origin xyz="-1.2814324404039028322e-17 1.5061285552064873627e-11 -0.034629677480538460788" rpy="0 0 0" />
      <mass value="0.015608633111865791165" />
      <inertia ixx="5.7160316393851747746e-06" ixy="-1.9710864478227450685e-13" ixz="7.233014216829709516e-28" iyy="5.8966955959438793294e-06" iyz="9.5685519510128541059e-14" izz="7.2203526828754625758e-07" />
    </inertial>
  </link>
  <link name="motor_hip1">
    <visual>
      <origin xyz="-0.04950000000000076561 -0.8579999999999999849 -0.10862499999999999933" rpy="-1.570796326794896558 2.0923724469924999242e-19 1.7344072130991537971e-17" />
      <geometry>
        <mesh filename="package:///motor_hip1.stl" />
      </geometry>
      <material name="motor_hip1_material">
        <color rgba="1 0 0 1.0" />
      </material>
    </visual>
    <collision>
      <origin xyz="-0.04950000000000076561 -0.8579999999999999849 -0.10862499999999999933" rpy="-1.570796326794896558 2.0923724469924999242e-19 1.7344072130991537971e-17" />
      <geometry>
        <mesh filename="package:///motor_hip1.stl" />
      </geometry>
    </collision>
    <inertial>
      <origin xyz="0 -0.012713533519811970329 -1.7256394980978638259e-19" rpy="0 0 0" />
      <mass value="0.17794962537636810351" />
      <inertia ixx="3.4377373668620134326e-05" ixy="1.9433052384466326993e-22" ixz="-4.3746077328193967118e-25" iyy="4.1215284105260629674e-05" iyz="1.8419158835085521781e-23" izz="3.4002456645612650764e-05" />
    </inertial>
  </link>
  <link name="cylinder_9">
    <visual>
      <origin xyz="-0.10179556944408767183 0.15392457132099851558 -0.8579999999999999849" rpy="-1.1724203792441073848e-18 1.271413016531692378e-17 6.9832995624594233198e-20" />
      <geometry>
        <mesh filename="package:///cylinder.stl" />
      </geometry>
      <material name="cylinder_material">
        <color rgba="0.91764705882352937127 0.91764705882352937127 0.91764705882352937127 1.0" />
      </material>
    </visual>
    <collision>
      <origin xyz="-0.10179556944408767183 0.15392457132099851558 -0.8579999999999999849" rpy="-1.1724203792441073848e-18 1.271413016531692378e-17 6.9832995624594233198e-20" />
      <geometry>
        <mesh filename="package:///cylinder.stl" />
      </geometry>
    </collision>
    <inertial>
      <origin xyz="0 3.8441351112167189449e-19 -0.011000000000000120792" rpy="0 0 0" />
      <mass value="0.0047041422996690132607" />
      <inertia ixx="2.6977766073778931429e-07" ixy="-2.9930455258862611924e-26" ixz="-1.7039360541923354424e-24" iyy="2.6977766073778931429e-07" iyz="-2.4498005883618633073e-25" izz="1.6008784263561083015e-07" />
    </inertial>
  </link>
  <link name="closedloop4_B">
    <inertial>
      <origin xyz="0 0 0" rpy="0 0 0" />
      <mass value="1e-9" />
      <inertia ixx="0" ixy="0" ixz="0" iyy="0" iyz="0" izz="0" />
    </inertial>
  </link>
  <joint name="closedloop4_B_frame" type="fixed">
    <origin xyz="0 0 -0.021999999999999866884" rpy="-5.2342383182449044881e-14 8.2074296634245360986e-15 1.4117770487744005312e-18" />
    <parent link="cylinder_9" />
    <child link="closedloop4_B" />
    <axis xyz="0 0 0" />
  </joint>
  <joint name="motor_hip_xy1" type="prismatic">
    <origin xyz="4.1633363423443370266e-17 -0.050156290972289171992 -4.1633363423443370266e-16" rpy="-1.5707963267949502928 -8.1160902808362363988e-15 5.5693133426199995086e-15" />
    <parent link="motor_hip1" />
    <child link="cylinder_9" />
    <axis xyz="0 0 1" />
    <limit effort="1" velocity="20" />
    <joint_properties friction="0.0" />
  </joint>
  <joint name="free_motor_holder_hip_xy2" type="revolute">
    <origin xyz="-5.5511151231257827021e-17 -1.9428902930940239457e-16 -0.054999999999999979461" rpy="-1.570796326794866804 -1.5002260895475847402 1.5707963267948659158" />
    <parent link="universal_hip" />
    <child link="motor_hip1" />
    <axis xyz="0 0 1" />
    <limit effort="1" velocity="20" />
    <joint_properties friction="0.0" />
  </joint>
  <joint name="free_motor_holder_hip_1" type="revolute">
    <origin xyz="0.012500000000000035388 -0.037124999999999769296 -0.077000000000000096145" rpy="1.57079632679489678 -0.020021707956276633966 -1.5707963267948994446" />
    <parent link="hip_part" />
    <child link="universal_hip" />
    <axis xyz="0 0 1" />
    <limit effort="1" velocity="20" />
    <joint_properties friction="0.0" />
  </joint>
  <link name="universal_hip_2">
    <visual>
      <origin xyz="0.10862499999999997158 0.85800000000000020695 -0.0055000000000023710478" rpy="1.570796326794896558 1.5707963267948930053 0" />
      <geometry>
        <mesh filename="package:///universal_hip.stl" />
      </geometry>
      <material name="universal_hip_material">
        <color rgba="0.49803921568627451677 0.49803921568627451677 0.49803921568627451677 1.0" />
      </material>
    </visual>
    <collision>
      <origin xyz="0.10862499999999997158 0.85800000000000020695 -0.0055000000000023710478" rpy="1.570796326794896558 1.5707963267948930053 0" />
      <geometry>
        <mesh filename="package:///universal_hip.stl" />
      </geometry>
    </collision>
    <inertial>
      <origin xyz="-2.3420324726390038631e-17 1.5061174529762411112e-11 -0.034629677480538453849" rpy="0 0 0" />
      <mass value="0.015608633111865791165" />
      <inertia ixx="5.7160316393851730806e-06" ixy="-1.9710864482010920987e-13" ixz="7.2293654450218830484e-28" iyy="5.8966955959438827176e-06" iyz="9.5685519510128566302e-14" izz="7.2203526828754625758e-07" />
    </inertial>
  </link>
  <link name="motor_hip1_2">
    <visual>
      <origin xyz="-0.049500000000000744793 -0.8579999999999999849 -0.10862499999999997158" rpy="-1.570796326794896558 -4.0168632694757165873e-20 -6.869266110542954379e-18" />
      <geometry>
        <mesh filename="package:///motor_hip1.stl" />
      </geometry>
      <material name="motor_hip1_material">
        <color rgba="1 0 0 1.0" />
      </material>
    </visual>
    <collision>
      <origin xyz="-0.049500000000000744793 -0.8579999999999999849 -0.10862499999999997158" rpy="-1.570796326794896558 -4.0168632694757165873e-20 -6.869266110542954379e-18" />
      <geometry>
        <mesh filename="package:///motor_hip1.stl" />
      </geometry>
    </collision>
    <inertial>
      <origin xyz="1.3877787807814456755e-17 -0.012713533519811970329 1.5069624433967306979e-17" rpy="0 0 0" />
      <mass value="0.17794962537636810351" />
      <inertia ixx="3.4377373668620134326e-05" ixy="-1.0497564693561919635e-21" ixz="1.6215018943055104917e-23" iyy="4.1215284105260629674e-05" iyz="-4.7554037583987398559e-23" izz="3.4002456645612637212e-05" />
    </inertial>
  </link>
  <link name="cylinder_10">
    <visual>
      <origin xyz="-0.10179556944408767183 0.15392457132099851558 -0.85799999999999987388" rpy="-2.1217087060472441817e-18 1.6192319597765250137e-17 -2.8309895054126109052e-19" />
      <geometry>
        <mesh filename="package:///cylinder.stl" />
      </geometry>
      <material name="cylinder_material">
        <color rgba="0.91764705882352937127 0.91764705882352937127 0.91764705882352937127 1.0" />
      </material>
    </visual>
    <collision>
      <origin xyz="-0.10179556944408767183 0.15392457132099851558 -0.85799999999999987388" rpy="-2.1217087060472441817e-18 1.6192319597765250137e-17 -2.8309895054126109052e-19" />
      <geometry>
        <mesh filename="package:///cylinder.stl" />
      </geometry>
    </collision>
    <inertial>
      <origin xyz="2.7755575615628913511e-17 2.8572419643559236682e-17 -0.011000000000000120792" rpy="0 0 0" />
      <mass value="0.0047041422996690132607" />
      <inertia ixx="2.6977766073778942017e-07" ixy="-1.0454792415637112953e-25" ixz="-2.1646834088251899383e-24" iyy="2.6977766073778920841e-07" iyz="-4.1255461185025103069e-25" izz="1.6008784263561077721e-07" />
    </inertial>
  </link>
  <link name="closedloop3_B">
    <inertial>
      <origin xyz="0 0 0" rpy="0 0 0" />
      <mass value="1e-9" />
      <inertia ixx="0" ixy="0" ixz="0" iyy="0" iyz="0" izz="0" />
    </inertial>
  </link>
  <joint name="closedloop3_B_frame" type="fixed">
    <origin xyz="2.7755575615628913511e-17 -5.5511151231257827021e-17 -0.021999999999999964029" rpy="-3.7983807026823699256e-15 -3.1724293295329463046e-16 -2.1021659879463730673e-17" />
    <parent link="cylinder_10" />
    <child link="closedloop3_B" />
    <axis xyz="0 0 0" />
  </joint>
  <joint name="motor_hip_xy2" type="prismatic">
    <origin xyz="1.3877787807814456755e-17 -0.050153775555251425833 3.6082248300317587564e-16" rpy="-1.5707963267948996666 2.6021963268559055545e-15 1.4416055078510302742e-15" />
    <parent link="motor_hip1_2" />
    <child link="cylinder_10" />
    <axis xyz="0 0 1" />
    <limit effort="1" velocity="20" />
    <joint_properties friction="0.0" />
  </joint>
  <joint name="free_motor_holder_hip_xy1" type="revolute">
    <origin xyz="5.5511151231257827021e-17 -2.7755575615628913511e-17 -0.055000000000000007216" rpy="-1.5707963267948972241 1.5002236252432261665 1.5707963267949194286" />
    <parent link="universal_hip_2" />
    <child link="motor_hip1_2" />
    <axis xyz="0 0 1" />
    <limit effort="1" velocity="20" />
    <joint_properties friction="0.0" />
  </joint>
  <joint name="free_motor_holder_hip_3" type="revolute">
    <origin xyz="0.012499999999999965999 0.037125000000000268896 -0.077000000000000956568" rpy="-1.570796326794896558 -0.018188083207083823034 1.5707963267948941155" />
    <parent link="hip_part" />
    <child link="universal_hip_2" />
    <axis xyz="0 0 1" />
    <limit effort="1" velocity="20" />
    <joint_properties friction="0.0" />
  </joint>
  <link name="cylinder_11">
    <visual>
      <origin xyz="-0.10179556944408765795 0.15392457132099851558 -0.85799999999999987388" rpy="1.1682216644146530683e-30 1.9046860637395577431e-31 1.2679065777781923061e-18" />
      <geometry>
        <mesh filename="package:///cylinder.stl" />
      </geometry>
      <material name="cylinder_material">
        <color rgba="0.91764705882352937127 0.91764705882352937127 0.91764705882352937127 1.0" />
      </material>
    </visual>
    <collision>
      <origin xyz="-0.10179556944408765795 0.15392457132099851558 -0.85799999999999987388" rpy="1.1682216644146530683e-30 1.9046860637395577431e-31 1.2679065777781923061e-18" />
      <geometry>
        <mesh filename="package:///cylinder.stl" />
      </geometry>
    </collision>
    <inertial>
      <origin xyz="0 1.2906727208674783401e-19 -0.01100000000000000977" rpy="0 0 0" />
      <mass value="0.0047041422996690132607" />
      <inertia ixx="2.6977766073778931429e-07" ixy="8.6147331510139461319e-26" ixz="-5.0209075598383541691e-38" iyy="2.6977766073778931429e-07" iyz="2.9859003221318652705e-37" izz="1.6008784263561083015e-07" />
    </inertial>
  </link>
  <link name="closedloop5_B">
    <inertial>
      <origin xyz="0 0 0" rpy="0 0 0" />
      <mass value="1e-9" />
      <inertia ixx="0" ixy="0" ixz="0" iyy="0" iyz="0" izz="0" />
    </inertial>
  </link>
  <joint name="closedloop5_B_frame" type="fixed">
    <origin xyz="-2.7755575615628913511e-17 -1.3877787807814456755e-17 -0.022000000000000054234" rpy="3.1415926535897917837 9.3675067702748754064e-17 -1.570796326794896558" />
    <parent link="cylinder_11" />
    <child link="closedloop5_B" />
    <axis xyz="0 0 0" />
  </joint>
  <joint name="free_zhip" type="revolute">
    <origin xyz="0.012500000000000170697 0.20500000000000265232 -0.0050000000000000044409" rpy="1.0057557210906877445e-14 -7.6592250448352642693e-15 2.7755575615630239783e-16" />
    <parent link="hip_ground" />
    <child link="hip_part" />
    <axis xyz="0 0 1" />
    <limit effort="1" velocity="20" />
    <joint_properties friction="0.0" />
  </joint>
  <link name="holder_hip">
    <visual>
      <origin xyz="0.12099999999999910827 0.033000000000000057065 -0.94000000000000027978" rpy="-3.8210450096638870721e-31 -3.6701587590914498546e-15 6.1878822381959584147e-31" />
      <geometry>
        <mesh filename="package:///holder_hip.stl" />
      </geometry>
      <material name="holder_hip_material">
        <color rgba="0.64705882352941179736 0.64705882352941179736 0.64705882352941179736 1.0" />
      </material>
    </visual>
    <collision>
      <origin xyz="0.12099999999999910827 0.033000000000000057065 -0.94000000000000027978" rpy="-3.8210450096638870721e-31 -3.6701587590914498546e-15 6.1878822381959584147e-31" />
      <geometry>
        <mesh filename="package:///holder_hip.stl" />
      </geometry>
    </collision>
    <inertial>
      <origin xyz="2.7755575615628913511e-17 1.3877787807814731008e-17 -0.03000000000000024869" rpy="0 0 0" />
      <mass value="0.01282947899909727546" />
      <inertia ixx="4.0671453033231804464e-06" ixy="-3.2576371264085592286e-36" ixz="1.3324665874380655257e-20" iyy="4.0671453033231812934e-06" iyz="-1.3872464758811780873e-36" izz="4.366032071880294742e-07" />
    </inertial>
  </link>
  <link name="rotation_motor_4">
    <visual>
      <origin xyz="0.033000000000000057065 0.8882500000000004281 -0.12099999999999909439" rpy="1.570796326794896558 1.5707963267948930053 0" />
      <geometry>
        <mesh filename="package:///rotation_motor.stl" />
      </geometry>
      <material name="rotation_motor_material">
        <color rgba="1 0 0 1.0" />
      </material>
    </visual>
    <collision>
      <origin xyz="0.033000000000000057065 0.8882500000000004281 -0.12099999999999909439" rpy="1.570796326794896558 1.5707963267948930053 0" />
      <geometry>
        <mesh filename="package:///rotation_motor.stl" />
      </geometry>
    </collision>
    <inertial>
      <origin xyz="1.2328758607125273744e-17 2.2204460492503130808e-16 -0.033743243243243264962" rpy="0 0 0" />
      <mass value="0.19339251676417062997" />
      <inertia ixx="4.9207470246053547824e-05" ixy="3.4691714546122680101e-22" ixz="-1.388668614931130774e-35" iyy="4.9207470246053547824e-05" iyz="-5.6924043322247487608e-20" izz="3.3697502678236654502e-05" />
    </inertial>
  </link>
  <link name="cylinder_12">
    <visual>
      <origin xyz="-0.10179556944408765795 0.15392457132099854333 -0.8579999999999999849" rpy="-1.137459159429640519e-30 -2.5500570182873539204e-31 -1.2373741884625232068e-18" />
      <geometry>
        <mesh filename="package:///cylinder.stl" />
      </geometry>
      <material name="cylinder_material">
        <color rgba="0.91764705882352937127 0.91764705882352937127 0.91764705882352937127 1.0" />
      </material>
    </visual>
    <collision>
      <origin xyz="-0.10179556944408765795 0.15392457132099854333 -0.8579999999999999849" rpy="-1.137459159429640519e-30 -2.5500570182873539204e-31 -1.2373741884625232068e-18" />
      <geometry>
        <mesh filename="package:///cylinder.stl" />
      </geometry>
    </collision>
    <inertial>
      <origin xyz="-1.3877787807814456755e-17 2.7629616405498600593e-17 -0.011000000000000120792" rpy="0 0 0" />
      <mass value="0.0047041422996690132607" />
      <inertia ixx="2.6977766073778920841e-07" ixy="1.4416229916061300168e-24" ixz="-6.6685068897271543004e-38" iyy="2.6977766073778931429e-07" iyz="-3.7374769582368779902e-37" izz="1.6008784263561083015e-07" />
    </inertial>
  </link>
  <link name="closedloop5_A">
    <inertial>
      <origin xyz="0 0 0" rpy="0 0 0" />
      <mass value="1e-9" />
      <inertia ixx="0" ixy="0" ixz="0" iyy="0" iyz="0" izz="0" />
    </inertial>
  </link>
  <joint name="closedloop5_A_frame" type="fixed">
    <origin xyz="0 0 -0.021999999999999943212" rpy="4.0939474033053051719e-16 2.1380466841413257505e-16 6.2026386493102164692e-16" />
    <parent link="cylinder_12" />
    <child link="closedloop5_A" />
    <axis xyz="0 0 0" />
  </joint>
  <joint name="motor_hipz" type="prismatic">
    <origin xyz="-1.0547118733938987134e-15 -8.7430063189231077558e-16 -0.071500000000001451284" rpy="-2.1233015345958489363e-15 4.1282117760629273878e-17 -1.5707963267949134334" />
    <parent link="rotation_motor_4" />
    <child link="cylinder_12" />
    <axis xyz="0 0 1" />
    <limit effort="1" velocity="20" />
    <joint_properties friction="0.0" />
  </joint>
  <joint name="free_motor_holder_hip_2" type="revolute">
    <origin xyz="-0.10299999999999821798 0.24350000000000304734 0" rpy="-1.0047518372857614626e-14 7.4933038271172496209e-15 3.1415926535897793492" />
    <parent link="hip_ground" />
    <child link="holder_hip" />
    <axis xyz="0 0 1" />
    <limit effort="1" velocity="20" />
    <joint_properties friction="0.0" />
  </joint>
  <link name="part_1_int1_1">
    <inertial>
      <mass value="0.0" />
      <inertia ixx="0.0" ixy="0.0" ixz="0.0" iyy="0.0" iyz="0.0" izz="0.0" />
    </inertial>
  </link>
  <link name="part_1_int2_1">
    <inertial>
      <mass value="0.0" />
      <inertia ixx="0.0" ixy="0.0" ixz="0.0" iyy="0.0" iyz="0.0" izz="0.0" />
    </inertial>
  </link>
  <joint name="part_1_cylinder_rev0" type="revolute">
    <origin xyz="-0.060500000000000039857 -1.9428902930940239457e-16 -0.03850000000000006195" />
    <parent link="part_1" />
    <child link="part_1_int1_1" />
    <axis xyz="1 0 0" />
    <limit effort="1" velocity="20" />
  </joint>
  <joint name="part_1_cylinder_rev1" type="revolute">
    <parent link="part_1_int1_1" />
    <child link="part_1_int2_1" />
    <axis xyz="0 1 0" />
    <limit effort="1" velocity="20" />
  </joint>
  <joint name="part_1_cylinder_rev2" type="revolute">
    <parent link="part_1_int2_1" />
    <child link="cylinder" />
    <axis xyz="0 0 1" />
    <limit effort="1" velocity="20" />
  </joint>
  <link name="part_1_int1_2">
    <inertial>
      <mass value="0.0" />
      <inertia ixx="0.0" ixy="0.0" ixz="0.0" iyy="0.0" iyz="0.0" izz="0.0" />
    </inertial>
  </link>
  <link name="part_1_int2_2">
    <inertial>
      <mass value="0.0" />
      <inertia ixx="0.0" ixy="0.0" ixz="0.0" iyy="0.0" iyz="0.0" izz="0.0" />
    </inertial>
  </link>
  <joint name="part_1_cylinder_2_rev0" type="revolute">
    <origin xyz="-0.060499999999999998224 -5.5511151231257827021e-17 0.038500000000000006439" />
    <parent link="part_1" />
    <child link="part_1_int1_2" />
    <axis xyz="1 0 0" />
    <limit effort="1" velocity="20" />
  </joint>
  <joint name="part_1_cylinder_2_rev1" type="revolute">
    <parent link="part_1_int1_2" />
    <child link="part_1_int2_2" />
    <axis xyz="0 1 0" />
    <limit effort="1" velocity="20" />
  </joint>
  <joint name="part_1_cylinder_2_rev2" type="revolute">
    <parent link="part_1_int2_2" />
    <child link="cylinder_2" />
    <axis xyz="0 0 1" />
    <limit effort="1" velocity="20" />
  </joint>
  <link name="part_3_int1_3">
    <inertial>
      <mass value="0.0" />
      <inertia ixx="0.0" ixy="0.0" ixz="0.0" iyy="0.0" iyz="0.0" izz="0.0" />
    </inertial>
  </link>
  <link name="part_3_int2_3">
    <inertial>
      <mass value="0.0" />
      <inertia ixx="0.0" ixy="0.0" ixz="0.0" iyy="0.0" iyz="0.0" izz="0.0" />
    </inertial>
  </link>
  <joint name="part_3_part_6_rev0" type="revolute">
    <origin xyz="0.038967453687049680155 -0.092095263467496885079 -1.1102230246251565404e-16" />
    <parent link="part_3" />
    <child link="part_3_int1_3" />
    <axis xyz="1 0 0" />
    <limit effort="1" velocity="20" />
  </joint>
  <joint name="part_3_part_6_rev1" type="revolute">
    <parent link="part_3_int1_3" />
    <child link="part_3_int2_3" />
    <axis xyz="0 1 0" />
    <limit effort="1" velocity="20" />
  </joint>
  <joint name="part_3_part_6_rev2" type="revolute">
    <parent link="part_3_int2_3" />
    <child link="part_6" />
    <axis xyz="0 0 1" />
    <limit effort="1" velocity="20" />
  </joint>
  <link name="transmission_ankle2_int1_4">
    <inertial>
      <mass value="0.0" />
      <inertia ixx="0.0" ixy="0.0" ixz="0.0" iyy="0.0" iyz="0.0" izz="0.0" />
    </inertial>
  </link>
  <link name="transmission_ankle2_int2_4">
    <inertial>
      <mass value="0.0" />
      <inertia ixx="0.0" ixy="0.0" ixz="0.0" iyy="0.0" iyz="0.0" izz="0.0" />
    </inertial>
  </link>
  <joint name="transmission_ankle2_part_7_rev0" type="revolute">
    <origin xyz="-0.059494699261975494964 0.01098320352752724105 -0.021999999999999964029" />
    <parent link="transmission_ankle2" />
    <child link="transmission_ankle2_int1_4" />
    <axis xyz="1 0 0" />
    <limit effort="1" velocity="20" />
  </joint>
  <joint name="transmission_ankle2_part_7_rev1" type="revolute">
    <parent link="transmission_ankle2_int1_4" />
    <child link="transmission_ankle2_int2_4" />
    <axis xyz="0 1 0" />
    <limit effort="1" velocity="20" />
  </joint>
  <joint name="transmission_ankle2_part_7_rev2" type="revolute">
    <parent link="transmission_ankle2_int2_4" />
    <child link="part_7" />
    <axis xyz="0 0 1" />
    <limit effort="1" velocity="20" />
  </joint>
  <link name="transmission_ankle_int1_5">
    <inertial>
      <mass value="0.0" />
      <inertia ixx="0.0" ixy="0.0" ixz="0.0" iyy="0.0" iyz="0.0" izz="0.0" />
    </inertial>
  </link>
  <link name="transmission_ankle_int2_5">
    <inertial>
      <mass value="0.0" />
      <inertia ixx="0.0" ixy="0.0" ixz="0.0" iyy="0.0" iyz="0.0" izz="0.0" />
    </inertial>
  </link>
  <joint name="transmission_ankle_part_7_2_rev0" type="revolute">
    <origin xyz="-0.059494699261975675375 0.010983203527527130028 0.021999999999999964029" />
    <parent link="transmission_ankle" />
    <child link="transmission_ankle_int1_5" />
    <axis xyz="1 0 0" />
    <limit effort="1" velocity="20" />
  </joint>
  <joint name="transmission_ankle_part_7_2_rev1" type="revolute">
    <parent link="transmission_ankle_int1_5" />
    <child link="transmission_ankle_int2_5" />
    <axis xyz="0 1 0" />
    <limit effort="1" velocity="20" />
  </joint>
  <joint name="transmission_ankle_part_7_2_rev2" type="revolute">
    <parent link="transmission_ankle_int2_5" />
    <child link="part_7_2" />
    <axis xyz="0 0 1" />
    <limit effort="1" velocity="20" />
  </joint>
  <link name="part_8_int1_6">
    <inertial>
      <mass value="0.0" />
      <inertia ixx="0.0" ixy="0.0" ixz="0.0" iyy="0.0" iyz="0.0" izz="0.0" />
    </inertial>
  </link>
  <link name="part_8_int2_6">
    <inertial>
      <mass value="0.0" />
      <inertia ixx="0.0" ixy="0.0" ixz="0.0" iyy="0.0" iyz="0.0" izz="0.0" />
    </inertial>
  </link>
  <joint name="part_8_cylinder_4_rev0" type="revolute">
    <origin xyz="0.043531328479973735446 0.0032046566522409281053 -0.025000000000000077716" />
    <parent link="part_8" />
    <child link="part_8_int1_6" />
    <axis xyz="1 0 0" />
    <limit effort="1" velocity="20" />
  </joint>
  <joint name="part_8_cylinder_4_rev1" type="revolute">
    <parent link="part_8_int1_6" />
    <child link="part_8_int2_6" />
    <axis xyz="0 1 0" />
    <limit effort="1" velocity="20" />
  </joint>
  <joint name="part_8_cylinder_4_rev2" type="revolute">
    <parent link="part_8_int2_6" />
    <child link="cylinder_4" />
    <axis xyz="0 0 1" />
    <limit effort="1" velocity="20" />
  </joint>
  <link name="part_8_int1_7">
    <inertial>
      <mass value="0.0" />
      <inertia ixx="0.0" ixy="0.0" ixz="0.0" iyy="0.0" iyz="0.0" izz="0.0" />
    </inertial>
  </link>
  <link name="part_8_int2_7">
    <inertial>
      <mass value="0.0" />
      <inertia ixx="0.0" ixy="0.0" ixz="0.0" iyy="0.0" iyz="0.0" izz="0.0" />
    </inertial>
  </link>
  <joint name="part_8_part_7_3_rev0" type="revolute">
    <origin xyz="0.041074543378118888448 0.036577067764912846171 -0.0050000000000000044409" />
    <parent link="part_8" />
    <child link="part_8_int1_7" />
    <axis xyz="1 0 0" />
    <limit effort="1" velocity="20" />
  </joint>
  <joint name="part_8_part_7_3_rev1" type="revolute">
    <parent link="part_8_int1_7" />
    <child link="part_8_int2_7" />
    <axis xyz="0 1 0" />
    <limit effort="1" velocity="20" />
  </joint>
  <joint name="part_8_part_7_3_rev2" type="revolute">
    <parent link="part_8_int2_7" />
    <child link="part_7_3" />
    <axis xyz="0 0 1" />
    <limit effort="1" velocity="20" />
  </joint>
  <link name="part_9_int1_8">
    <inertial>
      <mass value="0.0" />
      <inertia ixx="0.0" ixy="0.0" ixz="0.0" iyy="0.0" iyz="0.0" izz="0.0" />
    </inertial>
  </link>
  <link name="part_9_int2_8">
    <inertial>
      <mass value="0.0" />
      <inertia ixx="0.0" ixy="0.0" ixz="0.0" iyy="0.0" iyz="0.0" izz="0.0" />
    </inertial>
  </link>
  <joint name="part_9_cylinder_5_rev0" type="revolute">
    <origin xyz="0.043531328479973624423 -0.003204656652241011372 -0.024999999999999994449" />
    <parent link="part_9" />
    <child link="part_9_int1_8" />
    <axis xyz="1 0 0" />
    <limit effort="1" velocity="20" />
  </joint>
  <joint name="part_9_cylinder_5_rev1" type="revolute">
    <parent link="part_9_int1_8" />
    <child link="part_9_int2_8" />
    <axis xyz="0 1 0" />
    <limit effort="1" velocity="20" />
  </joint>
  <joint name="part_9_cylinder_5_rev2" type="revolute">
    <parent link="part_9_int2_8" />
    <child link="cylinder_5" />
    <axis xyz="0 0 1" />
    <limit effort="1" velocity="20" />
  </joint>
  <link name="part_9_int1_9">
    <inertial>
      <mass value="0.0" />
      <inertia ixx="0.0" ixy="0.0" ixz="0.0" iyy="0.0" iyz="0.0" izz="0.0" />
    </inertial>
  </link>
  <link name="part_9_int2_9">
    <inertial>
      <mass value="0.0" />
      <inertia ixx="0.0" ixy="0.0" ixz="0.0" iyy="0.0" iyz="0.0" izz="0.0" />
    </inertial>
  </link>
  <joint name="part_9_part_7_4_rev0" type="revolute">
    <origin xyz="0.041074543378118943959 -0.036577067764912957193 -0.0050000000000000044409" />
    <parent link="part_9" />
    <child link="part_9_int1_9" />
    <axis xyz="1 0 0" />
    <limit effort="1" velocity="20" />
  </joint>
  <joint name="part_9_part_7_4_rev1" type="revolute">
    <parent link="part_9_int1_9" />
    <child link="part_9_int2_9" />
    <axis xyz="0 1 0" />
    <limit effort="1" velocity="20" />
  </joint>
  <joint name="part_9_part_7_4_rev2" type="revolute">
    <parent link="part_9_int2_9" />
    <child link="part_7_4" />
    <axis xyz="0 0 1" />
    <limit effort="1" velocity="20" />
  </joint>
  <link name="part_1_int1_10">
    <inertial>
      <mass value="0.0" />
      <inertia ixx="0.0" ixy="0.0" ixz="0.0" iyy="0.0" iyz="0.0" izz="0.0" />
    </inertial>
  </link>
  <link name="part_1_int2_10">
    <inertial>
      <mass value="0.0" />
      <inertia ixx="0.0" ixy="0.0" ixz="0.0" iyy="0.0" iyz="0.0" izz="0.0" />
    </inertial>
  </link>
  <joint name="part_1_cylinder_6_rev0" type="revolute">
    <origin xyz="-0.013749999999999946293 0.0024999999999999744649 -0.072000000000000036193" />
    <parent link="part_1" />
    <child link="part_1_int1_10" />
    <axis xyz="1 0 0" />
    <limit effort="1" velocity="20" />
  </joint>
  <joint name="part_1_cylinder_6_rev1" type="revolute">
    <parent link="part_1_int1_10" />
    <child link="part_1_int2_10" />
    <axis xyz="0 1 0" />
    <limit effort="1" velocity="20" />
  </joint>
  <joint name="part_1_cylinder_6_rev2" type="revolute">
    <parent link="part_1_int2_10" />
    <child link="cylinder_6" />
    <axis xyz="0 0 1" />
    <limit effort="1" velocity="20" />
  </joint>
  <link name="hip_part_int1_11">
    <inertial>
      <mass value="0.0" />
      <inertia ixx="0.0" ixy="0.0" ixz="0.0" iyy="0.0" iyz="0.0" izz="0.0" />
    </inertial>
  </link>
  <link name="hip_part_int2_11">
    <inertial>
      <mass value="0.0" />
      <inertia ixx="0.0" ixy="0.0" ixz="0.0" iyy="0.0" iyz="0.0" izz="0.0" />
    </inertial>
  </link>
  <joint name="hip_part_cylinder_11_rev0" type="revolute">
    <origin xyz="3.2508717939805364949e-15 0.038500000000000034195 -0.046750000000000013767" />
    <parent link="hip_part" />
    <child link="hip_part_int1_11" />
    <axis xyz="1 0 0" />
    <limit effort="1" velocity="20" />
  </joint>
  <joint name="hip_part_cylinder_11_rev1" type="revolute">
    <parent link="hip_part_int1_11" />
    <child link="hip_part_int2_11" />
    <axis xyz="0 1 0" />
    <limit effort="1" velocity="20" />
  </joint>
  <joint name="hip_part_cylinder_11_rev2" type="revolute">
    <parent link="hip_part_int2_11" />
    <child link="cylinder_11" />
    <axis xyz="0 0 1" />
    <limit effort="1" velocity="20" />
  </joint>
  <link name="holder_hip_int1_12">
    <inertial>
      <mass value="0.0" />
      <inertia ixx="0.0" ixy="0.0" ixz="0.0" iyy="0.0" iyz="0.0" izz="0.0" />
    </inertial>
  </link>
  <link name="holder_hip_int2_12">
    <inertial>
      <mass value="0.0" />
      <inertia ixx="0.0" ixy="0.0" ixz="0.0" iyy="0.0" iyz="0.0" izz="0.0" />
    </inertial>
  </link>
  <joint name="holder_hip_rotation_motor_4_rev0" type="revolute">
    <origin xyz="1.3877787807814456755e-17 2.7755575615628913511e-17 -0.051749999999999775346" />
    <parent link="holder_hip" />
    <child link="holder_hip_int1_12" />
    <axis xyz="1 0 0" />
    <limit effort="1" velocity="20" />
  </joint>
  <joint name="holder_hip_rotation_motor_4_rev1" type="revolute">
    <parent link="holder_hip_int1_12" />
    <child link="holder_hip_int2_12" />
    <axis xyz="0 1 0" />
    <limit effort="1" velocity="20" />
  </joint>
  <joint name="holder_hip_rotation_motor_4_rev2" type="revolute">
    <parent link="holder_hip_int2_12" />
    <child link="rotation_motor_4" />
    <axis xyz="0 0 1" />
    <limit effort="1" velocity="20" />
  </joint>
</robot>
