<robot name="onshape">
<link name="hanche">
<visual>
<origin xyz="-0.018791666666666470564 -0.28679166666666666696 -1.0745833333333334458" rpy="0 -6.1232339957367660359e-17 3.141592653589793116" />
<geometry>
<mesh filename="package:///hanche.stl"/>
</geometry>
<material name="hanche_material">
<color rgba="0.61568627450980395466 0.81176470588235294379 0.92941176470588238168 1.0"/>
</material>
</visual>
<collision>
<origin xyz="-0.018791666666666470564 -0.28679166666666666696 -1.0745833333333334458" rpy="0 -6.1232339957367660359e-17 3.141592653589793116" />
<geometry>
<mesh filename="package:///hanche.stl"/>
</geometry>
<material name="hanche_material">
<color rgba="0.61568627450980395466 0.81176470588235294379 0.92941176470588238168 1.0"/>
</material>
</collision>
<inertial>
<origin xyz="0.0026400973615786950399 -0.12908406698772914578 0.024395572024549228018" rpy="0 0 0"/>
<mass value="1.1356034209800021095" />
<inertia ixx="0.0064522934693274358597" ixy="0.00035945585422071202157"  ixz="3.3623873327575207767e-05" iyy="0.0019918850512647429812" iyz="-6.8228058000940962108e-05" izz="0.0079598705100062706885" />
</inertial>
</link>

<link name="centre_hanche">
<inertial>
<origin xyz="0 0 0" rpy="0 0 0" />
<mass value="1e-9" />
<inertia ixx="0" ixy="0" ixz="0" iyy="0" iyz="0" izz="0" />
</inertial>
</link>
<joint name="centre_hanche_frame" type="fixed">
<origin xyz="0.0072868371002145423954 -0.12388192121052921113 5.290906601729261638e-17" rpy="0 -1.5429430116984873749e-15 0" />
<parent link="hanche" />
<child link="centre_hanche" />
<axis xyz="0 0 0"/>
</joint>

<link name="hanche_2">
<visual>
<origin xyz="0.0062916666666681317355 0.081791666666666679175 -1.0695833333333335524" rpy="0 -1.604175351655854949e-15 -3.0202081695363813006e-46" />
<geometry>
<mesh filename="package:///hanche.stl"/>
</geometry>
<material name="hanche_material">
<color rgba="0.97254901960784312376 0.52941176470588235947 0.0039215686274509803377 1.0"/>
</material>
</visual>
<collision>
<origin xyz="0.0062916666666681317355 0.081791666666666679175 -1.0695833333333335524" rpy="0 -1.604175351655854949e-15 -3.0202081695363813006e-46" />
<geometry>
<mesh filename="package:///hanche.stl"/>
</geometry>
<material name="hanche_material">
<color rgba="0.97254901960784312376 0.52941176470588235947 0.0039215686274509803377 1.0"/>
</material>
</collision>
<inertial>
<origin xyz="3.4307575783737442876e-08 0.002996463440407715062 -0.096315720421799144724" rpy="0 0 0"/>
<mass value="0.14955328973671463966" />
<inertia ixx="0.0004758751781325682188" ixy="2.2059652171059531583e-10"  ixz="-2.1604676563943649506e-11" iyy="0.00043553070247581124374" iyz="-1.9195810346953776174e-05" izz="5.884904061039586328e-05" />
</inertial>
</link>

<link name="cardan_foot">
<visual>
<origin xyz="0 0.044041666666666673402 -7.5000000000002148282e-05" rpy="1.570796326794896558 1.570796326794896558 0" />
<geometry>
<mesh filename="package:///cardan_foot.stl"/>
</geometry>
<material name="cardan_foot_material">
<color rgba="0.64705882352941179736 0.64705882352941179736 0.64705882352941179736 1.0"/>
</material>
</visual>
<collision>
<origin xyz="0 0.044041666666666673402 -7.5000000000002148282e-05" rpy="1.570796326794896558 1.570796326794896558 0" />
<geometry>
<mesh filename="package:///cardan_foot.stl"/>
</geometry>
<material name="cardan_foot_material">
<color rgba="0.64705882352941179736 0.64705882352941179736 0.64705882352941179736 1.0"/>
</material>
</collision>
<inertial>
<origin xyz="2.2944734336881823905e-08 0 -7.4977055265666050598e-05" rpy="0 0 0"/>
<mass value="0.0066552634961090364682" />
<inertia ixx="4.5170330905598590077e-07" ixy="2.5470220910056715885e-12"  ixz="1.5660183203317566813e-40" iyy="5.7905433802721882153e-07" iyz="-2.5470220909843720916e-12" izz="4.5170330905598590077e-07" />
</inertial>
</link>

<link name="tarsus">
<visual>
<origin xyz="0.0062916666666667196706 -0.88083333333333346804 -0.081791666666666706931" rpy="-1.570796326794896558 -9.4405252196610848924e-34 0" />
<geometry>
<mesh filename="package:///tarsus.stl"/>
</geometry>
<material name="tarsus_material">
<color rgba="0.91764705882352937127 0.91764705882352937127 0.91764705882352937127 1.0"/>
</material>
</visual>
<collision>
<origin xyz="0.0062916666666667196706 -0.88083333333333346804 -0.081791666666666706931" rpy="-1.570796326794896558 -9.4405252196610848924e-34 0" />
<geometry>
<mesh filename="package:///tarsus.stl"/>
</geometry>
<material name="tarsus_material">
<color rgba="0.91764705882352937127 0.91764705882352937127 0.91764705882352937127 1.0"/>
</material>
</collision>
<inertial>
<origin xyz="0.053154689654094117168 -0.19698830172026604579 -0.078513550003536269895" rpy="0 0 0"/>
<mass value="2.1073238681812558326" />
<inertia ixx="0.04814467183356242741" ixy="0.015163240245921501617"  ixz="0.00017822324045009053407" iyy="0.0086472529576917395167" iyz="-0.0013624880248352306839" izz="0.053648367038970218301" />
</inertial>
</link>

<link name="tibias">
<visual>
<origin xyz="-0.16987499999999999822 0.3900833333333334485 0" rpy="1.570796326794896558 9.4405252196036012072e-34 0" />
<geometry>
<mesh filename="package:///tibias.stl"/>
</geometry>
<material name="tibias_material">
<color rgba="0.2313725490196078538 0.38039215686274507888 0.7058823529411765163 1.0"/>
</material>
</visual>
<collision>
<origin xyz="-0.16987499999999999822 0.3900833333333334485 0" rpy="1.570796326794896558 9.4405252196036012072e-34 0" />
<geometry>
<mesh filename="package:///tibias.stl"/>
</geometry>
<material name="tibias_material">
<color rgba="0.2313725490196078538 0.38039215686274507888 0.7058823529411765163 1.0"/>
</material>
</collision>
<inertial>
<origin xyz="-0.076582271026864448538 0.15621438233256335071 -1.1094304067592593162e-08" rpy="0 0 0"/>
<mass value="0.17811841417215046324" />
<inertia ixx="0.0019764054154096585836" ixy="0.00096016337172479850059"  ixz="-1.0718588358473573459e-10" iyy="0.00049037133129023154684" iyz="2.8756588598226802519e-10" izz="0.00244830523441177993" />
</inertial>
</link>

<link name="cardan_foot_2">
<visual>
<origin xyz="0 0.044041666666666756669 -7.4999999999998678835e-05" rpy="1.570796326794896558 1.570796326794896558 0" />
<geometry>
<mesh filename="package:///cardan_foot.stl"/>
</geometry>
<material name="cardan_foot_material">
<color rgba="0.64705882352941179736 0.64705882352941179736 0.64705882352941179736 1.0"/>
</material>
</visual>
<collision>
<origin xyz="0 0.044041666666666756669 -7.4999999999998678835e-05" rpy="1.570796326794896558 1.570796326794896558 0" />
<geometry>
<mesh filename="package:///cardan_foot.stl"/>
</geometry>
<material name="cardan_foot_material">
<color rgba="0.64705882352941179736 0.64705882352941179736 0.64705882352941179736 1.0"/>
</material>
</collision>
<inertial>
<origin xyz="2.2944734336881823905e-08 8.3266726846886740532e-17 -7.4977055265662594704e-05" rpy="0 0 0"/>
<mass value="0.0066552634961090364682" />
<inertia ixx="4.5170330905598590077e-07" ixy="2.5470220910056715885e-12"  ixz="8.5286329618903013194e-40" iyy="5.7905433802721882153e-07" iyz="-2.5470220909843720916e-12" izz="4.5170330905598590077e-07" />
</inertial>
</link>

<link name="foot">
<visual>
<origin xyz="0 0.044041666666666756669 0" rpy="1.570796326794896558 9.4405252202421533485e-34 0" />
<geometry>
<mesh filename="package:///foot.stl"/>
</geometry>
<material name="foot_material">
<color rgba="0.61568627450980395466 0.81176470588235294379 0.92941176470588238168 1.0"/>
</material>
</visual>
<collision>
<origin xyz="0 0.044041666666666756669 0" rpy="1.570796326794896558 9.4405252202421533485e-34 0" />
<geometry>
<mesh filename="package:///foot.stl"/>
</geometry>
<material name="foot_material">
<color rgba="0.61568627450980395466 0.81176470588235294379 0.92941176470588238168 1.0"/>
</material>
</collision>
<inertial>
<origin xyz="-0.017858803267170125784 0.026154624544931014823 -6.5844145911600608258e-10" rpy="0 0 0"/>
<mass value="0.4130405170811343174" />
<inertia ixx="0.0004485171362783168668" ixy="-0.0001294640680019977562"  ixz="-3.0653895063853523361e-10" iyy="0.0014015188952783321896" iyz="-4.7489172979980373638e-10" izz="0.0010932169994883808844" />
</inertial>
</link>

<link name="centre_pied">
<inertial>
<origin xyz="0 0 0" rpy="0 0 0" />
<mass value="1e-9" />
<inertia ixx="0" ixy="0" ixz="0" iyy="0" iyz="0" izz="0" />
</inertial>
</link>
<joint name="centre_pied_frame" type="fixed">
<origin xyz="0.014111017407571532084 0.044041666666666756669 1.5991514223934188976e-09" rpy="-1.570796326794896558 -3.5345377042228960092e-28 -3.141592653589793116" />
<parent link="foot" />
<child link="centre_pied" />
<axis xyz="0 0 0"/>
</joint>

<link name="rode_tarsus">
<visual>
<origin xyz="-0.023755298455264826918 -1.0790665033514630355 -0.053479166666666633212" rpy="-1.570796326794896558 -1.5707963267948950037 0" />
<geometry>
<mesh filename="package:///rode_tarsus.stl"/>
</geometry>
<material name="rode_tarsus_material">
<color rgba="0.49803921568627451677 0.49803921568627451677 0.49803921568627451677 1.0"/>
</material>
</visual>
<collision>
<origin xyz="-0.023755298455264826918 -1.0790665033514630355 -0.053479166666666633212" rpy="-1.570796326794896558 -1.5707963267948950037 0" />
<geometry>
<mesh filename="package:///rode_tarsus.stl"/>
</geometry>
<material name="rode_tarsus_material">
<color rgba="0.49803921568627451677 0.49803921568627451677 0.49803921568627451677 1.0"/>
</material>
</collision>
<inertial>
<origin xyz="-6.9388939039072268369e-18 2.2204460492503130808e-16 -0.09594791666666649399" rpy="0 0 0"/>
<mass value="0.037586110560311969397" />
<inertia ixx="0.00011617619354049131195" ixy="4.2484542277485790914e-37"  ixz="-1.2618856200737355416e-52" iyy="0.00011617619354049131195" iyz="-1.8368186946440960047e-19" izz="1.6738298962610809591e-06" />
</inertial>
</link>

<link name="fermeture10_A">
<inertial>
<origin xyz="0 0 0" rpy="0 0 0" />
<mass value="1e-9" />
<inertia ixx="0" ixy="0" ixz="0" iyy="0" iyz="0" izz="0" />
</inertial>
</link>
<joint name="fermeture10_A_frame" type="fixed">
<origin xyz="-6.9388939039072283776e-18 0 -0.19189583333333304349" rpy="-3.141592653589793116 -3.3743525220828779976e-28 3.0361798708208753015e-29" />
<parent link="rode_tarsus" />
<child link="fermeture10_A" />
<axis xyz="0 0 0"/>
</joint>

<joint name="to_rotule_free_foot1" type="revolute">
<origin xyz="-0.0629166666666667318 -0.012583333333333612813 0.04404166666666681218" rpy="1.570796326794896558 -6.7617285292989753398e-30 3.141592653589793116" />
<parent link="foot" />
<child link="rode_tarsus" />
<axis xyz="0 0 1"/>
<limit effort="1" velocity="20" />
<joint_properties friction="0.0"/>
</joint>

<link name="rode_tarsus_2">
<visual>
<origin xyz="-0.023755298455264830387 -1.0790665033514630355 -0.053479166666666633212" rpy="-1.570796326794896558 -1.5707963267948950037 0" />
<geometry>
<mesh filename="package:///rode_tarsus.stl"/>
</geometry>
<material name="rode_tarsus_material">
<color rgba="0.49803921568627451677 0.49803921568627451677 0.49803921568627451677 1.0"/>
</material>
</visual>
<collision>
<origin xyz="-0.023755298455264830387 -1.0790665033514630355 -0.053479166666666633212" rpy="-1.570796326794896558 -1.5707963267948950037 0" />
<geometry>
<mesh filename="package:///rode_tarsus.stl"/>
</geometry>
<material name="rode_tarsus_material">
<color rgba="0.49803921568627451677 0.49803921568627451677 0.49803921568627451677 1.0"/>
</material>
</collision>
<inertial>
<origin xyz="-1.0408340855860842566e-17 2.2204460492503130808e-16 -0.09594791666666649399" rpy="0 0 0"/>
<mass value="0.037586110560311969397" />
<inertia ixx="0.00011617619354049131195" ixy="4.2484542277485790914e-37"  ixz="-1.2618856200737355416e-52" iyy="0.00011617619354049131195" iyz="-1.8368186946440960047e-19" izz="1.6738298962610809591e-06" />
</inertial>
</link>

<link name="fermeture9_B">
<inertial>
<origin xyz="0 0 0" rpy="0 0 0" />
<mass value="1e-9" />
<inertia ixx="0" ixy="0" ixz="0" iyy="0" iyz="0" izz="0" />
</inertial>
</link>
<joint name="fermeture9_B_frame" type="fixed">
<origin xyz="-6.9388939039072283776e-18 2.7755575615628913511e-17 -0.19189583333333304349" rpy="-3.141592653589793116 -3.3743525220828779976e-28 3.0361798708208753015e-29" />
<parent link="rode_tarsus_2" />
<child link="fermeture9_B" />
<axis xyz="0 0 0"/>
</joint>

<joint name="to_rotule_free_goot2" type="revolute">
<origin xyz="-0.062916666666666745678 -0.012583333333333612813 -0.044041666666666590135" rpy="1.570796326794896558 -6.7617285292989753398e-30 3.141592653589793116" />
<parent link="foot" />
<child link="rode_tarsus_2" />
<axis xyz="0 0 1"/>
<limit effort="1" velocity="20" />
<joint_properties friction="0.0"/>
</joint>

<joint name="free_cheville_cardanx" type="revolute">
<origin xyz="7.5000000000047251092e-05 0 -7.5000000000068067774e-05" rpy="-4.1267286104374180071e-29 -1.570796326794896558 0" />
<parent link="cardan_foot_2" />
<child link="foot" />
<axis xyz="0 0 1"/>
<limit effort="1" velocity="20" />
<joint_properties friction="0.0"/>
</joint>

<joint name="free_cheville_cardany" type="revolute">
<origin xyz="-0.1698000000000028098 0.34604166666666669183 5.5511151231257827021e-17" rpy="-0 1.570796326794896558 0" />
<parent link="tibias" />
<child link="cardan_foot_2" />
<axis xyz="0 0 1"/>
<limit effort="1" velocity="20" />
<joint_properties friction="0.0"/>
</joint>

<link name="piston">
<visual>
<origin xyz="-0.10179556944408764407 -0.15392457132099851558 0.9565000000000001279" rpy="3.141592653589793116 -0 -1.0917037999226161844e-33" />
<geometry>
<mesh filename="package:///piston.stl"/>
</geometry>
<material name="piston_material">
<color rgba="0.91764705882352937127 0.91764705882352937127 0.91764705882352937127 1.0"/>
</material>
</visual>
<collision>
<origin xyz="-0.10179556944408764407 -0.15392457132099851558 0.9565000000000001279" rpy="3.141592653589793116 -0 -1.0917037999226161844e-33" />
<geometry>
<mesh filename="package:///piston.stl"/>
</geometry>
<material name="piston_material">
<color rgba="0.91764705882352937127 0.91764705882352937127 0.91764705882352937127 1.0"/>
</material>
</collision>
<inertial>
<origin xyz="4.1633363423443370266e-17 -1.1113060997739708269e-34 -0.012499999999999953856" rpy="0 0 0"/>
<mass value="0.0048966814322412765756" />
<inertia ixx="3.6406794569277529096e-07" ixy="-7.9490871946637077743e-40"  ixz="0" iyy="3.6406794569277529096e-07" iyz="0" izz="2.1806490886041675402e-07" />
</inertial>
</link>

<link name="fermeture6_B">
<inertial>
<origin xyz="0 0 0" rpy="0 0 0" />
<mass value="1e-9" />
<inertia ixx="0" ixy="0" ixz="0" iyy="0" iyz="0" izz="0" />
</inertial>
</link>
<joint name="fermeture6_B_frame" type="fixed">
<origin xyz="0 0 -0.025000000000000022204" rpy="3.141592653589793116 -2.622962509859864253e-29 -3.141592653589793116" />
<parent link="piston" />
<child link="fermeture6_B" />
<axis xyz="0 0 0"/>
</joint>

<joint name="to_rotule_free_attache_genoux" type="revolute">
<origin xyz="-0.044041666666666673402 0.050333333333333230009 -5.5511151231257827021e-17" rpy="-1.57079632679489678 1.9438969795233453561e-29 -9.6635460889573946163e-30" />
<parent link="tibias" />
<child link="piston" />
<axis xyz="0 0 1"/>
<limit effort="1" velocity="20" />
<joint_properties friction="0.0"/>
</joint>

<joint name="free_genoux" type="revolute">
<origin xyz="0.17616666666662494922 -0.49075000000001511857 -0.081791666666666706931" rpy="3.141592653589793116 -3.8921152931043281558e-31 4.1415197524103119784e-30" />
<parent link="tarsus" />
<child link="tibias" />
<axis xyz="0 0 1"/>
<limit effort="1" velocity="20" />
<joint_properties friction="0.0"/>
</joint>

<link name="renvois_cheville">
<visual>
<origin xyz="-0.13212500000000004796 0.40895833333333320159 0.037750000000000005773" rpy="1.570796326794896558 -5.6312041102316812711e-34 5.7801324977178752524e-17" />
<geometry>
<mesh filename="package:///renvois_cheville.stl"/>
</geometry>
<material name="renvois_cheville_material">
<color rgba="0.76862745098039220171 0.88627450980392152857 0.95294117647058818044 1.0"/>
</material>
</visual>
<collision>
<origin xyz="-0.13212500000000004796 0.40895833333333320159 0.037750000000000005773" rpy="1.570796326794896558 -5.6312041102316812711e-34 5.7801324977178752524e-17" />
<geometry>
<mesh filename="package:///renvois_cheville.stl"/>
</geometry>
<material name="renvois_cheville_material">
<color rgba="0.76862745098039220171 0.88627450980392152857 0.95294117647058818044 1.0"/>
</material>
</collision>
<inertial>
<origin xyz="-0.038548646780021234015 0.021351922520206567668 -0.016601297994840141792" rpy="0 0 0"/>
<mass value="0.075465954638112592301" />
<inertia ixx="5.4311390351603859984e-05" ixy="-2.7554927892777790736e-06"  ixz="-2.7094024723524427023e-06" iyy="4.232053451843603817e-05" iyz="1.3329322471998968951e-05" izz="6.6609236448868702676e-05" />
</inertial>
</link>

<link name="rode_tarsus_3">
<visual>
<origin xyz="-0.023755298455264806101 -1.0790665033514630355 -0.053479166666666855257" rpy="-1.570796326794896558 -1.5707963267948950037 0" />
<geometry>
<mesh filename="package:///rode_tarsus.stl"/>
</geometry>
<material name="rode_tarsus_material">
<color rgba="0.49803921568627451677 0.49803921568627451677 0.49803921568627451677 1.0"/>
</material>
</visual>
<collision>
<origin xyz="-0.023755298455264806101 -1.0790665033514630355 -0.053479166666666855257" rpy="-1.570796326794896558 -1.5707963267948950037 0" />
<geometry>
<mesh filename="package:///rode_tarsus.stl"/>
</geometry>
<material name="rode_tarsus_material">
<color rgba="0.49803921568627451677 0.49803921568627451677 0.49803921568627451677 1.0"/>
</material>
</collision>
<inertial>
<origin xyz="1.5476802360987119527e-17 2.2204460492503130808e-16 -0.095947916666666716035" rpy="0 0 0"/>
<mass value="0.037586110560311969397" />
<inertia ixx="0.00011617619354049131195" ixy="1.7649608795290504014e-35"  ixz="2.1098706579314717418e-21" iyy="0.00011617619354049131195" iyz="-1.8368186946440960047e-19" izz="1.6738298962610809591e-06" />
</inertial>
</link>

<link name="fermeture9_A">
<inertial>
<origin xyz="0 0 0" rpy="0 0 0" />
<mass value="1e-9" />
<inertia ixx="0" ixy="0" ixz="0" iyy="0" iyz="0" izz="0" />
</inertial>
</link>
<joint name="fermeture9_A_frame" type="fixed">
<origin xyz="0 2.7755575615628913511e-17 -0.19189583333333337656" rpy="-4.1946134630726214399e-30 -2.8134745357242634154e-17 -3.141592653589793116" />
<parent link="rode_tarsus_3" />
<child link="fermeture9_A" />
<axis xyz="0 0 0"/>
</joint>

<joint name="to_rotule_free_triangle2" type="revolute">
<origin xyz="-0.068058330216350937381 -0.012564119186792344074 -0.012583333333333335258" rpy="1.570796326794896558 -9.8721378529962509943e-18 5.2019339086040904528e-17" />
<parent link="renvois_cheville" />
<child link="rode_tarsus_3" />
<axis xyz="0 0 1"/>
<limit effort="1" velocity="20" />
<joint_properties friction="0.0"/>
</joint>

<link name="rode_foot">
<visual>
<origin xyz="-0.035362814756396021565 -1.1126229936003479981 -0.069208333333333427184" rpy="-1.570796326794896558 -1.5707963267948950037 0" />
<geometry>
<mesh filename="package:///rode_foot.stl"/>
</geometry>
<material name="rode_foot_material">
<color rgba="0.97254901960784312376 0.52941176470588235947 0.0039215686274509803377 1.0"/>
</material>
</visual>
<collision>
<origin xyz="-0.035362814756396021565 -1.1126229936003479981 -0.069208333333333427184" rpy="-1.570796326794896558 -1.5707963267948950037 0" />
<geometry>
<mesh filename="package:///rode_foot.stl"/>
</geometry>
<material name="rode_foot_material">
<color rgba="0.97254901960784312376 0.52941176470588235947 0.0039215686274509803377 1.0"/>
</material>
</collision>
<inertial>
<origin xyz="-1.3751475834323205484e-16 0 -0.10381249999999996037" rpy="0 0 0"/>
<mass value="0.04066693929476376812" />
<inertia ixx="0.00014699519269296084214" ixy="6.0073792570494346732e-21"  ixz="-4.3807831777148011001e-21" iyy="0.00014699519269296084214" iyz="-2.3466754303254690074e-19" izz="1.8110290680857596429e-06" />
</inertial>
</link>

<link name="fermeture7_A">
<inertial>
<origin xyz="0 0 0" rpy="0 0 0" />
<mass value="1e-9" />
<inertia ixx="0" ixy="0" ixz="0" iyy="0" iyz="0" izz="0" />
</inertial>
</link>
<joint name="fermeture7_A_frame" type="fixed">
<origin xyz="-1.1102230246251565404e-16 -2.6367796834847467835e-16 -0.207625000000000004" rpy="-3.1415926535897913396 -2.9426902788492800649e-16 -1.5707963267948954478" />
<parent link="rode_foot" />
<child link="fermeture7_A" />
<axis xyz="0 0 0"/>
</joint>

<joint name="to_rotule_free_trianle3" type="revolute">
<origin xyz="-0.041015624251386106902 0.047709805194672050277 -0.047187499999999882316" rpy="1.57079632679489678 -0.40246863389381404286 1.5707963267948956698" />
<parent link="renvois_cheville" />
<child link="rode_foot" />
<axis xyz="0 0 1"/>
<limit effort="1" velocity="20" />
<joint_properties friction="0.0"/>
</joint>

<joint name="free_triangle1_tibias" type="revolute">
<origin xyz="0.13841666666666663232 -0.47187500000000004441 -0.044041666666666701158" rpy="3.141592653589793116 1.9899601408349094571e-30 -0.32415406750443093165" />
<parent link="tarsus" />
<child link="renvois_cheville" />
<axis xyz="0 0 1"/>
<limit effort="1" velocity="20" />
<joint_properties friction="0.0"/>
</joint>

<link name="renvois_cheville_2">
<visual>
<origin xyz="-0.13212499999999999245 -0.40895833333333331261 0.037750000000000005773" rpy="-1.570796326794896558 3.7883401209905207919e-33 -3.4686026790939379404e-17" />
<geometry>
<mesh filename="package:///renvois_cheville_2.stl"/>
</geometry>
<material name="renvois_cheville_2_material">
<color rgba="0.76862745098039220171 0.88627450980392152857 0.95294117647058818044 1.0"/>
</material>
</visual>
<collision>
<origin xyz="-0.13212499999999999245 -0.40895833333333331261 0.037750000000000005773" rpy="-1.570796326794896558 3.7883401209905207919e-33 -3.4686026790939379404e-17" />
<geometry>
<mesh filename="package:///renvois_cheville_2.stl"/>
</geometry>
<material name="renvois_cheville_2_material">
<color rgba="0.76862745098039220171 0.88627450980392152857 0.95294117647058818044 1.0"/>
</material>
</collision>
<inertial>
<origin xyz="-0.038548646377067175006 -0.021351922527764577442 -0.016601297938671023824" rpy="0 0 0"/>
<mass value="0.075465953879580452424" />
<inertia ixx="5.4311390357873774043e-05" ixy="2.7554926059569349289e-06"  ixz="-2.709402351296007105e-06" iyy="4.2320533739322570093e-05" iyz="-1.3329322467171953495e-05" izz="6.6609235780079392177e-05" />
</inertial>
</link>

<link name="rode_tarsus_4">
<visual>
<origin xyz="-0.023755298455264833857 -1.0790665033514630355 -0.053479166666666744234" rpy="-1.570796326794896558 -1.5707963267948950037 0" />
<geometry>
<mesh filename="package:///rode_tarsus.stl"/>
</geometry>
<material name="rode_tarsus_material">
<color rgba="0.49803921568627451677 0.49803921568627451677 0.49803921568627451677 1.0"/>
</material>
</visual>
<collision>
<origin xyz="-0.023755298455264833857 -1.0790665033514630355 -0.053479166666666744234" rpy="-1.570796326794896558 -1.5707963267948950037 0" />
<geometry>
<mesh filename="package:///rode_tarsus.stl"/>
</geometry>
<material name="rode_tarsus_material">
<color rgba="0.49803921568627451677 0.49803921568627451677 0.49803921568627451677 1.0"/>
</material>
</collision>
<inertial>
<origin xyz="-6.6477131096105397914e-18 2.2204460492503130808e-16 -0.095947916666666605012" rpy="0 0 0"/>
<mass value="0.037586110560311969397" />
<inertia ixx="0.00011617619354049136616" ixy="1.4956450152657245144e-36"  ixz="2.5736177737665257032e-21" iyy="0.00011617619354049131195" iyz="-1.8368186946440960047e-19" izz="1.6738298962610809591e-06" />
</inertial>
</link>

<link name="fermeture10_B">
<inertial>
<origin xyz="0 0 0" rpy="0 0 0" />
<mass value="1e-9" />
<inertia ixx="0" ixy="0" ixz="0" iyy="0" iyz="0" izz="0" />
</inertial>
</link>
<joint name="fermeture10_B_frame" type="fixed">
<origin xyz="-2.7755575615628913511e-17 0 -0.19189583333333337656" rpy="2.6226065419485429286e-28 1.9889647700117402434e-17 -3.141592653589793116" />
<parent link="rode_tarsus_4" />
<child link="fermeture10_B" />
<axis xyz="0 0 0"/>
</joint>

<joint name="to_rotule_free_triangle1" type="revolute">
<origin xyz="-0.068058330216350798603 0.012564119186792122029 -0.012583333333333335258" rpy="-1.57079632679489678 1.2422533291766141538e-17 -3.6260592545799792035e-17" />
<parent link="renvois_cheville_2" />
<child link="rode_tarsus_4" />
<axis xyz="0 0 1"/>
<limit effort="1" velocity="20" />
<joint_properties friction="0.0"/>
</joint>

<link name="rode_foot_2">
<visual>
<origin xyz="-0.035362814756396021565 -1.1126229936003482202 -0.069208333333333510451" rpy="-1.570796326794896558 -1.5707963267948950037 0" />
<geometry>
<mesh filename="package:///rode_foot.stl"/>
</geometry>
<material name="rode_foot_material">
<color rgba="0.97254901960784312376 0.52941176470588235947 0.0039215686274509803377 1.0"/>
</material>
</visual>
<collision>
<origin xyz="-0.035362814756396021565 -1.1126229936003482202 -0.069208333333333510451" rpy="-1.570796326794896558 -1.5707963267948950037 0" />
<geometry>
<mesh filename="package:///rode_foot.stl"/>
</geometry>
<material name="rode_foot_material">
<color rgba="0.97254901960784312376 0.52941176470588235947 0.0039215686274509803377 1.0"/>
</material>
</collision>
<inertial>
<origin xyz="-1.3906962303893589501e-16 0 -0.10381250000000001588" rpy="0 0 0"/>
<mass value="0.04066693929476376812" />
<inertia ixx="0.00014699519269296089635" ixy="-6.4392854565745792665e-36"  ixz="5.9288823947945851455e-22" iyy="0.00014699519269296089635" iyz="-2.3290085673779520776e-19" izz="1.8110290680857596429e-06" />
</inertial>
</link>

<link name="fermeture8_B">
<inertial>
<origin xyz="0 0 0" rpy="0 0 0" />
<mass value="1e-9" />
<inertia ixx="0" ixy="0" ixz="0" iyy="0" iyz="0" izz="0" />
</inertial>
</link>
<joint name="fermeture8_B_frame" type="fixed">
<origin xyz="-1.1102230246251565404e-16 -1.6653345369377348106e-16 -0.20762500000000005951" rpy="-3.141592653589793116 2.9827937381168234235e-17 1.2988615198508003668e-17" />
<parent link="rode_foot_2" />
<child link="fermeture8_B" />
<axis xyz="0 0 0"/>
</joint>

<joint name="to_rotule_free_triangle4" type="revolute">
<origin xyz="-0.041015624251386162413 -0.047709805194672050277 -0.047187500000000215383" rpy="-1.57079632679489678 -1.5156783735639931857e-19 -1.570796326794896558" />
<parent link="renvois_cheville_2" />
<child link="rode_foot_2" />
<axis xyz="0 0 1"/>
<limit effort="1" velocity="20" />
<joint_properties friction="0.0"/>
</joint>

<joint name="free_triangle2_tibias" type="revolute">
<origin xyz="0.13841666666666660457 -0.47187500000000015543 -0.1195416666666667127" rpy="-5.8177101283745972593e-29 9.3322004381232959028e-30 -0.23874661370881070099" />
<parent link="tarsus" />
<child link="renvois_cheville_2" />
<axis xyz="0 0 1"/>
<limit effort="1" velocity="20" />
<joint_properties friction="0.0"/>
</joint>

<link name="renvois_hanche_2">
<visual>
<origin xyz="-0.066062500000000079492 -0.82735416666666672381 0.053479166666666633212" rpy="-1.570796326794896558 6.3716597028957588574e-33 3.567962210164373316e-17" />
<geometry>
<mesh filename="package:///renvois_hanche_2.stl"/>
</geometry>
<material name="renvois_hanche_2_material">
<color rgba="0.76862745098039220171 0.88627450980392152857 0.95294117647058818044 1.0"/>
</material>
</visual>
<collision>
<origin xyz="-0.066062500000000079492 -0.82735416666666672381 0.053479166666666633212" rpy="-1.570796326794896558 6.3716597028957588574e-33 3.567962210164373316e-17" />
<geometry>
<mesh filename="package:///renvois_hanche_2.stl"/>
</geometry>
<material name="renvois_hanche_2_material">
<color rgba="0.76862745098039220171 0.88627450980392152857 0.95294117647058818044 1.0"/>
</material>
</collision>
<inertial>
<origin xyz="-0.071838889332595010084 -0.028325668402720997202 -0.0062916666666667092622" rpy="0 0 0"/>
<mass value="0.052048361392958070182" />
<inertia ixx="1.9958534542913006378e-05" ixy="-2.9941729812280453582e-05"  ixz="5.5924583147312064963e-38" iyy="8.5925596188234551454e-05" iyz="1.6557285139858211185e-37" izz="0.0001045105720643410346" />
</inertial>
</link>

<link name="piston_2">
<visual>
<origin xyz="-0.10179556944408767183 -0.15392457132099851558 0.95649999999999990585" rpy="-3.141592653589793116 6.8950200771308828667e-18 -2.502551717045212132e-34" />
<geometry>
<mesh filename="package:///piston.stl"/>
</geometry>
<material name="piston_material">
<color rgba="0.91764705882352937127 0.91764705882352937127 0.91764705882352937127 1.0"/>
</material>
</visual>
<collision>
<origin xyz="-0.10179556944408767183 -0.15392457132099851558 0.95649999999999990585" rpy="-3.141592653589793116 6.8950200771308828667e-18 -2.502551717045212132e-34" />
<geometry>
<mesh filename="package:///piston.stl"/>
</geometry>
<material name="piston_material">
<color rgba="0.91764705882352937127 0.91764705882352937127 0.91764705882352937127 1.0"/>
</material>
</collision>
<inertial>
<origin xyz="-1.3877787807814456755e-17 -2.9331685421028231594e-33 -0.01250000000000017937" rpy="0 0 0"/>
<mass value="0.0048966814322412765756" />
<inertia ixx="3.6406794569277529096e-07" ixy="-9.1109886261457761061e-41"  ixz="3.3488200029198922759e-24" iyy="3.6406794569277529096e-07" iyz="2.8980927787730819447e-39" izz="2.1806490886041675402e-07" />
</inertial>
</link>

<link name="fermeture1_B">
<inertial>
<origin xyz="0 0 0" rpy="0 0 0" />
<mass value="1e-9" />
<inertia ixx="0" ixy="0" ixz="0" iyy="0" iyz="0" izz="0" />
</inertial>
</link>
<joint name="fermeture1_B_frame" type="fixed">
<origin xyz="-2.7755575615628913511e-17 -5.5511151231257827021e-17 -0.025000000000000244249" rpy="-3.141592653589793116 -6.2877883210336418487e-17 3.1275980329687938195e-17" />
<parent link="piston_2" />
<child link="fermeture1_B" />
<axis xyz="0 0 0"/>
</joint>

<joint name="to_rotule_free_attache_hanche1" type="revolute">
<origin xyz="-0.13212500000000010347 -0.037750000000000172307 -2.7755575615628913511e-16" rpy="-1.57079632679489678 2.9120385417269680563e-17 -3.141592653589793116" />
<parent link="renvois_hanche_2" />
<child link="piston_2" />
<axis xyz="0 0 1"/>
<limit effort="1" velocity="20" />
<joint_properties friction="0.0"/>
</joint>

<link name="rode_foot_3">
<visual>
<origin xyz="-0.035362814756395882787 -1.1126229936003479981 -0.069208333333333482695" rpy="-1.570796326794896558 -1.5707963267948950037 0" />
<geometry>
<mesh filename="package:///rode_foot.stl"/>
</geometry>
<material name="rode_foot_material">
<color rgba="0.97254901960784312376 0.52941176470588235947 0.0039215686274509803377 1.0"/>
</material>
</visual>
<collision>
<origin xyz="-0.035362814756395882787 -1.1126229936003479981 -0.069208333333333482695" rpy="-1.570796326794896558 -1.5707963267948950037 0" />
<geometry>
<mesh filename="package:///rode_foot.stl"/>
</geometry>
<material name="rode_foot_material">
<color rgba="0.97254901960784312376 0.52941176470588235947 0.0039215686274509803377 1.0"/>
</material>
</collision>
<inertial>
<origin xyz="2.1472579393510083334e-18 2.2204460492503130808e-16 -0.10381249999999997424" rpy="0 0 0"/>
<mass value="0.04066693929476376812" />
<inertia ixx="0.00014699519269296089635" ixy="1.1251043011408027027e-35"  ixz="7.3794208274357135566e-23" iyy="0.00014699519269296089635" iyz="-2.3290085673779520776e-19" izz="1.8110290680857592194e-06" />
</inertial>
</link>

<link name="fermeture8_A">
<inertial>
<origin xyz="0 0 0" rpy="0 0 0" />
<mass value="1e-9" />
<inertia ixx="0" ixy="0" ixz="0" iyy="0" iyz="0" izz="0" />
</inertial>
</link>
<joint name="fermeture8_A_frame" type="fixed">
<origin xyz="-2.7755575615628913511e-17 5.5511151231257827021e-17 -0.207625000000000004" rpy="-2.6307610252349813393e-16 -4.4967931276871329446e-17 3.1415926535897926719" />
<parent link="rode_foot_3" />
<child link="fermeture8_A" />
<axis xyz="0 0 0"/>
</joint>

<joint name="to_rotule_free_renvois_hanche3" type="revolute">
<origin xyz="-0.10695833333333418236 -0.062916666666666842822 -3.7747582837255322374e-15" rpy="-1.57079632679489678 -3.8105612564473861213e-16 -3.5207910199695531523e-17" />
<parent link="renvois_hanche_2" />
<child link="rode_foot_3" />
<axis xyz="0 0 1"/>
<limit effort="1" velocity="20" />
<joint_properties friction="0.0"/>
</joint>

<joint name="free_renvois_hanche1" type="revolute">
<origin xyz="0.072354166666666955288 -0.053479166666666633212 -0.13527083333333345117" rpy="1.308414229027936131e-29 7.507728643138478293e-30 0.37563002773728437766" />
<parent link="tarsus" />
<child link="renvois_hanche_2" />
<axis xyz="0 0 1"/>
<limit effort="1" velocity="20" />
<joint_properties friction="0.0"/>
</joint>

<link name="renvois_hanche">
<visual>
<origin xyz="-0.066062500000000079492 0.82735416666666683483 0.053479166666666688723" rpy="1.570796326794896558 -2.3848366483884896898e-33 -1.2103825396487620425e-17" />
<geometry>
<mesh filename="package:///renvois_hanche.stl"/>
</geometry>
<material name="renvois_hanche_material">
<color rgba="0.76862745098039220171 0.88627450980392152857 0.95294117647058818044 1.0"/>
</material>
</visual>
<collision>
<origin xyz="-0.066062500000000079492 0.82735416666666683483 0.053479166666666688723" rpy="1.570796326794896558 -2.3848366483884896898e-33 -1.2103825396487620425e-17" />
<geometry>
<mesh filename="package:///renvois_hanche.stl"/>
</geometry>
<material name="renvois_hanche_material">
<color rgba="0.76862745098039220171 0.88627450980392152857 0.95294117647058818044 1.0"/>
</material>
</collision>
<inertial>
<origin xyz="-0.071838889332594982329 0.028325668402721215777 -0.0062916666666666468122" rpy="0 0 0"/>
<mass value="0.052048361392958063243" />
<inertia ixx="1.9958534542913006378e-05" ixy="2.9941729812280446806e-05"  ixz="-1.3504278540058994542e-37" iyy="8.5925596188234551454e-05" iyz="-2.5325719219945351813e-37" izz="0.00010451057206434102105" />
</inertial>
</link>

<link name="piston_3">
<visual>
<origin xyz="-0.10179556944408765795 -0.15392457132099851558 0.95649999999999990585" rpy="3.141592653589793116 1.5651750219141293086e-17 8.1766824171669237254e-33" />
<geometry>
<mesh filename="package:///piston.stl"/>
</geometry>
<material name="piston_material">
<color rgba="0.91764705882352937127 0.91764705882352937127 0.91764705882352937127 1.0"/>
</material>
</visual>
<collision>
<origin xyz="-0.10179556944408765795 -0.15392457132099851558 0.95649999999999990585" rpy="3.141592653589793116 1.5651750219141293086e-17 8.1766824171669237254e-33" />
<geometry>
<mesh filename="package:///piston.stl"/>
</geometry>
<material name="piston_material">
<color rgba="0.91764705882352937127 0.91764705882352937127 0.91764705882352937127 1.0"/>
</material>
</collision>
<inertial>
<origin xyz="4.1633363423443370266e-17 -1.4130889941619082348e-32 -0.012500000000000064879" rpy="0 0 0"/>
<mass value="0.0048966814322412765756" />
<inertia ixx="3.6406794569277529096e-07" ixy="3.5259545393292108696e-39"  ixz="-9.7017646127402067748e-24" iyy="3.6406794569277529096e-07" iyz="1.0284503729350356091e-39" izz="2.1806490886041670108e-07" />
</inertial>
</link>

<link name="fermeture2_B">
<inertial>
<origin xyz="0 0 0" rpy="0 0 0" />
<mass value="1e-9" />
<inertia ixx="0" ixy="0" ixz="0" iyy="0" iyz="0" izz="0" />
</inertial>
</link>
<joint name="fermeture2_B_frame" type="fixed">
<origin xyz="4.1633363423443370266e-17 0 -0.025000000000000188738" rpy="3.141592653589793116 1.3779502303722609972e-17 -1.6028373921264690291e-17" />
<parent link="piston_3" />
<child link="fermeture2_B" />
<axis xyz="0 0 0"/>
</joint>

<joint name="to_rotule_free_attache_hanche2" type="revolute">
<origin xyz="-0.13212499999999988143 0.037750000000000116795 -2.7755575615628913511e-17" rpy="1.570796326794896558 8.014186960619273474e-18 3.141592653589793116" />
<parent link="renvois_hanche" />
<child link="piston_3" />
<axis xyz="0 0 1"/>
<limit effort="1" velocity="20" />
<joint_properties friction="0.0"/>
</joint>

<link name="rode_foot_4">
<visual>
<origin xyz="-0.035362814756395882787 -1.1126229936003482202 -0.069208333333333482695" rpy="-1.570796326794896558 -1.5707963267948950037 0" />
<geometry>
<mesh filename="package:///rode_foot.stl"/>
</geometry>
<material name="rode_foot_material">
<color rgba="0.97254901960784312376 0.52941176470588235947 0.0039215686274509803377 1.0"/>
</material>
</visual>
<collision>
<origin xyz="-0.035362814756395882787 -1.1126229936003482202 -0.069208333333333482695" rpy="-1.570796326794896558 -1.5707963267948950037 0" />
<geometry>
<mesh filename="package:///rode_foot.stl"/>
</geometry>
<material name="rode_foot_material">
<color rgba="0.97254901960784312376 0.52941176470588235947 0.0039215686274509803377 1.0"/>
</material>
</collision>
<inertial>
<origin xyz="-4.1884279132430183043e-19 0 -0.103812500000000002" rpy="0 0 0"/>
<mass value="0.04066693929476376812" />
<inertia ixx="0.00014699519269296089635" ixy="-4.9893888552378156665e-36"  ixz="1.8011245261067254082e-21" iyy="0.00014699519269296089635" iyz="-2.3290085673779520776e-19" izz="1.8110290680857596429e-06" />
</inertial>
</link>

<link name="fermeture7_B">
<inertial>
<origin xyz="0 0 0" rpy="0 0 0" />
<mass value="1e-9" />
<inertia ixx="0" ixy="0" ixz="0" iyy="0" iyz="0" izz="0" />
</inertial>
</link>
<joint name="fermeture7_B_frame" type="fixed">
<origin xyz="-1.3877787807814456755e-17 -2.2204460492503130808e-16 -0.20762500000000011502" rpy="1.794624726976586498e-17 1.2103825396487620425e-17 -3.141592653589793116" />
<parent link="rode_foot_4" />
<child link="fermeture7_B" />
<axis xyz="0 0 0"/>
</joint>

<joint name="to_rotule_free_renvois_hanche4" type="revolute">
<origin xyz="-0.10695833333333407134 0.062916666666667064867 5.5511151231257827021e-17" rpy="1.570796326794896558 -2.1694817664039273641e-17 -1.2103825396487620425e-17" />
<parent link="renvois_hanche" />
<child link="rode_foot_4" />
<axis xyz="0 0 1"/>
<limit effort="1" velocity="20" />
<joint_properties friction="0.0"/>
</joint>

<joint name="free_renvois_hanche2" type="revolute">
<origin xyz="0.072354166666666844265 -0.053479166666666633212 -0.028312500000000018208" rpy="3.141592653589793116 -1.5804407405094530311e-30 0.26045626790084336344" />
<parent link="tarsus" />
<child link="renvois_hanche" />
<axis xyz="0 0 1"/>
<limit effort="1" velocity="20" />
<joint_properties friction="0.0"/>
</joint>

<link name="motteur_rotation">
<visual>
<origin xyz="0.037749999999999991895 1.0161041666666668082 -0.1384166666666665213" rpy="1.570796326794896558 1.5707963267948950037 0" />
<geometry>
<mesh filename="package:///motteur_rotation.stl"/>
</geometry>
<material name="motteur_rotation_material">
<color rgba="0.2313725490196078538 0.38039215686274507888 0.7058823529411765163 1.0"/>
</material>
</visual>
<collision>
<origin xyz="0.037749999999999991895 1.0161041666666668082 -0.1384166666666665213" rpy="1.570796326794896558 1.5707963267948950037 0" />
<geometry>
<mesh filename="package:///motteur_rotation.stl"/>
</geometry>
<material name="motteur_rotation_material">
<color rgba="0.2313725490196078538 0.38039215686274507888 0.7058823529411765163 1.0"/>
</material>
</collision>
<inertial>
<origin xyz="-6.9388939039072422443e-18 0 -0.038600225225225229253" rpy="0 0 0"/>
<mass value="0.050662516966540720176" />
<inertia ixx="1.6868799164751242944e-05" ixy="1.0597451758430356669e-37"  ixz="4.9754026830239486706e-37" iyy="1.6868799164751242944e-05" iyz="-8.5293484665262147169e-21" izz="1.155183150425073109e-05" />
</inertial>
</link>

<link name="piston_4">
<visual>
<origin xyz="-0.10179556944408768571 -0.15392457132099851558 0.95649999999999990585" rpy="3.141592653589793116 -8.351260583792729e-32 4.1731917109076003619e-33" />
<geometry>
<mesh filename="package:///piston.stl"/>
</geometry>
<material name="piston_material">
<color rgba="0.91764705882352937127 0.91764705882352937127 0.91764705882352937127 1.0"/>
</material>
</visual>
<collision>
<origin xyz="-0.10179556944408768571 -0.15392457132099851558 0.95649999999999990585" rpy="3.141592653589793116 -8.351260583792729e-32 4.1731917109076003619e-33" />
<geometry>
<mesh filename="package:///piston.stl"/>
</geometry>
<material name="piston_material">
<color rgba="0.91764705882352937127 0.91764705882352937127 0.91764705882352937127 1.0"/>
</material>
</collision>
<inertial>
<origin xyz="0 2.6799837947256404897e-33 -0.01250000000000017937" rpy="0 0 0"/>
<mass value="0.0048966814322412765756" />
<inertia ixx="3.6406794569277529096e-07" ixy="3.0386506663490271845e-39"  ixz="1.2193094066129105798e-38" iyy="3.6406794569277529096e-07" iyz="-1.9039464171354945741e-39" izz="2.1806490886041675402e-07" />
</inertial>
</link>

<link name="fermeture1_A">
<inertial>
<origin xyz="0 0 0" rpy="0 0 0" />
<mass value="1e-9" />
<inertia ixx="0" ixy="0" ixz="0" iyy="0" iyz="0" izz="0" />
</inertial>
</link>
<joint name="fermeture1_A_frame" type="fixed">
<origin xyz="0 0 -0.025000000000000133227" rpy="8.8831754777918187002e-30 -2.3157694083552497375e-29 2.8144901665607526915e-30" />
<parent link="piston_4" />
<child link="fermeture1_A" />
<axis xyz="0 0 0"/>
</joint>

<joint name="mot_cheville2" type="prismatic">
<origin xyz="-9.7144514654701197287e-17 2.2204460492503130808e-16 -4.7184478546569152968e-16" rpy="-3.141592653589793116 2.3759403100678058489e-29 3.141592653589793116" />
<parent link="motteur_rotation" />
<child link="piston_4" />
<axis xyz="0 0 1"/>
<limit effort="1" velocity="20" />
<joint_properties friction="0.0"/>
</joint>

<joint name="to_rotule_free_attache_moeur_4" type="revolute">
<origin xyz="-0.075500000000000150324 -0.044041666666666701158 -0.13527083333333378423" rpy="1.570796326794896558 -1.4677322981672841489e-30 1.242455925723093033e-29" />
<parent link="tarsus" />
<child link="motteur_rotation" />
<axis xyz="0 0 1"/>
<limit effort="1" velocity="20" />
<joint_properties friction="0.0"/>
</joint>

<link name="motteur_rotation_2">
<visual>
<origin xyz="0.037750000000000005773 1.0161041666666668082 -0.1384166666666665213" rpy="1.570796326794896558 1.5707963267948950037 0" />
<geometry>
<mesh filename="package:///motteur_rotation.stl"/>
</geometry>
<material name="motteur_rotation_material">
<color rgba="0.2313725490196078538 0.38039215686274507888 0.7058823529411765163 1.0"/>
</material>
</visual>
<collision>
<origin xyz="0.037750000000000005773 1.0161041666666668082 -0.1384166666666665213" rpy="1.570796326794896558 1.5707963267948950037 0" />
<geometry>
<mesh filename="package:///motteur_rotation.stl"/>
</geometry>
<material name="motteur_rotation_material">
<color rgba="0.2313725490196078538 0.38039215686274507888 0.7058823529411765163 1.0"/>
</material>
</collision>
<inertial>
<origin xyz="6.9388939039072268369e-18 0 -0.038600225225225229253" rpy="0 0 0"/>
<mass value="0.050662516966540720176" />
<inertia ixx="1.6868799164751242944e-05" ixy="2.0125161845097941744e-39"  ixz="-3.2770492451901197032e-53" iyy="1.6868799164751242944e-05" iyz="-8.5293484665262147169e-21" izz="1.155183150425073109e-05" />
</inertial>
</link>

<link name="piston_5">
<visual>
<origin xyz="-0.10179556944408767183 -0.15392457132099851558 0.9565000000000001279" rpy="3.141592653589793116 -0 1.0917037998626663713e-33" />
<geometry>
<mesh filename="package:///piston.stl"/>
</geometry>
<material name="piston_material">
<color rgba="0.91764705882352937127 0.91764705882352937127 0.91764705882352937127 1.0"/>
</material>
</visual>
<collision>
<origin xyz="-0.10179556944408767183 -0.15392457132099851558 0.9565000000000001279" rpy="3.141592653589793116 -0 1.0917037998626663713e-33" />
<geometry>
<mesh filename="package:///piston.stl"/>
</geometry>
<material name="piston_material">
<color rgba="0.91764705882352937127 0.91764705882352937127 0.91764705882352937127 1.0"/>
</material>
</collision>
<inertial>
<origin xyz="1.3877787807814456755e-17 1.1113060997129445525e-34 -0.012499999999999953856" rpy="0 0 0"/>
<mass value="0.0048966814322412765756" />
<inertia ixx="3.6406794569277529096e-07" ixy="7.9490871946639231094e-40"  ixz="0" iyy="3.6406794569277529096e-07" iyz="0" izz="2.1806490886041675402e-07" />
</inertial>
</link>

<link name="fermeture2_A">
<inertial>
<origin xyz="0 0 0" rpy="0 0 0" />
<mass value="1e-9" />
<inertia ixx="0" ixy="0" ixz="0" iyy="0" iyz="0" izz="0" />
</inertial>
</link>
<joint name="fermeture2_A_frame" type="fixed">
<origin xyz="0 0 -0.024999999999999994449" rpy="4.5710791672064410631e-29 -6.6855961717480750509e-29 7.600290954118671857e-29" />
<parent link="piston_5" />
<child link="fermeture2_A" />
<axis xyz="0 0 0"/>
</joint>

<joint name="mot_cheville1" type="prismatic">
<origin xyz="0 0 2.498001805406602216e-16" rpy="-3.141592653589793116 6.705317694378600346e-29 3.141592653589793116" />
<parent link="motteur_rotation_2" />
<child link="piston_5" />
<axis xyz="0 0 1"/>
<limit effort="1" velocity="20" />
<joint_properties friction="0.0"/>
</joint>

<joint name="to_rotule_free_attache_moeur_5" type="revolute">
<origin xyz="-0.075500000000000150324 -0.044041666666666756669 -0.028312500000000073719" rpy="1.570796326794896558 -3.8063482729435784759e-29 3.4118234150808760584e-29" />
<parent link="tarsus" />
<child link="motteur_rotation_2" />
<axis xyz="0 0 1"/>
<limit effort="1" velocity="20" />
<joint_properties friction="0.0"/>
</joint>

<link name="motteur_rotation_3">
<visual>
<origin xyz="0.037749999999999998834 1.0161041666666668082 -0.13841666666666646579" rpy="1.570796326794896558 1.5707963267948950037 0" />
<geometry>
<mesh filename="package:///motteur_rotation.stl"/>
</geometry>
<material name="motteur_rotation_material">
<color rgba="0.2313725490196078538 0.38039215686274507888 0.7058823529411765163 1.0"/>
</material>
</visual>
<collision>
<origin xyz="0.037749999999999998834 1.0161041666666668082 -0.13841666666666646579" rpy="1.570796326794896558 1.5707963267948950037 0" />
<geometry>
<mesh filename="package:///motteur_rotation.stl"/>
</geometry>
<material name="motteur_rotation_material">
<color rgba="0.2313725490196078538 0.38039215686274507888 0.7058823529411765163 1.0"/>
</material>
</collision>
<inertial>
<origin xyz="6.8800127248513569144e-34 0 -0.038600225225225173742" rpy="0 0 0"/>
<mass value="0.050662516966540720176" />
<inertia ixx="1.6868799164751242944e-05" ixy="-6.1687613390695016878e-38"  ixz="1.8322596427960366942e-53" iyy="1.6868799164751242944e-05" iyz="-8.5293484665262147169e-21" izz="1.155183150425073109e-05" />
</inertial>
</link>

<link name="piston_6">
<visual>
<origin xyz="-0.10179556944408774122 -0.15392457132099851558 0.95649999999999990585" rpy="3.141592653589793116 -0 2.9798088435973250695e-33" />
<geometry>
<mesh filename="package:///piston.stl"/>
</geometry>
<material name="piston_material">
<color rgba="0.91764705882352937127 0.91764705882352937127 0.91764705882352937127 1.0"/>
</material>
</visual>
<collision>
<origin xyz="-0.10179556944408774122 -0.15392457132099851558 0.95649999999999990585" rpy="3.141592653589793116 -0 2.9798088435973250695e-33" />
<geometry>
<mesh filename="package:///piston.stl"/>
</geometry>
<material name="piston_material">
<color rgba="0.91764705882352937127 0.91764705882352937127 0.91764705882352937127 1.0"/>
</material>
</collision>
<inertial>
<origin xyz="-5.5511151231257827021e-17 3.0333133806851811966e-34 -0.01250000000000017937" rpy="0 0 0"/>
<mass value="0.0048966814322412765756" />
<inertia ixx="3.6406794569277529096e-07" ixy="2.1697057686587880373e-39"  ixz="0" iyy="3.6406794569277529096e-07" iyz="0" izz="2.1806490886041675402e-07" />
</inertial>
</link>

<link name="fermeture6_A">
<inertial>
<origin xyz="0 0 0" rpy="0 0 0" />
<mass value="1e-9" />
<inertia ixx="0" ixy="0" ixz="0" iyy="0" iyz="0" izz="0" />
</inertial>
</link>
<joint name="fermeture6_A_frame" type="fixed">
<origin xyz="-5.5511151231257827021e-17 -6.9388939039072283776e-18 -0.2225000000000000866" rpy="9.211775309298636418e-27 -7.0307228177822677157e-28 -1.570796326794896558" />
<parent link="piston_6" />
<child link="fermeture6_A" />
<axis xyz="0 0 0"/>
</joint>

<joint name="mot_genoux" type="prismatic">
<origin xyz="-6.9388939039072283776e-18 5.5511151231257827021e-17 -0.062916666666666620777" rpy="-1.3213420162451947741e-29 -1.4845376160127915913e-28 1.570796326794896558" />
<parent link="motteur_rotation_3" />
<child link="piston_6" />
<axis xyz="0 0 1"/>
<limit effort="1" velocity="20" />
<joint_properties friction="0.0"/>
</joint>

<joint name="to_rotule_free_attache_mour_6" type="revolute">
<origin xyz="0.037750000000000172307 -0.1887499999999999456 -0.081791666666666706931" rpy="1.570796326794896558 -2.30400890492067767e-30 -3.141592653589793116" />
<parent link="tarsus" />
<child link="motteur_rotation_3" />
<axis xyz="0 0 1"/>
<limit effort="1" velocity="20" />
<joint_properties friction="0.0"/>
</joint>

<link name="piston_7">
<visual>
<origin xyz="-0.10179556944408767183 0.15392457132099851558 -0.98150000000000003908" rpy="0 -0 2.9798088438269088014e-33" />
<geometry>
<mesh filename="package:///piston.stl"/>
</geometry>
<material name="piston_material">
<color rgba="0.91764705882352937127 0.91764705882352937127 0.91764705882352937127 1.0"/>
</material>
</visual>
<collision>
<origin xyz="-0.10179556944408767183 0.15392457132099851558 -0.98150000000000003908" rpy="0 -0 2.9798088438269088014e-33" />
<geometry>
<mesh filename="package:///piston.stl"/>
</geometry>
<material name="piston_material">
<color rgba="0.91764705882352937127 0.91764705882352937127 0.91764705882352937127 1.0"/>
</material>
</collision>
<inertial>
<origin xyz="1.3877787807814456755e-17 3.0333133809188873152e-34 -0.012499999999999953856" rpy="0 0 0"/>
<mass value="0.0048966814322412765756" />
<inertia ixx="3.6406794569277529096e-07" ixy="2.1697057686587759655e-39"  ixz="0" iyy="3.6406794569277529096e-07" iyz="0" izz="2.1806490886041675402e-07" />
</inertial>
</link>

<link name="fermeture3_A">
<inertial>
<origin xyz="0 0 0" rpy="0 0 0" />
<mass value="1e-9" />
<inertia ixx="0" ixy="0" ixz="0" iyy="0" iyz="0" izz="0" />
</inertial>
</link>
<joint name="fermeture3_A_frame" type="fixed">
<origin xyz="1.3877787807814456755e-17 0 -0.025000000000000188738" rpy="3.141592653589793116 1.1832913578315177081e-30 2.6715483397867810683e-30" />
<parent link="piston_7" />
<child link="fermeture3_A" />
<axis xyz="0 0 0"/>
</joint>

<joint name="to_rotule_free_hanche_attache1" type="revolute">
<origin xyz="0.069208333333333371673 -2.7755575615628913511e-17 -0.044041666666666645646" rpy="-1.57079632679489678 1.4184284915909716117e-30 -3.141592653589793116" />
<parent link="tarsus" />
<child link="piston_7" />
<axis xyz="0 0 1"/>
<limit effort="1" velocity="20" />
<joint_properties friction="0.0"/>
</joint>

<link name="piston_8">
<visual>
<origin xyz="-0.10179556944408765795 0.15392457132099851558 -0.98150000000000003908" rpy="0 -0 2.9798088438269088014e-33" />
<geometry>
<mesh filename="package:///piston.stl"/>
</geometry>
<material name="piston_material">
<color rgba="0.91764705882352937127 0.91764705882352937127 0.91764705882352937127 1.0"/>
</material>
</visual>
<collision>
<origin xyz="-0.10179556944408765795 0.15392457132099851558 -0.98150000000000003908" rpy="0 -0 2.9798088438269088014e-33" />
<geometry>
<mesh filename="package:///piston.stl"/>
</geometry>
<material name="piston_material">
<color rgba="0.91764705882352937127 0.91764705882352937127 0.91764705882352937127 1.0"/>
</material>
</collision>
<inertial>
<origin xyz="2.7755575615628913511e-17 3.0333133809188873152e-34 -0.012499999999999953856" rpy="0 0 0"/>
<mass value="0.0048966814322412765756" />
<inertia ixx="3.6406794569277529096e-07" ixy="2.1697057686587759655e-39"  ixz="0" iyy="3.6406794569277529096e-07" iyz="0" izz="2.1806490886041675402e-07" />
</inertial>
</link>

<link name="fermeture4_A">
<inertial>
<origin xyz="0 0 0" rpy="0 0 0" />
<mass value="1e-9" />
<inertia ixx="0" ixy="0" ixz="0" iyy="0" iyz="0" izz="0" />
</inertial>
</link>
<joint name="fermeture4_A_frame" type="fixed">
<origin xyz="1.3877787807814456755e-17 0 -0.025000000000000188738" rpy="3.141592653589793116 1.1832913578315177081e-30 2.6715483397867810683e-30" />
<parent link="piston_8" />
<child link="fermeture4_A" />
<axis xyz="0 0 0"/>
</joint>

<joint name="to_rotule_free_hanche_attache2" type="revolute">
<origin xyz="0.069208333333333357795 -2.7755575615628913511e-17 0.044041666666666645646" rpy="-1.57079632679489678 1.4184284915909716117e-30 -3.141592653589793116" />
<parent link="tarsus" />
<child link="piston_8" />
<axis xyz="0 0 1"/>
<limit effort="1" velocity="20" />
<joint_properties friction="0.0"/>
</joint>

<joint name="free_cardan_xhips" type="revolute">
<origin xyz="7.5000000000019495516e-05 0 -7.5000000000000413558e-05" rpy="-3.141592653589793116 1.570796326794896558 0" />
<parent link="cardan_foot" />
<child link="tarsus" />
<axis xyz="0 0 1"/>
<limit effort="1" velocity="20" />
<joint_properties friction="0.0"/>
</joint>

<joint name="free_cardans_yhips" type="revolute">
<origin xyz="1.7347234759768070944e-18 0 -0.18875000000000008438" rpy="-1.570796326794896558 -8.6002330739638796169e-18 1.570796326794896558" />
<parent link="hanche_2" />
<child link="cardan_foot" />
<axis xyz="0 0 1"/>
<limit effort="1" velocity="20" />
<joint_properties friction="0.0"/>
</joint>

<link name="cardan_hache">
<visual>
<origin xyz="0.12426041666666665098 0.9815000000000001501 -0.006291666666668128266" rpy="1.570796326794896558 1.5707963267948950037 0" />
<geometry>
<mesh filename="package:///cardan_hache.stl"/>
</geometry>
<material name="cardan_hache_material">
<color rgba="0.49803921568627451677 0.49803921568627451677 0.49803921568627451677 1.0"/>
</material>
</visual>
<collision>
<origin xyz="0.12426041666666665098 0.9815000000000001501 -0.006291666666668128266" rpy="1.570796326794896558 1.5707963267948950037 0" />
<geometry>
<mesh filename="package:///cardan_hache.stl"/>
</geometry>
<material name="cardan_hache_material">
<color rgba="0.49803921568627451677 0.49803921568627451677 0.49803921568627451677 1.0"/>
</material>
</collision>
<inertial>
<origin xyz="-9.8001816547165751412e-49 1.5739742842413306789e-11 -0.038564852711678976327" rpy="0 0 0"/>
<mass value="0.015650981021718499836" />
<inertia ixx="7.4066993033887062477e-06" ixy="-2.6990293692808555784e-13"  ixz="4.3297163875955968083e-28" iyy="7.5433853822706915882e-06" iyz="1.149566359532617677e-13" izz="8.4764734220375487706e-07" />
</inertial>
</link>

<link name="moteur_hanche1">
<visual>
<origin xyz="-0.05662500000000013356 -0.98150000000000003908 -0.12426041666666666485" rpy="-1.570796326794896558 3.0366328384956959949e-47 0" />
<geometry>
<mesh filename="package:///moteur_hanche1.stl"/>
</geometry>
<material name="moteur_hanche1_material">
<color rgba="0.98039215686274505668 0.71372549019607844922 0.0039215686274509803377 1.0"/>
</material>
</visual>
<collision>
<origin xyz="-0.05662500000000013356 -0.98150000000000003908 -0.12426041666666666485" rpy="-1.570796326794896558 3.0366328384956959949e-47 0" />
<geometry>
<mesh filename="package:///moteur_hanche1.stl"/>
</geometry>
<material name="moteur_hanche1_material">
<color rgba="0.98039215686274505668 0.71372549019607844922 0.0039215686274509803377 1.0"/>
</material>
</collision>
<inertial>
<origin xyz="-2.0816681711721685133e-17 -0.014684805075465323654 2.7755575615628913511e-17" rpy="0 0 0"/>
<mass value="0.046264571606101846657" />
<inertia ixx="1.1597158512617963014e-05" ixy="0"  ixz="-2.2167880810779967222e-54" iyy="1.4057782313436138118e-05" iyz="0" izz="1.1524156994201784619e-05" />
</inertial>
</link>

<link name="piston_9">
<visual>
<origin xyz="-0.10179556944408765795 0.15392457132099851558 -0.98150000000000003908" rpy="0 -0 3.0366328384956959949e-47" />
<geometry>
<mesh filename="package:///piston.stl"/>
</geometry>
<material name="piston_material">
<color rgba="0.91764705882352937127 0.91764705882352937127 0.91764705882352937127 1.0"/>
</material>
</visual>
<collision>
<origin xyz="-0.10179556944408765795 0.15392457132099851558 -0.98150000000000003908" rpy="0 -0 3.0366328384956959949e-47" />
<geometry>
<mesh filename="package:///piston.stl"/>
</geometry>
<material name="piston_material">
<color rgba="0.91764705882352937127 0.91764705882352937127 0.91764705882352937127 1.0"/>
</material>
</collision>
<inertial>
<origin xyz="2.7755575615628913511e-17 3.0911576898728573213e-48 -0.012499999999999953856" rpy="0 0 0"/>
<mass value="0.0048966814322412765756" />
<inertia ixx="3.6406794569277529096e-07" ixy="7.9562471932245188724e-66"  ixz="0" iyy="3.6406794569277529096e-07" iyz="0" izz="2.1806490886041675402e-07" />
</inertial>
</link>

<link name="fermeture4_B">
<inertial>
<origin xyz="0 0 0" rpy="0 0 0" />
<mass value="1e-9" />
<inertia ixx="0" ixy="0" ixz="0" iyy="0" iyz="0" izz="0" />
</inertial>
</link>
<joint name="fermeture4_B_frame" type="fixed">
<origin xyz="0 0 -0.025000000000000077716" rpy="-1.5777218104420376238e-30 -2.8398992587956424995e-29 4.5495763117987201118e-30" />
<parent link="piston_9" />
<child link="fermeture4_B" />
<axis xyz="0 0 0"/>
</joint>

<joint name="mot_hanchexy1" type="prismatic">
<origin xyz="-1.3877787807814456755e-17 -0.031458333333333254878 0" rpy="-1.570796326794896558 3.0366328384956959949e-47 0" />
<parent link="moteur_hanche1" />
<child link="piston_9" />
<axis xyz="0 0 1"/>
<limit effort="1" velocity="20" />
<joint_properties friction="0.0"/>
</joint>

<joint name="free_attache_moeur_hanchexy2" type="revolute">
<origin xyz="0 -1.3877787807814456755e-17 -0.062916666666666662411" rpy="-0 -1.5707963267948950037 0" />
<parent link="cardan_hache" />
<child link="moteur_hanche1" />
<axis xyz="0 0 1"/>
<limit effort="1" velocity="20" />
<joint_properties friction="0.0"/>
</joint>

<joint name="free_attache_moeur_hanche_1" type="revolute">
<origin xyz="0.012500000000000000694 -0.0424687499999999718 -0.08808333333333337456" rpy="1.570796326794896558 1.5777218104420306173e-30 -1.570796326794896558" />
<parent link="hanche_2" />
<child link="cardan_hache" />
<axis xyz="0 0 1"/>
<limit effort="1" velocity="20" />
<joint_properties friction="0.0"/>
</joint>

<link name="cardan_hache_2">
<visual>
<origin xyz="0.12426041666666665098 0.9815000000000001501 -0.006291666666668128266" rpy="1.570796326794896558 1.5707963267948950037 0" />
<geometry>
<mesh filename="package:///cardan_hache.stl"/>
</geometry>
<material name="cardan_hache_material">
<color rgba="0.49803921568627451677 0.49803921568627451677 0.49803921568627451677 1.0"/>
</material>
</visual>
<collision>
<origin xyz="0.12426041666666665098 0.9815000000000001501 -0.006291666666668128266" rpy="1.570796326794896558 1.5707963267948950037 0" />
<geometry>
<mesh filename="package:///cardan_hache.stl"/>
</geometry>
<material name="cardan_hache_material">
<color rgba="0.49803921568627451677 0.49803921568627451677 0.49803921568627451677 1.0"/>
</material>
</collision>
<inertial>
<origin xyz="-9.8001816547165751412e-49 1.5739742842413306789e-11 -0.038564852711678976327" rpy="0 0 0"/>
<mass value="0.015650981021718499836" />
<inertia ixx="7.4066993033887062477e-06" ixy="-2.6990293692808555784e-13"  ixz="4.3297163875955968083e-28" iyy="7.5433853822706915882e-06" iyz="1.149566359532617677e-13" izz="8.4764734220375487706e-07" />
</inertial>
</link>

<link name="moteur_hanche1_2">
<visual>
<origin xyz="-0.05662500000000013356 -0.98150000000000003908 -0.12426041666666667873" rpy="-1.570796326794896558 3.0366328384956959949e-47 0" />
<geometry>
<mesh filename="package:///moteur_hanche1.stl"/>
</geometry>
<material name="moteur_hanche1_material">
<color rgba="0.98039215686274505668 0.71372549019607844922 0.0039215686274509803377 1.0"/>
</material>
</visual>
<collision>
<origin xyz="-0.05662500000000013356 -0.98150000000000003908 -0.12426041666666667873" rpy="-1.570796326794896558 3.0366328384956959949e-47 0" />
<geometry>
<mesh filename="package:///moteur_hanche1.stl"/>
</geometry>
<material name="moteur_hanche1_material">
<color rgba="0.98039215686274505668 0.71372549019607844922 0.0039215686274509803377 1.0"/>
</material>
</collision>
<inertial>
<origin xyz="-2.0816681711721685133e-17 -0.014684805075465323654 1.3877787807814456755e-17" rpy="0 0 0"/>
<mass value="0.046264571606101846657" />
<inertia ixx="1.1597158512617963014e-05" ixy="0"  ixz="-2.2167880810779967222e-54" iyy="1.4057782313436138118e-05" iyz="0" izz="1.1524156994201784619e-05" />
</inertial>
</link>

<link name="piston_10">
<visual>
<origin xyz="-0.10179556944408765795 0.15392457132099851558 -0.98150000000000003908" rpy="0 -0 3.0366328384956959949e-47" />
<geometry>
<mesh filename="package:///piston.stl"/>
</geometry>
<material name="piston_material">
<color rgba="0.91764705882352937127 0.91764705882352937127 0.91764705882352937127 1.0"/>
</material>
</visual>
<collision>
<origin xyz="-0.10179556944408765795 0.15392457132099851558 -0.98150000000000003908" rpy="0 -0 3.0366328384956959949e-47" />
<geometry>
<mesh filename="package:///piston.stl"/>
</geometry>
<material name="piston_material">
<color rgba="0.91764705882352937127 0.91764705882352937127 0.91764705882352937127 1.0"/>
</material>
</collision>
<inertial>
<origin xyz="2.7755575615628913511e-17 3.0911576898728573213e-48 -0.012499999999999953856" rpy="0 0 0"/>
<mass value="0.0048966814322412765756" />
<inertia ixx="3.6406794569277529096e-07" ixy="7.9562471932245188724e-66"  ixz="0" iyy="3.6406794569277529096e-07" iyz="0" izz="2.1806490886041675402e-07" />
</inertial>
</link>

<link name="fermeture3_B">
<inertial>
<origin xyz="0 0 0" rpy="0 0 0" />
<mass value="1e-9" />
<inertia ixx="0" ixy="0" ixz="0" iyy="0" iyz="0" izz="0" />
</inertial>
</link>
<joint name="fermeture3_B_frame" type="fixed">
<origin xyz="0 0 -0.025000000000000077716" rpy="-1.5777218104420376238e-30 -2.8398992587956424995e-29 4.5495763117987201118e-30" />
<parent link="piston_10" />
<child link="fermeture3_B" />
<axis xyz="0 0 0"/>
</joint>

<joint name="mot_hanchexy2" type="prismatic">
<origin xyz="-1.3877787807814456755e-17 -0.031458333333333476922 -5.5511151231257827021e-17" rpy="-1.570796326794896558 3.0366328384956959949e-47 0" />
<parent link="moteur_hanche1_2" />
<child link="piston_10" />
<axis xyz="0 0 1"/>
<limit effort="1" velocity="20" />
<joint_properties friction="0.0"/>
</joint>

<joint name="free_attache_moeur_hanchexy" type="revolute">
<origin xyz="0 2.0816681711721685133e-16 -0.062916666666666690166" rpy="-0 -1.5707963267948950037 0" />
<parent link="cardan_hache_2" />
<child link="moteur_hanche1_2" />
<axis xyz="0 0 1"/>
<limit effort="1" velocity="20" />
<joint_properties friction="0.0"/>
</joint>

<joint name="free_attache_moeur_hanche_3" type="revolute">
<origin xyz="0.012500000000000000694 0.042468750000000027311 -0.08808333333333337456" rpy="1.570796326794896558 1.5777218104420306173e-30 -1.570796326794896558" />
<parent link="hanche_2" />
<child link="cardan_hache_2" />
<axis xyz="0 0 1"/>
<limit effort="1" velocity="20" />
<joint_properties friction="0.0"/>
</joint>

<link name="piston_11">
<visual>
<origin xyz="-0.10179556944408768571 0.15392457132099851558 -0.98150000000000003908" rpy="0 -1.0626803141476406122e-45 0" />
<geometry>
<mesh filename="package:///piston.stl"/>
</geometry>
<material name="piston_material">
<color rgba="0.91764705882352937127 0.91764705882352937127 0.91764705882352937127 1.0"/>
</material>
</visual>
<collision>
<origin xyz="-0.10179556944408768571 0.15392457132099851558 -0.98150000000000003908" rpy="0 -1.0626803141476406122e-45 0" />
<geometry>
<mesh filename="package:///piston.stl"/>
</geometry>
<material name="piston_material">
<color rgba="0.91764705882352937127 0.91764705882352937127 0.91764705882352937127 1.0"/>
</material>
</collision>
<inertial>
<origin xyz="0 0 -0.012499999999999953856" rpy="0 0 0"/>
<mass value="0.0048966814322412765756" />
<inertia ixx="3.6406794569277529096e-07" ixy="0"  ixz="1.5515455304755772386e-52" iyy="3.6406794569277529096e-07" iyz="0" izz="2.1806490886041675402e-07" />
</inertial>
</link>

<link name="fermeture5_B">
<inertial>
<origin xyz="0 0 0" rpy="0 0 0" />
<mass value="1e-9" />
<inertia ixx="0" ixy="0" ixz="0" iyy="0" iyz="0" izz="0" />
</inertial>
</link>
<joint name="fermeture5_B_frame" type="fixed">
<origin xyz="0 -1.3877787807814456755e-17 -0.025000000000000074246" rpy="-3.141592653589793116 3.0278985551981991197e-28 -1.570796326794896558" />
<parent link="piston_11" />
<child link="fermeture5_B" />
<axis xyz="0 0 0"/>
</joint>

<joint name="to_rotule_free_attache2_moeur_hanchez" type="revolute">
<origin xyz="1.616762279610384212e-15 0.044041666666666673402 -0.053479166666666744234" rpy="1.570796326794896558 7.4941785995994790281e-30 1.570796326794896558" />
<parent link="hanche_2" />
<child link="piston_11" />
<axis xyz="0 0 1"/>
<limit effort="1" velocity="20" />
<joint_properties friction="0.0"/>
</joint>

<joint name="free_zhips" type="revolute">
<origin xyz="-0.012499999999999976408 -0.20499999999999998779 -0.0049999999999998934186" rpy="-7.8886090522101180541e-31 1.5429430116984919109e-15 3.141592653589793116" />
<parent link="hanche" />
<child link="hanche_2" />
<axis xyz="0 0 1"/>
<limit effort="1" velocity="20" />
<joint_properties friction="0.0"/>
</joint>

<link name="attache_hanche">
<visual>
<origin xyz="0.1384166666666665213 0.037750000000000005773 -1.0745833333333334458" rpy="0 -1.604175351655854949e-15 0" />
<geometry>
<mesh filename="package:///attache_hanche.stl"/>
</geometry>
<material name="attache_hanche_material">
<color rgba="0.64705882352941179736 0.64705882352941179736 0.64705882352941179736 1.0"/>
</material>
</visual>
<collision>
<origin xyz="0.1384166666666665213 0.037750000000000005773 -1.0745833333333334458" rpy="0 -1.604175351655854949e-15 0" />
<geometry>
<mesh filename="package:///attache_hanche.stl"/>
</geometry>
<material name="attache_hanche_material">
<color rgba="0.64705882352941179736 0.64705882352941179736 0.64705882352941179736 1.0"/>
</material>
</collision>
<inertial>
<origin xyz="0 -6.9388939039072283776e-18 -0.033958333333333312609" rpy="0 0 0"/>
<mass value="0.013302651224255402848" />
<inertia ixx="5.4096038561968625921e-06" ixy="0"  ixz="7.7276241791275040983e-21" iyy="5.4096038561968634391e-06" iyz="0" izz="5.9240966907079243215e-07" />
</inertial>
</link>

<link name="motteur_rotation_4">
<visual>
<origin xyz="0.037750000000000005773 1.0161041666666668082 -0.13841666666666649355" rpy="1.570796326794896558 1.5707963267948950037 0" />
<geometry>
<mesh filename="package:///motteur_rotation.stl"/>
</geometry>
<material name="motteur_rotation_material">
<color rgba="0.2313725490196078538 0.38039215686274507888 0.7058823529411765163 1.0"/>
</material>
</visual>
<collision>
<origin xyz="0.037750000000000005773 1.0161041666666668082 -0.13841666666666649355" rpy="1.570796326794896558 1.5707963267948950037 0" />
<geometry>
<mesh filename="package:///motteur_rotation.stl"/>
</geometry>
<material name="motteur_rotation_material">
<color rgba="0.2313725490196078538 0.38039215686274507888 0.7058823529411765163 1.0"/>
</material>
</collision>
<inertial>
<origin xyz="6.9388939039072283776e-18 0 -0.038600225225225201497" rpy="0 0 0"/>
<mass value="0.050662516966540720176" />
<inertia ixx="1.6868799164751242944e-05" ixy="0"  ixz="0" iyy="1.6868799164751242944e-05" iyz="-8.5293484665262147169e-21" izz="1.155183150425073109e-05" />
</inertial>
</link>

<link name="piston_12">
<visual>
<origin xyz="-0.10179556944408768571 0.15392457132099851558 -0.98149999999999992806" rpy="0 -0 0" />
<geometry>
<mesh filename="package:///piston.stl"/>
</geometry>
<material name="piston_material">
<color rgba="0.91764705882352937127 0.91764705882352937127 0.91764705882352937127 1.0"/>
</material>
</visual>
<collision>
<origin xyz="-0.10179556944408768571 0.15392457132099851558 -0.98149999999999992806" rpy="0 -0 0" />
<geometry>
<mesh filename="package:///piston.stl"/>
</geometry>
<material name="piston_material">
<color rgba="0.91764705882352937127 0.91764705882352937127 0.91764705882352937127 1.0"/>
</material>
</collision>
<inertial>
<origin xyz="0 0 -0.012499999999999844569" rpy="0 0 0"/>
<mass value="0.0048966814322412765756" />
<inertia ixx="3.6406794569277529096e-07" ixy="0"  ixz="0" iyy="3.6406794569277529096e-07" iyz="0" izz="2.1806490886041675402e-07" />
</inertial>
</link>

<link name="fermeture5_A">
<inertial>
<origin xyz="0 0 0" rpy="0 0 0" />
<mass value="1e-9" />
<inertia ixx="0" ixy="0" ixz="0" iyy="0" iyz="0" izz="0" />
</inertial>
</link>
<joint name="fermeture5_A_frame" type="fixed">
<origin xyz="-6.9388939039072283776e-18 0 -0.025000000000000077716" rpy="0 -0 0" />
<parent link="piston_12" />
<child link="fermeture5_A" />
<axis xyz="0 0 0"/>
</joint>

<joint name="mot_hanchez" type="prismatic">
<origin xyz="2.7755575615628913511e-17 -1.4571677198205179593e-16 -0.062916666666666648533" rpy="0 -0 -1.570796326794896558" />
<parent link="motteur_rotation_4" />
<child link="piston_12" />
<axis xyz="0 0 1"/>
<limit effort="1" velocity="20" />
<joint_properties friction="0.0"/>
</joint>

<joint name="to_rotule_free_attache_moeur_hanche_z" type="revolute">
<origin xyz="-1.3877787807814456755e-17 0 -0.058479166666666637653" rpy="1.570796326794896558 -0 1.570796326794896558" />
<parent link="attache_hanche" />
<child link="motteur_rotation_4" />
<axis xyz="0 0 1"/>
<limit effort="1" velocity="20" />
<joint_properties friction="0.0"/>
</joint>

<joint name="free_attache_moeur_hanche_2" type="revolute">
<origin xyz="0.11962499999999837152 -0.24904166666666668895 2.2204460492503130808e-16" rpy="0 -1.5429430116984873749e-15 0" />
<parent link="hanche" />
<child link="attache_hanche" />
<axis xyz="0 0 1"/>
<limit effort="1" velocity="20" />
<joint_properties friction="0.0"/>
</joint>


</robot>
