<robot name="onshape">
<link name="hanche_batis">
<visual>
<origin xyz="-0.018791666666666470564 -0.28679166666666666696 -1.0745833333333334458" rpy="0 -6.1232339957367660359e-17 3.141592653589793116" />
<geometry>
<mesh filename="package:///hanche_batis.stl"/>
</geometry>
<material name="hanche_batis_material">
<color rgba="0.61568627450980395466 0.81176470588235294379 0.92941176470588238168 1.0"/>
</material>
</visual>
<collision>
<origin xyz="-0.018791666666666470564 -0.28679166666666666696 -1.0745833333333334458" rpy="0 -6.1232339957367660359e-17 3.141592653589793116" />
<geometry>
<mesh filename="package:///hanche_batis.stl"/>
</geometry>
<material name="hanche_batis_material">
<color rgba="0.61568627450980395466 0.81176470588235294379 0.92941176470588238168 1.0"/>
</material>
</collision>
<inertial>
<origin xyz="0.0026400973615786950399 -0.12908406698772914578 0.024395572024549228018" rpy="0 0 0"/>
<mass value="1.1356034209800021095" />
<inertia ixx="0.0064522934693274349924" ixy="0.0003594558542207121842"  ixz="3.3623873327575187439e-05" iyy="0.0019918850512647429812" iyz="-6.8228058000940962108e-05" izz="0.0079598705100062706885" />
</inertial>
</link>

<link name="centre_hanche">
<inertial>
<origin xyz="0 0 0" rpy="0 0 0" />
<mass value="1e-9" />
<inertia ixx="0" ixy="0" ixz="0" iyy="0" iyz="0" izz="0" />
</inertial>
</link>
<joint name="centre_hanche_frame" type="fixed">
<origin xyz="0.0072868371002148442372 -0.28888192121052924666 -0.19749999999999995337" rpy="0 -1.5429430116984873749e-15 0" />
<parent link="hanche_batis" />
<child link="centre_hanche" />
<axis xyz="0 0 0"/>
</joint>

<link name="hanche">
<visual>
<origin xyz="0.0062916666666681334702 0.081791666666666679175 -1.0695833333333335524" rpy="0 -1.604175351655854949e-15 -4.3679400542503552248e-18" />
<geometry>
<mesh filename="package:///hanche.stl"/>
</geometry>
<material name="hanche_material">
<color rgba="0.97254901960784312376 0.52941176470588235947 0.0039215686274509803377 1.0"/>
</material>
</visual>
<collision>
<origin xyz="0.0062916666666681334702 0.081791666666666679175 -1.0695833333333335524" rpy="0 -1.604175351655854949e-15 -4.3679400542503552248e-18" />
<geometry>
<mesh filename="package:///hanche.stl"/>
</geometry>
<material name="hanche_material">
<color rgba="0.97254901960784312376 0.52941176470588235947 0.0039215686274509803377 1.0"/>
</material>
</collision>
<inertial>
<origin xyz="2.4297965946565303064e-08 0.0029964531584177889201 -0.096315760746443990215" rpy="0 0 0"/>
<mass value="0.14955339898895028683" />
<inertia ixx="0.00047587552365393277678" ixy="1.9440008194381670789e-10"  ixz="-1.1932288227636404533e-10" iyy="0.00043553104795692848235" iyz="-1.9195892455749433299e-05" izz="5.8849071132566822026e-05" />
</inertial>
</link>

<link name="cardan_foot">
<visual>
<origin xyz="2.7755575615628913511e-17 0.044041666666666673402 -7.4999999999998678835e-05" rpy="1.570796326794896558 1.570796326794896558 0" />
<geometry>
<mesh filename="package:///cardan_foot.stl"/>
</geometry>
<material name="cardan_foot_material">
<color rgba="0.64705882352941179736 0.64705882352941179736 0.64705882352941179736 1.0"/>
</material>
</visual>
<collision>
<origin xyz="2.7755575615628913511e-17 0.044041666666666673402 -7.4999999999998678835e-05" rpy="1.570796326794896558 1.570796326794896558 0" />
<geometry>
<mesh filename="package:///cardan_foot.stl"/>
</geometry>
<material name="cardan_foot_material">
<color rgba="0.64705882352941179736 0.64705882352941179736 0.64705882352941179736 1.0"/>
</material>
</collision>
<inertial>
<origin xyz="2.2944734364638547647e-08 0 -7.4977055265662594704e-05" rpy="0 0 0"/>
<mass value="0.0066552634961090364682" />
<inertia ixx="4.5170330905598590077e-07" ixy="2.5470220910056570482e-12"  ixz="1.1566606449762372431e-23" iyy="5.7905433802721882153e-07" iyz="-2.547022090984370476e-12" izz="4.5170330905598584783e-07" />
</inertial>
</link>

<link name="tarsus">
<visual>
<origin xyz="0.0062916666666667179358 -0.88083333333333335702 -0.081791666666666679175" rpy="-1.570796326794896558 -7.3872654913036496335e-18 7.4118976794832316656e-20" />
<geometry>
<mesh filename="package:///tarsus.stl"/>
</geometry>
<material name="tarsus_material">
<color rgba="0.91764705882352937127 0.91764705882352937127 0.91764705882352937127 1.0"/>
</material>
</visual>
<collision>
<origin xyz="0.0062916666666667179358 -0.88083333333333335702 -0.081791666666666679175" rpy="-1.570796326794896558 -7.3872654913036496335e-18 7.4118976794832316656e-20" />
<geometry>
<mesh filename="package:///tarsus.stl"/>
</geometry>
<material name="tarsus_material">
<color rgba="0.91764705882352937127 0.91764705882352937127 0.91764705882352937127 1.0"/>
</material>
</collision>
<inertial>
<origin xyz="0.053154689654094124107 -0.19698830172026582375 -0.078513550003536242139" rpy="0 0 0"/>
<mass value="2.1073238681812553885" />
<inertia ixx="0.048144671833562420471" ixy="0.015163240245921499882"  ixz="0.00017822324045008969382" iyy="0.0086472529576917360472" iyz="-0.0013624880248352309008" izz="0.053648367038970204423" />
</inertial>
</link>

<link name="tibias">
<visual>
<origin xyz="-0.16987499999999997047 0.39008333333333322646 5.5511151231257827021e-17" rpy="1.570796326794896558 -7.1655256553686505643e-20 2.0445922950745252352e-21" />
<geometry>
<mesh filename="package:///tibias.stl"/>
</geometry>
<material name="tibias_material">
<color rgba="0.2313725490196078538 0.38039215686274507888 0.7058823529411765163 1.0"/>
</material>
</visual>
<collision>
<origin xyz="-0.16987499999999997047 0.39008333333333322646 5.5511151231257827021e-17" rpy="1.570796326794896558 -7.1655256553686505643e-20 2.0445922950745252352e-21" />
<geometry>
<mesh filename="package:///tibias.stl"/>
</geometry>
<material name="tibias_material">
<color rgba="0.2313725490196078538 0.38039215686274507888 0.7058823529411765163 1.0"/>
</material>
</collision>
<inertial>
<origin xyz="-0.07658227102686443466 0.15621438233256315642 -1.1094304012078771792e-08" rpy="0 0 0"/>
<mass value="0.17811841417215046324" />
<inertia ixx="0.0019764054154096577162" ixy="0.00096016337172479828375"  ixz="-1.071858835946369185e-10" iyy="0.00049037133129023133" iyz="2.8756588598235829127e-10" izz="0.00244830523441177993" />
</inertial>
</link>

<link name="cardan_foot_2">
<visual>
<origin xyz="0 0.044041666666666534624 -7.5000000000000305138e-05" rpy="1.570796326794896558 1.570796326794896558 0" />
<geometry>
<mesh filename="package:///cardan_foot.stl"/>
</geometry>
<material name="cardan_foot_material">
<color rgba="0.64705882352941179736 0.64705882352941179736 0.64705882352941179736 1.0"/>
</material>
</visual>
<collision>
<origin xyz="0 0.044041666666666534624 -7.5000000000000305138e-05" rpy="1.570796326794896558 1.570796326794896558 0" />
<geometry>
<mesh filename="package:///cardan_foot.stl"/>
</geometry>
<material name="cardan_foot_material">
<color rgba="0.64705882352941179736 0.64705882352941179736 0.64705882352941179736 1.0"/>
</material>
</collision>
<inertial>
<origin xyz="2.2944734336881833831e-08 -1.4571677198205179593e-16 -7.4977055265664207455e-05" rpy="0 0 0"/>
<mass value="0.0066552634961090364682" />
<inertia ixx="4.5170330905598611253e-07" ixy="2.5470220910056723963e-12"  ixz="1.1935817592752220331e-23" iyy="5.7905433802721903329e-07" iyz="-2.5470220909843724955e-12" izz="4.5170330905598595371e-07" />
</inertial>
</link>

<link name="foot">
<visual>
<origin xyz="-1.1102230246251565404e-16 0.044041666666666645646 0" rpy="1.570796326794896558 -1.3017041712644265466e-17 -1.1426384530194127406e-16" />
<geometry>
<mesh filename="package:///foot.stl"/>
</geometry>
<material name="foot_material">
<color rgba="0.61568627450980395466 0.81176470588235294379 0.92941176470588238168 1.0"/>
</material>
</visual>
<collision>
<origin xyz="-1.1102230246251565404e-16 0.044041666666666645646 0" rpy="1.570796326794896558 -1.3017041712644265466e-17 -1.1426384530194127406e-16" />
<geometry>
<mesh filename="package:///foot.stl"/>
</geometry>
<material name="foot_material">
<color rgba="0.61568627450980395466 0.81176470588235294379 0.92941176470588238168 1.0"/>
</material>
</collision>
<inertial>
<origin xyz="-0.017858803267170236806 0.026154624544930907271 -6.5844145888967323357e-10" rpy="0 0 0"/>
<mass value="0.41304051708113420638" />
<inertia ixx="0.0004485171362783168668" ixy="-0.00012946406800199783751"  ixz="-3.0653895068095863889e-10" iyy="0.0014015188952783321896" iyz="-4.7489172979706049527e-10" izz="0.0010932169994883811012" />
</inertial>
</link>

<link name="bout_pied">
<inertial>
<origin xyz="0 0 0" rpy="0 0 0" />
<mass value="1e-9" />
<inertia ixx="0" ixy="0" ixz="0" iyy="0" iyz="0" izz="0" />
</inertial>
</link>
<joint name="bout_pied_frame" type="fixed">
<origin xyz="0.014111017407571480042 0.044041666666666756669 1.5991513668822676664e-09" rpy="-1.570796326794896558 1.3017041712644265466e-17 3.141592653589793116" />
<parent link="foot" />
<child link="bout_pied" />
<axis xyz="0 0 0"/>
</joint>

<link name="rode_tarsus">
<visual>
<origin xyz="-0.023755298455264806101 -1.0790665033514630355 -0.053479166666666855257" rpy="-1.570796326794896558 -1.5707963267948950037 0" />
<geometry>
<mesh filename="package:///rode_tarsus.stl"/>
</geometry>
<material name="rode_tarsus_material">
<color rgba="0.49803921568627451677 0.49803921568627451677 0.49803921568627451677 1.0"/>
</material>
</visual>
<collision>
<origin xyz="-0.023755298455264806101 -1.0790665033514630355 -0.053479166666666855257" rpy="-1.570796326794896558 -1.5707963267948950037 0" />
<geometry>
<mesh filename="package:///rode_tarsus.stl"/>
</geometry>
<material name="rode_tarsus_material">
<color rgba="0.49803921568627451677 0.49803921568627451677 0.49803921568627451677 1.0"/>
</material>
</collision>
<inertial>
<origin xyz="1.2393086505814740328e-17 4.4408920985006261617e-16 -0.095947916666666716035" rpy="0 0 0"/>
<mass value="0.037586110560311969397" />
<inertia ixx="0.00011617619354049128484" ixy="3.7937260113851488745e-22"  ixz="2.0092383840279728685e-21" iyy="0.00011617619354049133905" iyz="-1.8335950212504358843e-19" izz="1.6738298962610809591e-06" />
</inertial>
</link>

<link name="fermeture0_A">
<inertial>
<origin xyz="0 0 0" rpy="0 0 0" />
<mass value="1e-9" />
<inertia ixx="0" ixy="0" ixz="0" iyy="0" iyz="0" izz="0" />
</inertial>
</link>
<joint name="fermeture0_A_frame" type="fixed">
<origin xyz="0 2.7755575615628913511e-16 -0.19189583333333326554" rpy="3.141592653589793116 -1.6721638379069471494e-17 3.075854684320635955e-18" />
<parent link="rode_tarsus" />
<child link="fermeture0_A" />
<axis xyz="0 0 0"/>
</joint>

<joint name="to_rotule_free_foot1" type="revolute">
<origin xyz="-0.0629166666666667318 -0.012583333333333390769 0.044041666666666368091" rpy="1.570796326794896558 0.081892649261537886485 -3.141592653589793116" />
<parent link="foot" />
<child link="rode_tarsus" />
<axis xyz="0 0 1"/>
<limit effort="1" velocity="20" />
<joint_properties friction="0.0"/>
</joint>

<link name="rode_tarsus_2">
<visual>
<origin xyz="-0.023755298455264806101 -1.0790665033514630355 -0.053479166666666744234" rpy="-1.570796326794896558 -1.5707963267948950037 0" />
<geometry>
<mesh filename="package:///rode_tarsus.stl"/>
</geometry>
<material name="rode_tarsus_material">
<color rgba="0.49803921568627451677 0.49803921568627451677 0.49803921568627451677 1.0"/>
</material>
</visual>
<collision>
<origin xyz="-0.023755298455264806101 -1.0790665033514630355 -0.053479166666666744234" rpy="-1.570796326794896558 -1.5707963267948950037 0" />
<geometry>
<mesh filename="package:///rode_tarsus.stl"/>
</geometry>
<material name="rode_tarsus_material">
<color rgba="0.49803921568627451677 0.49803921568627451677 0.49803921568627451677 1.0"/>
</material>
</collision>
<inertial>
<origin xyz="1.2393086505814740328e-17 4.4408920985006261617e-16 -0.095947916666666605012" rpy="0 0 0"/>
<mass value="0.037586110560311969397" />
<inertia ixx="0.00011617619354049128484" ixy="3.7937260113851488745e-22"  ixz="2.0092383840279728685e-21" iyy="0.00011617619354049133905" iyz="-1.8335950212504358843e-19" izz="1.6738298962610809591e-06" />
</inertial>
</link>

<link name="fermeture9_B">
<inertial>
<origin xyz="0 0 0" rpy="0 0 0" />
<mass value="1e-9" />
<inertia ixx="0" ixy="0" ixz="0" iyy="0" iyz="0" izz="0" />
</inertial>
</link>
<joint name="fermeture9_B_frame" type="fixed">
<origin xyz="0 1.1102230246251565404e-16 -0.19189583333333337656" rpy="3.141592653589793116 -1.6721638379069471494e-17 3.075854684320635955e-18" />
<parent link="rode_tarsus_2" />
<child link="fermeture9_B" />
<axis xyz="0 0 0"/>
</joint>

<joint name="to_rotule_free_goot2" type="revolute">
<origin xyz="-0.062916666666666620777 -0.012583333333333168724 -0.044041666666666950958" rpy="1.570796326794896558 0.081892649261537886485 -3.141592653589793116" />
<parent link="foot" />
<child link="rode_tarsus_2" />
<axis xyz="0 0 1"/>
<limit effort="1" velocity="20" />
<joint_properties friction="0.0"/>
</joint>

<joint name="free_cheville_cardanx" type="revolute">
<origin xyz="7.4999999999825206487e-05 -2.2204460492503130808e-16 -7.5000000000002365122e-05" rpy="-1.570796326794896558 -1.0283708790559382695 1.570796326794896558" />
<parent link="cardan_foot_2" />
<child link="foot" />
<axis xyz="0 0 1"/>
<limit effort="1" velocity="20" />
<joint_properties friction="0.0"/>
</joint>

<joint name="free_cheville_cardany" type="revolute">
<origin xyz="-0.16980000000000278204 0.34604166666666646979 -1.1102230246251565404e-16" rpy="-1.5707963267942939289 1.5706585553043288517 -1.5707963267950366681" />
<parent link="tibias" />
<child link="cardan_foot_2" />
<axis xyz="0 0 1"/>
<limit effort="1" velocity="20" />
<joint_properties friction="0.0"/>
</joint>

<link name="piston">
<visual>
<origin xyz="-0.10179556944408769958 -0.15392457132099857109 0.9565000000000001279" rpy="3.141592653589793116 -1.1119874650498309646e-21 -1.0674500452153389231e-17" />
<geometry>
<mesh filename="package:///piston.stl"/>
</geometry>
<material name="piston_material">
<color rgba="0.91764705882352937127 0.91764705882352937127 0.91764705882352937127 1.0"/>
</material>
</visual>
<collision>
<origin xyz="-0.10179556944408769958 -0.15392457132099857109 0.9565000000000001279" rpy="3.141592653589793116 -1.1119874650498309646e-21 -1.0674500452153389231e-17" />
<geometry>
<mesh filename="package:///piston.stl"/>
</geometry>
<material name="piston_material">
<color rgba="0.91764705882352937127 0.91764705882352937127 0.91764705882352937127 1.0"/>
</material>
</collision>
<inertial>
<origin xyz="-1.3877787807814456755e-17 -8.4351440639452663405e-17 -0.01250000000000017937" rpy="0 0 0"/>
<mass value="0.0048966814322412765756" />
<inertia ixx="3.6406794569277529096e-07" ixy="-4.6176435283013680004e-24"  ixz="1.9048982213782129404e-29" iyy="3.6406794569277518508e-07" iyz="-1.7874715916180690407e-27" izz="2.180649088604168599e-07" />
</inertial>
</link>

<link name="fermeture6_B">
<inertial>
<origin xyz="0 0 0" rpy="0 0 0" />
<mass value="1e-9" />
<inertia ixx="0" ixy="0" ixz="0" iyy="0" iyz="0" izz="0" />
</inertial>
</link>
<joint name="fermeture6_B_frame" type="fixed">
<origin xyz="-3.6082248300317587564e-16 1.6653345369377348106e-16 -0.025000000000000133227" rpy="-3.141592653589793116 1.1119874650498309646e-21 3.141592653589793116" />
<parent link="piston" />
<child link="fermeture6_B" />
<axis xyz="0 0 0"/>
</joint>

<joint name="to_rotule_free_attache_genoux" type="revolute">
<origin xyz="-0.044041666666667284025 0.050333333333332563875 5.5511151231257827021e-17" rpy="-1.57079632679489678 0.026729912583035628226 -8.6038674056888522762e-19" />
<parent link="tibias" />
<child link="piston" />
<axis xyz="0 0 1"/>
<limit effort="1" velocity="20" />
<joint_properties friction="0.0"/>
</joint>

<joint name="free_genoux" type="revolute">
<origin xyz="0.17616666666662503249 -0.49075000000001500755 -0.081791666666666845709" rpy="3.141592653589793116 -1.2407226412650767997e-16 -0.00058875972722544967809" />
<parent link="tarsus" />
<child link="tibias" />
<axis xyz="0 0 1"/>
<limit effort="1" velocity="20" />
<joint_properties friction="0.0"/>
</joint>

<link name="renvois_cheville">
<visual>
<origin xyz="-0.13212500000000007572 0.40895833333333331261 0.037750000000000005773" rpy="1.570796326794896558 -9.9286728620811613539e-19 -1.3788585247188219925e-17" />
<geometry>
<mesh filename="package:///renvois_cheville.stl"/>
</geometry>
<material name="renvois_cheville_material">
<color rgba="0.76862745098039220171 0.88627450980392152857 0.95294117647058818044 1.0"/>
</material>
</visual>
<collision>
<origin xyz="-0.13212500000000007572 0.40895833333333331261 0.037750000000000005773" rpy="1.570796326794896558 -9.9286728620811613539e-19 -1.3788585247188219925e-17" />
<geometry>
<mesh filename="package:///renvois_cheville.stl"/>
</geometry>
<material name="renvois_cheville_material">
<color rgba="0.76862745098039220171 0.88627450980392152857 0.95294117647058818044 1.0"/>
</material>
</collision>
<inertial>
<origin xyz="-0.038548646780021234015 0.021351922520206623179 -0.016601297994840141792" rpy="0 0 0"/>
<mass value="0.075465954638112592301" />
<inertia ixx="5.4311390351603887089e-05" ixy="-2.7554927892777837323e-06"  ixz="-2.7094024723524435493e-06" iyy="4.2320534518436017841e-05" iyz="1.3329322471998967256e-05" izz="6.6609236448868702676e-05" />
</inertial>
</link>

<link name="rode_tarsus_3">
<visual>
<origin xyz="-0.023755298455264833857 -1.0790665033514634796 -0.053479166666666744234" rpy="-1.570796326794896558 -1.5707963267948950037 0" />
<geometry>
<mesh filename="package:///rode_tarsus.stl"/>
</geometry>
<material name="rode_tarsus_material">
<color rgba="0.49803921568627451677 0.49803921568627451677 0.49803921568627451677 1.0"/>
</material>
</visual>
<collision>
<origin xyz="-0.023755298455264833857 -1.0790665033514634796 -0.053479166666666744234" rpy="-1.570796326794896558 -1.5707963267948950037 0" />
<geometry>
<mesh filename="package:///rode_tarsus.stl"/>
</geometry>
<material name="rode_tarsus_material">
<color rgba="0.49803921568627451677 0.49803921568627451677 0.49803921568627451677 1.0"/>
</material>
</collision>
<inertial>
<origin xyz="-1.3536460889411821593e-17 0 -0.095947916666666605012" rpy="0 0 0"/>
<mass value="0.037586110560311969397" />
<inertia ixx="0.00011617619354049128484" ixy="-9.9556354753088082812e-24"  ixz="-1.7530116741746680648e-21" iyy="0.00011617619354049133905" iyz="-1.8383497031252969797e-19" izz="1.6738298962610818061e-06" />
</inertial>
</link>

<link name="fermeture9_A">
<inertial>
<origin xyz="0 0 0" rpy="0 0 0" />
<mass value="1e-9" />
<inertia ixx="0" ixy="0" ixz="0" iyy="0" iyz="0" izz="0" />
</inertial>
</link>
<joint name="fermeture9_A_frame" type="fixed">
<origin xyz="0 -3.3306690738754696213e-16 -0.19189583333333326554" rpy="6.9071019648092707407e-18 2.6624167757425087404e-17 -3.141592653589793116" />
<parent link="rode_tarsus_3" />
<child link="fermeture9_A" />
<axis xyz="0 0 0"/>
</joint>

<joint name="to_rotule_free_triangle2" type="revolute">
<origin xyz="-0.068058330216350965136 -0.012564119186792344074 -0.012583333333333057702" rpy="1.570796326794896558 -0.095385008856607569894 -2.6902869908268245684e-16" />
<parent link="renvois_cheville" />
<child link="rode_tarsus_3" />
<axis xyz="0 0 1"/>
<limit effort="1" velocity="20" />
<joint_properties friction="0.0"/>
</joint>

<link name="rode_foot">
<visual>
<origin xyz="-0.035362814756395938298 -1.1126229936003482202 -0.069208333333333427184" rpy="-1.570796326794896558 -1.5707963267948950037 0" />
<geometry>
<mesh filename="package:///rode_foot.stl"/>
</geometry>
<material name="rode_foot_material">
<color rgba="0.97254901960784312376 0.52941176470588235947 0.0039215686274509803377 1.0"/>
</material>
</visual>
<collision>
<origin xyz="-0.035362814756395938298 -1.1126229936003482202 -0.069208333333333427184" rpy="-1.570796326794896558 -1.5707963267948950037 0" />
<geometry>
<mesh filename="package:///rode_foot.stl"/>
</geometry>
<material name="rode_foot_material">
<color rgba="0.97254901960784312376 0.52941176470588235947 0.0039215686274509803377 1.0"/>
</material>
</collision>
<inertial>
<origin xyz="-6.3310733750468241507e-17 2.2204460492503130808e-16 -0.10381249999999994649" rpy="0 0 0"/>
<mass value="0.040666939294763761181" />
<inertia ixx="0.00014699519269296084214" ixy="-1.1966883707160749277e-22"  ixz="-9.1235177427656112765e-23" iyy="0.00014699519269296089635" iyz="-2.3392486866634696895e-19" izz="1.8110290680857596429e-06" />
</inertial>
</link>

<link name="fermeture7_A">
<inertial>
<origin xyz="0 0 0" rpy="0 0 0" />
<mass value="1e-9" />
<inertia ixx="0" ixy="0" ixz="0" iyy="0" iyz="0" izz="0" />
</inertial>
</link>
<joint name="fermeture7_A_frame" type="fixed">
<origin xyz="-2.7755575615628913511e-17 -3.0531133177191804862e-16 -0.20762500000000022604" rpy="3.1415926535897846783 2.3079233611404340129e-17 -1.570796326794896558" />
<parent link="rode_foot" />
<child link="fermeture7_A" />
<axis xyz="0 0 0"/>
</joint>

<joint name="to_rotule_free_trianle3" type="revolute">
<origin xyz="-0.041015624251385912613 0.047709805194671939255 -0.047187500000000021094" rpy="1.5707963267948961139 -1.4687456221646373322 3.141592653589658557" />
<parent link="renvois_cheville" />
<child link="rode_foot" />
<axis xyz="0 0 1"/>
<limit effort="1" velocity="20" />
<joint_properties friction="0.0"/>
</joint>

<joint name="free_triangle1_tibias" type="revolute">
<origin xyz="0.13841666666666663232 -0.47187499999999993339 -0.044041666666666784424" rpy="-3.141592653589793116 -1.3748255421293126449e-16 -0.066056290258646024882" />
<parent link="tarsus" />
<child link="renvois_cheville" />
<axis xyz="0 0 1"/>
<limit effort="1" velocity="20" />
<joint_properties friction="0.0"/>
</joint>

<link name="renvois_cheville_2">
<visual>
<origin xyz="-0.13212500000000010347 -0.40895833333333331261 0.037749999999999950262" rpy="-1.570796326794896558 9.3588139578535445373e-18 8.7294718771438682749e-18" />
<geometry>
<mesh filename="package:///renvois_cheville_2.stl"/>
</geometry>
<material name="renvois_cheville_2_material">
<color rgba="0.76862745098039220171 0.88627450980392152857 0.95294117647058818044 1.0"/>
</material>
</visual>
<collision>
<origin xyz="-0.13212500000000010347 -0.40895833333333331261 0.037749999999999950262" rpy="-1.570796326794896558 9.3588139578535445373e-18 8.7294718771438682749e-18" />
<geometry>
<mesh filename="package:///renvois_cheville_2.stl"/>
</geometry>
<material name="renvois_cheville_2_material">
<color rgba="0.76862745098039220171 0.88627450980392152857 0.95294117647058818044 1.0"/>
</material>
</collision>
<inertial>
<origin xyz="-0.038548646377067258273 -0.021351922527764521931 -0.016601297938671079335" rpy="0 0 0"/>
<mass value="0.075465953879580452424" />
<inertia ixx="5.43113903578738147e-05" ixy="2.75549260595693747e-06"  ixz="-2.7094023512960066815e-06" iyy="4.2320533739322583645e-05" iyz="-1.3329322467171953495e-05" izz="6.6609235780079392177e-05" />
</inertial>
</link>

<link name="rode_tarsus_4">
<visual>
<origin xyz="-0.023755298455264806101 -1.0790665033514632576 -0.053479166666666855257" rpy="-1.570796326794896558 -1.5707963267948950037 0" />
<geometry>
<mesh filename="package:///rode_tarsus.stl"/>
</geometry>
<material name="rode_tarsus_material">
<color rgba="0.49803921568627451677 0.49803921568627451677 0.49803921568627451677 1.0"/>
</material>
</visual>
<collision>
<origin xyz="-0.023755298455264806101 -1.0790665033514632576 -0.053479166666666855257" rpy="-1.570796326794896558 -1.5707963267948950037 0" />
<geometry>
<mesh filename="package:///rode_tarsus.stl"/>
</geometry>
<material name="rode_tarsus_material">
<color rgba="0.49803921568627451677 0.49803921568627451677 0.49803921568627451677 1.0"/>
</material>
</collision>
<inertial>
<origin xyz="4.9226911401141172525e-18 0 -0.095947916666666716035" rpy="0 0 0"/>
<mass value="0.037586110560311969397" />
<inertia ixx="0.00011617619354049128484" ixy="7.3716402555243034541e-22"  ixz="-1.3171507273730882692e-21" iyy="0.00011617619354049128484" iyz="-1.8371433480750122068e-19" izz="1.6738298962610805355e-06" />
</inertial>
</link>

<link name="fermeture0_B">
<inertial>
<origin xyz="0 0 0" rpy="0 0 0" />
<mass value="1e-9" />
<inertia ixx="0" ixy="0" ixz="0" iyy="0" iyz="0" izz="0" />
</inertial>
</link>
<joint name="fermeture0_B_frame" type="fixed">
<origin xyz="5.5511151231257827021e-17 -1.1102230246251565404e-16 -0.19189583333333348758" rpy="2.5464045949721037905e-16 -3.8499906812161220182e-16 -3.141592653589793116" />
<parent link="rode_tarsus_4" />
<child link="fermeture0_B" />
<axis xyz="0 0 0"/>
</joint>

<joint name="to_rotule_free_triangle1" type="revolute">
<origin xyz="-0.068058330216350965136 0.012564119186792344074 -0.012583333333333557302" rpy="-1.57079632679489678 0.16864244180508916604 3.6078898931567104179e-17" />
<parent link="renvois_cheville_2" />
<child link="rode_tarsus_4" />
<axis xyz="0 0 1"/>
<limit effort="1" velocity="20" />
<joint_properties friction="0.0"/>
</joint>

<link name="rode_foot_2">
<visual>
<origin xyz="-0.035362814756395910543 -1.1126229936003482202 -0.069208333333333427184" rpy="-1.570796326794896558 -1.5707963267948950037 0" />
<geometry>
<mesh filename="package:///rode_foot.stl"/>
</geometry>
<material name="rode_foot_material">
<color rgba="0.97254901960784312376 0.52941176470588235947 0.0039215686274509803377 1.0"/>
</material>
</visual>
<collision>
<origin xyz="-0.035362814756395910543 -1.1126229936003482202 -0.069208333333333427184" rpy="-1.570796326794896558 -1.5707963267948950037 0" />
<geometry>
<mesh filename="package:///rode_foot.stl"/>
</geometry>
<material name="rode_foot_material">
<color rgba="0.97254901960784312376 0.52941176470588235947 0.0039215686274509803377 1.0"/>
</material>
</collision>
<inertial>
<origin xyz="-2.6872125621028866986e-17 2.2204460492503130808e-16 -0.10381249999999993261" rpy="0 0 0"/>
<mass value="0.040666939294763761181" />
<inertia ixx="0.00014699519269296089635" ixy="4.3820881339940380194e-23"  ixz="-1.0527905424799349357e-21" iyy="0.00014699519269296089635" iyz="-2.3309584314642664504e-19" izz="1.8110290680857596429e-06" />
</inertial>
</link>

<link name="fermeture8_B">
<inertial>
<origin xyz="0 0 0" rpy="0 0 0" />
<mass value="1e-9" />
<inertia ixx="0" ixy="0" ixz="0" iyy="0" iyz="0" izz="0" />
</inertial>
</link>
<joint name="fermeture8_B_frame" type="fixed">
<origin xyz="-2.7755575615628913511e-17 1.1102230246251565404e-16 -0.20762500000000005951" rpy="3.141592653589793116 4.8299363385392145085e-17 3.5495078826400279975e-19" />
<parent link="rode_foot_2" />
<child link="fermeture8_B" />
<axis xyz="0 0 0"/>
</joint>

<joint name="to_rotule_free_triangle4" type="revolute">
<origin xyz="-0.041015624251386273436 -0.047709805194671606188 -0.047187499999999826805" rpy="-1.57079632679489678 -0.095087883447032894857 3.141592653589793116" />
<parent link="renvois_cheville_2" />
<child link="rode_foot_2" />
<axis xyz="0 0 1"/>
<limit effort="1" velocity="20" />
<joint_properties friction="0.0"/>
</joint>

<joint name="free_triangle2_tibias" type="revolute">
<origin xyz="0.13841666666666668783 -0.47187499999999993339 -0.11954166666666668495" rpy="-1.8461492555022878416e-18 -1.0252669703201268269e-16 -0.10263776941217567229" />
<parent link="tarsus" />
<child link="renvois_cheville_2" />
<axis xyz="0 0 1"/>
<limit effort="1" velocity="20" />
<joint_properties friction="0.0"/>
</joint>

<link name="renvois_hanche_2">
<visual>
<origin xyz="-0.066062500000000079492 -0.82735416666666672381 0.053479166666666633212" rpy="-1.570796326794896558 1.1435020750073987963e-17 -2.2263614003892139581e-17" />
<geometry>
<mesh filename="package:///renvois_hanche_2.stl"/>
</geometry>
<material name="renvois_hanche_2_material">
<color rgba="0.76862745098039220171 0.88627450980392152857 0.95294117647058818044 1.0"/>
</material>
</visual>
<collision>
<origin xyz="-0.066062500000000079492 -0.82735416666666672381 0.053479166666666633212" rpy="-1.570796326794896558 1.1435020750073987963e-17 -2.2263614003892139581e-17" />
<geometry>
<mesh filename="package:///renvois_hanche_2.stl"/>
</geometry>
<material name="renvois_hanche_2_material">
<color rgba="0.76862745098039220171 0.88627450980392152857 0.95294117647058818044 1.0"/>
</material>
</collision>
<inertial>
<origin xyz="-0.071838889332594968451 -0.028325668402720997202 -0.0062916666666667214053" rpy="0 0 0"/>
<mass value="0.052048361392958070182" />
<inertia ixx="1.9958534542913009766e-05" ixy="-2.9941729812280446806e-05"  ixz="2.5464819392151798652e-21" iyy="8.5925596188234551454e-05" iyz="5.6928278185528447161e-22" izz="0.00010451057206434108881" />
</inertial>
</link>

<link name="piston_2">
<visual>
<origin xyz="-0.1017955694440876302 -0.15392457132099851558 0.95649999999999990585" rpy="-3.141592653589793116 -1.300145704823427982e-17 -6.8807492732440010624e-19" />
<geometry>
<mesh filename="package:///piston.stl"/>
</geometry>
<material name="piston_material">
<color rgba="0.91764705882352937127 0.91764705882352937127 0.91764705882352937127 1.0"/>
</material>
</visual>
<collision>
<origin xyz="-0.1017955694440876302 -0.15392457132099851558 0.95649999999999990585" rpy="-3.141592653589793116 -1.300145704823427982e-17 -6.8807492732440010624e-19" />
<geometry>
<mesh filename="package:///piston.stl"/>
</geometry>
<material name="piston_material">
<color rgba="0.91764705882352937127 0.91764705882352937127 0.91764705882352937127 1.0"/>
</material>
</collision>
<inertial>
<origin xyz="5.5511151231257827021e-17 2.4127543752899946961e-18 -0.012500000000000064879" rpy="0 0 0"/>
<mass value="0.0048966814322412765756" />
<inertia ixx="3.6406794569277518508e-07" ixy="1.6033858032321509706e-24"  ixz="1.8565463305992366644e-24" iyy="3.6406794569277529096e-07" iyz="8.9685960415166777026e-25" izz="2.1806490886041670108e-07" />
</inertial>
</link>

<link name="fermeture1_B">
<inertial>
<origin xyz="0 0 0" rpy="0 0 0" />
<mass value="1e-9" />
<inertia ixx="0" ixy="0" ixz="0" iyy="0" iyz="0" izz="0" />
</inertial>
</link>
<joint name="fermeture1_B_frame" type="fixed">
<origin xyz="-8.3266726846886740532e-17 -5.5511151231257827021e-17 -0.025000000000000244249" rpy="-3.141592653589793116 -8.7685925630935976107e-17 2.9906032515748721767e-17" />
<parent link="piston_2" />
<child link="fermeture1_B" />
<axis xyz="0 0 0"/>
</joint>

<joint name="to_rotule_free_attache_hanche1" type="revolute">
<origin xyz="-0.13212499999999993694 -0.037750000000000172307 5.5511151231257827021e-17" rpy="-1.57079632679489678 -0.094042986969348249526 -3.1415926535897926719" />
<parent link="renvois_hanche_2" />
<child link="piston_2" />
<axis xyz="0 0 1"/>
<limit effort="1" velocity="20" />
<joint_properties friction="0.0"/>
</joint>

<link name="rode_foot_3">
<visual>
<origin xyz="-0.035362814756395868909 -1.1126229936003482202 -0.069208333333333427184" rpy="-1.570796326794896558 -1.5707963267948950037 0" />
<geometry>
<mesh filename="package:///rode_foot.stl"/>
</geometry>
<material name="rode_foot_material">
<color rgba="0.97254901960784312376 0.52941176470588235947 0.0039215686274509803377 1.0"/>
</material>
</visual>
<collision>
<origin xyz="-0.035362814756395868909 -1.1126229936003482202 -0.069208333333333427184" rpy="-1.570796326794896558 -1.5707963267948950037 0" />
<geometry>
<mesh filename="package:///rode_foot.stl"/>
</geometry>
<material name="rode_foot_material">
<color rgba="0.97254901960784312376 0.52941176470588235947 0.0039215686274509803377 1.0"/>
</material>
</collision>
<inertial>
<origin xyz="3.2774243662233649004e-18 2.2204460492503130808e-16 -0.10381249999999993261" rpy="0 0 0"/>
<mass value="0.040666939294763761181" />
<inertia ixx="0.00014699519269296084214" ixy="1.3581297886215345032e-23"  ixz="-1.4263208476909878255e-21" iyy="0.00014699519269296089635" iyz="-2.3264061102882883814e-19" izz="1.8110290680857592194e-06" />
</inertial>
</link>

<link name="fermeture8_A">
<inertial>
<origin xyz="0 0 0" rpy="0 0 0" />
<mass value="1e-9" />
<inertia ixx="0" ixy="0" ixz="0" iyy="0" iyz="0" izz="0" />
</inertial>
</link>
<joint name="fermeture8_A_frame" type="fixed">
<origin xyz="-1.3877787807814456755e-17 -4.4408920985006261617e-16 -0.20762499999999994849" rpy="-2.9697957125138915857e-16 -4.8836916697961571375e-16 3.1415926535897926719" />
<parent link="rode_foot_3" />
<child link="fermeture8_A" />
<axis xyz="0 0 0"/>
</joint>

<joint name="to_rotule_free_renvois_hanche3" type="revolute">
<origin xyz="-0.10695833333333404358 -0.062916666666667009356 -1.6653345369377348106e-16" rpy="-1.57079632679489678 0.09404298696934784707 -4.8159767687053810446e-16" />
<parent link="renvois_hanche_2" />
<child link="rode_foot_3" />
<axis xyz="0 0 1"/>
<limit effort="1" velocity="20" />
<joint_properties friction="0.0"/>
</joint>

<joint name="free_renvois_hanche1" type="revolute">
<origin xyz="0.072354166666666039354 -0.053479166666666105856 -0.13527083333333353443" rpy="-8.54568753867082763e-17 -1.8407509512760167408e-16 0.43838119428272348532" />
<parent link="tarsus" />
<child link="renvois_hanche_2" />
<axis xyz="0 0 1"/>
<limit effort="1" velocity="20" />
<joint_properties friction="0.0"/>
</joint>

<link name="renvois_hanche">
<visual>
<origin xyz="-0.066062499999999982347 0.82735416666666672381 0.053479166666666633212" rpy="1.570796326794896558 -7.0538260059813342369e-18 -5.787672587358763684e-17" />
<geometry>
<mesh filename="package:///renvois_hanche.stl"/>
</geometry>
<material name="renvois_hanche_material">
<color rgba="0.76862745098039220171 0.88627450980392152857 0.95294117647058818044 1.0"/>
</material>
</visual>
<collision>
<origin xyz="-0.066062499999999982347 0.82735416666666672381 0.053479166666666633212" rpy="1.570796326794896558 -7.0538260059813342369e-18 -5.787672587358763684e-17" />
<geometry>
<mesh filename="package:///renvois_hanche.stl"/>
</geometry>
<material name="renvois_hanche_material">
<color rgba="0.76862745098039220171 0.88627450980392152857 0.95294117647058818044 1.0"/>
</material>
</collision>
<inertial>
<origin xyz="-0.07183888933259491294 0.028325668402720997202 -0.006291666666666701456" rpy="0 0 0"/>
<mass value="0.052048361392958070182" />
<inertia ixx="1.9958534542913006378e-05" ixy="2.9941729812280450194e-05"  ixz="1.5622680463169285061e-21" iyy="8.5925596188234551454e-05" iyz="-7.9916173551881327648e-23" izz="0.0001045105720643410075" />
</inertial>
</link>

<link name="piston_3">
<visual>
<origin xyz="-0.10179556944408768571 -0.15392457132099851558 0.95649999999999990585" rpy="-3.141592653589793116 3.4919353965909875319e-18 1.7138658751784798623e-18" />
<geometry>
<mesh filename="package:///piston.stl"/>
</geometry>
<material name="piston_material">
<color rgba="0.91764705882352937127 0.91764705882352937127 0.91764705882352937127 1.0"/>
</material>
</visual>
<collision>
<origin xyz="-0.10179556944408768571 -0.15392457132099851558 0.95649999999999990585" rpy="-3.141592653589793116 3.4919353965909875319e-18 1.7138658751784798623e-18" />
<geometry>
<mesh filename="package:///piston.stl"/>
</geometry>
<material name="piston_material">
<color rgba="0.91764705882352937127 0.91764705882352937127 0.91764705882352937127 1.0"/>
</material>
</collision>
<inertial>
<origin xyz="-2.7755575615628913511e-17 2.1987380621046331817e-17 -0.01250000000000017937" rpy="0 0 0"/>
<mass value="0.0048966814322412765756" />
<inertia ixx="3.6406794569277529096e-07" ixy="1.9062874665857557973e-24"  ixz="3.5197528394747289909e-24" iyy="3.6406794569277550271e-07" iyz="3.2473203890273284116e-24" izz="2.1806490886041675402e-07" />
</inertial>
</link>

<link name="fermeture2_B">
<inertial>
<origin xyz="0 0 0" rpy="0 0 0" />
<mass value="1e-9" />
<inertia ixx="0" ixy="0" ixz="0" iyy="0" iyz="0" izz="0" />
</inertial>
</link>
<joint name="fermeture2_B_frame" type="fixed">
<origin xyz="1.1102230246251565404e-16 2.7755575615628913511e-17 -0.025000000000000133227" rpy="-3.141592653589793116 3.1456406373773374106e-16 -5.3319186701923333256e-17" />
<parent link="piston_3" />
<child link="fermeture2_B" />
<axis xyz="0 0 0"/>
</joint>

<joint name="to_rotule_free_attache_hanche2" type="revolute">
<origin xyz="-0.13212499999999971489 0.037749999999999950262 -2.7755575615628913511e-17" rpy="1.570796326794896558 0.092185476461817641991 3.141592653589793116" />
<parent link="renvois_hanche" />
<child link="piston_3" />
<axis xyz="0 0 1"/>
<limit effort="1" velocity="20" />
<joint_properties friction="0.0"/>
</joint>

<link name="rode_foot_4">
<visual>
<origin xyz="-0.035362814756395868909 -1.1126229936003479981 -0.069208333333333482695" rpy="-1.570796326794896558 -1.5707963267948950037 0" />
<geometry>
<mesh filename="package:///rode_foot.stl"/>
</geometry>
<material name="rode_foot_material">
<color rgba="0.97254901960784312376 0.52941176470588235947 0.0039215686274509803377 1.0"/>
</material>
</visual>
<collision>
<origin xyz="-0.035362814756395868909 -1.1126229936003479981 -0.069208333333333482695" rpy="-1.570796326794896558 -1.5707963267948950037 0" />
<geometry>
<mesh filename="package:///rode_foot.stl"/>
</geometry>
<material name="rode_foot_material">
<color rgba="0.97254901960784312376 0.52941176470588235947 0.0039215686274509803377 1.0"/>
</material>
</collision>
<inertial>
<origin xyz="5.5645640218466795183e-18 4.4408920985006261617e-16 -0.10381249999999998812" rpy="0 0 0"/>
<mass value="0.040666939294763761181" />
<inertia ixx="0.00014699519269296084214" ixy="-2.6679644254484182746e-22"  ixz="2.3585105612980041276e-21" iyy="0.00014699519269296089635" iyz="-2.3414609436374486076e-19" izz="1.8110290680857596429e-06" />
</inertial>
</link>

<link name="fermeture7_B">
<inertial>
<origin xyz="0 0 0" rpy="0 0 0" />
<mass value="1e-9" />
<inertia ixx="0" ixy="0" ixz="0" iyy="0" iyz="0" izz="0" />
</inertial>
</link>
<joint name="fermeture7_B_frame" type="fixed">
<origin xyz="4.1633363423443370266e-17 -3.0531133177191804862e-16 -0.20762499999999989297" rpy="4.7657994470008846293e-18 1.6442732956008238335e-17 -3.141592653589793116" />
<parent link="rode_foot_4" />
<child link="fermeture7_B" />
<axis xyz="0 0 0"/>
</joint>

<joint name="to_rotule_free_renvois_hanche4" type="revolute">
<origin xyz="-0.1069583333333340297 0.062916666666667064867 1.1102230246251565404e-16" rpy="1.570796326794896558 -0.092185476461817753013 2.6802825518558815111e-17" />
<parent link="renvois_hanche" />
<child link="rode_foot_4" />
<axis xyz="0 0 1"/>
<limit effort="1" velocity="20" />
<joint_properties friction="0.0"/>
</joint>

<joint name="free_renvois_hanche2" type="revolute">
<origin xyz="0.072354166666667982244 -0.05347916666666752139 -0.028312500000000073719" rpy="3.141592653589793116 1.1335268030418274217e-15 0.40020166506191917621" />
<parent link="tarsus" />
<child link="renvois_hanche" />
<axis xyz="0 0 1"/>
<limit effort="1" velocity="20" />
<joint_properties friction="0.0"/>
</joint>

<link name="motteur_rotation">
<visual>
<origin xyz="0.037750000000000005773 1.0161041666666668082 -0.1384166666666665213" rpy="1.570796326794896558 1.5707963267948950037 0" />
<geometry>
<mesh filename="package:///motteur_rotation.stl"/>
</geometry>
<material name="motteur_rotation_material">
<color rgba="0.2313725490196078538 0.38039215686274507888 0.7058823529411765163 1.0"/>
</material>
</visual>
<collision>
<origin xyz="0.037750000000000005773 1.0161041666666668082 -0.1384166666666665213" rpy="1.570796326794896558 1.5707963267948950037 0" />
<geometry>
<mesh filename="package:///motteur_rotation.stl"/>
</geometry>
<material name="motteur_rotation_material">
<color rgba="0.2313725490196078538 0.38039215686274507888 0.7058823529411765163 1.0"/>
</material>
</collision>
<inertial>
<origin xyz="1.3867526073082657308e-17 2.2204460492503130808e-16 -0.038600225225225229253" rpy="0 0 0"/>
<mass value="0.050662516966540720176" />
<inertia ixx="1.6868799164751242944e-05" ixy="-2.2674023303878449996e-28"  ixz="-2.659706538168265888e-24" iyy="1.6868799164751239556e-05" iyz="-8.5294128510248299929e-21" izz="1.155183150425073109e-05" />
</inertial>
</link>

<link name="piston_4">
<visual>
<origin xyz="-0.10179556944408765795 -0.15392457132099851558 0.95649999999999979483" rpy="3.141592653589793116 4.8283280534820453215e-20 5.1918393766029817483e-24" />
<geometry>
<mesh filename="package:///piston.stl"/>
</geometry>
<material name="piston_material">
<color rgba="0.91764705882352937127 0.91764705882352937127 0.91764705882352937127 1.0"/>
</material>
</visual>
<collision>
<origin xyz="-0.10179556944408765795 -0.15392457132099851558 0.95649999999999979483" rpy="3.141592653589793116 4.8283280534820453215e-20 5.1918393766029817483e-24" />
<geometry>
<mesh filename="package:///piston.stl"/>
</geometry>
<material name="piston_material">
<color rgba="0.91764705882352937127 0.91764705882352937127 0.91764705882352937127 1.0"/>
</material>
</collision>
<inertial>
<origin xyz="1.3877787807814456755e-17 -2.7764407305813594505e-17 -0.01250000000000017937" rpy="0 0 0"/>
<mass value="0.0048966814322412765756" />
<inertia ixx="3.6406794569277518508e-07" ixy="1.6850572950774129908e-30"  ixz="-1.0509100095822815665e-26" iyy="3.6406794569277518508e-07" iyz="4.7550319308723644751e-28" izz="2.1806490886041670108e-07" />
</inertial>
</link>

<link name="fermeture1_A">
<inertial>
<origin xyz="0 0 0" rpy="0 0 0" />
<mass value="1e-9" />
<inertia ixx="0" ixy="0" ixz="0" iyy="0" iyz="0" izz="0" />
</inertial>
</link>
<joint name="fermeture1_A_frame" type="fixed">
<origin xyz="1.3877787807814456755e-17 -5.5511151231257827021e-17 -0.025000000000000160982" rpy="-1.8744017465649457593e-18 -9.818041624348521577e-17 -2.79836129840733741e-20" />
<parent link="piston_4" />
<child link="fermeture1_A" />
<axis xyz="0 0 0"/>
</joint>

<joint name="mot_cheville2" type="prismatic">
<origin xyz="6.2450045135165055399e-17 -2.2204460492503130808e-16 -2.9548398438994372128e-05" rpy="-3.141592653589793116 -1.2075888392074055418e-16 3.141592653589793116" />
<parent link="motteur_rotation" />
<child link="piston_4" />
<axis xyz="0 0 1"/>
<limit effort="1" velocity="20" />
<joint_properties friction="0.0"/>
</joint>

<joint name="to_rotule_free_attache_moeur_4" type="revolute">
<origin xyz="-0.075500000000000150324 -0.044041666666666673402 -0.13527083333333314585" rpy="1.570796326794896558 0.095598525430158579064 -7.5072756837122450885e-16" />
<parent link="tarsus" />
<child link="motteur_rotation" />
<axis xyz="0 0 1"/>
<limit effort="1" velocity="20" />
<joint_properties friction="0.0"/>
</joint>

<link name="motteur_rotation_2">
<visual>
<origin xyz="0.037749999999999991895 1.0161041666666668082 -0.1384166666666665213" rpy="1.570796326794896558 1.5707963267948950037 0" />
<geometry>
<mesh filename="package:///motteur_rotation.stl"/>
</geometry>
<material name="motteur_rotation_material">
<color rgba="0.2313725490196078538 0.38039215686274507888 0.7058823529411765163 1.0"/>
</material>
</visual>
<collision>
<origin xyz="0.037749999999999991895 1.0161041666666668082 -0.1384166666666665213" rpy="1.570796326794896558 1.5707963267948950037 0" />
<geometry>
<mesh filename="package:///motteur_rotation.stl"/>
</geometry>
<material name="motteur_rotation_material">
<color rgba="0.2313725490196078538 0.38039215686274507888 0.7058823529411765163 1.0"/>
</material>
</collision>
<inertial>
<origin xyz="-6.378871269336906111e-21 2.2204460492503130808e-16 -0.038600225225225229253" rpy="0 0 0"/>
<mass value="0.050662516966540720176" />
<inertia ixx="1.6868799164751242944e-05" ixy="-1.2948922482956390042e-28"  ixz="-1.0372908588343965209e-24" iyy="1.6868799164751239556e-05" iyz="-8.5292558604092984749e-21" izz="1.155183150425073109e-05" />
</inertial>
</link>

<link name="piston_5">
<visual>
<origin xyz="-0.10179556944408765795 -0.15392457132099854333 0.95650000000000001688" rpy="-3.141592653589793116 -5.5001239547193146538e-21 1.6842726119609899759e-24" />
<geometry>
<mesh filename="package:///piston.stl"/>
</geometry>
<material name="piston_material">
<color rgba="0.91764705882352937127 0.91764705882352937127 0.91764705882352937127 1.0"/>
</material>
</visual>
<collision>
<origin xyz="-0.10179556944408765795 -0.15392457132099854333 0.95650000000000001688" rpy="-3.141592653589793116 -5.5001239547193146538e-21 1.6842726119609899759e-24" />
<geometry>
<mesh filename="package:///piston.stl"/>
</geometry>
<material name="piston_material">
<color rgba="0.91764705882352937127 0.91764705882352937127 0.91764705882352937127 1.0"/>
</material>
</collision>
<inertial>
<origin xyz="2.7755575615628913511e-17 -5.5515789764735800053e-17 -0.012499999999999953856" rpy="0 0 0"/>
<mass value="0.0048966814322412765756" />
<inertia ixx="3.6406794569277529096e-07" ixy="1.1738957167397852197e-30"  ixz="-2.6593388585410436857e-27" iyy="3.6406794569277518508e-07" iyz="1.1075152869045782978e-27" izz="2.1806490886041670108e-07" />
</inertial>
</link>

<link name="fermeture2_A">
<inertial>
<origin xyz="0 0 0" rpy="0 0 0" />
<mass value="1e-9" />
<inertia ixx="0" ixy="0" ixz="0" iyy="0" iyz="0" izz="0" />
</inertial>
</link>
<joint name="fermeture2_A_frame" type="fixed">
<origin xyz="-6.9388939039072283776e-18 -5.5511151231257827021e-17 -0.025000000000000105471" rpy="1.7473559706539229754e-22 -5.5001239547193146538e-21 1.6842726119609899759e-24" />
<parent link="piston_5" />
<child link="fermeture2_A" />
<axis xyz="0 0 0"/>
</joint>

<joint name="mot_cheville1" type="prismatic">
<origin xyz="1.3877787807814456755e-17 -1.3877787807814456755e-16 -4.1245097658793028472e-05" rpy="3.141592653589793116 5.6902940387883940848e-17 -3.141592653589793116" />
<parent link="motteur_rotation_2" />
<child link="piston_5" />
<axis xyz="0 0 1"/>
<limit effort="1" velocity="20" />
<joint_properties friction="0.0"/>
</joint>

<joint name="to_rotule_free_attache_moeur_5" type="revolute">
<origin xyz="-0.075500000000000136446 -0.044041666666666645646 -0.028312499999999851674" rpy="1.570796326794896558 0.095598525430158620697 -6.4409731452178782971e-16" />
<parent link="tarsus" />
<child link="motteur_rotation_2" />
<axis xyz="0 0 1"/>
<limit effort="1" velocity="20" />
<joint_properties friction="0.0"/>
</joint>

<link name="motteur_rotation_3">
<visual>
<origin xyz="0.037750000000000005773 1.0161041666666668082 -0.13841666666666657681" rpy="1.570796326794896558 1.5707963267948950037 0" />
<geometry>
<mesh filename="package:///motteur_rotation.stl"/>
</geometry>
<material name="motteur_rotation_material">
<color rgba="0.2313725490196078538 0.38039215686274507888 0.7058823529411765163 1.0"/>
</material>
</visual>
<collision>
<origin xyz="0.037750000000000005773 1.0161041666666668082 -0.13841666666666657681" rpy="1.570796326794896558 1.5707963267948950037 0" />
<geometry>
<mesh filename="package:///motteur_rotation.stl"/>
</geometry>
<material name="motteur_rotation_material">
<color rgba="0.2313725490196078538 0.38039215686274507888 0.7058823529411765163 1.0"/>
</material>
</collision>
<inertial>
<origin xyz="-2.7790403149768570029e-19 2.2204460492503130808e-16 -0.038600225225225284764" rpy="0 0 0"/>
<mass value="0.050662516966540720176" />
<inertia ixx="1.6868799164751256496e-05" ixy="5.1826880137259563107e-25"  ixz="-1.4951086653620134198e-25" iyy="1.6868799164751239556e-05" iyz="-8.5268946716822504371e-21" izz="1.155183150425073109e-05" />
</inertial>
</link>

<link name="piston_6">
<visual>
<origin xyz="-0.10179556944408768571 -0.15392457132099857109 0.95649999999999979483" rpy="-3.141592653589793116 -3.7643341247580961418e-20 -8.1624819833755613377e-20" />
<geometry>
<mesh filename="package:///piston.stl"/>
</geometry>
<material name="piston_material">
<color rgba="0.91764705882352937127 0.91764705882352937127 0.91764705882352937127 1.0"/>
</material>
</visual>
<collision>
<origin xyz="-0.10179556944408768571 -0.15392457132099857109 0.95649999999999979483" rpy="-3.141592653589793116 -3.7643341247580961418e-20 -8.1624819833755613377e-20" />
<geometry>
<mesh filename="package:///piston.stl"/>
</geometry>
<material name="piston_material">
<color rgba="0.91764705882352937127 0.91764705882352937127 0.91764705882352937127 1.0"/>
</material>
</collision>
<inertial>
<origin xyz="0 -5.5517871712379431972e-17 -0.01250000000000017937" rpy="0 0 0"/>
<mass value="0.0048966814322412765756" />
<inertia ixx="3.6406794569277529096e-07" ixy="-9.592614829142037094e-26"  ixz="3.9676661205878916719e-26" iyy="3.6406794569277529096e-07" iyz="2.1325991257469006822e-27" izz="2.1806490886041670108e-07" />
</inertial>
</link>

<link name="fermeture6_A">
<inertial>
<origin xyz="0 0 0" rpy="0 0 0" />
<mass value="1e-9" />
<inertia ixx="0" ixy="0" ixz="0" iyy="0" iyz="0" izz="0" />
</inertial>
</link>
<joint name="fermeture6_A_frame" type="fixed">
<origin xyz="-6.9388939039072283776e-18 -1.6653345369377348106e-16 -0.28249999999999997335" rpy="-4.2029392900949747559e-17 -7.4606014470714686977e-18 -1.570796326794896558" />
<parent link="piston_6" />
<child link="fermeture6_A" />
<axis xyz="0 0 0"/>
</joint>

<joint name="mot_genoux" type="prismatic">
<origin xyz="-5.5511151231257827021e-17 7.6327832942979512154e-17 -0.063110639745103724874" rpy="-6.0511400049598649395e-18 4.1907451314458865479e-18 1.570796326794896558" />
<parent link="motteur_rotation_3" />
<child link="piston_6" />
<axis xyz="0 0 1"/>
<limit effort="1" velocity="20" />
<joint_properties friction="0.0"/>
</joint>

<joint name="to_rotule_free_attache_mour_6" type="revolute">
<origin xyz="0.037749999999999464539 -0.188749999999999446 -0.081791666666666845709" rpy="1.5707963267948961139 1.4741965910877770085 3.1415926535897922278" />
<parent link="tarsus" />
<child link="motteur_rotation_3" />
<axis xyz="0 0 1"/>
<limit effort="1" velocity="20" />
<joint_properties friction="0.0"/>
</joint>

<link name="piston_7">
<visual>
<origin xyz="-0.10179556944408764407 0.15392457132099851558 -0.98150000000000003908" rpy="4.7707392583147122407e-21 -1.4924298254456226231e-19 -4.5162089082963286946e-24" />
<geometry>
<mesh filename="package:///piston.stl"/>
</geometry>
<material name="piston_material">
<color rgba="0.91764705882352937127 0.91764705882352937127 0.91764705882352937127 1.0"/>
</material>
</visual>
<collision>
<origin xyz="-0.10179556944408764407 0.15392457132099851558 -0.98150000000000003908" rpy="4.7707392583147122407e-21 -1.4924298254456226231e-19 -4.5162089082963286946e-24" />
<geometry>
<mesh filename="package:///piston.stl"/>
</geometry>
<material name="piston_material">
<color rgba="0.91764705882352937127 0.91764705882352937127 0.91764705882352937127 1.0"/>
</material>
</collision>
<inertial>
<origin xyz="2.7755575615628913511e-17 2.776894025751851408e-17 -0.012500000000000064879" rpy="0 0 0"/>
<mass value="0.0048966814322412765756" />
<inertia ixx="3.6406794569277518508e-07" ixy="4.2806091372342865086e-31"  ixz="4.8884388899718974673e-26" iyy="3.6406794569277518508e-07" iyz="4.7445715555564862311e-27" izz="2.1806490886041670108e-07" />
</inertial>
</link>

<link name="fermeture3_A">
<inertial>
<origin xyz="0 0 0" rpy="0 0 0" />
<mass value="1e-9" />
<inertia ixx="0" ixy="0" ixz="0" iyy="0" iyz="0" izz="0" />
</inertial>
</link>
<joint name="fermeture3_A_frame" type="fixed">
<origin xyz="0 -5.5511151231257827021e-17 -0.025000000000000216493" rpy="-3.141592653589793116 -1.4924298254456226231e-19 -4.5162089082963286946e-24" />
<parent link="piston_7" />
<child link="fermeture3_A" />
<axis xyz="0 0 0"/>
</joint>

<joint name="to_rotule_free_hanche_attache1" type="revolute">
<origin xyz="0.069208333333333316162 -1.6653345369377348106e-16 -0.04404166666666681218" rpy="-1.57079632679489678 -0.095598525430158579064 3.1415926535897926719" />
<parent link="tarsus" />
<child link="piston_7" />
<axis xyz="0 0 1"/>
<limit effort="1" velocity="20" />
<joint_properties friction="0.0"/>
</joint>

<link name="piston_8">
<visual>
<origin xyz="-0.10179556944408764407 0.15392457132099851558 -0.98149999999999992806" rpy="4.7707392583147122407e-21 -1.4924298254456226231e-19 -4.5162089082963286946e-24" />
<geometry>
<mesh filename="package:///piston.stl"/>
</geometry>
<material name="piston_material">
<color rgba="0.91764705882352937127 0.91764705882352937127 0.91764705882352937127 1.0"/>
</material>
</visual>
<collision>
<origin xyz="-0.10179556944408764407 0.15392457132099851558 -0.98149999999999992806" rpy="4.7707392583147122407e-21 -1.4924298254456226231e-19 -4.5162089082963286946e-24" />
<geometry>
<mesh filename="package:///piston.stl"/>
</geometry>
<material name="piston_material">
<color rgba="0.91764705882352937127 0.91764705882352937127 0.91764705882352937127 1.0"/>
</material>
</collision>
<inertial>
<origin xyz="2.7755575615628913511e-17 2.776894025751851408e-17 -0.012499999999999953856" rpy="0 0 0"/>
<mass value="0.0048966814322412765756" />
<inertia ixx="3.6406794569277518508e-07" ixy="4.2806091372342865086e-31"  ixz="4.8884388899718974673e-26" iyy="3.6406794569277518508e-07" iyz="4.7445715555564862311e-27" izz="2.1806490886041670108e-07" />
</inertial>
</link>

<link name="fermeture4_A">
<inertial>
<origin xyz="0 0 0" rpy="0 0 0" />
<mass value="1e-9" />
<inertia ixx="0" ixy="0" ixz="0" iyy="0" iyz="0" izz="0" />
</inertial>
</link>
<joint name="fermeture4_A_frame" type="fixed">
<origin xyz="0 8.3266726846886740532e-17 -0.025000000000000077716" rpy="-3.141592653589793116 -1.4924298254456226231e-19 -4.5162089082963286946e-24" />
<parent link="piston_8" />
<child link="fermeture4_A" />
<axis xyz="0 0 0"/>
</joint>

<joint name="to_rotule_free_hanche_attache2" type="revolute">
<origin xyz="0.069208333333333357795 0 0.044041666666666673402" rpy="-1.57079632679489678 -0.095598525430158579064 3.1415926535897926719" />
<parent link="tarsus" />
<child link="piston_8" />
<axis xyz="0 0 1"/>
<limit effort="1" velocity="20" />
<joint_properties friction="0.0"/>
</joint>

<joint name="free_cardan_xhips" type="revolute">
<origin xyz="7.4999999999936228789e-05 7.2164496600635175128e-16 -7.5000000000697772395e-05" rpy="1.5707963267932967266 1.5702141424144824278 -1.570796326796419784" />
<parent link="cardan_foot" />
<child link="tarsus" />
<axis xyz="0 0 1"/>
<limit effort="1" velocity="20" />
<joint_properties friction="0.0"/>
</joint>

<joint name="free_cardans_yhips" type="revolute">
<origin xyz="9.5409791178724390193e-18 -2.7755575615628913511e-17 -0.18875000000000002887" rpy="-1.57079632679489678 -0.00013745695438837276787 1.570796326794896558" />
<parent link="hanche" />
<child link="cardan_foot" />
<axis xyz="0 0 1"/>
<limit effort="1" velocity="20" />
<joint_properties friction="0.0"/>
</joint>

<link name="cardan_hache">
<visual>
<origin xyz="0.12426041666666662322 0.98150000000000003908 -0.0062916666666681291334" rpy="1.570796326794896558 1.5707963267948950037 0" />
<geometry>
<mesh filename="package:///cardan_hache.stl"/>
</geometry>
<material name="cardan_hache_material">
<color rgba="0.49803921568627451677 0.49803921568627451677 0.49803921568627451677 1.0"/>
</material>
</visual>
<collision>
<origin xyz="0.12426041666666662322 0.98150000000000003908 -0.0062916666666681291334" rpy="1.570796326794896558 1.5707963267948950037 0" />
<geometry>
<mesh filename="package:///cardan_hache.stl"/>
</geometry>
<material name="cardan_hache_material">
<color rgba="0.49803921568627451677 0.49803921568627451677 0.49803921568627451677 1.0"/>
</material>
</collision>
<inertial>
<origin xyz="-2.9636406301208572212e-17 1.5739742842413306789e-11 -0.038564852711678983266" rpy="0 0 0"/>
<mass value="0.015650981021718499836" />
<inertia ixx="7.4066993033887045536e-06" ixy="-2.6990293691933336697e-13"  ixz="7.5651500568216395051e-23" iyy="7.5433853822706890471e-06" iyz="1.1495663595307234011e-13" izz="8.4764734220375519469e-07" />
</inertial>
</link>

<link name="moteur_hanche1">
<visual>
<origin xyz="-0.056625000000000105804 -0.98150000000000003908 -0.12426041666666665098" rpy="-1.570796326794896558 -3.9077203161551190358e-18 -6.6344056694713867223e-20" />
<geometry>
<mesh filename="package:///moteur_hanche1.stl"/>
</geometry>
<material name="moteur_hanche1_material">
<color rgba="0.98039215686274505668 0.71372549019607844922 0.0039215686274509803377 1.0"/>
</material>
</visual>
<collision>
<origin xyz="-0.056625000000000105804 -0.98150000000000003908 -0.12426041666666665098" rpy="-1.570796326794896558 -3.9077203161551190358e-18 -6.6344056694713867223e-20" />
<geometry>
<mesh filename="package:///moteur_hanche1.stl"/>
</geometry>
<material name="moteur_hanche1_material">
<color rgba="0.98039215686274505668 0.71372549019607844922 0.0039215686274509803377 1.0"/>
</material>
</collision>
<inertial>
<origin xyz="6.9388939039072283776e-18 -0.014684805075465323654 7.0208545591615691488e-17" rpy="0 0 0"/>
<mass value="0.046264571606101846657" />
<inertia ixx="1.1597158512617963014e-05" ixy="6.397468539937551349e-25"  ixz="1.5448495106276460573e-22" iyy="1.4057782313436138118e-05" iyz="4.0477455191202339916e-24" izz="1.1524156994201791395e-05" />
</inertial>
</link>

<link name="piston_9">
<visual>
<origin xyz="-0.10179556944408767183 0.15392457132099851558 -0.98150000000000003908" rpy="1.1160994889302602654e-18 6.2394804750431383568e-20 1.1774112289867942571e-17" />
<geometry>
<mesh filename="package:///piston.stl"/>
</geometry>
<material name="piston_material">
<color rgba="0.91764705882352937127 0.91764705882352937127 0.91764705882352937127 1.0"/>
</material>
</visual>
<collision>
<origin xyz="-0.10179556944408767183 0.15392457132099851558 -0.98150000000000003908" rpy="1.1160994889302602654e-18 6.2394804750431383568e-20 1.1774112289867942571e-17" />
<geometry>
<mesh filename="package:///piston.stl"/>
</geometry>
<material name="piston_material">
<color rgba="0.91764705882352937127 0.91764705882352937127 0.91764705882352937127 1.0"/>
</material>
</collision>
<inertial>
<origin xyz="1.3877787807814456755e-17 7.4915896260954059045e-19 -0.012499999999999953856" rpy="0 0 0"/>
<mass value="0.0048966814322412765756" />
<inertia ixx="3.6406794569277529096e-07" ixy="3.2688510860192709885e-24"  ixz="-1.4339561155391647241e-26" iyy="3.6406794569277529096e-07" iyz="3.0520400148290900991e-25" izz="2.1806490886041675402e-07" />
</inertial>
</link>

<link name="fermeture4_B">
<inertial>
<origin xyz="0 0 0" rpy="0 0 0" />
<mass value="1e-9" />
<inertia ixx="0" ixy="0" ixz="0" iyy="0" iyz="0" izz="0" />
</inertial>
</link>
<joint name="fermeture4_B_frame" type="fixed">
<origin xyz="0 -2.7755575615628913511e-17 -0.025000000000000022204" rpy="1.1160994889302602654e-18 6.2394804750431383568e-20 1.1774112289867942571e-17" />
<parent link="piston_9" />
<child link="fermeture4_B" />
<axis xyz="0 0 0"/>
</joint>

<joint name="mot_hanchexy1" type="prismatic">
<origin xyz="5.5511151231257827021e-17 -0.03147530555841833444 8.3266726846886740532e-17" rpy="-1.570796326794896558 -4.8539988437297803109e-17 3.2508222489336867815e-16" />
<parent link="moteur_hanche1" />
<child link="piston_9" />
<axis xyz="0 0 1"/>
<limit effort="1" velocity="20" />
<joint_properties friction="0.0"/>
</joint>

<joint name="free_attache_moeur_hanchexy2" type="revolute">
<origin xyz="-8.3266726846886740532e-17 -1.3877787807814456755e-16 -0.062916666666666676289" rpy="-1.5707963267950315611 -1.5704936563091338453 1.5707963267928437556" />
<parent link="cardan_hache" />
<child link="moteur_hanche1" />
<axis xyz="0 0 1"/>
<limit effort="1" velocity="20" />
<joint_properties friction="0.0"/>
</joint>

<joint name="free_attache_moeur_hanche_1" type="revolute">
<origin xyz="0.012499999999999990286 -0.0424687499999999718 -0.088083333333333277415" rpy="1.570796326794896558 0.0047435069561565304519 -1.570796326794896336" />
<parent link="hanche" />
<child link="cardan_hache" />
<axis xyz="0 0 1"/>
<limit effort="1" velocity="20" />
<joint_properties friction="0.0"/>
</joint>

<link name="cardan_hache_2">
<visual>
<origin xyz="0.1242604166666666371 0.98150000000000003908 -0.0062916666666681265313" rpy="1.570796326794896558 1.5707963267948950037 0" />
<geometry>
<mesh filename="package:///cardan_hache.stl"/>
</geometry>
<material name="cardan_hache_material">
<color rgba="0.49803921568627451677 0.49803921568627451677 0.49803921568627451677 1.0"/>
</material>
</visual>
<collision>
<origin xyz="0.1242604166666666371 0.98150000000000003908 -0.0062916666666681265313" rpy="1.570796326794896558 1.5707963267948950037 0" />
<geometry>
<mesh filename="package:///cardan_hache.stl"/>
</geometry>
<material name="cardan_hache_material">
<color rgba="0.49803921568627451677 0.49803921568627451677 0.49803921568627451677 1.0"/>
</material>
</collision>
<inertial>
<origin xyz="-1.5035681662188399867e-17 1.5739742842413306789e-11 -0.038564852711678969388" rpy="0 0 0"/>
<mass value="0.015650981021718499836" />
<inertia ixx="7.4066993033887045536e-06" ixy="-2.6990293692457089851e-13"  ixz="-3.7961096248847594851e-23" iyy="7.5433853822706890471e-06" iyz="1.1495663595299630654e-13" izz="8.4764734220375477118e-07" />
</inertial>
</link>

<link name="moteur_hanche1_2">
<visual>
<origin xyz="-0.05662500000000013356 -0.9815000000000001501 -0.12426041666666666485" rpy="-1.570796326794896558 9.9481605772792586487e-18 -5.6464736044352189874e-21" />
<geometry>
<mesh filename="package:///moteur_hanche1.stl"/>
</geometry>
<material name="moteur_hanche1_material">
<color rgba="0.98039215686274505668 0.71372549019607844922 0.0039215686274509803377 1.0"/>
</material>
</visual>
<collision>
<origin xyz="-0.05662500000000013356 -0.9815000000000001501 -0.12426041666666666485" rpy="-1.570796326794896558 9.9481605772792586487e-18 -5.6464736044352189874e-21" />
<geometry>
<mesh filename="package:///moteur_hanche1.stl"/>
</geometry>
<material name="moteur_hanche1_material">
<color rgba="0.98039215686274505668 0.71372549019607844922 0.0039215686274509803377 1.0"/>
</material>
</collision>
<inertial>
<origin xyz="-2.0816681711721685133e-17 -0.014684805075465547433 2.7086022941698832772e-17" rpy="0 0 0"/>
<mass value="0.046264571606101846657" />
<inertia ixx="1.1597158512617963014e-05" ixy="-3.2871365176926132464e-25"  ixz="-2.0655975959658704261e-22" iyy="1.405778231343613473e-05" iyz="-7.5235635348633962373e-24" izz="1.1524156994201784619e-05" />
</inertial>
</link>

<link name="piston_10">
<visual>
<origin xyz="-0.10179556944408768571 0.15392457132099851558 -0.98150000000000003908" rpy="7.7095856618526664724e-20 -2.8590462254934253294e-20 1.8588697243342543712e-18" />
<geometry>
<mesh filename="package:///piston.stl"/>
</geometry>
<material name="piston_material">
<color rgba="0.91764705882352937127 0.91764705882352937127 0.91764705882352937127 1.0"/>
</material>
</visual>
<collision>
<origin xyz="-0.10179556944408768571 0.15392457132099851558 -0.98150000000000003908" rpy="7.7095856618526664724e-20 -2.8590462254934253294e-20 1.8588697243342543712e-18" />
<geometry>
<mesh filename="package:///piston.stl"/>
</geometry>
<material name="piston_material">
<color rgba="0.91764705882352937127 0.91764705882352937127 0.91764705882352937127 1.0"/>
</material>
</collision>
<inertial>
<origin xyz="-1.3877787807814456755e-17 2.0834420973279220978e-19 -0.012499999999999953856" rpy="0 0 0"/>
<mass value="0.0048966814322412765756" />
<inertia ixx="3.6406794569277518508e-07" ixy="-7.6261578646985321418e-24"  ixz="-1.858013291408121453e-26" iyy="3.6406794569277529096e-07" iyz="3.2370806804109248977e-26" izz="2.1806490886041675402e-07" />
</inertial>
</link>

<link name="fermeture3_B">
<inertial>
<origin xyz="0 0 0" rpy="0 0 0" />
<mass value="1e-9" />
<inertia ixx="0" ixy="0" ixz="0" iyy="0" iyz="0" izz="0" />
</inertial>
</link>
<joint name="fermeture3_B_frame" type="fixed">
<origin xyz="-1.3877787807814456755e-17 2.7755575615628913511e-17 -0.025000000000000133227" rpy="7.7095856618526664724e-20 -2.8590462254934253294e-20 1.8588697243342543712e-18" />
<parent link="piston_10" />
<child link="fermeture3_B" />
<axis xyz="0 0 0"/>
</joint>

<joint name="mot_hanchexy2" type="prismatic">
<origin xyz="4.1633363423443370266e-17 -0.031475761426423623512 0" rpy="-1.570796326794896558 -4.0842560888460044134e-16 3.7225087496077564125e-16" />
<parent link="moteur_hanche1_2" />
<child link="piston_10" />
<axis xyz="0 0 1"/>
<limit effort="1" velocity="20" />
<joint_properties friction="0.0"/>
</joint>

<joint name="free_attache_moeur_hanchexy" type="revolute">
<origin xyz="-5.5511151231257827021e-17 3.1918911957973250537e-16 -0.062916666666666662411" rpy="-1.570796326794672737 -1.5705013744383484742 1.5707963267936437823" />
<parent link="cardan_hache_2" />
<child link="moteur_hanche1_2" />
<axis xyz="0 0 1"/>
<limit effort="1" velocity="20" />
<joint_properties friction="0.0"/>
</joint>

<joint name="free_attache_moeur_hanche_3" type="revolute">
<origin xyz="0.012500000000000011102 0.042468750000000055067 -0.088083333333333485582" rpy="1.570796326794896558 0.0047908213534053481833 -1.57079632679489678" />
<parent link="hanche" />
<child link="cardan_hache_2" />
<axis xyz="0 0 1"/>
<limit effort="1" velocity="20" />
<joint_properties friction="0.0"/>
</joint>

<link name="piston_11">
<visual>
<origin xyz="-0.10179556944408765795 0.15392457132099848782 -0.9815000000000001501" rpy="0 6.2606537362296609677e-18 0" />
<geometry>
<mesh filename="package:///piston.stl"/>
</geometry>
<material name="piston_material">
<color rgba="0.91764705882352937127 0.91764705882352937127 0.91764705882352937127 1.0"/>
</material>
</visual>
<collision>
<origin xyz="-0.10179556944408765795 0.15392457132099848782 -0.9815000000000001501" rpy="0 6.2606537362296609677e-18 0" />
<geometry>
<mesh filename="package:///piston.stl"/>
</geometry>
<material name="piston_material">
<color rgba="0.91764705882352937127 0.91764705882352937127 0.91764705882352937127 1.0"/>
</material>
</collision>
<inertial>
<origin xyz="2.7755575615628913511e-17 -2.7755575615628722458e-17 -0.012499999999999844569" rpy="0 0 0"/>
<mass value="0.0048966814322412765756" />
<inertia ixx="3.6406794569277529096e-07" ixy="1.8650511195934019078e-55"  ixz="-1.3336100759593679203e-24" iyy="3.6406794569277529096e-07" iyz="4.3005720350141460055e-38" izz="2.180649088604168599e-07" />
</inertial>
</link>

<link name="fermeture5_B">
<inertial>
<origin xyz="0 0 0" rpy="0 0 0" />
<mass value="1e-9" />
<inertia ixx="0" ixy="0" ixz="0" iyy="0" iyz="0" izz="0" />
</inertial>
</link>
<joint name="fermeture5_B_frame" type="fixed">
<origin xyz="-8.3266726846886740532e-17 -2.7755575615628913511e-17 -0.025000000000000105471" rpy="3.141592653589793116 3.025978467155636249e-28 -1.570796326794896558" />
<parent link="piston_11" />
<child link="fermeture5_B" />
<axis xyz="0 0 0"/>
</joint>

<joint name="to_rotule_free_attache2_moeur_hanchez" type="revolute">
<origin xyz="1.7078352620991665844e-15 0.044041666666666673402 -0.053479166666666723418" rpy="1.570796326794896558 -1.9832067293240475674e-17 1.570796326794896558" />
<parent link="hanche" />
<child link="piston_11" />
<axis xyz="0 0 1"/>
<limit effort="1" velocity="20" />
<joint_properties friction="0.0"/>
</joint>

<joint name="free_zhips" type="revolute">
<origin xyz="-0.012499999999999986816 -0.20499999999999996003 -0.0049999999999998934186" rpy="-1.4726037963295123608e-16 1.5370811015985778338e-15 3.0459941681722826345" />
<parent link="hanche_batis" />
<child link="hanche" />
<axis xyz="0 0 1"/>
<limit effort="1" velocity="20" />
<joint_properties friction="0.0"/>
</joint>

<link name="attache_hanche">
<visual>
<origin xyz="0.1384166666666665213 0.037750000000000005773 -1.0745833333333334458" rpy="0 -1.604175351655854949e-15 0" />
<geometry>
<mesh filename="package:///attache_hanche.stl"/>
</geometry>
<material name="attache_hanche_material">
<color rgba="0.64705882352941179736 0.64705882352941179736 0.64705882352941179736 1.0"/>
</material>
</visual>
<collision>
<origin xyz="0.1384166666666665213 0.037750000000000005773 -1.0745833333333334458" rpy="0 -1.604175351655854949e-15 0" />
<geometry>
<mesh filename="package:///attache_hanche.stl"/>
</geometry>
<material name="attache_hanche_material">
<color rgba="0.64705882352941179736 0.64705882352941179736 0.64705882352941179736 1.0"/>
</material>
</collision>
<inertial>
<origin xyz="0 -6.9388939039072283776e-18 -0.033958333333333312609" rpy="0 0 0"/>
<mass value="0.013302651224255402848" />
<inertia ixx="5.4096038561968625921e-06" ixy="0"  ixz="7.7276241791275040983e-21" iyy="5.4096038561968634391e-06" iyz="0" izz="5.9240966907079243215e-07" />
</inertial>
</link>

<link name="motteur_rotation_4">
<visual>
<origin xyz="0.037750000000000005773 1.0161041666666668082 -0.13841666666666649355" rpy="1.570796326794896558 1.5707963267948950037 0" />
<geometry>
<mesh filename="package:///motteur_rotation.stl"/>
</geometry>
<material name="motteur_rotation_material">
<color rgba="0.2313725490196078538 0.38039215686274507888 0.7058823529411765163 1.0"/>
</material>
</visual>
<collision>
<origin xyz="0.037750000000000005773 1.0161041666666668082 -0.13841666666666649355" rpy="1.570796326794896558 1.5707963267948950037 0" />
<geometry>
<mesh filename="package:///motteur_rotation.stl"/>
</geometry>
<material name="motteur_rotation_material">
<color rgba="0.2313725490196078538 0.38039215686274507888 0.7058823529411765163 1.0"/>
</material>
</collision>
<inertial>
<origin xyz="6.9388939039072283776e-18 0 -0.038600225225225201497" rpy="0 0 0"/>
<mass value="0.050662516966540720176" />
<inertia ixx="1.686879916475124972e-05" ixy="0"  ixz="0" iyy="1.6868799164751246332e-05" iyz="-8.5293484665262207354e-21" izz="1.155183150425073109e-05" />
</inertial>
</link>

<link name="piston_12">
<visual>
<origin xyz="-0.10179556944408768571 0.15392457132099851558 -0.98149999999999992806" rpy="0 -0 0" />
<geometry>
<mesh filename="package:///piston.stl"/>
</geometry>
<material name="piston_material">
<color rgba="0.91764705882352937127 0.91764705882352937127 0.91764705882352937127 1.0"/>
</material>
</visual>
<collision>
<origin xyz="-0.10179556944408768571 0.15392457132099851558 -0.98149999999999992806" rpy="0 -0 0" />
<geometry>
<mesh filename="package:///piston.stl"/>
</geometry>
<material name="piston_material">
<color rgba="0.91764705882352937127 0.91764705882352937127 0.91764705882352937127 1.0"/>
</material>
</collision>
<inertial>
<origin xyz="0 0 -0.012499999999999844569" rpy="0 0 0"/>
<mass value="0.0048966814322412765756" />
<inertia ixx="3.6406794569277529096e-07" ixy="0"  ixz="0" iyy="3.6406794569277529096e-07" iyz="0" izz="2.1806490886041675402e-07" />
</inertial>
</link>

<link name="fermeture5_A">
<inertial>
<origin xyz="0 0 0" rpy="0 0 0" />
<mass value="1e-9" />
<inertia ixx="0" ixy="0" ixz="0" iyy="0" iyz="0" izz="0" />
</inertial>
</link>
<joint name="fermeture5_A_frame" type="fixed">
<origin xyz="-6.9388939039072283776e-18 0 -0.025000000000000077716" rpy="0 -0 0" />
<parent link="piston_12" />
<child link="fermeture5_A" />
<axis xyz="0 0 0"/>
</joint>

<joint name="mot_hanchez" type="prismatic">
<origin xyz="2.7755575615628913511e-17 -1.4571677198205179593e-16 -0.062916666666666648533" rpy="0 -0 -1.570796326794896558" />
<parent link="motteur_rotation_4" />
<child link="piston_12" />
<axis xyz="0 0 1"/>
<limit effort="1" velocity="20" />
<joint_properties friction="0.0"/>
</joint>

<joint name="to_rotule_free_attache_moeur_hanche_z" type="revolute">
<origin xyz="-1.3877787807814456755e-17 0 -0.058479166666666637653" rpy="1.570796326794896558 -0 1.570796326794896558" />
<parent link="attache_hanche" />
<child link="motteur_rotation_4" />
<axis xyz="0 0 1"/>
<limit effort="1" velocity="20" />
<joint_properties friction="0.0"/>
</joint>

<joint name="free_attache_moeur_hanche_2" type="revolute">
<origin xyz="0.11962499999999837152 -0.24904166666666668895 2.2204460492503130808e-16" rpy="0 -1.5429430116984873749e-15 0" />
<parent link="hanche_batis" />
<child link="attache_hanche" />
<axis xyz="0 0 1"/>
<limit effort="1" velocity="20" />
<joint_properties friction="0.0"/>
</joint>


</robot>
