<robot name="onshape">
  <link name="torso">
    <visual>
      <origin xyz="-3.6658488180179105565e-18 2.0816681711721685133e-17 0.059867854479678836443" rpy="-6.1232339957367660359e-17 -0 1.570796326794896558" />
      <geometry>
        <mesh filename="package:///torso.stl" />
      </geometry>
      <material name="torso_material">
        <color rgba="0.61568627450980395466 0.81176470588235294379 0.92941176470588238168 1.0" />
      </material>
    </visual>
    <collision>
      <origin xyz="-3.6658488180179105565e-18 2.0816681711721685133e-17 0.059867854479678836443" rpy="-6.1232339957367660359e-17 -0 1.570796326794896558" />
      <geometry>
        <mesh filename="package:///torso.stl" />
      </geometry>
    </collision>
    <inertial>
      <origin xyz="-4.4586984416800995021e-18 2.5045018153878196526e-17 0.070603948746371325562" rpy="0 0 0" />
      <mass value="3.2452322404414171153" />
      <inertia ixx="0.012163262961236534151" ixy="0" ixz="1.2921033060725064293e-19" iyy="0.0040573041803173628961" iyz="0" izz="0.010053098125184019296" />
    </inertial>
  </link>
  <link name="hip">
    <inertial>
      <origin xyz="0 0 0" rpy="0 0 0" />
      <mass value="1e-9" />
      <inertia ixx="0" ixy="0" ixz="0" iyy="0" iyz="0" izz="0" />
    </inertial>
  </link>
  <joint name="hip_frame" type="fixed">
    <origin xyz="2.4027501270446886779e-19 -1.626303258728255688e-19 0.0024999999999999996184" rpy="2.8421709430404007435e-14 3.0814879110196404233e-31 0" />
    <parent link="torso" />
    <child link="hip" />
    <axis xyz="0 0 0" />
  </joint>
  <link name="hip_y">
    <visual>
      <origin xyz="0.10706579297345658608 0 -0.035199999999999995182" rpy="-1.570796326794896558 -5.6312007645629446763e-33 5.39435319285282521e-58" />
      <geometry>
        <mesh filename="package:///hip_y.stl" />
      </geometry>
      <material name="hip_y_material">
        <color rgba="0.2313725490196078538 0.38039215686274507888 0.7058823529411765163 1.0" />
      </material>
    </visual>
    <collision>
      <origin xyz="0.10706579297345658608 0 -0.035199999999999995182" rpy="-1.570796326794896558 -5.6312007645629446763e-33 5.39435319285282521e-58" />
      <geometry>
        <mesh filename="package:///hip_y.stl" />
      </geometry>
    </collision>
    <inertial>
      <origin xyz="0.015578666288194945033 -1.2357431137270427259e-07 -0.034149457045324432825" rpy="0 0 0" />
      <mass value="1.2895238899898622265" />
      <inertia ixx="0.00089621011138626548598" ixy="-1.7957438648418447173e-09" ixz="3.2112420914059147952e-05" iyy="0.0010420724953831758935" iyz="3.0492496474583042268e-09" izz="0.0010213484696825509291" />
    </inertial>
  </link>
  <link name="hip_x">
    <visual>
      <origin xyz="1.3877787807814456755e-17 0 -0.054400000000000003908" rpy="1.570796326794896558 1.570796326794896558 0" />
      <geometry>
        <mesh filename="package:///hip_x.stl" />
      </geometry>
      <material name="hip_x_material">
        <color rgba="0.64705882352941179736 0.64705882352941179736 0.64705882352941179736 1.0" />
      </material>
    </visual>
    <collision>
      <origin xyz="1.3877787807814456755e-17 0 -0.054400000000000003908" rpy="1.570796326794896558 1.570796326794896558 0" />
      <geometry>
        <mesh filename="package:///hip_x.stl" />
      </geometry>
    </collision>
    <inertial>
      <origin xyz="0.0023378176535870207227 -8.6641550262918365894e-19 -0.045216753463575065641" rpy="0 0 0" />
      <mass value="1.4197410037164888141" />
      <inertia ixx="0.0014949229305128528423" ixy="-1.1380610552544594995e-36" ixz="-1.2476184392984380401e-05" iyy="0.0013017541081209299796" iyz="6.0953403205600394821e-36" izz="0.00094724669336309881909" />
    </inertial>
  </link>
  <link name="hip_z">
    <visual>
      <origin xyz="-0.11999999999999998168 1.3877787807814456755e-17 -0.070000000000000006661" rpy="-1.570796326794896558 5.680752870292893348e-33 2.4401878169922787833e-18" />
      <geometry>
        <mesh filename="package:///hip_z.stl" />
      </geometry>
      <material name="hip_z_material">
        <color rgba="0.61568627450980395466 0.81176470588235294379 0.92941176470588238168 1.0" />
      </material>
    </visual>
    <collision>
      <origin xyz="-0.11999999999999998168 1.3877787807814456755e-17 -0.070000000000000006661" rpy="-1.570796326794896558 5.680752870292893348e-33 2.4401878169922787833e-18" />
      <geometry>
        <mesh filename="package:///hip_z.stl" />
      </geometry>
    </collision>
    <inertial>
      <origin xyz="-0.059999999999999983902 1.4460071761737509291e-17 -0.021999999999999998723" rpy="0 0 0" />
      <mass value="3.893275615304738313" />
      <inertia ixx="0.0040205863361596526698" ixy="5.1720596697205702394e-19" ixz="5.0372461844683392763e-36" iyy="0.014779167671256707509" iyz="4.7399047807875029264e-34" izz="0.017543523742211363653" />
    </inertial>
  </link>
  <link name="shin">
    <visual>
      <origin xyz="0 6.9388939039072283776e-18 -0.025000000000000008327" rpy="-1.570796326794896558 2.8899253672147855847e-33 -3.7166240201221414042e-17" />
      <geometry>
        <mesh filename="package:///shin.stl" />
      </geometry>
      <material name="shin_material">
        <color rgba="0.61568627450980395466 0.81176470588235294379 0.92941176470588238168 1.0" />
      </material>
    </visual>
    <collision>
      <origin xyz="0 6.9388939039072283776e-18 -0.025000000000000008327" rpy="-1.570796326794896558 2.8899253672147855847e-33 -3.7166240201221414042e-17" />
      <geometry>
        <mesh filename="package:///shin.stl" />
      </geometry>
    </collision>
    <inertial>
      <origin xyz="0.086542930154570346657 0.024349627108824736105 -0.025000000824260217025" rpy="0 0 0" />
      <mass value="0.55578140933316355632" />
      <inertia ixx="0.00046644066811272702098" ixy="-0.00088329043391741632937" ixz="6.3639809445707090249e-13" iyy="0.009055909587116245385" iyz="1.1189385759788385046e-11" izz="0.0093490826129847756643" />
    </inertial>
  </link>
  <link name="tarsus">
    <visual>
      <origin xyz="-0.11600000000000029732 -0.11491398237765959589 -1.3877787807814456755e-16" rpy="-3.141592653589793116 1.570796326794896558 0" />
      <geometry>
        <mesh filename="package:///actuator_molet.stl" />
      </geometry>
      <material name="actuator_molet_material">
        <color rgba="0.91764705882352937127 0.91764705882352937127 0.91764705882352937127 1.0" />
      </material>
    </visual>
    <collision>
      <origin xyz="-0.11600000000000029732 -0.11491398237765959589 -1.3877787807814456755e-16" rpy="-3.141592653589793116 1.570796326794896558 0" />
      <geometry>
        <mesh filename="package:///actuator_molet.stl" />
      </geometry>
    </collision>
    <visual>
      <origin xyz="-2.7755575615628913511e-17 0.0010860176223413953167 0" rpy="-1.570796326794896558 -1.570796326794896558 0" />
      <geometry>
        <mesh filename="package:///tarsus.stl" />
      </geometry>
      <material name="tarsus_material">
        <color rgba="0.61568627450980395466 0.81176470588235294379 0.92941176470588238168 1.0" />
      </material>
    </visual>
    <collision>
      <origin xyz="-2.7755575615628913511e-17 0.0010860176223413953167 0" rpy="-1.570796326794896558 -1.570796326794896558 0" />
      <geometry>
        <mesh filename="package:///tarsus.stl" />
      </geometry>
    </collision>
    <inertial>
      <origin xyz="-0.083086291902174785884 -0.020033778925019916917 2.8736095514456528726e-08" rpy="0 0 0" />
      <mass value="0.74284619422086228813" />
      <inertia ixx="0.00039818835112512214513" ixy="-0.00054213231673499973854" ixz="-5.2637644317294867134e-10" iyy="0.0079851917842741013814" iyz="1.2685116124571937586e-10" izz="0.0079848716361182493773" />
    </inertial>
  </link>
  <link name="foot_roll">
    <visual>
      <origin xyz="0.32599840000000013251 0.039744000000000001549 -0.013999999999999873657" rpy="-1.570796326794896558 -1.570796326794896336 0" />
      <geometry>
        <mesh filename="package:///foot_roll.stl" />
      </geometry>
      <material name="foot_roll_material">
        <color rgba="0.2313725490196078538 0.38039215686274507888 0.7058823529411765163 1.0" />
      </material>
    </visual>
    <collision>
      <origin xyz="0.32599840000000013251 0.039744000000000001549 -0.013999999999999873657" rpy="-1.570796326794896558 -1.570796326794896336 0" />
      <geometry>
        <mesh filename="package:///foot_roll.stl" />
      </geometry>
    </collision>
    <inertial>
      <origin xyz="-2.1851523702337901694e-08 -0.0014449033387292642416 -0.013999993222565306969" rpy="0 0 0" />
      <mass value="0.0027067106871796996204" />
      <inertia ixx="1.8232396912107799174e-07" ixy="1.2456494874696662968e-13" ixz="-3.0177862000950179661e-13" iyy="1.1958745424438046988e-07" iyz="4.5807687216462854167e-14" izz="1.0944659228682656112e-07" />
    </inertial>
  </link>
  <link name="foot_part">
    <visual>
      <origin xyz="-0.0011288304490431055882 0 0.0090799999999999769784" rpy="1.570796326794896558 1.4161182041695280242e-18 -2.4795877953606935439e-20" />
      <geometry>
        <mesh filename="package:///foot_part.stl" />
      </geometry>
      <material name="foot_part_material">
        <color rgba="0.61568627450980395466 0.81176470588235294379 0.92941176470588238168 1.0" />
      </material>
    </visual>
    <collision>
      <origin xyz="-0.0011288304490431055882 0 0.0090799999999999769784" rpy="1.570796326794896558 1.4161182041695280242e-18 -2.4795877953606935439e-20" />
      <geometry>
        <mesh filename="package:///foot_part.stl" />
      </geometry>
    </collision>
    <inertial>
      <origin xyz="-0.042296631354857269769 -6.7228492053652296851e-10 0.011797351827666179708" rpy="0 0 0" />
      <mass value="0.33095167420253657209" />
      <inertia ixx="0.0010118322945958282532" ixy="2.5339652298518396222e-12" ixz="-0.00049446274168876594261" iyy="0.0012276801049992628473" iyz="7.2849212776786672486e-12" izz="0.00051045333461432877177" />
    </inertial>
  </link>
  <link name="foot">
    <inertial>
      <origin xyz="0 0 0" rpy="0 0 0" />
      <mass value="1e-9" />
      <inertia ixx="0" ixy="0" ixz="0" iyy="0" iyz="0" izz="0" />
    </inertial>
  </link>
  <joint name="foot_frame" type="fixed">
    <origin xyz="-0.055897619600577819199 2.7755575615628913511e-16 0.014375929767894812805" rpy="3.141592653589793116 1.0420837364882524767 3.141592653589793116" />
    <parent link="foot_part" />
    <child link="foot" />
    <axis xyz="0 0 0" />
  </joint>
  <link name="toe_b_1/2">
    <visual>
      <origin xyz="-0.054171488011523771799 -0.043924303555988974956 4.9999999999994493294e-05" rpy="-1.570796326794896558 -1.570796326794896558 0" />
      <geometry>
        <mesh filename="package:///toe_b_1_2.stl" />
      </geometry>
      <material name="toe_b_1/2_material">
        <color rgba="0.64705882352941179736 0.64705882352941179736 0.64705882352941179736 1.0" />
      </material>
    </visual>
    <collision>
      <origin xyz="-0.054171488011523771799 -0.043924303555988974956 4.9999999999994493294e-05" rpy="-1.570796326794896558 -1.570796326794896558 0" />
      <geometry>
        <mesh filename="package:///toe_b_1_2.stl" />
      </geometry>
    </collision>
    <inertial>
      <origin xyz="6.9378274468258536923e-18 -2.7755575615628913511e-17 -0.0599749999999999589" rpy="0 0 0" />
      <mass value="0.0060293446207695467268" />
      <inertia ixx="7.2533028348992182064e-06" ixy="3.6841790582579530773e-27" ixz="-1.5576798258460358522e-25" iyy="7.2533028348992105832e-06" iyz="-4.3457671256913357088e-23" izz="4.8234756966146912223e-08" />
    </inertial>
  </link>
  <link name="closedloop3_B">
    <inertial>
      <origin xyz="0 0 0" rpy="0 0 0" />
      <mass value="1e-9" />
      <inertia ixx="0" ixy="0" ixz="0" iyy="0" iyz="0" izz="0" />
    </inertial>
  </link>
  <joint name="closedloop3_B_frame" type="fixed">
    <origin xyz="-4.1633363423443370266e-17 5.5511151231257827021e-17 -0.11995000000000011209" rpy="-3.141592653589793116 6.050439432614581419e-18 1.570796326794896558" />
    <parent link="toe_b_1/2" />
    <child link="closedloop3_B" />
    <axis xyz="0 0 0" />
  </joint>
  <link name="toe_b_1/2_2">
    <visual>
      <origin xyz="-0.054171488011523792616 0.043924303555989085979 -0.11999999999999999556" rpy="1.570796326794896558 1.570796326794896558 0" />
      <geometry>
        <mesh filename="package:///toe_b_1_2.stl" />
      </geometry>
      <material name="toe_b_1/2_material">
        <color rgba="0.64705882352941179736 0.64705882352941179736 0.64705882352941179736 1.0" />
      </material>
    </visual>
    <collision>
      <origin xyz="-0.054171488011523792616 0.043924303555989085979 -0.11999999999999999556" rpy="1.570796326794896558 1.570796326794896558 0" />
      <geometry>
        <mesh filename="package:///toe_b_1_2.stl" />
      </geometry>
    </collision>
    <inertial>
      <origin xyz="-6.9378064251734532553e-18 1.4571677198205179593e-16 -0.059975000000000042166" rpy="0 0 0" />
      <mass value="0.0060293446207695467268" />
      <inertia ixx="7.2533028348992199005e-06" ixy="-2.5024026648690658932e-25" ixz="4.102905989623183494e-26" iyy="7.2533028348992105832e-06" iyz="2.498807008966941157e-22" izz="4.8234756966146925458e-08" />
    </inertial>
  </link>
  <link name="closedloop2_B">
    <inertial>
      <origin xyz="0 0 0" rpy="0 0 0" />
      <mass value="1e-9" />
      <inertia ixx="0" ixy="0" ixz="0" iyy="0" iyz="0" izz="0" />
    </inertial>
  </link>
  <joint name="closedloop2_B_frame" type="fixed">
    <origin xyz="-1.0408340855860842566e-16 1.6653345369377348106e-16 -0.11995000000000022311" rpy="3.141592653589793116 -3.4014104205904975495e-17 1.570796326794896558" />
    <parent link="toe_b_1/2_2" />
    <child link="closedloop2_B" />
    <axis xyz="0 0 0" />
  </joint>
  <joint name="free_foot2" type="revolute">
    <origin xyz="1.1102230246251565404e-16 0.0089999999999998969713 -0.013999999999999956923" rpy="-1.5707963267948961139 0.00018013600906293872469 -3.141592653589793116" />
    <parent link="foot_roll" />
    <child link="foot_part" />
    <axis xyz="0 0 1" />
    <limit effort="1" velocity="20" />
    <joint_properties friction="0.0" />
  </joint>
  <joint name="free_foot1" type="revolute">
    <origin xyz="-0.32599840000000002149 -0.038657982377658606232 -0.01400000000000004019" rpy="-3.1415926535897926719 3.4117039112211768089e-17 -2.8764747500822966941" />
    <parent link="tarsus" />
    <child link="foot_roll" />
    <axis xyz="0 0 1" />
    <limit effort="1" velocity="20" />
    <joint_properties friction="0.0" />
  </joint>
  <link name="crank">
    <visual>
      <origin xyz="0.088799999999999962297 0.027200000000000001954 0.02999999999999999889" rpy="-1.570796326794896558 -1.570796326794896558 0" />
      <geometry>
        <mesh filename="package:///crank.stl" />
      </geometry>
      <material name="crank_material">
        <color rgba="0.64705882352941179736 0.64705882352941179736 0.64705882352941179736 1.0" />
      </material>
    </visual>
    <collision>
      <origin xyz="0.088799999999999962297 0.027200000000000001954 0.02999999999999999889" rpy="-1.570796326794896558 -1.570796326794896558 0" />
      <geometry>
        <mesh filename="package:///crank.stl" />
      </geometry>
    </collision>
    <inertial>
      <origin xyz="-6.95043608422764636e-17 0.015221680213895987313 -0.00095148915120264754026" rpy="0 0 0" />
      <mass value="0.0045332434126214744829" />
      <inertia ixx="2.0190313503504421684e-06" ixy="1.0863806619131201541e-23" ixz="-8.8530075403880418313e-26" iyy="3.8254267160843608508e-07" iyz="-9.1875323763545053031e-09" izz="2.3968139039834545946e-06" />
    </inertial>
  </link>
  <link name="toe_b_2/2">
    <visual>
      <origin xyz="-0.054171488011523771799 -0.043924303555988974956 -0.11999999999999999556" rpy="-1.57079632679489678 -1.570796326794896558 0" />
      <geometry>
        <mesh filename="package:///toe_b_2_2.stl" />
      </geometry>
      <material name="toe_b_2/2_material">
        <color rgba="0.64705882352941179736 0.64705882352941179736 0.64705882352941179736 1.0" />
      </material>
    </visual>
    <collision>
      <origin xyz="-0.054171488011523771799 -0.043924303555988974956 -0.11999999999999999556" rpy="-1.57079632679489678 -1.570796326794896558 0" />
      <geometry>
        <mesh filename="package:///toe_b_2_2.stl" />
      </geometry>
    </collision>
    <inertial>
      <origin xyz="5.3287317172169309455e-18 -2.7755575615628913511e-17 -0.059974999999999938083" rpy="0 0 0" />
      <mass value="0.0060293446207695345837" />
      <inertia ixx="7.2533028348991961836e-06" ixy="7.7428992113222343634e-23" ixz="2.3977556201737357245e-23" iyy="7.2533028348991911014e-06" iyz="-5.4414295269397458357e-22" izz="4.8234756966146826196e-08" />
    </inertial>
  </link>
  <link name="closedloop2_A">
    <inertial>
      <origin xyz="0 0 0" rpy="0 0 0" />
      <mass value="1e-9" />
      <inertia ixx="0" ixy="0" ixz="0" iyy="0" iyz="0" izz="0" />
    </inertial>
  </link>
  <joint name="closedloop2_A_frame" type="fixed">
    <origin xyz="0 0 -0.11994999999999994555" rpy="1.7235773343990823765e-16 -3.2166375860020982159e-18 -9.2330428060222376469e-17" />
    <parent link="toe_b_2/2" />
    <child link="closedloop2_A" />
    <axis xyz="0 0 0" />
  </joint>
  <joint name="motor_shin1" type="revolute">
    <origin xyz="-0.088800000000000073319 -0.026113982377658606637 0.02999999999999999889" rpy="-3.141592653589793116 3.3674348063693462321e-18 0.085487820950950324517" />
    <parent link="tarsus" />
    <child link="crank" />
    <axis xyz="0 0 1" />
    <limit effort="1" velocity="20" />
    <joint_properties friction="0.0" />
  </joint>
  <link name="crank_2">
    <visual>
      <origin xyz="0.088799999999999990052 0.027200000000000001954 0.02999999999999999889" rpy="-1.57079632679489678 -1.570796326794896558 0" />
      <geometry>
        <mesh filename="package:///crank.stl" />
      </geometry>
      <material name="crank_material">
        <color rgba="0.64705882352941179736 0.64705882352941179736 0.64705882352941179736 1.0" />
      </material>
    </visual>
    <collision>
      <origin xyz="0.088799999999999990052 0.027200000000000001954 0.02999999999999999889" rpy="-1.57079632679489678 -1.570796326794896558 0" />
      <geometry>
        <mesh filename="package:///crank.stl" />
      </geometry>
    </collision>
    <inertial>
      <origin xyz="-4.0890722795718946873e-17 0.015221680213895995987 -0.00095148915120264754026" rpy="0 0 0" />
      <mass value="0.0045332434126214744829" />
      <inertia ixx="2.0190313503504421684e-06" ixy="-2.2418276526623355094e-22" ixz="5.6961534948581010668e-25" iyy="3.8254267160843608508e-07" iyz="-9.1875323763545053031e-09" izz="2.3968139039834545946e-06" />
    </inertial>
  </link>
  <link name="toe_b_2/2_2">
    <visual>
      <origin xyz="-0.054171488011523771799 -0.043924303555988974956 -0.11999999999999994005" rpy="-1.570796326794896558 -1.570796326794896558 0" />
      <geometry>
        <mesh filename="package:///toe_b_2_2.stl" />
      </geometry>
      <material name="toe_b_2/2_material">
        <color rgba="0.64705882352941179736 0.64705882352941179736 0.64705882352941179736 1.0" />
      </material>
    </visual>
    <collision>
      <origin xyz="-0.054171488011523771799 -0.043924303555988974956 -0.11999999999999994005" rpy="-1.570796326794896558 -1.570796326794896558 0" />
      <geometry>
        <mesh filename="package:///toe_b_2_2.stl" />
      </geometry>
    </collision>
    <inertial>
      <origin xyz="6.7800497435559132421e-18 -2.7755575615628913511e-17 -0.059974999999999868694" rpy="0 0 0" />
      <mass value="0.0060293446207695345837" />
      <inertia ixx="7.2533028348991978777e-06" ixy="3.4661133647742148462e-24" ixz="9.1340561609002552721e-23" iyy="7.2533028348991877133e-06" iyz="-3.0568852247366612531e-22" izz="4.8234756966146826196e-08" />
    </inertial>
  </link>
  <link name="closedloop3_A">
    <inertial>
      <origin xyz="0 0 0" rpy="0 0 0" />
      <mass value="1e-9" />
      <inertia ixx="0" ixy="0" ixz="0" iyy="0" iyz="0" izz="0" />
    </inertial>
  </link>
  <joint name="closedloop3_A_frame" type="fixed">
    <origin xyz="-2.7755575615628913511e-17 0 -0.11994999999999972351" rpy="2.4425794194715678642e-16 -1.2567090974513322893e-17 9.4104185549181988163e-18" />
    <parent link="toe_b_2/2_2" />
    <child link="closedloop3_A" />
    <axis xyz="0 0 0" />
  </joint>
  <joint name="motor_shin2" type="revolute">
    <origin xyz="-0.088800000000000017808 -0.02611398237765871766 -0.02999999999999999889" rpy="-7.5875284351392275809e-17 -8.5523186607038729703e-18 -3.0649221372054666901" />
    <parent link="tarsus" />
    <child link="crank_2" />
    <axis xyz="0 0 1" />
    <limit effort="1" velocity="20" />
    <joint_properties friction="0.0" />
  </joint>
  <link name="toe_a_1/2">
    <visual>
      <origin xyz="0.056794565202878989629 -0.040773406646044479951 4.9999999999883470991e-05" rpy="-1.570796326794896558 -1.570796326794896558 0" />
      <geometry>
        <mesh filename="package:///toe_a_1_2.stl" />
      </geometry>
      <material name="toe_a_1/2_material">
        <color rgba="0.61568627450980395466 0.81176470588235294379 0.92941176470588238168 1.0" />
      </material>
    </visual>
    <collision>
      <origin xyz="0.056794565202878989629 -0.040773406646044479951 4.9999999999883470991e-05" rpy="-1.570796326794896558 -1.570796326794896558 0" />
      <geometry>
        <mesh filename="package:///toe_a_1_2.stl" />
      </geometry>
    </collision>
    <inertial>
      <origin xyz="-1.1592354093169458138e-17 -2.0816681711721685133e-17 -0.099975000000000063816" rpy="0 0 0" />
      <mass value="0.015704036277131967758" />
      <inertia ixx="5.241876769505099447e-05" ixy="-2.7645120639820579465e-21" ixz="-2.3687548558444086484e-22" iyy="5.2418767695050967365e-05" iyz="1.5504119990154681007e-22" izz="1.9630045346413520373e-07" />
    </inertial>
  </link>
  <link name="closedloop1_B">
    <inertial>
      <origin xyz="0 0 0" rpy="0 0 0" />
      <mass value="1e-9" />
      <inertia ixx="0" ixy="0" ixz="0" iyy="0" iyz="0" izz="0" />
    </inertial>
  </link>
  <joint name="closedloop1_B_frame" type="fixed">
    <origin xyz="-4.1633363423443370266e-17 -8.3266726846886740532e-17 -0.19995000000000001661" rpy="3.141592653589793116 -4.3598202726084071025e-18 3.141592653589793116" />
    <parent link="toe_a_1/2" />
    <child link="closedloop1_B" />
    <axis xyz="0 0 0" />
  </joint>
  <joint name="free_knee" type="revolute">
    <origin xyz="0.39567486363081366685 0.053875166733171879485 -0.025000000000000008327" rpy="3.141592653589793116 1.7052319612022700791e-18 -1.6910768536229012771" />
    <parent link="shin" />
    <child link="tarsus" />
    <axis xyz="0 0 1" />
    <limit effort="1" velocity="20" />
    <joint_properties friction="0.0" />
  </joint>
  <joint name="motor_knee" type="revolute">
    <origin xyz="-0.11999999999999998168 0 0" rpy="3.141592653589793116 1.6137487424794804186e-16 -2.6828651102102365478" />
    <parent link="hip_z" />
    <child link="shin" />
    <axis xyz="0 0 1" />
    <limit effort="1" velocity="20" />
    <joint_properties friction="0.0" />
  </joint>
  <joint name="motor_hip_y" type="revolute">
    <origin xyz="-0.025999999999999995337 -2.7755575615628913511e-17 -0.054400000000000010847" rpy="-1.570796326794896336 -1.1931918349460142181 -1.570796326794896558" />
    <parent link="hip_x" />
    <child link="hip_z" />
    <axis xyz="0 0 1" />
    <limit effort="1" velocity="20" />
    <joint_properties friction="0.0" />
  </joint>
  <link name="toe_a_2/2">
    <visual>
      <origin xyz="0.056794565202878989629 -0.040773406646044459134 -0.20000000000000006661" rpy="-1.570796326794896558 -1.570796326794896558 0" />
      <geometry>
        <mesh filename="package:///toe_a_2_2.stl" />
      </geometry>
      <material name="toe_a_2/2_material">
        <color rgba="0.61568627450980395466 0.81176470588235294379 0.92941176470588238168 1.0" />
      </material>
    </visual>
    <collision>
      <origin xyz="0.056794565202878989629 -0.040773406646044459134 -0.20000000000000006661" rpy="-1.570796326794896558 -1.570796326794896558 0" />
      <geometry>
        <mesh filename="package:///toe_a_2_2.stl" />
      </geometry>
    </collision>
    <inertial>
      <origin xyz="-6.9388939039072299184e-18 -6.9388939039072283776e-18 -0.099974999999999994427" rpy="0 0 0" />
      <mass value="0.015704036277131950411" />
      <inertia ixx="5.2418767695050838616e-05" ixy="-6.3359323996596978598e-37" ixz="2.5455800733206132009e-35" iyy="5.2418767695050825063e-05" iyz="-1.5040958649228347148e-36" izz="1.9630045346413507138e-07" />
    </inertial>
  </link>
  <link name="closedloop1_A">
    <inertial>
      <origin xyz="0 0 0" rpy="0 0 0" />
      <mass value="1e-9" />
      <inertia ixx="0" ixy="0" ixz="0" iyy="0" iyz="0" izz="0" />
    </inertial>
  </link>
  <joint name="closedloop1_A_frame" type="fixed">
    <origin xyz="8.3266726846886740532e-17 -6.9388939039072283776e-18 -0.19994999999999990559" rpy="-3.7112781480334543363e-16 -7.6145285777054681417e-31 -1.2325951642497940378e-32" />
    <parent link="toe_a_2/2" />
    <child link="closedloop1_A" />
    <axis xyz="0 0 0" />
  </joint>
  <joint name="motor_hip_z" type="revolute">
    <origin xyz="0.05266579297345658911 1.3877787807814456755e-17 -0.035199999999999995182" rpy="-1.57079632679489678 1.1102230246014436281e-16 1.570796326794896558" />
    <parent link="hip_y" />
    <child link="hip_x" />
    <axis xyz="0 0 1" />
    <limit effort="1" velocity="20" />
    <joint_properties friction="0.0" />
  </joint>
  <joint name="motor_hip_x" type="revolute">
    <origin xyz="-0.02999999999999999889 -0.072799999999999975842 0.059867854479678822566" rpy="1.0689153541114032999e-25 1.570796326794896558 0" />
    <parent link="torso" />
    <child link="hip_y" />
    <axis xyz="0 0 1" />
    <limit effort="1" velocity="20" />
    <joint_properties friction="0.0" />
  </joint>
  <link name="hip_y_2">
    <visual>
      <origin xyz="0.10440000000000002056 0 -0.035199999999999995182" rpy="-1.570796326794896558 -0 0" />
      <geometry>
        <mesh filename="package:///hip_y.stl" />
      </geometry>
      <material name="hip_y_material">
        <color rgba="0.2313725490196078538 0.38039215686274507888 0.7058823529411765163 1.0" />
      </material>
    </visual>
    <collision>
      <origin xyz="0.10440000000000002056 0 -0.035199999999999995182" rpy="-1.570796326794896558 -0 0" />
      <geometry>
        <mesh filename="package:///hip_y.stl" />
      </geometry>
    </collision>
    <inertial>
      <origin xyz="0.012912873314738379515 -1.2357431137270427259e-07 -0.034149457045324432825" rpy="0 0 0" />
      <mass value="1.2895238899898622265" />
      <inertia ixx="0.00089621011138626548598" ixy="-1.7957438648418447173e-09" ixz="3.2112420914059147952e-05" iyy="0.0010420724953831758935" iyz="3.0492496474583042268e-09" izz="0.0010213484696825509291" />
    </inertial>
  </link>
  <link name="hip_x_2">
    <visual>
      <origin xyz="-0.0031172266567815881677 0 -0.054400000000000003908" rpy="1.570796326794896558 1.570796326794896558 0" />
      <geometry>
        <mesh filename="package:///hip_x.stl" />
      </geometry>
      <material name="hip_x_material">
        <color rgba="0.64705882352941179736 0.64705882352941179736 0.64705882352941179736 1.0" />
      </material>
    </visual>
    <collision>
      <origin xyz="-0.0031172266567815881677 0 -0.054400000000000003908" rpy="1.570796326794896558 1.570796326794896558 0" />
      <geometry>
        <mesh filename="package:///hip_x.stl" />
      </geometry>
    </collision>
    <inertial>
      <origin xyz="-0.00077940900319458132281 -8.6641550262918375523e-19 -0.045216753463575065641" rpy="0 0 0" />
      <mass value="1.4197410037164888141" />
      <inertia ixx="0.0014949229305128528423" ixy="0" ixz="-1.2476184392984380401e-05" iyy="0.0013017541081209299796" iyz="0" izz="0.00094724669336309881909" />
    </inertial>
  </link>
  <link name="hip_z_2">
    <visual>
      <origin xyz="0 0 -0.070000000000000006661" rpy="-1.570796326794896558 -0 -3.6217972674632358542e-17" />
      <geometry>
        <mesh filename="package:///hip_z.stl" />
      </geometry>
      <material name="hip_z_material">
        <color rgba="0.61568627450980395466 0.81176470588235294379 0.92941176470588238168 1.0" />
      </material>
    </visual>
    <collision>
      <origin xyz="0 0 -0.070000000000000006661" rpy="-1.570796326794896558 -0 -3.6217972674632358542e-17" />
      <geometry>
        <mesh filename="package:///hip_z.stl" />
      </geometry>
    </collision>
    <inertial>
      <origin xyz="0.059999999999999990841 -1.7372056755744257965e-18 -0.021999999999999998723" rpy="0 0 0" />
      <mass value="3.893275615304738313" />
      <inertia ixx="0.0040205863361596509351" ixy="5.1429225604894204844e-19" ixz="0" iyy="0.014779167671256707509" iyz="0" izz="0.017543523742211363653" />
    </inertial>
  </link>
  <link name="shin_2">
    <visual>
      <origin xyz="0 -6.9388939039072283776e-18 -0.024999999999999994449" rpy="1.570796326794896558 -0 6.0456418469048474632e-17" />
      <geometry>
        <mesh filename="package:///shin.stl" />
      </geometry>
      <material name="shin_material">
        <color rgba="0.61568627450980395466 0.81176470588235294379 0.92941176470588238168 1.0" />
      </material>
    </visual>
    <collision>
      <origin xyz="0 -6.9388939039072283776e-18 -0.024999999999999994449" rpy="1.570796326794896558 -0 6.0456418469048474632e-17" />
      <geometry>
        <mesh filename="package:///shin.stl" />
      </geometry>
    </collision>
    <inertial>
      <origin xyz="0.086542930154570346657 -0.024349627108824732635 -0.024999999175739785751" rpy="0 0 0" />
      <mass value="0.55578140933316355632" />
      <inertia ixx="0.00046644066811272691256" ixy="0.00088329043391741578727" ixz="-6.3639809445707160931e-13" iyy="0.009055909587116245385" iyz="1.1189385759788385046e-11" izz="0.0093490826129847756643" />
    </inertial>
  </link>
  <link name="tarsus_2">
    <visual>
      <origin xyz="1.3877787807814456755e-17 0.0010860176223413953167 0" rpy="-1.570796326794896558 -1.570796326794896558 0" />
      <geometry>
        <mesh filename="package:///tarsus.stl" />
      </geometry>
      <material name="tarsus_material">
        <color rgba="0.61568627450980395466 0.81176470588235294379 0.92941176470588238168 1.0" />
      </material>
    </visual>
    <collision>
      <origin xyz="1.3877787807814456755e-17 0.0010860176223413953167 0" rpy="-1.570796326794896558 -1.570796326794896558 0" />
      <geometry>
        <mesh filename="package:///tarsus.stl" />
      </geometry>
    </collision>
    <visual>
      <origin xyz="-0.061600000000000057487 -0.11491398237765870771 0" rpy="-3.141592653589793116 -1.570796326794896558 0" />
      <geometry>
        <mesh filename="package:///actuator_molet.stl" />
      </geometry>
      <material name="actuator_molet_material">
        <color rgba="0.91764705882352937127 0.91764705882352937127 0.91764705882352937127 1.0" />
      </material>
    </visual>
    <collision>
      <origin xyz="-0.061600000000000057487 -0.11491398237765870771 0" rpy="-3.141592653589793116 -1.570796326794896558 0" />
      <geometry>
        <mesh filename="package:///actuator_molet.stl" />
      </geometry>
    </collision>
    <inertial>
      <origin xyz="-0.083086291902174744251 -0.020033778925019920386 2.8736095531656611363e-08" rpy="0 0 0" />
      <mass value="0.74284619422086228813" />
      <inertia ixx="0.00039818835112512165723" ixy="-0.00054213231673500028064" ixz="-5.2637644310029284865e-10" iyy="0.0079851917842740996467" iyz="1.2685116132103344685e-10" izz="0.0079848716361182493773" />
    </inertial>
  </link>
  <link name="foot_roll_2">
    <visual>
      <origin xyz="0.325998400000000077 0.039743999999999890527 1.249000902703301108e-16" rpy="-1.570796326794896558 -1.570796326794896336 0" />
      <geometry>
        <mesh filename="package:///foot_roll.stl" />
      </geometry>
      <material name="foot_roll_material">
        <color rgba="0.2313725490196078538 0.38039215686274507888 0.7058823529411765163 1.0" />
      </material>
    </visual>
    <collision>
      <origin xyz="0.325998400000000077 0.039743999999999890527 1.249000902703301108e-16" rpy="-1.570796326794896558 -1.570796326794896336 0" />
      <geometry>
        <mesh filename="package:///foot_roll.stl" />
      </geometry>
    </collision>
    <inertial>
      <origin xyz="-2.1851523803977209919e-08 -0.0014449033387293822028 6.7774346909967706705e-09" rpy="0 0 0" />
      <mass value="0.0027067106871796996204" />
      <inertia ixx="1.8232396912107804468e-07" ixy="1.2456494871913400136e-13" ixz="-3.0177862000950179661e-13" iyy="1.1958745424438052282e-07" iyz="4.5807687216462860478e-14" izz="1.0944659228682656112e-07" />
    </inertial>
  </link>
  <link name="foot_part_2">
    <visual>
      <origin xyz="-0.0011288304490431055882 -1.3877787807814456755e-17 0.0090799999999999769784" rpy="-1.570796326794896558 -1.253981591208055539e-17 9.5956049968737077813e-34" />
      <geometry>
        <mesh filename="package:///foot_part.stl" />
      </geometry>
      <material name="foot_part_material">
        <color rgba="0.61568627450980395466 0.81176470588235294379 0.92941176470588238168 1.0" />
      </material>
    </visual>
    <collision>
      <origin xyz="-0.0011288304490431055882 -1.3877787807814456755e-17 0.0090799999999999769784" rpy="-1.570796326794896558 -1.253981591208055539e-17 9.5956049968737077813e-34" />
      <geometry>
        <mesh filename="package:///foot_part.stl" />
      </geometry>
    </collision>
    <inertial>
      <origin xyz="-0.042296631354857269769 6.7228490665975414382e-10 0.0063626481723337733817" rpy="0 0 0" />
      <mass value="0.33095167420253657209" />
      <inertia ixx="0.0010118322945958282532" ixy="-2.5339652298730971138e-12" ixz="0.00049446274168876605103" iyy="0.001227680104999263281" iyz="7.2849212776777399016e-12" izz="0.00051045333461432877177" />
    </inertial>
  </link>
  <link name="foot_left">
    <inertial>
      <origin xyz="0 0 0" rpy="0 0 0" />
      <mass value="1e-9" />
      <inertia ixx="0" ixy="0" ixz="0" iyy="0" iyz="0" izz="0" />
    </inertial>
  </link>
  <joint name="foot_left_frame" type="fixed">
    <origin xyz="-0.055897619600577430621 0 0.0037840702321054742185" rpy="-2.0029632011476419211e-16 -1.0420837364882549192 -3.141592653589793116" />
    <parent link="foot_part_2" />
    <child link="foot_left" />
    <axis xyz="0 0 0" />
  </joint>
  <link name="toe_b_1/2_3">
    <visual>
      <origin xyz="-0.054171488011523778738 0.043924303555988974956 -0.11999999999999999556" rpy="1.570796326794896558 1.570796326794896558 0" />
      <geometry>
        <mesh filename="package:///toe_b_1_2.stl" />
      </geometry>
      <material name="toe_b_1/2_material">
        <color rgba="0.64705882352941179736 0.64705882352941179736 0.64705882352941179736 1.0" />
      </material>
    </visual>
    <collision>
      <origin xyz="-0.054171488011523778738 0.043924303555988974956 -0.11999999999999999556" rpy="1.570796326794896558 1.570796326794896558 0" />
      <geometry>
        <mesh filename="package:///toe_b_1_2.stl" />
      </geometry>
    </collision>
    <inertial>
      <origin xyz="6.9388939039072276073e-18 3.4694469519536141888e-17 -0.059975000000000042166" rpy="0 0 0" />
      <mass value="0.0060293446207695467268" />
      <inertia ixx="7.2533028348992199005e-06" ixy="-6.5986121973754776589e-37" ixz="2.9997503754211440851e-37" iyy="7.2533028348992105832e-06" iyz="-3.217685428198045049e-22" izz="4.8234756966146925458e-08" />
    </inertial>
  </link>
  <link name="closedloop4_A">
    <inertial>
      <origin xyz="0 0 0" rpy="0 0 0" />
      <mass value="1e-9" />
      <inertia ixx="0" ixy="0" ixz="0" iyy="0" iyz="0" izz="0" />
    </inertial>
  </link>
  <joint name="closedloop4_A_frame" type="fixed">
    <origin xyz="0 -1.1102230246251565404e-16 -0.11995000000000000107" rpy="-3.1415926535897926719 1.4557857793770605109e-15 1.570796326794896558" />
    <parent link="toe_b_1/2_3" />
    <child link="closedloop4_A" />
    <axis xyz="0 0 0" />
  </joint>
  <link name="toe_b_2/2_3">
    <visual>
      <origin xyz="-0.054171488011523771799 0.043924303555988974956 5.0000000000105515596e-05" rpy="1.570796326794896558 1.570796326794896558 0" />
      <geometry>
        <mesh filename="package:///toe_b_2_2.stl" />
      </geometry>
      <material name="toe_b_2/2_material">
        <color rgba="0.64705882352941179736 0.64705882352941179736 0.64705882352941179736 1.0" />
      </material>
    </visual>
    <collision>
      <origin xyz="-0.054171488011523771799 0.043924303555988974956 5.0000000000105515596e-05" rpy="1.570796326794896558 1.570796326794896558 0" />
      <geometry>
        <mesh filename="package:///toe_b_2_2.stl" />
      </geometry>
    </collision>
    <inertial>
      <origin xyz="6.9388939039072299184e-18 2.0816681711721685133e-17 -0.0599749999999999589" rpy="0 0 0" />
      <mass value="0.0060293446207695345837" />
      <inertia ixx="7.2533028348991978777e-06" ixy="-8.3866893974319306484e-37" ixz="6.575904775534079715e-37" iyy="7.2533028348991877133e-06" iyz="-3.2176854281980351748e-22" izz="4.8234756966146826196e-08" />
    </inertial>
  </link>
  <link name="closedloop5_A">
    <inertial>
      <origin xyz="0 0 0" rpy="0 0 0" />
      <mass value="1e-9" />
      <inertia ixx="0" ixy="0" ixz="0" iyy="0" iyz="0" izz="0" />
    </inertial>
  </link>
  <joint name="closedloop5_A_frame" type="fixed">
    <origin xyz="0 1.1102230246251565404e-16 -0.11994999999999977902" rpy="-3.1415926535897926719 1.4557857793770605109e-15 1.570796326794896558" />
    <parent link="toe_b_2/2_3" />
    <child link="closedloop5_A" />
    <axis xyz="0 0 0" />
  </joint>
  <joint name="free_foot2_left" type="revolute">
    <origin xyz="1.1102230246251565404e-16 0.0090000000000000079936 -8.3266726846886740532e-17" rpy="-1.570796326794896558 7.3354943207976340417e-16 -3.141592653589793116" />
    <parent link="foot_roll_2" />
    <child link="foot_part_2" />
    <axis xyz="0 0 1" />
    <limit effort="1" velocity="20" />
    <joint_properties friction="0.0" />
  </joint>
  <joint name="free_foot1_left" type="revolute">
    <origin xyz="-0.325998400000000077 -0.038657982377658717255 -5.5511151231257827021e-17" rpy="5.5511151231257814695e-17 2.7597873481449337343e-16 -3.1415926535897624738" />
    <parent link="tarsus_2" />
    <child link="foot_roll_2" />
    <axis xyz="0 0 1" />
    <limit effort="1" velocity="20" />
    <joint_properties friction="0.0" />
  </joint>
  <link name="crank_3">
    <visual>
      <origin xyz="0.088799999999999990052 0.027200000000000001954 0.02999999999999999889" rpy="-1.570796326794896558 -1.570796326794896558 0" />
      <geometry>
        <mesh filename="package:///crank.stl" />
      </geometry>
      <material name="crank_material">
        <color rgba="0.64705882352941179736 0.64705882352941179736 0.64705882352941179736 1.0" />
      </material>
    </visual>
    <collision>
      <origin xyz="0.088799999999999990052 0.027200000000000001954 0.02999999999999999889" rpy="-1.570796326794896558 -1.570796326794896558 0" />
      <geometry>
        <mesh filename="package:///crank.stl" />
      </geometry>
    </collision>
    <inertial>
      <origin xyz="-4.1591130659041493929e-17 0.015221680213895983844 -0.00095148915120264754026" rpy="0 0 0" />
      <mass value="0.0045332434126214744829" />
      <inertia ixx="2.0190313503504421684e-06" ixy="6.7402656531618112296e-23" ixz="3.2393098298753812272e-26" iyy="3.825426716084359792e-07" iyz="-9.1875323763545036488e-09" izz="2.3968139039834545946e-06" />
    </inertial>
  </link>
  <link name="toe_b_2/2_4">
    <visual>
      <origin xyz="-0.054171488011523827311 0.043924303555988961079 5.0000000000105515596e-05" rpy="1.570796326794896558 1.570796326794896558 0" />
      <geometry>
        <mesh filename="package:///toe_b_2_2.stl" />
      </geometry>
      <material name="toe_b_2/2_material">
        <color rgba="0.64705882352941179736 0.64705882352941179736 0.64705882352941179736 1.0" />
      </material>
    </visual>
    <collision>
      <origin xyz="-0.054171488011523827311 0.043924303555988961079 5.0000000000105515596e-05" rpy="1.570796326794896558 1.570796326794896558 0" />
      <geometry>
        <mesh filename="package:///toe_b_2_2.stl" />
      </geometry>
    </collision>
    <inertial>
      <origin xyz="-5.7792268147074716097e-17 6.9388939039072283776e-18 -0.0599749999999999589" rpy="0 0 0" />
      <mass value="0.0060293446207695345837" />
      <inertia ixx="7.2533028348991978777e-06" ixy="1.0798552882945252195e-34" ixz="2.9748227916399741654e-22" iyy="7.2533028348991877133e-06" iyz="-4.4111929785268494234e-22" izz="4.8234756966146826196e-08" />
    </inertial>
  </link>
  <link name="closedloop4_B">
    <inertial>
      <origin xyz="0 0 0" rpy="0 0 0" />
      <mass value="1e-9" />
      <inertia ixx="0" ixy="0" ixz="0" iyy="0" iyz="0" izz="0" />
    </inertial>
  </link>
  <joint name="closedloop4_B_frame" type="fixed">
    <origin xyz="0 -2.7755575615628913511e-17 -0.11994999999999983453" rpy="2.5132107670464821188e-16 -1.5516628120086465861e-16 -7.8371506725709791247e-17" />
    <parent link="toe_b_2/2_4" />
    <child link="closedloop4_B" />
    <axis xyz="0 0 0" />
  </joint>
  <joint name="motor_shin1_left" type="revolute">
    <origin xyz="-0.088800000000002418665 -0.026113982377657718459 0.02999999999999999889" rpy="3.141592653589793116 -0 -1.1936089721976891145e-17" />
    <parent link="tarsus_2" />
    <child link="crank_3" />
    <axis xyz="0 0 1" />
    <limit effort="1" velocity="20" />
    <joint_properties friction="0.0" />
  </joint>
  <link name="crank_4">
    <visual>
      <origin xyz="0.088800000000000045564 0.027200000000000001954 0.02999999999999999889" rpy="-1.57079632679489678 -1.570796326794896558 0" />
      <geometry>
        <mesh filename="package:///crank.stl" />
      </geometry>
      <material name="crank_material">
        <color rgba="0.64705882352941179736 0.64705882352941179736 0.64705882352941179736 1.0" />
      </material>
    </visual>
    <collision>
      <origin xyz="0.088800000000000045564 0.027200000000000001954 0.02999999999999999889" rpy="-1.57079632679489678 -1.570796326794896558 0" />
      <geometry>
        <mesh filename="package:///crank.stl" />
      </geometry>
    </collision>
    <inertial>
      <origin xyz="1.4145304685638640009e-17 0.015221680213895992517 -0.00095148915120264754026" rpy="0 0 0" />
      <mass value="0.0045332434126214744829" />
      <inertia ixx="2.0190313503504421684e-06" ixy="-1.3716314016687034688e-22" ixz="2.0518904321472194748e-25" iyy="3.8254267160843608508e-07" iyz="-9.1875323763545053031e-09" izz="2.3968139039834545946e-06" />
    </inertial>
  </link>
  <link name="toe_b_1/2_4">
    <visual>
      <origin xyz="-0.054171488011523827311 0.043924303555988947201 -0.1199999999999999678" rpy="1.570796326794896558 1.570796326794896558 0" />
      <geometry>
        <mesh filename="package:///toe_b_1_2.stl" />
      </geometry>
      <material name="toe_b_1/2_material">
        <color rgba="0.64705882352941179736 0.64705882352941179736 0.64705882352941179736 1.0" />
      </material>
    </visual>
    <collision>
      <origin xyz="-0.054171488011523827311 0.043924303555988947201 -0.1199999999999999678" rpy="1.570796326794896558 1.570796326794896558 0" />
      <geometry>
        <mesh filename="package:///toe_b_1_2.stl" />
      </geometry>
    </collision>
    <inertial>
      <origin xyz="-3.7825359619280775841e-17 0 -0.059975000000000014411" rpy="0 0 0" />
      <mass value="0.0060293446207695467268" />
      <inertia ixx="7.2533028348992199005e-06" ixy="-3.66085727954482691e-38" ixz="-1.1433637232898348e-22" iyy="7.2533028348992105832e-06" iyz="-9.8307778635727617543e-41" izz="4.8234756966146912223e-08" />
    </inertial>
  </link>
  <link name="closedloop5_B">
    <inertial>
      <origin xyz="0 0 0" rpy="0 0 0" />
      <mass value="1e-9" />
      <inertia ixx="0" ixy="0" ixz="0" iyy="0" iyz="0" izz="0" />
    </inertial>
  </link>
  <joint name="closedloop5_B_frame" type="fixed">
    <origin xyz="-3.3306690738754696213e-16 0 -0.1199499999999999178" rpy="1.3570894085680469023e-16 1.1131720658713263778e-15 -3.141592653589793116" />
    <parent link="toe_b_1/2_4" />
    <child link="closedloop5_B" />
    <axis xyz="0 0 0" />
  </joint>
  <joint name="motor_shin2_left" type="revolute">
    <origin xyz="-0.08880000000000000393 -0.026113982377658606637 -0.029999999999999978073" rpy="-2.4214412524677942898e-16 -8.9555256306153669199e-17 3.141592653589793116" />
    <parent link="tarsus_2" />
    <child link="crank_4" />
    <axis xyz="0 0 1" />
    <limit effort="1" velocity="20" />
    <joint_properties friction="0.0" />
  </joint>
  <link name="toe_a_1/2_2">
    <visual>
      <origin xyz="0.056794565202879024324 0.040773406646044459134 -0.19999999999999995559" rpy="1.570796326794896558 1.570796326794896558 0" />
      <geometry>
        <mesh filename="package:///toe_a_1_2.stl" />
      </geometry>
      <material name="toe_a_1/2_material">
        <color rgba="0.61568627450980395466 0.81176470588235294379 0.92941176470588238168 1.0" />
      </material>
    </visual>
    <collision>
      <origin xyz="0.056794565202879024324 0.040773406646044459134 -0.19999999999999995559" rpy="1.570796326794896558 1.570796326794896558 0" />
      <geometry>
        <mesh filename="package:///toe_a_1_2.stl" />
      </geometry>
    </collision>
    <inertial>
      <origin xyz="1.5636775695836450254e-17 -6.9388939039072283776e-18 -0.099974999999999966671" rpy="0 0 0" />
      <mass value="0.015704036277131967758" />
      <inertia ixx="5.2418767695050980918e-05" ixy="-2.0997297292780270681e-37" ixz="5.3594272756806182536e-21" iyy="5.2418767695050980918e-05" iyz="-1.3098890123765843119e-37" izz="1.9630045346413536255e-07" />
    </inertial>
  </link>
  <link name="closedloop6_A">
    <inertial>
      <origin xyz="0 0 0" rpy="0 0 0" />
      <mass value="1e-9" />
      <inertia ixx="0" ixy="0" ixz="0" iyy="0" iyz="0" izz="0" />
    </inertial>
  </link>
  <joint name="closedloop6_A_frame" type="fixed">
    <origin xyz="6.5919492087118669588e-17 0 -0.19995000000000007212" rpy="-3.141592653589793116 -7.0048445437832687964e-17 -2.6752620058038898353e-33" />
    <parent link="toe_a_1/2_2" />
    <child link="closedloop6_A" />
    <axis xyz="0 0 0" />
  </joint>
  <joint name="free_knee_left" type="revolute">
    <origin xyz="0.39567486363081372236 -0.053875166733171747646 -0.024999999999999994449" rpy="0 -0 1.570796326794896558" />
    <parent link="shin_2" />
    <child link="tarsus_2" />
    <axis xyz="0 0 1" />
    <limit effort="1" velocity="20" />
    <joint_properties friction="0.0" />
  </joint>
  <joint name="motor_knee_left" type="revolute">
    <origin xyz="0.1199999999999999678 0 1.6930901125533637241e-15" rpy="3.141592653589793116 -0 -0.55703373375772102793" />
    <parent link="hip_z_2" />
    <child link="shin_2" />
    <axis xyz="0 0 1" />
    <limit effort="1" velocity="20" />
    <joint_properties friction="0.0" />
  </joint>
  <joint name="motor_hip_y_left" type="revolute">
    <origin xyz="-0.029117226656781597383 0 -0.047379470518249228173" rpy="-1.570796326794896558 1.2655169802117200994 -1.570796326794896558" />
    <parent link="hip_x_2" />
    <child link="hip_z_2" />
    <axis xyz="0 0 1" />
    <limit effort="1" velocity="20" />
    <joint_properties friction="0.0" />
  </joint>
  <link name="toe_a_2/2_2">
    <visual>
      <origin xyz="0.056794565202879003507 0.040773406646044445256 5.0000000000133271172e-05" rpy="1.570796326794896558 1.570796326794896558 0" />
      <geometry>
        <mesh filename="package:///toe_a_2_2.stl" />
      </geometry>
      <material name="toe_a_2/2_material">
        <color rgba="0.61568627450980395466 0.81176470588235294379 0.92941176470588238168 1.0" />
      </material>
    </visual>
    <collision>
      <origin xyz="0.056794565202879003507 0.040773406646044445256 5.0000000000133271172e-05" rpy="1.570796326794896558 1.570796326794896558 0" />
      <geometry>
        <mesh filename="package:///toe_a_2_2.stl" />
      </geometry>
    </collision>
    <inertial>
      <origin xyz="6.9388939039072283776e-18 -1.3877787807814456755e-17 -0.099974999999999938916" rpy="0 0 0" />
      <mass value="0.015704036277131950411" />
      <inertia ixx="5.2418767695050838616e-05" ixy="0" ixz="0" iyy="5.2418767695050825063e-05" iyz="-3.1972408633164225501e-21" izz="1.9630045346413507138e-07" />
    </inertial>
  </link>
  <link name="closedloop6_B">
    <inertial>
      <origin xyz="0 0 0" rpy="0 0 0" />
      <mass value="1e-9" />
      <inertia ixx="0" ixy="0" ixz="0" iyy="0" iyz="0" izz="0" />
    </inertial>
  </link>
  <joint name="closedloop6_B_frame" type="fixed">
    <origin xyz="6.9388939039072283776e-18 -2.0816681711721685133e-17 -0.19994999999999985008" rpy="-6.1223473960463149353e-17 2.4651903288156618919e-32 9.6553912330110834249e-33" />
    <parent link="toe_a_2/2_2" />
    <child link="closedloop6_B" />
    <axis xyz="0 0 0" />
  </joint>
  <joint name="motor_hip_z_left" type="revolute">
    <origin xyz="0.050000000000000016653 0 -0.035199999999999981304" rpy="1.570796326794896558 -0 -1.570796326794896558" />
    <parent link="hip_y_2" />
    <child link="hip_x_2" />
    <axis xyz="0 0 1" />
    <limit effort="1" velocity="20" />
    <joint_properties friction="0.0" />
  </joint>
  <joint name="motor_hip_x_left" type="revolute">
    <origin xyz="-0.02999999999999999889 0.072800000000000031353 0.059867854479678822566" rpy="-0 1.570796326794896558 0" />
    <parent link="torso" />
    <child link="hip_y_2" />
    <axis xyz="0 0 1" />
    <limit effort="1" velocity="20" />
    <joint_properties friction="0.0" />
  </joint>
  <link name="foot_part_int1_1">
    <inertial>
      <mass value="0.0" />
      <inertia ixx="0.0" ixy="0.0" ixz="0.0" iyy="0.0" iyz="0.0" izz="0.0" />
    </inertial>
  </link>
  <link name="foot_part_int2_1">
    <inertial>
      <mass value="0.0" />
      <inertia ixx="0.0" ixy="0.0" ixz="0.0" iyy="0.0" iyz="0.0" izz="0.0" />
    </inertial>
  </link>
  <joint name="foot_part_toe_b_1/2_rev0" type="revolute">
    <origin xyz="-0.0091288304490431126936 -0.014275999999999927637 0.052813599999999960577" />
    <parent link="foot_part" />
    <child link="foot_part_int1_1" />
    <axis xyz="1 0 0" />
    <limit effort="1" velocity="20" />
  </joint>
  <joint name="foot_part_toe_b_1/2_rev1" type="revolute">
    <parent link="foot_part_int1_1" />
    <child link="foot_part_int2_1" />
    <axis xyz="0 1 0" />
    <limit effort="1" velocity="20" />
  </joint>
  <joint name="foot_part_toe_b_1/2_rev2" type="revolute">
    <parent link="foot_part_int2_1" />
    <child link="toe_b_1/2" />
    <axis xyz="0 0 1" />
    <limit effort="1" velocity="20" />
  </joint>
  <link name="foot_part_int1_2">
    <inertial>
      <mass value="0.0" />
      <inertia ixx="0.0" ixy="0.0" ixz="0.0" iyy="0.0" iyz="0.0" izz="0.0" />
    </inertial>
  </link>
  <link name="foot_part_int2_2">
    <inertial>
      <mass value="0.0" />
      <inertia ixx="0.0" ixy="0.0" ixz="0.0" iyy="0.0" iyz="0.0" izz="0.0" />
    </inertial>
  </link>
  <joint name="foot_part_toe_b_1/2_2_rev0" type="revolute">
    <origin xyz="-0.009128830449042890649 0.014276000000000017842 0.052813599999999794044" />
    <parent link="foot_part" />
    <child link="foot_part_int1_2" />
    <axis xyz="1 0 0" />
    <limit effort="1" velocity="20" />
  </joint>
  <joint name="foot_part_toe_b_1/2_2_rev1" type="revolute">
    <parent link="foot_part_int1_2" />
    <child link="foot_part_int2_2" />
    <axis xyz="0 1 0" />
    <limit effort="1" velocity="20" />
  </joint>
  <joint name="foot_part_toe_b_1/2_2_rev2" type="revolute">
    <parent link="foot_part_int2_2" />
    <child link="toe_b_1/2_2" />
    <axis xyz="0 0 1" />
    <limit effort="1" velocity="20" />
  </joint>
  <link name="crank_int1_3">
    <inertial>
      <mass value="0.0" />
      <inertia ixx="0.0" ixy="0.0" ixz="0.0" iyy="0.0" iyz="0.0" izz="0.0" />
    </inertial>
  </link>
  <link name="crank_int2_3">
    <inertial>
      <mass value="0.0" />
      <inertia ixx="0.0" ixy="0.0" ixz="0.0" iyy="0.0" iyz="0.0" izz="0.0" />
    </inertial>
  </link>
  <joint name="crank_toe_b_2/2_rev0" type="revolute">
    <origin xyz="5.5511151231257827021e-17 0.057000000000000050626 0.002499999999999967526" />
    <parent link="crank" />
    <child link="crank_int1_3" />
    <axis xyz="1 0 0" />
    <limit effort="1" velocity="20" />
  </joint>
  <joint name="crank_toe_b_2/2_rev1" type="revolute">
    <parent link="crank_int1_3" />
    <child link="crank_int2_3" />
    <axis xyz="0 1 0" />
    <limit effort="1" velocity="20" />
  </joint>
  <joint name="crank_toe_b_2/2_rev2" type="revolute">
    <parent link="crank_int2_3" />
    <child link="toe_b_2/2" />
    <axis xyz="0 0 1" />
    <limit effort="1" velocity="20" />
  </joint>
  <link name="crank_2_int1_4">
    <inertial>
      <mass value="0.0" />
      <inertia ixx="0.0" ixy="0.0" ixz="0.0" iyy="0.0" iyz="0.0" izz="0.0" />
    </inertial>
  </link>
  <link name="crank_2_int2_4">
    <inertial>
      <mass value="0.0" />
      <inertia ixx="0.0" ixy="0.0" ixz="0.0" iyy="0.0" iyz="0.0" izz="0.0" />
    </inertial>
  </link>
  <joint name="crank_2_toe_b_2/2_2_rev0" type="revolute">
    <origin xyz="5.5511151231257827021e-17 0.056999999999999939604 0.0024999999999999883427" />
    <parent link="crank_2" />
    <child link="crank_2_int1_4" />
    <axis xyz="1 0 0" />
    <limit effort="1" velocity="20" />
  </joint>
  <joint name="crank_2_toe_b_2/2_2_rev1" type="revolute">
    <parent link="crank_2_int1_4" />
    <child link="crank_2_int2_4" />
    <axis xyz="0 1 0" />
    <limit effort="1" velocity="20" />
  </joint>
  <joint name="crank_2_toe_b_2/2_2_rev2" type="revolute">
    <parent link="crank_2_int2_4" />
    <child link="toe_b_2/2_2" />
    <axis xyz="0 0 1" />
    <limit effort="1" velocity="20" />
  </joint>
  <link name="tarsus_int1_5">
    <inertial>
      <mass value="0.0" />
      <inertia ixx="0.0" ixy="0.0" ixz="0.0" iyy="0.0" iyz="0.0" izz="0.0" />
    </inertial>
  </link>
  <link name="tarsus_int2_5">
    <inertial>
      <mass value="0.0" />
      <inertia ixx="0.0" ixy="0.0" ixz="0.0" iyy="0.0" iyz="0.0" izz="0.0" />
    </inertial>
  </link>
  <joint name="tarsus_toe_a_1/2_rev0" type="revolute">
    <origin xyz="0.1141899349863703117 0.036206749731294562977 0" />
    <parent link="tarsus" />
    <child link="tarsus_int1_5" />
    <axis xyz="1 0 0" />
    <limit effort="1" velocity="20" />
  </joint>
  <joint name="tarsus_toe_a_1/2_rev1" type="revolute">
    <parent link="tarsus_int1_5" />
    <child link="tarsus_int2_5" />
    <axis xyz="0 1 0" />
    <limit effort="1" velocity="20" />
  </joint>
  <joint name="tarsus_toe_a_1/2_rev2" type="revolute">
    <parent link="tarsus_int2_5" />
    <child link="toe_a_1/2" />
    <axis xyz="0 0 1" />
    <limit effort="1" velocity="20" />
  </joint>
  <link name="hip_x_int1_6">
    <inertial>
      <mass value="0.0" />
      <inertia ixx="0.0" ixy="0.0" ixz="0.0" iyy="0.0" iyz="0.0" izz="0.0" />
    </inertial>
  </link>
  <link name="hip_x_int2_6">
    <inertial>
      <mass value="0.0" />
      <inertia ixx="0.0" ixy="0.0" ixz="0.0" iyy="0.0" iyz="0.0" izz="0.0" />
    </inertial>
  </link>
  <joint name="hip_x_toe_a_2/2_rev0" type="revolute">
    <origin xyz="0.033686000000000014543 -4.1633363423443370266e-17 -0.054400000000000017786" />
    <parent link="hip_x" />
    <child link="hip_x_int1_6" />
    <axis xyz="1 0 0" />
    <limit effort="1" velocity="20" />
  </joint>
  <joint name="hip_x_toe_a_2/2_rev1" type="revolute">
    <parent link="hip_x_int1_6" />
    <child link="hip_x_int2_6" />
    <axis xyz="0 1 0" />
    <limit effort="1" velocity="20" />
  </joint>
  <joint name="hip_x_toe_a_2/2_rev2" type="revolute">
    <parent link="hip_x_int2_6" />
    <child link="toe_a_2/2" />
    <axis xyz="0 0 1" />
    <limit effort="1" velocity="20" />
  </joint>
  <link name="foot_part_2_int1_7">
    <inertial>
      <mass value="0.0" />
      <inertia ixx="0.0" ixy="0.0" ixz="0.0" iyy="0.0" iyz="0.0" izz="0.0" />
    </inertial>
  </link>
  <link name="foot_part_2_int2_7">
    <inertial>
      <mass value="0.0" />
      <inertia ixx="0.0" ixy="0.0" ixz="0.0" iyy="0.0" iyz="0.0" izz="0.0" />
    </inertial>
  </link>
  <joint name="foot_part_2_toe_b_1/2_3_rev0" type="revolute">
    <origin xyz="-0.0091288304490432237159 -0.014276000000000010903 -0.034653600000000173154" />
    <parent link="foot_part_2" />
    <child link="foot_part_2_int1_7" />
    <axis xyz="1 0 0" />
    <limit effort="1" velocity="20" />
  </joint>
  <joint name="foot_part_2_toe_b_1/2_3_rev1" type="revolute">
    <parent link="foot_part_2_int1_7" />
    <child link="foot_part_2_int2_7" />
    <axis xyz="0 1 0" />
    <limit effort="1" velocity="20" />
  </joint>
  <joint name="foot_part_2_toe_b_1/2_3_rev2" type="revolute">
    <parent link="foot_part_2_int2_7" />
    <child link="toe_b_1/2_3" />
    <axis xyz="0 0 1" />
    <limit effort="1" velocity="20" />
  </joint>
  <link name="foot_part_2_int1_8">
    <inertial>
      <mass value="0.0" />
      <inertia ixx="0.0" ixy="0.0" ixz="0.0" iyy="0.0" iyz="0.0" izz="0.0" />
    </inertial>
  </link>
  <link name="foot_part_2_int2_8">
    <inertial>
      <mass value="0.0" />
      <inertia ixx="0.0" ixy="0.0" ixz="0.0" iyy="0.0" iyz="0.0" izz="0.0" />
    </inertial>
  </link>
  <joint name="foot_part_2_toe_b_2/2_3_rev0" type="revolute">
    <origin xyz="-0.0091288304490432237159 0.014275999999999927637 -0.034653600000000284176" />
    <parent link="foot_part_2" />
    <child link="foot_part_2_int1_8" />
    <axis xyz="1 0 0" />
    <limit effort="1" velocity="20" />
  </joint>
  <joint name="foot_part_2_toe_b_2/2_3_rev1" type="revolute">
    <parent link="foot_part_2_int1_8" />
    <child link="foot_part_2_int2_8" />
    <axis xyz="0 1 0" />
    <limit effort="1" velocity="20" />
  </joint>
  <joint name="foot_part_2_toe_b_2/2_3_rev2" type="revolute">
    <parent link="foot_part_2_int2_8" />
    <child link="toe_b_2/2_3" />
    <axis xyz="0 0 1" />
    <limit effort="1" velocity="20" />
  </joint>
  <link name="crank_3_int1_9">
    <inertial>
      <mass value="0.0" />
      <inertia ixx="0.0" ixy="0.0" ixz="0.0" iyy="0.0" iyz="0.0" izz="0.0" />
    </inertial>
  </link>
  <link name="crank_3_int2_9">
    <inertial>
      <mass value="0.0" />
      <inertia ixx="0.0" ixy="0.0" ixz="0.0" iyy="0.0" iyz="0.0" izz="0.0" />
    </inertial>
  </link>
  <joint name="crank_3_toe_b_2/2_4_rev0" type="revolute">
    <origin xyz="-5.5511151231257827021e-17 0.057000000000000050626 0.0025000000000000022204" />
    <parent link="crank_3" />
    <child link="crank_3_int1_9" />
    <axis xyz="1 0 0" />
    <limit effort="1" velocity="20" />
  </joint>
  <joint name="crank_3_toe_b_2/2_4_rev1" type="revolute">
    <parent link="crank_3_int1_9" />
    <child link="crank_3_int2_9" />
    <axis xyz="0 1 0" />
    <limit effort="1" velocity="20" />
  </joint>
  <joint name="crank_3_toe_b_2/2_4_rev2" type="revolute">
    <parent link="crank_3_int2_9" />
    <child link="toe_b_2/2_4" />
    <axis xyz="0 0 1" />
    <limit effort="1" velocity="20" />
  </joint>
  <link name="crank_4_int1_10">
    <inertial>
      <mass value="0.0" />
      <inertia ixx="0.0" ixy="0.0" ixz="0.0" iyy="0.0" iyz="0.0" izz="0.0" />
    </inertial>
  </link>
  <link name="crank_4_int2_10">
    <inertial>
      <mass value="0.0" />
      <inertia ixx="0.0" ixy="0.0" ixz="0.0" iyy="0.0" iyz="0.0" izz="0.0" />
    </inertial>
  </link>
  <joint name="crank_4_toe_b_1/2_4_rev0" type="revolute">
    <origin xyz="2.2204460492503130808e-16 0.057000000000000494715 0.0025000000000004185541" />
    <parent link="crank_4" />
    <child link="crank_4_int1_10" />
    <axis xyz="1 0 0" />
    <limit effort="1" velocity="20" />
  </joint>
  <joint name="crank_4_toe_b_1/2_4_rev1" type="revolute">
    <parent link="crank_4_int1_10" />
    <child link="crank_4_int2_10" />
    <axis xyz="0 1 0" />
    <limit effort="1" velocity="20" />
  </joint>
  <joint name="crank_4_toe_b_1/2_4_rev2" type="revolute">
    <parent link="crank_4_int2_10" />
    <child link="toe_b_1/2_4" />
    <axis xyz="0 0 1" />
    <limit effort="1" velocity="20" />
  </joint>
  <link name="tarsus_2_int1_11">
    <inertial>
      <mass value="0.0" />
      <inertia ixx="0.0" ixy="0.0" ixz="0.0" iyy="0.0" iyz="0.0" izz="0.0" />
    </inertial>
  </link>
  <link name="tarsus_2_int2_11">
    <inertial>
      <mass value="0.0" />
      <inertia ixx="0.0" ixy="0.0" ixz="0.0" iyy="0.0" iyz="0.0" izz="0.0" />
    </inertial>
  </link>
  <joint name="tarsus_2_toe_a_1/2_2_rev0" type="revolute">
    <origin xyz="0.1141899349863718105 0.03620674973129278662 7.3552275381416620803e-16" />
    <parent link="tarsus_2" />
    <child link="tarsus_2_int1_11" />
    <axis xyz="1 0 0" />
    <limit effort="1" velocity="20" />
  </joint>
  <joint name="tarsus_2_toe_a_1/2_2_rev1" type="revolute">
    <parent link="tarsus_2_int1_11" />
    <child link="tarsus_2_int2_11" />
    <axis xyz="0 1 0" />
    <limit effort="1" velocity="20" />
  </joint>
  <joint name="tarsus_2_toe_a_1/2_2_rev2" type="revolute">
    <parent link="tarsus_2_int2_11" />
    <child link="toe_a_1/2_2" />
    <axis xyz="0 0 1" />
    <limit effort="1" velocity="20" />
  </joint>
  <link name="hip_x_2_int1_12">
    <inertial>
      <mass value="0.0" />
      <inertia ixx="0.0" ixy="0.0" ixz="0.0" iyy="0.0" iyz="0.0" izz="0.0" />
    </inertial>
  </link>
  <link name="hip_x_2_int2_12">
    <inertial>
      <mass value="0.0" />
      <inertia ixx="0.0" ixy="0.0" ixz="0.0" iyy="0.0" iyz="0.0" izz="0.0" />
    </inertial>
  </link>
  <joint name="hip_x_2_toe_a_2/2_2_rev0" type="revolute">
    <origin xyz="0.030568773343218405558 0 -0.054400000000000003908" />
    <parent link="hip_x_2" />
    <child link="hip_x_2_int1_12" />
    <axis xyz="1 0 0" />
    <limit effort="1" velocity="20" />
  </joint>
  <joint name="hip_x_2_toe_a_2/2_2_rev1" type="revolute">
    <parent link="hip_x_2_int1_12" />
    <child link="hip_x_2_int2_12" />
    <axis xyz="0 1 0" />
    <limit effort="1" velocity="20" />
  </joint>
  <joint name="hip_x_2_toe_a_2/2_2_rev2" type="revolute">
    <parent link="hip_x_2_int2_12" />
    <child link="toe_a_2/2_2" />
    <axis xyz="0 0 1" />
    <limit effort="1" velocity="20" />
  </joint>
</robot>
