<robot name="onshape">
<link name="part_1">
<visual>
<origin xyz="0 4.9491320895156936001e-17 -0.099999999999999977796" rpy="-6.1232339957367660359e-17 -0 3.141592653589793116" />
<geometry>
<mesh filename="package:///part_1.stl"/>
</geometry>
<material name="part_1_material">
<color rgba="0.61568627450980395466 0.81176470588235294379 0.92941176470588238168 1.0"/>
</material>
</visual>
<collision>
<origin xyz="0 4.9491320895156936001e-17 -0.099999999999999977796" rpy="-6.1232339957367660359e-17 -0 3.141592653589793116" />
<geometry>
<mesh filename="package:///part_1.stl"/>
</geometry>
<material name="part_1_material">
<color rgba="0.61568627450980395466 0.81176470588235294379 0.92941176470588238168 1.0"/>
</material>
</collision>
<inertial>
<origin xyz="0 4.1197992844936494035e-17 -0.099999999999999991673" rpy="0 0 0"/>
<mass value="174.92300466135978354" />
<inertia ixx="5.1502018764278556517" ixy="0"  ixz="0" iyy="1.1250508605245987948" iyz="-3.2177960467595314388e-17" izz="5.1913043803123226638" />
</inertial>
</link>

<link name="batie">
<inertial>
<origin xyz="0 0 0" rpy="0 0 0" />
<mass value="1e-9" />
<inertia ixx="0" ixy="0" ixz="0" iyy="0" iyz="0" izz="0" />
</inertial>
</link>
<joint name="batie_frame" type="fixed">
<origin xyz="-0.10000000000000001943 5.1102441431071390109e-17 -0.099999999999999991673" rpy="-3.141592653589793116 -1.570796326794896558 0" />
<parent link="part_1" />
<child link="batie" />
<axis xyz="0 0 0"/>
</joint>

<link name="part_2">
<visual>
<origin xyz="-0.00095444091044741274921 -0.31664243671083236453 -0.4000000000000000222" rpy="-1.570796326794896558 -1.570796326794896558 0" />
<geometry>
<mesh filename="package:///part_2.stl"/>
</geometry>
<material name="part_2_material">
<color rgba="0.64705882352941179736 0.64705882352941179736 0.64705882352941179736 1.0"/>
</material>
</visual>
<collision>
<origin xyz="-0.00095444091044741274921 -0.31664243671083236453 -0.4000000000000000222" rpy="-1.570796326794896558 -1.570796326794896558 0" />
<geometry>
<mesh filename="package:///part_2.stl"/>
</geometry>
<material name="part_2_material">
<color rgba="0.64705882352941179736 0.64705882352941179736 0.64705882352941179736 1.0"/>
</material>
</collision>
<inertial>
<origin xyz="-3.3176586478056417192e-17 0 -0.1500000000000000222" rpy="0 0 0"/>
<mass value="23.550000000000011369" />
<inertia ixx="0.19625000000000011879" ixy="1.0101081261135699114e-32"  ixz="-9.4301956020697503714e-34" iyy="0.19625000000000006328" iyz="-5.9264716248681446018e-33" izz="0.039250000000000062617" />
</inertial>
</link>

<link name="part_2_2">
<visual>
<origin xyz="-0.00095444091044737111584 -0.31664243671083236453 -0.40000000000000013323" rpy="-1.570796326794896558 -1.570796326794896558 0" />
<geometry>
<mesh filename="package:///part_2.stl"/>
</geometry>
<material name="part_2_material">
<color rgba="0.64705882352941179736 0.64705882352941179736 0.64705882352941179736 1.0"/>
</material>
</visual>
<collision>
<origin xyz="-0.00095444091044737111584 -0.31664243671083236453 -0.40000000000000013323" rpy="-1.570796326794896558 -1.570796326794896558 0" />
<geometry>
<mesh filename="package:///part_2.stl"/>
</geometry>
<material name="part_2_material">
<color rgba="0.64705882352941179736 0.64705882352941179736 0.64705882352941179736 1.0"/>
</material>
</collision>
<inertial>
<origin xyz="8.456776945386942289e-18 0 -0.15000000000000013323" rpy="0 0 0"/>
<mass value="23.550000000000011369" />
<inertia ixx="0.19625000000000011879" ixy="1.103654154631154354e-32"  ixz="7.9825944334964615624e-33" iyy="0.19625000000000006328" iyz="-4.7245468947645804301e-36" izz="0.039250000000000062617" />
</inertial>
</link>

<link name="fermeture1_A">
<inertial>
<origin xyz="0 0 0" rpy="0 0 0" />
<mass value="1e-9" />
<inertia ixx="0" ixy="0" ixz="0" iyy="0" iyz="0" izz="0" />
</inertial>
</link>
<joint name="fermeture1_A_frame" type="fixed">
<origin xyz="6.9388939039072283776e-17 -5.5511151231257827021e-17 -0.30000000000000004441" rpy="2.4980018054065889039e-16 -1.0408340855860879544e-16 -1.5707963267948974462" />
<parent link="part_2_2" />
<child link="fermeture1_A" />
<axis xyz="0 0 0"/>
</joint>

<joint name="motor2" type="prismatic">
<origin xyz="1.1102230246251565404e-16 4.1633363423443370266e-17 -0.61345629347963237521" rpy="-5.8980598183211428884e-17 -9.7144514654701433945e-16 -1.570796326794896336" />
<parent link="part_2" />
<child link="part_2_2" />
<axis xyz="0 0 1"/>
<limit effort="1" velocity="20" />
<joint_properties friction="0.0"/>
</joint>

<joint name="to_rotule" type="revolute">
<origin xyz="-0.10000000000000142109 -0.19999999999999984457 -0.099999999999999922284" rpy="-1.5707963267948970021 -2.1293730667615297223e-16 -1.570796326794896558" />
<parent link="part_1" />
<child link="part_2" />
<axis xyz="0 0 1"/>
<limit effort="1" velocity="20" />
<joint_properties friction="0.0"/>
</joint>

<link name="part_2_3">
<visual>
<origin xyz="-0.40000000000000007772 -0.050954440910447373891 -0.31664243671083236453" rpy="-1.3877787807814451825e-16 1.7253817200391751735e-47 4.6214039140477177825e-17" />
<geometry>
<mesh filename="package:///part_2.stl"/>
</geometry>
<material name="part_2_material">
<color rgba="0.64705882352941179736 0.64705882352941179736 0.64705882352941179736 1.0"/>
</material>
</visual>
<collision>
<origin xyz="-0.40000000000000007772 -0.050954440910447373891 -0.31664243671083236453" rpy="-1.3877787807814451825e-16 1.7253817200391751735e-47 4.6214039140477177825e-17" />
<geometry>
<mesh filename="package:///part_2.stl"/>
</geometry>
<material name="part_2_material">
<color rgba="0.64705882352941179736 0.64705882352941179736 0.64705882352941179736 1.0"/>
</material>
</collision>
<inertial>
<origin xyz="-0.15000000000000007772 -0.049999999999999940326 0" rpy="0 0 0"/>
<mass value="23.550000000000011369" />
<inertia ixx="0.039250000000000062617" ixy="-7.7810701991852540335e-18"  ixz="8.5269476674145135655e-34" iyy="0.19625000000000011879" iyz="-9.2444637330587320947e-33" izz="0.19625000000000006328" />
</inertial>
</link>

<link name="part_2_4">
<visual>
<origin xyz="-0.00095444091044744050478 -0.31664243671083236453 -0.4000000000000000222" rpy="-1.570796326794896558 -1.570796326794896558 0" />
<geometry>
<mesh filename="package:///part_2.stl"/>
</geometry>
<material name="part_2_material">
<color rgba="0.64705882352941179736 0.64705882352941179736 0.64705882352941179736 1.0"/>
</material>
</visual>
<collision>
<origin xyz="-0.00095444091044744050478 -0.31664243671083236453 -0.4000000000000000222" rpy="-1.570796326794896558 -1.570796326794896558 0" />
<geometry>
<mesh filename="package:///part_2.stl"/>
</geometry>
<material name="part_2_material">
<color rgba="0.64705882352941179736 0.64705882352941179736 0.64705882352941179736 1.0"/>
</material>
</collision>
<inertial>
<origin xyz="-7.4412689513283588481e-17 0 -0.1500000000000000222" rpy="0 0 0"/>
<mass value="23.550000000000011369" />
<inertia ixx="0.19625000000000011879" ixy="-3.4240952832492484431e-32"  ixz="7.9403051653769911278e-18" iyy="0.19625000000000006328" iyz="2.4252347105668953534e-32" izz="0.039250000000000062617" />
</inertial>
</link>

<link name="part_1_2">
<visual>
<origin xyz="0.20000000000000006661 -1.1102230246251565404e-16 -0.10000000000000000555" rpy="-1.57079632679489678 -1.570796326794896558 0" />
<geometry>
<mesh filename="package:///part_1.stl"/>
</geometry>
<material name="part_1_material">
<color rgba="0.61568627450980395466 0.81176470588235294379 0.92941176470588238168 1.0"/>
</material>
</visual>
<collision>
<origin xyz="0.20000000000000006661 -1.1102230246251565404e-16 -0.10000000000000000555" rpy="-1.57079632679489678 -1.570796326794896558 0" />
<geometry>
<mesh filename="package:///part_1.stl"/>
</geometry>
<material name="part_1_material">
<color rgba="0.61568627450980395466 0.81176470588235294379 0.92941176470588238168 1.0"/>
</material>
</collision>
<inertial>
<origin xyz="0.20000000000000006661 -1.2067419910598100712e-16 -0.10000000000000000555" rpy="0 0 0"/>
<mass value="174.92300466135978354" />
<inertia ixx="1.1250508605245992388" ixy="-7.6761138321909859343e-16"  ixz="1.4936285375283268042e-32" iyy="5.1913043803123226638" iyz="5.7662844354335625374e-32" izz="5.1502018764278556517" />
</inertial>
</link>

<link name="effecteur">
<inertial>
<origin xyz="0 0 0" rpy="0 0 0" />
<mass value="1e-9" />
<inertia ixx="0" ixy="0" ixz="0" iyy="0" iyz="0" izz="0" />
</inertial>
</link>
<joint name="effecteur_frame" type="fixed">
<origin xyz="0.19999999999999978906 -0.099999999999999200639 -0.10000000000000000555" rpy="-1.570796326794896558 -1.570796326794896558 0" />
<parent link="part_1_2" />
<child link="effecteur" />
<axis xyz="0 0 0"/>
</joint>

<link name="part_3">
<visual>
<origin xyz="-0.00095444091044727397133 0.31664243671083236453 0.39999999999999996669" rpy="1.570796326794896558 1.570796326794896558 0" />
<geometry>
<mesh filename="package:///part_3.stl"/>
</geometry>
<material name="part_3_material">
<color rgba="0.2313725490196078538 0.38039215686274507888 0.7058823529411765163 1.0"/>
</material>
</visual>
<collision>
<origin xyz="-0.00095444091044727397133 0.31664243671083236453 0.39999999999999996669" rpy="1.570796326794896558 1.570796326794896558 0" />
<geometry>
<mesh filename="package:///part_3.stl"/>
</geometry>
<material name="part_3_material">
<color rgba="0.2313725490196078538 0.38039215686274507888 0.7058823529411765163 1.0"/>
</material>
</collision>
<inertial>
<origin xyz="1.0181528788729936578e-16 0 -0.012500000000000066613" rpy="0 0 0"/>
<mass value="1.9625000000000021316" />
<inertia ixx="0.0017376302083333403699" ixy="9.3909137287569923271e-21"  ixz="2.3814734769930313987e-34" iyy="0.0017376302083333353826" iyz="2.0742371737829827504e-35" izz="0.0032708333333333417317" />
</inertial>
</link>

<link name="fermeture1_B">
<inertial>
<origin xyz="0 0 0" rpy="0 0 0" />
<mass value="1e-9" />
<inertia ixx="0" ixy="0" ixz="0" iyy="0" iyz="0" izz="0" />
</inertial>
</link>
<joint name="fermeture1_B_frame" type="fixed">
<origin xyz="1.1102230246251565404e-16 -1.1102230246251565404e-16 -0.025000000000000036082" rpy="-3.141592653589793116 7.553776154132985338e-31 -1.570796326794896558" />
<parent link="part_3" />
<child link="fermeture1_B" />
<axis xyz="0 0 0"/>
</joint>

<joint name="to_rotule_2" type="revolute">
<origin xyz="0.4000000000000000222 -1.1102230246251565404e-16 1.3877787807814456755e-17" rpy="-3.141592653589793116 1.4293005401540192488e-16 1.3445448286360310863" />
<parent link="part_1_2" />
<child link="part_3" />
<axis xyz="0 0 1"/>
<limit effort="1" velocity="20" />
<joint_properties friction="0.0"/>
</joint>

<joint name="pivot2" type="revolute">
<origin xyz="0.050000000000000086042 -1.3877787807814456755e-17 -0.30000000000000015543" rpy="1.570796326794896558 0.2410374659180490875 1.5959059426034487278e-15" />
<parent link="part_2_4" />
<child link="part_1_2" />
<axis xyz="0 0 1"/>
<limit effort="1" velocity="20" />
<joint_properties friction="0.0"/>
</joint>

<joint name="motor1" type="prismatic">
<origin xyz="-0.3865375451250520622 -0.050000000000000044409 0" rpy="1.570796326794896558 1.58206796785906213e-15 1.570796326794896558" />
<parent link="part_2_3" />
<child link="part_2_4" />
<axis xyz="0 0 1"/>
<limit effort="1" velocity="20" />
<joint_properties friction="0.0"/>
</joint>

<joint name="pivot" type="revolute">
<origin xyz="-0.099999999999999977796 0.20000000000000006661 -0.099999999999999977796" rpy="-1.570796326794896558 -0.9124440617713069912 -1.570796326794896558" />
<parent link="part_1" />
<child link="part_2_3" />
<axis xyz="0 0 1"/>
<limit effort="1" velocity="20" />
<joint_properties friction="0.0"/>
</joint>


</robot>
