<robot name="onshape">
<link name="built">
<visual>
<origin xyz="0 0 0" rpy="0 -0 0" />
<geometry>
<mesh filename="package:///built.stl"/>
</geometry>
<material name="built_material">
<color rgba="0.61568627450980395466 0.81176470588235294379 0.92941176470588238168 1.0"/>
</material>
</visual>
<collision>
<origin xyz="0 0 0" rpy="0 -0 0" />
<geometry>
<mesh filename="package:///built.stl"/>
</geometry>
<material name="built_material">
<color rgba="0.61568627450980395466 0.81176470588235294379 0.92941176470588238168 1.0"/>
</material>
</collision>
<inertial>
<origin xyz="0.050000000000000009714 2.862766224799237303e-17 0.04201870900558794808" rpy="0 0 0"/>
<mass value="90.55799165500025083" />
<inertia ixx="2.3756861654595264888" ixy="0"  ixz="0" iyy="0.57624941965684406409" iyz="-3.180615493203475216e-16" izz="1.9503667318943500586" />
</inertial>
</link>

<link name="rod">
<visual>
<origin xyz="-0.11026961925186587465 -0.24753479872234485093 0" rpy="-1.570796326794896558 -1.570796326794896558 0" />
<geometry>
<mesh filename="package:///rod.stl"/>
</geometry>
<material name="rod_material">
<color rgba="0.64705882352941179736 0.64705882352941179736 0.64705882352941179736 1.0"/>
</material>
</visual>
<collision>
<origin xyz="-0.11026961925186587465 -0.24753479872234485093 0" rpy="-1.570796326794896558 -1.570796326794896558 0" />
<geometry>
<mesh filename="package:///rod.stl"/>
</geometry>
<material name="rod_material">
<color rgba="0.64705882352941179736 0.64705882352941179736 0.64705882352941179736 1.0"/>
</material>
</collision>
<inertial>
<origin xyz="-2.7755575615628913511e-17 -0.23000000000000000999 0.024999999999999997918" rpy="0 0 0"/>
<mass value="24.820995827500130559" />
<inertia ixx="0.68085505004432478326" ixy="0"  ixz="2.3617511963093135611e-114" iyy="0.037611570769567767569" iyz="0" izz="0.70812453921910079035" />
</inertial>
</link>

<link name="rod_2">
<visual>
<origin xyz="-0.11026961925186590241 -0.24753479872234479542 0" rpy="-1.570796326794896558 -1.570796326794896558 0" />
<geometry>
<mesh filename="package:///rod.stl"/>
</geometry>
<material name="rod_material">
<color rgba="0.64705882352941179736 0.64705882352941179736 0.64705882352941179736 1.0"/>
</material>
</visual>
<collision>
<origin xyz="-0.11026961925186590241 -0.24753479872234479542 0" rpy="-1.570796326794896558 -1.570796326794896558 0" />
<geometry>
<mesh filename="package:///rod.stl"/>
</geometry>
<material name="rod_material">
<color rgba="0.64705882352941179736 0.64705882352941179736 0.64705882352941179736 1.0"/>
</material>
</collision>
<inertial>
<origin xyz="-5.5511151231257827021e-17 -0.22999999999999998224 0.024999999999999997918" rpy="0 0 0"/>
<mass value="24.820995827500130559" />
<inertia ixx="0.68085505004432478326" ixy="-1.5669169297254520099e-93"  ixz="-2.2658786799448306426e-55" iyy="0.037611570769567767569" iyz="3.1111634638674341725e-55" izz="0.70812453921910079035" />
</inertial>
</link>

<link name="sphere">
<inertial>
<origin xyz="1.9147421060431300434e-93 2.1048616860345132863e-18 6.9360053546730981713e-65" rpy="0 0 0"/>
<mass value="654498.46949787356425" />
<inertia ixx="163.62461737446844268" ixy="-3.1914071074697915335e-73"  ixz="4.1530907812548682644e-44" iyy="163.62461737446841425" iyz="2.8696653677657470257e-44" izz="163.62461737446841425" />
</inertial>
</link>

<joint name="closedloop1_A" type="revolute">
<origin xyz="2.7755575615628913511e-17 -0.46000000000000001998 -2.7755575615628913511e-17" rpy="2.0436181652775820801e-30 6.9767163393490848699e-30 1.570796326794896558" />
<parent link="rod_2" />
<child link="sphere" />
<axis xyz="0 0 1"/>
<limit effort="1" velocity="20" />
<joint_properties friction="0.0"/>
</joint>

<joint name="free1" type="revolute">
<origin xyz="2.7755575615628913511e-17 -0.45999999999999990896 0.050000000000000016653" rpy="-1.5128280870939263564e-40 -3.6734198463195946286e-40 -6.1876044703704446752e-78" />
<parent link="rod" />
<child link="rod_2" />
<axis xyz="0 0 1"/>
<limit effort="1" velocity="20" />
<joint_properties friction="0.0"/>
</joint>

<joint name="mot1" type="revolute">
<origin xyz="0.10000000000000000555 0.14999999999999996669 0.042018709005587850935" rpy="1.570796326794896558 -0 1.570796326794896558" />
<parent link="built" />
<child link="rod" />
<axis xyz="0 0 1"/>
<limit effort="1" velocity="20" />
<joint_properties friction="0.0"/>
</joint>

<link name="rod_3">
<visual>
<origin xyz="-0.11026961925186590241 0.24753479872234485093 0.050000000000000002776" rpy="1.570796326794896558 1.570796326794896558 0" />
<geometry>
<mesh filename="package:///rod.stl"/>
</geometry>
<material name="rod_material">
<color rgba="0.64705882352941179736 0.64705882352941179736 0.64705882352941179736 1.0"/>
</material>
</visual>
<collision>
<origin xyz="-0.11026961925186590241 0.24753479872234485093 0.050000000000000002776" rpy="1.570796326794896558 1.570796326794896558 0" />
<geometry>
<mesh filename="package:///rod.stl"/>
</geometry>
<material name="rod_material">
<color rgba="0.64705882352941179736 0.64705882352941179736 0.64705882352941179736 1.0"/>
</material>
</collision>
<inertial>
<origin xyz="-5.5511151231257827021e-17 0.23000000000000000999 0.025000000000000004857" rpy="0 0 0"/>
<mass value="24.820995827500130559" />
<inertia ixx="0.68085505004432478326" ixy="-3.2940647725149681806e-48"  ixz="-1.809762378694714269e-59" iyy="0.037611570769567767569" iyz="-2.8424453976423529291e-60" izz="0.70812453921910079035" />
</inertial>
</link>

<link name="end_rod">
<visual>
<origin xyz="0.1102696192518658469 -0.24753479872234485093 -0.050000000000000002776" rpy="-1.570796326794896558 -1.570796326794896558 0" />
<geometry>
<mesh filename="package:///end_rod.stl"/>
</geometry>
<material name="end_rod_material">
<color rgba="0.64705882352941179736 0.64705882352941179736 0.64705882352941179736 1.0"/>
</material>
</visual>
<collision>
<origin xyz="0.1102696192518658469 -0.24753479872234485093 -0.050000000000000002776" rpy="-1.570796326794896558 -1.570796326794896558 0" />
<geometry>
<mesh filename="package:///end_rod.stl"/>
</geometry>
<material name="end_rod_material">
<color rgba="0.64705882352941179736 0.64705882352941179736 0.64705882352941179736 1.0"/>
</material>
</collision>
<inertial>
<origin xyz="7.3652695577478214884e-48 -0.26855892668729658412 -0.0166176246331963956" rpy="0 0 0"/>
<mass value="29.820293741250193165" />
<inertia ixx="0.92256274106550961722" ixy="-1.9752304257615537266e-47"  ixz="-1.6764275804372035731e-47" iyy="0.056382861354550263544" iyz="0.047853547920913584723" izz="0.94571458962747512178" />
</inertial>
</link>

<link name="effector">
<inertial>
<origin xyz="0 0 0" rpy="0 0 0" />
<mass value="1e-9" />
<inertia ixx="0" ixy="0" ixz="0" iyy="0" iyz="0" izz="0" />
</inertial>
</link>
<joint name="effector_frame" type="fixed">
<origin xyz="0 -0.52750000000000019096 1.3877787807814456755e-17" rpy="-1.5707963267948958919 -1.570796326794896558 0" />
<parent link="end_rod" />
<child link="effector" />
<axis xyz="0 0 0"/>
</joint>

<link name="sphere_2">
<inertial>
<origin xyz="7.7833270078606882883e-50 1.1312716414855017426e-16 4.5715251076753544539e-64" rpy="0 0 0"/>
<mass value="654498.46949787356425" />
<inertia ixx="163.62461737446844268" ixy="9.5799383273081893888e-30"  ixz="-1.7305163109789151173e-43" iyy="163.62461737446841425" iyz="7.1118621353242679629e-44" izz="163.62461737446841425" />
</inertial>
</link>

<joint name="closedloop1_B" type="revolute">
<origin xyz="-5.5511151231257827021e-17 -0.45999999999999985345 0.050000000000000002776" rpy="-6.1152609076707444674e-30 1.2212640759497854267e-29 -2.9143354396410176762e-16" />
<parent link="end_rod" />
<child link="sphere_2" />
<axis xyz="0 0 1"/>
<limit effort="1" velocity="20" />
<joint_properties friction="0.0"/>
</joint>

<joint name="free2" type="revolute">
<origin xyz="2.7755575615628913511e-17 0.45999999999999996447 0" rpy="3.7235323964476006137e-42 7.1746481373430608542e-42 -3.141592653589793116" />
<parent link="rod_3" />
<child link="end_rod" />
<axis xyz="0 0 1"/>
<limit effort="1" velocity="20" />
<joint_properties friction="0.0"/>
</joint>

<joint name="mot2" type="revolute">
<origin xyz="0.10000000000000001943 -0.15000000000000007772 0.042018709005587989713" rpy="-1.570796326794896558 -2.2204460492503120948e-16 -1.570796326794896558" />
<parent link="built" />
<child link="rod_3" />
<axis xyz="0 0 1"/>
<limit effort="1" velocity="20" />
<joint_properties friction="0.0"/>
</joint>


</robot>
