<robot name="onshape">
  <link name="torso">
    <visual>
      <origin xyz="-3.6658488180179105565e-18 2.0816681711721685133e-17 0.059867854479678836443" rpy="-6.1232339957367660359e-17 -0 1.570796326794896558" />
      <geometry>
        <mesh filename="package:///torso.stl" />
      </geometry>
      <material name="torso_material">
        <color rgba="0.61568627450980395466 0.81176470588235294379 0.92941176470588238168 1.0" />
      </material>
    </visual>
    <collision>
      <origin xyz="-3.6658488180179105565e-18 2.0816681711721685133e-17 0.059867854479678836443" rpy="-6.1232339957367660359e-17 -0 1.570796326794896558" />
      <geometry>
        <mesh filename="package:///torso.stl" />
      </geometry>
    </collision>
    <inertial>
      <origin xyz="-4.9939687660375113953e-18 2.3635572673159359395e-17 0.070603948746371325562" rpy="0 0 0" />
      <mass value="3.2452322404414175594" />
      <inertia ixx="0.012163262961236534151" ixy="0" ixz="1.2921033060725054663e-19" iyy="0.0040573041803173637634" iyz="0" izz="0.010053098125184021031" />
    </inertial>
  </link>
  <link name="hip">
    <inertial>
      <origin xyz="0 0 0" rpy="0 0 0" />
      <mass value="1e-9" />
      <inertia ixx="0" ixy="0" ixz="0" iyy="0" iyz="0" izz="0" />
    </inertial>
  </link>
  <joint name="hip_frame" type="fixed">
    <origin xyz="2.4027501270446886779e-19 -1.626303258728255688e-19 0.0024999999999999996184" rpy="2.8421709430404007435e-14 3.0814879110196404233e-31 0" />
    <parent link="torso" />
    <child link="hip" />
    <axis xyz="0 0 0" />
  </joint>
  <link name="hip_y">
    <visual>
      <origin xyz="0.10706579297345659996 -1.3877787807814456755e-17 -0.035199999999999995182" rpy="-1.570796326794896558 4.9297741930698701868e-33 -5.7455175537265283628e-21" />
      <geometry>
        <mesh filename="package:///hip_y.stl" />
      </geometry>
      <material name="hip_y_material">
        <color rgba="0.2313725490196078538 0.38039215686274507888 0.7058823529411765163 1.0" />
      </material>
    </visual>
    <collision>
      <origin xyz="0.10706579297345659996 -1.3877787807814456755e-17 -0.035199999999999995182" rpy="-1.570796326794896558 4.9297741930698701868e-33 -5.7455175537265283628e-21" />
      <geometry>
        <mesh filename="package:///hip_y.stl" />
      </geometry>
    </collision>
    <inertial>
      <origin xyz="0.015578666288194957176 -1.23574311386581531e-07 -0.034149457045324432825" rpy="0 0 0" />
      <mass value="1.2895238899898622265" />
      <inertia ixx="0.00089621011138626548598" ixy="-1.7957438648418668444e-09" ixz="3.2112420914059141175e-05" iyy="0.0010420724953831758935" iyz="3.0492496474583046404e-09" izz="0.0010213484696825509291" />
    </inertial>
  </link>
  <link name="hip_x">
    <visual>
      <origin xyz="0 1.3877787807814456755e-17 -0.054400000000000003908" rpy="1.570796326794896558 1.570796326794896558 0" />
      <geometry>
        <mesh filename="package:///hip_x.stl" />
      </geometry>
      <material name="hip_x_material">
        <color rgba="0.64705882352941179736 0.64705882352941179736 0.64705882352941179736 1.0" />
      </material>
    </visual>
    <collision>
      <origin xyz="0 1.3877787807814456755e-17 -0.054400000000000003908" rpy="1.570796326794896558 1.570796326794896558 0" />
      <geometry>
        <mesh filename="package:///hip_x.stl" />
      </geometry>
    </collision>
    <inertial>
      <origin xyz="0.0023378176535870055439 1.2990891538658346927e-17 -0.04521675346357507258" rpy="0 0 0" />
      <mass value="1.4197410037164885921" />
      <inertia ixx="0.0014949229305128524086" ixy="-2.8291893305217437424e-24" ixz="-1.2476184392984387178e-05" iyy="0.0013017541081209299796" iyz="1.0322047914401249082e-26" izz="0.00094724669336309903593" />
    </inertial>
  </link>
  <link name="hip_z">
    <visual>
      <origin xyz="-0.11999999999999998168 0 -0.070000000000000006661" rpy="-1.570796326794896558 3.2384280349137880083e-21 -4.6318377315047902468e-17" />
      <geometry>
        <mesh filename="package:///hip_z.stl" />
      </geometry>
      <material name="hip_z_material">
        <color rgba="0.61568627450980395466 0.81176470588235294379 0.92941176470588238168 1.0" />
      </material>
    </visual>
    <collision>
      <origin xyz="-0.11999999999999998168 0 -0.070000000000000006661" rpy="-1.570796326794896558 3.2384280349137880083e-21 -4.6318377315047902468e-17" />
      <geometry>
        <mesh filename="package:///hip_z.stl" />
      </geometry>
    </collision>
    <inertial>
      <origin xyz="-0.059999999999999970024 -2.3430704604525477966e-18 -0.022000000000000005662" rpy="0 0 0" />
      <mass value="3.8932756153047387571" />
      <inertia ixx="0.0040205863361596526698" ixy="-5.5316639517601245531e-19" ixz="3.3390638840432860903e-23" iyy="0.014779167671256707509" iyz="1.3508559005082247566e-22" izz="0.017543523742211356714" />
    </inertial>
  </link>
  <link name="shin">
    <visual>
      <origin xyz="0 2.0816681711721685133e-17 -0.025000000000000008327" rpy="-1.570796326794896558 5.2243950615035981016e-22 -4.3834746067120642029e-17" />
      <geometry>
        <mesh filename="package:///shin.stl" />
      </geometry>
      <material name="shin_material">
        <color rgba="0.61568627450980395466 0.81176470588235294379 0.92941176470588238168 1.0" />
      </material>
    </visual>
    <collision>
      <origin xyz="0 2.0816681711721685133e-17 -0.025000000000000008327" rpy="-1.570796326794896558 5.2243950615035981016e-22 -4.3834746067120642029e-17" />
      <geometry>
        <mesh filename="package:///shin.stl" />
      </geometry>
    </collision>
    <inertial>
      <origin xyz="0.086542930154570277268 0.024349627108824756921 -0.025000000824260217025" rpy="0 0 0" />
      <mass value="0.5557814093331634453" />
      <inertia ixx="0.00046644066811272637046" ixy="-0.00088329043391741405254" ixz="6.3639813725573143421e-13" iyy="0.0090559095871162419156" iyz="1.1189385758805062784e-11" izz="0.0093490826129847687254" />
    </inertial>
  </link>
  <link name="tarsus">
    <visual>
      <origin xyz="-0.11600000000000026956 -0.11491398237765959589 -1.1102230246251565404e-16" rpy="-3.141592653589793116 1.570796326794896558 0" />
      <geometry>
        <mesh filename="package:///actuator_molet.stl" />
      </geometry>
      <material name="actuator_molet_material">
        <color rgba="0.91764705882352937127 0.91764705882352937127 0.91764705882352937127 1.0" />
      </material>
    </visual>
    <collision>
      <origin xyz="-0.11600000000000026956 -0.11491398237765959589 -1.1102230246251565404e-16" rpy="-3.141592653589793116 1.570796326794896558 0" />
      <geometry>
        <mesh filename="package:///actuator_molet.stl" />
      </geometry>
    </collision>
    <visual>
      <origin xyz="5.5511151231257827021e-17 0.0010860176223412842944 0" rpy="-1.57079632679489678 -1.570796326794896558 0" />
      <geometry>
        <mesh filename="package:///tarsus.stl" />
      </geometry>
      <material name="tarsus_material">
        <color rgba="0.61568627450980395466 0.81176470588235294379 0.92941176470588238168 1.0" />
      </material>
    </visual>
    <collision>
      <origin xyz="5.5511151231257827021e-17 0.0010860176223412842944 0" rpy="-1.57079632679489678 -1.570796326794896558 0" />
      <geometry>
        <mesh filename="package:///tarsus.stl" />
      </geometry>
    </collision>
    <inertial>
      <origin xyz="-0.083086291902174716495 -0.020033778925020007122 2.8736095518193009432e-08" rpy="0 0 0" />
      <mass value="0.7428461942208621771" />
      <inertia ixx="0.00039818835112512209091" ixy="-0.0005421323167350016901" ixz="-5.2637644313052516266e-10" iyy="0.0079851917842741031162" iyz="1.2685116126373679132e-10" izz="0.0079848716361182441731" />
    </inertial>
  </link>
  <link name="closedloop5_B">
    <inertial>
      <origin xyz="0 0 0" rpy="0 0 0" />
      <mass value="1e-9" />
      <inertia ixx="0" ixy="0" ixz="0" iyy="0" iyz="0" izz="0" />
    </inertial>
  </link>
  <joint name="closedloop5_B_frame" type="fixed">
    <origin xyz="0.11418993498637049211 0.036206749731294562977 1.3877787807814456755e-17" rpy="-1.57079632679489678 -1.3768350498166480264e-15 8.8189738139560535329e-16" />
    <parent link="tarsus" />
    <child link="closedloop5_B" />
    <axis xyz="0 0 0" />
  </joint>
  <link name="foot_roll">
    <visual>
      <origin xyz="0.32599839999999996598 0.039744000000000001549 -0.013999999999999887534" rpy="-1.570796326794896558 -1.570796326794896336 0" />
      <geometry>
        <mesh filename="package:///foot_roll.stl" />
      </geometry>
      <material name="foot_roll_material">
        <color rgba="0.2313725490196078538 0.38039215686274507888 0.7058823529411765163 1.0" />
      </material>
    </visual>
    <collision>
      <origin xyz="0.32599839999999996598 0.039744000000000001549 -0.013999999999999887534" rpy="-1.570796326794896558 -1.570796326794896336 0" />
      <geometry>
        <mesh filename="package:///foot_roll.stl" />
      </geometry>
    </collision>
    <inertial>
      <origin xyz="-2.1851523924012058745e-08 -0.0014449033387292503638 -0.013999993222565320847" rpy="0 0 0" />
      <mass value="0.0027067106871796991867" />
      <inertia ixx="1.8232396912107804468e-07" ixy="1.2456494873268150727e-13" ixz="-3.0177862000949977712e-13" iyy="1.1958745424438046988e-07" iyz="4.5807687216419574102e-14" izz="1.0944659228682656112e-07" />
    </inertial>
  </link>
  <link name="foot_part">
    <visual>
      <origin xyz="-0.0011288304490430500771 1.3877787807814456755e-17 0.0090799999999998659561" rpy="1.570796326794896558 -5.6238564851494237452e-17 -4.6175484037764408987e-20" />
      <geometry>
        <mesh filename="package:///foot_part.stl" />
      </geometry>
      <material name="foot_part_material">
        <color rgba="0.61568627450980395466 0.81176470588235294379 0.92941176470588238168 1.0" />
      </material>
    </visual>
    <collision>
      <origin xyz="-0.0011288304490430500771 1.3877787807814456755e-17 0.0090799999999998659561" rpy="1.570796326794896558 -5.6238564851494237452e-17 -4.6175484037764408987e-20" />
      <geometry>
        <mesh filename="package:///foot_part.stl" />
      </geometry>
    </collision>
    <inertial>
      <origin xyz="-0.042296631354857207319 -6.7228490680718109683e-10 0.011797351827666066951" rpy="0 0 0" />
      <mass value="0.3309516742025366276" />
      <inertia ixx="0.0010118322945958278195" ixy="2.5339652280593012685e-12" ixz="-0.00049446274168876561735" iyy="0.0012276801049992628473" iyz="7.2849212775434216028e-12" izz="0.00051045333461432877177" />
    </inertial>
  </link>
  <link name="foot">
    <inertial>
      <origin xyz="0 0 0" rpy="0 0 0" />
      <mass value="1e-9" />
      <inertia ixx="0" ixy="0" ixz="0" iyy="0" iyz="0" izz="0" />
    </inertial>
  </link>
  <joint name="foot_frame" type="fixed">
    <origin xyz="-0.05589761960057737511 0 0.014375929767894257694" rpy="3.141592653589793116 1.0420837364882524767 3.141592653589793116" />
    <parent link="foot_part" />
    <child link="foot" />
    <axis xyz="0 0 0" />
  </joint>
  <link name="closedloop3_B">
    <inertial>
      <origin xyz="0 0 0" rpy="0 0 0" />
      <mass value="1e-9" />
      <inertia ixx="0" ixy="0" ixz="0" iyy="0" iyz="0" izz="0" />
    </inertial>
  </link>
  <joint name="closedloop3_B_frame" type="fixed">
    <origin xyz="-0.0091288304490430016713 -0.014275999999999997025 0.052813599999999905066" rpy="1.570796326794896558 3.4353068163921696563e-17 1.5707963267948972241" />
    <parent link="foot_part" />
    <child link="closedloop3_B" />
    <axis xyz="0 0 0" />
  </joint>
  <link name="closedloop4_A">
    <inertial>
      <origin xyz="0 0 0" rpy="0 0 0" />
      <mass value="1e-9" />
      <inertia ixx="0" ixy="0" ixz="0" iyy="0" iyz="0" izz="0" />
    </inertial>
  </link>
  <joint name="closedloop4_A_frame" type="fixed">
    <origin xyz="-0.0091288304490430571825 0.014276000000000010903 0.052813599999999905066" rpy="1.570796326794896558 3.4353068163921696563e-17 1.5707963267948972241" />
    <parent link="foot_part" />
    <child link="closedloop4_A" />
    <axis xyz="0 0 0" />
  </joint>
  <joint name="free_foot2" type="revolute">
    <origin xyz="5.5511151231257827021e-17 0.0089999999999998969713 -0.013999999999999998557" rpy="-1.5707963267948961139 6.4836092119029229298e-05 3.141592653589793116" />
    <parent link="foot_roll" />
    <child link="foot_part" />
    <axis xyz="0 0 1" />
    <limit effort="1" velocity="20" />
    <joint_properties friction="0.0" />
  </joint>
  <joint name="free_foot1" type="revolute">
    <origin xyz="-0.32599839999999991047 -0.038657982377658717255 -0.014000000000000054068" rpy="-3.141592653589793116 -2.6753703726026536382e-16 3.0536904360859087326" />
    <parent link="tarsus" />
    <child link="foot_roll" />
    <axis xyz="0 0 1" />
    <limit effort="1" velocity="20" />
    <joint_properties friction="0.0" />
  </joint>
  <link name="crank">
    <visual>
      <origin xyz="0.088799999999999990052 0.027200000000000001954 0.029999999999999985012" rpy="-1.570796326794896558 -1.570796326794896558 0" />
      <geometry>
        <mesh filename="package:///crank.stl" />
      </geometry>
      <material name="crank_material">
        <color rgba="0.64705882352941179736 0.64705882352941179736 0.64705882352941179736 1.0" />
      </material>
    </visual>
    <collision>
      <origin xyz="0.088799999999999990052 0.027200000000000001954 0.029999999999999985012" rpy="-1.570796326794896558 -1.570796326794896558 0" />
      <geometry>
        <mesh filename="package:///crank.stl" />
      </geometry>
    </collision>
    <inertial>
      <origin xyz="-4.1699609127137192844e-17 0.015221680213895987313 -0.00095148915120265784018" rpy="0 0 0" />
      <mass value="0.0045332434126214744829" />
      <inertia ixx="2.0190313503504425919e-06" ixy="9.3105310085333965821e-24" ixz="1.3164464830436457342e-27" iyy="3.8254267160843608508e-07" iyz="-9.1875323763544904139e-09" izz="2.3968139039834545946e-06" />
    </inertial>
  </link>
  <link name="toe_b_2/2">
    <visual>
      <origin xyz="-0.054171488011523882822 -0.043924303555988961079 -0.12000000000000005107" rpy="-1.570796326794896558 -1.570796326794896558 0" />
      <geometry>
        <mesh filename="package:///toe_b_2_2.stl" />
      </geometry>
      <material name="toe_b_2/2_material">
        <color rgba="0.64705882352941179736 0.64705882352941179736 0.64705882352941179736 1.0" />
      </material>
    </visual>
    <collision>
      <origin xyz="-0.054171488011523882822 -0.043924303555988961079 -0.12000000000000005107" rpy="-1.570796326794896558 -1.570796326794896558 0" />
      <geometry>
        <mesh filename="package:///toe_b_2_2.stl" />
      </geometry>
    </collision>
    <inertial>
      <origin xyz="-1.0364081693084915286e-16 -6.9388939039072283776e-18 -0.12000000000000005107" rpy="0 0 0" />
      <mass value="0.012063715789784825241" />
      <inertia ixx="5.7954090654126296683e-05" ixy="1.3241463880840878483e-22" ixz="-4.6755474295472650334e-22" iyy="5.7954090654126310235e-05" iyz="-5.1224472532574453106e-23" izz="9.6509726318278778164e-08" />
    </inertial>
  </link>
  <link name="closedloop4_B">
    <inertial>
      <origin xyz="0 0 0" rpy="0 0 0" />
      <mass value="1e-9" />
      <inertia ixx="0" ixy="0" ixz="0" iyy="0" iyz="0" izz="0" />
    </inertial>
  </link>
  <joint name="closedloop4_B_frame" type="fixed">
    <origin xyz="0 0 -0.23999999999999993561" rpy="1.8356640193417453512e-14 -8.4564942913565752023e-15 -1.570796326794896558" />
    <parent link="toe_b_2/2" />
    <child link="closedloop4_B" />
    <axis xyz="0 0 0" />
  </joint>
  <joint name="motor_shin1" type="revolute">
    <origin xyz="-0.08879999999999987903 -0.026113982377658606637 0.02999999999999999889" rpy="-3.141592653589793116 -1.2049317579789118454e-17 0.37000796544916397801" />
    <parent link="tarsus" />
    <child link="crank" />
    <axis xyz="0 0 1" />
    <limit effort="1" velocity="20" />
    <joint_properties friction="0.0" />
  </joint>
  <link name="crank_2">
    <visual>
      <origin xyz="0.088800000000000101075 0.027199999999999946443 0.030000000000000012768" rpy="-1.570796326794896558 -1.570796326794896558 0" />
      <geometry>
        <mesh filename="package:///crank.stl" />
      </geometry>
      <material name="crank_material">
        <color rgba="0.64705882352941179736 0.64705882352941179736 0.64705882352941179736 1.0" />
      </material>
    </visual>
    <collision>
      <origin xyz="0.088800000000000101075 0.027199999999999946443 0.030000000000000012768" rpy="-1.570796326794896558 -1.570796326794896558 0" />
      <geometry>
        <mesh filename="package:///crank.stl" />
      </geometry>
    </collision>
    <inertial>
      <origin xyz="6.971720219454935989e-17 0.015221680213895926598 -0.00095148915120263355405" rpy="0 0 0" />
      <mass value="0.0045332434126214744829" />
      <inertia ixx="2.0190313503504425919e-06" ixy="8.3254919979248169206e-23" ixz="2.2388402804159503808e-25" iyy="3.8254267160843608508e-07" iyz="-9.1875323763544920682e-09" izz="2.3968139039834554417e-06" />
    </inertial>
  </link>
  <link name="toe_b_2/2_2">
    <visual>
      <origin xyz="-0.054171488011523771799 -0.043924303555988974956 -0.11999999999999999556" rpy="-1.570796326794896558 -1.570796326794896558 0" />
      <geometry>
        <mesh filename="package:///toe_b_2_2.stl" />
      </geometry>
      <material name="toe_b_2/2_material">
        <color rgba="0.64705882352941179736 0.64705882352941179736 0.64705882352941179736 1.0" />
      </material>
    </visual>
    <collision>
      <origin xyz="-0.054171488011523771799 -0.043924303555988974956 -0.11999999999999999556" rpy="-1.570796326794896558 -1.570796326794896558 0" />
      <geometry>
        <mesh filename="package:///toe_b_2_2.stl" />
      </geometry>
    </collision>
    <inertial>
      <origin xyz="1.3185654119469512788e-17 -2.0816681711721685133e-17 -0.11999999999999999556" rpy="0 0 0" />
      <mass value="0.012063715789784825241" />
      <inertia ixx="5.7954090654126310235e-05" ixy="-2.4527585036816170262e-23" ixz="-2.8500005225509368531e-24" iyy="5.7954090654126310235e-05" iyz="-2.9263517955606597429e-22" izz="9.6509726318278778164e-08" />
    </inertial>
  </link>
  <link name="closedloop3_A">
    <inertial>
      <origin xyz="0 0 0" rpy="0 0 0" />
      <mass value="1e-9" />
      <inertia ixx="0" ixy="0" ixz="0" iyy="0" iyz="0" izz="0" />
    </inertial>
  </link>
  <joint name="closedloop3_A_frame" type="fixed">
    <origin xyz="5.5511151231257827021e-17 0 -0.23999999999999999112" rpy="1.2637941783772522263e-14 6.0675155236033963645e-15 5.4148235365884768465e-17" />
    <parent link="toe_b_2/2_2" />
    <child link="closedloop3_A" />
    <axis xyz="0 0 0" />
  </joint>
  <joint name="motor_shin2" type="revolute">
    <origin xyz="-0.088799999999999990052 -0.02611398237765871766 -0.030000000000000012768" rpy="-8.3026830780108650904e-18 1.2722518878500193295e-17 -2.7597162002066317754" />
    <parent link="tarsus" />
    <child link="crank_2" />
    <axis xyz="0 0 1" />
    <limit effort="1" velocity="20" />
    <joint_properties friction="0.0" />
  </joint>
  <joint name="free_knee" type="revolute">
    <origin xyz="0.39567486363081383338 0.053875166733171823974 -0.025000000000000008327" rpy="3.141592653589793116 -3.2586698722640405165e-17 -1.7163975088181722128" />
    <parent link="shin" />
    <child link="tarsus" />
    <axis xyz="0 0 1" />
    <limit effort="1" velocity="20" />
    <joint_properties friction="0.0" />
  </joint>
  <joint name="motor_knee" type="revolute">
    <origin xyz="-0.12000000000000000944 1.3877787807814456755e-17 -1.3877787807814456755e-17" rpy="3.141592653589793116 1.7546436006552944212e-16 -2.7122573923719275335" />
    <parent link="hip_z" />
    <child link="shin" />
    <axis xyz="0 0 1" />
    <limit effort="1" velocity="20" />
    <joint_properties friction="0.0" />
  </joint>
  <joint name="motor_hip_y" type="revolute">
    <origin xyz="-0.026000000000000009215 1.3877787807814456755e-17 -0.054400000000000003908" rpy="-1.570796326794896558 -1.1851659341776752399 -1.5707963267948961139" />
    <parent link="hip_x" />
    <child link="hip_z" />
    <axis xyz="0 0 1" />
    <limit effort="1" velocity="20" />
    <joint_properties friction="0.0" />
  </joint>
  <link name="toe_a_2/2">
    <visual>
      <origin xyz="0.056794565202879003507 -0.040773406646044452195 -0.2000000000000000111" rpy="-1.570796326794896558 -1.570796326794896558 0" />
      <geometry>
        <mesh filename="package:///toe_a_2_2.stl" />
      </geometry>
      <material name="toe_a_2/2_material">
        <color rgba="0.61568627450980395466 0.81176470588235294379 0.92941176470588238168 1.0" />
      </material>
    </visual>
    <collision>
      <origin xyz="0.056794565202879003507 -0.040773406646044452195 -0.2000000000000000111" rpy="-1.570796326794896558 -1.570796326794896558 0" />
      <geometry>
        <mesh filename="package:///toe_a_2_2.stl" />
      </geometry>
    </collision>
    <inertial>
      <origin xyz="1.495267289267648599e-17 0 -0.2000000000000000111" rpy="0 0 0" />
      <mass value="0.031415926535897899241" />
      <inertia ixx="0.00041907537001948795856" ixy="1.290049460679863052e-20" ixz="-3.6522718323296923814e-25" iyy="0.00041907537001948795856" iyz="6.6426489858155568137e-26" izz="3.9269908169872326592e-07" />
    </inertial>
  </link>
  <link name="closedloop5_A">
    <inertial>
      <origin xyz="0 0 0" rpy="0 0 0" />
      <mass value="1e-9" />
      <inertia ixx="0" ixy="0" ixz="0" iyy="0" iyz="0" izz="0" />
    </inertial>
  </link>
  <joint name="closedloop5_A_frame" type="fixed">
    <origin xyz="-6.9388939039072283776e-18 -6.9388939039072283776e-18 -0.4000000000000000222" rpy="-7.3492708020674768926e-15 -3.5255485219768856353e-22 1.570796326794896558" />
    <parent link="toe_a_2/2" />
    <child link="closedloop5_A" />
    <axis xyz="0 0 0" />
  </joint>
  <joint name="motor_hip_z" type="revolute">
    <origin xyz="0.052665792973456596049 -1.3877787807814456755e-17 -0.035199999999999995182" rpy="-1.57079632679489678 -1.9934308164667167464e-05 1.570796326794896336" />
    <parent link="hip_y" />
    <child link="hip_x" />
    <axis xyz="0 0 1" />
    <limit effort="1" velocity="20" />
    <joint_properties friction="0.0" />
  </joint>
  <joint name="motor_hip_x" type="revolute">
    <origin xyz="-0.02999999999999999889 -0.072799999999999961964 0.059867854479678829505" rpy="-1.5707963267943847452 1.5706767216447374835 -1.5707963267943847452" />
    <parent link="torso" />
    <child link="hip_y" />
    <axis xyz="0 0 1" />
    <limit effort="1" velocity="20" />
    <joint_properties friction="0.0" />
  </joint>
  <link name="hip_y_2">
    <visual>
      <origin xyz="0.10440000000000002056 0 -0.035199999999999995182" rpy="-1.570796326794896558 -0 0" />
      <geometry>
        <mesh filename="package:///hip_y.stl" />
      </geometry>
      <material name="hip_y_material">
        <color rgba="0.2313725490196078538 0.38039215686274507888 0.7058823529411765163 1.0" />
      </material>
    </visual>
    <collision>
      <origin xyz="0.10440000000000002056 0 -0.035199999999999995182" rpy="-1.570796326794896558 -0 0" />
      <geometry>
        <mesh filename="package:///hip_y.stl" />
      </geometry>
    </collision>
    <inertial>
      <origin xyz="0.012912873314738379515 -1.2357431137270427259e-07 -0.034149457045324432825" rpy="0 0 0" />
      <mass value="1.2895238899898622265" />
      <inertia ixx="0.00089621011138626548598" ixy="-1.7957438648418447173e-09" ixz="3.2112420914059141175e-05" iyy="0.0010420724953831758935" iyz="3.0492496474583046404e-09" izz="0.0010213484696825509291" />
    </inertial>
  </link>
  <link name="hip_x_2">
    <visual>
      <origin xyz="-0.0031172266567815881677 0 -0.054400000000000003908" rpy="1.570796326794896558 1.570796326794896558 0" />
      <geometry>
        <mesh filename="package:///hip_x.stl" />
      </geometry>
      <material name="hip_x_material">
        <color rgba="0.64705882352941179736 0.64705882352941179736 0.64705882352941179736 1.0" />
      </material>
    </visual>
    <collision>
      <origin xyz="-0.0031172266567815881677 0 -0.054400000000000003908" rpy="1.570796326794896558 1.570796326794896558 0" />
      <geometry>
        <mesh filename="package:///hip_x.stl" />
      </geometry>
    </collision>
    <inertial>
      <origin xyz="-0.00077940900319458219017 -8.8689441085539130503e-19 -0.04521675346357507258" rpy="0 0 0" />
      <mass value="1.4197410037164885921" />
      <inertia ixx="0.0014949229305128528423" ixy="0" ixz="-1.2476184392984388872e-05" iyy="0.0013017541081209299796" iyz="0" izz="0.00094724669336309903593" />
    </inertial>
  </link>
  <link name="hip_z_2">
    <visual>
      <origin xyz="0 0 -0.070000000000000006661" rpy="-1.570796326794896558 -0 -3.6217972674632358542e-17" />
      <geometry>
        <mesh filename="package:///hip_z.stl" />
      </geometry>
      <material name="hip_z_material">
        <color rgba="0.61568627450980395466 0.81176470588235294379 0.92941176470588238168 1.0" />
      </material>
    </visual>
    <collision>
      <origin xyz="0 0 -0.070000000000000006661" rpy="-1.570796326794896558 -0 -3.6217972674632358542e-17" />
      <geometry>
        <mesh filename="package:///hip_z.stl" />
      </geometry>
    </collision>
    <inertial>
      <origin xyz="0.060000000000000004718 -1.7372056755744265669e-18 -0.021999999999999998723" rpy="0 0 0" />
      <mass value="3.8932756153047387571" />
      <inertia ixx="0.0040205863361596509351" ixy="5.1429225604894204844e-19" ixz="0" iyy="0.014779167671256707509" iyz="0" izz="0.017543523742211363653" />
    </inertial>
  </link>
  <link name="shin_2">
    <visual>
      <origin xyz="0 -6.9388939039072283776e-18 -0.024999999999999994449" rpy="1.570796326794896558 -0 6.0456418469048474632e-17" />
      <geometry>
        <mesh filename="package:///shin.stl" />
      </geometry>
      <material name="shin_material">
        <color rgba="0.61568627450980395466 0.81176470588235294379 0.92941176470588238168 1.0" />
      </material>
    </visual>
    <collision>
      <origin xyz="0 -6.9388939039072283776e-18 -0.024999999999999994449" rpy="1.570796326794896558 -0 6.0456418469048474632e-17" />
      <geometry>
        <mesh filename="package:///shin.stl" />
      </geometry>
    </collision>
    <inertial>
      <origin xyz="0.086542930154570277268 -0.024349627108824732635 -0.024999999175739785751" rpy="0 0 0" />
      <mass value="0.5557814093331634453" />
      <inertia ixx="0.00046644066811272680414" ixy="0.00088329043391741600411" ixz="-6.3639813756520250134e-13" iyy="0.0090559095871162384461" iyz="1.1189385758839301922e-11" izz="0.0093490826129847687254" />
    </inertial>
  </link>
  <link name="tarsus_2">
    <visual>
      <origin xyz="1.3877787807814456755e-17 0.0010860176223413953167 0" rpy="-1.570796326794896558 -1.570796326794896558 0" />
      <geometry>
        <mesh filename="package:///tarsus.stl" />
      </geometry>
      <material name="tarsus_material">
        <color rgba="0.61568627450980395466 0.81176470588235294379 0.92941176470588238168 1.0" />
      </material>
    </visual>
    <collision>
      <origin xyz="1.3877787807814456755e-17 0.0010860176223413953167 0" rpy="-1.570796326794896558 -1.570796326794896558 0" />
      <geometry>
        <mesh filename="package:///tarsus.stl" />
      </geometry>
    </collision>
    <visual>
      <origin xyz="-0.061600000000000057487 -0.11491398237765870771 0" rpy="-3.141592653589793116 -1.570796326794896558 0" />
      <geometry>
        <mesh filename="package:///actuator_molet.stl" />
      </geometry>
      <material name="actuator_molet_material">
        <color rgba="0.91764705882352937127 0.91764705882352937127 0.91764705882352937127 1.0" />
      </material>
    </visual>
    <collision>
      <origin xyz="-0.061600000000000057487 -0.11491398237765870771 0" rpy="-3.141592653589793116 -1.570796326794896558 0" />
      <geometry>
        <mesh filename="package:///actuator_molet.stl" />
      </geometry>
    </collision>
    <inertial>
      <origin xyz="-0.083086291902174758128 -0.020033778925019923856 2.8736095531674428834e-08" rpy="0 0 0" />
      <mass value="0.7428461942208621771" />
      <inertia ixx="0.00039818835112512165723" ixy="-0.0005421323167350006059" ixz="-5.2637644307352848935e-10" iyy="0.007985191784274097912" iyz="1.268511613222600523e-10" izz="0.0079848716361182476425" />
    </inertial>
  </link>
  <link name="closedloop6_A">
    <inertial>
      <origin xyz="0 0 0" rpy="0 0 0" />
      <mass value="1e-9" />
      <inertia ixx="0" ixy="0" ixz="0" iyy="0" iyz="0" izz="0" />
    </inertial>
  </link>
  <joint name="closedloop6_A_frame" type="fixed">
    <origin xyz="0.11418993498637028394 0.036206749731294340933 1.3877787807814456755e-17" rpy="-1.57079632679489678 -6.5433720594048050941e-32 -7.9210684197412081021e-16" />
    <parent link="tarsus_2" />
    <child link="closedloop6_A" />
    <axis xyz="0 0 0" />
  </joint>
  <link name="foot_roll_2">
    <visual>
      <origin xyz="0.325998400000000077 0.039743999999999890527 1.249000902703301108e-16" rpy="-1.570796326794896558 -1.570796326794896336 0" />
      <geometry>
        <mesh filename="package:///foot_roll.stl" />
      </geometry>
      <material name="foot_roll_material">
        <color rgba="0.2313725490196078538 0.38039215686274507888 0.7058823529411765163 1.0" />
      </material>
    </visual>
    <collision>
      <origin xyz="0.325998400000000077 0.039743999999999890527 1.249000902703301108e-16" rpy="-1.570796326794896558 -1.570796326794896336 0" />
      <geometry>
        <mesh filename="package:///foot_roll.stl" />
      </geometry>
    </collision>
    <inertial>
      <origin xyz="-2.1851523803977209919e-08 -0.0014449033387293893586 6.7774346909514089129e-09" rpy="0 0 0" />
      <mass value="0.0027067106871796991867" />
      <inertia ixx="1.8232396912107804468e-07" ixy="1.2456494871913402661e-13" ixz="-3.0177862000950184709e-13" iyy="1.1958745424438052282e-07" iyz="4.5807687216419334289e-14" izz="1.0944659228682656112e-07" />
    </inertial>
  </link>
  <link name="foot_part_2">
    <visual>
      <origin xyz="-0.0011288304490430500771 0 0.0090799999999999769784" rpy="-1.570796326794896558 -5.3730308978757022037e-17 4.5455597141397567369e-18" />
      <geometry>
        <mesh filename="package:///foot_part.stl" />
      </geometry>
      <material name="foot_part_material">
        <color rgba="0.61568627450980395466 0.81176470588235294379 0.92941176470588238168 1.0" />
      </material>
    </visual>
    <collision>
      <origin xyz="-0.0011288304490430500771 0 0.0090799999999999769784" rpy="-1.570796326794896558 -5.3730308978757022037e-17 4.5455597141397567369e-18" />
      <geometry>
        <mesh filename="package:///foot_part.stl" />
      </geometry>
    </collision>
    <inertial>
      <origin xyz="-0.042296631354857207319 6.7228492050861193009e-10 0.006362648172333771647" rpy="0 0 0" />
      <mass value="0.3309516742025366276" />
      <inertia ixx="0.0010118322945958278195" ixy="-2.5339652211479188683e-12" ixz="0.00049446274168876594261" iyy="0.0012276801049992637146" iyz="7.2849212790886192209e-12" izz="0.00051045333461432898861" />
    </inertial>
  </link>
  <link name="foot_left">
    <inertial>
      <origin xyz="0 0 0" rpy="0 0 0" />
      <mass value="1e-9" />
      <inertia ixx="0" ixy="0" ixz="0" iyy="0" iyz="0" izz="0" />
    </inertial>
  </link>
  <joint name="foot_left_frame" type="fixed">
    <origin xyz="-0.055897619600576708976 5.6898930012039272697e-16 0.0037840702321058072854" rpy="1.9176336729514462538e-16 -1.0420837364882551412 -3.1415926535897922278" />
    <parent link="foot_part_2" />
    <child link="foot_left" />
    <axis xyz="0 0 0" />
  </joint>
  <link name="closedloop1_B">
    <inertial>
      <origin xyz="0 0 0" rpy="0 0 0" />
      <mass value="1e-9" />
      <inertia ixx="0" ixy="0" ixz="0" iyy="0" iyz="0" izz="0" />
    </inertial>
  </link>
  <joint name="closedloop1_B_frame" type="fixed">
    <origin xyz="-0.0091288304490431126936 -0.014276000000000010903 -0.034653600000000062131" rpy="-1.57079632679489678 -1.2619339181212321345e-19 1.570796326794896558" />
    <parent link="foot_part_2" />
    <child link="closedloop1_B" />
    <axis xyz="0 0 0" />
  </joint>
  <link name="closedloop2_B">
    <inertial>
      <origin xyz="0 0 0" rpy="0 0 0" />
      <mass value="1e-9" />
      <inertia ixx="0" ixy="0" ixz="0" iyy="0" iyz="0" izz="0" />
    </inertial>
  </link>
  <joint name="closedloop2_B_frame" type="fixed">
    <origin xyz="-0.0091288304490430571825 0.014275999999999941514 -0.034653600000000062131" rpy="-1.57079632679489678 -1.1265743504782139157e-18 1.570796326794896558" />
    <parent link="foot_part_2" />
    <child link="closedloop2_B" />
    <axis xyz="0 0 0" />
  </joint>
  <joint name="free_foot2_left" type="revolute">
    <origin xyz="1.1102230246251565404e-16 0.008999999999999785949 0" rpy="-1.5707963267948972241 -0.068727198803337011257 -3.1415926535897926719" />
    <parent link="foot_roll_2" />
    <child link="foot_part_2" />
    <axis xyz="0 0 1" />
    <limit effort="1" velocity="20" />
    <joint_properties friction="0.0" />
  </joint>
  <joint name="free_foot1_left" type="revolute">
    <origin xyz="-0.325998400000000077 -0.038657982377658717255 -5.5511151231257827021e-17" rpy="5.5511151231257814695e-17 2.7597873481449337343e-16 -3.1415926535897624738" />
    <parent link="tarsus_2" />
    <child link="foot_roll_2" />
    <axis xyz="0 0 1" />
    <limit effort="1" velocity="20" />
    <joint_properties friction="0.0" />
  </joint>
  <link name="crank_3">
    <visual>
      <origin xyz="0.088799999999999990052 0.027200000000000057465 0.02999999999999999889" rpy="-1.570796326794896558 -1.570796326794896558 0" />
      <geometry>
        <mesh filename="package:///crank.stl" />
      </geometry>
      <material name="crank_material">
        <color rgba="0.64705882352941179736 0.64705882352941179736 0.64705882352941179736 1.0" />
      </material>
    </visual>
    <collision>
      <origin xyz="0.088799999999999990052 0.027200000000000057465 0.02999999999999999889" rpy="-1.570796326794896558 -1.570796326794896558 0" />
      <geometry>
        <mesh filename="package:///crank.stl" />
      </geometry>
    </collision>
    <inertial>
      <origin xyz="-4.111107410308182301e-17 0.01522168021389603762 -0.00095148915120264754026" rpy="0 0 0" />
      <mass value="0.0045332434126214744829" />
      <inertia ixx="2.0190313503504425919e-06" ixy="3.6322986811028286837e-23" ixz="4.006029331603475697e-25" iyy="3.825426716084359792e-07" iyz="-9.1875323763544904139e-09" izz="2.3968139039834554417e-06" />
    </inertial>
  </link>
  <link name="toe_b_2/2_3">
    <visual>
      <origin xyz="-0.054171488011523938333 -0.043924303555988947201 -0.12000000000000005107" rpy="-1.570796326794896558 -1.570796326794896558 0" />
      <geometry>
        <mesh filename="package:///toe_b_2_2.stl" />
      </geometry>
      <material name="toe_b_2/2_material">
        <color rgba="0.64705882352941179736 0.64705882352941179736 0.64705882352941179736 1.0" />
      </material>
    </visual>
    <collision>
      <origin xyz="-0.054171488011523938333 -0.043924303555988947201 -0.12000000000000005107" rpy="-1.570796326794896558 -1.570796326794896558 0" />
      <geometry>
        <mesh filename="package:///toe_b_2_2.stl" />
      </geometry>
    </collision>
    <inertial>
      <origin xyz="-1.5265566588595902431e-16 6.9388939039072283776e-18 -0.12000000000000005107" rpy="0 0 0" />
      <mass value="0.012063715789784825241" />
      <inertia ixx="5.7954090654126310235e-05" ixy="2.5708917302264823653e-36" ixz="7.9957944336208893062e-22" iyy="5.7954090654126310235e-05" iyz="-1.0718977344588926676e-36" izz="9.6509726318278778164e-08" />
    </inertial>
  </link>
  <link name="closedloop1_A">
    <inertial>
      <origin xyz="0 0 0" rpy="0 0 0" />
      <mass value="1e-9" />
      <inertia ixx="0" ixy="0" ixz="0" iyy="0" iyz="0" izz="0" />
    </inertial>
  </link>
  <joint name="closedloop1_A_frame" type="fixed">
    <origin xyz="-1.1102230246251565404e-16 1.3877787807814456755e-17 -0.24000000000000004663" rpy="3.1415926535897851224 -4.4150077378662487332e-16 1.5707963267948958919" />
    <parent link="toe_b_2/2_3" />
    <child link="closedloop1_A" />
    <axis xyz="0 0 0" />
  </joint>
  <joint name="motor_shin1_left" type="revolute">
    <origin xyz="-0.088800000000000059441 -0.026113982377658828682 0.03000000000000169198" rpy="3.141592653589793116 -0 0.36867217991166933988" />
    <parent link="tarsus_2" />
    <child link="crank_3" />
    <axis xyz="0 0 1" />
    <limit effort="1" velocity="20" />
    <joint_properties friction="0.0" />
  </joint>
  <link name="crank_4">
    <visual>
      <origin xyz="0.088799999999999990052 0.027200000000000001954 0.029999999999999991951" rpy="-1.570796326794896558 -1.570796326794896558 0" />
      <geometry>
        <mesh filename="package:///crank.stl" />
      </geometry>
      <material name="crank_material">
        <color rgba="0.64705882352941179736 0.64705882352941179736 0.64705882352941179736 1.0" />
      </material>
    </visual>
    <collision>
      <origin xyz="0.088799999999999990052 0.027200000000000001954 0.029999999999999991951" rpy="-1.570796326794896558 -1.570796326794896558 0" />
      <geometry>
        <mesh filename="package:///crank.stl" />
      </geometry>
    </collision>
    <inertial>
      <origin xyz="-4.1647352199013102996e-17 0.015221680213895983844 -0.00095148915120265447915" rpy="0 0 0" />
      <mass value="0.0045332434126214744829" />
      <inertia ixx="2.0190313503504425919e-06" ixy="4.231007778585293478e-23" ixz="-1.0729579001757340516e-26" iyy="3.825426716084359792e-07" iyz="-9.1875323763544904139e-09" izz="2.3968139039834554417e-06" />
    </inertial>
  </link>
  <link name="toe_b_2/2_4">
    <visual>
      <origin xyz="-0.054171488011523827311 -0.043924303555988940262 -0.11999999999999999556" rpy="-1.570796326794896558 -1.570796326794896558 0" />
      <geometry>
        <mesh filename="package:///toe_b_2_2.stl" />
      </geometry>
      <material name="toe_b_2/2_material">
        <color rgba="0.64705882352941179736 0.64705882352941179736 0.64705882352941179736 1.0" />
      </material>
    </visual>
    <collision>
      <origin xyz="-0.054171488011523827311 -0.043924303555988940262 -0.11999999999999999556" rpy="-1.570796326794896558 -1.570796326794896558 0" />
      <geometry>
        <mesh filename="package:///toe_b_2_2.stl" />
      </geometry>
    </collision>
    <inertial>
      <origin xyz="-4.1633363423443382592e-17 1.3877787807814456755e-17 -0.11999999999999999556" rpy="0 0 0" />
      <mass value="0.012063715789784825241" />
      <inertia ixx="5.7954090654126310235e-05" ixy="-1.3152042543137852677e-35" ixz="-3.979340712583267787e-21" iyy="5.7954090654126310235e-05" iyz="-4.9896487390761448794e-35" izz="9.6509726318278778164e-08" />
    </inertial>
  </link>
  <link name="closedloop2_A">
    <inertial>
      <origin xyz="0 0 0" rpy="0 0 0" />
      <mass value="1e-9" />
      <inertia ixx="0" ixy="0" ixz="0" iyy="0" iyz="0" izz="0" />
    </inertial>
  </link>
  <joint name="closedloop2_A_frame" type="fixed">
    <origin xyz="-1.1102230246251565404e-16 0 -0.24000000000000004663" rpy="-3.141592653589793116 -1.3573762659468082498e-17 -1.57079632679489678" />
    <parent link="toe_b_2/2_4" />
    <child link="closedloop2_A" />
    <axis xyz="0 0 0" />
  </joint>
  <joint name="motor_shin2_left" type="revolute">
    <origin xyz="-0.088800000000000031686 -0.026113982377658606637 -0.029999999999998375189" rpy="-2.2646805033865016308e-16 -1.6559512450572042394e-16 -2.8397248482115817758" />
    <parent link="tarsus_2" />
    <child link="crank_4" />
    <axis xyz="0 0 1" />
    <limit effort="1" velocity="20" />
    <joint_properties friction="0.0" />
  </joint>
  <joint name="free_knee_left" type="revolute">
    <origin xyz="0.39567486363081372236 -0.053875166733171747646 -0.024999999999999994449" rpy="0 -0 1.570796326794896558" />
    <parent link="shin_2" />
    <child link="tarsus_2" />
    <axis xyz="0 0 1" />
    <limit effort="1" velocity="20" />
    <joint_properties friction="0.0" />
  </joint>
  <joint name="motor_knee_left" type="revolute">
    <origin xyz="0.1199999999999999678 0 1.6930901125533637241e-15" rpy="3.141592653589793116 -0 -0.55703373375772102793" />
    <parent link="hip_z_2" />
    <child link="shin_2" />
    <axis xyz="0 0 1" />
    <limit effort="1" velocity="20" />
    <joint_properties friction="0.0" />
  </joint>
  <joint name="motor_hip_y_left" type="revolute">
    <origin xyz="-0.029117226656781597383 0 -0.047379470518249228173" rpy="-1.570796326794896558 1.2655169802117200994 -1.570796326794896558" />
    <parent link="hip_x_2" />
    <child link="hip_z_2" />
    <axis xyz="0 0 1" />
    <limit effort="1" velocity="20" />
    <joint_properties friction="0.0" />
  </joint>
  <link name="toe_a_2/2_2">
    <visual>
      <origin xyz="0.056794565202878996568 -0.040773406646044459134 -0.2000000000000000111" rpy="-1.570796326794896558 -1.570796326794896558 0" />
      <geometry>
        <mesh filename="package:///toe_a_2_2.stl" />
      </geometry>
      <material name="toe_a_2/2_material">
        <color rgba="0.61568627450980395466 0.81176470588235294379 0.92941176470588238168 1.0" />
      </material>
    </visual>
    <collision>
      <origin xyz="0.056794565202878996568 -0.040773406646044459134 -0.2000000000000000111" rpy="-1.570796326794896558 -1.570796326794896558 0" />
      <geometry>
        <mesh filename="package:///toe_a_2_2.stl" />
      </geometry>
    </collision>
    <inertial>
      <origin xyz="6.9388939039072283776e-18 -6.9388939039072283776e-18 -0.2000000000000000111" rpy="0 0 0" />
      <mass value="0.031415926535897899241" />
      <inertia ixx="0.00041907537001948795856" ixy="-3.7584048815350653831e-46" ixz="1.0637546740265564334e-36" iyy="0.00041907537001948795856" iyz="-1.0637546739844378378e-36" izz="3.9269908169872326592e-07" />
    </inertial>
  </link>
  <link name="closedloop6_B">
    <inertial>
      <origin xyz="0 0 0" rpy="0 0 0" />
      <mass value="1e-9" />
      <inertia ixx="0" ixy="0" ixz="0" iyy="0" iyz="0" izz="0" />
    </inertial>
  </link>
  <joint name="closedloop6_B_frame" type="fixed">
    <origin xyz="6.9388939039072283776e-18 -6.9388939039072283776e-18 -0.4000000000000000222" rpy="-1.1071056474933263853e-28 7.1824453147824133667e-29 3.141592653589793116" />
    <parent link="toe_a_2/2_2" />
    <child link="closedloop6_B" />
    <axis xyz="0 0 0" />
  </joint>
  <joint name="motor_hip_z_left" type="revolute">
    <origin xyz="0.050000000000000016653 0 -0.035199999999999981304" rpy="1.570796326794896558 -0 -1.570796326794896558" />
    <parent link="hip_y_2" />
    <child link="hip_x_2" />
    <axis xyz="0 0 1" />
    <limit effort="1" velocity="20" />
    <joint_properties friction="0.0" />
  </joint>
  <joint name="motor_hip_x_left" type="revolute">
    <origin xyz="-0.02999999999999999889 0.072800000000000031353 0.059867854479678822566" rpy="-0 1.570796326794896558 0" />
    <parent link="torso" />
    <child link="hip_y_2" />
    <axis xyz="0 0 1" />
    <limit effort="1" velocity="20" />
    <joint_properties friction="0.0" />
  </joint>
  <link name="crank_int1_1">
    <inertial>
      <mass value="0.0" />
      <inertia ixx="0.0" ixy="0.0" ixz="0.0" iyy="0.0" iyz="0.0" izz="0.0" />
    </inertial>
  </link>
  <link name="crank_int2_1">
    <inertial>
      <mass value="0.0" />
      <inertia ixx="0.0" ixy="0.0" ixz="0.0" iyy="0.0" iyz="0.0" izz="0.0" />
    </inertial>
  </link>
  <joint name="crank_toe_b_2/2_rev0" type="revolute">
    <origin xyz="0 0.056999999999999939604 0.0025000000000000091593" />
    <parent link="crank" />
    <child link="crank_int1_1" />
    <axis xyz="1 0 0" />
    <limit effort="1" velocity="20" />
  </joint>
  <joint name="crank_toe_b_2/2_rev1" type="revolute">
    <parent link="crank_int1_1" />
    <child link="crank_int2_1" />
    <axis xyz="0 1 0" />
    <limit effort="1" velocity="20" />
  </joint>
  <joint name="crank_toe_b_2/2_rev2" type="revolute">
    <parent link="crank_int2_1" />
    <child link="toe_b_2/2" />
    <axis xyz="0 0 1" />
    <limit effort="1" velocity="20" />
  </joint>
  <link name="crank_2_int1_2">
    <inertial>
      <mass value="0.0" />
      <inertia ixx="0.0" ixy="0.0" ixz="0.0" iyy="0.0" iyz="0.0" izz="0.0" />
    </inertial>
  </link>
  <link name="crank_2_int2_2">
    <inertial>
      <mass value="0.0" />
      <inertia ixx="0.0" ixy="0.0" ixz="0.0" iyy="0.0" iyz="0.0" izz="0.0" />
    </inertial>
  </link>
  <joint name="crank_2_toe_b_2/2_2_rev0" type="revolute">
    <origin xyz="5.5511151231257827021e-17 0.056999999999999939604 0.0024999999999999467093" />
    <parent link="crank_2" />
    <child link="crank_2_int1_2" />
    <axis xyz="1 0 0" />
    <limit effort="1" velocity="20" />
  </joint>
  <joint name="crank_2_toe_b_2/2_2_rev1" type="revolute">
    <parent link="crank_2_int1_2" />
    <child link="crank_2_int2_2" />
    <axis xyz="0 1 0" />
    <limit effort="1" velocity="20" />
  </joint>
  <joint name="crank_2_toe_b_2/2_2_rev2" type="revolute">
    <parent link="crank_2_int2_2" />
    <child link="toe_b_2/2_2" />
    <axis xyz="0 0 1" />
    <limit effort="1" velocity="20" />
  </joint>
  <link name="hip_x_int1_3">
    <inertial>
      <mass value="0.0" />
      <inertia ixx="0.0" ixy="0.0" ixz="0.0" iyy="0.0" iyz="0.0" izz="0.0" />
    </inertial>
  </link>
  <link name="hip_x_int2_3">
    <inertial>
      <mass value="0.0" />
      <inertia ixx="0.0" ixy="0.0" ixz="0.0" iyy="0.0" iyz="0.0" izz="0.0" />
    </inertial>
  </link>
  <joint name="hip_x_toe_a_2/2_rev0" type="revolute">
    <origin xyz="0.033686000000000014543 2.7755575615628913511e-17 -0.054399999999999996969" />
    <parent link="hip_x" />
    <child link="hip_x_int1_3" />
    <axis xyz="1 0 0" />
    <limit effort="1" velocity="20" />
  </joint>
  <joint name="hip_x_toe_a_2/2_rev1" type="revolute">
    <parent link="hip_x_int1_3" />
    <child link="hip_x_int2_3" />
    <axis xyz="0 1 0" />
    <limit effort="1" velocity="20" />
  </joint>
  <joint name="hip_x_toe_a_2/2_rev2" type="revolute">
    <parent link="hip_x_int2_3" />
    <child link="toe_a_2/2" />
    <axis xyz="0 0 1" />
    <limit effort="1" velocity="20" />
  </joint>
  <link name="crank_3_int1_4">
    <inertial>
      <mass value="0.0" />
      <inertia ixx="0.0" ixy="0.0" ixz="0.0" iyy="0.0" iyz="0.0" izz="0.0" />
    </inertial>
  </link>
  <link name="crank_3_int2_4">
    <inertial>
      <mass value="0.0" />
      <inertia ixx="0.0" ixy="0.0" ixz="0.0" iyy="0.0" iyz="0.0" izz="0.0" />
    </inertial>
  </link>
  <joint name="crank_3_toe_b_2/2_3_rev0" type="revolute">
    <origin xyz="1.6653345369377348106e-16 0.057000000000000106137 0.0025000000000000022204" />
    <parent link="crank_3" />
    <child link="crank_3_int1_4" />
    <axis xyz="1 0 0" />
    <limit effort="1" velocity="20" />
  </joint>
  <joint name="crank_3_toe_b_2/2_3_rev1" type="revolute">
    <parent link="crank_3_int1_4" />
    <child link="crank_3_int2_4" />
    <axis xyz="0 1 0" />
    <limit effort="1" velocity="20" />
  </joint>
  <joint name="crank_3_toe_b_2/2_3_rev2" type="revolute">
    <parent link="crank_3_int2_4" />
    <child link="toe_b_2/2_3" />
    <axis xyz="0 0 1" />
    <limit effort="1" velocity="20" />
  </joint>
  <link name="crank_4_int1_5">
    <inertial>
      <mass value="0.0" />
      <inertia ixx="0.0" ixy="0.0" ixz="0.0" iyy="0.0" iyz="0.0" izz="0.0" />
    </inertial>
  </link>
  <link name="crank_4_int2_5">
    <inertial>
      <mass value="0.0" />
      <inertia ixx="0.0" ixy="0.0" ixz="0.0" iyy="0.0" iyz="0.0" izz="0.0" />
    </inertial>
  </link>
  <joint name="crank_4_toe_b_2/2_4_rev0" type="revolute">
    <origin xyz="-1.6653345369377348106e-16 0.056999999999999939604 0.0024999999999999952816" />
    <parent link="crank_4" />
    <child link="crank_4_int1_5" />
    <axis xyz="1 0 0" />
    <limit effort="1" velocity="20" />
  </joint>
  <joint name="crank_4_toe_b_2/2_4_rev1" type="revolute">
    <parent link="crank_4_int1_5" />
    <child link="crank_4_int2_5" />
    <axis xyz="0 1 0" />
    <limit effort="1" velocity="20" />
  </joint>
  <joint name="crank_4_toe_b_2/2_4_rev2" type="revolute">
    <parent link="crank_4_int2_5" />
    <child link="toe_b_2/2_4" />
    <axis xyz="0 0 1" />
    <limit effort="1" velocity="20" />
  </joint>
  <link name="hip_x_2_int1_6">
    <inertial>
      <mass value="0.0" />
      <inertia ixx="0.0" ixy="0.0" ixz="0.0" iyy="0.0" iyz="0.0" izz="0.0" />
    </inertial>
  </link>
  <link name="hip_x_2_int2_6">
    <inertial>
      <mass value="0.0" />
      <inertia ixx="0.0" ixy="0.0" ixz="0.0" iyy="0.0" iyz="0.0" izz="0.0" />
    </inertial>
  </link>
  <joint name="hip_x_2_toe_a_2/2_2_rev0" type="revolute">
    <origin xyz="0.030568773343218426375 0 -0.054400000000000017786" />
    <parent link="hip_x_2" />
    <child link="hip_x_2_int1_6" />
    <axis xyz="1 0 0" />
    <limit effort="1" velocity="20" />
  </joint>
  <joint name="hip_x_2_toe_a_2/2_2_rev1" type="revolute">
    <parent link="hip_x_2_int1_6" />
    <child link="hip_x_2_int2_6" />
    <axis xyz="0 1 0" />
    <limit effort="1" velocity="20" />
  </joint>
  <joint name="hip_x_2_toe_a_2/2_2_rev2" type="revolute">
    <parent link="hip_x_2_int2_6" />
    <child link="toe_a_2/2_2" />
    <axis xyz="0 0 1" />
    <limit effort="1" velocity="20" />
  </joint>
</robot>
