<robot name="onshape">
<link name="hanche_batis_gauche">
<visual>
<origin xyz="0.018000000000003173184 0.52649999999999996803 -0.94000000000000016875" rpy="-3.0121599956385240381e-42 -4.5021244384580876102e-15 -8.9790747947209470253e-29" />
<geometry>
<mesh filename="package:///hanche_batis_gauche.stl"/>
</geometry>
<material name="hanche_batis_gauche_material">
<color rgba="0.61568627450980395466 0.81176470588235294379 0.92941176470588238168 1.0"/>
</material>
</visual>
<collision>
<origin xyz="0.018000000000003173184 0.52649999999999996803 -0.94000000000000016875" rpy="-3.0121599956385240381e-42 -4.5021244384580876102e-15 -8.9790747947209470253e-29" />
<geometry>
<mesh filename="package:///hanche_batis_gauche.stl"/>
</geometry>
</collision>
<inertial>
<origin xyz="-0.0014786115366823872341 0.12234575313934131779 0.024304995635825329264" rpy="0 0 0"/>
<mass value="1.5865591647149870358" />
<inertia ixx="0.0088382827967695681143" ixy="-0.00027487762182023519958"  ixz="-2.9207645496747368895e-05" iyy="0.0025754201921632980006" iyz="-6.885840799262295947e-05" izz="0.010752178054608367563" />
</inertial>
</link>

<link name="hanche_gauche">
<visual>
<origin xyz="0.0055000000000023745172 0.48149999999999998357 -0.93500000000000027534" rpy="-3.3280069439011435541e-31 -3.6701587590914506434e-15 -1.7765336303158987701e-18" />
<geometry>
<mesh filename="package:///hanche_gauche.stl"/>
</geometry>
<material name="hanche_gauche_material">
<color rgba="0.2313725490196078538 0.38039215686274507888 0.7058823529411765163 1.0"/>
</material>
</visual>
<collision>
<origin xyz="0.0055000000000023745172 0.48149999999999998357 -0.93500000000000027534" rpy="-3.3280069439011435541e-31 -3.6701587590914506434e-15 -1.7765336303158987701e-18" />
<geometry>
<mesh filename="package:///hanche_gauche.stl"/>
</geometry>
</collision>
<inertial>
<origin xyz="-4.802391351775570083e-09 -0.0030510712498241776558 -0.083365235886017852174" rpy="0 0 0"/>
<mass value="0.14908820308432116364" />
<inertia ixx="0.00035636864608480205976" ixy="1.5243715372082467329e-10"  ixz="3.20834605899060082e-10" iyy="0.00032228378845976208373" iyz="1.6655090320431488362e-05" izz="4.9201075862855858688e-05" />
</inertial>
</link>

<link name="cardan_foot">
<visual>
<origin xyz="0 0.038499999999999978684 -6.6000000000000086375e-05" rpy="1.570796326794896558 1.570796326794896558 0" />
<geometry>
<mesh filename="package:///cardan_foot.stl"/>
</geometry>
<material name="cardan_foot_material">
<color rgba="0.64705882352941179736 0.64705882352941179736 0.64705882352941179736 1.0"/>
</material>
</visual>
<collision>
<origin xyz="0 0.038499999999999978684 -6.6000000000000086375e-05" rpy="1.570796326794896558 1.570796326794896558 0" />
<geometry>
<mesh filename="package:///cardan_foot.stl"/>
</geometry>
</collision>
<inertial>
<origin xyz="6.7228290681228176484e-09 -2.0816681711721685133e-17 -6.599327717093125649e-05" rpy="0 0 0"/>
<mass value="0.0064135211594024202353" />
<inertia ixx="3.3475011343990655066e-07" ixy="-2.8486583237315313981e-12"  ixz="4.18217495851782041e-25" iyy="4.3082408299805979528e-07" iyz="2.84865832377020088e-12" izz="3.3475011343990649772e-07" />
</inertial>
</link>

<link name="part_1_gauche">
<visual>
<origin xyz="5.5511151231257827021e-17 2.7755575615628913511e-17 0.077000000000000012879" rpy="-1.570796326794896558 -1.570796326794896558 0" />
<geometry>
<mesh filename="package:///part_1_gauche.stl"/>
</geometry>
<material name="part_1_gauche_material">
<color rgba="0.34901960784313723618 0.37647058823529411242 0.4000000000000000222 1.0"/>
</material>
</visual>
<collision>
<origin xyz="5.5511151231257827021e-17 2.7755575615628913511e-17 0.077000000000000012879" rpy="-1.570796326794896558 -1.570796326794896558 0" />
<geometry>
<mesh filename="package:///part_1_gauche.stl"/>
</geometry>
</collision>
<inertial>
<origin xyz="0.0067026040073146107498 -0.016607315579005108713 -0.045523329336489407049" rpy="0 0 0"/>
<mass value="0.24432174482850427255" />
<inertia ixx="0.00038002986506503223796" ixy="4.5343822748855145202e-05"  ixz="0.00019115477820551995567" iyy="0.0006326280548785063497" iyz="-7.0096671205036674532e-05" izz="0.00036002210136874563534" />
</inertial>
</link>

<link name="closedloop13_B_3D">
<inertial>
<origin xyz="0 0 0" rpy="0 0 0" />
<mass value="1e-9" />
<inertia ixx="0" ixy="0" ixz="0" iyy="0" iyz="0" izz="0" />
</inertial>
</link>
<joint name="closedloop13_B_3D_frame" type="fixed">
<origin xyz="0.083867056794542482745 0.0077119035015027481705 -0.071500000000000007994" rpy="1.570796326794896558 2.8360520648029955147e-19 -3.141592653589793116" />
<parent link="part_1_gauche" />
<child link="closedloop13_B_3D" />
<axis xyz="0 0 0"/>
</joint>

<link name="piston">
<visual>
<origin xyz="-0.10179556944408765795 0.15392457132099857109 -0.8579999999999999849" rpy="-3.1656865451889511115e-20 -2.3850006220383799507e-18 1.4320802785837140017e-18" />
<geometry>
<mesh filename="package:///piston.stl"/>
</geometry>
<material name="piston_material">
<color rgba="0.91764705882352937127 0.91764705882352937127 0.91764705882352937127 1.0"/>
</material>
</visual>
<collision>
<origin xyz="-0.10179556944408765795 0.15392457132099857109 -0.8579999999999999849" rpy="-3.1656865451889511115e-20 -2.3850006220383799507e-18 1.4320802785837140017e-18" />
<geometry>
<mesh filename="package:///piston.stl"/>
</geometry>
</collision>
<inertial>
<origin xyz="-1.3877787807814456755e-17 5.5705445537144774065e-17 -0.011000000000000120792" rpy="0 0 0"/>
<mass value="0.0047041422996690132607" />
<inertia ixx="2.6977766073778920841e-07" ixy="4.7576912976430433783e-25"  ixz="5.7761950872428089888e-25" iyy="2.6977766073778931429e-07" iyz="6.2927429588504482299e-28" izz="1.6008784263561083015e-07" />
</inertial>
</link>

<link name="closedloop17_A_6D">
<inertial>
<origin xyz="0 0 0" rpy="0 0 0" />
<mass value="1e-9" />
<inertia ixx="0" ixy="0" ixz="0" iyy="0" iyz="0" izz="0" />
</inertial>
</link>
<joint name="closedloop17_A_6D_frame" type="fixed">
<origin xyz="1.3877787807814456755e-17 3.6429192995512948983e-17 -0.022000000000000075051" rpy="-3.141592653589793116 2.3850006220383799507e-18 -3.141592653589793116" />
<parent link="piston" />
<child link="closedloop17_A_6D" />
<axis xyz="0 0 0"/>
</joint>

<joint name="free_spherical_hip_xy_1_left" type="revolute">
<origin xyz="-0.060499999999999970468 -2.7755575615628913511e-17 -0.038500000000000013378" rpy="1.570796326794896558 9.8397440977066039283e-15 -9.8885767237220441916e-16" />
<parent link="part_1_gauche" />
<child link="piston" />
<axis xyz="0 0 1"/>
<limit effort="1" velocity="20" />
<joint_properties friction="0.0"/>
</joint>

<link name="piston_2">
<visual>
<origin xyz="-0.10179556944408768571 0.15392457132099851558 -0.8579999999999999849" rpy="3.7955060752504929268e-20 -8.5472555591560846729e-19 1.5313784291649802482e-18" />
<geometry>
<mesh filename="package:///piston.stl"/>
</geometry>
<material name="piston_material">
<color rgba="0.91764705882352937127 0.91764705882352937127 0.91764705882352937127 1.0"/>
</material>
</visual>
<collision>
<origin xyz="-0.10179556944408768571 0.15392457132099851558 -0.8579999999999999849" rpy="3.7955060752504929268e-20 -8.5472555591560846729e-19 1.5313784291649802482e-18" />
<geometry>
<mesh filename="package:///piston.stl"/>
</geometry>
</collision>
<inertial>
<origin xyz="-2.7755575615628913511e-17 1.210568847405046729e-19 -0.011000000000000120792" rpy="0 0 0"/>
<mass value="0.0047041422996690132607" />
<inertia ixx="2.6977766073778931429e-07" ixy="-2.5462583608141386913e-25"  ixz="-5.6807608842621988086e-25" iyy="2.6977766073778931429e-07" iyz="3.6562346635282140529e-27" izz="1.6008784263561083015e-07" />
</inertial>
</link>

<link name="closedloop18_A_6D">
<inertial>
<origin xyz="0 0 0" rpy="0 0 0" />
<mass value="1e-9" />
<inertia ixx="0" ixy="0" ixz="0" iyy="0" iyz="0" izz="0" />
</inertial>
</link>
<joint name="closedloop18_A_6D_frame" type="fixed">
<origin xyz="-2.7755575615628913511e-17 1.3877787807814456755e-17 -0.021999999999999964029" rpy="-3.141592653589793116 -7.7893742605831685744e-18 1.5311910373604695636e-18" />
<parent link="piston_2" />
<child link="closedloop18_A_6D" />
<axis xyz="0 0 0"/>
</joint>

<joint name="free_spherical_hipxy_2_left" type="revolute">
<origin xyz="-0.060499999999999984346 1.1102230246251565404e-16 0.038500000000000013378" rpy="-1.57079632679489678 -1.021615604280151078e-14 3.1415926535897908956" />
<parent link="part_1_gauche" />
<child link="piston_2" />
<axis xyz="0 0 1"/>
<limit effort="1" velocity="20" />
<joint_properties friction="0.0"/>
</joint>

<link name="part_2">
<visual>
<origin xyz="-2.3453461395206431916e-15 0.046752000000001542324 -0.071500000000000007994" rpy="-1.570796326794896558 -1.570796326794896558 0" />
<geometry>
<mesh filename="package:///part_2.stl"/>
</geometry>
<material name="part_2_material">
<color rgba="0.76862745098039220171 0.88627450980392152857 0.95294117647058818044 1.0"/>
</material>
</visual>
<collision>
<origin xyz="-2.3453461395206431916e-15 0.046752000000001542324 -0.071500000000000007994" rpy="-1.570796326794896558 -1.570796326794896558 0" />
<geometry>
<mesh filename="package:///part_2.stl"/>
</geometry>
</collision>
<inertial>
<origin xyz="-0.10353133038219139439 -0.14056766472890799835 -5.9850735478761397551e-13" rpy="0 0 0"/>
<mass value="0.39806472503371781446" />
<inertia ixx="0.0031977111359881450064" ixy="-0.001858846357492638943"  ixz="5.7043183100435970654e-15" iyy="0.0012912945788078693775" iyz="2.6363833129184601927e-14" izz="0.0044624680664483223555" />
</inertial>
</link>

<link name="part_3">
<visual>
<origin xyz="0.21747050071614926203 0.38247000862966429313 -0.071500000000000007994" rpy="-1.570796326794896558 -1.570796326794896558 0" />
<geometry>
<mesh filename="package:///part_3.stl"/>
</geometry>
<material name="part_3_material">
<color rgba="0.76862745098039220171 0.88627450980392152857 0.95294117647058818044 1.0"/>
</material>
</visual>
<collision>
<origin xyz="0.21747050071614926203 0.38247000862966429313 -0.071500000000000007994" rpy="-1.570796326794896558 -1.570796326794896558 0" />
<geometry>
<mesh filename="package:///part_3.stl"/>
</geometry>
</collision>
<inertial>
<origin xyz="0.1060893883547637806 -0.17986935727287678422 -1.3877787807814456755e-17" rpy="0 0 0"/>
<mass value="0.2021348089396567127" />
<inertia ixx="0.0018459328059746533349" ixy="0.0012583807608323397537"  ixz="-1.9880712633219774471e-22" iyy="0.00088797005323680837808" iyz="3.7356998984883330555e-22" izz="0.0027204272052821516087" />
</inertial>
</link>

<link name="cardan_foot_2">
<visual>
<origin xyz="0 0.038500000000000089706 6.6000000000010494716e-05" rpy="1.570796326794896558 1.570796326794896558 0" />
<geometry>
<mesh filename="package:///cardan_foot.stl"/>
</geometry>
<material name="cardan_foot_material">
<color rgba="0.64705882352941179736 0.64705882352941179736 0.64705882352941179736 1.0"/>
</material>
</visual>
<collision>
<origin xyz="0 0.038500000000000089706 6.6000000000010494716e-05" rpy="1.570796326794896558 1.570796326794896558 0" />
<geometry>
<mesh filename="package:///cardan_foot.stl"/>
</geometry>
</collision>
<inertial>
<origin xyz="6.7228290677842898468e-09 9.0205620750793956583e-17 6.6006722829076505676e-05" rpy="0 0 0"/>
<mass value="0.0064135211594024202353" />
<inertia ixx="3.3475011343990644478e-07" ixy="-2.8486583237202630817e-12"  ixz="5.2783708372310716773e-25" iyy="4.3082408299805979528e-07" iyz="2.8486583238102779423e-12" izz="3.3475011343990649772e-07" />
</inertial>
</link>

<link name="foot">
<visual>
<origin xyz="0 0.038499999999999978684 -1.3877787807814456755e-17" rpy="1.570796326794896558 3.9343514738443138783e-18 7.8541465883003997931e-18" />
<geometry>
<mesh filename="package:///foot.stl"/>
</geometry>
<material name="foot_material">
<color rgba="0.61568627450980395466 0.81176470588235294379 0.92941176470588238168 1.0"/>
</material>
</visual>
<collision>
<origin xyz="0 0.038499999999999978684 -1.3877787807814456755e-17" rpy="1.570796326794896558 3.9343514738443138783e-18 7.8541465883003997931e-18" />
<geometry>
<mesh filename="package:///foot.stl"/>
</geometry>
</collision>
<inertial>
<origin xyz="-0.0036358817134152219587 0.02496644936992965455 9.0007330144478898714e-08" rpy="0 0 0"/>
<mass value="0.31091298222930185968" />
<inertia ixx="0.00026328612588329922692" ixy="-5.3028311481376195049e-05"  ixz="-1.7872776046536212582e-09" iyy="0.00071897520566115982136" iyz="-2.0903095188096233269e-10" izz="0.00052661427618999395381" />
</inertial>
</link>

<link name="foot_left">
<inertial>
<origin xyz="0 0 0" rpy="0 0 0" />
<mass value="1e-9" />
<inertia ixx="0" ixy="0" ixz="0" iyy="0" iyz="0" izz="0" />
</inertial>
</link>
<joint name="foot_left_frame" type="fixed">
<origin xyz="0.012016949221079764598 0.038499999999999923173 6.8117394363964578474e-09" rpy="1.5707963267948974462 -1.4061551475580533876e-17 1.3040345811105885313e-15" />
<parent link="foot" />
<child link="foot_left" />
<axis xyz="0 0 0"/>
</joint>

<link name="closedloop21_A_3D">
<inertial>
<origin xyz="0 0 0" rpy="0 0 0" />
<mass value="1e-9" />
<inertia ixx="0" ixy="0" ixz="0" iyy="0" iyz="0" izz="0" />
</inertial>
</link>
<joint name="closedloop21_A_3D_frame" type="fixed">
<origin xyz="-0.054999999999999937828 -0.01100000000000000977 -0.038500000000000006439" rpy="1.570796326794896558 5.5775440709909559897e-17 -1.5707963267948958919" />
<parent link="foot" />
<child link="closedloop21_A_3D" />
<axis xyz="0 0 0"/>
</joint>

<link name="closedloop22_A_3D">
<inertial>
<origin xyz="0 0 0" rpy="0 0 0" />
<mass value="1e-9" />
<inertia ixx="0" ixy="0" ixz="0" iyy="0" iyz="0" izz="0" />
</inertial>
</link>
<joint name="closedloop22_A_3D_frame" type="fixed">
<origin xyz="-0.054999999999999993339 -0.01100000000000000977 0.038499999999999992562" rpy="1.570796326794896558 5.5775440709909559897e-17 -1.5707963267948958919" />
<parent link="foot" />
<child link="closedloop22_A_3D" />
<axis xyz="0 0 0"/>
</joint>

<joint name="free_ankle_universal_x_left" type="revolute">
<origin xyz="6.6000000000010494716e-05 2.2204460492503130808e-16 6.5999999999954983565e-05" rpy="-1.570796326794896558 -0.99367489314673695944 -1.57079632679489678" />
<parent link="cardan_foot_2" />
<child link="foot" />
<axis xyz="0 0 1"/>
<limit effort="1" velocity="20" />
<joint_properties friction="0.0"/>
</joint>

<joint name="free_universal_y_foot_left" type="revolute">
<origin xyz="0.21747050071614942857 -0.33571800862966399981 -3.4694469519536141888e-18" rpy="-1.5707963267948958919 -1.4835298641951766285 1.5707963267949331954" />
<parent link="part_3" />
<child link="cardan_foot_2" />
<axis xyz="0 0 1"/>
<limit effort="1" velocity="20" />
<joint_properties friction="0.0"/>
</joint>

<link name="part_6">
<visual>
<origin xyz="0.10788167727912303939 -0.039150197130724581629 5.5511151231257827021e-17" rpy="-3.141592653589793116 1.0115724044382810845e-18 -3.2099959913854695587e-17" />
<geometry>
<mesh filename="package:///part_6.stl"/>
</geometry>
<material name="part_6_material">
<color rgba="0.76862745098039220171 0.88627450980392152857 0.95294117647058818044 1.0"/>
</material>
</visual>
<collision>
<origin xyz="0.10788167727912303939 -0.039150197130724581629 5.5511151231257827021e-17" rpy="-3.141592653589793116 1.0115724044382810845e-18 -3.2099959913854695587e-17" />
<geometry>
<mesh filename="package:///part_6.stl"/>
</geometry>
</collision>
<inertial>
<origin xyz="5.5511151231257827021e-17 -4.0448913005911551404e-18 -0.21359999999999998432" rpy="0 0 0"/>
<mass value="0.033552209540339043847" />
<inertia ixx="0.00051048244070615617519" ixy="1.572380772545045121e-21"  ixz="-4.9754200853304337008e-22" iyy="0.00051048244070615639203" iyz="8.8597101295436671043e-21" izz="4.1940261925423882626e-07" />
</inertial>
</link>

<link name="closedloop12_A_3D">
<inertial>
<origin xyz="0 0 0" rpy="0 0 0" />
<mass value="1e-9" />
<inertia ixx="0" ixy="0" ixz="0" iyy="0" iyz="0" izz="0" />
</inertial>
</link>
<joint name="closedloop12_A_3D_frame" type="fixed">
<origin xyz="5.5511151231257827021e-17 0 -0.42720000000000002416" rpy="-3.141592653589793116 -4.5932359763492642923e-17 -1.035331779239029349e-16" />
<parent link="part_6" />
<child link="closedloop12_A_3D" />
<axis xyz="0 0 0"/>
</joint>

<joint name="spherical_shin_left" type="revolute">
<origin xyz="0.038967453687049735667 -0.092095263467496746301 -6.9388939039072283776e-18" rpy="-1.570796326794896558 0.34266875905739935249 1.5707963267948972241" />
<parent link="part_3" />
<child link="part_6" />
<axis xyz="0 0 1"/>
<limit effort="1" velocity="20" />
<joint_properties friction="0.0"/>
</joint>

<joint name="lower_knee_left" type="revolute">
<origin xyz="-0.2174705007161515935 -0.33571800862966272305 -3.4694469519536141888e-18" rpy="-3.6654208353707214918e-17 7.4236255477340962066e-17 0.89630439304597309125" />
<parent link="part_2" />
<child link="part_3" />
<axis xyz="0 0 1"/>
<limit effort="1" velocity="20" />
<joint_properties friction="0.0"/>
</joint>

<link name="renvois_cheville_2_8">
<visual>
<origin xyz="-0.11549999999999997768 -0.35749999999999992895 0.033000000000000001554" rpy="-1.570796326794896558 -8.416253686631036033e-19 9.6344801354933481419e-18" />
<geometry>
<mesh filename="package:///renvois_cheville_2_8.stl"/>
</geometry>
<material name="renvois_cheville_2_8_material">
<color rgba="0.91764705882352937127 0.91764705882352937127 0.91764705882352937127 1.0"/>
</material>
</visual>
<collision>
<origin xyz="-0.11549999999999997768 -0.35749999999999992895 0.033000000000000001554" rpy="-1.570796326794896558 -8.416253686631036033e-19 9.6344801354933481419e-18" />
<geometry>
<mesh filename="package:///renvois_cheville_2_8.stl"/>
</geometry>
</collision>
<inertial>
<origin xyz="-0.033596086250149245767 -0.018380744757818923141 -0.014122199558543433937" rpy="0 0 0"/>
<mass value="0.074310320490072731547" />
<inertia ixx="4.1295450354366541358e-05" ixy="1.9886051938184650641e-06"  ixz="-2.0689202263474869013e-06" iyy="3.2625641947312141421e-05" iyz="-9.9798202174584469521e-06" izz="5.1310129727252684509e-05" />
</inertial>
</link>

<link name="closedloop23_B_3D">
<inertial>
<origin xyz="0 0 0" rpy="0 0 0" />
<mass value="1e-9" />
<inertia ixx="0" ixy="0" ixz="0" iyy="0" iyz="0" izz="0" />
</inertial>
</link>
<joint name="closedloop23_B_3D_frame" type="fixed">
<origin xyz="-0.035854717888628866163 -0.039206584673488142911 -0.051749999999999990452" rpy="-1.57079632679489678 -8.5717888844702030861e-19 3.3378249364540351951e-17" />
<parent link="renvois_cheville_2_8" />
<child link="closedloop23_B_3D" />
<axis xyz="0 0 0"/>
</joint>

<link name="part_7">
<visual>
<origin xyz="0.062087559207389952931 0.15255026628033757641 -3.1225022567582527699e-17" rpy="3.141592653589793116 -3.204311919789308906e-17 -4.7514684857837923291e-17" />
<geometry>
<mesh filename="package:///part_7.stl"/>
</geometry>
<material name="part_7_material">
<color rgba="0.91764705882352937127 0.91764705882352937127 0.91764705882352937127 1.0"/>
</material>
</visual>
<collision>
<origin xyz="0.062087559207389952931 0.15255026628033757641 -3.1225022567582527699e-17" rpy="3.141592653589793116 -3.204311919789308906e-17 -4.7514684857837923291e-17" />
<geometry>
<mesh filename="package:///part_7.stl"/>
</geometry>
</collision>
<inertial>
<origin xyz="1.3183898417423733918e-16 -6.435323453913125862e-19 -0.20000000000000003886" rpy="0 0 0"/>
<mass value="0.031415926535897982508" />
<inertia ixx="0.00041907537001948915118" ixy="-3.5711065707240252405e-20"  ixz="1.33929676115569031e-20" iyy="0.00041907537001948904276" iyz="-3.8738049171293025859e-21" izz="3.9269908169872548938e-07" />
</inertial>
</link>

<link name="closedloop22_B_3D">
<inertial>
<origin xyz="0 0 0" rpy="0 0 0" />
<mass value="1e-9" />
<inertia ixx="0" ixy="0" ixz="0" iyy="0" iyz="0" izz="0" />
</inertial>
</link>
<joint name="closedloop22_B_3D_frame" type="fixed">
<origin xyz="2.2204460492503130808e-16 -2.7755575615628913511e-17 -0.4000000000000000222" rpy="3.1415926535897913396 1.3112097711421770153e-15 -1.570796326794896558" />
<parent link="part_7" />
<child link="closedloop22_B_3D" />
<axis xyz="0 0 0"/>
</joint>

<joint name="spherical_transmission_foot2_left" type="revolute">
<origin xyz="-0.059494699261975370064 0.010983203527527130028 -0.02200000000000001607" rpy="-1.57079632679489678 0.26749612184641674562 -1.570796326794896558" />
<parent link="renvois_cheville_2_8" />
<child link="part_7" />
<axis xyz="0 0 1"/>
<limit effort="1" velocity="20" />
<joint_properties friction="0.0"/>
</joint>

<joint name="transmission_1_knee_left" type="revolute">
<origin xyz="-0.21747050071615153799 -0.33571800862966272305 0.0099999999999999741873" rpy="3.1415926535897922278 2.5607839141882122881e-15 3.0182803045709212242" />
<parent link="part_2" />
<child link="renvois_cheville_2_8" />
<axis xyz="0 0 1"/>
<limit effort="1" velocity="20" />
<joint_properties friction="0.0"/>
</joint>

<link name="renvois_cheville">
<visual>
<origin xyz="-0.1155000000000001581 -0.35750000000000003997 -0.032999999999999952982" rpy="-1.570796326794896558 9.7008393832270241853e-20 2.2223766996000520932e-17" />
<geometry>
<mesh filename="package:///renvois_cheville.stl"/>
</geometry>
<material name="renvois_cheville_material">
<color rgba="0.91764705882352937127 0.91764705882352937127 0.91764705882352937127 1.0"/>
</material>
</visual>
<collision>
<origin xyz="-0.1155000000000001581 -0.35750000000000003997 -0.032999999999999952982" rpy="-1.570796326794896558 9.7008393832270241853e-20 2.2223766996000520932e-17" />
<geometry>
<mesh filename="package:///renvois_cheville.stl"/>
</geometry>
</collision>
<inertial>
<origin xyz="-0.033596086592530965964 -0.018380744754187328116 0.014122199609931570738" rpy="0 0 0"/>
<mass value="0.074310321213953547947" />
<inertia ixx="4.1295450352451941965e-05" ixy="1.9886053203183274036e-06"  ixz="2.0689203249184063097e-06" iyy="3.2625642523550451148e-05" iyz="9.9798202218794608814e-06" izz="5.1310130219953352371e-05" />
</inertial>
</link>

<link name="closedloop20_B_3D">
<inertial>
<origin xyz="0 0 0" rpy="0 0 0" />
<mass value="1e-9" />
<inertia ixx="0" ixy="0" ixz="0" iyy="0" iyz="0" izz="0" />
</inertial>
</link>
<joint name="closedloop20_B_3D_frame" type="fixed">
<origin xyz="-0.035854717888629046574 -0.041706584673488200643 0.052250000000000053346" rpy="1.570796326794896558 -7.9018780590913059168e-20 -3.1415926535897908956" />
<parent link="renvois_cheville" />
<child link="closedloop20_B_3D" />
<axis xyz="0 0 0"/>
</joint>

<link name="part_7_2">
<visual>
<origin xyz="0.062087559207389841909 -0.15255026628033757641 -0.39999999999999996669" rpy="-2.6749056103516416041e-17 -9.0260321641607935627e-18 9.3397346100936950488e-18" />
<geometry>
<mesh filename="package:///part_7.stl"/>
</geometry>
<material name="part_7_material">
<color rgba="0.91764705882352937127 0.91764705882352937127 0.91764705882352937127 1.0"/>
</material>
</visual>
<collision>
<origin xyz="0.062087559207389841909 -0.15255026628033757641 -0.39999999999999996669" rpy="-2.6749056103516416041e-17 -9.0260321641607935627e-18 9.3397346100936950488e-18" />
<geometry>
<mesh filename="package:///part_7.stl"/>
</geometry>
</collision>
<inertial>
<origin xyz="-1.3877787807814456755e-17 2.3630011051865765497e-17 -0.19999999999999995559" rpy="0 0 0"/>
<mass value="0.031415926535897982508" />
<inertia ixx="0.00041907537001948915118" ixy="-5.8333481257422858175e-21"  ixz="3.7871950114621784818e-21" iyy="0.00041907537001948915118" iyz="-1.1216832517011349971e-20" izz="3.9269908169872548938e-07" />
</inertial>
</link>

<link name="closedloop21_B_3D">
<inertial>
<origin xyz="0 0 0" rpy="0 0 0" />
<mass value="1e-9" />
<inertia ixx="0" ixy="0" ixz="0" iyy="0" iyz="0" izz="0" />
</inertial>
</link>
<joint name="closedloop21_B_3D_frame" type="fixed">
<origin xyz="-5.5511151231257827021e-17 0 -0.39999999999999996669" rpy="3.1415926535897895633 -3.6738326735530833518e-16 1.57079632679489678" />
<parent link="part_7_2" />
<child link="closedloop21_B_3D" />
<axis xyz="0 0 0"/>
</joint>

<joint name="spherical_transmission_foot1_left" type="revolute">
<origin xyz="-0.059494699261975619864 0.010983203527527019006 0.022000000000000040357" rpy="1.570796326794896558 -0.30096768397183631949 1.5707963267948978903" />
<parent link="renvois_cheville" />
<child link="part_7_2" />
<axis xyz="0 0 1"/>
<limit effort="1" velocity="20" />
<joint_properties friction="0.0"/>
</joint>

<joint name="transmission_2_knee_left" type="revolute">
<origin xyz="-0.2174705007161515935 -0.33571800862966272305 -0.01000000000000001929" rpy="3.1415926535897926719 2.4170968488441313662e-15 3.0435251672843857129" />
<parent link="part_2" />
<child link="renvois_cheville" />
<axis xyz="0 0 1"/>
<limit effort="1" velocity="20" />
<joint_properties friction="0.0"/>
</joint>

<link name="part_4">
<visual>
<origin xyz="-0.010530049701071103607 0.092146047735299219106 -0.071500000000000007994" rpy="-1.570796326794896558 -1.570796326794896558 0" />
<geometry>
<mesh filename="package:///part_4.stl"/>
</geometry>
<material name="part_4_material">
<color rgba="1 0.7568627450980391913 0.054901960784313724728 1.0"/>
</material>
</visual>
<collision>
<origin xyz="-0.010530049701071103607 0.092146047735299219106 -0.071500000000000007994" rpy="-1.570796326794896558 -1.570796326794896558 0" />
<geometry>
<mesh filename="package:///part_4.stl"/>
</geometry>
</collision>
<inertial>
<origin xyz="0.019483726843524843547 -0.046047631733748289884 1.3877787807814456755e-17" rpy="0 0 0"/>
<mass value="0.011311035579799528367" />
<inertia ixx="1.0009836990585408185e-05" ixy="4.1536946028868310457e-06"  ixz="7.349384890333274783e-24" iyy="1.9505556032253759876e-06" iyz="-2.2602910710935867714e-23" izz="1.1771875334147456995e-05" />
</inertial>
</link>

<link name="closedloop12_B_3D">
<inertial>
<origin xyz="0 0 0" rpy="0 0 0" />
<mass value="1e-9" />
<inertia ixx="0" ixy="0" ixz="0" iyy="0" iyz="0" izz="0" />
</inertial>
</link>
<joint name="closedloop12_B_3D_frame" type="fixed">
<origin xyz="0.038967453687049735667 -0.09209526346749669079 -6.9388939039072283776e-18" rpy="-1.57079632679489678 -6.0039660859700073265e-22 -3.141592653589793116" />
<parent link="part_4" />
<child link="closedloop12_B_3D" />
<axis xyz="0 0 0"/>
</joint>

<link name="part_5">
<visual>
<origin xyz="0.063404956281616783875 0.05332211252813562341 -5.5511151231257827021e-17" rpy="3.141592653589793116 1.8929769196227808674e-20 8.5029241607180082452e-18" />
<geometry>
<mesh filename="package:///part_5.stl"/>
</geometry>
<material name="part_5_material">
<color rgba="0.91764705882352937127 0.91764705882352937127 0.91764705882352937127 1.0"/>
</material>
</visual>
<collision>
<origin xyz="0.063404956281616783875 0.05332211252813562341 -5.5511151231257827021e-17" rpy="3.141592653589793116 1.8929769196227808674e-20 8.5029241607180082452e-18" />
<geometry>
<mesh filename="package:///part_5.stl"/>
</geometry>
</collision>
<inertial>
<origin xyz="0 -1.441676109982018556e-17 -0.070710000000000050591" rpy="0 0 0"/>
<mass value="0.011107100826766714077" />
<inertia ixx="1.8580899034455386872e-05" ixy="6.4669638289153321219e-22"  ixz="-3.4977565557575417623e-25" iyy="1.8580899034455386872e-05" iyz="-1.1427841314747034335e-25" izz="1.3883876033458398932e-07" />
</inertial>
</link>

<link name="closedloop13_A_3D">
<inertial>
<origin xyz="0 0 0" rpy="0 0 0" />
<mass value="1e-9" />
<inertia ixx="0" ixy="0" ixz="0" iyy="0" iyz="0" izz="0" />
</inertial>
</link>
<joint name="closedloop13_A_3D_frame" type="fixed">
<origin xyz="-1.3877787807814456755e-17 -3.4694469519536141888e-18 -0.14141999999999999016" rpy="-3.141592653589793116 1.2734996606920880132e-19 8.5029346353481308663e-18" />
<parent link="part_5" />
<child link="closedloop13_A_3D" />
<axis xyz="0 0 0"/>
</joint>

<joint name="spherical_4rod_left" type="revolute">
<origin xyz="0.0194837268435249511 -0.046047631733748352334 -6.9388939039072283776e-18" rpy="1.57079632679489678 0.15824418733945430637 1.5707963267948952257" />
<parent link="part_4" />
<child link="part_5" />
<axis xyz="0 0 1"/>
<limit effort="1" velocity="20" />
<joint_properties friction="0.0"/>
</joint>

<joint name="4rof_knee_left" type="revolute">
<origin xyz="0.046047631733746000049 -0.019483726843523313521 -1.7347234759768070944e-17" rpy="3.141592653589793116 4.5795419413634097813e-17 -0.96785189103621938056" />
<parent link="part_2" />
<child link="part_4" />
<axis xyz="0 0 1"/>
<limit effort="1" velocity="20" />
<joint_properties friction="0.0"/>
</joint>

<link name="motteur_rotation">
<visual>
<origin xyz="0.033000000000000022371 0.88825000000000031708 -0.10449999999999906586" rpy="1.570796326794896558 1.5707963267948930053 0" />
<geometry>
<mesh filename="package:///motteur_rotation.stl"/>
</geometry>
<material name="motteur_rotation_material">
<color rgba="1 0 0 1.0"/>
</material>
</visual>
<collision>
<origin xyz="0.033000000000000022371 0.88825000000000031708 -0.10449999999999906586" rpy="1.570796326794896558 1.5707963267948930053 0" />
<geometry>
<mesh filename="package:///motteur_rotation.stl"/>
</geometry>
</collision>
<inertial>
<origin xyz="3.4489992683069327506e-18 -2.2204460492503130808e-16 -0.017243243243243264184" rpy="0 0 0"/>
<mass value="0.19339251676417060222" />
<inertia ixx="4.9207470246053541048e-05" ixy="-1.4090980805227676913e-21"  ixz="-6.5737888733283339633e-23" iyy="4.9207470246053561377e-05" iyz="-5.4178635252453810392e-20" izz="3.3697502678236647725e-05" />
</inertial>
</link>

<link name="piston_3">
<visual>
<origin xyz="-0.10179556944408768571 0.15392457132099854333 -0.8579999999999999849" rpy="8.1919716478217444844e-17 -7.5134827251522585907e-18 -4.6592019168490059564e-17" />
<geometry>
<mesh filename="package:///piston.stl"/>
</geometry>
<material name="piston_material">
<color rgba="0.91764705882352937127 0.91764705882352937127 0.91764705882352937127 1.0"/>
</material>
</visual>
<collision>
<origin xyz="-0.10179556944408768571 0.15392457132099854333 -0.8579999999999999849" rpy="8.1919716478217444844e-17 -7.5134827251522585907e-18 -4.6592019168490059564e-17" />
<geometry>
<mesh filename="package:///piston.stl"/>
</geometry>
</collision>
<inertial>
<origin xyz="0 1.3177951169464814068e-17 -0.011000000000000120792" rpy="0 0 0"/>
<mass value="0.0047041422996690132607" />
<inertia ixx="2.6977766073778942017e-07" ixy="-1.7236985204873094513e-23"  ixz="3.2683670574201498267e-24" iyy="2.6977766073778931429e-07" iyz="2.0241282982431402136e-23" izz="1.6008784263561083015e-07" />
</inertial>
</link>

<link name="closedloop16_B_6D">
<inertial>
<origin xyz="0 0 0" rpy="0 0 0" />
<mass value="1e-9" />
<inertia ixx="0" ixy="0" ixz="0" iyy="0" iyz="0" izz="0" />
</inertial>
</link>
<joint name="closedloop16_B_6D_frame" type="fixed">
<origin xyz="-2.7755575615628913511e-17 -2.7755575615628913511e-17 -0.022000000000000033418" rpy="3.141592653589793116 1.5080939153133216998e-16 -1.57079632679489678" />
<parent link="piston_3" />
<child link="closedloop16_B_6D" />
<axis xyz="0 0 0"/>
</joint>

<joint name="motor_knee_left" type="prismatic">
<origin xyz="4.8572257327350598644e-17 -2.498001805406602216e-16 0.0086304170048060457887" rpy="3.141592653589793116 -2.5197765118340936491e-15 -2.1135107621004381678e-15" />
<parent link="motteur_rotation" />
<child link="piston_3" />
<axis xyz="0 0 1"/>
<limit effort="1" velocity="20" />
<joint_properties friction="0.0"/>
</joint>

<joint name="free_motor_knee_left" type="revolute">
<origin xyz="-0.061655078133537488672 -0.018724201373191667885 4.2973298530757375602e-12" rpy="-1.570796326794896558 1.3873492000155343007 -0.60601731071219677727" />
<parent link="part_2" />
<child link="motteur_rotation" />
<axis xyz="0 0 1"/>
<limit effort="1" velocity="20" />
<joint_properties friction="0.0"/>
</joint>

<joint name="upper_knee_left" type="revolute">
<origin xyz="2.0469737016526323714e-16 -0.046752000000000043523 -0.071499999999999980238" rpy="-5.7342617493489877044e-15 7.864783300419491944e-15 -0.63853922414920383233" />
<parent link="part_1_gauche" />
<child link="part_2" />
<axis xyz="0 0 1"/>
<limit effort="1" velocity="20" />
<joint_properties friction="0.0"/>
</joint>

<link name="part_8">
<visual>
<origin xyz="2.7755575615628913511e-17 -0.046752000000000001889 0.088000000000000008771" rpy="1.570796326794896558 1.570796326794896558 0" />
<geometry>
<mesh filename="package:///part_8.stl"/>
</geometry>
<material name="part_8_material">
<color rgba="0.49803921568627451677 0.49803921568627451677 0.49803921568627451677 1.0"/>
</material>
</visual>
<collision>
<origin xyz="2.7755575615628913511e-17 -0.046752000000000001889 0.088000000000000008771" rpy="1.570796326794896558 1.570796326794896558 0" />
<geometry>
<mesh filename="package:///part_8.stl"/>
</geometry>
</collision>
<inertial>
<origin xyz="0.031934770108260200627 0.010733820853410659668 -0.0056648401062836120992" rpy="0 0 0"/>
<mass value="0.0062040903886272725024" />
<inertia ixx="9.1742111640422057722e-07" ixy="-1.6316603808924177561e-07"  ixz="2.2769789117187736485e-07" iyy="1.3280669465102744511e-06" iyz="-1.4783479338790844283e-07" izz="1.7548720440932142221e-06" />
</inertial>
</link>

<link name="piston_4">
<visual>
<origin xyz="-0.10179556944408767183 -0.15392457132099851558 0.83599999999999996536" rpy="-3.141592653589793116 1.729017174857427777e-18 -7.3393565422645404042e-18" />
<geometry>
<mesh filename="package:///piston.stl"/>
</geometry>
<material name="piston_material">
<color rgba="0.91764705882352937127 0.91764705882352937127 0.91764705882352937127 1.0"/>
</material>
</visual>
<collision>
<origin xyz="-0.10179556944408767183 -0.15392457132099851558 0.83599999999999996536" rpy="-3.141592653589793116 1.729017174857427777e-18 -7.3393565422645404042e-18" />
<geometry>
<mesh filename="package:///piston.stl"/>
</geometry>
</collision>
<inertial>
<origin xyz="-4.1633363423443370266e-17 4.0593190806305950242e-17 -0.011000000000000120792" rpy="0 0 0"/>
<mass value="0.0047041422996690132607" />
<inertia ixx="2.6977766073778920841e-07" ixy="1.3106852984997507412e-24"  ixz="3.164401275255547335e-24" iyy="2.6977766073778931429e-07" iyz="1.4890398336540349657e-23" izz="1.6008784263561088309e-07" />
</inertial>
</link>

<link name="closedloop14_A_6D">
<inertial>
<origin xyz="0 0 0" rpy="0 0 0" />
<mass value="1e-9" />
<inertia ixx="0" ixy="0" ixz="0" iyy="0" iyz="0" izz="0" />
</inertial>
</link>
<joint name="closedloop14_A_6D_frame" type="fixed">
<origin xyz="-6.9388939039072283776e-18 0 -0.022000000000000033418" rpy="-3.141592653589793116 8.9294959238987079639e-17 -1.570796326794896558" />
<parent link="piston_4" />
<child link="closedloop14_A_6D" />
<axis xyz="0 0 0"/>
</joint>

<joint name="spherical_motor_transmission_hip1_left" type="revolute">
<origin xyz="0.043531328479973735446 0.0032046566522410946387 -0.025000000000000001388" rpy="1.5707963267948970021 -1.3881446540757400587 -3.1415926535897527039" />
<parent link="part_8" />
<child link="piston_4" />
<axis xyz="0 0 1"/>
<limit effort="1" velocity="20" />
<joint_properties friction="0.0"/>
</joint>

<link name="part_7_3">
<visual>
<origin xyz="0.062087559207389786398 -0.15255026628033763192 -0.4000000000000000222" rpy="-1.0950595030595913441e-17 -2.822674850981358798e-18 7.9670936357162291903e-17" />
<geometry>
<mesh filename="package:///part_7.stl"/>
</geometry>
<material name="part_7_material">
<color rgba="0.91764705882352937127 0.91764705882352937127 0.91764705882352937127 1.0"/>
</material>
</visual>
<collision>
<origin xyz="0.062087559207389786398 -0.15255026628033763192 -0.4000000000000000222" rpy="-1.0950595030595913441e-17 -2.822674850981358798e-18 7.9670936357162291903e-17" />
<geometry>
<mesh filename="package:///part_7.stl"/>
</geometry>
</collision>
<inertial>
<origin xyz="-6.9388939039072283776e-17 -2.2544911738620224768e-17 -0.19999999999999992784" rpy="0 0 0"/>
<mass value="0.031415926535897982508" />
<inertia ixx="0.00041907537001948936802" ixy="3.156905280987031676e-20"  ixz="1.1905617978476639346e-21" iyy="0.00041907537001948915118" iyz="-4.5691809744889147681e-21" izz="3.9269908169872580702e-07" />
</inertial>
</link>

<link name="closedloop23_A_3D">
<inertial>
<origin xyz="0 0 0" rpy="0 0 0" />
<mass value="1e-9" />
<inertia ixx="0" ixy="0" ixz="0" iyy="0" iyz="0" izz="0" />
</inertial>
</link>
<joint name="closedloop23_A_3D_frame" type="fixed">
<origin xyz="-5.5511151231257827021e-17 -5.5511151231257827021e-17 -0.39999999999999991118" rpy="2.0595706521359607965e-16 6.9689394429105795176e-16 -3.8311948294342778263e-16" />
<parent link="part_7_3" />
<child link="closedloop23_A_3D" />
<axis xyz="0 0 0"/>
</joint>

<joint name="spherical_transmission_hip3_left" type="revolute">
<origin xyz="0.041074543378118943959 0.03657706776491291556 -0.0049999999999999888284" rpy="-1.570796326794896558 0.6730343672339298422 3.1415926535897922278" />
<parent link="part_8" />
<child link="part_7_3" />
<axis xyz="0 0 1"/>
<limit effort="1" velocity="20" />
<joint_properties friction="0.0"/>
</joint>

<joint name="transmission_ankle3_left" type="revolute">
<origin xyz="6.2450045135165055399e-17 -0.046751999999999988011 -0.055000000000000014155" rpy="-3.1415926535897895633 -4.799310970213847672e-16 -1.2495340742674121426" />
<parent link="part_1_gauche" />
<child link="part_8" />
<axis xyz="0 0 1"/>
<limit effort="1" velocity="20" />
<joint_properties friction="0.0"/>
</joint>

<link name="part_9">
<visual>
<origin xyz="0 0.046752000000000022706 -0.055000000000000007216" rpy="-1.570796326794896558 -1.570796326794896558 0" />
<geometry>
<mesh filename="package:///part_9.stl"/>
</geometry>
<material name="part_9_material">
<color rgba="0.49803921568627451677 0.49803921568627451677 0.49803921568627451677 1.0"/>
</material>
</visual>
<collision>
<origin xyz="0 0.046752000000000022706 -0.055000000000000007216" rpy="-1.570796326794896558 -1.570796326794896558 0" />
<geometry>
<mesh filename="package:///part_9.stl"/>
</geometry>
</collision>
<inertial>
<origin xyz="0.031934770108260165933 -0.010733820853410619769 -0.0056648401062835904152" rpy="0 0 0"/>
<mass value="0.0062040903886272699003" />
<inertia ixx="9.1742111640423370623e-07" ixy="1.631660380892437079e-07"  ixz="2.2769789117187747073e-07" iyy="1.3280669465102729688e-06" iyz="1.4783479338790947515e-07" izz="1.7548720440932269276e-06" />
</inertial>
</link>

<link name="piston_5">
<visual>
<origin xyz="-0.10179556944408765795 -0.15392457132099848782 0.83599999999999985434" rpy="-3.141592653589793116 -3.9622424591774593143e-18 -1.1316281187079200426e-16" />
<geometry>
<mesh filename="package:///piston.stl"/>
</geometry>
<material name="piston_material">
<color rgba="0.91764705882352937127 0.91764705882352937127 0.91764705882352937127 1.0"/>
</material>
</visual>
<collision>
<origin xyz="-0.10179556944408765795 -0.15392457132099848782 0.83599999999999985434" rpy="-3.141592653589793116 -3.9622424591774593143e-18 -1.1316281187079200426e-16" />
<geometry>
<mesh filename="package:///piston.stl"/>
</geometry>
</collision>
<inertial>
<origin xyz="-1.3877787807814456755e-17 6.1394057265580892168e-17 -0.01100000000000000977" rpy="0 0 0"/>
<mass value="0.0047041422996690132607" />
<inertia ixx="2.6977766073778931429e-07" ixy="-3.9899519034092998659e-23"  ixz="3.4276797045403196699e-24" iyy="2.6977766073778931429e-07" iyz="2.957220630684091271e-24" izz="1.6008784263561083015e-07" />
</inertial>
</link>

<link name="closedloop15_B_6D">
<inertial>
<origin xyz="0 0 0" rpy="0 0 0" />
<mass value="1e-9" />
<inertia ixx="0" ixy="0" ixz="0" iyy="0" iyz="0" izz="0" />
</inertial>
</link>
<joint name="closedloop15_B_6D_frame" type="fixed">
<origin xyz="6.9388939039072283776e-18 0 -0.022000000000000047296" rpy="2.9668696099179873576e-15 -1.6282746472828449155e-16 1.570796326794896558" />
<parent link="piston_5" />
<child link="closedloop15_B_6D" />
<axis xyz="0 0 0"/>
</joint>

<joint name="spherical_motor_transmission_hip2_left" type="revolute">
<origin xyz="0.043531328479973624423 -0.0032046566522409697386 -0.025000000000000022204" rpy="1.570796326794896558 -1.0520766825141725231 -6.564748380207484938e-15" />
<parent link="part_9" />
<child link="piston_5" />
<axis xyz="0 0 1"/>
<limit effort="1" velocity="20" />
<joint_properties friction="0.0"/>
</joint>

<link name="part_7_4">
<visual>
<origin xyz="0.062087559207389800275 -0.15255026628033757641 -0.40000000000000013323" rpy="-6.6465450688821020531e-18 -3.1318090323893008049e-17 -6.892538942352151265e-17" />
<geometry>
<mesh filename="package:///part_7.stl"/>
</geometry>
<material name="part_7_material">
<color rgba="0.91764705882352937127 0.91764705882352937127 0.91764705882352937127 1.0"/>
</material>
</visual>
<collision>
<origin xyz="0.062087559207389800275 -0.15255026628033757641 -0.40000000000000013323" rpy="-6.6465450688821020531e-18 -3.1318090323893008049e-17 -6.892538942352151265e-17" />
<geometry>
<mesh filename="package:///part_7.stl"/>
</geometry>
</collision>
<inertial>
<origin xyz="-3.4694469519536141888e-17 -4.272583000033597957e-19 -0.20000000000000009437" rpy="0 0 0"/>
<mass value="0.031415926535897982508" />
<inertia ixx="0.00041907537001948915118" ixy="5.9098471533384866476e-21"  ixz="1.3120526768239785891e-20" iyy="0.00041907537001948904276" iyz="-2.794644854112111064e-21" izz="3.9269908169872559526e-07" />
</inertial>
</link>

<link name="closedloop20_A_3D">
<inertial>
<origin xyz="0 0 0" rpy="0 0 0" />
<mass value="1e-9" />
<inertia ixx="0" ixy="0" ixz="0" iyy="0" iyz="0" izz="0" />
</inertial>
</link>
<joint name="closedloop20_A_3D_frame" type="fixed">
<origin xyz="-8.3266726846886740532e-17 -5.5511151231257827021e-17 -0.4000000000000000222" rpy="-2.2514125294094559383e-15 -8.4956633181430522698e-16 -1.5707963267948974462" />
<parent link="part_7_4" />
<child link="closedloop20_A_3D" />
<axis xyz="0 0 0"/>
</joint>

<joint name="spherical_transmission_hip4_left" type="revolute">
<origin xyz="0.04107454337811874967 -0.036577067764912860048 -0.004999999999999997502" rpy="1.57079632679489678 0.73924967494909110677 3.1415926535897900074" />
<parent link="part_9" />
<child link="part_7_4" />
<axis xyz="0 0 1"/>
<limit effort="1" velocity="20" />
<joint_properties friction="0.0"/>
</joint>

<joint name="transmission_ankle4_left" type="revolute">
<origin xyz="4.5102810375396984455e-17 -0.046752000000000043523 -0.087999999999999981015" rpy="-8.8738167568813836499e-15 3.5840702149163616535e-15 -1.2172645625817111181" />
<parent link="part_1_gauche" />
<child link="part_9" />
<axis xyz="0 0 1"/>
<limit effort="1" velocity="20" />
<joint_properties friction="0.0"/>
</joint>

<link name="piston_6">
<visual>
<origin xyz="-0.10179556944408765795 0.15392457132099851558 -0.8579999999999999849" rpy="-1.1895523874973306693e-18 -8.670466646602893662e-20 -6.339097647909028305e-20" />
<geometry>
<mesh filename="package:///piston.stl"/>
</geometry>
<material name="piston_material">
<color rgba="0.91764705882352937127 0.91764705882352937127 0.91764705882352937127 1.0"/>
</material>
</visual>
<collision>
<origin xyz="-0.10179556944408765795 0.15392457132099851558 -0.8579999999999999849" rpy="-1.1895523874973306693e-18 -8.670466646602893662e-20 -6.339097647909028305e-20" />
<geometry>
<mesh filename="package:///piston.stl"/>
</geometry>
</collision>
<inertial>
<origin xyz="-1.3877787807814456755e-17 2.7797948334426820481e-17 -0.011000000000000120792" rpy="0 0 0"/>
<mass value="0.0047041422996690132607" />
<inertia ixx="2.6977766073778920841e-07" ixy="-2.5963264231247240457e-26"  ixz="8.1458446484490216416e-26" iyy="2.6977766073778920841e-07" iyz="-3.116863354320632873e-25" izz="1.6008784263561083015e-07" />
</inertial>
</link>

<link name="closedloop16_A_6D">
<inertial>
<origin xyz="0 0 0" rpy="0 0 0" />
<mass value="1e-9" />
<inertia ixx="0" ixy="0" ixz="0" iyy="0" iyz="0" izz="0" />
</inertial>
</link>
<joint name="closedloop16_A_6D_frame" type="fixed">
<origin xyz="0 3.1225022567582527699e-17 -0.022000000000000012601" rpy="-1.1895523874969165944e-18 2.1422087479376391186e-18 -6.3367552503614883775e-20" />
<parent link="piston_6" />
<child link="closedloop16_A_6D" />
<axis xyz="0 0 0"/>
</joint>

<joint name="spherical_actuation_knee_left" type="revolute">
<origin xyz="-0.013749999999999866496 -0.0024999999999999467093 -0.070874999999999993561" rpy="1.570796326794896558 8.9605786434077115269e-17 1.570796326794896558" />
<parent link="part_1_gauche" />
<child link="piston_6" />
<axis xyz="0 0 1"/>
<limit effort="1" velocity="20" />
<joint_properties friction="0.0"/>
</joint>

<link name="motteur_rotation_2">
<visual>
<origin xyz="0.033000000000000043188 0.8882500000000004281 -0.10449999999999909361" rpy="1.570796326794896558 1.5707963267948930053 0" />
<geometry>
<mesh filename="package:///motteur_rotation.stl"/>
</geometry>
<material name="motteur_rotation_material">
<color rgba="1 0 0 1.0"/>
</material>
</visual>
<collision>
<origin xyz="0.033000000000000043188 0.8882500000000004281 -0.10449999999999909361" rpy="1.570796326794896558 1.5707963267948930053 0" />
<geometry>
<mesh filename="package:///motteur_rotation.stl"/>
</geometry>
</collision>
<inertial>
<origin xyz="6.7776551054426007923e-18 -1.1102230246251565404e-16 -0.017243243243243264184" rpy="0 0 0"/>
<mass value="0.19339251676417060222" />
<inertia ixx="4.9207470246053541048e-05" ixy="-8.7495559152149869836e-25"  ixz="-7.4366206771373923627e-22" iyy="4.9207470246053561377e-05" iyz="-5.6954716546359656641e-20" izz="3.3697502678236647725e-05" />
</inertial>
</link>

<link name="piston_7">
<visual>
<origin xyz="-0.10179556944408765795 -0.15392457132099854333 0.83600000000000007638" rpy="-3.141592653589793116 -1.7519114479165284573e-17 1.0865763940504849066e-19" />
<geometry>
<mesh filename="package:///piston.stl"/>
</geometry>
<material name="piston_material">
<color rgba="0.91764705882352937127 0.91764705882352937127 0.91764705882352937127 1.0"/>
</material>
</visual>
<collision>
<origin xyz="-0.10179556944408765795 -0.15392457132099854333 0.83600000000000007638" rpy="-3.141592653589793116 -1.7519114479165284573e-17 1.0865763940504849066e-19" />
<geometry>
<mesh filename="package:///piston.stl"/>
</geometry>
</collision>
<inertial>
<origin xyz="-1.3877787807814456755e-17 -7.5631028023240160557e-19 -0.010999999999999787725" rpy="0 0 0"/>
<mass value="0.0047041422996690132607" />
<inertia ixx="2.6977766073778931429e-07" ixy="3.1555968671790727877e-26"  ixz="6.2852674308455590666e-24" iyy="2.6977766073778942017e-07" iyz="3.1728214643463944243e-25" izz="1.6008784263561083015e-07" />
</inertial>
</link>

<link name="closedloop15_A_6D">
<inertial>
<origin xyz="0 0 0" rpy="0 0 0" />
<mass value="1e-9" />
<inertia ixx="0" ixy="0" ixz="0" iyy="0" iyz="0" izz="0" />
</inertial>
</link>
<joint name="closedloop15_A_6D_frame" type="fixed">
<origin xyz="-2.7755575615628913511e-17 -1.3877787807814456755e-17 -0.021999999999999964029" rpy="6.3846877427644474244e-19 -1.6649989410368488151e-17 1.05387434053115508e-20" />
<parent link="piston_7" />
<child link="closedloop15_A_6D" />
<axis xyz="0 0 0"/>
</joint>

<joint name="motor_ankle2_left" type="prismatic">
<origin xyz="-6.9388939039072283776e-16 -5.5511151231257827021e-17 0.036860927393517817219" rpy="-3.141592653589793116 -2.3101201183360073099e-15 -3.1415926535897829019" />
<parent link="motteur_rotation_2" />
<child link="piston_7" />
<axis xyz="0 0 1"/>
<limit effort="1" velocity="20" />
<joint_properties friction="0.0"/>
</joint>

<joint name="frame_motor_ankle1_left" type="revolute">
<origin xyz="0.054086706326755308594 -0.014047405294960818578 -0.11824999999999991074" rpy="1.570796326794896558 0.014238452528742229219 -0.28589337779933110539" />
<parent link="part_1_gauche" />
<child link="motteur_rotation_2" />
<axis xyz="0 0 1"/>
<limit effort="1" velocity="20" />
<joint_properties friction="0.0"/>
</joint>

<link name="motteur_rotation_3">
<visual>
<origin xyz="0.03300000000000002931 0.88825000000000031708 -0.10449999999999906586" rpy="1.570796326794896558 1.5707963267948930053 0" />
<geometry>
<mesh filename="package:///motteur_rotation.stl"/>
</geometry>
<material name="motteur_rotation_material">
<color rgba="1 0 0 1.0"/>
</material>
</visual>
<collision>
<origin xyz="0.03300000000000002931 0.88825000000000031708 -0.10449999999999906586" rpy="1.570796326794896558 1.5707963267948930053 0" />
<geometry>
<mesh filename="package:///motteur_rotation.stl"/>
</geometry>
</collision>
<inertial>
<origin xyz="2.4864595424146665267e-18 0 -0.017243243243243236429" rpy="0 0 0"/>
<mass value="0.19339251676417060222" />
<inertia ixx="4.9207470246053527495e-05" ixy="-8.8802052300489174928e-25"  ixz="5.3479905312539600055e-22" iyy="4.9207470246053534272e-05" iyz="-5.6916377208839698039e-20" izz="3.3697502678236647725e-05" />
</inertial>
</link>

<link name="piston_8">
<visual>
<origin xyz="-0.10179556944408765795 -0.15392457132099851558 0.83599999999999985434" rpy="-3.141592653589793116 -1.0116207585356170845e-17 4.4851798576174026014e-20" />
<geometry>
<mesh filename="package:///piston.stl"/>
</geometry>
<material name="piston_material">
<color rgba="0.91764705882352937127 0.91764705882352937127 0.91764705882352937127 1.0"/>
</material>
</visual>
<collision>
<origin xyz="-0.10179556944408765795 -0.15392457132099851558 0.83599999999999985434" rpy="-3.141592653589793116 -1.0116207585356170845e-17 4.4851798576174026014e-20" />
<geometry>
<mesh filename="package:///piston.stl"/>
</geometry>
</collision>
<inertial>
<origin xyz="-4.1633363423443370266e-17 1.0027591844113009849e-18 -0.010999999999999898748" rpy="0 0 0"/>
<mass value="0.0047041422996690132607" />
<inertia ixx="2.6977766073778931429e-07" ixy="-2.2934741445462381156e-26"  ixz="1.1000951998528327118e-23" iyy="2.6977766073778931429e-07" iyz="-1.3873998892925104301e-25" izz="1.6008784263561077721e-07" />
</inertial>
</link>

<link name="closedloop14_B_6D">
<inertial>
<origin xyz="0 0 0" rpy="0 0 0" />
<mass value="1e-9" />
<inertia ixx="0" ixy="0" ixz="0" iyy="0" iyz="0" izz="0" />
</inertial>
</link>
<joint name="closedloop14_B_6D_frame" type="fixed">
<origin xyz="2.7755575615628913511e-17 0 -0.022000000000000047296" rpy="-1.8505714609404598692e-19 -1.6770242961476544053e-17 -3.141592653589793116" />
<parent link="piston_8" />
<child link="closedloop14_B_6D" />
<axis xyz="0 0 0"/>
</joint>

<joint name="motor_ankle1_left" type="prismatic">
<origin xyz="-6.8001160258290838101e-16 1.249000902703301108e-16 0.041658869056533737174" rpy="3.141592653589793116 1.0794107117225389546e-14 -3.1415926535897873428" />
<parent link="motteur_rotation_3" />
<child link="piston_8" />
<axis xyz="0 0 1"/>
<limit effort="1" velocity="20" />
<joint_properties friction="0.0"/>
</joint>

<joint name="frame_motor_ankle2_left" type="revolute">
<origin xyz="0.054086706326755280838 -0.014047405294960763067 -0.024750000000000119127" rpy="-1.570796326794896558 -0.014238452528742286465 2.8556992757904868796" />
<parent link="part_1_gauche" />
<child link="motteur_rotation_3" />
<axis xyz="0 0 1"/>
<limit effort="1" velocity="20" />
<joint_properties friction="0.0"/>
</joint>

<joint name="free_universal_y_hip_left" type="revolute">
<origin xyz="-6.5999999999961922459e-05 -2.7755575615628913511e-17 -6.5999999999998351652e-05" rpy="-1.5707963267951692288 -1.5358146150088003434 1.5707963267951787767" />
<parent link="cardan_foot" />
<child link="part_1_gauche" />
<axis xyz="0 0 1"/>
<limit effort="1" velocity="20" />
<joint_properties friction="0.0"/>
</joint>

<joint name="free_universal_x_hip_left" type="revolute">
<origin xyz="0 -9.0205620750793968909e-17 -0.1649999999999999245" rpy="1.570796326794896558 8.3262389442822325955e-18 -1.570796326794896558" />
<parent link="hanche_gauche" />
<child link="cardan_foot" />
<axis xyz="0 0 1"/>
<limit effort="1" velocity="20" />
<joint_properties friction="0.0"/>
</joint>

<link name="piston_9">
<visual>
<origin xyz="-0.10179556944408765795 0.15392457132099848782 -0.8579999999999999849" rpy="1.5474172226998211273e-18 4.6132340954022002067e-32 -4.9556328700879128894e-32" />
<geometry>
<mesh filename="package:///piston.stl"/>
</geometry>
<material name="piston_material">
<color rgba="0.91764705882352937127 0.91764705882352937127 0.91764705882352937127 1.0"/>
</material>
</visual>
<collision>
<origin xyz="-0.10179556944408765795 0.15392457132099848782 -0.8579999999999999849" rpy="1.5474172226998211273e-18 4.6132340954022002067e-32 -4.9556328700879128894e-32" />
<geometry>
<mesh filename="package:///piston.stl"/>
</geometry>
</collision>
<inertial>
<origin xyz="0 -3.3200554815540407224e-19 -0.011000000000000120792" rpy="0 0 0"/>
<mass value="0.0047041422996690132607" />
<inertia ixx="2.6977766073778931429e-07" ixy="-5.3204262414505280686e-38"  ixz="-3.6632008201976058109e-38" iyy="2.6977766073778920841e-07" iyz="3.5470765171629107134e-25" izz="1.6008784263561083015e-07" />
</inertial>
</link>

<link name="closedloop19_B_6D">
<inertial>
<origin xyz="0 0 0" rpy="0 0 0" />
<mass value="1e-9" />
<inertia ixx="0" ixy="0" ixz="0" iyy="0" iyz="0" izz="0" />
</inertial>
</link>
<joint name="closedloop19_B_6D_frame" type="fixed">
<origin xyz="0 7.8062556418956319249e-18 -0.021999999999999908518" rpy="-3.1415926535897820138 1.3686361436822294661e-14 1.570796326794896558" />
<parent link="piston_9" />
<child link="closedloop19_B_6D" />
<axis xyz="0 0 0"/>
</joint>

<joint name="spherical_free_hip_left" type="revolute">
<origin xyz="3.1537272793258352976e-15 -0.03850000000000006195 -0.046750000000000027645" rpy="2.1518574910359218682e-16 1.5707963267948954478 0" />
<parent link="hanche_gauche" />
<child link="piston_9" />
<axis xyz="0 0 1"/>
<limit effort="1" velocity="20" />
<joint_properties friction="0.0"/>
</joint>

<link name="cardan_hache">
<visual>
<origin xyz="0.10862499999999999933 0.85800000000000009592 -0.0055000000000023710478" rpy="1.570796326794896558 1.5707963267948930053 0" />
<geometry>
<mesh filename="package:///cardan_hache.stl"/>
</geometry>
<material name="cardan_hache_material">
<color rgba="0.49803921568627451677 0.49803921568627451677 0.49803921568627451677 1.0"/>
</material>
</visual>
<collision>
<origin xyz="0.10862499999999999933 0.85800000000000009592 -0.0055000000000023710478" rpy="1.570796326794896558 1.5707963267948930053 0" />
<geometry>
<mesh filename="package:///cardan_hache.stl"/>
</geometry>
</collision>
<inertial>
<origin xyz="-1.5850003394303151431e-17 1.5061396574367336143e-11 -0.034629677480538467726" rpy="0 0 0"/>
<mass value="0.015608633111865791165" />
<inertia ixx="5.7160316393851747746e-06" ixy="-1.9710864478232660953e-13"  ixz="-3.0017829442562070721e-24" iyy="5.8966955959438776354e-06" iyz="9.5685519509886947673e-14" izz="7.2203526828754657522e-07" />
</inertial>
</link>

<link name="moteur_hanche1">
<visual>
<origin xyz="-0.049500000000000793365 -0.85800000000000009592 -0.10862499999999999933" rpy="-1.570796326794896558 5.3817757744455734324e-19 -1.2493625108208931322e-17" />
<geometry>
<mesh filename="package:///moteur_hanche1.stl"/>
</geometry>
<material name="moteur_hanche1_material">
<color rgba="1 0 0 1.0"/>
</material>
</visual>
<collision>
<origin xyz="-0.049500000000000793365 -0.85800000000000009592 -0.10862499999999999933" rpy="-1.570796326794896558 5.3817757744455734324e-19 -1.2493625108208931322e-17" />
<geometry>
<mesh filename="package:///moteur_hanche1.stl"/>
</geometry>
</collision>
<inertial>
<origin xyz="-1.3877787807814456755e-17 -0.012713533519811970329 1.1283142564332791009e-18" rpy="0 0 0"/>
<mass value="0.17794962537636813127" />
<inertia ixx="3.4377373668620134326e-05" ixy="1.9874524933721430471e-23"  ixz="-9.8696794500999789462e-23" iyy="4.1215284105260629674e-05" iyz="6.9949651191078728165e-23" izz="3.4002456645612650764e-05" />
</inertial>
</link>

<link name="piston_10">
<visual>
<origin xyz="-0.10179556944408768571 0.15392457132099848782 -0.85800000000000009592" rpy="-5.9407647068876257037e-19 1.5449531274143009299e-18 1.0452910060497726438e-18" />
<geometry>
<mesh filename="package:///piston.stl"/>
</geometry>
<material name="piston_material">
<color rgba="0.91764705882352937127 0.91764705882352937127 0.91764705882352937127 1.0"/>
</material>
</visual>
<collision>
<origin xyz="-0.10179556944408768571 0.15392457132099848782 -0.85800000000000009592" rpy="-5.9407647068876257037e-19 1.5449531274143009299e-18 1.0452910060497726438e-18" />
<geometry>
<mesh filename="package:///piston.stl"/>
</geometry>
</collision>
<inertial>
<origin xyz="-1.3877787807814456755e-17 3.675984153752732547e-18 -0.01100000000000000977" rpy="0 0 0"/>
<mass value="0.0047041422996690132607" />
<inertia ixx="2.6977766073778931429e-07" ixy="3.3455025196058666946e-25"  ixz="1.6387177413761775749e-24" iyy="2.6977766073778920841e-07" iyz="5.1440212048046744894e-25" izz="1.6008784263561088309e-07" />
</inertial>
</link>

<link name="closedloop17_B_6D">
<inertial>
<origin xyz="0 0 0" rpy="0 0 0" />
<mass value="1e-9" />
<inertia ixx="0" ixy="0" ixz="0" iyy="0" iyz="0" izz="0" />
</inertial>
</link>
<joint name="closedloop17_B_6D_frame" type="fixed">
<origin xyz="-2.7755575615628913511e-17 2.7755575615628913511e-17 -0.02199999999999989464" rpy="5.9407647068876257037e-19 -1.5422740935228754604e-17 -3.141592653589793116" />
<parent link="piston_10" />
<child link="closedloop17_B_6D" />
<axis xyz="0 0 0"/>
</joint>

<joint name="motor_hip_xy_1_left" type="prismatic">
<origin xyz="1.3877787807814456755e-17 -0.049224876560801336667 1.3877787807814456755e-17" rpy="-1.570796326794896558 -8.4128073089814322834e-15 7.43963769432937431e-15" />
<parent link="moteur_hanche1" />
<child link="piston_10" />
<axis xyz="0 0 1"/>
<limit effort="1" velocity="20" />
<joint_properties friction="0.0"/>
</joint>

<joint name="free_motor_holder_hip_xy2_left" type="revolute">
<origin xyz="5.2041704279304212832e-18 1.8041124150158793782e-16 -0.054999999999999993339" rpy="-1.570796326794896558 -1.4803191601263148147 1.5707963267948810149" />
<parent link="cardan_hache" />
<child link="moteur_hanche1" />
<axis xyz="0 0 1"/>
<limit effort="1" velocity="20" />
<joint_properties friction="0.0"/>
</joint>

<joint name="free_motor_holder_1_left" type="revolute">
<origin xyz="0.012500000000000007633 -0.037125000000000123179 -0.07700000000000006839" rpy="1.570796326794896558 -0.019211068168970831666 -1.5707963267948918951" />
<parent link="hanche_gauche" />
<child link="cardan_hache" />
<axis xyz="0 0 1"/>
<limit effort="1" velocity="20" />
<joint_properties friction="0.0"/>
</joint>

<link name="cardan_hache_2">
<visual>
<origin xyz="0.10862500000000001321 0.85800000000000031797 -0.0055000000000023745172" rpy="1.570796326794896558 1.5707963267948930053 0" />
<geometry>
<mesh filename="package:///cardan_hache.stl"/>
</geometry>
<material name="cardan_hache_material">
<color rgba="0.49803921568627451677 0.49803921568627451677 0.49803921568627451677 1.0"/>
</material>
</visual>
<collision>
<origin xyz="0.10862500000000001321 0.85800000000000031797 -0.0055000000000023745172" rpy="1.570796326794896558 1.5707963267948930053 0" />
<geometry>
<mesh filename="package:///cardan_hache.stl"/>
</geometry>
</collision>
<inertial>
<origin xyz="-2.4805602360254969558e-17 1.5061507596669798659e-11 -0.034629677480538460788" rpy="0 0 0"/>
<mass value="0.015608633111865791165" />
<inertia ixx="5.7160316393851764687e-06" ixy="-1.9710864481570115611e-13"  ixz="8.37837634896594512e-24" iyy="5.8966955959438793294e-06" iyz="9.5685519510005642841e-14" izz="7.220352682875461517e-07" />
</inertial>
</link>

<link name="moteur_hanche1_2">
<visual>
<origin xyz="-0.049500000000000793365 -0.85799999999999987388 -0.10862500000000001321" rpy="-1.570796326794896558 1.7493640138072929483e-18 7.0157065866657330253e-18" />
<geometry>
<mesh filename="package:///moteur_hanche1.stl"/>
</geometry>
<material name="moteur_hanche1_material">
<color rgba="1 0 0 1.0"/>
</material>
</visual>
<collision>
<origin xyz="-0.049500000000000793365 -0.85799999999999987388 -0.10862500000000001321" rpy="-1.570796326794896558 1.7493640138072929483e-18 7.0157065866657330253e-18" />
<geometry>
<mesh filename="package:///moteur_hanche1.stl"/>
</geometry>
</collision>
<inertial>
<origin xyz="-6.9388939039072283776e-18 -0.012713533519811748285 -1.3595795281175873217e-17" rpy="0 0 0"/>
<mass value="0.17794962537636813127" />
<inertia ixx="3.4377373668620147878e-05" ixy="1.9709408393789730844e-22"  ixz="-7.1969398875580065713e-23" iyy="4.1215284105260629674e-05" iyz="1.6430845677865352059e-22" izz="3.4002456645612650764e-05" />
</inertial>
</link>

<link name="piston_11">
<visual>
<origin xyz="-0.10179556944408767183 0.15392457132099854333 -0.8579999999999999849" rpy="-5.8224664018376246896e-19 8.6176233811753774968e-18 -3.1521531370982677572e-19" />
<geometry>
<mesh filename="package:///piston.stl"/>
</geometry>
<material name="piston_material">
<color rgba="0.91764705882352937127 0.91764705882352937127 0.91764705882352937127 1.0"/>
</material>
</visual>
<collision>
<origin xyz="-0.10179556944408767183 0.15392457132099854333 -0.8579999999999999849" rpy="-5.8224664018376246896e-19 8.6176233811753774968e-18 -3.1521531370982677572e-19" />
<geometry>
<mesh filename="package:///piston.stl"/>
</geometry>
</collision>
<inertial>
<origin xyz="-4.1633363423443370266e-17 2.8719717530321850019e-17 -0.011000000000000120792" rpy="0 0 0"/>
<mass value="0.0047041422996690132607" />
<inertia ixx="2.6977766073778920841e-07" ixy="1.7966576096338644143e-25"  ixz="-3.297259914437632865e-24" iyy="2.6977766073778931429e-07" iyz="3.121592288075554438e-26" izz="1.6008784263561083015e-07" />
</inertial>
</link>

<link name="closedloop18_B_6D">
<inertial>
<origin xyz="0 0 0" rpy="0 0 0" />
<mass value="1e-9" />
<inertia ixx="0" ixy="0" ixz="0" iyy="0" iyz="0" izz="0" />
</inertial>
</link>
<joint name="closedloop18_B_6D_frame" type="fixed">
<origin xyz="2.7755575615628913511e-17 2.7755575615628913511e-17 -0.021999999999999991784" rpy="2.8720513250545159028e-18 5.0069198964034734906e-17 -1.195602383648069109e-18" />
<parent link="piston_11" />
<child link="closedloop18_B_6D" />
<axis xyz="0 0 0"/>
</joint>

<joint name="motor_hip_xy_2_left" type="prismatic">
<origin xyz="0 -0.04333782624542449613 4.1633363423443370266e-17" rpy="-1.570796326794896558 2.612321956315469991e-15 2.3456370119822959644e-15" />
<parent link="moteur_hanche1_2" />
<child link="piston_11" />
<axis xyz="0 0 1"/>
<limit effort="1" velocity="20" />
<joint_properties friction="0.0"/>
</joint>

<joint name="free_motor_holder_hip_xy1_left" type="revolute">
<origin xyz="4.1633363423443370266e-17 4.1633363423443370266e-17 -0.054999999999999993339" rpy="-1.570796326794896558 1.4797294953454118716 1.5707963267949098807" />
<parent link="cardan_hache_2" />
<child link="moteur_hanche1_2" />
<axis xyz="0 0 1"/>
<limit effort="1" velocity="20" />
<joint_properties friction="0.0"/>
</joint>

<joint name="free_motor_holder_2_left" type="revolute">
<origin xyz="0.012500000000000007633 0.037124999999999908074 -0.076999999999999971245" rpy="-1.570796326794896558 -0.021147767637937589513 1.5707963267948983344" />
<parent link="hanche_gauche" />
<child link="cardan_hache_2" />
<axis xyz="0 0 1"/>
<limit effort="1" velocity="20" />
<joint_properties friction="0.0"/>
</joint>

<joint name="free_hip_left" type="revolute">
<origin xyz="0.012500000000000019776 0.045000000000000095479 -0.0049999999999998934186" rpy="3.3570871694184550475e-17 -7.9158602963494340966e-16 -0.014698705078103748572" />
<parent link="hanche_batis_gauche" />
<child link="hanche_gauche" />
<axis xyz="0 0 1"/>
<limit effort="1" velocity="20" />
<joint_properties friction="0.0"/>
</joint>

<link name="hanche_batis">
<visual>
<origin xyz="0.017999999999998839845 -0.96475000000000032951 -0.27649999999999996803" rpy="-1.570796326794896558 1.4890245820567744385e-45 0" />
<geometry>
<mesh filename="package:///hanche_batis.stl"/>
</geometry>
<material name="hanche_batis_material">
<color rgba="0.61568627450980395466 0.81176470588235294379 0.92941176470588238168 1.0"/>
</material>
</visual>
<collision>
<origin xyz="0.017999999999998839845 -0.96475000000000032951 -0.27649999999999996803" rpy="-1.570796326794896558 1.4890245820567744385e-45 0" />
<geometry>
<mesh filename="package:///hanche_batis.stl"/>
</geometry>
</collision>
<inertial>
<origin xyz="-0.0014786115366823976425 -0.00044500436417471695002 -0.12765424686065846016" rpy="0 0 0"/>
<mass value="1.5865591647149870358" />
<inertia ixx="0.0088382827967695663796" ixy="-2.920764549673867156e-05"  ixz="-0.00027487762182023736798" iyy="0.010752178054608369298" iyz="-6.8858407992621807506e-05" izz="0.0025754201921632993016" />
</inertial>
</link>

<link name="center_hip">
<inertial>
<origin xyz="0 0 0" rpy="0 0 0" />
<mass value="1e-9" />
<inertia ixx="0" ixy="0" ixz="0" iyy="0" iyz="0" izz="0" />
</inertial>
</link>
<joint name="center_hip_frame" type="fixed">
<origin xyz="-0.0047474699229011207979 -0.19725000000000003642 -0.28861143158344787496" rpy="-1.570796326794896558 -2.5144941353924022455e-29 -3.670158759091543729e-15" />
<parent link="hanche_batis" />
<child link="center_hip" />
<axis xyz="0 0 0"/>
</joint>

<link name="hanche">
<visual>
<origin xyz="0.005500000000002376252 0.071500000000000007994 -0.93500000000000027534" rpy="-3.3109585821359983486e-31 -3.6701587590914506434e-15 1.0774010199652129295e-44" />
<geometry>
<mesh filename="package:///hanche.stl"/>
</geometry>
<material name="hanche_material">
<color rgba="0.2313725490196078538 0.38039215686274507888 0.7058823529411765163 1.0"/>
</material>
</visual>
<collision>
<origin xyz="0.005500000000002376252 0.071500000000000007994 -0.93500000000000027534" rpy="-3.3109585821359983486e-31 -3.6701587590914506434e-15 1.0774010199652129295e-44" />
<geometry>
<mesh filename="package:///hanche.stl"/>
</geometry>
</collision>
<inertial>
<origin xyz="3.4156793823902908969e-08 0.003051083573353055578 -0.08336523680757901289" rpy="0 0 0"/>
<mass value="0.14908820646980494584" />
<inertia ixx="0.00035636864137915792803" ixy="1.6418959534109276851e-10"  ixz="-6.6325805549022850031e-11" iyy="0.00032228379449719348924" iyz="-1.6655006554546130049e-05" izz="4.9201065872666315557e-05" />
</inertial>
</link>

<link name="cardan_foot_3">
<visual>
<origin xyz="0 0.038499999999999978684 -6.6000000000000086375e-05" rpy="1.570796326794896558 1.570796326794896558 0" />
<geometry>
<mesh filename="package:///cardan_foot.stl"/>
</geometry>
<material name="cardan_foot_material">
<color rgba="0.64705882352941179736 0.64705882352941179736 0.64705882352941179736 1.0"/>
</material>
</visual>
<collision>
<origin xyz="0 0.038499999999999978684 -6.6000000000000086375e-05" rpy="1.570796326794896558 1.570796326794896558 0" />
<geometry>
<mesh filename="package:///cardan_foot.stl"/>
</geometry>
</collision>
<inertial>
<origin xyz="6.7228290681228176484e-09 -2.0816681711721685133e-17 -6.599327717093125649e-05" rpy="0 0 0"/>
<mass value="0.0064135211594024202353" />
<inertia ixx="3.3475011343990655066e-07" ixy="-2.8486583237315313981e-12"  ixz="-2.8685952759541640894e-38" iyy="4.3082408299805979528e-07" iyz="2.84865832377020088e-12" izz="3.3475011343990649772e-07" />
</inertial>
</link>

<link name="part_1">
<visual>
<origin xyz="-6.2450045135165055399e-17 0 0" rpy="1.570796326794896558 1.570796326794896558 0" />
<geometry>
<mesh filename="package:///part_1.stl"/>
</geometry>
<material name="part_1_material">
<color rgba="0.34901960784313723618 0.37647058823529411242 0.4000000000000000222 1.0"/>
</material>
</visual>
<collision>
<origin xyz="-6.2450045135165055399e-17 0 0" rpy="1.570796326794896558 1.570796326794896558 0" />
<geometry>
<mesh filename="package:///part_1.stl"/>
</geometry>
</collision>
<inertial>
<origin xyz="0.006702603912780952071 0.016607315554245549727 -0.045523329198624416791" rpy="0 0 0"/>
<mass value="0.24432174426363428843" />
<inertia ixx="0.00038002986328721232194" ixy="-4.5343822480551170787e-05"  ixz="0.00019115477962150837594" iyy="0.0006326280520654822305" iyz="7.0096670808240458313e-05" izz="0.00036002210019491691449" />
</inertial>
</link>

<link name="closedloop7_B_3D">
<inertial>
<origin xyz="0 0 0" rpy="0 0 0" />
<mass value="1e-9" />
<inertia ixx="0" ixy="0" ixz="0" iyy="0" iyz="0" izz="0" />
</inertial>
</link>
<joint name="closedloop7_B_3D_frame" type="fixed">
<origin xyz="0.083867056794542343967 -0.0077119035015027481705 -0.071500000000000063505" rpy="1.570796326794896558 -1.3655413196735760511e-30 -1.3856394439909555038e-14" />
<parent link="part_1" />
<child link="closedloop7_B_3D" />
<axis xyz="0 0 0"/>
</joint>

<link name="piston_12">
<visual>
<origin xyz="-0.10179556944408764407 0.15392457132099851558 -0.85800000000000009592" rpy="2.1460810929844521109e-18 -2.2403987591271383437e-17 8.021287193239704977e-19" />
<geometry>
<mesh filename="package:///piston.stl"/>
</geometry>
<material name="piston_material">
<color rgba="0.91764705882352937127 0.91764705882352937127 0.91764705882352937127 1.0"/>
</material>
</visual>
<collision>
<origin xyz="-0.10179556944408764407 0.15392457132099851558 -0.85800000000000009592" rpy="2.1460810929844521109e-18 -2.2403987591271383437e-17 8.021287193239704977e-19" />
<geometry>
<mesh filename="package:///piston.stl"/>
</geometry>
</collision>
<inertial>
<origin xyz="-2.7755575615628913511e-17 5.004911124027160015e-18 -0.011000000000000231815" rpy="0 0 0"/>
<mass value="0.0047041422996690132607" />
<inertia ixx="2.6977766073778920841e-07" ixy="-1.897352290347905143e-25"  ixz="2.3692339726764927502e-25" iyy="2.6977766073778931429e-07" iyz="1.5094886423795478475e-24" izz="1.6008784263561083015e-07" />
</inertial>
</link>

<link name="closedloop3_A_6D">
<inertial>
<origin xyz="0 0 0" rpy="0 0 0" />
<mass value="1e-9" />
<inertia ixx="0" ixy="0" ixz="0" iyy="0" iyz="0" izz="0" />
</inertial>
</link>
<joint name="closedloop3_A_6D_frame" type="fixed">
<origin xyz="-2.4286128663675299322e-17 0 -0.022000000000000158318" rpy="-3.141592653589793116 -8.9238004832296958299e-16 2.3469316244365445958e-17" />
<parent link="piston_12" />
<child link="closedloop3_A_6D" />
<axis xyz="0 0 0"/>
</joint>

<joint name="spherical_lower_hip1" type="revolute">
<origin xyz="-0.060500000000000137002 2.7755575615628913511e-17 -0.038499999999999978684" rpy="1.57079632679489678 -0.083114644637941520466 -3.1415926535897846783" />
<parent link="part_1" />
<child link="piston_12" />
<axis xyz="0 0 1"/>
<limit effort="1" velocity="20" />
<joint_properties friction="0.0"/>
</joint>

<link name="piston_13">
<visual>
<origin xyz="-0.10179556944408768571 0.15392457132099851558 -0.8579999999999999849" rpy="8.4569414494565946214e-18 3.2015687363518250876e-17 -1.2585452492874716195e-17" />
<geometry>
<mesh filename="package:///piston.stl"/>
</geometry>
<material name="piston_material">
<color rgba="0.91764705882352937127 0.91764705882352937127 0.91764705882352937127 1.0"/>
</material>
</visual>
<collision>
<origin xyz="-0.10179556944408768571 0.15392457132099851558 -0.8579999999999999849" rpy="8.4569414494565946214e-18 3.2015687363518250876e-17 -1.2585452492874716195e-17" />
<geometry>
<mesh filename="package:///piston.stl"/>
</geometry>
</collision>
<inertial>
<origin xyz="-5.5511151231257827021e-17 8.4288303774755839736e-18 -0.011000000000000120792" rpy="0 0 0"/>
<mass value="0.0047041422996690132607" />
<inertia ixx="2.6977766073778931429e-07" ixy="-4.221999687130320163e-24"  ixz="-1.3211356669722153596e-23" iyy="2.6977766073778931429e-07" iyz="4.1167344226614388426e-24" izz="1.6008784263561083015e-07" />
</inertial>
</link>

<link name="closedloop4_A_6D">
<inertial>
<origin xyz="0 0 0" rpy="0 0 0" />
<mass value="1e-9" />
<inertia ixx="0" ixy="0" ixz="0" iyy="0" iyz="0" izz="0" />
</inertial>
</link>
<joint name="closedloop4_A_6D_frame" type="fixed">
<origin xyz="1.7347234759768070944e-17 0 -0.02200000000000001954" rpy="-3.1415926535897895633 -5.8631330626161750329e-14 -2.5740459072486076896e-17" />
<parent link="piston_13" />
<child link="closedloop4_A_6D" />
<axis xyz="0 0 0"/>
</joint>

<joint name="spherical_lower_hip2" type="revolute">
<origin xyz="-0.060500000000000150879 2.7755575615628913511e-17 0.03850000000000006195" rpy="-1.57079632679489678 0.090109706454325047553 -5.2539072764179264277e-14" />
<parent link="part_1" />
<child link="piston_13" />
<axis xyz="0 0 1"/>
<limit effort="1" velocity="20" />
<joint_properties friction="0.0"/>
</joint>

<link name="part_2_2">
<visual>
<origin xyz="-2.3869795029440865619e-15 0.046752000000001542324 -0.071500000000000007994" rpy="-1.570796326794896558 -1.570796326794896558 0" />
<geometry>
<mesh filename="package:///part_2.stl"/>
</geometry>
<material name="part_2_material">
<color rgba="0.76862745098039220171 0.88627450980392152857 0.95294117647058818044 1.0"/>
</material>
</visual>
<collision>
<origin xyz="-2.3869795029440865619e-15 0.046752000000001542324 -0.071500000000000007994" rpy="-1.570796326794896558 -1.570796326794896558 0" />
<geometry>
<mesh filename="package:///part_2.stl"/>
</geometry>
</collision>
<inertial>
<origin xyz="-0.1035313303821914499 -0.14056766472890799835 -5.9849347699980626203e-13" rpy="0 0 0"/>
<mass value="0.39806472503371781446" />
<inertia ixx="0.0031977111359881450064" ixy="-0.001858846357492638943"  ixz="5.7043161333344648304e-15" iyy="0.0012912945788078693775" iyz="2.6363837589087470259e-14" izz="0.0044624680664483240902" />
</inertial>
</link>

<link name="part_3_2">
<visual>
<origin xyz="0.21747050071614920652 0.38247000862966429313 -0.071500000000000035749" rpy="-1.570796326794896558 -1.570796326794896558 0" />
<geometry>
<mesh filename="package:///part_3.stl"/>
</geometry>
<material name="part_3_material">
<color rgba="0.76862745098039220171 0.88627450980392152857 0.95294117647058818044 1.0"/>
</material>
</visual>
<collision>
<origin xyz="0.21747050071614920652 0.38247000862966429313 -0.071500000000000035749" rpy="-1.570796326794896558 -1.570796326794896558 0" />
<geometry>
<mesh filename="package:///part_3.stl"/>
</geometry>
</collision>
<inertial>
<origin xyz="0.10608938835476373896 -0.17986935727287689524 -4.1633363423443370266e-17" rpy="0 0 0"/>
<mass value="0.2021348089396567127" />
<inertia ixx="0.0018459328059746529013" ixy="0.0012583807608323397537"  ixz="-1.0532249618520378307e-35" iyy="0.00088797005323680859492" iyz="8.3651939008526278951e-35" izz="0.0027204272052821516087" />
</inertial>
</link>

<link name="cardan_foot_4">
<visual>
<origin xyz="0 0.038499999999999867661 6.5999999999954983565e-05" rpy="1.570796326794896558 1.570796326794896558 0" />
<geometry>
<mesh filename="package:///cardan_foot.stl"/>
</geometry>
<material name="cardan_foot_material">
<color rgba="0.64705882352941179736 0.64705882352941179736 0.64705882352941179736 1.0"/>
</material>
</visual>
<collision>
<origin xyz="0 0.038499999999999867661 6.5999999999954983565e-05" rpy="1.570796326794896558 1.570796326794896558 0" />
<geometry>
<mesh filename="package:///cardan_foot.stl"/>
</geometry>
</collision>
<inertial>
<origin xyz="6.7228290672610625406e-09 -1.3877787807814456755e-16 6.6006722829024965416e-05" rpy="0 0 0"/>
<mass value="0.0064135211594024202353" />
<inertia ixx="3.3475011343990665654e-07" ixy="-2.8486583237211431728e-12"  ixz="-7.3569067863775769189e-25" iyy="4.3082408299806000704e-07" iyz="2.8486583237600570123e-12" izz="3.3475011343990649772e-07" />
</inertial>
</link>

<link name="foot_2">
<visual>
<origin xyz="1.1102230246251565404e-16 0.038499999999999978684 2.7755575615628913511e-17" rpy="1.570796326794896558 4.5913922084482475084e-18 6.1122437649161357642e-17" />
<geometry>
<mesh filename="package:///foot.stl"/>
</geometry>
<material name="foot_material">
<color rgba="0.61568627450980395466 0.81176470588235294379 0.92941176470588238168 1.0"/>
</material>
</visual>
<collision>
<origin xyz="1.1102230246251565404e-16 0.038499999999999978684 2.7755575615628913511e-17" rpy="1.570796326794896558 4.5913922084482475084e-18 6.1122437649161357642e-17" />
<geometry>
<mesh filename="package:///foot.stl"/>
</geometry>
</collision>
<inertial>
<origin xyz="-0.0036358817134151118038 0.02496644936992965802 9.0007330186029491136e-08" rpy="0 0 0"/>
<mass value="0.31091298222930185968" />
<inertia ixx="0.00026328612588329933534" ixy="-5.3028311481376154391e-05"  ixz="-1.787277604656267409e-09" iyy="0.00071897520566115960452" iyz="-2.0903095188772817896e-10" izz="0.00052661427618999395381" />
</inertial>
</link>

<link name="foot_right">
<inertial>
<origin xyz="0 0 0" rpy="0 0 0" />
<mass value="1e-9" />
<inertia ixx="0" ixy="0" ixz="0" iyy="0" iyz="0" izz="0" />
</inertial>
</link>
<joint name="foot_right_frame" type="fixed">
<origin xyz="0.01201694922107987562 0.038499999999999923173 6.8117393392519431927e-09" rpy="1.5707963267948972241 4.1530747501458917702e-18 1.4689606375488657859e-15" />
<parent link="foot_2" />
<child link="foot_right" />
<axis xyz="0 0 0"/>
</joint>

<link name="closedloop0_A_3D">
<inertial>
<origin xyz="0 0 0" rpy="0 0 0" />
<mass value="1e-9" />
<inertia ixx="0" ixy="0" ixz="0" iyy="0" iyz="0" izz="0" />
</inertial>
</link>
<joint name="closedloop0_A_3D_frame" type="fixed">
<origin xyz="-0.054999999999999715783 -0.010999999999999843237 0.038500000000000006439" rpy="1.570796326794896558 6.2711683153062856565e-17 -1.5707963267948958919" />
<parent link="foot_2" />
<child link="closedloop0_A_3D" />
<axis xyz="0 0 0"/>
</joint>

<link name="closedloop11_A_3D">
<inertial>
<origin xyz="0 0 0" rpy="0 0 0" />
<mass value="1e-9" />
<inertia ixx="0" ixy="0" ixz="0" iyy="0" iyz="0" izz="0" />
</inertial>
</link>
<joint name="closedloop11_A_3D_frame" type="fixed">
<origin xyz="-0.054999999999999826805 -0.010999999999999954259 -0.038500000000000034195" rpy="1.570796326794896558 6.2711683153062856565e-17 -1.5707963267948958919" />
<parent link="foot_2" />
<child link="closedloop11_A_3D" />
<axis xyz="0 0 0"/>
</joint>

<joint name="free_ankle_universalx" type="revolute">
<origin xyz="6.6000000007115922074e-05 -1.1102230246251565404e-16 6.6000000002341963068e-05" rpy="-1.570796326794896558 -0.95882611835293629632 -1.570796326794896558" />
<parent link="cardan_foot_4" />
<child link="foot_2" />
<axis xyz="0 0 1"/>
<limit effort="1" velocity="20" />
<joint_properties friction="0.0"/>
</joint>

<joint name="uneveral_foot1" type="revolute">
<origin xyz="0.21747050071614926203 -0.33571800862966427736 0" rpy="-1.5707963267948958919 -1.4835298641951766285 1.5707963267949329733" />
<parent link="part_3_2" />
<child link="cardan_foot_4" />
<axis xyz="0 0 1"/>
<limit effort="1" velocity="20" />
<joint_properties friction="0.0"/>
</joint>

<link name="part_6_2">
<visual>
<origin xyz="0.10788167727912306715 -0.039150197130724595507 0" rpy="-3.141592653589793116 4.3426581166330444926e-18 -1.6449010937653612579e-17" />
<geometry>
<mesh filename="package:///part_6.stl"/>
</geometry>
<material name="part_6_material">
<color rgba="0.76862745098039220171 0.88627450980392152857 0.95294117647058818044 1.0"/>
</material>
</visual>
<collision>
<origin xyz="0.10788167727912306715 -0.039150197130724595507 0" rpy="-3.141592653589793116 4.3426581166330444926e-18 -1.6449010937653612579e-17" />
<geometry>
<mesh filename="package:///part_6.stl"/>
</geometry>
</collision>
<inertial>
<origin xyz="6.9388939039072283776e-17 -2.3317405811156506712e-17 -0.21360000000000003983" rpy="0 0 0"/>
<mass value="0.033552209540339043847" />
<inertia ixx="0.00051048244070615639203" ixy="-4.0490051119284429592e-20"  ixz="-2.2162705274137305424e-21" iyy="0.00051048244070615617519" iyz="6.0584032988690868539e-21" izz="4.1940261925423882626e-07" />
</inertial>
</link>

<link name="closedloop6_B_3D">
<inertial>
<origin xyz="0 0 0" rpy="0 0 0" />
<mass value="1e-9" />
<inertia ixx="0" ixy="0" ixz="0" iyy="0" iyz="0" izz="0" />
</inertial>
</link>
<joint name="closedloop6_B_3D_frame" type="fixed">
<origin xyz="-2.7755575615628913511e-17 0 -0.42720000000000007967" rpy="-3.1415926535897926719 4.3171515544792239751e-16 3.141592653589793116" />
<parent link="part_6_2" />
<child link="closedloop6_B_3D" />
<axis xyz="0 0 0"/>
</joint>

<joint name="spherical_shin_rod1" type="revolute">
<origin xyz="0.038967453687049735667 -0.092095263467496524257 0" rpy="-1.57079632679489678 -1.3380503778517247593 1.5707963267948987784" />
<parent link="part_3_2" />
<child link="part_6_2" />
<axis xyz="0 0 1"/>
<limit effort="1" velocity="20" />
<joint_properties friction="0.0"/>
</joint>

<joint name="lower_knee" type="revolute">
<origin xyz="-0.21747050071615142697 -0.33571800862966272305 -5.5511151231257827021e-17" rpy="2.0331881193927353103e-17 3.4472918726955580133e-17 0.89630439304597731009" />
<parent link="part_2_2" />
<child link="part_3_2" />
<axis xyz="0 0 1"/>
<limit effort="1" velocity="20" />
<joint_properties friction="0.0"/>
</joint>

<link name="renvois_cheville_2_8_2">
<visual>
<origin xyz="-0.11550000000000024136 -0.35750000000000003997 0.03300000000000002931" rpy="-1.570796326794896558 1.0489594920773023007e-31 1.9731702801127553748e-17" />
<geometry>
<mesh filename="package:///renvois_cheville_2_8.stl"/>
</geometry>
<material name="renvois_cheville_2_8_material">
<color rgba="0.91764705882352937127 0.91764705882352937127 0.91764705882352937127 1.0"/>
</material>
</visual>
<collision>
<origin xyz="-0.11550000000000024136 -0.35750000000000003997 0.03300000000000002931" rpy="-1.570796326794896558 1.0489594920773023007e-31 1.9731702801127553748e-17" />
<geometry>
<mesh filename="package:///renvois_cheville_2_8.stl"/>
</geometry>
</collision>
<inertial>
<origin xyz="-0.033596086250149523322 -0.018380744757819034163 -0.014122199558543407916" rpy="0 0 0"/>
<mass value="0.074310320490072731547" />
<inertia ixx="4.1295450354366541358e-05" ixy="1.988605193818464217e-06"  ixz="-2.0689202263474864778e-06" iyy="3.2625641947312141421e-05" iyz="-9.9798202174584469521e-06" izz="5.1310129727252684509e-05" />
</inertial>
</link>

<link name="closedloop10_B_3D">
<inertial>
<origin xyz="0 0 0" rpy="0 0 0" />
<mass value="1e-9" />
<inertia ixx="0" ixy="0" ixz="0" iyy="0" iyz="0" izz="0" />
</inertial>
</link>
<joint name="closedloop10_B_3D_frame" type="fixed">
<origin xyz="-0.035854717888629136779 -0.041706584673488200643 -0.052249999999999963141" rpy="-1.57079632679489678 4.2500725161430485751e-17 -2.5782405335516153514e-16" />
<parent link="renvois_cheville_2_8_2" />
<child link="closedloop10_B_3D" />
<axis xyz="0 0 0"/>
</joint>

<link name="part_7_5">
<visual>
<origin xyz="0.062087559207389841909 0.15255026628033763192 -5.898059818321144121e-17" rpy="-3.141592653589793116 1.0842292048905287506e-17 3.9791344991194272221e-17" />
<geometry>
<mesh filename="package:///part_7.stl"/>
</geometry>
<material name="part_7_material">
<color rgba="0.91764705882352937127 0.91764705882352937127 0.91764705882352937127 1.0"/>
</material>
</visual>
<collision>
<origin xyz="0.062087559207389841909 0.15255026628033763192 -5.898059818321144121e-17" rpy="-3.141592653589793116 1.0842292048905287506e-17 3.9791344991194272221e-17" />
<geometry>
<mesh filename="package:///part_7.stl"/>
</geometry>
</collision>
<inertial>
<origin xyz="-4.8572257327350598644e-17 6.8878456047544325266e-18 -0.20000000000000014988" rpy="0 0 0"/>
<mass value="0.031415926535897982508" />
<inertia ixx="0.00041907537001948915118" ixy="4.1520380399802351722e-20"  ixz="-4.4799237397910850856e-21" iyy="0.00041907537001948936802" iyz="7.6840952568232838521e-21" izz="3.9269908169872580702e-07" />
</inertial>
</link>

<link name="closedloop0_B_3D">
<inertial>
<origin xyz="0 0 0" rpy="0 0 0" />
<mass value="1e-9" />
<inertia ixx="0" ixy="0" ixz="0" iyy="0" iyz="0" izz="0" />
</inertial>
</link>
<joint name="closedloop0_B_3D_frame" type="fixed">
<origin xyz="-1.1102230246251565404e-16 5.5511151231257827021e-17 -0.40000000000000007772" rpy="3.1415926535897913396 1.3110944058270872971e-15 -1.570796326794896558" />
<parent link="part_7_5" />
<child link="closedloop0_B_3D" />
<axis xyz="0 0 0"/>
</joint>

<joint name="spherical_transmission_foot2" type="revolute">
<origin xyz="-0.059494699261975703131 0.010983203527527130028 -0.021999999999999964029" rpy="-1.57079632679489678 0.2674961218464166901 -1.570796326794896558" />
<parent link="renvois_cheville_2_8_2" />
<child link="part_7_5" />
<axis xyz="0 0 1"/>
<limit effort="1" velocity="20" />
<joint_properties friction="0.0"/>
</joint>

<joint name="triangle_knee1" type="revolute">
<origin xyz="-0.21747050071615148248 -0.33571800862966283407 0.010000000000000008882" rpy="3.1415926535897922278 2.5397996671417581801e-15 3.0532620163569994531" />
<parent link="part_2_2" />
<child link="renvois_cheville_2_8_2" />
<axis xyz="0 0 1"/>
<limit effort="1" velocity="20" />
<joint_properties friction="0.0"/>
</joint>

<link name="renvois_cheville_2">
<visual>
<origin xyz="-0.11550000000000004707 -0.35749999999999981792 -0.032999999999999918288" rpy="-1.570796326794896558 -3.8842663271013338846e-32 -1.7292512105627270119e-17" />
<geometry>
<mesh filename="package:///renvois_cheville.stl"/>
</geometry>
<material name="renvois_cheville_material">
<color rgba="0.91764705882352937127 0.91764705882352937127 0.91764705882352937127 1.0"/>
</material>
</visual>
<collision>
<origin xyz="-0.11550000000000004707 -0.35749999999999981792 -0.032999999999999918288" rpy="-1.570796326794896558 -3.8842663271013338846e-32 -1.7292512105627270119e-17" />
<geometry>
<mesh filename="package:///renvois_cheville.stl"/>
</geometry>
</collision>
<inertial>
<origin xyz="-0.033596086592530896575 -0.018380744754187161583 0.014122199609931607167" rpy="0 0 0"/>
<mass value="0.074310321213953547947" />
<inertia ixx="4.1295450352451928413e-05" ixy="1.988605320318323592e-06"  ixz="2.0689203249184050392e-06" iyy="3.2625642523550437595e-05" iyz="9.9798202218794591873e-06" izz="5.1310130219953352371e-05" />
</inertial>
</link>

<link name="closedloop9_B_3D">
<inertial>
<origin xyz="0 0 0" rpy="0 0 0" />
<mass value="1e-9" />
<inertia ixx="0" ixy="0" ixz="0" iyy="0" iyz="0" izz="0" />
</inertial>
</link>
<joint name="closedloop9_B_3D_frame" type="fixed">
<origin xyz="-0.035854717888628991063 -0.041706584673488089621 0.052250000000000074163" rpy="1.570796326794896558 7.4525120443701586197e-31 -3.1415926535897908956" />
<parent link="renvois_cheville_2" />
<child link="closedloop9_B_3D" />
<axis xyz="0 0 0"/>
</joint>

<link name="part_7_6">
<visual>
<origin xyz="0.062087559207389841909 -0.15255026628033763192 -0.40000000000000007772" rpy="-1.2019258149202308314e-17 7.4557898188730944883e-19 -3.0411119548499977744e-18" />
<geometry>
<mesh filename="package:///part_7.stl"/>
</geometry>
<material name="part_7_material">
<color rgba="0.91764705882352937127 0.91764705882352937127 0.91764705882352937127 1.0"/>
</material>
</visual>
<collision>
<origin xyz="0.062087559207389841909 -0.15255026628033763192 -0.40000000000000007772" rpy="-1.2019258149202308314e-17 7.4557898188730944883e-19 -3.0411119548499977744e-18" />
<geometry>
<mesh filename="package:///part_7.stl"/>
</geometry>
</collision>
<inertial>
<origin xyz="0 -2.2047486419643679611e-17 -0.20000000000000003886" rpy="0 0 0"/>
<mass value="0.031415926535897982508" />
<inertia ixx="0.00041907537001948915118" ixy="6.17963700626129028e-22"  ixz="-2.9443561249316962678e-22" iyy="0.00041907537001948915118" iyz="-5.0261379871238113026e-21" izz="3.9269908169872559526e-07" />
</inertial>
</link>

<link name="closedloop11_B_3D">
<inertial>
<origin xyz="0 0 0" rpy="0 0 0" />
<mass value="1e-9" />
<inertia ixx="0" ixy="0" ixz="0" iyy="0" iyz="0" izz="0" />
</inertial>
</link>
<joint name="closedloop11_B_3D_frame" type="fixed">
<origin xyz="0 1.3877787807814456755e-17 -0.40000000000000013323" rpy="3.1415926535897895633 -3.5435748969399307641e-16 1.570796326794896558" />
<parent link="part_7_6" />
<child link="closedloop11_B_3D" />
<axis xyz="0 0 0"/>
</joint>

<joint name="spherical_transmission_foot1" type="revolute">
<origin xyz="-0.059494699261975536597 0.010983203527527130028 0.022000000000000047296" rpy="1.570796326794896558 -0.30096768397183631949 1.5707963267948981123" />
<parent link="renvois_cheville_2" />
<child link="part_7_6" />
<axis xyz="0 0 1"/>
<limit effort="1" velocity="20" />
<joint_properties friction="0.0"/>
</joint>

<joint name="triangle_knee2" type="revolute">
<origin xyz="-0.21747050071615164901 -0.33571800862966283407 -0.010000000000000008882" rpy="3.1415926535897926719 2.3960728016627840815e-15 3.0785068790704639419" />
<parent link="part_2_2" />
<child link="renvois_cheville_2" />
<axis xyz="0 0 1"/>
<limit effort="1" velocity="20" />
<joint_properties friction="0.0"/>
</joint>

<link name="part_4_2">
<visual>
<origin xyz="-0.010530049701071103607 0.09214604773529919135 -0.071500000000000063505" rpy="-1.570796326794896558 -1.570796326794896558 0" />
<geometry>
<mesh filename="package:///part_4.stl"/>
</geometry>
<material name="part_4_material">
<color rgba="1 0.7568627450980391913 0.054901960784313724728 1.0"/>
</material>
</visual>
<collision>
<origin xyz="-0.010530049701071103607 0.09214604773529919135 -0.071500000000000063505" rpy="-1.570796326794896558 -1.570796326794896558 0" />
<geometry>
<mesh filename="package:///part_4.stl"/>
</geometry>
</collision>
<inertial>
<origin xyz="0.019483726843524840078 -0.046047631733748345395 -4.1633363423443376429e-17" rpy="0 0 0"/>
<mass value="0.011311035579799528367" />
<inertia ixx="1.0009836990585404797e-05" ixy="4.1536946028868310457e-06"  ixz="-5.4133420794259693095e-37" iyy="1.9505556032253768346e-06" iyz="-6.8590833697575059641e-37" izz="1.1771875334147456995e-05" />
</inertial>
</link>

<link name="closedloop6_A_3D">
<inertial>
<origin xyz="0 0 0" rpy="0 0 0" />
<mass value="1e-9" />
<inertia ixx="0" ixy="0" ixz="0" iyy="0" iyz="0" izz="0" />
</inertial>
</link>
<joint name="closedloop6_A_3D_frame" type="fixed">
<origin xyz="0.038967453687049735667 -0.092095263467496704668 -5.5511151231257827021e-17" rpy="1.570796326794896558 4.0264892381777355687e-23 -1.570796326794896336" />
<parent link="part_4_2" />
<child link="closedloop6_A_3D" />
<axis xyz="0 0 0"/>
</joint>

<link name="part_5_2">
<visual>
<origin xyz="0.063404956281616797753 0.053322112528135567899 0" rpy="3.141592653589793116 5.4452107762399029678e-17 -1.581242105037273282e-17" />
<geometry>
<mesh filename="package:///part_5.stl"/>
</geometry>
<material name="part_5_material">
<color rgba="0.91764705882352937127 0.91764705882352937127 0.91764705882352937127 1.0"/>
</material>
</visual>
<collision>
<origin xyz="0.063404956281616797753 0.053322112528135567899 0" rpy="3.141592653589793116 5.4452107762399029678e-17 -1.581242105037273282e-17" />
<geometry>
<mesh filename="package:///part_5.stl"/>
</geometry>
</collision>
<inertial>
<origin xyz="1.3877787807814456755e-17 -6.8834275347424433365e-17 -0.070709999999999995079" rpy="0 0 0"/>
<mass value="0.011107100826766714077" />
<inertia ixx="1.8580899034455386872e-05" ixy="-4.052263004287151616e-22"  ixz="-1.0117787632511172689e-21" iyy="1.8580899034455386872e-05" iyz="-1.0615448880685626886e-22" izz="1.3883876033458398932e-07" />
</inertial>
</link>

<link name="closedloop7_A_3D">
<inertial>
<origin xyz="0 0 0" rpy="0 0 0" />
<mass value="1e-9" />
<inertia ixx="0" ixy="0" ixz="0" iyy="0" iyz="0" izz="0" />
</inertial>
</link>
<joint name="closedloop7_A_3D_frame" type="fixed">
<origin xyz="2.7755575615628913511e-17 -5.5511151231257827021e-17 -0.14142000000000004567" rpy="-3.141592653589793116 -2.5701272669893044796e-16 1.5487482446605287392e-16" />
<parent link="part_5_2" />
<child link="closedloop7_A_3D" />
<axis xyz="0 0 0"/>
</joint>

<joint name="spherical_4rod" type="revolute">
<origin xyz="0.0194837268435249511 -0.046047631733748414784 0" rpy="1.57079632679489678 0.15824418733945430637 1.5707963267948958919" />
<parent link="part_4_2" />
<child link="part_5_2" />
<axis xyz="0 0 1"/>
<limit effort="1" velocity="20" />
<joint_properties friction="0.0"/>
</joint>

<joint name="4rod_knee" type="revolute">
<origin xyz="0.046047631733745958416 -0.019483726843523313521 -1.1102230246251565404e-16" rpy="3.141592653589793116 2.0222300709208235426e-16 -1.2672660179279322534" />
<parent link="part_2_2" />
<child link="part_4_2" />
<axis xyz="0 0 1"/>
<limit effort="1" velocity="20" />
<joint_properties friction="0.0"/>
</joint>

<link name="motteur_rotation_4">
<visual>
<origin xyz="0.033000000000000001554 0.88825000000000020606 -0.10449999999999909361" rpy="1.570796326794896558 1.5707963267948927832 0" />
<geometry>
<mesh filename="package:///motteur_rotation.stl"/>
</geometry>
<material name="motteur_rotation_material">
<color rgba="1 0 0 1.0"/>
</material>
</visual>
<collision>
<origin xyz="0.033000000000000001554 0.88825000000000020606 -0.10449999999999909361" rpy="1.570796326794896558 1.5707963267948927832 0" />
<geometry>
<mesh filename="package:///motteur_rotation.stl"/>
</geometry>
</collision>
<inertial>
<origin xyz="-9.7925111873787854339e-17 0 -0.017243243243243222551" rpy="0 0 0"/>
<mass value="0.19339251676417060222" />
<inertia ixx="4.9207470246053568153e-05" ixy="9.2195496114233504155e-22"  ixz="1.6649633185126967165e-22" iyy="4.9207470246053520719e-05" iyz="-5.6408426651239359848e-20" izz="3.3697502678236661278e-05" />
</inertial>
</link>

<link name="piston_14">
<visual>
<origin xyz="-0.10179556944408774122 0.15392457132099854333 -0.8579999999999999849" rpy="5.5184706501581394422e-17 1.0102653392138596757e-17 -2.5003152933936445398e-17" />
<geometry>
<mesh filename="package:///piston.stl"/>
</geometry>
<material name="piston_material">
<color rgba="0.91764705882352937127 0.91764705882352937127 0.91764705882352937127 1.0"/>
</material>
</visual>
<collision>
<origin xyz="-0.10179556944408774122 0.15392457132099854333 -0.8579999999999999849" rpy="5.5184706501581394422e-17 1.0102653392138596757e-17 -2.5003152933936445398e-17" />
<geometry>
<mesh filename="package:///piston.stl"/>
</geometry>
</collision>
<inertial>
<origin xyz="-9.7144514654701197287e-17 4.0424596163214278435e-17 -0.011000000000000120792" rpy="0 0 0"/>
<mass value="0.0047041422996690132607" />
<inertia ixx="2.6977766073778931429e-07" ixy="-1.3173643011699640782e-23"  ixz="-4.3249117804461373126e-24" iyy="2.6977766073778931429e-07" iyz="1.7763177623857885991e-23" izz="1.6008784263561083015e-07" />
</inertial>
</link>

<link name="closedloop8_A_6D">
<inertial>
<origin xyz="0 0 0" rpy="0 0 0" />
<mass value="1e-9" />
<inertia ixx="0" ixy="0" ixz="0" iyy="0" iyz="0" izz="0" />
</inertial>
</link>
<joint name="closedloop8_A_6D_frame" type="fixed">
<origin xyz="-2.7755575615628913511e-17 -2.7755575615628913511e-17 -0.021999999999999991784" rpy="-3.141592653589793116 -7.5767938905805758326e-17 -1.570796326794896336" />
<parent link="piston_14" />
<child link="closedloop8_A_6D" />
<axis xyz="0 0 0"/>
</joint>

<joint name="motor_knee" type="prismatic">
<origin xyz="-8.2434059578417873126e-15 -1.8873791418627661187e-15 -0.0023309791397017609604" rpy="3.141592653589793116 1.4510931439305401901e-15 -4.1052068437918848451e-15" />
<parent link="motteur_rotation_4" />
<child link="piston_14" />
<axis xyz="0 0 1"/>
<limit effort="1" velocity="20" />
<joint_properties friction="0.0"/>
</joint>

<joint name="frame_motor_knee" type="revolute">
<origin xyz="-0.061655078133537336016 -0.018724201373191806663 4.297340261416593421e-12" rpy="-1.570796326794896558 1.2771385194773066107 -0.60601731071218278846" />
<parent link="part_2_2" />
<child link="motteur_rotation_4" />
<axis xyz="0 0 1"/>
<limit effort="1" velocity="20" />
<joint_properties friction="0.0"/>
</joint>

<joint name="upper_knee" type="revolute">
<origin xyz="-6.2450045135165055399e-17 0.046752000000000015767 -0.071500000000000007994" rpy="-3.1415926535897842342 -1.2696304357689524271e-15 0.22729525162017977236" />
<parent link="part_1" />
<child link="part_2_2" />
<axis xyz="0 0 1"/>
<limit effort="1" velocity="20" />
<joint_properties friction="0.0"/>
</joint>

<link name="part_8_2">
<visual>
<origin xyz="-2.7755575615628913511e-17 -0.046752000000000022706 0.087999999999999967137" rpy="1.570796326794896558 1.570796326794896558 0" />
<geometry>
<mesh filename="package:///part_8.stl"/>
</geometry>
<material name="part_8_material">
<color rgba="0.49803921568627451677 0.49803921568627451677 0.49803921568627451677 1.0"/>
</material>
</visual>
<collision>
<origin xyz="-2.7755575615628913511e-17 -0.046752000000000022706 0.087999999999999967137" rpy="1.570796326794896558 1.570796326794896558 0" />
<geometry>
<mesh filename="package:///part_8.stl"/>
</geometry>
</collision>
<inertial>
<origin xyz="0.031934770108260138177 0.010733820853410624974 -0.0056648401062836528652" rpy="0 0 0"/>
<mass value="0.0062040903886272725024" />
<inertia ixx="9.1742111640422036546e-07" ixy="-1.6316603808924172267e-07"  ixz="2.2769789117187733838e-07" iyy="1.3280669465102740276e-06" iyz="-1.4783479338790841636e-07" izz="1.7548720440932142221e-06" />
</inertial>
</link>

<link name="piston_15">
<visual>
<origin xyz="-0.10179556944408757468 -0.15392457132099851558 0.83600000000000007638" rpy="3.141592653589793116 3.0313180123444658749e-18 -1.4344834995909639864e-18" />
<geometry>
<mesh filename="package:///piston.stl"/>
</geometry>
<material name="piston_material">
<color rgba="0.91764705882352937127 0.91764705882352937127 0.91764705882352937127 1.0"/>
</material>
</visual>
<collision>
<origin xyz="-0.10179556944408757468 -0.15392457132099851558 0.83600000000000007638" rpy="3.141592653589793116 3.0313180123444658749e-18 -1.4344834995909639864e-18" />
<geometry>
<mesh filename="package:///piston.stl"/>
</geometry>
</collision>
<inertial>
<origin xyz="8.3266726846886740532e-17 -1.2079344994806974606e-17 -0.010999999999999787725" rpy="0 0 0"/>
<mass value="0.0047041422996690132607" />
<inertia ixx="2.6977766073778931429e-07" ixy="8.1379100244071893703e-24"  ixz="-5.1335311045345151016e-25" iyy="2.6977766073778920841e-07" iyz="-2.849347977685059506e-23" izz="1.6008784263561083015e-07" />
</inertial>
</link>

<link name="closedloop1_B_6D">
<inertial>
<origin xyz="0 0 0" rpy="0 0 0" />
<mass value="1e-9" />
<inertia ixx="0" ixy="0" ixz="0" iyy="0" iyz="0" izz="0" />
</inertial>
</link>
<joint name="closedloop1_B_6D_frame" type="fixed">
<origin xyz="5.5511151231257827021e-17 -5.5511151231257827021e-17 -0.021999999999999964029" rpy="-3.1415926535897900074 2.0244592807192931317e-15 -1.570796326794896336" />
<parent link="piston_15" />
<child link="closedloop1_B_6D" />
<axis xyz="0 0 0"/>
</joint>

<joint name="spherical_transmission_motor_hip1" type="revolute">
<origin xyz="0.043531328479973679935 0.0032046566522409558608 -0.025000000000000077716" rpy="1.5707963267948992225 -1.3881446540757451658 -3.1415926535897669147" />
<parent link="part_8_2" />
<child link="piston_15" />
<axis xyz="0 0 1"/>
<limit effort="1" velocity="20" />
<joint_properties friction="0.0"/>
</joint>

<link name="part_7_7">
<visual>
<origin xyz="0.062087559207389758642 -0.15255026628033768743 -0.40000000000000007772" rpy="-2.7213228885975979251e-17 -4.9312357427293890064e-17 3.0974761285468166481e-17" />
<geometry>
<mesh filename="package:///part_7.stl"/>
</geometry>
<material name="part_7_material">
<color rgba="0.91764705882352937127 0.91764705882352937127 0.91764705882352937127 1.0"/>
</material>
</visual>
<collision>
<origin xyz="0.062087559207389758642 -0.15255026628033768743 -0.40000000000000007772" rpy="-2.7213228885975979251e-17 -4.9312357427293890064e-17 3.0974761285468166481e-17" />
<geometry>
<mesh filename="package:///part_7.stl"/>
</geometry>
</collision>
<inertial>
<origin xyz="-8.3266726846886740532e-17 -8.0955879618977991587e-17 -0.20000000000000003886" rpy="0 0 0"/>
<mass value="0.031415926535897982508" />
<inertia ixx="0.00041907537001948915118" ixy="3.8001098215651305796e-20"  ixz="2.0659138009299931014e-20" iyy="0.00041907537001948915118" iyz="-1.139608053595072642e-20" izz="3.9269908169872559526e-07" />
</inertial>
</link>

<link name="closedloop10_A_3D">
<inertial>
<origin xyz="0 0 0" rpy="0 0 0" />
<mass value="1e-9" />
<inertia ixx="0" ixy="0" ixz="0" iyy="0" iyz="0" izz="0" />
</inertial>
</link>
<joint name="closedloop10_A_3D_frame" type="fixed">
<origin xyz="-8.6736173798840354721e-17 -1.1102230246251565404e-16 -0.40000000000000007772" rpy="1.4121142989576800076e-16 6.455226355074138767e-16 -4.8615344150257609708e-16" />
<parent link="part_7_7" />
<child link="closedloop10_A_3D" />
<axis xyz="0 0 0"/>
</joint>

<joint name="spherical_transmission_hip3" type="revolute">
<origin xyz="0.041074543378118832937 0.036577067764912832293 -0.005000000000000059952" rpy="-1.570796326794896558 0.67303436723393439411 3.141592653589793116" />
<parent link="part_8_2" />
<child link="part_7_7" />
<axis xyz="0 0 1"/>
<limit effort="1" velocity="20" />
<joint_properties friction="0.0"/>
</joint>

<joint name="transmission_hip1" type="revolute">
<origin xyz="-6.2450045135165055399e-17 0.046752000000000015767 -0.087999999999999967137" rpy="9.4681397285287776746e-15 -4.9405061162797479416e-15 0.77974518790642721733" />
<parent link="part_1" />
<child link="part_8_2" />
<axis xyz="0 0 1"/>
<limit effort="1" velocity="20" />
<joint_properties friction="0.0"/>
</joint>

<link name="part_9_2">
<visual>
<origin xyz="0 0.046752000000000001889 -0.055000000000000021094" rpy="-1.570796326794896558 -1.570796326794896558 0" />
<geometry>
<mesh filename="package:///part_9.stl"/>
</geometry>
<material name="part_9_material">
<color rgba="0.49803921568627451677 0.49803921568627451677 0.49803921568627451677 1.0"/>
</material>
</visual>
<collision>
<origin xyz="0 0.046752000000000001889 -0.055000000000000021094" rpy="-1.570796326794896558 -1.570796326794896558 0" />
<geometry>
<mesh filename="package:///part_9.stl"/>
</geometry>
</collision>
<inertial>
<origin xyz="0.031934770108260165933 -0.010733820853410638851 -0.005664840106283604293" rpy="0 0 0"/>
<mass value="0.0062040903886272699003" />
<inertia ixx="9.1742111640423370623e-07" ixy="1.6316603808924381378e-07"  ixz="2.2769789117187747073e-07" iyy="1.3280669465102729688e-06" iyz="1.4783479338790952809e-07" izz="1.7548720440932269276e-06" />
</inertial>
</link>

<link name="piston_16">
<visual>
<origin xyz="-0.1017955694440876302 -0.15392457132099854333 0.83599999999999985434" rpy="3.141592653589793116 1.8380694473692108142e-20 -2.2063544882257860807e-17" />
<geometry>
<mesh filename="package:///piston.stl"/>
</geometry>
<material name="piston_material">
<color rgba="0.91764705882352937127 0.91764705882352937127 0.91764705882352937127 1.0"/>
</material>
</visual>
<collision>
<origin xyz="-0.1017955694440876302 -0.15392457132099854333 0.83599999999999985434" rpy="3.141592653589793116 1.8380694473692108142e-20 -2.2063544882257860807e-17" />
<geometry>
<mesh filename="package:///piston.stl"/>
</geometry>
</collision>
<inertial>
<origin xyz="1.3877787807814456755e-17 -7.7292353175002801438e-17 -0.01100000000000000977" rpy="0 0 0"/>
<mass value="0.0047041422996690132607" />
<inertia ixx="2.6977766073778931429e-07" ixy="-2.4250340631096371772e-23"  ixz="4.3410945207216600811e-25" iyy="2.6977766073778931429e-07" iyz="7.2441089953997774678e-24" izz="1.6008784263561083015e-07" />
</inertial>
</link>

<link name="closedloop2_B_6D">
<inertial>
<origin xyz="0 0 0" rpy="0 0 0" />
<mass value="1e-9" />
<inertia ixx="0" ixy="0" ixz="0" iyy="0" iyz="0" izz="0" />
</inertial>
</link>
<joint name="closedloop2_B_6D_frame" type="fixed">
<origin xyz="0 -8.3266726846886740532e-17 -0.021999999999999977907" rpy="3.1415926535897926719 3.2544751110174058161e-15 -1.570796326794896558" />
<parent link="piston_16" />
<child link="closedloop2_B_6D" />
<axis xyz="0 0 0"/>
</joint>

<joint name="spherical_transmission_motor_hip2" type="revolute">
<origin xyz="0.043531328479973679935 -0.0032046566522410668831 -0.024999999999999938938" rpy="1.570796326794896558 -1.0520766825141583123 -1.2677408616997643214e-14" />
<parent link="part_9_2" />
<child link="piston_16" />
<axis xyz="0 0 1"/>
<limit effort="1" velocity="20" />
<joint_properties friction="0.0"/>
</joint>

<link name="part_7_8">
<visual>
<origin xyz="0.062087559207389841909 -0.1525502662803375209 -0.4000000000000000222" rpy="3.8060233474434495746e-17 -3.2833984157243235594e-17 2.4327067168634518076e-17" />
<geometry>
<mesh filename="package:///part_7.stl"/>
</geometry>
<material name="part_7_material">
<color rgba="0.91764705882352937127 0.91764705882352937127 0.91764705882352937127 1.0"/>
</material>
</visual>
<collision>
<origin xyz="0.062087559207389841909 -0.1525502662803375209 -0.4000000000000000222" rpy="3.8060233474434495746e-17 -3.2833984157243235594e-17 2.4327067168634518076e-17" />
<geometry>
<mesh filename="package:///part_7.stl"/>
</geometry>
</collision>
<inertial>
<origin xyz="-1.3877787807814456755e-17 8.4918173977677808342e-17 -0.19999999999999998335" rpy="0 0 0"/>
<mass value="0.031415926535897982508" />
<inertia ixx="0.00041907537001948915118" ixy="7.947469223284384149e-21"  ixz="1.3747665877502258623e-20" iyy="0.00041907537001948915118" iyz="1.5956314714796616443e-20" izz="3.9269908169872559526e-07" />
</inertial>
</link>

<link name="closedloop9_A_3D">
<inertial>
<origin xyz="0 0 0" rpy="0 0 0" />
<mass value="1e-9" />
<inertia ixx="0" ixy="0" ixz="0" iyy="0" iyz="0" izz="0" />
</inertial>
</link>
<joint name="closedloop9_A_3D_frame" type="fixed">
<origin xyz="0 6.2450045135165055399e-17 -0.40000000000000013323" rpy="-2.3882228318976020147e-15 -1.0948393169349909809e-15 -1.5707963267948972241" />
<parent link="part_7_8" />
<child link="closedloop9_A_3D" />
<axis xyz="0 0 0"/>
</joint>

<joint name="spherical_transmission_hip4" type="revolute">
<origin xyz="0.041074543378118888448 -0.036577067764912901682 -0.0050000000000000044409" rpy="1.570796326794896558 0.73924967494907445342 3.1415926535897851224" />
<parent link="part_9_2" />
<child link="part_7_8" />
<axis xyz="0 0 1"/>
<limit effort="1" velocity="20" />
<joint_properties friction="0.0"/>
</joint>

<joint name="transmission_hip2" type="revolute">
<origin xyz="-6.2450045135165055399e-17 0.046752000000000015767 -0.054999999999999993339" rpy="-3.1415926535897837901 -5.6800076792079728017e-15 0.82801632278258496811" />
<parent link="part_1" />
<child link="part_9_2" />
<axis xyz="0 0 1"/>
<limit effort="1" velocity="20" />
<joint_properties friction="0.0"/>
</joint>

<link name="piston_17">
<visual>
<origin xyz="-0.10179556944408768571 0.15392457132099859884 -0.85799999999999987388" rpy="-7.7035955094031656929e-17 2.0068078061820709058e-18 3.5700819086584817064e-18" />
<geometry>
<mesh filename="package:///piston.stl"/>
</geometry>
<material name="piston_material">
<color rgba="0.91764705882352937127 0.91764705882352937127 0.91764705882352937127 1.0"/>
</material>
</visual>
<collision>
<origin xyz="-0.10179556944408768571 0.15392457132099859884 -0.85799999999999987388" rpy="-7.7035955094031656929e-17 2.0068078061820709058e-18 3.5700819086584817064e-18" />
<geometry>
<mesh filename="package:///piston.stl"/>
</geometry>
</collision>
<inertial>
<origin xyz="-8.3266726846886740532e-17 4.5798488824920518216e-17 -0.01100000000000000977" rpy="0 0 0"/>
<mass value="0.0047041422996690132607" />
<inertia ixx="2.6977766073778931429e-07" ixy="1.608129261479285732e-23"  ixz="-7.7946788342991668606e-24" iyy="2.6977766073778931429e-07" iyz="-2.7932979143177590072e-23" izz="1.6008784263561083015e-07" />
</inertial>
</link>

<link name="closedloop8_B_6D">
<inertial>
<origin xyz="0 0 0" rpy="0 0 0" />
<mass value="1e-9" />
<inertia ixx="0" ixy="0" ixz="0" iyy="0" iyz="0" izz="0" />
</inertial>
</link>
<joint name="closedloop8_B_6D_frame" type="fixed">
<origin xyz="0 -1.3877787807814456755e-17 -0.022000000000000047296" rpy="9.6232195658333659591e-16 -1.7756561743236490927e-16 1.5707963267948978903" />
<parent link="piston_17" />
<child link="closedloop8_B_6D" />
<axis xyz="0 0 0"/>
</joint>

<joint name="spherical_motor_knee_holder" type="revolute">
<origin xyz="-0.013749999999999956701 0.0024999999999999744649 -0.072000000000000008438" rpy="-1.57079632679489678 -0.99860729712136542258 -1.5707963267949036634" />
<parent link="part_1" />
<child link="piston_17" />
<axis xyz="0 0 1"/>
<limit effort="1" velocity="20" />
<joint_properties friction="0.0"/>
</joint>

<link name="motteur_rotation_5">
<visual>
<origin xyz="0.03300000000000002931 0.88825000000000020606 -0.10449999999999912137" rpy="1.570796326794896558 1.5707963267948927832 0" />
<geometry>
<mesh filename="package:///motteur_rotation.stl"/>
</geometry>
<material name="motteur_rotation_material">
<color rgba="1 0 0 1.0"/>
</material>
</visual>
<collision>
<origin xyz="0.03300000000000002931 0.88825000000000020606 -0.10449999999999912137" rpy="1.570796326794896558 1.5707963267948927832 0" />
<geometry>
<mesh filename="package:///motteur_rotation.stl"/>
</geometry>
</collision>
<inertial>
<origin xyz="-8.0774250302767111022e-18 -3.3306690738754696213e-16 -0.017243243243243250307" rpy="0 0 0"/>
<mass value="0.19339251676417060222" />
<inertia ixx="4.9207470246053541048e-05" ixy="3.8466600980139597356e-22"  ixz="-2.2249546611953510428e-21" iyy="4.9207470246053561377e-05" iyz="-5.654027424343045174e-20" izz="3.3697502678236647725e-05" />
</inertial>
</link>

<link name="piston_18">
<visual>
<origin xyz="-0.10179556944408785224 -0.15392457132099859884 0.83599999999999996536" rpy="3.141592653589793116 5.8570179371731231987e-18 -3.7470352506369749676e-17" />
<geometry>
<mesh filename="package:///piston.stl"/>
</geometry>
<material name="piston_material">
<color rgba="0.91764705882352937127 0.91764705882352937127 0.91764705882352937127 1.0"/>
</material>
</visual>
<collision>
<origin xyz="-0.10179556944408785224 -0.15392457132099859884 0.83599999999999996536" rpy="3.141592653589793116 5.8570179371731231987e-18 -3.7470352506369749676e-17" />
<geometry>
<mesh filename="package:///piston.stl"/>
</geometry>
</collision>
<inertial>
<origin xyz="-1.8041124150158793782e-16 -2.5519274744455967854e-17 -0.010999999999999898748" rpy="0 0 0"/>
<mass value="0.0047041422996690132607" />
<inertia ixx="2.6977766073778931429e-07" ixy="-1.5936446037818668138e-23"  ixz="-3.7648861627789904991e-24" iyy="2.6977766073778931429e-07" iyz="-4.1721961375996565739e-23" izz="1.6008784263561083015e-07" />
</inertial>
</link>

<link name="closedloop1_A_6D">
<inertial>
<origin xyz="0 0 0" rpy="0 0 0" />
<mass value="1e-9" />
<inertia ixx="0" ixy="0" ixz="0" iyy="0" iyz="0" izz="0" />
</inertial>
</link>
<joint name="closedloop1_A_6D_frame" type="fixed">
<origin xyz="-1.6653345369377348106e-16 -8.3266726846886740532e-17 -0.02200000000000001954" rpy="-3.5035493923141009984e-15 1.2814418519762241213e-14 7.7830227665322737198e-18" />
<parent link="piston_18" />
<child link="closedloop1_A_6D" />
<axis xyz="0 0 0"/>
</joint>

<joint name="motor_ankle2" type="prismatic">
<origin xyz="4.2743586448068526806e-15 7.5772721430666933884e-15 0.021140168165682704515" rpy="3.1415926535897926719 1.8047950485096526647e-14 3.1415926535897802374" />
<parent link="motteur_rotation_5" />
<child link="piston_18" />
<axis xyz="0 0 1"/>
<limit effort="1" velocity="20" />
<joint_properties friction="0.0"/>
</joint>

<joint name="frame_motor_ankle1" type="revolute">
<origin xyz="0.054086706326755232266 0.014047405294960763067 -0.11825000000000002176" rpy="-1.570796326794896558 0.73498046737731748124 0.2858933777993256653" />
<parent link="part_1" />
<child link="motteur_rotation_5" />
<axis xyz="0 0 1"/>
<limit effort="1" velocity="20" />
<joint_properties friction="0.0"/>
</joint>

<link name="motteur_rotation_6">
<visual>
<origin xyz="0.033000000000000084821 0.88825000000000020606 -0.10449999999999910749" rpy="1.570796326794896558 1.5707963267948930053 0" />
<geometry>
<mesh filename="package:///motteur_rotation.stl"/>
</geometry>
<material name="motteur_rotation_material">
<color rgba="1 0 0 1.0"/>
</material>
</visual>
<collision>
<origin xyz="0.033000000000000084821 0.88825000000000020606 -0.10449999999999910749" rpy="1.570796326794896558 1.5707963267948930053 0" />
<geometry>
<mesh filename="package:///motteur_rotation.stl"/>
</geometry>
</collision>
<inertial>
<origin xyz="4.0469824391873859958e-17 -1.1102230246251565404e-16 -0.017243243243243264184" rpy="0 0 0"/>
<mass value="0.19339251676417060222" />
<inertia ixx="4.9207470246053541048e-05" ixy="-8.0661246340586886992e-23"  ixz="-8.0293218502517168479e-21" iyy="4.9207470246053534272e-05" iyz="-5.6295438736134967248e-20" izz="3.3697502678236661278e-05" />
</inertial>
</link>

<link name="piston_19">
<visual>
<origin xyz="-0.10179556944408776897 -0.15392457132099854333 0.83599999999999996536" rpy="-3.141592653589793116 1.9201584113773032332e-17 1.3666691791723158761e-17" />
<geometry>
<mesh filename="package:///piston.stl"/>
</geometry>
<material name="piston_material">
<color rgba="0.91764705882352937127 0.91764705882352937127 0.91764705882352937127 1.0"/>
</material>
</visual>
<collision>
<origin xyz="-0.10179556944408776897 -0.15392457132099854333 0.83599999999999996536" rpy="-3.141592653589793116 1.9201584113773032332e-17 1.3666691791723158761e-17" />
<geometry>
<mesh filename="package:///piston.stl"/>
</geometry>
</collision>
<inertial>
<origin xyz="-2.7755575615628913511e-17 -1.0173242892725766534e-17 -0.010999999999999898748" rpy="0 0 0"/>
<mass value="0.0047041422996690132607" />
<inertia ixx="2.6977766073778931429e-07" ixy="1.7585423779779781021e-23"  ixz="-1.8780385933889713329e-23" iyy="2.6977766073778931429e-07" iyz="-2.889454929313855312e-24" izz="1.6008784263561083015e-07" />
</inertial>
</link>

<link name="closedloop2_A_6D">
<inertial>
<origin xyz="0 0 0" rpy="0 0 0" />
<mass value="1e-9" />
<inertia ixx="0" ixy="0" ixz="0" iyy="0" iyz="0" izz="0" />
</inertial>
</link>
<joint name="closedloop2_A_6D_frame" type="fixed">
<origin xyz="-5.5511151231257827021e-17 -2.7755575615628913511e-17 -0.021999999999999964029" rpy="-1.3603990467924331356e-15 3.4203648913185160548e-15 4.0022067353557518153e-17" />
<parent link="piston_19" />
<child link="closedloop2_A_6D" />
<axis xyz="0 0 0"/>
</joint>

<joint name="motor_ankle1" type="prismatic">
<origin xyz="3.0531133177191804862e-16 -2.7755575615628913511e-17 0.018399835965480559885" rpy="-3.141592653589793116 2.2946682489661683897e-15 3.1415926535897926719" />
<parent link="motteur_rotation_6" />
<child link="piston_19" />
<axis xyz="0 0 1"/>
<limit effort="1" velocity="20" />
<joint_properties friction="0.0"/>
</joint>

<joint name="frame_motor_ankle2" type="revolute">
<origin xyz="0.054086706326755190632 0.014047405294960790823 -0.024750000000000021982" rpy="1.570796326794896558 -0.17956569756706666774 -2.8556992757904748892" />
<parent link="part_1" />
<child link="motteur_rotation_6" />
<axis xyz="0 0 1"/>
<limit effort="1" velocity="20" />
<joint_properties friction="0.0"/>
</joint>

<joint name="lower_hip" type="revolute">
<origin xyz="6.6000000000010494716e-05 -2.7755575615628913511e-17 -6.6000000000000086375e-05" rpy="-1.5707963267949025532 -1.1595523542658980887 -1.5707963267948952257" />
<parent link="cardan_foot_3" />
<child link="part_1" />
<axis xyz="0 0 1"/>
<limit effort="1" velocity="20" />
<joint_properties friction="0.0"/>
</joint>

<joint name="free_universal_yhip" type="revolute">
<origin xyz="0 -2.7755575615628913511e-17 -0.16500000000000009104" rpy="1.570796326794896558 -1.0038838022974944486e-17 -1.5707963267948992225" />
<parent link="hanche" />
<child link="cardan_foot_3" />
<axis xyz="0 0 1"/>
<limit effort="1" velocity="20" />
<joint_properties friction="0.0"/>
</joint>

<link name="cardan_hache_3">
<visual>
<origin xyz="0.10862500000000001321 0.85800000000000020695 -0.0055000000000023745172" rpy="1.570796326794896558 1.5707963267948930053 0" />
<geometry>
<mesh filename="package:///cardan_hache.stl"/>
</geometry>
<material name="cardan_hache_material">
<color rgba="0.49803921568627451677 0.49803921568627451677 0.49803921568627451677 1.0"/>
</material>
</visual>
<collision>
<origin xyz="0.10862500000000001321 0.85800000000000020695 -0.0055000000000023745172" rpy="1.570796326794896558 1.5707963267948930053 0" />
<geometry>
<mesh filename="package:///cardan_hache.stl"/>
</geometry>
</collision>
<inertial>
<origin xyz="6.9278991258672908181e-20 1.5061396574367336143e-11 -0.034629677480538460788" rpy="0 0 0"/>
<mass value="0.015608633111865791165" />
<inertia ixx="5.7160316393851747746e-06" ixy="-1.971086447913031903e-13"  ixz="7.2341229391976512443e-28" iyy="5.8966955959438793294e-06" iyz="9.5685519510128528437e-14" izz="7.220352682875461517e-07" />
</inertial>
</link>

<link name="moteur_hanche1_3">
<visual>
<origin xyz="-0.049500000000000710099 -0.85799999999999987388 -0.10862500000000001321" rpy="-1.570796326794896558 8.9950050068290457524e-19 -1.1173145081646938861e-16" />
<geometry>
<mesh filename="package:///moteur_hanche1.stl"/>
</geometry>
<material name="moteur_hanche1_material">
<color rgba="1 0 0 1.0"/>
</material>
</visual>
<collision>
<origin xyz="-0.049500000000000710099 -0.85799999999999987388 -0.10862500000000001321" rpy="-1.570796326794896558 8.9950050068290457524e-19 -1.1173145081646938861e-16" />
<geometry>
<mesh filename="package:///moteur_hanche1.stl"/>
</geometry>
</collision>
<inertial>
<origin xyz="6.2450045135165055399e-17 -0.012713533519811861042 -8.6137926851213809558e-18" rpy="0 0 0"/>
<mass value="0.17794962537636813127" />
<inertia ixx="3.4377373668620134326e-05" ixy="-3.8867373524181810196e-21"  ixz="2.0081036527363510443e-23" iyy="4.1215284105260616121e-05" iyz="3.5447475520577351224e-22" izz="3.4002456645612650764e-05" />
</inertial>
</link>

<link name="piston_20">
<visual>
<origin xyz="-0.10179556944408760244 0.15392457132099851558 -0.85799999999999987388" rpy="5.034370346941301877e-18 8.5534377630391343787e-17 -4.5276847853595702643e-18" />
<geometry>
<mesh filename="package:///piston.stl"/>
</geometry>
<material name="piston_material">
<color rgba="0.91764705882352937127 0.91764705882352937127 0.91764705882352937127 1.0"/>
</material>
</visual>
<collision>
<origin xyz="-0.10179556944408760244 0.15392457132099851558 -0.85799999999999987388" rpy="5.034370346941301877e-18 8.5534377630391343787e-17 -4.5276847853595702643e-18" />
<geometry>
<mesh filename="package:///piston.stl"/>
</geometry>
</collision>
<inertial>
<origin xyz="1.3877787807814456755e-17 2.2453291384355164582e-17 -0.011000000000000120792" rpy="0 0 0"/>
<mass value="0.0047041422996690132607" />
<inertia ixx="2.6977766073778931429e-07" ixy="-6.63673206890854224e-25"  ixz="-2.9758531523575276022e-23" iyy="2.6977766073778920841e-07" iyz="4.4311102508401006788e-25" izz="1.6008784263561077721e-07" />
</inertial>
</link>

<link name="closedloop4_B_6D">
<inertial>
<origin xyz="0 0 0" rpy="0 0 0" />
<mass value="1e-9" />
<inertia ixx="0" ixy="0" ixz="0" iyy="0" iyz="0" izz="0" />
</inertial>
</link>
<joint name="closedloop4_B_6D_frame" type="fixed">
<origin xyz="5.5511151231257827021e-17 0 -0.021999999999999887701" rpy="-5.2397508177699997199e-14 7.9985639615515115397e-15 -6.9853190798646948938e-18" />
<parent link="piston_20" />
<child link="closedloop4_B_6D" />
<axis xyz="0 0 0"/>
</joint>

<joint name="motor_hip_xy_2" type="prismatic">
<origin xyz="0 -0.026361686710175066817 -1.9428902930940239457e-16" rpy="-1.5707963267949502928 -7.9875720912898989692e-15 7.040089964984604181e-15" />
<parent link="moteur_hanche1_3" />
<child link="piston_20" />
<axis xyz="0 0 1"/>
<limit effort="1" velocity="20" />
<joint_properties friction="0.0"/>
</joint>

<joint name="free_motor_holder_hipxy2" type="revolute">
<origin xyz="-2.7755575615628913511e-17 -6.9388939039072283776e-17 -0.055000000000000062728" rpy="-1.570796326794896558 -1.1268255606165180627 1.5707963267948938935" />
<parent link="cardan_hache_3" />
<child link="moteur_hanche1_3" />
<axis xyz="0 0 1"/>
<limit effort="1" velocity="20" />
<joint_properties friction="0.0"/>
</joint>

<joint name="free_motor_holder_1" type="revolute">
<origin xyz="0.012499999999999998959 -0.037124999999999658273 -0.077000000000000151656" rpy="1.57079632679489678 -0.033001070205816974978 -1.5707963267948974462" />
<parent link="hanche" />
<child link="cardan_hache_3" />
<axis xyz="0 0 1"/>
<limit effort="1" velocity="20" />
<joint_properties friction="0.0"/>
</joint>

<link name="cardan_hache_4">
<visual>
<origin xyz="0.10862499999999997158 0.85800000000000009592 -0.0055000000000023745172" rpy="1.570796326794896558 1.5707963267948930053 0" />
<geometry>
<mesh filename="package:///cardan_hache.stl"/>
</geometry>
<material name="cardan_hache_material">
<color rgba="0.49803921568627451677 0.49803921568627451677 0.49803921568627451677 1.0"/>
</material>
</visual>
<collision>
<origin xyz="0.10862499999999997158 0.85800000000000009592 -0.0055000000000023745172" rpy="1.570796326794896558 1.5707963267948930053 0" />
<geometry>
<mesh filename="package:///cardan_hache.stl"/>
</geometry>
</collision>
<inertial>
<origin xyz="-4.175543159526418155e-17 1.5061396574367336143e-11 -0.034629677480538460788" rpy="0 0 0"/>
<mass value="0.015608633111865791165" />
<inertia ixx="5.7160316393851747746e-06" ixy="-1.971086447689202403e-13"  ixz="7.2343363232807057219e-28" iyy="5.8966955959438776354e-06" iyz="9.5685519510128515815e-14" izz="7.220352682875461517e-07" />
</inertial>
</link>

<link name="moteur_hanche1_4">
<visual>
<origin xyz="-0.049500000000000772549 -0.8579999999999999849 -0.10862499999999997158" rpy="-1.570796326794896558 -1.2638763838006455506e-18 -5.2226317901577246501e-17" />
<geometry>
<mesh filename="package:///moteur_hanche1.stl"/>
</geometry>
<material name="moteur_hanche1_material">
<color rgba="1 0 0 1.0"/>
</material>
</visual>
<collision>
<origin xyz="-0.049500000000000772549 -0.8579999999999999849 -0.10862499999999997158" rpy="-1.570796326794896558 -1.2638763838006455506e-18 -5.2226317901577246501e-17" />
<geometry>
<mesh filename="package:///moteur_hanche1.stl"/>
</geometry>
</collision>
<inertial>
<origin xyz="-2.0816681711721685133e-17 -0.012713533519811861042 2.626351889156016982e-17" rpy="0 0 0"/>
<mass value="0.17794962537636813127" />
<inertia ixx="3.4377373668620134326e-05" ixy="-2.8924313380968283259e-21"  ixz="-2.4191328857964440545e-23" iyy="4.1215284105260629674e-05" iyz="-3.5971653051358820958e-23" izz="3.4002456645612650764e-05" />
</inertial>
</link>

<link name="piston_21">
<visual>
<origin xyz="-0.10179556944408771346 0.15392457132099846007 -0.8579999999999999849" rpy="1.7056308624938989362e-18 2.6110465797600211382e-17 -3.4647986614754371482e-18" />
<geometry>
<mesh filename="package:///piston.stl"/>
</geometry>
<material name="piston_material">
<color rgba="0.91764705882352937127 0.91764705882352937127 0.91764705882352937127 1.0"/>
</material>
</visual>
<collision>
<origin xyz="-0.10179556944408771346 0.15392457132099846007 -0.8579999999999999849" rpy="1.7056308624938989362e-18 2.6110465797600211382e-17 -3.4647986614754371482e-18" />
<geometry>
<mesh filename="package:///piston.stl"/>
</geometry>
</collision>
<inertial>
<origin xyz="-5.5511151231257827021e-17 -2.9772157069498963504e-17 -0.011000000000000120792" rpy="0 0 0"/>
<mass value="0.0047041422996690132607" />
<inertia ixx="2.6977766073778931429e-07" ixy="-8.9146130759727108705e-25"  ixz="-6.8621757468507680815e-24" iyy="2.6977766073778920841e-07" iyz="1.4565821418991627209e-25" izz="1.6008784263561083015e-07" />
</inertial>
</link>

<link name="closedloop3_B_6D">
<inertial>
<origin xyz="0 0 0" rpy="0 0 0" />
<mass value="1e-9" />
<inertia ixx="0" ixy="0" ixz="0" iyy="0" iyz="0" izz="0" />
</inertial>
</link>
<joint name="closedloop3_B_6D_frame" type="fixed">
<origin xyz="-4.1633363423443370266e-17 -8.3266726846886740532e-17 -0.022000000000000005662" rpy="-3.8323071526180824844e-15 1.9454298298622066299e-16 1.4021234671943678824e-17" />
<parent link="piston_21" />
<child link="closedloop3_B_6D" />
<axis xyz="0 0 0"/>
</joint>

<joint name="motor_hip_xy_1" type="prismatic">
<origin xyz="5.5511151231257827021e-17 -0.026357933593704453712 2.7755575615628913511e-17" rpy="-1.5707963267948994446 2.6524860729722982745e-15 1.8903718014666384216e-15" />
<parent link="moteur_hanche1_4" />
<child link="piston_21" />
<axis xyz="0 0 1"/>
<limit effort="1" velocity="20" />
<joint_properties friction="0.0"/>
</joint>

<joint name="free_motor_holder_hipxy1" type="revolute">
<origin xyz="-2.7755575615628913511e-17 1.6653345369377348106e-16 -0.054999999999999979461" rpy="-1.57079632679489678 1.1267886452730790925 1.5707963267949007768" />
<parent link="cardan_hache_4" />
<child link="moteur_hanche1_4" />
<axis xyz="0 0 1"/>
<limit effort="1" velocity="20" />
<joint_properties friction="0.0"/>
</joint>

<joint name="free_motor_holder_3" type="revolute">
<origin xyz="0.012499999999999998959 0.037125000000000019096 -0.077000000000000151656" rpy="-1.570796326794896558 -0.029979973678264791592 1.5707963267948958919" />
<parent link="hanche" />
<child link="cardan_hache_4" />
<axis xyz="0 0 1"/>
<limit effort="1" velocity="20" />
<joint_properties friction="0.0"/>
</joint>

<link name="piston_22">
<visual>
<origin xyz="-0.10179556944408765795 0.15392457132099851558 -0.85800000000000009592" rpy="3.219160792380629143e-31 2.4168483622926910372e-32 1.2679065777781923061e-18" />
<geometry>
<mesh filename="package:///piston.stl"/>
</geometry>
<material name="piston_material">
<color rgba="0.91764705882352937127 0.91764705882352937127 0.91764705882352937127 1.0"/>
</material>
</visual>
<collision>
<origin xyz="-0.10179556944408765795 0.15392457132099851558 -0.85800000000000009592" rpy="3.219160792380629143e-31 2.4168483622926910372e-32 1.2679065777781923061e-18" />
<geometry>
<mesh filename="package:///piston.stl"/>
</geometry>
</collision>
<inertial>
<origin xyz="0 1.290672720867797563e-19 -0.011000000000000231815" rpy="0 0 0"/>
<mass value="0.0047041422996690132607" />
<inertia ixx="2.6977766073778931429e-07" ixy="8.6147331510139461319e-26"  ixz="-5.5878340125063292427e-39" iyy="2.6977766073778931429e-07" iyz="7.6305446136664883448e-38" izz="1.6008784263561083015e-07" />
</inertial>
</link>

<link name="closedloop5_B_6D">
<inertial>
<origin xyz="0 0 0" rpy="0 0 0" />
<mass value="1e-9" />
<inertia ixx="0" ixy="0" ixz="0" iyy="0" iyz="0" izz="0" />
</inertial>
</link>
<joint name="closedloop5_B_6D_frame" type="fixed">
<origin xyz="0 -2.7755575615628913511e-17 -0.022000000000000231176" rpy="3.1415926535897917837 9.3675067702747509143e-17 -1.570796326794896558" />
<parent link="piston_22" />
<child link="closedloop5_B_6D" />
<axis xyz="0 0 0"/>
</joint>

<joint name="free_spherical_motor_holder_hipz" type="revolute">
<origin xyz="3.380976054678797027e-15 0.038499999999999978684 -0.046750000000000131728" rpy="1.570796326794896558 0.051824161433119159126 1.5707963267948945596" />
<parent link="hanche" />
<child link="piston_22" />
<axis xyz="0 0 1"/>
<limit effort="1" velocity="20" />
<joint_properties friction="0.0"/>
</joint>

<joint name="free_zhip" type="revolute">
<origin xyz="0.012499999999999891406 -0.029749999999999887645 -0.20500000000000001554" rpy="-1.570796326794896558 2.6592413774926255711e-28 -3.5042375413817778047e-15" />
<parent link="hanche_batis" />
<child link="hanche" />
<axis xyz="0 0 1"/>
<limit effort="1" velocity="20" />
<joint_properties friction="0.0"/>
</joint>

<link name="attache_hanche">
<visual>
<origin xyz="0.12099999999999908051 0.033000000000000057065 -0.94000000000000016875" rpy="-3.3073821090691880549e-31 -3.6701587590914506434e-15 5.0518048865126687647e-32" />
<geometry>
<mesh filename="package:///attache_hanche.stl"/>
</geometry>
<material name="attache_hanche_material">
<color rgba="0.64705882352941179736 0.64705882352941179736 0.64705882352941179736 1.0"/>
</material>
</visual>
<collision>
<origin xyz="0.12099999999999908051 0.033000000000000057065 -0.94000000000000016875" rpy="-3.3073821090691880549e-31 -3.6701587590914506434e-15 5.0518048865126687647e-32" />
<geometry>
<mesh filename="package:///attache_hanche.stl"/>
</geometry>
</collision>
<inertial>
<origin xyz="0 1.3877787807814752578e-17 -0.030000000000000137668" rpy="0 0 0"/>
<mass value="0.01282947899909727546" />
<inertia ixx="4.0671453033231804464e-06" ixy="-9.2974170372714098574e-37"  ixz="1.3324665874380659771e-20" iyy="4.0671453033231812934e-06" iyz="-1.2007589974979871814e-36" izz="4.366032071880294742e-07" />
</inertial>
</link>

<link name="motteur_rotation_7">
<visual>
<origin xyz="0.033000000000000112577 0.8882500000000004281 -0.12099999999999910827" rpy="1.570796326794896558 1.5707963267948930053 0" />
<geometry>
<mesh filename="package:///motteur_rotation.stl"/>
</geometry>
<material name="motteur_rotation_material">
<color rgba="1 0 0 1.0"/>
</material>
</visual>
<collision>
<origin xyz="0.033000000000000112577 0.8882500000000004281 -0.12099999999999910827" rpy="1.570796326794896558 1.5707963267948930053 0" />
<geometry>
<mesh filename="package:///motteur_rotation.stl"/>
</geometry>
</collision>
<inertial>
<origin xyz="6.7839909838383009861e-17 1.1102230246251565404e-16 -0.033743243243243278839" rpy="0 0 0"/>
<mass value="0.19339251676417060222" />
<inertia ixx="4.9207470246053541048e-05" ixy="3.4691714546122661293e-22"  ixz="-1.1518995707636508857e-35" iyy="4.9207470246053534272e-05" iyz="-5.6924043322247439459e-20" izz="3.3697502678236647725e-05" />
</inertial>
</link>

<link name="piston_23">
<visual>
<origin xyz="-0.10179556944408768571 0.15392457132099851558 -0.85800000000000009592" rpy="-2.6525568067993152251e-31 1.2917052706353728952e-31 -1.2373741884625232068e-18" />
<geometry>
<mesh filename="package:///piston.stl"/>
</geometry>
<material name="piston_material">
<color rgba="0.91764705882352937127 0.91764705882352937127 0.91764705882352937127 1.0"/>
</material>
</visual>
<collision>
<origin xyz="-0.10179556944408768571 0.15392457132099851558 -0.85800000000000009592" rpy="-2.6525568067993152251e-31 1.2917052706353728952e-31 -1.2373741884625232068e-18" />
<geometry>
<mesh filename="package:///piston.stl"/>
</geometry>
</collision>
<inertial>
<origin xyz="-4.1633363423443370266e-17 -1.2595921012997231723e-19 -0.011000000000000231815" rpy="0 0 0"/>
<mass value="0.0047041422996690132607" />
<inertia ixx="2.6977766073778920841e-07" ixy="1.4416229916061300168e-24"  ixz="-3.739691011276885034e-38" iyy="2.6977766073778931429e-07" iyz="-7.4194641007668424928e-38" izz="1.6008784263561083015e-07" />
</inertial>
</link>

<link name="closedloop5_A_6D">
<inertial>
<origin xyz="0 0 0" rpy="0 0 0" />
<mass value="1e-9" />
<inertia ixx="0" ixy="0" ixz="0" iyy="0" iyz="0" izz="0" />
</inertial>
</link>
<joint name="closedloop5_A_6D_frame" type="fixed">
<origin xyz="-2.0816681711721685133e-17 0 -0.021999999999999936273" rpy="4.0939474033052918599e-16 2.1380466841413380764e-16 6.2026386493102164692e-16" />
<parent link="piston_23" />
<child link="closedloop5_A_6D" />
<axis xyz="0 0 0"/>
</joint>

<joint name="motor_hipz" type="prismatic">
<origin xyz="-1.3877787807814456755e-16 -3.8163916471489756077e-16 -0.07149999999999984146" rpy="-2.1233015345958434142e-15 4.128211776064302964e-17 -1.5707963267949134334" />
<parent link="motteur_rotation_7" />
<child link="piston_23" />
<axis xyz="0 0 1"/>
<limit effort="1" velocity="20" />
<joint_properties friction="0.0"/>
</joint>

<joint name="free_spherical_motor_holder_1" type="revolute">
<origin xyz="1.3877787807814456755e-17 -8.3266726846886740532e-17 -0.051749999999999775346" rpy="1.5707963267948976682 -0.051824161433118527686 1.5707963267948943376" />
<parent link="attache_hanche" />
<child link="motteur_rotation_7" />
<axis xyz="0 0 1"/>
<limit effort="1" velocity="20" />
<joint_properties friction="0.0"/>
</joint>

<joint name="free_motor_holder_2" type="revolute">
<origin xyz="-0.10299999999999680245 -0.024749999999999584832 -0.24349999999999993872" rpy="1.570796326794896558 4.4226638947527427442e-16 3.1415926535897895633" />
<parent link="hanche_batis" />
<child link="attache_hanche" />
<axis xyz="0 0 1"/>
<limit effort="1" velocity="20" />
<joint_properties friction="0.0"/>
</joint>

<joint name="test" type="fixed">
<origin xyz="-1.7347234759768070944e-17 5.5511151231257827021e-17 0.024750000000000049738" rpy="1.570796326794896558 -4.5021244384580876102e-15 -8.9782231775462504888e-29" />
<parent link="hanche_batis_gauche" />
<child link="hanche_batis" />
<axis xyz="0 0 1"/>
<limit effort="1" velocity="20" />
<joint_properties friction="0.0"/>
</joint>

<link name="attache_hanche_2">
<visual>
<origin xyz="0.12099999999999905276 0.033000000000000036249 -0.94000000000000027978" rpy="-3.3032027445473105087e-31 -3.6701587590914514323e-15 -5.9383014041950064178e-20" />
<geometry>
<mesh filename="package:///attache_hanche.stl"/>
</geometry>
<material name="attache_hanche_material">
<color rgba="0.64705882352941179736 0.64705882352941179736 0.64705882352941179736 1.0"/>
</material>
</visual>
<collision>
<origin xyz="0.12099999999999905276 0.033000000000000036249 -0.94000000000000027978" rpy="-3.3032027445473105087e-31 -3.6701587590914514323e-15 -5.9383014041950064178e-20" />
<geometry>
<mesh filename="package:///attache_hanche.stl"/>
</geometry>
</collision>
<inertial>
<origin xyz="-1.3877787807814456755e-17 7.185344699375529548e-21 -0.03000000000000024869" rpy="0 0 0"/>
<mass value="0.01282947899909727546" />
<inertia ixx="4.0671453033231787523e-06" ixy="1.343993050242305916e-24"  ixz="1.3324665874380656762e-20" iyy="4.0671453033231795993e-06" iyz="-1.200494724996204359e-36" izz="4.366032071880294742e-07" />
</inertial>
</link>

<link name="motteur_rotation_8">
<visual>
<origin xyz="0.033000000000000001554 0.88825000000000031708 -0.12099999999999908051" rpy="1.570796326794896558 1.5707963267948930053 0" />
<geometry>
<mesh filename="package:///motteur_rotation.stl"/>
</geometry>
<material name="motteur_rotation_material">
<color rgba="1 0 0 1.0"/>
</material>
</visual>
<collision>
<origin xyz="0.033000000000000001554 0.88825000000000031708 -0.12099999999999908051" rpy="1.570796326794896558 1.5707963267948930053 0" />
<geometry>
<mesh filename="package:///motteur_rotation.stl"/>
</geometry>
</collision>
<inertial>
<origin xyz="-7.1700528675036109864e-18 0 -0.033743243243243264962" rpy="0 0 0"/>
<mass value="0.19339251676417060222" />
<inertia ixx="4.9207470246053541048e-05" ixy="-3.1602615851609358553e-21"  ixz="-4.5625133944400991234e-24" iyy="4.9207470246053534272e-05" iyz="-5.6931792837572335458e-20" izz="3.3697502678236634173e-05" />
</inertial>
</link>

<link name="piston_24">
<visual>
<origin xyz="-0.10179556944408765795 0.15392457132099851558 -0.85799999999999976286" rpy="-9.8367137873644146436e-21 -1.3954966903031521671e-19 3.1315269419016519706e-17" />
<geometry>
<mesh filename="package:///piston.stl"/>
</geometry>
<material name="piston_material">
<color rgba="0.91764705882352937127 0.91764705882352937127 0.91764705882352937127 1.0"/>
</material>
</visual>
<collision>
<origin xyz="-0.10179556944408765795 0.15392457132099851558 -0.85799999999999976286" rpy="-9.8367137873644146436e-21 -1.3954966903031521671e-19 3.1315269419016519706e-17" />
<geometry>
<mesh filename="package:///piston.stl"/>
</geometry>
</collision>
<inertial>
<origin xyz="-1.3877787807814456755e-17 3.2823043329686977149e-18 -0.01100000000000000977" rpy="0 0 0"/>
<mass value="0.0047041422996690132607" />
<inertia ixx="2.6977766073778920841e-07" ixy="3.7194156174106487385e-24"  ixz="7.8149232145050931895e-28" iyy="2.6977766073778931429e-07" iyz="1.5216509818469511028e-26" izz="1.6008784263561077721e-07" />
</inertial>
</link>

<link name="closedloop19_A_6D">
<inertial>
<origin xyz="0 0 0" rpy="0 0 0" />
<mass value="1e-9" />
<inertia ixx="0" ixy="0" ixz="0" iyy="0" iyz="0" izz="0" />
</inertial>
</link>
<joint name="closedloop19_A_6D_frame" type="fixed">
<origin xyz="-2.4286128663675299322e-17 1.3877787807814456755e-17 -0.021999999999999981376" rpy="-9.4645443920224450633e-16 4.3138963368770645641e-15 -1.570796326794896558" />
<parent link="piston_24" />
<child link="closedloop19_A_6D" />
<axis xyz="0 0 0"/>
</joint>

<joint name="motor_hip_z_left" type="prismatic">
<origin xyz="5.5511151231257827021e-17 3.4694469519536141888e-18 -0.070937073864986127658" rpy="-2.3978477236838945599e-15 -1.3376382854703311896e-16 -1.570796326794871467" />
<parent link="motteur_rotation_8" />
<child link="piston_24" />
<axis xyz="0 0 1"/>
<limit effort="1" velocity="20" />
<joint_properties friction="0.0"/>
</joint>

<joint name="spherical_motor_holder_hip_z_left" type="revolute">
<origin xyz="-1.3877787807814456755e-17 -5.5511151231257827021e-17 -0.051749999999999823919" rpy="1.570796326794896336 1.3223675276875890283 1.5707963267949045516" />
<parent link="attache_hanche_2" />
<child link="motteur_rotation_8" />
<axis xyz="0 0 1"/>
<limit effort="1" velocity="20" />
<joint_properties friction="0.0"/>
</joint>

<joint name="free_universal_motor_holder_hipz_left" type="revolute">
<origin xyz="-0.10299999999999671918 0.0065000000000000057732 -1.1102230246251565404e-16" rpy="8.2923786594574648618e-18 8.3515882679392369696e-16 -3.1380685543604354137" />
<parent link="hanche_batis_gauche" />
<child link="attache_hanche_2" />
<axis xyz="0 0 1"/>
<limit effort="1" velocity="20" />
<joint_properties friction="0.0"/>
</joint>


</robot>
