<robot name="onshape">
<link name="hanche_batis_gauche">
<visual>
<origin xyz="0.018000000000003173184 0.52649999999999996803 -0.94000000000000016875" rpy="-3.0121599956385240381e-42 -4.5021244384580876102e-15 -8.9790747947209470253e-29" />
<geometry>
<mesh filename="package:///hanche_batis_gauche.stl"/>
</geometry>
<material name="hanche_batis_gauche_material">
<color rgba="0.61568627450980395466 0.81176470588235294379 0.92941176470588238168 1.0"/>
</material>
</visual>
<collision>
<origin xyz="0.018000000000003173184 0.52649999999999996803 -0.94000000000000016875" rpy="-3.0121599956385240381e-42 -4.5021244384580876102e-15 -8.9790747947209470253e-29" />
<geometry>
<mesh filename="package:///hanche_batis_gauche.stl"/>
</geometry>
</collision>
<inertial>
<origin xyz="-0.0014786115366823872341 0.12234575313934131779 0.024304995635825329264" rpy="0 0 0"/>
<mass value="1.5865591647149870358" />
<inertia ixx="0.0088382827967695681143" ixy="-0.00027487762182023519958"  ixz="-2.9207645496747368895e-05" iyy="0.0025754201921632971332" iyz="-6.8858407992622986575e-05" izz="0.010752178054608367563" />
</inertial>
</link>

<link name="hanche_gauche">
<visual>
<origin xyz="0.0055000000000023745172 0.48149999999999998357 -0.93500000000000027534" rpy="-3.3280069439011435541e-31 -3.6701587590914506434e-15 -1.7765336303158987701e-18" />
<geometry>
<mesh filename="package:///hanche_gauche.stl"/>
</geometry>
<material name="hanche_gauche_material">
<color rgba="0.2313725490196078538 0.38039215686274507888 0.7058823529411765163 1.0"/>
</material>
</visual>
<collision>
<origin xyz="0.0055000000000023745172 0.48149999999999998357 -0.93500000000000027534" rpy="-3.3280069439011435541e-31 -3.6701587590914506434e-15 -1.7765336303158987701e-18" />
<geometry>
<mesh filename="package:///hanche_gauche.stl"/>
</geometry>
</collision>
<inertial>
<origin xyz="-4.802391351775570083e-09 -0.0030510712498241776558 -0.083365235886017852174" rpy="0 0 0"/>
<mass value="0.14908820308432116364" />
<inertia ixx="0.00035636864608480205976" ixy="1.524371537207324168e-10"  ixz="3.2083460589900760773e-10" iyy="0.00032228378845976208373" iyz="1.6655090320431484974e-05" izz="4.9201075862855858688e-05" />
</inertial>
</link>

<link name="cardan_foot">
<visual>
<origin xyz="0 0.038499999999999978684 -6.6000000000000086375e-05" rpy="1.570796326794896558 1.570796326794896558 0" />
<geometry>
<mesh filename="package:///cardan_foot.stl"/>
</geometry>
<material name="cardan_foot_material">
<color rgba="0.64705882352941179736 0.64705882352941179736 0.64705882352941179736 1.0"/>
</material>
</visual>
<collision>
<origin xyz="0 0.038499999999999978684 -6.6000000000000086375e-05" rpy="1.570796326794896558 1.570796326794896558 0" />
<geometry>
<mesh filename="package:///cardan_foot.stl"/>
</geometry>
</collision>
<inertial>
<origin xyz="6.7228290681873054761e-09 -1.3877787807814456755e-17 -6.5993277170931446225e-05" rpy="0 0 0"/>
<mass value="0.0064135211594024193679" />
<inertia ixx="3.3475011343990655066e-07" ixy="-2.848658323731531802e-12"  ixz="4.18217495851782041e-25" iyy="4.3082408299805979528e-07" iyz="2.84865832377020088e-12" izz="3.3475011343990649772e-07" />
</inertial>
</link>

<link name="part_1_gauche">
<visual>
<origin xyz="6.2450045135165055399e-17 0 0.076999999999999999001" rpy="-1.570796326794896558 -1.570796326794896558 0" />
<geometry>
<mesh filename="package:///part_1_gauche.stl"/>
</geometry>
<material name="part_1_gauche_material">
<color rgba="0.34901960784313723618 0.37647058823529411242 0.4000000000000000222 1.0"/>
</material>
</visual>
<collision>
<origin xyz="6.2450045135165055399e-17 0 0.076999999999999999001" rpy="-1.570796326794896558 -1.570796326794896558 0" />
<geometry>
<mesh filename="package:///part_1_gauche.stl"/>
</geometry>
</collision>
<inertial>
<origin xyz="0.0067026040073146185561 -0.016607315579005136469 -0.045523329336489434804" rpy="0 0 0"/>
<mass value="0.24432174482850427255" />
<inertia ixx="0.00038002986506503223796" ixy="4.5343822748855145202e-05"  ixz="0.00019115477820551995567" iyy="0.00063262805487850645812" iyz="-7.009667120503671519e-05" izz="0.00036002210136874579797" />
</inertial>
</link>

<link name="closedloop13_B_3D">
<inertial>
<origin xyz="0 0 0" rpy="0 0 0" />
<mass value="1e-9" />
<inertia ixx="0" ixy="0" ixz="0" iyy="0" iyz="0" izz="0" />
</inertial>
</link>
<joint name="closedloop13_B_3D_frame" type="fixed">
<origin xyz="0.083867056794542510501 0.007711903501502720415 -0.071500000000000063505" rpy="1.570796326794896558 -2.7708369985933544671e-19 3.141592653589793116" />
<parent link="part_1_gauche" />
<child link="closedloop13_B_3D" />
<axis xyz="0 0 0"/>
</joint>

<link name="piston">
<visual>
<origin xyz="-0.10179556944408768571 0.15392457132099851558 -0.8579999999999999849" rpy="4.4164072410610472098e-20 4.8517792999468327746e-19 8.7970689560333116979e-19" />
<geometry>
<mesh filename="package:///piston.stl"/>
</geometry>
<material name="piston_material">
<color rgba="0.91764705882352937127 0.91764705882352937127 0.91764705882352937127 1.0"/>
</material>
</visual>
<collision>
<origin xyz="-0.10179556944408768571 0.15392457132099851558 -0.8579999999999999849" rpy="4.4164072410610472098e-20 4.8517792999468327746e-19 8.7970689560333116979e-19" />
<geometry>
<mesh filename="package:///piston.stl"/>
</geometry>
</collision>
<inertial>
<origin xyz="-4.1633363423443370266e-17 1.3010165000612962701e-19 -0.011000000000000120792" rpy="0 0 0"/>
<mass value="0.0047041422996690132607" />
<inertia ixx="2.6977766073778920841e-07" ixy="1.7800258376150092551e-25"  ixz="4.5466131604471819355e-25" iyy="2.6977766073778931429e-07" iyz="1.9578923874968508301e-26" izz="1.6008784263561083015e-07" />
</inertial>
</link>

<link name="closedloop17_A_6D">
<inertial>
<origin xyz="0 0 0" rpy="0 0 0" />
<mass value="1e-9" />
<inertia ixx="0" ixy="0" ixz="0" iyy="0" iyz="0" izz="0" />
</inertial>
</link>
<joint name="closedloop17_A_6D_frame" type="fixed">
<origin xyz="0 2.168404344971008868e-17 -0.021999999999999964029" rpy="3.141592653589793116 -4.8517792999468327746e-19 -3.141592653589793116" />
<parent link="piston" />
<child link="closedloop17_A_6D" />
<axis xyz="0 0 0"/>
</joint>

<joint name="free_spherical_hip_xy_1_left" type="revolute">
<origin xyz="-0.06049999999999995659 1.3877787807814456755e-16 -0.038500000000000034195" rpy="1.570796326794896558 4.477119026960201655e-15 -9.9292638772409921535e-16" />
<parent link="part_1_gauche" />
<child link="piston" />
<axis xyz="0 0 1"/>
<limit effort="1" velocity="20" />
<joint_properties friction="0.0"/>
</joint>

<link name="piston_2">
<visual>
<origin xyz="-0.10179556944408768571 0.15392457132099851558 -0.85799999999999987388" rpy="-1.0702904687869484892e-19 1.6210897607045645555e-18 -2.309519188645782419e-17" />
<geometry>
<mesh filename="package:///piston.stl"/>
</geometry>
<material name="piston_material">
<color rgba="0.91764705882352937127 0.91764705882352937127 0.91764705882352937127 1.0"/>
</material>
</visual>
<collision>
<origin xyz="-0.10179556944408768571 0.15392457132099851558 -0.85799999999999987388" rpy="-1.0702904687869484892e-19 1.6210897607045645555e-18 -2.309519188645782419e-17" />
<geometry>
<mesh filename="package:///piston.stl"/>
</geometry>
</collision>
<inertial>
<origin xyz="1.3877787807814456755e-17 2.6761769627105038341e-17 -0.011000000000000120792" rpy="0 0 0"/>
<mass value="0.0047041422996690132607" />
<inertia ixx="2.6977766073778942017e-07" ixy="-2.0571131653493871097e-23"  ixz="-3.0233692806063036161e-25" iyy="2.6977766073778920841e-07" iyz="2.2764115341714334259e-25" izz="1.6008784263561077721e-07" />
</inertial>
</link>

<link name="closedloop18_A_6D">
<inertial>
<origin xyz="0 0 0" rpy="0 0 0" />
<mass value="1e-9" />
<inertia ixx="0" ixy="0" ixz="0" iyy="0" iyz="0" izz="0" />
</inertial>
</link>
<joint name="closedloop18_A_6D_frame" type="fixed">
<origin xyz="2.7755575615628913511e-17 1.3877787807814456755e-17 -0.022000000000000075051" rpy="3.141592653589793116 -5.3135589439629951664e-18 -2.4122454690407664662e-16" />
<parent link="piston_2" />
<child link="closedloop18_A_6D" />
<axis xyz="0 0 0"/>
</joint>

<joint name="free_spherical_hipxy_2_left" type="revolute">
<origin xyz="-0.06049999999999995659 8.3266726846886740532e-17 0.038499999999999964806" rpy="-1.57079632679489678 0.17430796725365393929 3.1415926535897908956" />
<parent link="part_1_gauche" />
<child link="piston_2" />
<axis xyz="0 0 1"/>
<limit effort="1" velocity="20" />
<joint_properties friction="0.0"/>
</joint>

<link name="part_2">
<visual>
<origin xyz="-2.3592239273284576484e-15 0.046752000000001570079 -0.071500000000000007994" rpy="-1.570796326794896558 -1.570796326794896558 0" />
<geometry>
<mesh filename="package:///part_2.stl"/>
</geometry>
<material name="part_2_material">
<color rgba="0.76862745098039220171 0.88627450980392152857 0.95294117647058818044 1.0"/>
</material>
</visual>
<collision>
<origin xyz="-2.3592239273284576484e-15 0.046752000000001570079 -0.071500000000000007994" rpy="-1.570796326794896558 -1.570796326794896558 0" />
<geometry>
<mesh filename="package:///part_2.stl"/>
</geometry>
</collision>
<inertial>
<origin xyz="-0.10353133038219142215 -0.14056766472890794284 -5.9850735478761397551e-13" rpy="0 0 0"/>
<mass value="0.39806472503371781446" />
<inertia ixx="0.0031977111359881450064" ixy="-0.0018588463574926387262"  ixz="5.7043079067900549414e-15" iyy="0.0012912945788078689438" iyz="2.6363829651344087194e-14" izz="0.0044624680664483223555" />
</inertial>
</link>

<link name="part_3">
<visual>
<origin xyz="0.21747050071614926203 0.38247000862966429313 -0.071500000000000007994" rpy="-1.570796326794896558 -1.570796326794896558 0" />
<geometry>
<mesh filename="package:///part_3.stl"/>
</geometry>
<material name="part_3_material">
<color rgba="0.76862745098039220171 0.88627450980392152857 0.95294117647058818044 1.0"/>
</material>
</visual>
<collision>
<origin xyz="0.21747050071614926203 0.38247000862966429313 -0.071500000000000007994" rpy="-1.570796326794896558 -1.570796326794896558 0" />
<geometry>
<mesh filename="package:///part_3.stl"/>
</geometry>
</collision>
<inertial>
<origin xyz="0.1060893883547637806 -0.17986935727287678422 -1.3877787807814456755e-17" rpy="0 0 0"/>
<mass value="0.2021348089396567127" />
<inertia ixx="0.0018459328059746535518" ixy="0.0012583807608323397537"  ixz="-1.9880712633219788577e-22" iyy="0.0008879700532368084865" iyz="3.7356998984883307045e-22" izz="0.0027204272052821520424" />
</inertial>
</link>

<link name="cardan_foot_2">
<visual>
<origin xyz="0 0.038500000000000089706 6.6000000000010494716e-05" rpy="1.570796326794896558 1.570796326794896558 0" />
<geometry>
<mesh filename="package:///cardan_foot.stl"/>
</geometry>
<material name="cardan_foot_material">
<color rgba="0.64705882352941179736 0.64705882352941179736 0.64705882352941179736 1.0"/>
</material>
</visual>
<collision>
<origin xyz="0 0.038500000000000089706 6.6000000000010494716e-05" rpy="1.570796326794896558 1.570796326794896558 0" />
<geometry>
<mesh filename="package:///cardan_foot.stl"/>
</geometry>
</collision>
<inertial>
<origin xyz="6.7228290678487776745e-09 9.7144514654701197287e-17 6.6006722829076302388e-05" rpy="0 0 0"/>
<mass value="0.0064135211594024193679" />
<inertia ixx="3.3475011343990644478e-07" ixy="-2.8486583237202634856e-12"  ixz="5.2783708372310716773e-25" iyy="4.3082408299805979528e-07" iyz="2.8486583238102779423e-12" izz="3.3475011343990649772e-07" />
</inertial>
</link>

<link name="foot">
<visual>
<origin xyz="0 0.038499999999999978684 -1.3877787807814456755e-17" rpy="1.570796326794896558 3.9343514738443138783e-18 7.8541465883003997931e-18" />
<geometry>
<mesh filename="package:///foot.stl"/>
</geometry>
<material name="foot_material">
<color rgba="0.61568627450980395466 0.81176470588235294379 0.92941176470588238168 1.0"/>
</material>
</visual>
<collision>
<origin xyz="0 0.038499999999999978684 -1.3877787807814456755e-17" rpy="1.570796326794896558 3.9343514738443138783e-18 7.8541465883003997931e-18" />
<geometry>
<mesh filename="package:///foot.stl"/>
</geometry>
</collision>
<inertial>
<origin xyz="-0.0036358817134152158872 0.024966449369929651081 9.0007330144478872244e-08" rpy="0 0 0"/>
<mass value="0.3109129822293019707" />
<inertia ixx="0.00026328612588329922692" ixy="-5.3028311481376188272e-05"  ixz="-1.7872776046536210514e-09" iyy="0.00071897520566115971294" iyz="-2.0903095188096243609e-10" izz="0.00052661427618999384539" />
</inertial>
</link>

<link name="foot_left">
<inertial>
<origin xyz="0 0 0" rpy="0 0 0" />
<mass value="1e-9" />
<inertia ixx="0" ixy="0" ixz="0" iyy="0" iyz="0" izz="0" />
</inertial>
</link>
<joint name="foot_left_frame" type="fixed">
<origin xyz="0.012016949221079764598 0.038499999999999923173 6.8117394363964578474e-09" rpy="1.5707963267948974462 -1.4061551475580533876e-17 1.3040345811105885313e-15" />
<parent link="foot" />
<child link="foot_left" />
<axis xyz="0 0 0"/>
</joint>

<link name="closedloop21_A_3D">
<inertial>
<origin xyz="0 0 0" rpy="0 0 0" />
<mass value="1e-9" />
<inertia ixx="0" ixy="0" ixz="0" iyy="0" iyz="0" izz="0" />
</inertial>
</link>
<joint name="closedloop21_A_3D_frame" type="fixed">
<origin xyz="-0.054999999999999937828 -0.01100000000000000977 -0.038500000000000006439" rpy="1.570796326794896558 5.5775440709909559897e-17 -1.5707963267948958919" />
<parent link="foot" />
<child link="closedloop21_A_3D" />
<axis xyz="0 0 0"/>
</joint>

<link name="closedloop22_A_3D">
<inertial>
<origin xyz="0 0 0" rpy="0 0 0" />
<mass value="1e-9" />
<inertia ixx="0" ixy="0" ixz="0" iyy="0" iyz="0" izz="0" />
</inertial>
</link>
<joint name="closedloop22_A_3D_frame" type="fixed">
<origin xyz="-0.054999999999999993339 -0.01100000000000000977 0.038499999999999992562" rpy="1.570796326794896558 5.5775440709909559897e-17 -1.5707963267948958919" />
<parent link="foot" />
<child link="closedloop22_A_3D" />
<axis xyz="0 0 0"/>
</joint>

<joint name="free_ankle_universal_x_left" type="revolute">
<origin xyz="6.6000000000010494716e-05 2.2204460492503130808e-16 6.5999999999954983565e-05" rpy="-1.570796326794896558 -0.99367489314673695944 -1.57079632679489678" />
<parent link="cardan_foot_2" />
<child link="foot" />
<axis xyz="0 0 1"/>
<limit effort="1" velocity="20" />
<joint_properties friction="0.0"/>
</joint>

<joint name="free_universal_y_foot_left" type="revolute">
<origin xyz="0.21747050071614942857 -0.33571800862966399981 -3.4694469519536141888e-18" rpy="-1.5707963267948958919 -1.4835298641951766285 1.5707963267949331954" />
<parent link="part_3" />
<child link="cardan_foot_2" />
<axis xyz="0 0 1"/>
<limit effort="1" velocity="20" />
<joint_properties friction="0.0"/>
</joint>

<link name="part_6">
<visual>
<origin xyz="0.10788167727912303939 -0.039150197130724581629 5.5511151231257827021e-17" rpy="-3.141592653589793116 1.0115724044382810845e-18 -3.2099959913854695587e-17" />
<geometry>
<mesh filename="package:///part_6.stl"/>
</geometry>
<material name="part_6_material">
<color rgba="0.76862745098039220171 0.88627450980392152857 0.95294117647058818044 1.0"/>
</material>
</visual>
<collision>
<origin xyz="0.10788167727912303939 -0.039150197130724581629 5.5511151231257827021e-17" rpy="-3.141592653589793116 1.0115724044382810845e-18 -3.2099959913854695587e-17" />
<geometry>
<mesh filename="package:///part_6.stl"/>
</geometry>
</collision>
<inertial>
<origin xyz="5.5511151231257827021e-17 -4.0448913005911551404e-18 -0.21359999999999998432" rpy="0 0 0"/>
<mass value="0.033552209540339043847" />
<inertia ixx="0.00051048244070615617519" ixy="1.572380772545045121e-21"  ixz="-4.9754200853304337008e-22" iyy="0.00051048244070615639203" iyz="8.8597101295436671043e-21" izz="4.1940261925423882626e-07" />
</inertial>
</link>

<link name="closedloop12_A_3D">
<inertial>
<origin xyz="0 0 0" rpy="0 0 0" />
<mass value="1e-9" />
<inertia ixx="0" ixy="0" ixz="0" iyy="0" iyz="0" izz="0" />
</inertial>
</link>
<joint name="closedloop12_A_3D_frame" type="fixed">
<origin xyz="5.5511151231257827021e-17 0 -0.42720000000000002416" rpy="-3.141592653589793116 -4.5932359763492642923e-17 -1.035331779239029349e-16" />
<parent link="part_6" />
<child link="closedloop12_A_3D" />
<axis xyz="0 0 0"/>
</joint>

<joint name="spherical_shin_left" type="revolute">
<origin xyz="0.038967453687049735667 -0.092095263467496746301 -6.9388939039072283776e-18" rpy="-1.570796326794896558 0.34266875905739935249 1.5707963267948972241" />
<parent link="part_3" />
<child link="part_6" />
<axis xyz="0 0 1"/>
<limit effort="1" velocity="20" />
<joint_properties friction="0.0"/>
</joint>

<joint name="lower_knee_left" type="revolute">
<origin xyz="-0.21747050071615153799 -0.33571800862966250101 -1.3877787807814456755e-17" rpy="-3.6654208353707282711e-17 7.4236255477340986718e-17 0.89630439304596909444" />
<parent link="part_2" />
<child link="part_3" />
<axis xyz="0 0 1"/>
<limit effort="1" velocity="20" />
<joint_properties friction="0.0"/>
</joint>

<link name="renvois_cheville_2_8">
<visual>
<origin xyz="-0.11549999999999997768 -0.35749999999999992895 0.033000000000000001554" rpy="-1.570796326794896558 -8.416253686631036033e-19 9.6344801354933481419e-18" />
<geometry>
<mesh filename="package:///renvois_cheville_2_8.stl"/>
</geometry>
<material name="renvois_cheville_2_8_material">
<color rgba="0.91764705882352937127 0.91764705882352937127 0.91764705882352937127 1.0"/>
</material>
</visual>
<collision>
<origin xyz="-0.11549999999999997768 -0.35749999999999992895 0.033000000000000001554" rpy="-1.570796326794896558 -8.416253686631036033e-19 9.6344801354933481419e-18" />
<geometry>
<mesh filename="package:///renvois_cheville_2_8.stl"/>
</geometry>
</collision>
<inertial>
<origin xyz="-0.033596086250149245767 -0.018380744757818923141 -0.014122199558543433937" rpy="0 0 0"/>
<mass value="0.074310320490072731547" />
<inertia ixx="4.1295450354366541358e-05" ixy="1.9886051938184650641e-06"  ixz="-2.0689202263474873248e-06" iyy="3.2625641947312141421e-05" iyz="-9.9798202174584469521e-06" izz="5.1310129727252684509e-05" />
</inertial>
</link>

<link name="closedloop23_B_3D">
<inertial>
<origin xyz="0 0 0" rpy="0 0 0" />
<mass value="1e-9" />
<inertia ixx="0" ixy="0" ixz="0" iyy="0" iyz="0" izz="0" />
</inertial>
</link>
<joint name="closedloop23_B_3D_frame" type="fixed">
<origin xyz="-0.035854717888628866163 -0.039206584673488142911 -0.051749999999999990452" rpy="-1.57079632679489678 -8.5717888844702030861e-19 3.3378249364540351951e-17" />
<parent link="renvois_cheville_2_8" />
<child link="closedloop23_B_3D" />
<axis xyz="0 0 0"/>
</joint>

<link name="part_7">
<visual>
<origin xyz="0.062087559207389952931 0.15255026628033757641 -3.1225022567582527699e-17" rpy="3.141592653589793116 -3.204311919789308906e-17 -4.7514684857837923291e-17" />
<geometry>
<mesh filename="package:///part_7.stl"/>
</geometry>
<material name="part_7_material">
<color rgba="0.91764705882352937127 0.91764705882352937127 0.91764705882352937127 1.0"/>
</material>
</visual>
<collision>
<origin xyz="0.062087559207389952931 0.15255026628033757641 -3.1225022567582527699e-17" rpy="3.141592653589793116 -3.204311919789308906e-17 -4.7514684857837923291e-17" />
<geometry>
<mesh filename="package:///part_7.stl"/>
</geometry>
</collision>
<inertial>
<origin xyz="1.3183898417423733918e-16 -6.435323453913125862e-19 -0.20000000000000003886" rpy="0 0 0"/>
<mass value="0.031415926535897982508" />
<inertia ixx="0.00041907537001948915118" ixy="-3.5711065707240252405e-20"  ixz="1.33929676115569031e-20" iyy="0.00041907537001948904276" iyz="-3.8738049171293025859e-21" izz="3.9269908169872548938e-07" />
</inertial>
</link>

<link name="closedloop22_B_3D">
<inertial>
<origin xyz="0 0 0" rpy="0 0 0" />
<mass value="1e-9" />
<inertia ixx="0" ixy="0" ixz="0" iyy="0" iyz="0" izz="0" />
</inertial>
</link>
<joint name="closedloop22_B_3D_frame" type="fixed">
<origin xyz="2.2204460492503130808e-16 -2.7755575615628913511e-17 -0.4000000000000000222" rpy="3.1415926535897913396 1.3112097711421770153e-15 -1.570796326794896558" />
<parent link="part_7" />
<child link="closedloop22_B_3D" />
<axis xyz="0 0 0"/>
</joint>

<joint name="spherical_transmission_foot2_left" type="revolute">
<origin xyz="-0.059494699261975370064 0.010983203527527130028 -0.02200000000000001607" rpy="-1.57079632679489678 0.26749612184641674562 -1.570796326794896558" />
<parent link="renvois_cheville_2_8" />
<child link="part_7" />
<axis xyz="0 0 1"/>
<limit effort="1" velocity="20" />
<joint_properties friction="0.0"/>
</joint>

<joint name="transmission_1_knee_left" type="revolute">
<origin xyz="-0.21747050071615148248 -0.33571800862966238999 0.009999999999999963779" rpy="3.1415926535897922278 2.5607839141882122881e-15 3.0182803045709176715" />
<parent link="part_2" />
<child link="renvois_cheville_2_8" />
<axis xyz="0 0 1"/>
<limit effort="1" velocity="20" />
<joint_properties friction="0.0"/>
</joint>

<link name="renvois_cheville">
<visual>
<origin xyz="-0.1155000000000001581 -0.35750000000000003997 -0.032999999999999952982" rpy="-1.570796326794896558 9.7008393832270241853e-20 2.2223766996000520932e-17" />
<geometry>
<mesh filename="package:///renvois_cheville.stl"/>
</geometry>
<material name="renvois_cheville_material">
<color rgba="0.91764705882352937127 0.91764705882352937127 0.91764705882352937127 1.0"/>
</material>
</visual>
<collision>
<origin xyz="-0.1155000000000001581 -0.35750000000000003997 -0.032999999999999952982" rpy="-1.570796326794896558 9.7008393832270241853e-20 2.2223766996000520932e-17" />
<geometry>
<mesh filename="package:///renvois_cheville.stl"/>
</geometry>
</collision>
<inertial>
<origin xyz="-0.033596086592530965964 -0.018380744754187328116 0.014122199609931570738" rpy="0 0 0"/>
<mass value="0.074310321213953547947" />
<inertia ixx="4.1295450352451941965e-05" ixy="1.9886053203183274036e-06"  ixz="2.0689203249184071568e-06" iyy="3.2625642523550451148e-05" iyz="9.9798202218794608814e-06" izz="5.1310130219953338818e-05" />
</inertial>
</link>

<link name="closedloop20_B_3D">
<inertial>
<origin xyz="0 0 0" rpy="0 0 0" />
<mass value="1e-9" />
<inertia ixx="0" ixy="0" ixz="0" iyy="0" iyz="0" izz="0" />
</inertial>
</link>
<joint name="closedloop20_B_3D_frame" type="fixed">
<origin xyz="-0.035854717888629046574 -0.041706584673488200643 0.052250000000000053346" rpy="1.570796326794896558 -7.9018780590913059168e-20 -3.1415926535897908956" />
<parent link="renvois_cheville" />
<child link="closedloop20_B_3D" />
<axis xyz="0 0 0"/>
</joint>

<link name="part_7_2">
<visual>
<origin xyz="0.062087559207389841909 -0.15255026628033757641 -0.39999999999999996669" rpy="-2.6749056103516416041e-17 -9.0260321641607935627e-18 9.3397346100936950488e-18" />
<geometry>
<mesh filename="package:///part_7.stl"/>
</geometry>
<material name="part_7_material">
<color rgba="0.91764705882352937127 0.91764705882352937127 0.91764705882352937127 1.0"/>
</material>
</visual>
<collision>
<origin xyz="0.062087559207389841909 -0.15255026628033757641 -0.39999999999999996669" rpy="-2.6749056103516416041e-17 -9.0260321641607935627e-18 9.3397346100936950488e-18" />
<geometry>
<mesh filename="package:///part_7.stl"/>
</geometry>
</collision>
<inertial>
<origin xyz="-1.3877787807814456755e-17 2.3630011051865765497e-17 -0.19999999999999995559" rpy="0 0 0"/>
<mass value="0.031415926535897982508" />
<inertia ixx="0.00041907537001948915118" ixy="-5.8333481257422858175e-21"  ixz="3.7871950114621784818e-21" iyy="0.00041907537001948915118" iyz="-1.1216832517011349971e-20" izz="3.9269908169872548938e-07" />
</inertial>
</link>

<link name="closedloop21_B_3D">
<inertial>
<origin xyz="0 0 0" rpy="0 0 0" />
<mass value="1e-9" />
<inertia ixx="0" ixy="0" ixz="0" iyy="0" iyz="0" izz="0" />
</inertial>
</link>
<joint name="closedloop21_B_3D_frame" type="fixed">
<origin xyz="-5.5511151231257827021e-17 0 -0.39999999999999996669" rpy="3.1415926535897895633 -3.6738326735530833518e-16 1.57079632679489678" />
<parent link="part_7_2" />
<child link="closedloop21_B_3D" />
<axis xyz="0 0 0"/>
</joint>

<joint name="spherical_transmission_foot1_left" type="revolute">
<origin xyz="-0.059494699261975619864 0.010983203527527019006 0.022000000000000040357" rpy="1.570796326794896558 -0.30096768397183631949 1.5707963267948978903" />
<parent link="renvois_cheville" />
<child link="part_7_2" />
<axis xyz="0 0 1"/>
<limit effort="1" velocity="20" />
<joint_properties friction="0.0"/>
</joint>

<joint name="transmission_2_knee_left" type="revolute">
<origin xyz="-0.21747050071615153799 -0.33571800862966250101 -0.010000000000000029698" rpy="3.1415926535897926719 2.4170968488441309718e-15 3.0435251672843821602" />
<parent link="part_2" />
<child link="renvois_cheville" />
<axis xyz="0 0 1"/>
<limit effort="1" velocity="20" />
<joint_properties friction="0.0"/>
</joint>

<link name="part_4">
<visual>
<origin xyz="-0.010530049701071103607 0.092146047735299232984 -0.071500000000000007994" rpy="-1.570796326794896558 -1.570796326794896558 0" />
<geometry>
<mesh filename="package:///part_4.stl"/>
</geometry>
<material name="part_4_material">
<color rgba="1 0.7568627450980391913 0.054901960784313724728 1.0"/>
</material>
</visual>
<collision>
<origin xyz="-0.010530049701071103607 0.092146047735299232984 -0.071500000000000007994" rpy="-1.570796326794896558 -1.570796326794896558 0" />
<geometry>
<mesh filename="package:///part_4.stl"/>
</geometry>
</collision>
<inertial>
<origin xyz="0.019483726843524836608 -0.046047631733748276006 1.3877787807814456755e-17" rpy="0 0 0"/>
<mass value="0.011311035579799528367" />
<inertia ixx="1.0009836990585404797e-05" ixy="4.1536946028868293516e-06"  ixz="-5.0270944199314155445e-24" iyy="1.9505556032253759876e-06" iyz="6.477150795160163983e-24" izz="1.1771875334147456995e-05" />
</inertial>
</link>

<link name="closedloop12_B_3D">
<inertial>
<origin xyz="0 0 0" rpy="0 0 0" />
<mass value="1e-9" />
<inertia ixx="0" ixy="0" ixz="0" iyy="0" iyz="0" izz="0" />
</inertial>
</link>
<joint name="closedloop12_B_3D_frame" type="fixed">
<origin xyz="0.038967453687049680155 -0.092095263467496718546 3.8163916471489756077e-17" rpy="-1.57079632679489678 1.342843395992826004e-18 3.141592653589793116" />
<parent link="part_4" />
<child link="closedloop12_B_3D" />
<axis xyz="0 0 0"/>
</joint>

<link name="part_5">
<visual>
<origin xyz="0.06340495628161675612 0.053322112528135630349 0" rpy="3.141592653589793116 4.0907557778710928219e-17 -5.6977393277845192855e-18" />
<geometry>
<mesh filename="package:///part_5.stl"/>
</geometry>
<material name="part_5_material">
<color rgba="0.91764705882352937127 0.91764705882352937127 0.91764705882352937127 1.0"/>
</material>
</visual>
<collision>
<origin xyz="0.06340495628161675612 0.053322112528135630349 0" rpy="3.141592653589793116 4.0907557778710928219e-17 -5.6977393277845192855e-18" />
<geometry>
<mesh filename="package:///part_5.stl"/>
</geometry>
</collision>
<inertial>
<origin xyz="-1.3877787807814456755e-17 5.5479641956965522687e-19 -0.070709999999999995079" rpy="0 0 0"/>
<mass value="0.011107100826766714077" />
<inertia ixx="1.8580899034455380096e-05" ixy="4.0689140477506539639e-22"  ixz="-7.6263308443478873376e-22" iyy="1.8580899034455380096e-05" iyz="-1.7163656661730317246e-22" izz="1.3883876033458398932e-07" />
</inertial>
</link>

<link name="closedloop13_A_3D">
<inertial>
<origin xyz="0 0 0" rpy="0 0 0" />
<mass value="1e-9" />
<inertia ixx="0" ixy="0" ixz="0" iyy="0" iyz="0" izz="0" />
</inertial>
</link>
<joint name="closedloop13_A_3D_frame" type="fixed">
<origin xyz="0 8.6736173798840354721e-19 -0.14142000000000001791" rpy="3.141592653589793116 4.0907557778710928219e-17 -5.6977393277845192855e-18" />
<parent link="part_5" />
<child link="closedloop13_A_3D" />
<axis xyz="0 0 0"/>
</joint>

<joint name="spherical_4rod_left" type="revolute">
<origin xyz="0.019483726843525006611 -0.046047631733748345395 1.0408340855860842566e-17" rpy="1.57079632679489678 0.15824418733945425086 1.5707963267948952257" />
<parent link="part_4" />
<child link="part_5" />
<axis xyz="0 0 1"/>
<limit effort="1" velocity="20" />
<joint_properties friction="0.0"/>
</joint>

<joint name="4rof_knee_left" type="revolute">
<origin xyz="0.046047631733747068639 -0.019483726843524284966 6.5919492087118669588e-17" rpy="3.141592653589793116 4.405771113082074377e-17 -1.2499268310990390152" />
<parent link="part_2" />
<child link="part_4" />
<axis xyz="0 0 1"/>
<limit effort="1" velocity="20" />
<joint_properties friction="0.0"/>
</joint>

<link name="motteur_rotation">
<visual>
<origin xyz="0.033000000000000050127 0.88825000000000020606 -0.10449999999999914913" rpy="1.570796326794896558 1.5707963267948930053 0" />
<geometry>
<mesh filename="package:///motteur_rotation.stl"/>
</geometry>
<material name="motteur_rotation_material">
<color rgba="1 0 0 1.0"/>
</material>
</visual>
<collision>
<origin xyz="0.033000000000000050127 0.88825000000000020606 -0.10449999999999914913" rpy="1.570796326794896558 1.5707963267948930053 0" />
<geometry>
<mesh filename="package:///motteur_rotation.stl"/>
</geometry>
</collision>
<inertial>
<origin xyz="-5.980234823572048775e-18 1.1102230246251565404e-16 -0.017243243243243319696" rpy="0 0 0"/>
<mass value="0.19339251676417062997" />
<inertia ixx="4.9207470246053547824e-05" ixy="2.4988159442010042092e-21"  ixz="-2.716951696409726149e-22" iyy="4.9207470246053534272e-05" iyz="-5.5730256068895838603e-20" izz="3.3697502678236647725e-05" />
</inertial>
</link>

<link name="piston_3">
<visual>
<origin xyz="-0.10179556944408765795 0.15392457132099848782 -0.85800000000000009592" rpy="5.8130172867032463786e-17 -4.697419961737112609e-18 -4.3986749737494880142e-17" />
<geometry>
<mesh filename="package:///piston.stl"/>
</geometry>
<material name="piston_material">
<color rgba="0.91764705882352937127 0.91764705882352937127 0.91764705882352937127 1.0"/>
</material>
</visual>
<collision>
<origin xyz="-0.10179556944408765795 0.15392457132099848782 -0.85800000000000009592" rpy="5.8130172867032463786e-17 -4.697419961737112609e-18 -4.3986749737494880142e-17" />
<geometry>
<mesh filename="package:///piston.stl"/>
</geometry>
</collision>
<inertial>
<origin xyz="-1.3877787807814456755e-17 -5.6739415889605831307e-17 -0.011000000000000231815" rpy="0 0 0"/>
<mass value="0.0047041422996690132607" />
<inertia ixx="2.6977766073778931429e-07" ixy="-5.9667539635542854517e-24"  ixz="-1.6382629061680298075e-25" iyy="2.6977766073778942017e-07" iyz="1.6296375640878398786e-23" izz="1.6008784263561083015e-07" />
</inertial>
</link>

<link name="closedloop16_B_6D">
<inertial>
<origin xyz="0 0 0" rpy="0 0 0" />
<mass value="1e-9" />
<inertia ixx="0" ixy="0" ixz="0" iyy="0" iyz="0" izz="0" />
</inertial>
</link>
<joint name="closedloop16_B_6D_frame" type="fixed">
<origin xyz="2.0816681711721685133e-17 -2.7755575615628913511e-17 -0.021999999999999977907" rpy="3.141592653589793116 1.2701984792014930899e-16 -1.57079632679489678" />
<parent link="piston_3" />
<child link="closedloop16_B_6D" />
<axis xyz="0 0 0"/>
</joint>

<joint name="motor_knee_left" type="prismatic">
<origin xyz="2.8449465006019636348e-16 -1.1102230246251565404e-16 0.0086304170048063511" rpy="-3.141592653589793116 -1.9712230431965199595e-15 -2.1147901089949034214e-15" />
<parent link="motteur_rotation" />
<child link="piston_3" />
<axis xyz="0 0 1"/>
<limit effort="1" velocity="20" />
<joint_properties friction="0.0"/>
</joint>

<joint name="free_motor_knee_left" type="revolute">
<origin xyz="-0.061655078133537329077 -0.018724201373191612374 4.2973576086513531891e-12" rpy="-1.5707963267948972241 1.3873492000155343007 -0.60601731071219733238" />
<parent link="part_2" />
<child link="motteur_rotation" />
<axis xyz="0 0 1"/>
<limit effort="1" velocity="20" />
<joint_properties friction="0.0"/>
</joint>

<joint name="upper_knee_left" type="revolute">
<origin xyz="7.2858385991025897965e-17 -0.046751999999999821478 -0.071500000000000313305" rpy="-1.4618783972762011617e-14 -5.3385657868507484047e-15 -0.63853922414918695694" />
<parent link="part_1_gauche" />
<child link="part_2" />
<axis xyz="0 0 1"/>
<limit effort="1" velocity="20" />
<joint_properties friction="0.0"/>
</joint>

<link name="part_8">
<visual>
<origin xyz="5.5511151231257827021e-17 -0.046752000000000022706 0.088000000000000008771" rpy="1.570796326794896558 1.570796326794896558 0" />
<geometry>
<mesh filename="package:///part_8.stl"/>
</geometry>
<material name="part_8_material">
<color rgba="0.49803921568627451677 0.49803921568627451677 0.49803921568627451677 1.0"/>
</material>
</visual>
<collision>
<origin xyz="5.5511151231257827021e-17 -0.046752000000000022706 0.088000000000000008771" rpy="1.570796326794896558 1.570796326794896558 0" />
<geometry>
<mesh filename="package:///part_8.stl"/>
</geometry>
</collision>
<inertial>
<origin xyz="0.031934770108260228383 0.010733820853410638851 -0.0056648401062835973541" rpy="0 0 0"/>
<mass value="0.0062040903886272725024" />
<inertia ixx="9.1742111640422036546e-07" ixy="-1.631660380892416962e-07"  ixz="2.2769789117187741779e-07" iyy="1.3280669465102752981e-06" iyz="-1.4783479338790849577e-07" izz="1.7548720440932146456e-06" />
</inertial>
</link>

<link name="piston_4">
<visual>
<origin xyz="-0.10179556944408765795 -0.15392457132099846007 0.83599999999999996536" rpy="-3.141592653589793116 2.9557363066987555049e-18 -5.1664924320402953942e-17" />
<geometry>
<mesh filename="package:///piston.stl"/>
</geometry>
<material name="piston_material">
<color rgba="0.91764705882352937127 0.91764705882352937127 0.91764705882352937127 1.0"/>
</material>
</visual>
<collision>
<origin xyz="-0.10179556944408765795 -0.15392457132099846007 0.83599999999999996536" rpy="-3.141592653589793116 2.9557363066987555049e-18 -5.1664924320402953942e-17" />
<geometry>
<mesh filename="package:///piston.stl"/>
</geometry>
</collision>
<inertial>
<origin xyz="-2.7755575615628913511e-17 1.04459572645076294e-16 -0.011000000000000120792" rpy="0 0 0"/>
<mass value="0.0047041422996690132607" />
<inertia ixx="2.6977766073778920841e-07" ixy="-2.8012149047389921163e-23"  ixz="-2.0118437811902595165e-24" iyy="2.6977766073778942017e-07" iyz="6.0848862478995215065e-24" izz="1.6008784263561088309e-07" />
</inertial>
</link>

<link name="closedloop14_A_3D">
<inertial>
<origin xyz="0 0 0" rpy="0 0 0" />
<mass value="1e-9" />
<inertia ixx="0" ixy="0" ixz="0" iyy="0" iyz="0" izz="0" />
</inertial>
</link>
<joint name="closedloop14_A_3D_frame" type="fixed">
<origin xyz="-6.9388939039072283776e-18 -2.7755575615628913511e-17 -0.021999999999999991784" rpy="-3.141592653589793116 4.6224429555000727957e-17 -1.570796326794896558" />
<parent link="piston_4" />
<child link="closedloop14_A_3D" />
<axis xyz="0 0 0"/>
</joint>

<joint name="spherical_motor_transmission_hip1_left" type="revolute">
<origin xyz="0.043531328479973790957 0.0032046566522410530053 -0.024999999999999994449" rpy="1.5707963267948970021 -1.3881446540757560459 -3.1415926535897527039" />
<parent link="part_8" />
<child link="piston_4" />
<axis xyz="0 0 1"/>
<limit effort="1" velocity="20" />
<joint_properties friction="0.0"/>
</joint>

<link name="part_7_3">
<visual>
<origin xyz="0.062087559207389841909 -0.1525502662803375209 -0.40000000000000007772" rpy="1.3578401560158616044e-20 -2.4751021715293509852e-17 1.6480188583678306288e-18" />
<geometry>
<mesh filename="package:///part_7.stl"/>
</geometry>
<material name="part_7_material">
<color rgba="0.91764705882352937127 0.91764705882352937127 0.91764705882352937127 1.0"/>
</material>
</visual>
<collision>
<origin xyz="0.062087559207389841909 -0.1525502662803375209 -0.40000000000000007772" rpy="1.3578401560158616044e-20 -2.4751021715293509852e-17 1.6480188583678306288e-18" />
<geometry>
<mesh filename="package:///part_7.stl"/>
</geometry>
</collision>
<inertial>
<origin xyz="-2.0816681711721685133e-17 5.2363331148964938433e-17 -0.19999999999999998335" rpy="0 0 0"/>
<mass value="0.031415926535897982508" />
<inertia ixx="0.00041907537001948915118" ixy="-3.6821919828642244821e-20"  ixz="1.0374367978856144917e-20" iyy="0.00041907537001948904276" iyz="-2.8944888676968450399e-25" izz="3.9269908169872580702e-07" />
</inertial>
</link>

<link name="closedloop23_A_3D">
<inertial>
<origin xyz="0 0 0" rpy="0 0 0" />
<mass value="1e-9" />
<inertia ixx="0" ixy="0" ixz="0" iyy="0" iyz="0" izz="0" />
</inertial>
</link>
<joint name="closedloop23_A_3D_frame" type="fixed">
<origin xyz="2.7755575615628913511e-17 2.7755575615628913511e-17 -0.39999999999999996669" rpy="2.1692123864575216095e-16 7.3047674865800371478e-16 -4.6114240044222220693e-16" />
<parent link="part_7_3" />
<child link="closedloop23_A_3D" />
<axis xyz="0 0 0"/>
</joint>

<joint name="spherical_transmission_hip3_left" type="revolute">
<origin xyz="0.041074543378118971715 0.036577067764912846171 -0.0050000000000000061756" rpy="-1.570796326794896558 0.67303436723391374397 3.1415926535897922278" />
<parent link="part_8" />
<child link="part_7_3" />
<axis xyz="0 0 1"/>
<limit effort="1" velocity="20" />
<joint_properties friction="0.0"/>
</joint>

<joint name="transmission_ankle3_left" type="revolute">
<origin xyz="6.2450045135165055399e-17 -0.046752000000000043523 -0.055000000000000055789" rpy="-3.1415926535897895633 -4.7723251426136212841e-16 -1.2495340742673988199" />
<parent link="part_1_gauche" />
<child link="part_8" />
<axis xyz="0 0 1"/>
<limit effort="1" velocity="20" />
<joint_properties friction="0.0"/>
</joint>

<link name="part_9">
<visual>
<origin xyz="0 0.046752000000000022706 -0.055000000000000007216" rpy="-1.570796326794896558 -1.570796326794896558 0" />
<geometry>
<mesh filename="package:///part_9.stl"/>
</geometry>
<material name="part_9_material">
<color rgba="0.49803921568627451677 0.49803921568627451677 0.49803921568627451677 1.0"/>
</material>
</visual>
<collision>
<origin xyz="0 0.046752000000000022706 -0.055000000000000007216" rpy="-1.570796326794896558 -1.570796326794896558 0" />
<geometry>
<mesh filename="package:///part_9.stl"/>
</geometry>
</collision>
<inertial>
<origin xyz="0.031934770108260172872 -0.010733820853410618035 -0.0056648401062835904152" rpy="0 0 0"/>
<mass value="0.0062040903886272707676" />
<inertia ixx="9.1742111640423360035e-07" ixy="1.6316603808924354909e-07"  ixz="2.2769789117187752367e-07" iyy="1.3280669465102725453e-06" iyz="1.4783479338790931633e-07" izz="1.7548720440932265041e-06" />
</inertial>
</link>

<link name="piston_5">
<visual>
<origin xyz="-0.10179556944408765795 -0.15392457132099848782 0.83599999999999985434" rpy="-3.141592653589793116 -3.9622424591774593143e-18 -1.1316281187079200426e-16" />
<geometry>
<mesh filename="package:///piston.stl"/>
</geometry>
<material name="piston_material">
<color rgba="0.91764705882352937127 0.91764705882352937127 0.91764705882352937127 1.0"/>
</material>
</visual>
<collision>
<origin xyz="-0.10179556944408765795 -0.15392457132099848782 0.83599999999999985434" rpy="-3.141592653589793116 -3.9622424591774593143e-18 -1.1316281187079200426e-16" />
<geometry>
<mesh filename="package:///piston.stl"/>
</geometry>
</collision>
<inertial>
<origin xyz="-1.3877787807814456755e-17 6.1394057265580892168e-17 -0.01100000000000000977" rpy="0 0 0"/>
<mass value="0.0047041422996690132607" />
<inertia ixx="2.6977766073778931429e-07" ixy="-3.9899519034092998659e-23"  ixz="3.4276797045403196699e-24" iyy="2.6977766073778931429e-07" iyz="2.957220630684091271e-24" izz="1.6008784263561083015e-07" />
</inertial>
</link>

<link name="closedloop15_B_3D">
<inertial>
<origin xyz="0 0 0" rpy="0 0 0" />
<mass value="1e-9" />
<inertia ixx="0" ixy="0" ixz="0" iyy="0" iyz="0" izz="0" />
</inertial>
</link>
<joint name="closedloop15_B_3D_frame" type="fixed">
<origin xyz="0 2.7755575615628913511e-17 -0.021999999999999977907" rpy="2.9668696099179873576e-15 -4.3043349733024282915e-15 1.570796326794896558" />
<parent link="piston_5" />
<child link="closedloop15_B_3D" />
<axis xyz="0 0 0"/>
</joint>

<joint name="spherical_motor_transmission_hip2_left" type="revolute">
<origin xyz="0.043531328479973624423 -0.0032046566522409697386 -0.025000000000000022204" rpy="1.570796326794896558 -1.0520766825141725231 -6.564748380207484938e-15" />
<parent link="part_9" />
<child link="piston_5" />
<axis xyz="0 0 1"/>
<limit effort="1" velocity="20" />
<joint_properties friction="0.0"/>
</joint>

<link name="part_7_4">
<visual>
<origin xyz="0.062087559207389800275 -0.15255026628033757641 -0.40000000000000013323" rpy="-6.6465450688821020531e-18 -3.1318090323893008049e-17 -6.892538942352151265e-17" />
<geometry>
<mesh filename="package:///part_7.stl"/>
</geometry>
<material name="part_7_material">
<color rgba="0.91764705882352937127 0.91764705882352937127 0.91764705882352937127 1.0"/>
</material>
</visual>
<collision>
<origin xyz="0.062087559207389800275 -0.15255026628033757641 -0.40000000000000013323" rpy="-6.6465450688821020531e-18 -3.1318090323893008049e-17 -6.892538942352151265e-17" />
<geometry>
<mesh filename="package:///part_7.stl"/>
</geometry>
</collision>
<inertial>
<origin xyz="-3.4694469519536141888e-17 -4.272583000033597957e-19 -0.20000000000000009437" rpy="0 0 0"/>
<mass value="0.031415926535897982508" />
<inertia ixx="0.00041907537001948915118" ixy="5.9098471533384866476e-21"  ixz="1.3120526768239785891e-20" iyy="0.00041907537001948904276" iyz="-2.794644854112111064e-21" izz="3.9269908169872559526e-07" />
</inertial>
</link>

<link name="closedloop20_A_3D">
<inertial>
<origin xyz="0 0 0" rpy="0 0 0" />
<mass value="1e-9" />
<inertia ixx="0" ixy="0" ixz="0" iyy="0" iyz="0" izz="0" />
</inertial>
</link>
<joint name="closedloop20_A_3D_frame" type="fixed">
<origin xyz="-8.3266726846886740532e-17 -5.5511151231257827021e-17 -0.4000000000000000222" rpy="-2.2514125294094559383e-15 -8.4956633181430522698e-16 -1.5707963267948974462" />
<parent link="part_7_4" />
<child link="closedloop20_A_3D" />
<axis xyz="0 0 0"/>
</joint>

<joint name="spherical_transmission_hip4_left" type="revolute">
<origin xyz="0.04107454337811874967 -0.036577067764912860048 -0.004999999999999997502" rpy="1.57079632679489678 0.73924967494909110677 3.1415926535897900074" />
<parent link="part_9" />
<child link="part_7_4" />
<axis xyz="0 0 1"/>
<limit effort="1" velocity="20" />
<joint_properties friction="0.0"/>
</joint>

<joint name="transmission_ankle4_left" type="revolute">
<origin xyz="7.1817551905439813709e-16 -0.04675200000000137579 -0.088000000000000341838" rpy="-9.0884089792933966647e-15 -1.2326465145342669532e-14 -1.2172645625816977955" />
<parent link="part_1_gauche" />
<child link="part_9" />
<axis xyz="0 0 1"/>
<limit effort="1" velocity="20" />
<joint_properties friction="0.0"/>
</joint>

<link name="piston_6">
<visual>
<origin xyz="-0.10179556944408765795 0.15392457132099854333 -0.8579999999999999849" rpy="3.8407815244316538316e-19 -2.9526380192243992091e-18 -1.0506554566943196642e-19" />
<geometry>
<mesh filename="package:///piston.stl"/>
</geometry>
<material name="piston_material">
<color rgba="0.91764705882352937127 0.91764705882352937127 0.91764705882352937127 1.0"/>
</material>
</visual>
<collision>
<origin xyz="-0.10179556944408765795 0.15392457132099854333 -0.8579999999999999849" rpy="3.8407815244316538316e-19 -2.9526380192243992091e-18 -1.0506554566943196642e-19" />
<geometry>
<mesh filename="package:///piston.stl"/>
</geometry>
</collision>
<inertial>
<origin xyz="0 2.4721560767813095305e-17 -0.010999999999999898748" rpy="0 0 0"/>
<mass value="0.0047041422996690132607" />
<inertia ixx="2.6977766073778931429e-07" ixy="-4.1460038319997724419e-26"  ixz="-2.8594678585572388881e-25" iyy="2.6977766073778931429e-07" iyz="-4.6780899211796005719e-25" izz="1.6008784263561088309e-07" />
</inertial>
</link>

<link name="closedloop16_A_6D">
<inertial>
<origin xyz="0 0 0" rpy="0 0 0" />
<mass value="1e-9" />
<inertia ixx="0" ixy="0" ixz="0" iyy="0" iyz="0" izz="0" />
</inertial>
</link>
<joint name="closedloop16_A_6D_frame" type="fixed">
<origin xyz="0 2.0816681711721685133e-17 -0.022000000000000040357" rpy="3.8407815244357912106e-19 -7.2372460481629324552e-19 -1.0504212169390065499e-19" />
<parent link="piston_6" />
<child link="closedloop16_A_6D" />
<axis xyz="0 0 0"/>
</joint>

<joint name="spherical_actuation_knee_left" type="revolute">
<origin xyz="-0.013749999999999821393 -0.0024999999999999744649 -0.070875000000000021316" rpy="1.570796326794896558 1.503667491693747211e-14 1.570796326794896558" />
<parent link="part_1_gauche" />
<child link="piston_6" />
<axis xyz="0 0 1"/>
<limit effort="1" velocity="20" />
<joint_properties friction="0.0"/>
</joint>

<link name="motteur_rotation_2">
<visual>
<origin xyz="0.033000000000000043188 0.88825000000000031708 -0.10449999999999907974" rpy="1.570796326794896558 1.5707963267948930053 0" />
<geometry>
<mesh filename="package:///motteur_rotation.stl"/>
</geometry>
<material name="motteur_rotation_material">
<color rgba="1 0 0 1.0"/>
</material>
</visual>
<collision>
<origin xyz="0.033000000000000043188 0.88825000000000031708 -0.10449999999999907974" rpy="1.570796326794896558 1.5707963267948930053 0" />
<geometry>
<mesh filename="package:///motteur_rotation.stl"/>
</geometry>
</collision>
<inertial>
<origin xyz="1.7827268422739096846e-17 -1.1102230246251565404e-16 -0.017243243243243264184" rpy="0 0 0"/>
<mass value="0.19339251676417062997" />
<inertia ixx="4.9207470246053534272e-05" ixy="9.8137972257776389216e-24"  ixz="-6.7561795963583611137e-22" iyy="4.9207470246053574929e-05" iyz="-5.6970248923211987675e-20" izz="3.3697502678236634173e-05" />
</inertial>
</link>

<link name="piston_7">
<visual>
<origin xyz="-0.10179556944408769958 -0.15392457132099857109 0.83599999999999985434" rpy="-3.141592653589793116 -6.362310215720990565e-17 -1.1721467039814270588e-19" />
<geometry>
<mesh filename="package:///piston.stl"/>
</geometry>
<material name="piston_material">
<color rgba="0.91764705882352937127 0.91764705882352937127 0.91764705882352937127 1.0"/>
</material>
</visual>
<collision>
<origin xyz="-0.10179556944408769958 -0.15392457132099857109 0.83599999999999985434" rpy="-3.141592653589793116 -6.362310215720990565e-17 -1.1721467039814270588e-19" />
<geometry>
<mesh filename="package:///piston.stl"/>
</geometry>
</collision>
<inertial>
<origin xyz="-4.1633363423443370266e-17 -2.819766715022094381e-17 -0.01100000000000000977" rpy="0 0 0"/>
<mass value="0.0047041422996690132607" />
<inertia ixx="2.6977766073778931429e-07" ixy="-2.9240206288572629871e-26"  ixz="1.7108874298891752127e-23" iyy="2.6977766073778942017e-07" iyz="2.7059218375831018691e-25" izz="1.6008784263561083015e-07" />
</inertial>
</link>

<link name="closedloop15_A_3D">
<inertial>
<origin xyz="0 0 0" rpy="0 0 0" />
<mass value="1e-9" />
<inertia ixx="0" ixy="0" ixz="0" iyy="0" iyz="0" izz="0" />
</inertial>
</link>
<joint name="closedloop15_A_3D_frame" type="fixed">
<origin xyz="4.1633363423443370266e-17 -5.5511151231257827021e-17 -0.022000000000000075051" rpy="-3.1415926535897922278 8.277323861869742215e-19 5.6322170327204818248e-20" />
<parent link="piston_7" />
<child link="closedloop15_A_3D" />
<axis xyz="0 0 0"/>
</joint>

<joint name="motor_ankle2_left" type="prismatic">
<origin xyz="1.4988010832439613296e-15 0 0.036860927393518538864" rpy="-3.141592653589793116 1.5464271431180720134e-14 -3.1415926535897829019" />
<parent link="motteur_rotation_2" />
<child link="piston_7" />
<axis xyz="0 0 1"/>
<limit effort="1" velocity="20" />
<joint_properties friction="0.0"/>
</joint>

<joint name="frame_motor_ankle1_left" type="revolute">
<origin xyz="0.054086706326755343288 -0.014047405294960818578 -0.11825000000000003564" rpy="1.570796326794896558 0.014238452528732936306 -0.2858933777993311609" />
<parent link="part_1_gauche" />
<child link="motteur_rotation_2" />
<axis xyz="0 0 1"/>
<limit effort="1" velocity="20" />
<joint_properties friction="0.0"/>
</joint>

<link name="motteur_rotation_3">
<visual>
<origin xyz="0.03300000000000002931 0.88825000000000020606 -0.10449999999999906586" rpy="1.570796326794896558 1.5707963267948930053 0" />
<geometry>
<mesh filename="package:///motteur_rotation.stl"/>
</geometry>
<material name="motteur_rotation_material">
<color rgba="1 0 0 1.0"/>
</material>
</visual>
<collision>
<origin xyz="0.03300000000000002931 0.88825000000000020606 -0.10449999999999906586" rpy="1.570796326794896558 1.5707963267948930053 0" />
<geometry>
<mesh filename="package:///motteur_rotation.stl"/>
</geometry>
</collision>
<inertial>
<origin xyz="2.9440367967411865922e-18 0 -0.017243243243243236429" rpy="0 0 0"/>
<mass value="0.19339251676417062997" />
<inertia ixx="4.9207470246053534272e-05" ixy="4.5662065492258023935e-24"  ixz="1.0143278970229888465e-21" iyy="4.9207470246053547824e-05" iyz="-5.6916377821722750896e-20" izz="3.3697502678236647725e-05" />
</inertial>
</link>

<link name="piston_8">
<visual>
<origin xyz="-0.10179556944408767183 -0.15392457132099851558 0.83599999999999996536" rpy="-3.141592653589793116 4.2554870051794758875e-17 5.8543308238553520768e-21" />
<geometry>
<mesh filename="package:///piston.stl"/>
</geometry>
<material name="piston_material">
<color rgba="0.91764705882352937127 0.91764705882352937127 0.91764705882352937127 1.0"/>
</material>
</visual>
<collision>
<origin xyz="-0.10179556944408767183 -0.15392457132099851558 0.83599999999999996536" rpy="-3.141592653589793116 4.2554870051794758875e-17 5.8543308238553520768e-21" />
<geometry>
<mesh filename="package:///piston.stl"/>
</geometry>
</collision>
<inertial>
<origin xyz="-5.5511151231257827021e-17 4.9476724667685156202e-19 -0.010999999999999898748" rpy="0 0 0"/>
<mass value="0.0047041422996690132607" />
<inertia ixx="2.6977766073778920841e-07" ixy="-1.4930020078633166483e-26"  ixz="-7.2589766759958350992e-24" iyy="2.6977766073778931429e-07" iyz="-1.850733978100518797e-26" izz="1.6008784263561083015e-07" />
</inertial>
</link>

<link name="closedloop14_B_3D">
<inertial>
<origin xyz="0 0 0" rpy="0 0 0" />
<mass value="1e-9" />
<inertia ixx="0" ixy="0" ixz="0" iyy="0" iyz="0" izz="0" />
</inertial>
</link>
<joint name="closedloop14_B_3D_frame" type="fixed">
<origin xyz="0 -1.0408340855860842566e-17 -0.02200000000000001954" rpy="-2.7761328130793523422e-19 -6.9441320598627267313e-17 -3.141592653589793116" />
<parent link="piston_8" />
<child link="closedloop14_B_3D" />
<axis xyz="0 0 0"/>
</joint>

<joint name="motor_ankle1_left" type="prismatic">
<origin xyz="0 4.8572257327350598644e-17 0.041658869056533182063" rpy="3.1415926535897820138 -6.7374372523019637495e-15 -3.1415926535897873428" />
<parent link="motteur_rotation_3" />
<child link="piston_8" />
<axis xyz="0 0 1"/>
<limit effort="1" velocity="20" />
<joint_properties friction="0.0"/>
</joint>

<joint name="frame_motor_ankle2_left" type="revolute">
<origin xyz="0.054086706326755315533 -0.014047405294960790823 -0.024750000000000008105" rpy="-1.570796326794896558 -0.014238452528733023042 2.8556992757904868796" />
<parent link="part_1_gauche" />
<child link="motteur_rotation_3" />
<axis xyz="0 0 1"/>
<limit effort="1" velocity="20" />
<joint_properties friction="0.0"/>
</joint>

<joint name="free_universal_y_hip_left" type="revolute">
<origin xyz="-6.6000000001009695438e-05 0 -6.5999999999575079124e-05" rpy="-1.5707963267950024733 -1.5358146150088136661 1.5707963267950271202" />
<parent link="cardan_foot" />
<child link="part_1_gauche" />
<axis xyz="0 0 1"/>
<limit effort="1" velocity="20" />
<joint_properties friction="0.0"/>
</joint>

<joint name="free_universal_x_hip_left" type="revolute">
<origin xyz="0 -9.0205620750793968909e-17 -0.1649999999999999245" rpy="1.570796326794896558 8.3262389442822325955e-18 -1.570796326794896558" />
<parent link="hanche_gauche" />
<child link="cardan_foot" />
<axis xyz="0 0 1"/>
<limit effort="1" velocity="20" />
<joint_properties friction="0.0"/>
</joint>

<link name="piston_9">
<visual>
<origin xyz="-0.10179556944408765795 0.15392457132099848782 -0.8579999999999999849" rpy="1.5474172226998211273e-18 4.6132340954022002067e-32 -4.9556328700879128894e-32" />
<geometry>
<mesh filename="package:///piston.stl"/>
</geometry>
<material name="piston_material">
<color rgba="0.91764705882352937127 0.91764705882352937127 0.91764705882352937127 1.0"/>
</material>
</visual>
<collision>
<origin xyz="-0.10179556944408765795 0.15392457132099848782 -0.8579999999999999849" rpy="1.5474172226998211273e-18 4.6132340954022002067e-32 -4.9556328700879128894e-32" />
<geometry>
<mesh filename="package:///piston.stl"/>
</geometry>
</collision>
<inertial>
<origin xyz="0 -3.3200554815540407224e-19 -0.011000000000000120792" rpy="0 0 0"/>
<mass value="0.0047041422996690132607" />
<inertia ixx="2.6977766073778931429e-07" ixy="-5.3204262414505280686e-38"  ixz="-3.6632008201976058109e-38" iyy="2.6977766073778920841e-07" iyz="3.5470765171629107134e-25" izz="1.6008784263561083015e-07" />
</inertial>
</link>

<link name="closedloop19_B_6D">
<inertial>
<origin xyz="0 0 0" rpy="0 0 0" />
<mass value="1e-9" />
<inertia ixx="0" ixy="0" ixz="0" iyy="0" iyz="0" izz="0" />
</inertial>
</link>
<joint name="closedloop19_B_6D_frame" type="fixed">
<origin xyz="0 7.8062556418956319249e-18 -0.021999999999999908518" rpy="-3.1415926535897820138 1.3686361436822294661e-14 1.570796326794896558" />
<parent link="piston_9" />
<child link="closedloop19_B_6D" />
<axis xyz="0 0 0"/>
</joint>

<joint name="spherical_free_hip_left" type="revolute">
<origin xyz="3.1537272793258352976e-15 -0.03850000000000006195 -0.046750000000000027645" rpy="2.1518574910359218682e-16 1.5707963267948954478 0" />
<parent link="hanche_gauche" />
<child link="piston_9" />
<axis xyz="0 0 1"/>
<limit effort="1" velocity="20" />
<joint_properties friction="0.0"/>
</joint>

<link name="cardan_hache">
<visual>
<origin xyz="0.10862499999999999933 0.85800000000000009592 -0.0055000000000023779867" rpy="1.570796326794896558 1.5707963267948930053 0" />
<geometry>
<mesh filename="package:///cardan_hache.stl"/>
</geometry>
<material name="cardan_hache_material">
<color rgba="0.49803921568627451677 0.49803921568627451677 0.49803921568627451677 1.0"/>
</material>
</visual>
<collision>
<origin xyz="0.10862499999999999933 0.85800000000000009592 -0.0055000000000023779867" rpy="1.570796326794896558 1.5707963267948930053 0" />
<geometry>
<mesh filename="package:///cardan_hache.stl"/>
</geometry>
</collision>
<inertial>
<origin xyz="-4.1781179162957524227e-17 1.5061285552064873627e-11 -0.034629677480538467726" rpy="0 0 0"/>
<mass value="0.015608633111865791165" />
<inertia ixx="5.7160316393851764687e-06" ixy="-1.9710864479939384872e-13"  ixz="-1.4761406623621653863e-23" iyy="5.8966955959438793294e-06" iyz="9.5685519509911332942e-14" izz="7.2203526828754625758e-07" />
</inertial>
</link>

<link name="moteur_hanche1">
<visual>
<origin xyz="-0.049500000000000737854 -0.85799999999999976286 -0.10862500000000001321" rpy="-1.570796326794896558 -2.3020433877834042736e-18 -1.2351261922945550483e-17" />
<geometry>
<mesh filename="package:///moteur_hanche1.stl"/>
</geometry>
<material name="moteur_hanche1_material">
<color rgba="1 0 0 1.0"/>
</material>
</visual>
<collision>
<origin xyz="-0.049500000000000737854 -0.85799999999999976286 -0.10862500000000001321" rpy="-1.570796326794896558 -2.3020433877834042736e-18 -1.2351261922945550483e-17" />
<geometry>
<mesh filename="package:///moteur_hanche1.stl"/>
</geometry>
</collision>
<inertial>
<origin xyz="0 -0.012713533519811859307 -1.067414053629129514e-17" rpy="0 0 0"/>
<mass value="0.17794962537636810351" />
<inertia ixx="3.4377373668620120773e-05" ixy="-1.7486761735890108264e-21"  ixz="1.0883291511954144099e-22" iyy="4.1215284105260616121e-05" iyz="2.4435860453706894175e-22" izz="3.4002456645612650764e-05" />
</inertial>
</link>

<link name="piston_10">
<visual>
<origin xyz="-0.10179556944408764407 0.15392457132099854333 -0.8579999999999999849" rpy="3.9459199271606617764e-19 -5.5537164729157577356e-18 -3.392684685547294356e-18" />
<geometry>
<mesh filename="package:///piston.stl"/>
</geometry>
<material name="piston_material">
<color rgba="0.91764705882352937127 0.91764705882352937127 0.91764705882352937127 1.0"/>
</material>
</visual>
<collision>
<origin xyz="-0.10179556944408764407 0.15392457132099854333 -0.8579999999999999849" rpy="3.9459199271606617764e-19 -5.5537164729157577356e-18 -3.392684685547294356e-18" />
<geometry>
<mesh filename="package:///piston.stl"/>
</geometry>
</collision>
<inertial>
<origin xyz="-1.3877787807814456755e-17 2.4204259691075322024e-17 -0.011000000000000120792" rpy="0 0 0"/>
<mass value="0.0047041422996690132607" />
<inertia ixx="2.6977766073778920841e-07" ixy="-1.3726088878569667195e-24"  ixz="-4.2060490087211816132e-25" iyy="2.6977766073778931429e-07" iyz="-4.9949184378510246215e-25" izz="1.6008784263561083015e-07" />
</inertial>
</link>

<link name="closedloop17_B_6D">
<inertial>
<origin xyz="0 0 0" rpy="0 0 0" />
<mass value="1e-9" />
<inertia ixx="0" ixy="0" ixz="0" iyy="0" iyz="0" izz="0" />
</inertial>
</link>
<joint name="closedloop17_B_6D_frame" type="fixed">
<origin xyz="-1.3877787807814456755e-17 2.4286128663675299322e-17 -0.022000000000000116684" rpy="-3.9459199271606617764e-19 -2.2201859142713151923e-17 3.141592653589793116" />
<parent link="piston_10" />
<child link="closedloop17_B_6D" />
<axis xyz="0 0 0"/>
</joint>

<joint name="motor_hip_xy_1_left" type="prismatic">
<origin xyz="-1.3877787807814456755e-17 -0.044933728103784570385 2.7755575615628913511e-17" rpy="-1.570796326794896558 -1.2579840982866257012e-14 7.4392748255148293694e-15" />
<parent link="moteur_hanche1" />
<child link="piston_10" />
<axis xyz="0 0 1"/>
<limit effort="1" velocity="20" />
<joint_properties friction="0.0"/>
</joint>

<joint name="free_motor_holder_hip_xy2_left" type="revolute">
<origin xyz="0 -5.5511151231257827021e-17 -0.0549999999999999864" rpy="-1.570796326794896558 -1.4802679079841647436 1.5707963267948810149" />
<parent link="cardan_hache" />
<child link="moteur_hanche1" />
<axis xyz="0 0 1"/>
<limit effort="1" velocity="20" />
<joint_properties friction="0.0"/>
</joint>

<joint name="free_motor_holder_1_left" type="revolute">
<origin xyz="0.012500000000000000694 -0.037125000000000150935 -0.076999999999999957367" rpy="1.570796326794896558 -0.026529746372805688981 -1.5707963267948918951" />
<parent link="hanche_gauche" />
<child link="cardan_hache" />
<axis xyz="0 0 1"/>
<limit effort="1" velocity="20" />
<joint_properties friction="0.0"/>
</joint>

<link name="cardan_hache_2">
<visual>
<origin xyz="0.10862499999999997158 0.85800000000000009592 -0.0055000000000023745172" rpy="1.570796326794896558 1.5707963267948930053 0" />
<geometry>
<mesh filename="package:///cardan_hache.stl"/>
</geometry>
<material name="cardan_hache_material">
<color rgba="0.49803921568627451677 0.49803921568627451677 0.49803921568627451677 1.0"/>
</material>
</visual>
<collision>
<origin xyz="0.10862499999999997158 0.85800000000000009592 -0.0055000000000023745172" rpy="1.570796326794896558 1.5707963267948930053 0" />
<geometry>
<mesh filename="package:///cardan_hache.stl"/>
</geometry>
</collision>
<inertial>
<origin xyz="-2.8585214284519563121e-17 1.5061396574367336143e-11 -0.034629677480538460788" rpy="0 0 0"/>
<mass value="0.015608633111865791165" />
<inertia ixx="5.7160316393851730806e-06" ixy="-1.9710864477932171844e-13"  ixz="-1.644309748492670075e-23" iyy="5.8966955959438776354e-06" iyz="9.5685519509873417131e-14" izz="7.2203526828754625758e-07" />
</inertial>
</link>

<link name="moteur_hanche1_2">
<visual>
<origin xyz="-0.04950000000000076561 -0.85800000000000009592 -0.10862499999999997158" rpy="-1.570796326794896558 2.6946904090488928511e-18 4.123799835294532367e-18" />
<geometry>
<mesh filename="package:///moteur_hanche1.stl"/>
</geometry>
<material name="moteur_hanche1_material">
<color rgba="1 0 0 1.0"/>
</material>
</visual>
<collision>
<origin xyz="-0.04950000000000076561 -0.85800000000000009592 -0.10862499999999997158" rpy="-1.570796326794896558 2.6946904090488928511e-18 4.123799835294532367e-18" />
<geometry>
<mesh filename="package:///moteur_hanche1.stl"/>
</geometry>
</collision>
<inertial>
<origin xyz="6.9388939039072283776e-18 -0.012713533519812081352 3.0208860841336195149e-17" rpy="0 0 0"/>
<mass value="0.17794962537636810351" />
<inertia ixx="3.4377373668620134326e-05" ixy="1.9526379010602662017e-22"  ixz="-1.4013048025540610832e-22" iyy="4.1215284105260629674e-05" iyz="3.614707405490162003e-23" izz="3.4002456645612650764e-05" />
</inertial>
</link>

<link name="piston_11">
<visual>
<origin xyz="-0.10179556944408768571 0.15392457132099846007 -0.85800000000000009592" rpy="1.7699474212156417537e-18 -6.4588672045082495108e-18 2.786662422421681951e-18" />
<geometry>
<mesh filename="package:///piston.stl"/>
</geometry>
<material name="piston_material">
<color rgba="0.91764705882352937127 0.91764705882352937127 0.91764705882352937127 1.0"/>
</material>
</visual>
<collision>
<origin xyz="-0.10179556944408768571 0.15392457132099846007 -0.85800000000000009592" rpy="1.7699474212156417537e-18 -6.4588672045082495108e-18 2.786662422421681951e-18" />
<geometry>
<mesh filename="package:///piston.stl"/>
</geometry>
</collision>
<inertial>
<origin xyz="-2.7755575615628913511e-17 -2.2205870741536479156e-17 -0.011000000000000231815" rpy="0 0 0"/>
<mass value="0.0047041422996690132607" />
<inertia ixx="2.6977766073778931429e-07" ixy="1.0929051348326833352e-24"  ixz="1.1734749514677134894e-24" iyy="2.6977766073778920841e-07" iyz="1.4728029952844827552e-24" izz="1.6008784263561083015e-07" />
</inertial>
</link>

<link name="closedloop18_B_6D">
<inertial>
<origin xyz="0 0 0" rpy="0 0 0" />
<mass value="1e-9" />
<inertia ixx="0" ixy="0" ixz="0" iyy="0" iyz="0" izz="0" />
</inertial>
</link>
<joint name="closedloop18_B_6D_frame" type="fixed">
<origin xyz="-2.7755575615628913511e-17 -1.3877787807814456755e-17 -0.021999999999999908518" rpy="1.7699474212156413685e-18 2.1115912505350949368e-17 3.4380251162177467281e-18" />
<parent link="piston_11" />
<child link="closedloop18_B_6D" />
<axis xyz="0 0 0"/>
</joint>

<joint name="motor_hip_xy_2_left" type="prismatic">
<origin xyz="4.1633363423443370266e-17 -0.046444953521772067151 0" rpy="-1.570796326794896558 7.4805795211536263427e-17 2.5368452273096694247e-15" />
<parent link="moteur_hanche1_2" />
<child link="piston_11" />
<axis xyz="0 0 1"/>
<limit effort="1" velocity="20" />
<joint_properties friction="0.0"/>
</joint>

<joint name="free_motor_holder_hip_xy1_left" type="revolute">
<origin xyz="-2.7755575615628913511e-17 4.1633363423443370266e-17 -0.0549999999999999864" rpy="-1.570796326794896558 1.4812643203298270222 1.5707963267949109909" />
<parent link="cardan_hache_2" />
<child link="moteur_hanche1_2" />
<axis xyz="0 0 1"/>
<limit effort="1" velocity="20" />
<joint_properties friction="0.0"/>
</joint>

<joint name="free_motor_holder_2_left" type="revolute">
<origin xyz="0.012500000000000004163 0.037124999999999880318 -0.077000000000000082268" rpy="-1.570796326794896558 -0.026024394633311673242 1.5707963267948983344" />
<parent link="hanche_gauche" />
<child link="cardan_hache_2" />
<axis xyz="0 0 1"/>
<limit effort="1" velocity="20" />
<joint_properties friction="0.0"/>
</joint>

<joint name="free_hip_left" type="revolute">
<origin xyz="0.012500000000000019776 0.045000000000000095479 -0.0049999999999998934186" rpy="3.3570871694184550475e-17 -7.9158602963494340966e-16 -0.014698705078103748572" />
<parent link="hanche_batis_gauche" />
<child link="hanche_gauche" />
<axis xyz="0 0 1"/>
<limit effort="1" velocity="20" />
<joint_properties friction="0.0"/>
</joint>

<link name="hanche_batis">
<visual>
<origin xyz="0.017999999999998839845 -0.96475000000000032951 -0.27649999999999996803" rpy="-1.570796326794896558 1.4890245820567744385e-45 0" />
<geometry>
<mesh filename="package:///hanche_batis.stl"/>
</geometry>
<material name="hanche_batis_material">
<color rgba="0.61568627450980395466 0.81176470588235294379 0.92941176470588238168 1.0"/>
</material>
</visual>
<collision>
<origin xyz="0.017999999999998839845 -0.96475000000000032951 -0.27649999999999996803" rpy="-1.570796326794896558 1.4890245820567744385e-45 0" />
<geometry>
<mesh filename="package:///hanche_batis.stl"/>
</geometry>
</collision>
<inertial>
<origin xyz="-0.0014786115366823907036 -0.00044500436417471700423 -0.12765424686065846016" rpy="0 0 0"/>
<mass value="1.5865591647149872578" />
<inertia ixx="0.0088382827967695663796" ixy="-2.920764549673867156e-05"  ixz="-0.00027487762182023736798" iyy="0.010752178054608367563" iyz="-6.8858407992621780401e-05" izz="0.002575420192163298868" />
</inertial>
</link>

<link name="center_hip">
<inertial>
<origin xyz="0 0 0" rpy="0 0 0" />
<mass value="1e-9" />
<inertia ixx="0" ixy="0" ixz="0" iyy="0" iyz="0" izz="0" />
</inertial>
</link>
<joint name="center_hip_frame" type="fixed">
<origin xyz="-0.0047474699229011207979 -0.19725000000000003642 -0.28861143158344787496" rpy="-1.570796326794896558 -2.5144941353924022455e-29 -3.670158759091543729e-15" />
<parent link="hanche_batis" />
<child link="center_hip" />
<axis xyz="0 0 0"/>
</joint>

<link name="hanche">
<visual>
<origin xyz="0.005500000000002376252 0.071500000000000007994 -0.93500000000000027534" rpy="-3.3109585821359983486e-31 -3.6701587590914506434e-15 1.0774010199652129295e-44" />
<geometry>
<mesh filename="package:///hanche.stl"/>
</geometry>
<material name="hanche_material">
<color rgba="0.2313725490196078538 0.38039215686274507888 0.7058823529411765163 1.0"/>
</material>
</visual>
<collision>
<origin xyz="0.005500000000002376252 0.071500000000000007994 -0.93500000000000027534" rpy="-3.3109585821359983486e-31 -3.6701587590914506434e-15 1.0774010199652129295e-44" />
<geometry>
<mesh filename="package:///hanche.stl"/>
</geometry>
</collision>
<inertial>
<origin xyz="3.4156793823902908969e-08 0.003051083573353055578 -0.08336523680757901289" rpy="0 0 0"/>
<mass value="0.14908820646980494584" />
<inertia ixx="0.00035636864137915792803" ixy="1.6418959534105006531e-10"  ixz="-6.6325805549332913514e-11" iyy="0.00032228379449719343503" iyz="-1.6655006554546136825e-05" izz="4.9201065872666315557e-05" />
</inertial>
</link>

<link name="cardan_foot_3">
<visual>
<origin xyz="0 0.038499999999999978684 -6.6000000000000086375e-05" rpy="1.570796326794896558 1.570796326794896558 0" />
<geometry>
<mesh filename="package:///cardan_foot.stl"/>
</geometry>
<material name="cardan_foot_material">
<color rgba="0.64705882352941179736 0.64705882352941179736 0.64705882352941179736 1.0"/>
</material>
</visual>
<collision>
<origin xyz="0 0.038499999999999978684 -6.6000000000000086375e-05" rpy="1.570796326794896558 1.570796326794896558 0" />
<geometry>
<mesh filename="package:///cardan_foot.stl"/>
</geometry>
</collision>
<inertial>
<origin xyz="6.7228290681873054761e-09 -1.3877787807814456755e-17 -6.5993277170931446225e-05" rpy="0 0 0"/>
<mass value="0.0064135211594024193679" />
<inertia ixx="3.3475011343990655066e-07" ixy="-2.848658323731531802e-12"  ixz="-2.8685952759541640894e-38" iyy="4.3082408299805979528e-07" iyz="2.84865832377020088e-12" izz="3.3475011343990649772e-07" />
</inertial>
</link>

<link name="part_1">
<visual>
<origin xyz="-5.898059818321144121e-17 0 -2.7755575615628913511e-17" rpy="1.570796326794896558 1.570796326794896558 0" />
<geometry>
<mesh filename="package:///part_1.stl"/>
</geometry>
<material name="part_1_material">
<color rgba="0.34901960784313723618 0.37647058823529411242 0.4000000000000000222 1.0"/>
</material>
</visual>
<collision>
<origin xyz="-5.898059818321144121e-17 0 -2.7755575615628913511e-17" rpy="1.570796326794896558 1.570796326794896558 0" />
<geometry>
<mesh filename="package:///part_1.stl"/>
</geometry>
</collision>
<inertial>
<origin xyz="0.006702603912780952071 0.016607315554245556666 -0.045523329198624444547" rpy="0 0 0"/>
<mass value="0.24432174426363423292" />
<inertia ixx="0.00038002986328721232194" ixy="-4.5343822480551197892e-05"  ixz="0.00019115477962150843015" iyy="0.00063262805206548244734" iyz="7.0096670808240431208e-05" izz="0.00036002210019491691449" />
</inertial>
</link>

<link name="closedloop7_B_3D">
<inertial>
<origin xyz="0 0 0" rpy="0 0 0" />
<mass value="1e-9" />
<inertia ixx="0" ixy="0" ixz="0" iyy="0" iyz="0" izz="0" />
</inertial>
</link>
<joint name="closedloop7_B_3D_frame" type="fixed">
<origin xyz="0.083867056794542371723 -0.007711903501502720415 -0.071500000000000063505" rpy="1.570796326794896558 -2.0564927122134184515e-32 -1.3872350632051290567e-14" />
<parent link="part_1" />
<child link="closedloop7_B_3D" />
<axis xyz="0 0 0"/>
</joint>

<link name="piston_12">
<visual>
<origin xyz="-0.10179556944408769958 0.15392457132099851558 -0.8579999999999999849" rpy="-3.3538081441135531553e-19 -8.4827911765797611319e-18 -1.3027733361319404027e-17" />
<geometry>
<mesh filename="package:///piston.stl"/>
</geometry>
<material name="piston_material">
<color rgba="0.91764705882352937127 0.91764705882352937127 0.91764705882352937127 1.0"/>
</material>
</visual>
<collision>
<origin xyz="-0.10179556944408769958 0.15392457132099851558 -0.8579999999999999849" rpy="-3.3538081441135531553e-19 -8.4827911765797611319e-18 -1.3027733361319404027e-17" />
<geometry>
<mesh filename="package:///piston.stl"/>
</geometry>
</collision>
<inertial>
<origin xyz="-4.1633363423443370266e-17 -1.5273599183752535971e-18 -0.011000000000000231815" rpy="0 0 0"/>
<mass value="0.0047041422996690132607" />
<inertia ixx="2.6977766073778931429e-07" ixy="-3.935034543396205062e-24"  ixz="1.8598751360281076833e-24" iyy="2.6977766073778931429e-07" iyz="-1.2850514013003868441e-25" izz="1.6008784263561077721e-07" />
</inertial>
</link>

<link name="closedloop3_A_6D">
<inertial>
<origin xyz="0 0 0" rpy="0 0 0" />
<mass value="1e-9" />
<inertia ixx="0" ixy="0" ixz="0" iyy="0" iyz="0" izz="0" />
</inertial>
</link>
<joint name="closedloop3_A_6D_frame" type="fixed">
<origin xyz="-2.7755575615628913511e-17 -2.7755575615628913511e-17 -0.022000000000000130562" rpy="-3.141592653589793116 -9.9990740856057949295e-16 -3.7021204681756544686e-17" />
<parent link="piston_12" />
<child link="closedloop3_A_6D" />
<axis xyz="0 0 0"/>
</joint>

<joint name="spherical_lower_hip1" type="revolute">
<origin xyz="-0.060500000000000109246 2.7755575615628913511e-17 -0.038499999999999978684" rpy="1.57079632679489678 -0.083114644637934484428 -3.1415926535897846783" />
<parent link="part_1" />
<child link="piston_12" />
<axis xyz="0 0 1"/>
<limit effort="1" velocity="20" />
<joint_properties friction="0.0"/>
</joint>

<link name="piston_13">
<visual>
<origin xyz="-0.10179556944408768571 0.15392457132099846007 -0.8579999999999999849" rpy="3.9154410938960741765e-19 1.7783039300998860428e-18 2.5083595712093066153e-18" />
<geometry>
<mesh filename="package:///piston.stl"/>
</geometry>
<material name="piston_material">
<color rgba="0.91764705882352937127 0.91764705882352937127 0.91764705882352937127 1.0"/>
</material>
</visual>
<collision>
<origin xyz="-0.10179556944408768571 0.15392457132099846007 -0.8579999999999999849" rpy="3.9154410938960741765e-19 1.7783039300998860428e-18 2.5083595712093066153e-18" />
<geometry>
<mesh filename="package:///piston.stl"/>
</geometry>
</collision>
<inertial>
<origin xyz="-2.7755575615628913511e-17 -2.7559930634807332824e-17 -0.011000000000000120792" rpy="0 0 0"/>
<mass value="0.0047041422996690132607" />
<inertia ixx="2.6977766073778931429e-07" ixy="1.0976611335343757713e-24"  ixz="-1.4805728334943739736e-25" iyy="2.6977766073778920841e-07" iyz="9.4347174598327162763e-26" izz="1.6008784263561083015e-07" />
</inertial>
</link>

<link name="closedloop4_A_6D">
<inertial>
<origin xyz="0 0 0" rpy="0 0 0" />
<mass value="1e-9" />
<inertia ixx="0" ixy="0" ixz="0" iyy="0" iyz="0" izz="0" />
</inertial>
</link>
<joint name="closedloop4_A_6D_frame" type="fixed">
<origin xyz="-2.7755575615628913511e-17 0 -0.022000000000000075051" rpy="-3.1415926535897895633 -5.8588589039601575851e-14 -8.1060924113090465019e-18" />
<parent link="piston_13" />
<child link="closedloop4_A_6D" />
<axis xyz="0 0 0"/>
</joint>

<joint name="spherical_lower_hip2" type="revolute">
<origin xyz="-0.06050000000000008149 -8.3266726846886740532e-17 0.038500000000000006439" rpy="-1.57079632679489678 -0.044003745446504607952 -5.158214291223756956e-14" />
<parent link="part_1" />
<child link="piston_13" />
<axis xyz="0 0 1"/>
<limit effort="1" velocity="20" />
<joint_properties friction="0.0"/>
</joint>

<link name="part_2_2">
<visual>
<origin xyz="-2.3453461395206431916e-15 0.046752000000001542324 -0.071500000000000007994" rpy="-1.570796326794896558 -1.570796326794896558 0" />
<geometry>
<mesh filename="package:///part_2.stl"/>
</geometry>
<material name="part_2_material">
<color rgba="0.76862745098039220171 0.88627450980392152857 0.95294117647058818044 1.0"/>
</material>
</visual>
<collision>
<origin xyz="-2.3453461395206431916e-15 0.046752000000001542324 -0.071500000000000007994" rpy="-1.570796326794896558 -1.570796326794896558 0" />
<geometry>
<mesh filename="package:///part_2.stl"/>
</geometry>
</collision>
<inertial>
<origin xyz="-0.10353133038219140827 -0.14056766472890799835 -5.9849347699980626203e-13" rpy="0 0 0"/>
<mass value="0.39806472503371781446" />
<inertia ixx="0.0031977111359881450064" ixy="-0.0018588463574926393767"  ixz="5.7043156992911780596e-15" iyy="0.0012912945788078693775" iyz="2.6363837301527983493e-14" izz="0.0044624680664483240902" />
</inertial>
</link>

<link name="part_3_2">
<visual>
<origin xyz="0.21747050071614923428 0.38247000862966429313 -0.071499999999999980238" rpy="-1.570796326794896558 -1.570796326794896558 0" />
<geometry>
<mesh filename="package:///part_3.stl"/>
</geometry>
<material name="part_3_material">
<color rgba="0.76862745098039220171 0.88627450980392152857 0.95294117647058818044 1.0"/>
</material>
</visual>
<collision>
<origin xyz="0.21747050071614923428 0.38247000862966429313 -0.071499999999999980238" rpy="-1.570796326794896558 -1.570796326794896558 0" />
<geometry>
<mesh filename="package:///part_3.stl"/>
</geometry>
</collision>
<inertial>
<origin xyz="0.10608938835476375284 -0.17986935727287689524 1.3877787807814456755e-17" rpy="0 0 0"/>
<mass value="0.2021348089396567127" />
<inertia ixx="0.0018459328059746544191" ixy="0.0012583807608323401873"  ixz="4.2644445198124430869e-36" iyy="0.00088797005323680870334" iyz="2.8457454866394394501e-36" izz="0.0027204272052821520424" />
</inertial>
</link>

<link name="cardan_foot_4">
<visual>
<origin xyz="0 0.038499999999999978684 6.5999999999954983565e-05" rpy="1.570796326794896558 1.570796326794896558 0" />
<geometry>
<mesh filename="package:///cardan_foot.stl"/>
</geometry>
<material name="cardan_foot_material">
<color rgba="0.64705882352941179736 0.64705882352941179736 0.64705882352941179736 1.0"/>
</material>
</visual>
<collision>
<origin xyz="0 0.038499999999999978684 6.5999999999954983565e-05" rpy="1.570796326794896558 1.570796326794896558 0" />
<geometry>
<mesh filename="package:///cardan_foot.stl"/>
</geometry>
</collision>
<inertial>
<origin xyz="6.7228290684942986712e-09 -1.3877787807814456755e-17 6.6006722829023827003e-05" rpy="0 0 0"/>
<mass value="0.0064135211594024193679" />
<inertia ixx="3.3475011343990655066e-07" ixy="-2.8486583237325762791e-12"  ixz="7.8484521369528770951e-25" iyy="4.3082408299805979528e-07" iyz="2.848658323770701712e-12" izz="3.3475011343990649772e-07" />
</inertial>
</link>

<link name="foot_2">
<visual>
<origin xyz="1.1102230246251565404e-16 0.038499999999999978684 0" rpy="1.570796326794896558 4.5913922084482475084e-18 6.1122437649161357642e-17" />
<geometry>
<mesh filename="package:///foot.stl"/>
</geometry>
<material name="foot_material">
<color rgba="0.61568627450980395466 0.81176470588235294379 0.92941176470588238168 1.0"/>
</material>
</visual>
<collision>
<origin xyz="1.1102230246251565404e-16 0.038499999999999978684 0" rpy="1.570796326794896558 4.5913922084482475084e-18 6.1122437649161357642e-17" />
<geometry>
<mesh filename="package:///foot.stl"/>
</geometry>
</collision>
<inertial>
<origin xyz="-0.0036358817134151065996 0.024966449369929651081 9.0007330158273889051e-08" rpy="0 0 0"/>
<mass value="0.3109129822293019707" />
<inertia ixx="0.00026328612588329933534" ixy="-5.3028311481376147615e-05"  ixz="-1.7872776046562672022e-09" iyy="0.0007189752056611594961" iyz="-2.0903095188772828236e-10" izz="0.00052661427618999384539" />
</inertial>
</link>

<link name="foot_right">
<inertial>
<origin xyz="0 0 0" rpy="0 0 0" />
<mass value="1e-9" />
<inertia ixx="0" ixy="0" ixz="0" iyy="0" iyz="0" izz="0" />
</inertial>
</link>
<joint name="foot_right_frame" type="fixed">
<origin xyz="0.01201694922107987562 0.038499999999999923173 6.8117394225186700396e-09" rpy="1.5707963267948972241 4.1530747501458917702e-18 1.4689606375488657859e-15" />
<parent link="foot_2" />
<child link="foot_right" />
<axis xyz="0 0 0"/>
</joint>

<link name="closedloop0_A_3D">
<inertial>
<origin xyz="0 0 0" rpy="0 0 0" />
<mass value="1e-9" />
<inertia ixx="0" ixy="0" ixz="0" iyy="0" iyz="0" izz="0" />
</inertial>
</link>
<joint name="closedloop0_A_3D_frame" type="fixed">
<origin xyz="-0.054999999999999882316 -0.01100000000000000977 0.038500000000000006439" rpy="1.570796326794896558 6.2711683153062856565e-17 -1.5707963267948958919" />
<parent link="foot_2" />
<child link="closedloop0_A_3D" />
<axis xyz="0 0 0"/>
</joint>

<link name="closedloop11_A_3D">
<inertial>
<origin xyz="0 0 0" rpy="0 0 0" />
<mass value="1e-9" />
<inertia ixx="0" ixy="0" ixz="0" iyy="0" iyz="0" izz="0" />
</inertial>
</link>
<joint name="closedloop11_A_3D_frame" type="fixed">
<origin xyz="-0.054999999999999826805 -0.01100000000000000977 -0.038500000000000006439" rpy="1.570796326794896558 6.2711683153062856565e-17 -1.5707963267948958919" />
<parent link="foot_2" />
<child link="closedloop11_A_3D" />
<axis xyz="0 0 0"/>
</joint>

<joint name="free_ankle_universalx" type="revolute">
<origin xyz="6.5999999999899472414e-05 -9.9920072216264088638e-16 6.6000000001481540224e-05" rpy="-1.5707963267948978903 -0.95882611835293851676 -1.5707963267948956698" />
<parent link="cardan_foot_4" />
<child link="foot_2" />
<axis xyz="0 0 1"/>
<limit effort="1" velocity="20" />
<joint_properties friction="0.0"/>
</joint>

<joint name="uneveral_foot1" type="revolute">
<origin xyz="0.21747050071614928979 -0.33571800862966416634 0" rpy="-1.5707963267948958919 -1.4835298641951766285 1.5707963267949329733" />
<parent link="part_3_2" />
<child link="cardan_foot_4" />
<axis xyz="0 0 1"/>
<limit effort="1" velocity="20" />
<joint_properties friction="0.0"/>
</joint>

<link name="part_6_2">
<visual>
<origin xyz="0.10788167727912306715 -0.039150197130724595507 5.5511151231257827021e-17" rpy="-3.141592653589793116 -3.5714115552455553433e-18 -1.9102401721926463047e-17" />
<geometry>
<mesh filename="package:///part_6.stl"/>
</geometry>
<material name="part_6_material">
<color rgba="0.76862745098039220171 0.88627450980392152857 0.95294117647058818044 1.0"/>
</material>
</visual>
<collision>
<origin xyz="0.10788167727912306715 -0.039150197130724595507 5.5511151231257827021e-17" rpy="-3.141592653589793116 -3.5714115552455553433e-18 -1.9102401721926463047e-17" />
<geometry>
<mesh filename="package:///part_6.stl"/>
</geometry>
</collision>
<inertial>
<origin xyz="6.9388939039072283776e-17 -2.5406741300251306394e-17 -0.21359999999999998432" rpy="0 0 0"/>
<mass value="0.033552209540339043847" />
<inertia ixx="0.00051048244070615639203" ixy="-1.5008122992165967766e-20"  ixz="1.8246454166957101667e-21" iyy="0.00051048244070615639203" iyz="1.2772442293649579136e-20" izz="4.1940261925423882626e-07" />
</inertial>
</link>

<link name="closedloop6_B_3D">
<inertial>
<origin xyz="0 0 0" rpy="0 0 0" />
<mass value="1e-9" />
<inertia ixx="0" ixy="0" ixz="0" iyy="0" iyz="0" izz="0" />
</inertial>
</link>
<joint name="closedloop6_B_3D_frame" type="fixed">
<origin xyz="2.7755575615628913511e-17 -5.5511151231257827021e-17 -0.42719999999999991314" rpy="-3.1415926535897926719 4.3962922511980055669e-16 3.141592653589793116" />
<parent link="part_6_2" />
<child link="closedloop6_B_3D" />
<axis xyz="0 0 0"/>
</joint>

<joint name="spherical_shin_rod1" type="revolute">
<origin xyz="0.038967453687049735667 -0.092095263467496718546 1.1102230246251565404e-16" rpy="-1.57079632679489678 -1.3380503778517249813 1.5707963267948987784" />
<parent link="part_3_2" />
<child link="part_6_2" />
<axis xyz="0 0 1"/>
<limit effort="1" velocity="20" />
<joint_properties friction="0.0"/>
</joint>

<joint name="lower_knee" type="revolute">
<origin xyz="-0.21747050071615126043 -0.3357180086296619459 -2.2204460492503130808e-16" rpy="-1.2825270953943237956e-16 -5.2913746228227154917e-16 0.89630439304597941952" />
<parent link="part_2_2" />
<child link="part_3_2" />
<axis xyz="0 0 1"/>
<limit effort="1" velocity="20" />
<joint_properties friction="0.0"/>
</joint>

<link name="renvois_cheville_2_8_2">
<visual>
<origin xyz="-0.11550000000000004707 -0.35749999999999992895 0.032999999999999973799" rpy="-1.570796326794896558 1.0489594920773023007e-31 1.9731702801127553748e-17" />
<geometry>
<mesh filename="package:///renvois_cheville_2_8.stl"/>
</geometry>
<material name="renvois_cheville_2_8_material">
<color rgba="0.91764705882352937127 0.91764705882352937127 0.91764705882352937127 1.0"/>
</material>
</visual>
<collision>
<origin xyz="-0.11550000000000004707 -0.35749999999999992895 0.032999999999999973799" rpy="-1.570796326794896558 1.0489594920773023007e-31 1.9731702801127553748e-17" />
<geometry>
<mesh filename="package:///renvois_cheville_2_8.stl"/>
</geometry>
</collision>
<inertial>
<origin xyz="-0.033596086250149329033 -0.018380744757818923141 -0.014122199558543463427" rpy="0 0 0"/>
<mass value="0.074310320490072731547" />
<inertia ixx="4.1295450354366541358e-05" ixy="1.988605193818464217e-06"  ixz="-2.0689202263474869013e-06" iyy="3.2625641947312141421e-05" iyz="-9.9798202174584469521e-06" izz="5.1310129727252684509e-05" />
</inertial>
</link>

<link name="closedloop10_B_3D">
<inertial>
<origin xyz="0 0 0" rpy="0 0 0" />
<mass value="1e-9" />
<inertia ixx="0" ixy="0" ixz="0" iyy="0" iyz="0" izz="0" />
</inertial>
</link>
<joint name="closedloop10_B_3D_frame" type="fixed">
<origin xyz="-0.03585471788862894249 -0.041706584673488089621 -0.052249999999999963141" rpy="-1.57079632679489678 4.2500725161430485751e-17 -2.5782405335516153514e-16" />
<parent link="renvois_cheville_2_8_2" />
<child link="closedloop10_B_3D" />
<axis xyz="0 0 0"/>
</joint>

<link name="part_7_5">
<visual>
<origin xyz="0.062087559207389952931 0.15255026628033757641 -1.9081958235744878039e-17" rpy="-3.141592653589793116 1.0842292048905287506e-17 3.9791344991194272221e-17" />
<geometry>
<mesh filename="package:///part_7.stl"/>
</geometry>
<material name="part_7_material">
<color rgba="0.91764705882352937127 0.91764705882352937127 0.91764705882352937127 1.0"/>
</material>
</visual>
<collision>
<origin xyz="0.062087559207389952931 0.15255026628033757641 -1.9081958235744878039e-17" rpy="-3.141592653589793116 1.0842292048905287506e-17 3.9791344991194272221e-17" />
<geometry>
<mesh filename="package:///part_7.stl"/>
</geometry>
</collision>
<inertial>
<origin xyz="6.2450045135165055399e-17 -4.8623305626503394495e-17 -0.20000000000000012212" rpy="0 0 0"/>
<mass value="0.031415926535897982508" />
<inertia ixx="0.00041907537001948915118" ixy="4.1520380399802351722e-20"  ixz="-4.4799237397910850856e-21" iyy="0.00041907537001948936802" iyz="7.6840952568232838521e-21" izz="3.9269908169872580702e-07" />
</inertial>
</link>

<link name="closedloop0_B_3D">
<inertial>
<origin xyz="0 0 0" rpy="0 0 0" />
<mass value="1e-9" />
<inertia ixx="0" ixy="0" ixz="0" iyy="0" iyz="0" izz="0" />
</inertial>
</link>
<joint name="closedloop0_B_3D_frame" type="fixed">
<origin xyz="0 -5.5511151231257827021e-17 -0.40000000000000007772" rpy="3.1415926535897913396 1.3110944058270872971e-15 -1.570796326794896558" />
<parent link="part_7_5" />
<child link="closedloop0_B_3D" />
<axis xyz="0 0 0"/>
</joint>

<joint name="spherical_transmission_foot2" type="revolute">
<origin xyz="-0.059494699261975467208 0.01098320352752724105 -0.021999999999999964029" rpy="-1.57079632679489678 0.2674961218464166901 -1.570796326794896558" />
<parent link="renvois_cheville_2_8_2" />
<child link="part_7_5" />
<axis xyz="0 0 1"/>
<limit effort="1" velocity="20" />
<joint_properties friction="0.0"/>
</joint>

<joint name="triangle_knee1" type="revolute">
<origin xyz="-0.21747050071615151023 -0.33571800862966283407 0.010000000000000008882" rpy="3.1415926535897922278 2.5397996671417581801e-15 3.0532620163569994531" />
<parent link="part_2_2" />
<child link="renvois_cheville_2_8_2" />
<axis xyz="0 0 1"/>
<limit effort="1" velocity="20" />
<joint_properties friction="0.0"/>
</joint>

<link name="renvois_cheville_2">
<visual>
<origin xyz="-0.11550000000000001932 -0.35749999999999981792 -0.032999999999999918288" rpy="-1.570796326794896558 -3.8842663271013338846e-32 -1.7292512105627270119e-17" />
<geometry>
<mesh filename="package:///renvois_cheville.stl"/>
</geometry>
<material name="renvois_cheville_material">
<color rgba="0.91764705882352937127 0.91764705882352937127 0.91764705882352937127 1.0"/>
</material>
</visual>
<collision>
<origin xyz="-0.11550000000000001932 -0.35749999999999981792 -0.032999999999999918288" rpy="-1.570796326794896558 -3.8842663271013338846e-32 -1.7292512105627270119e-17" />
<geometry>
<mesh filename="package:///renvois_cheville.stl"/>
</geometry>
</collision>
<inertial>
<origin xyz="-0.03359608659253086882 -0.018380744754187161583 0.014122199609931607167" rpy="0 0 0"/>
<mass value="0.074310321213953547947" />
<inertia ixx="4.1295450352451928413e-05" ixy="1.988605320318323592e-06"  ixz="2.0689203249184058862e-06" iyy="3.2625642523550437595e-05" iyz="9.9798202218794591873e-06" izz="5.1310130219953338818e-05" />
</inertial>
</link>

<link name="closedloop9_B_3D">
<inertial>
<origin xyz="0 0 0" rpy="0 0 0" />
<mass value="1e-9" />
<inertia ixx="0" ixy="0" ixz="0" iyy="0" iyz="0" izz="0" />
</inertial>
</link>
<joint name="closedloop9_B_3D_frame" type="fixed">
<origin xyz="-0.035854717888628921674 -0.041706584673488200643 0.052250000000000046407" rpy="1.570796326794896558 7.4525120443701586197e-31 -3.1415926535897908956" />
<parent link="renvois_cheville_2" />
<child link="closedloop9_B_3D" />
<axis xyz="0 0 0"/>
</joint>

<link name="part_7_6">
<visual>
<origin xyz="0.06208755920738989742 -0.15255026628033763192 -0.40000000000000013323" rpy="-1.2019258149202308314e-17 7.4557898188730944883e-19 -3.0411119548499977744e-18" />
<geometry>
<mesh filename="package:///part_7.stl"/>
</geometry>
<material name="part_7_material">
<color rgba="0.91764705882352937127 0.91764705882352937127 0.91764705882352937127 1.0"/>
</material>
</visual>
<collision>
<origin xyz="0.06208755920738989742 -0.15255026628033763192 -0.40000000000000013323" rpy="-1.2019258149202308314e-17 7.4557898188730944883e-19 -3.0411119548499977744e-18" />
<geometry>
<mesh filename="package:///part_7.stl"/>
</geometry>
</collision>
<inertial>
<origin xyz="5.5511151231257827021e-17 -2.2047486419643679611e-17 -0.20000000000000009437" rpy="0 0 0"/>
<mass value="0.031415926535897982508" />
<inertia ixx="0.00041907537001948915118" ixy="6.17963700626129028e-22"  ixz="-2.9443561249316962678e-22" iyy="0.00041907537001948915118" iyz="-5.0261379871238113026e-21" izz="3.9269908169872559526e-07" />
</inertial>
</link>

<link name="closedloop11_B_3D">
<inertial>
<origin xyz="0 0 0" rpy="0 0 0" />
<mass value="1e-9" />
<inertia ixx="0" ixy="0" ixz="0" iyy="0" iyz="0" izz="0" />
</inertial>
</link>
<joint name="closedloop11_B_3D_frame" type="fixed">
<origin xyz="0 2.7755575615628913511e-17 -0.40000000000000013323" rpy="3.1415926535897895633 -3.5435748969399307641e-16 1.570796326794896558" />
<parent link="part_7_6" />
<child link="closedloop11_B_3D" />
<axis xyz="0 0 0"/>
</joint>

<joint name="spherical_transmission_foot1" type="revolute">
<origin xyz="-0.059494699261975467208 0.010983203527527130028 0.02200000000000001954" rpy="1.570796326794896558 -0.30096768397183631949 1.5707963267948981123" />
<parent link="renvois_cheville_2" />
<child link="part_7_6" />
<axis xyz="0 0 1"/>
<limit effort="1" velocity="20" />
<joint_properties friction="0.0"/>
</joint>

<joint name="triangle_knee2" type="revolute">
<origin xyz="-0.2174705007161515935 -0.33571800862966272305 -0.010000000000000008882" rpy="3.1415926535897926719 2.3960728016627840815e-15 3.0785068790704639419" />
<parent link="part_2_2" />
<child link="renvois_cheville_2" />
<axis xyz="0 0 1"/>
<limit effort="1" velocity="20" />
<joint_properties friction="0.0"/>
</joint>

<link name="part_4_2">
<visual>
<origin xyz="-0.010530049701071103607 0.092146047735299205228 -0.071500000000000063505" rpy="-1.570796326794896558 -1.570796326794896558 0" />
<geometry>
<mesh filename="package:///part_4.stl"/>
</geometry>
<material name="part_4_material">
<color rgba="1 0.7568627450980391913 0.054901960784313724728 1.0"/>
</material>
</visual>
<collision>
<origin xyz="-0.010530049701071103607 0.092146047735299205228 -0.071500000000000063505" rpy="-1.570796326794896558 -1.570796326794896558 0" />
<geometry>
<mesh filename="package:///part_4.stl"/>
</geometry>
</collision>
<inertial>
<origin xyz="0.019483726843524840078 -0.046047631733748324578 -4.1633363423443376429e-17" rpy="0 0 0"/>
<mass value="0.011311035579799528367" />
<inertia ixx="1.0009836990585404797e-05" ixy="4.1536946028868301987e-06"  ixz="-5.4133420794259693095e-37" iyy="1.9505556032253768346e-06" iyz="-6.8590833697575009527e-37" izz="1.1771875334147456995e-05" />
</inertial>
</link>

<link name="closedloop6_A_3D">
<inertial>
<origin xyz="0 0 0" rpy="0 0 0" />
<mass value="1e-9" />
<inertia ixx="0" ixy="0" ixz="0" iyy="0" iyz="0" izz="0" />
</inertial>
</link>
<joint name="closedloop6_A_3D_frame" type="fixed">
<origin xyz="0.038967453687049735667 -0.092095263467496676912 -5.5511151231257827021e-17" rpy="1.570796326794896558 4.0264892381777355687e-23 -1.570796326794896336" />
<parent link="part_4_2" />
<child link="closedloop6_A_3D" />
<axis xyz="0 0 0"/>
</joint>

<link name="part_5_2">
<visual>
<origin xyz="0.063404956281616797753 0.053322112528135567899 0" rpy="3.141592653589793116 5.4452107762399029678e-17 -1.581242105037273282e-17" />
<geometry>
<mesh filename="package:///part_5.stl"/>
</geometry>
<material name="part_5_material">
<color rgba="0.91764705882352937127 0.91764705882352937127 0.91764705882352937127 1.0"/>
</material>
</visual>
<collision>
<origin xyz="0.063404956281616797753 0.053322112528135567899 0" rpy="3.141592653589793116 5.4452107762399029678e-17 -1.581242105037273282e-17" />
<geometry>
<mesh filename="package:///part_5.stl"/>
</geometry>
</collision>
<inertial>
<origin xyz="1.3877787807814456755e-17 -6.8834275347424433365e-17 -0.070709999999999995079" rpy="0 0 0"/>
<mass value="0.011107100826766714077" />
<inertia ixx="1.8580899034455386872e-05" ixy="-4.052263004287151616e-22"  ixz="-1.0117787632511172689e-21" iyy="1.8580899034455386872e-05" iyz="-1.0615448880685626886e-22" izz="1.3883876033458398932e-07" />
</inertial>
</link>

<link name="closedloop7_A_3D">
<inertial>
<origin xyz="0 0 0" rpy="0 0 0" />
<mass value="1e-9" />
<inertia ixx="0" ixy="0" ixz="0" iyy="0" iyz="0" izz="0" />
</inertial>
</link>
<joint name="closedloop7_A_3D_frame" type="fixed">
<origin xyz="1.3877787807814456755e-17 -5.5511151231257827021e-17 -0.14142000000000001791" rpy="-3.141592653589793116 -2.5701272669893044796e-16 1.5487482446605287392e-16" />
<parent link="part_5_2" />
<child link="closedloop7_A_3D" />
<axis xyz="0 0 0"/>
</joint>

<joint name="spherical_4rod" type="revolute">
<origin xyz="0.0194837268435249511 -0.046047631733748387028 0" rpy="1.57079632679489678 0.15824418733945430637 1.5707963267948958919" />
<parent link="part_4_2" />
<child link="part_5_2" />
<axis xyz="0 0 1"/>
<limit effort="1" velocity="20" />
<joint_properties friction="0.0"/>
</joint>

<joint name="4rod_knee" type="revolute">
<origin xyz="0.046047631733745986171 -0.019483726843523341277 -1.1102230246251565404e-16" rpy="3.141592653589793116 2.0222300709208235426e-16 -1.2672660179279322534" />
<parent link="part_2_2" />
<child link="part_4_2" />
<axis xyz="0 0 1"/>
<limit effort="1" velocity="20" />
<joint_properties friction="0.0"/>
</joint>

<link name="motteur_rotation_4">
<visual>
<origin xyz="0.033000000000000057065 0.88825000000000020606 -0.10449999999999914913" rpy="1.570796326794896558 1.5707963267948927832 0" />
<geometry>
<mesh filename="package:///motteur_rotation.stl"/>
</geometry>
<material name="motteur_rotation_material">
<color rgba="1 0 0 1.0"/>
</material>
</visual>
<collision>
<origin xyz="0.033000000000000057065 0.88825000000000020606 -0.10449999999999914913" rpy="1.570796326794896558 1.5707963267948927832 0" />
<geometry>
<mesh filename="package:///motteur_rotation.stl"/>
</geometry>
</collision>
<inertial>
<origin xyz="-4.2413960642530027318e-17 1.1102230246251565404e-16 -0.017243243243243278062" rpy="0 0 0"/>
<mass value="0.19339251676417062997" />
<inertia ixx="4.9207470246053574929e-05" ixy="9.2195496114233579387e-22"  ixz="1.6649633185126964814e-22" iyy="4.9207470246053534272e-05" iyz="-5.6408426651239407996e-20" izz="3.3697502678236661278e-05" />
</inertial>
</link>

<link name="piston_14">
<visual>
<origin xyz="-0.10179556944408774122 0.15392457132099854333 -0.8579999999999999849" rpy="5.5184706501581394422e-17 1.0102653392138596757e-17 -2.5003152933936445398e-17" />
<geometry>
<mesh filename="package:///piston.stl"/>
</geometry>
<material name="piston_material">
<color rgba="0.91764705882352937127 0.91764705882352937127 0.91764705882352937127 1.0"/>
</material>
</visual>
<collision>
<origin xyz="-0.10179556944408774122 0.15392457132099854333 -0.8579999999999999849" rpy="5.5184706501581394422e-17 1.0102653392138596757e-17 -2.5003152933936445398e-17" />
<geometry>
<mesh filename="package:///piston.stl"/>
</geometry>
</collision>
<inertial>
<origin xyz="-9.7144514654701197287e-17 4.0424596163214278435e-17 -0.011000000000000120792" rpy="0 0 0"/>
<mass value="0.0047041422996690132607" />
<inertia ixx="2.6977766073778931429e-07" ixy="-1.3173643011699640782e-23"  ixz="-4.3249117804461373126e-24" iyy="2.6977766073778931429e-07" iyz="1.7763177623857885991e-23" izz="1.6008784263561083015e-07" />
</inertial>
</link>

<link name="closedloop8_A_6D">
<inertial>
<origin xyz="0 0 0" rpy="0 0 0" />
<mass value="1e-9" />
<inertia ixx="0" ixy="0" ixz="0" iyy="0" iyz="0" izz="0" />
</inertial>
</link>
<joint name="closedloop8_A_6D_frame" type="fixed">
<origin xyz="-8.3266726846886740532e-17 8.3266726846886740532e-17 -0.022000000000000075051" rpy="-3.141592653589793116 -7.5767938905805758326e-17 -1.570796326794896336" />
<parent link="piston_14" />
<child link="closedloop8_A_6D" />
<axis xyz="0 0 0"/>
</joint>

<joint name="motor_knee" type="prismatic">
<origin xyz="5.5511151231257827021e-17 1.6653345369377348106e-16 -0.020205644373555181614" rpy="3.141592653589793116 1.4510931439305401901e-15 -4.1052068437918848451e-15" />
<parent link="motteur_rotation_4" />
<child link="piston_14" />
<axis xyz="0 0 1"/>
<limit effort="1" velocity="20" />
<joint_properties friction="0.0"/>
</joint>

<joint name="frame_motor_knee" type="revolute">
<origin xyz="-0.061655078133537280505 -0.018724201373191778908 4.297340261416593421e-12" rpy="-1.570796326794896558 1.2771385194773066107 -0.60601731071218278846" />
<parent link="part_2_2" />
<child link="motteur_rotation_4" />
<axis xyz="0 0 1"/>
<limit effort="1" velocity="20" />
<joint_properties friction="0.0"/>
</joint>

<joint name="upper_knee" type="revolute">
<origin xyz="-5.2041704279304212832e-16 0.046752000000001264768 -0.071500000000000007994" rpy="-3.1415926535897860106 -5.537490036297666694e-15 0.67044957344281030931" />
<parent link="part_1" />
<child link="part_2_2" />
<axis xyz="0 0 1"/>
<limit effort="1" velocity="20" />
<joint_properties friction="0.0"/>
</joint>

<link name="part_8_2">
<visual>
<origin xyz="0 -0.046752000000000029645 0.087999999999999939382" rpy="1.570796326794896558 1.570796326794896558 0" />
<geometry>
<mesh filename="package:///part_8.stl"/>
</geometry>
<material name="part_8_material">
<color rgba="0.49803921568627451677 0.49803921568627451677 0.49803921568627451677 1.0"/>
</material>
</visual>
<collision>
<origin xyz="0 -0.046752000000000029645 0.087999999999999939382" rpy="1.570796326794896558 1.570796326794896558 0" />
<geometry>
<mesh filename="package:///part_8.stl"/>
</geometry>
</collision>
<inertial>
<origin xyz="0.031934770108260165933 0.010733820853410619769 -0.0056648401062836658756" rpy="0 0 0"/>
<mass value="0.0062040903886272725024" />
<inertia ixx="9.174211164042201537e-07" ixy="-1.6316603808924172267e-07"  ixz="2.2769789117187739132e-07" iyy="1.3280669465102748746e-06" iyz="-1.478347933879084693e-07" izz="1.7548720440932146456e-06" />
</inertial>
</link>

<link name="piston_15">
<visual>
<origin xyz="-0.1017955694440876302 -0.15392457132099848782 0.83600000000000007638" rpy="3.141592653589793116 3.0313180123444658749e-18 -1.4344834995909639864e-18" />
<geometry>
<mesh filename="package:///piston.stl"/>
</geometry>
<material name="piston_material">
<color rgba="0.91764705882352937127 0.91764705882352937127 0.91764705882352937127 1.0"/>
</material>
</visual>
<collision>
<origin xyz="-0.1017955694440876302 -0.15392457132099848782 0.83600000000000007638" rpy="3.141592653589793116 3.0313180123444658749e-18 -1.4344834995909639864e-18" />
<geometry>
<mesh filename="package:///piston.stl"/>
</geometry>
</collision>
<inertial>
<origin xyz="2.7755575615628913511e-17 1.5676230620821940446e-17 -0.010999999999999787725" rpy="0 0 0"/>
<mass value="0.0047041422996690132607" />
<inertia ixx="2.6977766073778931429e-07" ixy="8.1379100244071893703e-24"  ixz="-5.1335311045345151016e-25" iyy="2.6977766073778920841e-07" iyz="-2.849347977685059506e-23" izz="1.6008784263561083015e-07" />
</inertial>
</link>

<link name="closedloop1_B_3D">
<inertial>
<origin xyz="0 0 0" rpy="0 0 0" />
<mass value="1e-9" />
<inertia ixx="0" ixy="0" ixz="0" iyy="0" iyz="0" izz="0" />
</inertial>
</link>
<joint name="closedloop1_B_3D_frame" type="fixed">
<origin xyz="1.1102230246251565404e-16 -5.5511151231257827021e-17 -0.021999999999999908518" rpy="-3.1415926535897900074 2.0244592807192931317e-15 -1.570796326794896336" />
<parent link="piston_15" />
<child link="closedloop1_B_3D" />
<axis xyz="0 0 0"/>
</joint>

<joint name="spherical_transmission_motor_hip1" type="revolute">
<origin xyz="0.043531328479973735446 0.0032046566522409003497 -0.025000000000000077716" rpy="1.5707963267948992225 -1.3881446540757451658 -3.1415926535897669147" />
<parent link="part_8_2" />
<child link="piston_15" />
<axis xyz="0 0 1"/>
<limit effort="1" velocity="20" />
<joint_properties friction="0.0"/>
</joint>

<link name="part_7_7">
<visual>
<origin xyz="0.062087559207389821092 -0.15255026628033760416 -0.4000000000000000222" rpy="-2.7213228885975979251e-17 -4.9312357427293890064e-17 3.0974761285468166481e-17" />
<geometry>
<mesh filename="package:///part_7.stl"/>
</geometry>
<material name="part_7_material">
<color rgba="0.91764705882352937127 0.91764705882352937127 0.91764705882352937127 1.0"/>
</material>
</visual>
<collision>
<origin xyz="0.062087559207389821092 -0.15255026628033760416 -0.4000000000000000222" rpy="-2.7213228885975979251e-17 -4.9312357427293890064e-17 3.0974761285468166481e-17" />
<geometry>
<mesh filename="package:///part_7.stl"/>
</geometry>
</collision>
<inertial>
<origin xyz="-2.0816681711721685133e-17 2.3108472279087474041e-18 -0.19999999999999998335" rpy="0 0 0"/>
<mass value="0.031415926535897982508" />
<inertia ixx="0.00041907537001948915118" ixy="3.8001098215651305796e-20"  ixz="2.0659138009299931014e-20" iyy="0.00041907537001948915118" iyz="-1.139608053595072642e-20" izz="3.9269908169872559526e-07" />
</inertial>
</link>

<link name="closedloop10_A_3D">
<inertial>
<origin xyz="0 0 0" rpy="0 0 0" />
<mass value="1e-9" />
<inertia ixx="0" ixy="0" ixz="0" iyy="0" iyz="0" izz="0" />
</inertial>
</link>
<joint name="closedloop10_A_3D_frame" type="fixed">
<origin xyz="-2.5695591487906455086e-17 0 -0.4000000000000000222" rpy="1.4121142989576800076e-16 6.455226355074138767e-16 -4.8615344150257609708e-16" />
<parent link="part_7_7" />
<child link="closedloop10_A_3D" />
<axis xyz="0 0 0"/>
</joint>

<joint name="spherical_transmission_hip3" type="revolute">
<origin xyz="0.041074543378118805181 0.036577067764912860048 -0.0050000000000000044409" rpy="-1.570796326794896558 0.67303436723393439411 3.141592653589793116" />
<parent link="part_8_2" />
<child link="part_7_7" />
<axis xyz="0 0 1"/>
<limit effort="1" velocity="20" />
<joint_properties friction="0.0"/>
</joint>

<joint name="transmission_hip1" type="revolute">
<origin xyz="-5.1694759584108851413e-16 0.046752000000001264768 -0.088000000000000022649" rpy="5.7225514480077479615e-15 -7.6451103975374452784e-15 1.22289950972905892" />
<parent link="part_1" />
<child link="part_8_2" />
<axis xyz="0 0 1"/>
<limit effort="1" velocity="20" />
<joint_properties friction="0.0"/>
</joint>

<link name="part_9_2">
<visual>
<origin xyz="2.7755575615628913511e-17 0.046752000000000036584 -0.05500000000000004885" rpy="-1.570796326794896558 -1.570796326794896558 0" />
<geometry>
<mesh filename="package:///part_9.stl"/>
</geometry>
<material name="part_9_material">
<color rgba="0.49803921568627451677 0.49803921568627451677 0.49803921568627451677 1.0"/>
</material>
</visual>
<collision>
<origin xyz="2.7755575615628913511e-17 0.046752000000000036584 -0.05500000000000004885" rpy="-1.570796326794896558 -1.570796326794896558 0" />
<geometry>
<mesh filename="package:///part_9.stl"/>
</geometry>
</collision>
<inertial>
<origin xyz="0.031934770108260200627 -0.010733820853410604157 -0.0056648401062836320485" rpy="0 0 0"/>
<mass value="0.0062040903886272707676" />
<inertia ixx="9.1742111640423360035e-07" ixy="1.6316603808924365497e-07"  ixz="2.2769789117187752367e-07" iyy="1.3280669465102725453e-06" iyz="1.4783479338790936927e-07" izz="1.7548720440932265041e-06" />
</inertial>
</link>

<link name="piston_16">
<visual>
<origin xyz="-0.10179556944408765795 -0.15392457132099857109 0.83599999999999996536" rpy="3.141592653589793116 1.8380694473692108142e-20 -2.2063544882257860807e-17" />
<geometry>
<mesh filename="package:///piston.stl"/>
</geometry>
<material name="piston_material">
<color rgba="0.91764705882352937127 0.91764705882352937127 0.91764705882352937127 1.0"/>
</material>
</visual>
<collision>
<origin xyz="-0.10179556944408765795 -0.15392457132099857109 0.83599999999999996536" rpy="3.141592653589793116 1.8380694473692108142e-20 -2.2063544882257860807e-17" />
<geometry>
<mesh filename="package:///piston.stl"/>
</geometry>
</collision>
<inertial>
<origin xyz="-1.3877787807814456755e-17 -1.0504792879063171495e-16 -0.010999999999999898748" rpy="0 0 0"/>
<mass value="0.0047041422996690132607" />
<inertia ixx="2.6977766073778931429e-07" ixy="-2.4250340631096371772e-23"  ixz="4.3410945207216600811e-25" iyy="2.6977766073778931429e-07" iyz="7.2441089953997774678e-24" izz="1.6008784263561083015e-07" />
</inertial>
</link>

<link name="closedloop2_B_3D">
<inertial>
<origin xyz="0 0 0" rpy="0 0 0" />
<mass value="1e-9" />
<inertia ixx="0" ixy="0" ixz="0" iyy="0" iyz="0" izz="0" />
</inertial>
</link>
<joint name="closedloop2_B_3D_frame" type="fixed">
<origin xyz="0 -8.3266726846886740532e-17 -0.021999999999999936273" rpy="3.1415926535897926719 3.2183378182619466957e-15 -1.570796326794896558" />
<parent link="piston_16" />
<child link="closedloop2_B_3D" />
<axis xyz="0 0 0"/>
</joint>

<joint name="spherical_transmission_motor_hip2" type="revolute">
<origin xyz="0.04353132847997370769 -0.0032046566522409836164 -0.024999999999999994449" rpy="1.570796326794896558 -1.0520766825141583123 -1.2677408616997643214e-14" />
<parent link="part_9_2" />
<child link="piston_16" />
<axis xyz="0 0 1"/>
<limit effort="1" velocity="20" />
<joint_properties friction="0.0"/>
</joint>

<link name="part_7_8">
<visual>
<origin xyz="0.06208755920738989742 -0.1525502662803375209 -0.4000000000000000222" rpy="3.8060233474434495746e-17 -3.2833984157243235594e-17 2.4327067168634518076e-17" />
<geometry>
<mesh filename="package:///part_7.stl"/>
</geometry>
<material name="part_7_material">
<color rgba="0.91764705882352937127 0.91764705882352937127 0.91764705882352937127 1.0"/>
</material>
</visual>
<collision>
<origin xyz="0.06208755920738989742 -0.1525502662803375209 -0.4000000000000000222" rpy="3.8060233474434495746e-17 -3.2833984157243235594e-17 2.4327067168634518076e-17" />
<geometry>
<mesh filename="package:///part_7.stl"/>
</geometry>
</collision>
<inertial>
<origin xyz="4.1633363423443370266e-17 8.4918173977677808342e-17 -0.19999999999999998335" rpy="0 0 0"/>
<mass value="0.031415926535897982508" />
<inertia ixx="0.00041907537001948915118" ixy="7.947469223284384149e-21"  ixz="1.3747665877502258623e-20" iyy="0.00041907537001948915118" iyz="1.5956314714796616443e-20" izz="3.9269908169872559526e-07" />
</inertial>
</link>

<link name="closedloop9_A_3D">
<inertial>
<origin xyz="0 0 0" rpy="0 0 0" />
<mass value="1e-9" />
<inertia ixx="0" ixy="0" ixz="0" iyy="0" iyz="0" izz="0" />
</inertial>
</link>
<joint name="closedloop9_A_3D_frame" type="fixed">
<origin xyz="0 5.2041704279304212832e-17 -0.40000000000000013323" rpy="-2.3882228318976020147e-15 -1.0948393169349909809e-15 -1.5707963267948972241" />
<parent link="part_7_8" />
<child link="closedloop9_A_3D" />
<axis xyz="0 0 0"/>
</joint>

<joint name="spherical_transmission_hip4" type="revolute">
<origin xyz="0.041074543378118943959 -0.036577067764912887804 -0.005000000000000059952" rpy="1.570796326794896558 0.73924967494907445342 3.1415926535897851224" />
<parent link="part_9_2" />
<child link="part_7_8" />
<axis xyz="0 0 1"/>
<limit effort="1" velocity="20" />
<joint_properties friction="0.0"/>
</joint>

<joint name="transmission_hip2" type="revolute">
<origin xyz="-5.1000870193718128576e-16 0.046752000000001264768 -0.05500000000000004885" rpy="-3.1415926535897877869 -8.2007279796863668596e-15 1.2711706446052168928" />
<parent link="part_1" />
<child link="part_9_2" />
<axis xyz="0 0 1"/>
<limit effort="1" velocity="20" />
<joint_properties friction="0.0"/>
</joint>

<link name="piston_17">
<visual>
<origin xyz="-0.10179556944408768571 0.15392457132099848782 -0.8579999999999999849" rpy="-6.0379725571924557816e-18 -2.3521748706793173673e-18 9.4637311982421986332e-17" />
<geometry>
<mesh filename="package:///piston.stl"/>
</geometry>
<material name="piston_material">
<color rgba="0.91764705882352937127 0.91764705882352937127 0.91764705882352937127 1.0"/>
</material>
</visual>
<collision>
<origin xyz="-0.10179556944408768571 0.15392457132099848782 -0.8579999999999999849" rpy="-6.0379725571924557816e-18 -2.3521748706793173673e-18 9.4637311982421986332e-17" />
<geometry>
<mesh filename="package:///piston.stl"/>
</geometry>
</collision>
<inertial>
<origin xyz="-1.3877787807814456755e-17 -1.5089093096108227201e-17 -0.011000000000000120792" rpy="0 0 0"/>
<mass value="0.0047041422996690132607" />
<inertia ixx="2.6977766073778931429e-07" ixy="-6.0466880265735616161e-25"  ixz="7.4872837915258437739e-25" iyy="2.6977766073778931429e-07" iyz="-1.055689139110644559e-24" izz="1.6008784263561083015e-07" />
</inertial>
</link>

<link name="closedloop8_B_6D">
<inertial>
<origin xyz="0 0 0" rpy="0 0 0" />
<mass value="1e-9" />
<inertia ixx="0" ixy="0" ixz="0" iyy="0" iyz="0" izz="0" />
</inertial>
</link>
<joint name="closedloop8_B_6D_frame" type="fixed">
<origin xyz="-5.5511151231257827021e-17 -1.1275702593849246114e-17 -0.021999999999999950151" rpy="1.0351578883266661055e-15 -3.0410359695203482574e-16 1.5707963267948981123" />
<parent link="piston_17" />
<child link="closedloop8_B_6D" />
<axis xyz="0 0 0"/>
</joint>

<joint name="spherical_motor_knee_holder" type="revolute">
<origin xyz="-0.013750000000000071193 0.0024999999999999744649 -0.072000000000000008438" rpy="-1.57079632679489678 -0.99860729712135265501 -1.5707963267949038855" />
<parent link="part_1" />
<child link="piston_17" />
<axis xyz="0 0 1"/>
<limit effort="1" velocity="20" />
<joint_properties friction="0.0"/>
</joint>

<link name="motteur_rotation_5">
<visual>
<origin xyz="0.03300000000000002931 0.88825000000000031708 -0.1044999999999990381" rpy="1.570796326794896558 1.5707963267948930053 0" />
<geometry>
<mesh filename="package:///motteur_rotation.stl"/>
</geometry>
<material name="motteur_rotation_material">
<color rgba="1 0 0 1.0"/>
</material>
</visual>
<collision>
<origin xyz="0.03300000000000002931 0.88825000000000031708 -0.1044999999999990381" rpy="1.570796326794896558 1.5707963267948930053 0" />
<geometry>
<mesh filename="package:///motteur_rotation.stl"/>
</geometry>
</collision>
<inertial>
<origin xyz="-4.9986630486429854462e-17 1.1102230246251565404e-16 -0.017243243243243264184" rpy="0 0 0"/>
<mass value="0.19339251676417062997" />
<inertia ixx="4.9207470246053547824e-05" ixy="3.9318944872351139478e-21"  ixz="-1.0936715236718809562e-21" iyy="4.9207470246053547824e-05" iyz="-5.5043641735253037534e-20" izz="3.3697502678236634173e-05" />
</inertial>
</link>

<link name="piston_18">
<visual>
<origin xyz="-0.10179556944408768571 -0.15392457132099857109 0.83599999999999985434" rpy="-3.141592653589793116 -7.9346047379956861019e-18 1.517274423331973466e-18" />
<geometry>
<mesh filename="package:///piston.stl"/>
</geometry>
<material name="piston_material">
<color rgba="0.91764705882352937127 0.91764705882352937127 0.91764705882352937127 1.0"/>
</material>
</visual>
<collision>
<origin xyz="-0.10179556944408768571 -0.15392457132099857109 0.83599999999999985434" rpy="-3.141592653589793116 -7.9346047379956861019e-18 1.517274423331973466e-18" />
<geometry>
<mesh filename="package:///piston.stl"/>
</geometry>
</collision>
<inertial>
<origin xyz="0 -9.1618369725617014903e-17 -0.010999999999999898748" rpy="0 0 0"/>
<mass value="0.0047041422996690132607" />
<inertia ixx="2.6977766073778931429e-07" ixy="3.4549937314385076942e-23"  ixz="-1.4615327738838856784e-24" iyy="2.6977766073778920841e-07" iyz="8.3394248030861432757e-24" izz="1.6008784263561077721e-07" />
</inertial>
</link>

<link name="closedloop1_A_3D">
<inertial>
<origin xyz="0 0 0" rpy="0 0 0" />
<mass value="1e-9" />
<inertia ixx="0" ixy="0" ixz="0" iyy="0" iyz="0" izz="0" />
</inertial>
</link>
<joint name="closedloop1_A_3D_frame" type="fixed">
<origin xyz="0 -2.7755575615628913511e-17 -0.021999999999999964029" rpy="-3.5858412855701039305e-15 1.2795475548061141038e-14 1.9564349175002147908e-16" />
<parent link="piston_18" />
<child link="closedloop1_A_3D" />
<axis xyz="0 0 0"/>
</joint>

<joint name="motor_ankle2" type="prismatic">
<origin xyz="1.1102230246251565404e-16 2.2204460492503130808e-16 0.046304810707238769352" rpy="3.1415926535897926719 1.8282399324537366167e-14 3.1415926535897797933" />
<parent link="motteur_rotation_5" />
<child link="piston_18" />
<axis xyz="0 0 1"/>
<limit effort="1" velocity="20" />
<joint_properties friction="0.0"/>
</joint>

<joint name="frame_motor_ankle1" type="revolute">
<origin xyz="0.054086706326755218388 0.014047405294960790823 -0.11824999999999985523" rpy="-1.57079632679489678 0.73498046737729960665 0.2858933777993256653" />
<parent link="part_1" />
<child link="motteur_rotation_5" />
<axis xyz="0 0 1"/>
<limit effort="1" velocity="20" />
<joint_properties friction="0.0"/>
</joint>

<link name="motteur_rotation_6">
<visual>
<origin xyz="0.033000000000000057065 0.88825000000000031708 -0.10449999999999906586" rpy="1.570796326794896558 1.5707963267948930053 0" />
<geometry>
<mesh filename="package:///motteur_rotation.stl"/>
</geometry>
<material name="motteur_rotation_material">
<color rgba="1 0 0 1.0"/>
</material>
</visual>
<collision>
<origin xyz="0.033000000000000057065 0.88825000000000031708 -0.10449999999999906586" rpy="1.570796326794896558 1.5707963267948930053 0" />
<geometry>
<mesh filename="package:///motteur_rotation.stl"/>
</geometry>
</collision>
<inertial>
<origin xyz="2.2925990425498893328e-18 1.1102230246251565404e-16 -0.017243243243243236429" rpy="0 0 0"/>
<mass value="0.19339251676417062997" />
<inertia ixx="4.9207470246053547824e-05" ixy="-2.4080771811549658171e-22"  ixz="1.0298187946837699065e-21" iyy="4.9207470246053547824e-05" iyz="-5.6984479984356652939e-20" izz="3.3697502678236647725e-05" />
</inertial>
</link>

<link name="piston_19">
<visual>
<origin xyz="-0.10179556944408769958 -0.15392457132099851558 0.83599999999999996536" rpy="3.141592653589793116 -2.3417559196315516664e-18 -4.3267186075245997708e-17" />
<geometry>
<mesh filename="package:///piston.stl"/>
</geometry>
<material name="piston_material">
<color rgba="0.91764705882352937127 0.91764705882352937127 0.91764705882352937127 1.0"/>
</material>
</visual>
<collision>
<origin xyz="-0.10179556944408769958 -0.15392457132099851558 0.83599999999999996536" rpy="3.141592653589793116 -2.3417559196315516664e-18 -4.3267186075245997708e-17" />
<geometry>
<mesh filename="package:///piston.stl"/>
</geometry>
</collision>
<inertial>
<origin xyz="-1.3877787807814456755e-17 -5.6601038139654063862e-18 -0.010999999999999898748" rpy="0 0 0"/>
<mass value="0.0047041422996690132607" />
<inertia ixx="2.6977766073778920841e-07" ixy="-1.6667627043483837658e-23"  ixz="-7.4617032571654549608e-24" iyy="2.6977766073778931429e-07" iyz="1.7285107941375799765e-25" izz="1.6008784263561083015e-07" />
</inertial>
</link>

<link name="closedloop2_A_3D">
<inertial>
<origin xyz="0 0 0" rpy="0 0 0" />
<mass value="1e-9" />
<inertia ixx="0" ixy="0" ixz="0" iyy="0" iyz="0" izz="0" />
</inertial>
</link>
<joint name="closedloop2_A_3D_frame" type="fixed">
<origin xyz="0 -2.7755575615628913511e-17 -0.021999999999999880762" rpy="-1.0697317727682620177e-15 -1.8801810800543854443e-17 -3.3869376106552871114e-17" />
<parent link="piston_19" />
<child link="closedloop2_A_3D" />
<axis xyz="0 0 0"/>
</joint>

<joint name="motor_ankle1" type="prismatic">
<origin xyz="0 0 0.043564478507036985544" rpy="3.1415926535897891192 2.6153764022898610303e-15 3.1415926535897926719" />
<parent link="motteur_rotation_6" />
<child link="piston_19" />
<axis xyz="0 0 1"/>
<limit effort="1" velocity="20" />
<joint_properties friction="0.0"/>
</joint>

<joint name="frame_motor_ankle2" type="revolute">
<origin xyz="0.054086706326755190632 0.014047405294960846334 -0.024750000000000133005" rpy="1.5707963267948925612 -0.17956569756705717533 -2.855699275790474001" />
<parent link="part_1" />
<child link="motteur_rotation_6" />
<axis xyz="0 0 1"/>
<limit effort="1" velocity="20" />
<joint_properties friction="0.0"/>
</joint>

<joint name="lower_hip" type="revolute">
<origin xyz="6.6000000000038250292e-05 0 -6.6000000000003555822e-05" rpy="1.5707963267949520692 -1.5388859775012673214 1.5707963267948683583" />
<parent link="cardan_foot_3" />
<child link="part_1" />
<axis xyz="0 0 1"/>
<limit effort="1" velocity="20" />
<joint_properties friction="0.0"/>
</joint>

<joint name="free_universal_yhip" type="revolute">
<origin xyz="0 -2.7755575615628913511e-17 -0.16500000000000009104" rpy="1.570796326794896558 -1.0038838022974944486e-17 -1.5707963267948992225" />
<parent link="hanche" />
<child link="cardan_foot_3" />
<axis xyz="0 0 1"/>
<limit effort="1" velocity="20" />
<joint_properties friction="0.0"/>
</joint>

<link name="cardan_hache_3">
<visual>
<origin xyz="0.10862499999999999933 0.85800000000000009592 -0.0055000000000023745172" rpy="1.570796326794896558 1.5707963267948930053 0" />
<geometry>
<mesh filename="package:///cardan_hache.stl"/>
</geometry>
<material name="cardan_hache_material">
<color rgba="0.49803921568627451677 0.49803921568627451677 0.49803921568627451677 1.0"/>
</material>
</visual>
<collision>
<origin xyz="0.10862499999999999933 0.85800000000000009592 -0.0055000000000023745172" rpy="1.570796326794896558 1.5707963267948930053 0" />
<geometry>
<mesh filename="package:///cardan_hache.stl"/>
</geometry>
</collision>
<inertial>
<origin xyz="-1.5153844576352840195e-17 1.5061396574367336143e-11 -0.034629677480538460788" rpy="0 0 0"/>
<mass value="0.015608633111865791165" />
<inertia ixx="5.7160316393851747746e-06" ixy="-1.9710864476891236432e-13"  ixz="7.2356232706140455517e-28" iyy="5.8966955959438776354e-06" iyz="9.5685519510128528437e-14" izz="7.2203526828754625758e-07" />
</inertial>
</link>

<link name="moteur_hanche1_3">
<visual>
<origin xyz="-0.049500000000000793365 -0.85800000000000009592 -0.10862499999999999933" rpy="-1.570796326794896558 -3.9543138271365519281e-20 1.3836858464257643144e-18" />
<geometry>
<mesh filename="package:///moteur_hanche1.stl"/>
</geometry>
<material name="moteur_hanche1_material">
<color rgba="1 0 0 1.0"/>
</material>
</visual>
<collision>
<origin xyz="-0.049500000000000793365 -0.85800000000000009592 -0.10862499999999999933" rpy="-1.570796326794896558 -3.9543138271365519281e-20 1.3836858464257643144e-18" />
<geometry>
<mesh filename="package:///moteur_hanche1.stl"/>
</geometry>
</collision>
<inertial>
<origin xyz="-1.3877787807814456755e-17 -0.012713533519812081352 -2.4370118223469330664e-18" rpy="0 0 0"/>
<mass value="0.17794962537636810351" />
<inertia ixx="3.4377373668620134326e-05" ixy="2.4427088803503671332e-22"  ixz="1.2446868040231682097e-23" iyy="4.1215284105260629674e-05" iyz="3.4696993109316621124e-23" izz="3.4002456645612650764e-05" />
</inertial>
</link>

<link name="piston_20">
<visual>
<origin xyz="-0.10179556944408765795 0.15392457132099851558 -0.8579999999999999849" rpy="-8.1514455777738857651e-19 -8.1917267957983919617e-18 -1.3831805124968450131e-19" />
<geometry>
<mesh filename="package:///piston.stl"/>
</geometry>
<material name="piston_material">
<color rgba="0.91764705882352937127 0.91764705882352937127 0.91764705882352937127 1.0"/>
</material>
</visual>
<collision>
<origin xyz="-0.10179556944408765795 0.15392457132099851558 -0.8579999999999999849" rpy="-8.1514455777738857651e-19 -8.1917267957983919617e-18 -1.3831805124968450131e-19" />
<geometry>
<mesh filename="package:///piston.stl"/>
</geometry>
</collision>
<inertial>
<origin xyz="-1.3877787807814456755e-17 -1.7934550433537405215e-18 -0.011000000000000120792" rpy="0 0 0"/>
<mass value="0.0047041422996690132607" />
<inertia ixx="2.6977766073778920841e-07" ixy="-7.7260649950774976753e-26"  ixz="1.8103267262565355395e-24" iyy="2.6977766073778931429e-07" iyz="-5.5621981740194561247e-25" izz="1.6008784263561083015e-07" />
</inertial>
</link>

<link name="closedloop4_B_6D">
<inertial>
<origin xyz="0 0 0" rpy="0 0 0" />
<mass value="1e-9" />
<inertia ixx="0" ixy="0" ixz="0" iyy="0" iyz="0" izz="0" />
</inertial>
</link>
<joint name="closedloop4_B_6D_frame" type="fixed">
<origin xyz="0 -2.7755575615628913511e-17 -0.022000000000000172196" rpy="-6.0488890030723583321e-14 2.4688424028795064476e-15 -1.0953694299338978907e-18" />
<parent link="piston_20" />
<child link="closedloop4_B_6D" />
<axis xyz="0 0 0"/>
</joint>

<joint name="motor_hip_xy_2" type="prismatic">
<origin xyz="-5.5511151231257827021e-17 -0.046244712027414175415 -4.1633363423443370266e-16" rpy="-1.5707963267949494046 -7.6308472951699595211e-15 7.1448122585686606186e-15" />
<parent link="moteur_hanche1_3" />
<child link="piston_20" />
<axis xyz="0 0 1"/>
<limit effort="1" velocity="20" />
<joint_properties friction="0.0"/>
</joint>

<joint name="free_motor_holder_hipxy2" type="revolute">
<origin xyz="2.7755575615628913511e-17 -5.5511151231257827021e-17 -0.055000000000000000278" rpy="-1.570796326794876796 -1.4788959325009420898 1.5707963267948323871" />
<parent link="cardan_hache_3" />
<child link="moteur_hanche1_3" />
<axis xyz="0 0 1"/>
<limit effort="1" velocity="20" />
<joint_properties friction="0.0"/>
</joint>

<joint name="free_motor_holder_1" type="revolute">
<origin xyz="0.01249999999999999202 -0.037124999999999713785 -0.077000000000000151656" rpy="1.57079632679489678 -0.021206259450691003487 -1.5707963267948974462" />
<parent link="hanche" />
<child link="cardan_hache_3" />
<axis xyz="0 0 1"/>
<limit effort="1" velocity="20" />
<joint_properties friction="0.0"/>
</joint>

<link name="cardan_hache_4">
<visual>
<origin xyz="0.10862499999999994382 0.8579999999999999849 -0.0055000000000023745172" rpy="1.570796326794896558 1.5707963267948930053 0" />
<geometry>
<mesh filename="package:///cardan_hache.stl"/>
</geometry>
<material name="cardan_hache_material">
<color rgba="0.49803921568627451677 0.49803921568627451677 0.49803921568627451677 1.0"/>
</material>
</visual>
<collision>
<origin xyz="0.10862499999999994382 0.8579999999999999849 -0.0055000000000023745172" rpy="1.570796326794896558 1.5707963267948930053 0" />
<geometry>
<mesh filename="package:///cardan_hache.stl"/>
</geometry>
</collision>
<inertial>
<origin xyz="-7.2217033010359303978e-17 1.5061285552064873627e-11 -0.034629677480538460788" rpy="0 0 0"/>
<mass value="0.015608633111865791165" />
<inertia ixx="5.7160316393851747746e-06" ixy="-1.9710864477400901161e-13"  ixz="7.2373541307153673356e-28" iyy="5.8966955959438776354e-06" iyz="9.5685519510128528437e-14" izz="7.2203526828754625758e-07" />
</inertial>
</link>

<link name="moteur_hanche1_4">
<visual>
<origin xyz="-0.049500000000000779488 -0.85800000000000009592 -0.10862499999999997158" rpy="-1.570796326794896558 2.0397578087888765832e-19 -7.8852976280139052422e-18" />
<geometry>
<mesh filename="package:///moteur_hanche1.stl"/>
</geometry>
<material name="moteur_hanche1_material">
<color rgba="1 0 0 1.0"/>
</material>
</visual>
<collision>
<origin xyz="-0.049500000000000779488 -0.85800000000000009592 -0.10862499999999997158" rpy="-1.570796326794896558 2.0397578087888765832e-19 -7.8852976280139052422e-18" />
<geometry>
<mesh filename="package:///moteur_hanche1.stl"/>
</geometry>
</collision>
<inertial>
<origin xyz="-2.0816681711721682051e-17 -0.012713533519811859307 2.7807524060969053294e-17" rpy="0 0 0"/>
<mass value="0.17794962537636810351" />
<inertia ixx="3.4377373668620134326e-05" ixy="-1.1073222002978431692e-21"  ixz="-7.4427034466965006461e-24" iyy="4.1215284105260643227e-05" iyz="-1.6598431860595398636e-25" izz="3.4002456645612650764e-05" />
</inertial>
</link>

<link name="piston_21">
<visual>
<origin xyz="-0.10179556944408768571 0.15392457132099848782 -0.8579999999999999849" rpy="2.5267906524140809338e-20 8.8342825616723868772e-18 -4.0225207628029488833e-19" />
<geometry>
<mesh filename="package:///piston.stl"/>
</geometry>
<material name="piston_material">
<color rgba="0.91764705882352937127 0.91764705882352937127 0.91764705882352937127 1.0"/>
</material>
</visual>
<collision>
<origin xyz="-0.10179556944408768571 0.15392457132099848782 -0.8579999999999999849" rpy="2.5267906524140809338e-20 8.8342825616723868772e-18 -4.0225207628029488833e-19" />
<geometry>
<mesh filename="package:///piston.stl"/>
</geometry>
</collision>
<inertial>
<origin xyz="-1.3877787807814456755e-17 -2.4345874302594547413e-17 -0.011000000000000120792" rpy="0 0 0"/>
<mass value="0.0047041422996690132607" />
<inertia ixx="2.6977766073778931429e-07" ixy="-1.4164044286329015503e-25"  ixz="5.4323348093474822544e-25" iyy="2.6977766073778931429e-07" iyz="6.5900906716999446211e-25" izz="1.6008784263561083015e-07" />
</inertial>
</link>

<link name="closedloop3_B_6D">
<inertial>
<origin xyz="0 0 0" rpy="0 0 0" />
<mass value="1e-9" />
<inertia ixx="0" ixy="0" ixz="0" iyy="0" iyz="0" izz="0" />
</inertial>
</link>
<joint name="closedloop3_B_6D_frame" type="fixed">
<origin xyz="0 2.7755575615628913511e-17 -0.022000000000000047296" rpy="-3.8418763942784059345e-15 1.8594444041235966788e-16 1.1399726909584655164e-17" />
<parent link="piston_21" />
<child link="closedloop3_B_6D" />
<axis xyz="0 0 0"/>
</joint>

<joint name="motor_hip_xy_1" type="prismatic">
<origin xyz="0 -0.046242052428871111003 5.5511151231257827021e-17" rpy="-1.5707963267948996666 2.6244546298293282002e-15 1.7228045307915577077e-15" />
<parent link="moteur_hanche1_4" />
<child link="piston_21" />
<axis xyz="0 0 1"/>
<limit effort="1" velocity="20" />
<joint_properties friction="0.0"/>
</joint>

<joint name="free_motor_holder_hipxy1" type="revolute">
<origin xyz="-5.5511151231257827021e-17 5.5511151231257827021e-17 -0.055000000000000007216" rpy="-1.5707963267948976682 1.4788923407475595972 1.5707963267949134334" />
<parent link="cardan_hache_4" />
<child link="moteur_hanche1_4" />
<axis xyz="0 0 1"/>
<limit effort="1" velocity="20" />
<joint_properties friction="0.0"/>
</joint>

<joint name="free_motor_holder_3" type="revolute">
<origin xyz="0.01249999999999999549 0.03712499999999999134 -0.07699999999999981859" rpy="-1.570796326794896558 -0.019264206118359661346 1.5707963267948950037" />
<parent link="hanche" />
<child link="cardan_hache_4" />
<axis xyz="0 0 1"/>
<limit effort="1" velocity="20" />
<joint_properties friction="0.0"/>
</joint>

<link name="piston_22">
<visual>
<origin xyz="-0.10179556944408765795 0.15392457132099851558 -0.85800000000000009592" rpy="3.219160792380629143e-31 2.4168483622926910372e-32 1.2679065777781923061e-18" />
<geometry>
<mesh filename="package:///piston.stl"/>
</geometry>
<material name="piston_material">
<color rgba="0.91764705882352937127 0.91764705882352937127 0.91764705882352937127 1.0"/>
</material>
</visual>
<collision>
<origin xyz="-0.10179556944408765795 0.15392457132099851558 -0.85800000000000009592" rpy="3.219160792380629143e-31 2.4168483622926910372e-32 1.2679065777781923061e-18" />
<geometry>
<mesh filename="package:///piston.stl"/>
</geometry>
</collision>
<inertial>
<origin xyz="0 1.290672720867797563e-19 -0.011000000000000231815" rpy="0 0 0"/>
<mass value="0.0047041422996690132607" />
<inertia ixx="2.6977766073778931429e-07" ixy="8.6147331510139461319e-26"  ixz="-5.5878340125063292427e-39" iyy="2.6977766073778931429e-07" iyz="7.6305446136664883448e-38" izz="1.6008784263561083015e-07" />
</inertial>
</link>

<link name="closedloop5_B_6D">
<inertial>
<origin xyz="0 0 0" rpy="0 0 0" />
<mass value="1e-9" />
<inertia ixx="0" ixy="0" ixz="0" iyy="0" iyz="0" izz="0" />
</inertial>
</link>
<joint name="closedloop5_B_6D_frame" type="fixed">
<origin xyz="0 -2.7755575615628913511e-17 -0.022000000000000231176" rpy="3.1415926535897917837 9.3675067702747509143e-17 -1.570796326794896558" />
<parent link="piston_22" />
<child link="closedloop5_B_6D" />
<axis xyz="0 0 0"/>
</joint>

<joint name="free_spherical_motor_holder_hipz" type="revolute">
<origin xyz="3.380976054678797027e-15 0.038499999999999978684 -0.046750000000000131728" rpy="1.570796326794896558 0.051824161433119159126 1.5707963267948945596" />
<parent link="hanche" />
<child link="piston_22" />
<axis xyz="0 0 1"/>
<limit effort="1" velocity="20" />
<joint_properties friction="0.0"/>
</joint>

<joint name="free_zhip" type="revolute">
<origin xyz="0.012499999999999891406 -0.029749999999999887645 -0.20500000000000001554" rpy="-1.570796326794896558 2.6592413774926255711e-28 -3.5042375413817778047e-15" />
<parent link="hanche_batis" />
<child link="hanche" />
<axis xyz="0 0 1"/>
<limit effort="1" velocity="20" />
<joint_properties friction="0.0"/>
</joint>

<link name="attache_hanche">
<visual>
<origin xyz="0.12099999999999908051 0.033000000000000057065 -0.94000000000000016875" rpy="-3.3073821090691880549e-31 -3.6701587590914506434e-15 5.0518048865126687647e-32" />
<geometry>
<mesh filename="package:///attache_hanche.stl"/>
</geometry>
<material name="attache_hanche_material">
<color rgba="0.64705882352941179736 0.64705882352941179736 0.64705882352941179736 1.0"/>
</material>
</visual>
<collision>
<origin xyz="0.12099999999999908051 0.033000000000000057065 -0.94000000000000016875" rpy="-3.3073821090691880549e-31 -3.6701587590914506434e-15 5.0518048865126687647e-32" />
<geometry>
<mesh filename="package:///attache_hanche.stl"/>
</geometry>
</collision>
<inertial>
<origin xyz="0 1.3877787807814752578e-17 -0.030000000000000137668" rpy="0 0 0"/>
<mass value="0.01282947899909727546" />
<inertia ixx="4.0671453033231804464e-06" ixy="-9.2974170372714098574e-37"  ixz="1.3324665874380659771e-20" iyy="4.0671453033231812934e-06" iyz="-1.2007589974979871814e-36" izz="4.366032071880294742e-07" />
</inertial>
</link>

<link name="motteur_rotation_7">
<visual>
<origin xyz="0.03300000000000002931 0.88825000000000020606 -0.12099999999999909439" rpy="1.570796326794896558 1.5707963267948930053 0" />
<geometry>
<mesh filename="package:///motteur_rotation.stl"/>
</geometry>
<material name="motteur_rotation_material">
<color rgba="1 0 0 1.0"/>
</material>
</visual>
<collision>
<origin xyz="0.03300000000000002931 0.88825000000000020606 -0.12099999999999909439" rpy="1.570796326794896558 1.5707963267948930053 0" />
<geometry>
<mesh filename="package:///motteur_rotation.stl"/>
</geometry>
</collision>
<inertial>
<origin xyz="5.2975305764322102796e-18 1.1102230246251565404e-16 -0.033743243243243264962" rpy="0 0 0"/>
<mass value="0.19339251676417062997" />
<inertia ixx="4.9207470246053534272e-05" ixy="3.0764228076376224167e-22"  ixz="4.3939917142234536934e-35" iyy="4.9207470246053534272e-05" iyz="-5.6924043322247487608e-20" izz="3.3697502678236647725e-05" />
</inertial>
</link>

<link name="piston_23">
<visual>
<origin xyz="-0.10179556944408765795 0.15392457132099848782 -0.8579999999999999849" rpy="-3.5490847159330501048e-32 -4.8184575018741910252e-32 -6.6237143403040363235e-18" />
<geometry>
<mesh filename="package:///piston.stl"/>
</geometry>
<material name="piston_material">
<color rgba="0.91764705882352937127 0.91764705882352937127 0.91764705882352937127 1.0"/>
</material>
</visual>
<collision>
<origin xyz="-0.10179556944408765795 0.15392457132099848782 -0.8579999999999999849" rpy="-3.5490847159330501048e-32 -4.8184575018741910252e-32 -6.6237143403040363235e-18" />
<geometry>
<mesh filename="package:///piston.stl"/>
</geometry>
</collision>
<inertial>
<origin xyz="0 -2.8429840388735195827e-17 -0.011000000000000120792" rpy="0 0 0"/>
<mass value="0.0047041422996690132607" />
<inertia ixx="2.6977766073778931429e-07" ixy="-3.3769722911324953202e-25"  ixz="-5.479019217363189393e-39" iyy="2.6977766073778931429e-07" iyz="-2.1978402404151833443e-38" izz="1.6008784263561083015e-07" />
</inertial>
</link>

<link name="closedloop5_A_6D">
<inertial>
<origin xyz="0 0 0" rpy="0 0 0" />
<mass value="1e-9" />
<inertia ixx="0" ixy="0" ixz="0" iyy="0" iyz="0" izz="0" />
</inertial>
</link>
<joint name="closedloop5_A_6D_frame" type="fixed">
<origin xyz="0 0 -0.021999999999999929334" rpy="4.093947403305292846e-16 2.1380466841413412812e-16 4.0514340995891024666e-16" />
<parent link="piston_23" />
<child link="closedloop5_A_6D" />
<axis xyz="0 0 0"/>
</joint>

<joint name="motor_hipz" type="prismatic">
<origin xyz="-2.498001805406602216e-16 -1.8388068845354155201e-16 -0.071499999999999813705" rpy="-3.459434076669788135e-15 1.2825791172804655208e-15 -1.5707963267949132113" />
<parent link="motteur_rotation_7" />
<child link="piston_23" />
<axis xyz="0 0 1"/>
<limit effort="1" velocity="20" />
<joint_properties friction="0.0"/>
</joint>

<joint name="free_spherical_motor_holder_1" type="revolute">
<origin xyz="-1.3877787807814456755e-17 0 -0.051749999999999886369" rpy="1.570796326794896558 -0.094549574280562209694 1.5707963267948930053" />
<parent link="attache_hanche" />
<child link="motteur_rotation_7" />
<axis xyz="0 0 1"/>
<limit effort="1" velocity="20" />
<joint_properties friction="0.0"/>
</joint>

<joint name="free_motor_holder_2" type="revolute">
<origin xyz="-0.10299999999999680245 -0.024749999999999584832 -0.24349999999999993872" rpy="1.570796326794896558 4.4226638947527427442e-16 3.1415926535897895633" />
<parent link="hanche_batis" />
<child link="attache_hanche" />
<axis xyz="0 0 1"/>
<limit effort="1" velocity="20" />
<joint_properties friction="0.0"/>
</joint>

<joint name="test" type="fixed">
<origin xyz="-1.7347234759768070944e-17 5.5511151231257827021e-17 0.024750000000000049738" rpy="1.570796326794896558 -4.5021244384580876102e-15 -8.9782231775462504888e-29" />
<parent link="hanche_batis_gauche" />
<child link="hanche_batis" />
<axis xyz="0 0 1"/>
<limit effort="1" velocity="20" />
<joint_properties friction="0.0"/>
</joint>

<link name="attache_hanche_2">
<visual>
<origin xyz="0.12099999999999905276 0.033000000000000036249 -0.94000000000000027978" rpy="-3.3032027445473105087e-31 -3.6701587590914514323e-15 -5.9383014041950064178e-20" />
<geometry>
<mesh filename="package:///attache_hanche.stl"/>
</geometry>
<material name="attache_hanche_material">
<color rgba="0.64705882352941179736 0.64705882352941179736 0.64705882352941179736 1.0"/>
</material>
</visual>
<collision>
<origin xyz="0.12099999999999905276 0.033000000000000036249 -0.94000000000000027978" rpy="-3.3032027445473105087e-31 -3.6701587590914514323e-15 -5.9383014041950064178e-20" />
<geometry>
<mesh filename="package:///attache_hanche.stl"/>
</geometry>
</collision>
<inertial>
<origin xyz="-1.3877787807814456755e-17 7.185344699375529548e-21 -0.03000000000000024869" rpy="0 0 0"/>
<mass value="0.01282947899909727546" />
<inertia ixx="4.0671453033231787523e-06" ixy="1.343993050242305916e-24"  ixz="1.3324665874380656762e-20" iyy="4.0671453033231795993e-06" iyz="-1.200494724996204359e-36" izz="4.366032071880294742e-07" />
</inertial>
</link>

<link name="motteur_rotation_8">
<visual>
<origin xyz="0.03300000000000002931 0.88825000000000020606 -0.12099999999999908051" rpy="1.570796326794896558 1.5707963267948930053 0" />
<geometry>
<mesh filename="package:///motteur_rotation.stl"/>
</geometry>
<material name="motteur_rotation_material">
<color rgba="1 0 0 1.0"/>
</material>
</visual>
<collision>
<origin xyz="0.03300000000000002931 0.88825000000000020606 -0.12099999999999908051" rpy="1.570796326794896558 1.5707963267948930053 0" />
<geometry>
<mesh filename="package:///motteur_rotation.stl"/>
</geometry>
</collision>
<inertial>
<origin xyz="-1.5195915013502203115e-17 1.1102230246251565404e-16 -0.033743243243243251084" rpy="0 0 0"/>
<mass value="0.19339251676417062997" />
<inertia ixx="4.9207470246053520719e-05" ixy="1.3802228924226059079e-21"  ixz="-2.7297502089349609052e-23" iyy="4.9207470246053534272e-05" iyz="-5.6918658405189181675e-20" izz="3.3697502678236647725e-05" />
</inertial>
</link>

<link name="piston_24">
<visual>
<origin xyz="-0.10179556944408768571 0.15392457132099851558 -0.8579999999999999849" rpy="4.7834849311353482513e-19 -4.4870542662247000627e-20 -4.1625346221495168371e-18" />
<geometry>
<mesh filename="package:///piston.stl"/>
</geometry>
<material name="piston_material">
<color rgba="0.91764705882352937127 0.91764705882352937127 0.91764705882352937127 1.0"/>
</material>
</visual>
<collision>
<origin xyz="-0.10179556944408768571 0.15392457132099851558 -0.8579999999999999849" rpy="4.7834849311353482513e-19 -4.4870542662247000627e-20 -4.1625346221495168371e-18" />
<geometry>
<mesh filename="package:///piston.stl"/>
</geometry>
</collision>
<inertial>
<origin xyz="-2.7755575615628913511e-17 -4.1929533611031519333e-19 -0.011000000000000120792" rpy="0 0 0"/>
<mass value="0.0047041422996690132607" />
<inertia ixx="2.6977766073778931429e-07" ixy="-2.7123491066793085197e-25"  ixz="2.3779054245432008255e-26" iyy="2.6977766073778931429e-07" iyz="1.298854573400498705e-25" izz="1.6008784263561083015e-07" />
</inertial>
</link>

<link name="closedloop19_A_6D">
<inertial>
<origin xyz="0 0 0" rpy="0 0 0" />
<mass value="1e-9" />
<inertia ixx="0" ixy="0" ixz="0" iyy="0" iyz="0" izz="0" />
</inertial>
</link>
<joint name="closedloop19_A_6D_frame" type="fixed">
<origin xyz="0 1.3877787807814456755e-17 -0.022000000000000071582" rpy="-9.4224279476490090478e-16 4.313236932270966082e-15 -1.570796326794896558" />
<parent link="piston_24" />
<child link="closedloop19_A_6D" />
<axis xyz="0 0 0"/>
</joint>

<joint name="motor_hip_z_left" type="prismatic">
<origin xyz="-1.4398204850607498884e-16 1.5265566588595902431e-16 -0.070937073864986155414" rpy="-2.3897270858110496043e-15 -1.556724709680402787e-16 -1.5707963267948730213" />
<parent link="motteur_rotation_8" />
<child link="piston_24" />
<axis xyz="0 0 1"/>
<limit effort="1" velocity="20" />
<joint_properties friction="0.0"/>
</joint>

<joint name="spherical_motor_holder_hip_z_left" type="revolute">
<origin xyz="-1.3877787807814456755e-17 2.7755575615628913511e-17 -0.051749999999999934941" rpy="1.5707963267948961139 -0.14866879169792945881 1.5707963267948972241" />
<parent link="attache_hanche_2" />
<child link="motteur_rotation_8" />
<axis xyz="0 0 1"/>
<limit effort="1" velocity="20" />
<joint_properties friction="0.0"/>
</joint>

<joint name="free_universal_motor_holder_hipz_left" type="revolute">
<origin xyz="-0.10299999999999671918 0.0065000000000000057732 -1.1102230246251565404e-16" rpy="8.2923786594574648618e-18 8.3515882679392369696e-16 -3.1380685543604354137" />
<parent link="hanche_batis_gauche" />
<child link="attache_hanche_2" />
<axis xyz="0 0 1"/>
<limit effort="1" velocity="20" />
<joint_properties friction="0.0"/>
</joint>


</robot>
