<robot name="onshape">
<link name="part_1">
<visual>
<origin xyz="0.025000000000000004857 9.3436487521972863471e-18 1.5530399871765379534e-18" rpy="3.141592653589793116 -0 -1.570796326794896558" />
<geometry>
<mesh filename="package:///part_1.stl"/>
</geometry>
<material name="part_1_material">
<color rgba="0.61568627450980395466 0.81176470588235294379 0.92941176470588238168 1.0"/>
</material>
</visual>
<collision>
<origin xyz="0.025000000000000004857 9.3436487521972863471e-18 1.5530399871765379534e-18" rpy="3.141592653589793116 -0 -1.570796326794896558" />
<geometry>
<mesh filename="package:///part_1.stl"/>
</geometry>
<material name="part_1_material">
<color rgba="0.61568627450980395466 0.81176470588235294379 0.92941176470588238168 1.0"/>
</material>
</collision>
<inertial>
<origin xyz="0.012500000000000004163 3.7305382795809911412e-17 -1.0548186435455824715e-18" rpy="0 0 0"/>
<mass value="2.2946626147876587609" />
<inertia ixx="0.029409277005752607753" ixy="0"  ixz="-1.7943075814930523626e-19" iyy="0.003169354014368664773" iyz="0" izz="0.026478950347090992462" />
</inertial>
</link>

<link name="centre_hanche">
<inertial>
<origin xyz="0 0 0" rpy="0 0 0" />
<mass value="1e-9" />
<inertia ixx="0" ixy="0" ixz="0" iyy="0" iyz="0" izz="0" />
</inertial>
</link>
<joint name="centre_hanche_frame" type="fixed">
<origin xyz="0.087499999999999994449 6.4691807936984159579e-18 -0.059999999999999990841" rpy="-3.7007434154171896185e-16 6.1232339957367660359e-17 1.0947644252537633367e-47" />
<parent link="part_1" />
<child link="centre_hanche" />
<axis xyz="0 0 0"/>
</joint>

<link name="part_2">
<visual>
<origin xyz="0.14999999999999999445 -5.42101086242752217e-17 0" rpy="1.570796326794896558 -8.3672886306133263501e-35 8.6518790804725472091e-19" />
<geometry>
<mesh filename="package:///part_2.stl"/>
</geometry>
<material name="part_2_material">
<color rgba="0.64705882352941179736 0.64705882352941179736 0.64705882352941179736 1.0"/>
</material>
</visual>
<collision>
<origin xyz="0.14999999999999999445 -5.42101086242752217e-17 0" rpy="1.570796326794896558 -8.3672886306133263501e-35 8.6518790804725472091e-19" />
<geometry>
<mesh filename="package:///part_2.stl"/>
</geometry>
<material name="part_2_material">
<color rgba="0.64705882352941179736 0.64705882352941179736 0.64705882352941179736 1.0"/>
</material>
</collision>
<inertial>
<origin xyz="-1.9668055656341110193e-08 -0.059907069836739476609 -0.058820580957796284038" rpy="0 0 0"/>
<mass value="0.89039644551396013306" />
<inertia ixx="0.007125991411599849612" ixy="-2.0431833882573872635e-09"  ixz="-1.6994146884638425052e-09" iyy="0.0011186437057284124522" iyz="0.0011372607353434143786" izz="0.0062850904193800169462" />
</inertial>
</link>

<link name="part_4">
<visual>
<origin xyz="0.1500000000000000222 -0.087499999999999994449 0.02499999999999998751" rpy="1.570796326794896558 6.1232339957367623381e-17 -1.5665808583808863716e-18" />
<geometry>
<mesh filename="package:///part_4.stl"/>
</geometry>
<material name="part_4_material">
<color rgba="0.91764705882352937127 0.91764705882352937127 0.91764705882352937127 1.0"/>
</material>
</visual>
<collision>
<origin xyz="0.1500000000000000222 -0.087499999999999994449 0.02499999999999998751" rpy="1.570796326794896558 6.1232339957367623381e-17 -1.5665808583808863716e-18" />
<geometry>
<mesh filename="package:///part_4.stl"/>
</geometry>
<material name="part_4_material">
<color rgba="0.91764705882352937127 0.91764705882352937127 0.91764705882352937127 1.0"/>
</material>
</collision>
<inertial>
<origin xyz="0.068078690960163584789 7.8090537508623825147e-09 -0.012500018520882049192" rpy="0 0 0"/>
<mass value="0.16139278769787171464" />
<inertia ixx="1.2982580317980122654e-05" ixy="4.4490796309977062079e-11"  ixz="-1.3969239536077340642e-10" iyy="0.00036360474045782597815" iyz="-1.876251737389522889e-10" izz="0.00036339084218598279247" />
</inertial>
</link>

<link name="fermeture4_B_6D">
<inertial>
<origin xyz="0 0 0" rpy="0 0 0" />
<mass value="1e-9" />
<inertia ixx="0" ixy="0" ixz="0" iyy="0" iyz="0" izz="0" />
</inertial>
</link>
<joint name="fermeture4_B_6D_frame" type="fixed">
<origin xyz="0.14999999999999993894 0 -0.012500000000000011102" rpy="1.57079632679489678 1.9907516512049869905e-31 1.5707963267948970021" />
<parent link="part_4" />
<child link="fermeture4_B_6D" />
<axis xyz="0 0 0"/>
</joint>

<joint name="to_rotule_1" type="revolute">
<origin xyz="2.7755575615628913511e-17 0.087499999999999952816 -0.050000000000000002776" rpy="1.5337681796622941241e-16 1.6331628603689328158e-16 2.7771156075277989572" />
<parent link="part_2" />
<child link="part_4" />
<axis xyz="0 0 1"/>
<limit effort="1" velocity="20" />
<joint_properties friction="0.0"/>
</joint>

<link name="part_6">
<visual>
<origin xyz="0.03750000000000001249 0.1624999999999999778 -0.12499999999999994449" rpy="1.57079632679489678 1.570796326794896558 0" />
<geometry>
<mesh filename="package:///part_6.stl"/>
</geometry>
<material name="part_6_material">
<color rgba="0.97254901960784312376 0.52941176470588235947 0.0039215686274509803377 1.0"/>
</material>
</visual>
<collision>
<origin xyz="0.03750000000000001249 0.1624999999999999778 -0.12499999999999994449" rpy="1.57079632679489678 1.570796326794896558 0" />
<geometry>
<mesh filename="package:///part_6.stl"/>
</geometry>
<material name="part_6_material">
<color rgba="0.97254901960784312376 0.52941176470588235947 0.0039215686274509803377 1.0"/>
</material>
</collision>
<inertial>
<origin xyz="-0.035355341728539810275 -0.035355341728539796398 -0.024999999999999966693" rpy="0 0 0"/>
<mass value="0.17551650370110782884" />
<inertia ixx="0.00017174797865715228672" ixy="-0.00014130922109905220529"  ixz="-2.1413438503998459842e-10" iyy="0.00017174799171019406135" iyz="2.1413438492675277495e-10" izz="0.00029665639647466187159" />
</inertial>
</link>

<link name="part_8">
<visual>
<origin xyz="0.10821067811865472952 0.23321067811865478503 -0.049999999999999961142" rpy="1.570796326794896558 1.570796326794896558 0" />
<geometry>
<mesh filename="package:///part_8.stl"/>
</geometry>
<material name="part_8_material">
<color rgba="0.98039215686274505668 0.71372549019607844922 0.0039215686274509803377 1.0"/>
</material>
</visual>
<collision>
<origin xyz="0.10821067811865472952 0.23321067811865478503 -0.049999999999999961142" rpy="1.570796326794896558 1.570796326794896558 0" />
<geometry>
<mesh filename="package:///part_8.stl"/>
</geometry>
<material name="part_8_material">
<color rgba="0.98039215686274505668 0.71372549019607844922 0.0039215686274509803377 1.0"/>
</material>
</collision>
<inertial>
<origin xyz="-0.061855907839602090881 0.3508027333013911675 2.0947770719426106467e-08" rpy="0 0 0"/>
<mass value="0.77497596930249534886" />
<inertia ixx="0.038565136483213580121" ixy="0.0067879416145973162089"  ixz="2.5944817380769231719e-09" iyy="0.0012658045210698332626" iyz="6.3686268013930126552e-09" izz="0.039753831424396555982" />
</inertial>
</link>

<link name="fermeture1_B_3D">
<inertial>
<origin xyz="0 0 0" rpy="0 0 0" />
<mass value="1e-9" />
<inertia ixx="0" ixy="0" ixz="0" iyy="0" iyz="0" izz="0" />
</inertial>
</link>
<joint name="fermeture1_B_3D_frame" type="fixed">
<origin xyz="-0.13023613325019789411 0.7386058147591560985 0" rpy="1.570796326794896558 5.03492802678681616e-17 0.17453292519943311434" />
<parent link="part_8" />
<child link="fermeture1_B_3D" />
<axis xyz="0 0 0"/>
</joint>

<joint name="to_rotule_3" type="revolute">
<origin xyz="-0.070710678118654696211 -0.070710678118654779478 -0.025000000000000022204" rpy="9.9617606251183357107e-16 3.8198292193847984716e-16 0.39409309421094185222" />
<parent link="part_6" />
<child link="part_8" />
<axis xyz="0 0 1"/>
<limit effort="1" velocity="20" />
<joint_properties friction="0.0"/>
</joint>

<joint name="motor_3" type="revolute">
<origin xyz="0.024999999999999938938 -0.16250000000000008882 -0.037499999999999991673" rpy="1.570796326794896558 -1.2758510727997685041 -1.570796326794896558" />
<parent link="part_2" />
<child link="part_6" />
<axis xyz="0 0 1"/>
<limit effort="1" velocity="20" />
<joint_properties friction="0.0"/>
</joint>

<link name="part_6_2">
<visual>
<origin xyz="0.037500000000000005551 0.16250000000000003331 -0.125" rpy="1.570796326794896558 1.570796326794896558 0" />
<geometry>
<mesh filename="package:///part_6.stl"/>
</geometry>
<material name="part_6_material">
<color rgba="0.97254901960784312376 0.52941176470588235947 0.0039215686274509803377 1.0"/>
</material>
</visual>
<collision>
<origin xyz="0.037500000000000005551 0.16250000000000003331 -0.125" rpy="1.570796326794896558 1.570796326794896558 0" />
<geometry>
<mesh filename="package:///part_6.stl"/>
</geometry>
<material name="part_6_material">
<color rgba="0.97254901960784312376 0.52941176470588235947 0.0039215686274509803377 1.0"/>
</material>
</collision>
<inertial>
<origin xyz="-0.035355341728539810275 -0.035355341728539768642 -0.025000000000000022204" rpy="0 0 0"/>
<mass value="0.17551650370110782884" />
<inertia ixx="0.00017174797865715228672" ixy="-0.00014130922109905220529"  ixz="-2.1413438504095485543e-10" iyy="0.00017174799171019406135" iyz="2.1413438492727387289e-10" izz="0.00029665639647466187159" />
</inertial>
</link>

<link name="part_10">
<visual>
<origin xyz="-0.1500000000000000222 0.037499999999999977796 -0.5374999999999999778" rpy="-5.9702185741026477647e-17 6.1369028452092178133e-17 -9.2490865013647054847e-18" />
<geometry>
<mesh filename="package:///part_10.stl"/>
</geometry>
<material name="part_10_material">
<color rgba="0.64705882352941179736 0.64705882352941179736 0.64705882352941179736 1.0"/>
</material>
</visual>
<collision>
<origin xyz="-0.1500000000000000222 0.037499999999999977796 -0.5374999999999999778" rpy="-5.9702185741026477647e-17 6.1369028452092178133e-17 -9.2490865013647054847e-18" />
<geometry>
<mesh filename="package:///part_10.stl"/>
</geometry>
<material name="part_10_material">
<color rgba="0.64705882352941179736 0.64705882352941179736 0.64705882352941179736 1.0"/>
</material>
</collision>
<inertial>
<origin xyz="-9.3876438511664161979e-08 -0.013400831090399563036 -0.36166020475101046117" rpy="0 0 0"/>
<mass value="0.90567963678863572241" />
<inertia ixx="0.03638148215704131716" ixy="-3.9476791246381778514e-09"  ixz="4.4372887870260845632e-09" iyy="0.035469136279841273485" iyz="0.00091260421732966144799" izz="0.0009833240198905885722" />
</inertial>
</link>

<link name="fermeture1_A_3D">
<inertial>
<origin xyz="0 0 0" rpy="0 0 0" />
<mass value="1e-9" />
<inertia ixx="0" ixy="0" ixz="0" iyy="0" iyz="0" izz="0" />
</inertial>
</link>
<joint name="fermeture1_A_3D_frame" type="fixed">
<origin xyz="-2.7755575615628913511e-17 -0.13258252147247762132 -0.24241747852752240644" rpy="-0.78539816339742640761 -4.5827873791404860184e-17 3.141592653589793116" />
<parent link="part_10" />
<child link="fermeture1_A_3D" />
<axis xyz="0 0 0"/>
</joint>

<link name="part_11">
<visual>
<origin xyz="0.024999999999999716893 0.12793667596226657168 -1.2991229031629221158" rpy="-2.9670597283903603625 -1.1681447195714874764e-16 1.5682698563439640592e-18" />
<geometry>
<mesh filename="package:///part_11.stl"/>
</geometry>
<material name="part_11_material">
<color rgba="0.2313725490196078538 0.38039215686274507888 0.7058823529411765163 1.0"/>
</material>
</visual>
<collision>
<origin xyz="0.024999999999999716893 0.12793667596226657168 -1.2991229031629221158" rpy="-2.9670597283903603625 -1.1681447195714874764e-16 1.5682698563439640592e-18" />
<geometry>
<mesh filename="package:///part_11.stl"/>
</geometry>
<material name="part_11_material">
<color rgba="0.2313725490196078538 0.38039215686274507888 0.7058823529411765163 1.0"/>
</material>
</collision>
<inertial>
<origin xyz="-0.043253047751056220016 -8.3266726846886740532e-17 -0.0050000000000003375078" rpy="0 0 0"/>
<mass value="0.8642975688726014516" />
<inertia ixx="0.0076244090856789148783" ixy="6.4463137938681832243e-23"  ixz="-1.6929310182199401932e-19" iyy="0.0013575864967298972678" iyz="-6.1007788198681744039e-19" izz="0.0089675906229276028392" />
</inertial>
</link>

<link name="fermeture2_B_3D">
<inertial>
<origin xyz="0 0 0" rpy="0 0 0" />
<mass value="1e-9" />
<inertia ixx="0" ixy="0" ixz="0" iyy="0" iyz="0" izz="0" />
</inertial>
</link>
<joint name="fermeture2_B_3D_frame" type="fixed">
<origin xyz="-0.087500000000000105471 0.11249999999999971134 -4.4408920985006261617e-16" rpy="6.7233776258586636952e-15 2.6045361486186078984e-14 3.141592653589793116" />
<parent link="part_11" />
<child link="fermeture2_B_3D" />
<axis xyz="0 0 0"/>
</joint>

<link name="fermeture3_B_3D">
<inertial>
<origin xyz="0 0 0" rpy="0 0 0" />
<mass value="1e-9" />
<inertia ixx="0" ixy="0" ixz="0" iyy="0" iyz="0" izz="0" />
</inertial>
</link>
<joint name="fermeture3_B_3D_frame" type="fixed">
<origin xyz="-0.087499999999999966693 -0.11250000000000004441 -8.8817841970012523234e-16" rpy="6.7233776258586636952e-15 2.6045361486186078984e-14 3.141592653589793116" />
<parent link="part_11" />
<child link="fermeture3_B_3D" />
<axis xyz="0 0 0"/>
</joint>

<link name="bout_pied">
<inertial>
<origin xyz="0 0 0" rpy="0 0 0" />
<mass value="1e-9" />
<inertia ixx="0" ixy="0" ixz="0" iyy="0" iyz="0" izz="0" />
</inertial>
</link>
<joint name="bout_pied_frame" type="fixed">
<origin xyz="-0.042253047751056094228 -1.6653345369377348106e-16 -0.0099999999999996758149" rpy="-1.1358752210888944033e-17 -5.5582323750526868971e-17 -1.570796326794896336" />
<parent link="part_11" />
<child link="bout_pied" />
<axis xyz="0 0 0"/>
</joint>

<joint name="to_rotule_5" type="revolute">
<origin xyz="-2.7755575615628913511e-17 -2.7755575615628913511e-17 -0.74999999999999955591" rpy="-8.5137740643839942495e-16 2.6500876599504935188e-15 0.083874122280483048852" />
<parent link="part_10" />
<child link="part_11" />
<axis xyz="0 0 1"/>
<limit effort="1" velocity="20" />
<joint_properties friction="0.0"/>
</joint>

<joint name="to_rotule_4" type="revolute">
<origin xyz="-0.070710678118654626823 -0.070710678118654710089 -0.02500000000000004996" rpy="-1.57079632679489678 1.2954895654242877256 -1.5707963267948905628" />
<parent link="part_6_2" />
<child link="part_10" />
<axis xyz="0 0 1"/>
<limit effort="1" velocity="20" />
<joint_properties friction="0.0"/>
</joint>

<joint name="motor_4" type="revolute">
<origin xyz="0.02500000000000004996 -4.5970172113385388002e-17 -0.099999999999999963918" rpy="1.5707963267948961139 0.051325342138394722258 -1.5707963267948972241" />
<parent link="part_2" />
<child link="part_6_2" />
<axis xyz="0 0 1"/>
<limit effort="1" velocity="20" />
<joint_properties friction="0.0"/>
</joint>

<joint name="motor_1" type="revolute">
<origin xyz="0.024999999999999997918 0.14999999999999993894 6.2016364266170853625e-17" rpy="-1.57079632679489678 0.013989913782349417543 1.570796326794896558" />
<parent link="part_1" />
<child link="part_2" />
<axis xyz="0 0 1"/>
<limit effort="1" velocity="20" />
<joint_properties friction="0.0"/>
</joint>

<link name="part_3">
<visual>
<origin xyz="-0.14999999999999999445 0 3.4694469519536141888e-18" rpy="1.570796326794896558 -1.3666262314034771019e-32 7.2181309166948328129e-18" />
<geometry>
<mesh filename="package:///part_3.stl"/>
</geometry>
<material name="part_3_material">
<color rgba="0.2313725490196078538 0.38039215686274507888 0.7058823529411765163 1.0"/>
</material>
</visual>
<collision>
<origin xyz="-0.14999999999999999445 0 3.4694469519536141888e-18" rpy="1.570796326794896558 -1.3666262314034771019e-32 7.2181309166948328129e-18" />
<geometry>
<mesh filename="package:///part_3.stl"/>
</geometry>
<material name="part_3_material">
<color rgba="0.2313725490196078538 0.38039215686274507888 0.7058823529411765163 1.0"/>
</material>
</collision>
<inertial>
<origin xyz="-1.9668055600829958962e-08 -0.059907069836739448854 -0.058820580957796256283" rpy="0 0 0"/>
<mass value="0.89039644551396013306" />
<inertia ixx="0.0071259914115998461426" ixy="-2.0431833884581150468e-09"  ixz="-1.6994146886149071918e-09" iyy="0.0011186437057284131028" iyz="0.0011372607353434156796" izz="0.006285090419380011742" />
</inertial>
</link>

<link name="part_4_2">
<visual>
<origin xyz="0.1500000000000000222 0.087500000000000008327 -0.050000000000000002776" rpy="-1.570796326794896558 -6.1232339957367660359e-17 -5.5600120258161464222e-18" />
<geometry>
<mesh filename="package:///part_4.stl"/>
</geometry>
<material name="part_4_material">
<color rgba="0.91764705882352937127 0.91764705882352937127 0.91764705882352937127 1.0"/>
</material>
</visual>
<collision>
<origin xyz="0.1500000000000000222 0.087500000000000008327 -0.050000000000000002776" rpy="-1.570796326794896558 -6.1232339957367660359e-17 -5.5600120258161464222e-18" />
<geometry>
<mesh filename="package:///part_4.stl"/>
</geometry>
<material name="part_4_material">
<color rgba="0.91764705882352937127 0.91764705882352937127 0.91764705882352937127 1.0"/>
</material>
</collision>
<inertial>
<origin xyz="0.068078690960163598667 -7.8090537231068068991e-09 -0.012499981479117964339" rpy="0 0 0"/>
<mass value="0.16139278769787171464" />
<inertia ixx="1.2982580317980115878e-05" ixy="-4.4490796314333686656e-11"  ixz="1.3969239536077338057e-10" iyy="0.00036360474045782586973" iyz="-1.876251737389522372e-10" izz="0.00036339084218598279247" />
</inertial>
</link>

<link name="fermeture4_A_6D">
<inertial>
<origin xyz="0 0 0" rpy="0 0 0" />
<mass value="1e-9" />
<inertia ixx="0" ixy="0" ixz="0" iyy="0" iyz="0" izz="0" />
</inertial>
</link>
<joint name="fermeture4_A_6D_frame" type="fixed">
<origin xyz="0.15000000000000010547 1.3877787807814456755e-17 -0.012500000000000011102" rpy="1.57079632679489678 7.5481860448668965881e-32 -1.5707963267948972241" />
<parent link="part_4_2" />
<child link="fermeture4_A_6D" />
<axis xyz="0 0 0"/>
</joint>

<joint name="to_rotule_2" type="revolute">
<origin xyz="-2.7755575615628913511e-17 0.08750000000000004996 -0.04999999999999997502" rpy="-8.9502306368965188187e-16 -3.2298024022125919443e-16 -0.22686538676885123489" />
<parent link="part_3" />
<child link="part_4_2" />
<axis xyz="0 0 1"/>
<limit effort="1" velocity="20" />
<joint_properties friction="0.0"/>
</joint>

<link name="part_5">
<visual>
<origin xyz="0.037499999999999977796 -0.16250000000000000555 -0.125" rpy="-1.57079632679489678 -1.570796326794896558 0" />
<geometry>
<mesh filename="package:///part_5.stl"/>
</geometry>
<material name="part_5_material">
<color rgba="0.76862745098039220171 0.88627450980392152857 0.95294117647058818044 1.0"/>
</material>
</visual>
<collision>
<origin xyz="0.037499999999999977796 -0.16250000000000000555 -0.125" rpy="-1.57079632679489678 -1.570796326794896558 0" />
<geometry>
<mesh filename="package:///part_5.stl"/>
</geometry>
<material name="part_5_material">
<color rgba="0.76862745098039220171 0.88627450980392152857 0.95294117647058818044 1.0"/>
</material>
</collision>
<inertial>
<origin xyz="-0.05639521740213002815 0.056395220324961914393 -0.024999999855950319483" rpy="0 0 0"/>
<mass value="0.41358872938673529873" />
<inertia ixx="0.00042741628234743901009" ixy="0.00027187610450303984497"  ixz="1.4782400244256316969e-10" iyy="0.00042741629562205370749" iyz="1.4848231413857153737e-10" izz="0.00070211058220667342707" />
</inertial>
</link>

<link name="part_7">
<visual>
<origin xyz="0.10821067811865475727 -0.23321067811865472952 -0.075000000000000038858" rpy="-1.570796326794896558 -1.570796326794896558 0" />
<geometry>
<mesh filename="package:///part_7.stl"/>
</geometry>
<material name="part_7_material">
<color rgba="0.49803921568627451677 0.49803921568627451677 0.49803921568627451677 1.0"/>
</material>
</visual>
<collision>
<origin xyz="0.10821067811865475727 -0.23321067811865472952 -0.075000000000000038858" rpy="-1.570796326794896558 -1.570796326794896558 0" />
<geometry>
<mesh filename="package:///part_7.stl"/>
</geometry>
<material name="part_7_material">
<color rgba="0.49803921568627451677 0.49803921568627451677 0.49803921568627451677 1.0"/>
</material>
</collision>
<inertial>
<origin xyz="-0.10520701255565163834 -0.59665825866968547064 -0.024999943916012887235" rpy="0 0 0"/>
<mass value="1.265846116802230803" />
<inertia ixx="0.16930115712399654293" ixy="-0.029833403540811712779"  ixz="-9.2844440020719764654e-09" iyy="0.0053676764405772197167" iyz="-1.746263923764789778e-08" izz="0.17455337417460853322" />
</inertial>
</link>

<link name="fermeture3_A_3D">
<inertial>
<origin xyz="0 0 0" rpy="0 0 0" />
<mass value="1e-9" />
<inertia ixx="0" ixy="0" ixz="0" iyy="0" iyz="0" izz="0" />
</inertial>
</link>
<joint name="fermeture3_A_3D_frame" type="fixed">
<origin xyz="-0.21706022208366310133 -1.2310096912652599421 -0.025000000000000022204" rpy="-1.7453292519943326422 -1.5707963267948950037 0" />
<parent link="part_7" />
<child link="fermeture3_A_3D" />
<axis xyz="0 0 0"/>
</joint>

<joint name="motor_5" type="revolute">
<origin xyz="-0.070710678118654710089 0.070710678118654779478 -0.049999999999999988898" rpy="6.3333643009512519113e-16 2.1040868441862875751e-16 -0.38222784846587853913" />
<parent link="part_5" />
<child link="part_7" />
<axis xyz="0 0 1"/>
<limit effort="1" velocity="20" />
<joint_properties friction="0.0"/>
</joint>

<joint name="motor_2" type="revolute">
<origin xyz="-0.024999999999999994449 -0.16250000000000003331 -0.037499999999999991673" rpy="-1.5707963267948938935 -1.2866019799549408553 -1.570796326794896336" />
<parent link="part_3" />
<child link="part_5" />
<axis xyz="0 0 1"/>
<limit effort="1" velocity="20" />
<joint_properties friction="0.0"/>
</joint>

<link name="part_6_3">
<visual>
<origin xyz="0.10821067811865475727 0.23321067811865472952 -0.12499999999999994449" rpy="1.570796326794896558 1.570796326794896558 0" />
<geometry>
<mesh filename="package:///part_6.stl"/>
</geometry>
<material name="part_6_material">
<color rgba="0.97254901960784312376 0.52941176470588235947 0.0039215686274509803377 1.0"/>
</material>
</visual>
<collision>
<origin xyz="0.10821067811865475727 0.23321067811865472952 -0.12499999999999994449" rpy="1.570796326794896558 1.570796326794896558 0" />
<geometry>
<mesh filename="package:///part_6.stl"/>
</geometry>
<material name="part_6_material">
<color rgba="0.97254901960784312376 0.52941176470588235947 0.0039215686274509803377 1.0"/>
</material>
</collision>
<inertial>
<origin xyz="0.035355336390114934508 0.035355336390114927569 -0.024999999999999980571" rpy="0 0 0"/>
<mass value="0.17551650370110782884" />
<inertia ixx="0.00017174797865715234093" ixy="-0.00014130922109905223239"  ixz="-2.1413438504591734457e-10" iyy="0.00017174799171019406135" iyz="2.1413438492983019702e-10" izz="0.00029665639647466187159" />
</inertial>
</link>

<link name="part_9">
<visual>
<origin xyz="0.23844681136885254036 -0.5053951366405011747 -0.074999999999999927836" rpy="1.570796326794896558 1.570796326794896558 0" />
<geometry>
<mesh filename="package:///part_9.stl"/>
</geometry>
<material name="part_9_material">
<color rgba="0.61568627450980395466 0.81176470588235294379 0.92941176470588238168 1.0"/>
</material>
</visual>
<collision>
<origin xyz="0.23844681136885254036 -0.5053951366405011747 -0.074999999999999927836" rpy="1.570796326794896558 1.570796326794896558 0" />
<geometry>
<mesh filename="package:///part_9.stl"/>
</geometry>
<material name="part_9_material">
<color rgba="0.61568627450980395466 0.81176470588235294379 0.92941176470588238168 1.0"/>
</material>
</collision>
<inertial>
<origin xyz="-0.061855907839602049247 0.35080273330139100096 -0.024999979052229306248" rpy="0 0 0"/>
<mass value="0.7749759693024955709" />
<inertia ixx="0.038565136483213607876" ixy="0.006787941614597318811"  ixz="2.5944817376921894748e-09" iyy="0.001265804521069832829" iyz="6.3686268019586098067e-09" izz="0.039753831424396597616" />
</inertial>
</link>

<link name="fermeture2_A_3D">
<inertial>
<origin xyz="0 0 0" rpy="0 0 0" />
<mass value="1e-9" />
<inertia ixx="0" ixy="0" ixz="0" iyy="0" iyz="0" izz="0" />
</inertial>
</link>
<joint name="fermeture2_A_3D_frame" type="fixed">
<origin xyz="-0.13023613325019786635 0.73860581475915543237 -0.025000000000000327516" rpy="1.7453292519943301997 -1.5707963267948950037 0" />
<parent link="part_9" />
<child link="fermeture2_A_3D" />
<axis xyz="0 0 0"/>
</joint>

<joint name="free_2" type="revolute">
<origin xyz="0.070710678118654751723 0.070710678118654626823 -5.5511151231257827021e-17" rpy="3.4265642180934863276e-15 1.7795788820697097267e-15 -0.32856305123369911048" />
<parent link="part_6_3" />
<child link="part_9" />
<axis xyz="0 0 1"/>
<limit effort="1" velocity="20" />
<joint_properties friction="0.0"/>
</joint>

<joint name="motor_6" type="revolute">
<origin xyz="-0.02500000000000004996 -3.4694469519536141888e-18 -0.10000000000000000555" rpy="1.5707963267948936714 1.4906963158485633247 1.5707963267948894526" />
<parent link="part_3" />
<child link="part_6_3" />
<axis xyz="0 0 1"/>
<limit effort="1" velocity="20" />
<joint_properties friction="0.0"/>
</joint>

<joint name="free_1" type="revolute">
<origin xyz="0.024999999999999997918 -0.1500000000000000222 6.9388939039072283776e-18" rpy="-1.57079632679489678 0.15752016499006332717 1.570796326794896558" />
<parent link="part_1" />
<child link="part_3" />
<axis xyz="0 0 1"/>
<limit effort="1" velocity="20" />
<joint_properties friction="0.0"/>
</joint>


</robot>
